Workbook

Sheet Cover
A1: Discounted Cash Flow Analysis — CELH | C1: BUY | D1: +106.8% to IP $58.99
A2: (Values in USD, except per share data) | C2: Bear $39.65 / Base $58.99 / Bull $87.41
A3: Analyst: | C3: Date: | D3: June 25, 2026
A5: VALUATION SUMMARY
A6: Method | B6: Implied Price | C6: vs. Current | D6: Upside Signal
A7: Current Price | B7: ='DCF & TV'!$B$25
A8: Gordon Growth Perpetuity | B8: ='DCF & TV'!$B$22 | C8: ='DCF & TV'!$B$22/'DCF & TV'!$B$25-1 | D8: BUY ▲
A9: EV/EBITDA Exit Multiple | B9: ='DCF & TV'!$B$23 | C9: ='DCF & TV'!$B$23/'DCF & TV'!$B$25-1 | D9: BUY ▲
A10: Blended 50/50 ★ Primary | B10: ='DCF & TV'!$B$24 | C10: ='DCF & TV'!$B$24/'DCF & TV'!$B$25-1 | D10: BUY ▲
A12: SCENARIO ANALYSIS
A13: Scenario | B13: Implied Price | C13: vs. Current | D13: Terminal g
A14: Bear | B14: 39.650077 | C14: 0.39025516 | D14: 0.02
A15: Base | B15: 58.986703 | C15: 1.0682575 | D15: 0.025
A16: Bull | B16: 87.408402 | C16: 2.0648107 | D16: 0.03
A18: KEY ASSUMPTIONS
A19: WACC | B19: ='WACC Build'!$B$17
A20: Terminal Growth Rate | B20: =Inputs!$B$40
A21: Year-1 Revenue Growth | B21: =Inputs!$B$26
A22: Year-N Revenue Growth (fade) | B22: =Inputs!$B$35
A23: EBIT Margin Target (Year N) | B23: =Inputs!$B$36
A24: EV/EBITDA Exit Multiple | B24: =Inputs!$B$41
A25: TV % of EV (Gordon) | B25: ='DCF & TV'!$B$8 | C25: ⚠ Terminal value bet — >75% of EV
A27: EQUITY BRIDGE (BLENDED)
A28: Enterprise Value (Blended) | B28: ='DCF & TV'!$B$15
A29: (Less) Total Debt + Leases | B29: ='DCF & TV'!$B$16+'DCF & TV'!$B$17
A30: (Plus) Cash | B30: ='DCF & TV'!$B$18
A31: Equity Value (Blended) | B31: ='DCF & TV'!$B$20
A32: Diluted Shares | B32: =Inputs!$B$12
A34: COMPANY FRAMING
A35: Celsius Holdings generates revenue through branded energy drink sales via retail and distributor channels, with Pepsi distribution partnership since 2022 driving rapid expansion. Company is in high-growth phase with 86% CAGR from FY2022-FY2025, though FY2024 deceleration to 8% YoY suggests transition toward maturation before projected FY2025 reacceleration to 79%. Central debate is whether CELH can sustain premium growth and shelf space gains against Monster and Red Bull or faces margin compression and share loss as energy drink category matures and competition intensifies.
A37: INVESTMENT CONCLUSION
A38: Implied value of $58.99 versus current price of $28.52 yields 106.8% upside, supporting the BUY rating. Thesis hinges on Celsius sustaining premium revenue growth rates in a maturing energy drink category where terminal value comprises 76% of enterprise value. Invalidation trigger: two consecutive quarters of market share loss to Monster or Red Bull in tracked channels, or Pepsi distribution agreement non-renewal in 2026.

Sheet Trading View
A1: Trading View — CELH | June 25, 2026
A2: (Implied prices from blended Gordon Growth + EV/EBITDA DCF)
A4: RATING & PRICE TARGET
A5: BUY | B5: +106.8% upside to IP | C5: Current: $28.52 | D5: IP (Blended): $58.99
A7: SCENARIO PRICE RANGE (Bear / Base / Bull)
A8: Scenario | B8: Implied Price | C8: vs. Current | D8: WACC
A9: Bear | B9: 39.650077 | C9: 0.39025516 | D9: 0.087398008
A10: Base | B10: 58.986703 | C10: 1.0682575 | D10: 0.087398008
A11: Bull | B11: 87.408402 | C11: 2.0648107 | D11: 0.087398008
A13: POSITIONING & HEDGING STRATEGIES
A14: BUY — 107% upside to base IP $58.99.
A16: Strategy | B16: Details
A17: EQUITY — Increase position.
A18: LONG CALL (5% OTM) | B18: Strike: $30.00 (+5.2% vs current $28.52)
A19: CALL SPREAD (ATM / +15% OTM) | B19: Buy $27.50 call / Sell $32.50 call | Spread width: $5.00
A21: DISCLAIMER: This analysis is model-generated for internal use only. Options strikes are indicative levels derived from current price — no expiry date or premium is specified. Not investment advice.

Sheet Inputs
A1: Inputs & Assumptions — CELH
A2: (Values in USD, except per share data)
A3: Input | B3: Value | C3: Source
A5: SECTION A — MARKET & BRIDGE DATA
A6: Current Stock Price | B6: 28.52 | C6: Yahoo Finance — info['currentPrice']
A7: Market Capitalization (Equity) | B7: 7290863104 | C7: Yahoo Finance — info['marketCap'] (used as equity weight in WACC)
A8: Total Debt (LT + ST, ex-leases) | B8: 683926000 | C8: SEC EDGAR — LongTermDebt + ShortTermBorrowings (clean, no leases)
A9: Cash & Equivalents | B9: 549201024 | C9: Yahoo Finance — info['totalCash'] (falls back to EDGAR)
A10: Lease Liabilities | B10: 18216000 | C10: SEC EDGAR — OperatingLeaseLiability (most recent 10-K FY; added separately)
A11: Shares Outstanding | B11: 255640360 | C11: Yahoo Finance — info['sharesOutstanding']
A12: Shares Diluted (Weighted Avg) | B12: 254911000 | C12: SEC EDGAR — WeightedAverageNumberOfDilutedSharesOutstanding (falls back to Yahoo impliedSharesOutstanding)
A14: SECTION B — WACC INPUTS
A15: Risk-Free Rate (10Y Treasury) | B15: 0.045 | C15: FRED — series DGS10 (10-Year Treasury Constant Maturity)
A16: Equity Risk Premium (ERP) | B16: 0.045 | C16: config.py BASE_ERP constant — Damodaran-consistent forward ERP (~4.5%). NOT a trailing realized return. See config.py for documentation.
A17: Country Risk Premium (CRP) | B17: 0 | C17: data/market_risk.py — 0% for US (sovereign spread data required for non-US)
A18: Unlevered Beta | B18: 0.83878309 | C18: yfinance — levered beta (5-yr monthly vs S&P 500), unlevered via Hamada using company D/E ratio and EDGAR effective tax rate
A19: Tax Rate | B19: 0.20502451 | C19: SEC EDGAR — IncomeTax ÷ (NetIncome + IncomeTax) most recent 10-K; capped at 40%
A20: Size Premium | B20: 0.005 | C20: Duff & Phelps style: <$500M→3.5%, <$2B→2.5%, <$5B→1.5%, <$10B→0.5%, >$10B→0%
A21: Cost of Debt Spread (EDGAR-derived) | B21: 0.022657321 | C21: EDGAR-derived: InterestExpense/TotalDebt − rf (fallback: rf + 200bps if data insufficient)
A23: SECTION C — FORECAST ASSUMPTIONS
A24: Base Revenue — Last Fiscal Year | B24: 2515269000 | C24: SEC EDGAR — Revenues (or RevenueFromContractWithCustomer) FY2025
A25: Base EBIT Margin — Smoothed Anchor | B25: 0.037555773 | C25: SEC EDGAR — recency-weighted avg of historical OperatingIncomeLoss ÷ Revenues (weights 1..n, newest heaviest; one-off years clipped). Used by the forecast engine AND these sheet formulas — identical by construction
A26: Revenue Growth — Year 1 | B26: 0.35507028 | C26: Year-1 growth — 50/50 blend of 3-yr historical CAGR and consensus revenue est (assumption input, not target anchoring); capped at 50%
A27: Revenue Growth — Year 2 | B27: 0.3183958 | C27: Linear fade from Year-1 to Year-N growth
A28: Revenue Growth — Year 3 | B28: 0.28172133 | C28: Linear fade from Year-1 to Year-N growth
A29: Revenue Growth — Year 4 | B29: 0.24504685 | C29: Linear fade from Year-1 to Year-N growth
A30: Revenue Growth — Year 5 | B30: 0.20837238 | C30: Linear fade from Year-1 to Year-N growth
A31: Revenue Growth — Year 6 | B31: 0.1716979 | C31: Linear fade from Year-1 to Year-N growth
A32: Revenue Growth — Year 7 | B32: 0.13502343 | C32: Linear fade from Year-1 to Year-N growth
A33: Revenue Growth — Year 8 | B33: 0.09834895 | C33: Linear fade from Year-1 to Year-N growth
A34: Revenue Growth — Year 9 | B34: 0.061674475 | C34: Linear fade from Year-1 to Year-N growth
A35: Revenue Growth — Year 10 | B35: 0.025 | C35: Year-10 growth — fades to Terminal Growth Rate
... A43: Analyst Consensus Target — BENCHMARK ONLY | B43: 60.2381 | C43: Yahoo Finance targetMeanPrice — reasonableness benchmark for validation; NOT a model input, used in no calculation
A44: Pipeline Fingerprint | B44: 69251fe7222b | C44: SHA-256 (12 hex) over the model source files that produced this workbook — validation fails any workbook built by a superseded pipeline version
A45: SECTION D — SCENARIO ASSUMPTIONS [Bear / Base / Bull]
A46: Bear: revenue growth −5pp each year, terminal_g −0.5pp [WACC unchanged]
A47: Base: No adjustment — main model output
A48: Bull: revenue growth +5pp each year, terminal_g +0.5pp [WACC unchanged]
A49: Scenarios rebuilt via build_forecast() with adjusted growth schedule — not a blunt FCFF multiplier.
A52: ⚠ SECTION E — KEY WARNINGS
...

Sheet P&L Bridge
A1: CELH — Historical + Forecast P&L Bridge
A2: (Values in USD, except per share data)
B3: ◀ Historical Period | G3: Projection Period ►
A4: Metric | B4: FY2021 | C4: FY2022 | D4: FY2023 | E4: FY2024 | F4: FY2025 | G4: Y1 ► | H4: Y2 ► | I4: Y3 ► | J4: Y4 ► | K4: Y5 ► | L4: Y6 ► | M4: Y7 ► | N4: Y8 ► | O4: Y9 ► | P4: Y10 ►
A5: Revenue | B5: 315000 | C5: 653604000 | D5: 1318014000 | E5: 1355630000 | F5: 2515269000 | G5: =Forecast!$B$4 | H5: =Forecast!$C$4 | I5: =Forecast!$D$4 | J5: =Forecast!$E$4 | K5: =Forecast!$F$4 | L5: =Forecast!$G$4 | M5: =Forecast!$H$4 | N5: =Forecast!$I$4 | O5: =Forecast!$J$4 | P5: =Forecast!$K$4
A6: Revenue Growth (%) | C6: 2073.9333 | D6: 1.0165329 | E6: 0.028539909 | F6: 0.85542442 | G6: =Inputs!$B$26 | H6: =Inputs!$B$27 | I6: =Inputs!$B$28 | J6: =Inputs!$B$29 | K6: =Inputs!$B$30 | L6: =Inputs!$B$31 | M6: =Inputs!$B$32 | N6: =Inputs!$B$33 | O6: =Inputs!$B$34 | P6: =Inputs!$B$35
A7: EBIT — Operating Income | B7: -4090000 | C7: -157801000 | D7: 266366000 | E7: 155728000 | F7: 141062000 | G7: =Forecast!$B$6 | H7: =Forecast!$C$6 | I7: =Forecast!$D$6 | J7: =Forecast!$E$6 | K7: =Forecast!$F$6 | L7: =Forecast!$G$6 | M7: =Forecast!$H$6 | N7: =Forecast!$I$6 | O7: =Forecast!$J$6 | P7: =Forecast!$K$6
A8: EBIT Margin (%) | B8: -12.984127 | C8: -0.24143212 | D8: 0.20209649 | E8: 0.114875 | F8: 0.056082272 | G8: =Forecast!$B$5 | H8: =Forecast!$C$5 | I8: =Forecast!$D$5 | J8: =Forecast!$E$5 | K8: =Forecast!$F$5 | L8: =Forecast!$G$5 | M8: =Forecast!$H$5 | N8: =Forecast!$I$5 | O8: =Forecast!$J$5 | P8: =Forecast!$K$5
A9: NOPAT [EBIT × (1−t)] | B9: -3251449 | C9: -125447927 | D9: 211754441 | E9: 123799943 | F9: 112140832 | G9: =Forecast!$B$7 | H9: =Forecast!$C$7 | I9: =Forecast!$D$7 | J9: =Forecast!$E$7 | K9: =Forecast!$F$7 | L9: =Forecast!$G$7 | M9: =Forecast!$H$7 | N9: =Forecast!$I$7 | O9: =Forecast!$J$7 | P9: =Forecast!$K$7
A10: D&A | B10: 1264000 | C10: 1917000 | D10: 3226000 | E10: 7274000 | F10: 29451000 | G10: =Forecast!$B$8 | H10: =Forecast!$C$8 | I10: =Forecast!$D$8 | J10: =Forecast!$E$8 | K10: =Forecast!$F$8 | L10: =Forecast!$G$8 | M10: =Forecast!$H$8 | N10: =Forecast!$I$8 | O10: =Forecast!$J$8 | P10: =Forecast!$K$8
A11: Capex | B11: 30830 | C11: 49534 | D11: 110417 | E11: 77974 | F11: 573751 | G11: =Forecast!$B$9 | H11: =Forecast!$C$9 | I11: =Forecast!$D$9 | J11: =Forecast!$E$9 | K11: =Forecast!$F$9 | L11: =Forecast!$G$9 | M11: =Forecast!$H$9 | N11: =Forecast!$I$9 | O11: =Forecast!$J$9 | P11: =Forecast!$K$9
A12: FCFF [NOPAT + D&A − Capex − ΔNWC] | B12: -2018279 | C12: -123580461 | D12: 214870024 | E12: 130995969 | F12: 141018081 | G12: =Forecast!$B$11 | H12: =Forecast!$C$11 | I12: =Forecast!$D$11 | J12: =Forecast!$E$11 | K12: =Forecast!$F$11 | L12: =Forecast!$G$11 | M12: =Forecast!$H$11 | N12: =Forecast!$I$11 | O12: =Forecast!$J$11 | P12: =Forecast!$K$11
A14: Historical FCFF simplified as NOPAT+D&A−Capex (ΔNWC excluded for actuals). Forecast columns are live Excel formulas referencing the Forecast sheet. Thick blue border = start of forecast period.

Sheet WACC Build
A1: WACC Build
A2: (Values in USD, except per share data)
A3: Component | B3: Value
A4: Risk-Free Rate | B4: =Inputs!$B$15
A5: Equity Risk Premium (ERP) | B5: =Inputs!$B$16
A6: Country Risk Premium (CRP) | B6: =Inputs!$B$17
A7: Unlevered Beta (Damodaran) | B7: =Inputs!$B$18
A8: D/E Ratio [(Debt+Leases) ÷ Market Cap Equity] | B8: =(Inputs!$B$8+Inputs!$B$10)/Inputs!$B$7
A9: Tax Rate | B9: =Inputs!$B$19
A10: Levered Beta [Hamada: B7×(1+(1−B9)×B8)] | B10: =B7*(1+(1-B9)*B8)
A11: Size Premium | B11: =Inputs!$B$20
A12: Cost of Equity [CAPM: B4+B10×(B5+B6)+B11] | B12: =B4+B10*(B5+B6)+B11
A13: Cost of Debt (pre-tax) [rf + spread] | B13: =Inputs!$B$15+Inputs!$B$21
A14: Cost of Debt (after-tax) [B13×(1−B9)] | B14: =B13*(1-B9)
A15: Weight: Equity [MktCap÷(MktCap+Debt+Leases)] | B15: =Inputs!$B$7/(Inputs!$B$7+Inputs!$B$8+Inputs!$B$10)
A16: Weight: Debt [(Debt+Leases)÷(MktCap+Debt+Leases)] | B16: =(Inputs!$B$8+Inputs!$B$10)/(Inputs!$B$7+Inputs!$B$8+Inputs!$B$10)
A17: WACC [B15×B12 + B16×B14] | B17: =B15*B12+B16*B14
A20: Analyst Notes
A21: WACC of 8.7% driven primarily by cost of equity at 9.1% (91% weight) and low leverage with D/E of just 0.10. Hamada unlevering from levered beta 0.90 to unlevered beta 0.84 uses formula uB = lB / (1 + (1-t) × D/E) = 0.90 / (1 + 0.795 × 0.10) = 0.83, which rounds to the stated 0.84. ERP assumption of 4.50% is most sensitive given it flows directly through the 0.90 beta to move Ke by 90bps per 100bp ERP change. Levered beta of 0.90 appears low for a high-growth consumer beverage company with significant revenue volatility; peer Monster trades closer to 1

Sheet Forecast
A1: 10-Year FCF Projections
A2: (Values in USD, except per share data)
A3: Metric | B3: Year 1 | C3: Year 2 | D3: Year 3 | E3: Year 4 | F3: Year 5 | G3: Year 6 | H3: Year 7 | I3: Year 8 | J3: Year 9 | K3: Year 10
A4: Revenue | B4: =Inputs!$B$24*(1+Inputs!$B$26) | C4: =B4*(1+Inputs!$B$27) | D4: =C4*(1+Inputs!$B$28) | E4: =D4*(1+Inputs!$B$29) | F4: =E4*(1+Inputs!$B$30) | G4: =F4*(1+Inputs!$B$31) | H4: =G4*(1+Inputs!$B$32) | I4: =H4*(1+Inputs!$B$33) | J4: =I4*(1+Inputs!$B$34) | K4: =J4*(1+Inputs!$B$35)
A5: EBIT Margin | B5: =Inputs!$B$25+(Inputs!$B$36-Inputs!$B$25)*(1/10) | C5: =Inputs!$B$25+(Inputs!$B$36-Inputs!$B$25)*(2/10) | D5: =Inputs!$B$25+(Inputs!$B$36-Inputs!$B$25)*(3/10) | E5: =Inputs!$B$25+(Inputs!$B$36-Inputs!$B$25)*(4/10) | F5: =Inputs!$B$25+(Inputs!$B$36-Inputs!$B$25)*(5/10) | G5: =Inputs!$B$25+(Inputs!$B$36-Inputs!$B$25)*(6/10) | H5: =Inputs!$B$25+(Inputs!$B$36-Inputs!$B$25)*(7/10) | I5: =Inputs!$B$25+(Inputs!$B$36-Inputs!$B$25)*(8/10) | J5: =Inputs!$B$25+(Inputs!$B$36-Inputs!$B$25)*(9/10) | K5: =Inputs!$B$25+(Inputs!$B$36-Inputs!$B$25)*(10/10)
A6: EBIT | B6: =B4*B5 | C6: =C4*C5 | D6: =D4*D5 | E6: =E4*E5 | F6: =F4*F5 | G6: =G4*G5 | H6: =H4*H5 | I6: =I4*I5 | ... K6: =K4*K5
A7: NOPAT | B7: =B6*(1-Inputs!$B$19) | C7: =C6*(1-Inputs!$B$19) | D7: =D6*(1-Inputs!$B$19) | E7: =E6*(1-Inputs!$B$19) | F7: =F6*(1-Inputs!$B$19) | G7: =G6*(1-Inputs!$B$19) | H7: =H6*(1-Inputs!$B$19) | I7: =I6*(1-Inputs!$B$19) | ... K7: =K6*(1-Inputs!$B$19)
A8: D&A | B8: =B4*Inputs!$B$37 | C8: =C4*Inputs!$B$37 | D8: =D4*Inputs!$B$37 | E8: =E4*Inputs!$B$37 | F8: =F4*Inputs!$B$37 | G8: =G4*Inputs!$B$37 | H8: =H4*Inputs!$B$37 | I8: =I4*Inputs!$B$37 | ... K8: =K4*Inputs!$B$37
A9: Capex | B9: =B4*Inputs!$B$38 | C9: =C4*Inputs!$B$38 | D9: =D4*Inputs!$B$38 | E9: =E4*Inputs!$B$38 | F9: =F4*Inputs!$B$38 | G9: =G4*Inputs!$B$38 | H9: =H4*Inputs!$B$38 | I9: =I4*Inputs!$B$38 | ... K9: =K4*Inputs!$B$38
A10: ΔNWC | B10: =(B4-Inputs!$B$24)*Inputs!$B$39 | C10: =(C4-B4)*Inputs!$B$39 | D10: =(D4-C4)*Inputs!$B$39 | E10: =(E4-D4)*Inputs!$B$39 | F10: =(F4-E4)*Inputs!$B$39 | G10: =(G4-F4)*Inputs!$B$39 | H10: =(H4-G4)*Inputs!$B$39 | I10: =(I4-H4)*Inputs!$B$39 | J10: =(J4-I4)*Inputs!$B$39 | K10: =(K4-J4)*Inputs!$B$39
A11: FCFF | B11: =B7+B8-B9-B10 | C11: =C7+C8-C9-C10 | D11: =D7+D8-D9-D10 | E11: =E7+E8-E9-E10 | F11: =F7+F8-F9-F10 | G11: =G7+G8-G9-G10 | H11: =H7+H8-H9-H10 | I11: =I7+I8-I9-I10 | ... K11: =K7+K8-K9-K10

Sheet DCF & TV
A1: DCF Output — Terminal Value Methods & Equity Bridge
A2: (Values in USD, except per share data)
A3: Line Item | B3: Value
A4: PV of Explicit FCFFs [Σ FCFF÷(1+WACC)^(yr−0.5)] | B4: =Forecast!$B$11/(1+'WACC Build'!$B$17)^0.5+Forecast!$C$11/(1+'WACC Build'!$B$17)^1.5+Forecast!$D$11/(1+'WACC Build'!$B$17)^2.5+Forecast!$E$11/(1+'WACC Build'!$B$17)^3.5+Forecast!$F$11/(1+'WACC Build'!$B$17)^4.5+Forecast!$G$11/(1+'WACC Build'!$B$17)^5.5+Forecast!$H$11/(1+'WACC Build'!$B$17)^6.5+Forecast!$I$11/(1+'WACC Build'!$B$17)^7.5+Forecast!$J$11/(1+'WACC Build'!$B$17)^8.5+Forecast!$K$11/(1+'WACC Build'!$B$17)^9.5
A5: Terminal FCFF [Yr-10 FCFF × (1+g)] | B5: =Forecast!$K$11*(1+Inputs!$B$40)
A6: Terminal Value — Gordon Growth [B5÷(WACC−g)] | B6: =B5/('WACC Build'!$B$17-Inputs!$B$40)
A7: PV of TV (Gordon) [B6÷(1+WACC)^10] | B7: =B6/(1+'WACC Build'!$B$17)^10
A8: ⚠ TV as % of EV — TERMINAL VALUE BET (>75%) | B8: =B7/(B4+B7)
A9: Terminal Value — EV/EBITDA Multiple [(EBIT+D&A)×13x] | B9: =(Forecast!$K$6+Forecast!$K$8)*Inputs!$B$41
A10: PV of TV (EV/EBITDA) [B9÷(1+WACC)^10] | B10: =B9/(1+'WACC Build'!$B$17)^10
A11: Terminal Value — Blended 50/50 [(B6+B9)×50%] | B11: =(B6+B9)*0.5
A12: PV of TV (Blended) [(B7+B10)×50%] | B12: =(B7+B10)*0.5
A14: Enterprise Value — Gordon [B4+B7] | B14: =B4+B7
A15: Enterprise Value — Blended [B4+B12] | B15: =B4+B12
A16: (Less) Total Debt | B16: =-Inputs!$B$8
A17: (Less) Lease Liabilities | B17: =-Inputs!$B$10
A18: (Plus) Cash | B18: =Inputs!$B$9
A19: Equity Value — Gordon [B14+B16+B17+B18] | B19: =B14+B16+B17+B18
A20: Equity Value — Blended [B15+B16+B17+B18] | B20: =B15+B16+B17+B18
A21: Diluted Shares | B21: =Inputs!$B$12
A22: Implied Share Price — Gordon Growth [B19÷B21] | B22: =B19/B21
A23: Implied Share Price — EV/EBITDA Multiple [(B4+B10+B16+B17+B18)÷B21] | B23: =(B4+B10+B16+B17+B18)/B21
A24: Implied Share Price — Blended 50/50 [B20÷B21] ★ | B24: =B20/B21
A25: Current Share Price | B25: =Inputs!$B$6

Sheet Scenarios
A1: Scenario Analysis — Bear / Base / Bull
A2: (Values in USD, except per share data)
A3: Assumption / Output | B3: Bear | C3: Base | D3: Bull
A4: SCENARIO PARAMETERS
A5: WACC (all scenarios) | B5: 0.087398008 | C5: 0.087398008 | D5: 0.087398008
A6: Terminal Growth | B6: 0.02 | C6: 0.025 | D6: 0.03
A8: Bear: revenue growth −5pp each year, terminal_g −0.5pp [WACC unchanged at 8.7%]
A9: Base: no adjustment — main model output [WACC = 8.7%, g = 2.5%]
A10: Bull: revenue growth +5pp each year, terminal_g +0.5pp [WACC unchanged at 8.7%]
A12: SCENARIO OUTPUTS
A13: Metric | B13: Bear | C13: Base | D13: Bull
A14: Enterprise Value | B14: 1.0260182e+10 | C14: 1.51893e+10 | D14: 2.2434304e+10
A15: Implied Share Price (Blended TV) | B15: 39.650077 | C15: 58.986703 | D15: 87.408402
A16: Upside / Downside vs. Current | B16: 0.39025516 | C16: 1.0682575 | D16: 2.0648107

Sheet Football Field
A1: Implied Per Share Value Range | June 25, 2026
A2: (Values in USD, except per share data)
A3: Current Price: $28.52 (reference)
A4: Method | B4: Implied Price | C4: vs. Current ($) | D4: vs. Current (%) | E4: EV ($B)
A5: Bear Scenario | B5: 39.650077 | C5: 11.130077 | D5: 0.39025516 | E5: 10.260182
A6: Base Scenario | B6: 58.986703 | C6: 30.466703 | D6: 1.0682575 | E6: 15.1893
A7: Bull Scenario | B7: 87.408402 | C7: 58.888402 | D7: 2.0648107 | E7: 22.434304
A8: Gordon Growth (Base) | B8: 55.564752 | C8: 27.044752 | D8: 0.9482732 | E8: 14.317007
A9: EV/EBITDA Multiple (Base) | B9: 62.408655 | C9: 33.888655 | D9: 1.1882418 | E9: 16.061594
A10: Blended 50/50 (Base) ★ | B10: 58.986703 | C10: 30.466703 | D10: 1.0682575 | E10: 15.1893
A11: Current Price (Reference) | B11: 28.52

Sheet Sensitivity
A1: Sensitivity Analysis — Implied Share Price
A2: (Values in USD, except per share data)
A3: Grid 1: WACC × Terminal Growth Rate → Implied Price
B4: 1.0% | C4: 1.5% | D4: 2.0% | E4: 2.5% | F4: 3.0% | G4: 3.5% | H4: 4.0%
A5: 7.2% | B5: 62.59 | C5: 67.06 | D5: 72.39 | E5: 78.84 | F5: 86.82 | G5: 96.92 | H5: 110.14
A6: 7.7% | B6: 56.49 | C6: 60.14 | D6: 64.43 | E6: 69.54 | F6: 75.73 | G6: 83.37 | H6: 93.06
A7: 8.2% | B7: 51.28 | C7: 54.3 | D7: 57.8 | E7: 61.92 | F7: 66.82 | G7: 72.75 | H7: 80.09
A8: 8.7% | B8: 46.78 | C8: 49.3 | D8: 52.2 | E8: 55.56 | F8: 59.51 | G8: 64.21 | H8: 69.91
A9: 9.2% | B9: 42.87 | C9: 45 | D9: 47.42 | E9: 50.2 | F9: 53.42 | G9: 57.21 | H9: 61.72
A10: 9.7% | B10: 39.44 | C10: 41.25 | D10: 43.29 | E10: 45.61 | F10: 48.28 | G10: 51.38 | H10: 55.01
A11: 10.2% | B11: 36.41 | C11: 37.96 | D11: 39.69 | E11: 41.65 | F11: 43.88 | G11: 46.45 | H11: 49.42
A14: Grid 2: WACC × Revenue CAGR → Implied Price
B15: 29.5% | C15: 31.5% | D15: 33.5% | E15: 35.5% | F15: 37.5% | G15: 39.5% | H15: 41.5%
A16: 7.2% | B16: 69.43 | C16: 74.9 | D16: 80.76 | E16: 87.02 | F16: 93.71 | G16: 100.85 | H16: 108.47
A17: 7.7% | B17: 62.01 | C17: 66.85 | D17: 72.04 | E17: 77.58 | F17: 83.49 | G17: 89.81 | H17: 96.55
A18: 8.2% | B18: 55.9 | C18: 60.24 | D18: 64.87 | E18: 69.81 | F18: 75.1 | G18: 80.73 | H18: 86.75
A19: 8.7% | B19: 50.8 | C19: 54.7 | D19: 58.87 | E19: 63.33 | F19: 68.08 | G19: 73.15 | H19: 78.56
A20: 9.2% | B20: 46.48 | C20: 50.01 | D20: 53.79 | E20: 57.83 | F20: 62.14 | G20: 66.73 | H20: 71.63
A21: 9.7% | B21: 42.76 | C21: 45.99 | D21: 49.44 | E21: 53.12 | F21: 57.04 | G21: 61.23 | H21: 65.69
A22: 10.2% | B22: 39.55 | C22: 42.51 | D22: 45.67 | E22: 49.04 | F22: 52.63 | G22: 56.46 | H22: 60.55
A25: Grid 3: EBIT Margin Target × Revenue CAGR → Implied Price
B26: 29.5% | C26: 31.5% | D26: 33.5% | E26: 35.5% | F26: 37.5% | G26: 39.5% | H26: 41.5%
A27: 6.0% | B27: 21.63 | C27: 23.12 | D27: 24.71 | E27: 26.39 | F27: 28.19 | G27: 30.1 | H27: 32.13
A28: 9.0% | B28: 31.35 | C28: 33.65 | D28: 36.1 | E28: 38.71 | F28: 41.49 | G28: 44.45 | H28: 47.61
A29: 12.0% | B29: 41.08 | C29: 44.18 | D29: 47.48 | E29: 51.02 | F29: 54.79 | G29: 58.8 | H29: 63.08
A30: 15.0% | B30: 50.8 | C30: 54.7 | D30: 58.87 | E30: 63.33 | F30: 68.08 | G30: 73.15 | H30: 78.56
A31: 18.0% | B31: 60.53 | C31: 65.23 | D31: 70.26 | E31: 75.64 | F31: 81.38 | G31: 87.51 | H31: 94.04
A32: 21.0% | B32: 70.25 | C32: 75.76 | D32: 81.65 | E32: 87.95 | F32: 94.68 | G32: 101.86 | H32: 109.52
A33: 24.0% | B33: 79.98 | C33: 86.29 | D33: 93.04 | E33: 100.26 | F33: 107.97 | G33: 116.21 | H33: 124.99
