Workbook

Sheet Cover
B2: Alphabet Inc. (GOOGL) - Discounted Cash Flow Model
B3: ($ in millions, except per-share data, unless noted)
B4: Subject: Alphabet Inc. - Class A (GOOGL), Class B (GOOGL.B/unlisted), Class C (GOOG) common stock
B5: Prepared by: Akul Veauli
B6: Date: August 23, 2026
B8: Model description: Five-year (FY2026E-FY2030E) unlevered discounted cash flow valuation of Alphabet Inc., built on FY2023A-FY2025A historicals. Reflects the AI infrastructure capex supercycle: capex/revenue starts sharply elevated on the back of the FY2026 $180-190B capex guidance and fades as the buildout matures; D&A/revenue rises with a lag behind capex per standard PP&E depreciation timing. Terminal value is cross-checked via both the Gordon Growth and Exit Multiple methods. Combined Class A+B+C diluted share count is used throughout; GOOGL (Class A) is the quoted share price basis. Two live sensitivity grids (WACC x terminal growth; WACC x exit multiple) rebuild the valuation algebraically from the UFCF row for every cell - no Excel Data Tables, no circularity, no iterative calc.
B12: Color-code legend
B13: 123.4 (hardcoded input) | C13: Blue font / yellow fill = hardcoded assumption
B14: B13*2 (same-sheet formula) | C14: Black font = formula referencing same tab
B15: 'Assumptions'!D9 (cross-tab link) | C15: Green font = formula linking from another tab
B16: 59,000 (estimated/derived input) | C16: Orange font/fill = data-pack gap; value annualized, derived, or judgment-based (see adjacent note)
B19: Table of contents
B20: Cover
B21: Assumptions
B22: DCF
B23: WACC
B24: Sensitivity
B26: Key outputs
B27: Implied share price - Gordon Growth method | D27: =DCF!D53
B28: Implied share price - Exit Multiple method | D28: =DCF!F53
B29: Implied enterprise value - Gordon Growth ($mm) | D29: =DCF!D48
B30: Implied enterprise value - Exit Multiple ($mm) | D30: =DCF!F48
B31: Actual share price (GOOGL, as of Aug 21, 2026) | D31: =DCF!D54
B32: Implied upside/(downside) - Gordon Growth | D32: =DCF!D55
B33: Implied upside/(downside) - Exit Multiple | D33: =DCF!F55
B34: WACC | D34: =WACC!D28
B36: Sources: Alphabet FY2025 10-K (filed ~Feb 2026); FY2023 10-K; Q1 2026 and Q2 2026 earnings releases and 10-Q (period ended 6/30/2026); Damodaran equity risk premium data update (July 2026); U.S. Treasury 10Y yield (Advisor Perspectives, as of 8/21/2026); CNBC quotes for GOOGL share price (8/21/2026). See Assumptions and WACC tab notes for line-by-line citations and flagged estimates/gaps.

Sheet Assumptions
B2: Alphabet Inc. (GOOGL) - DCF Assumptions
B3: ($ in millions, except per-share and % data)
B5: 1. Valuation Setup
B6: Valuation date | D6: Aug 23, 2026
B7: Actual share price - GOOGL (Class A) | D7: 344.82 | F7: Source: CNBC quote, close 8/21/2026 (most recent available; Aug 23 close not yet captured)
B8: Diluted shares outstanding - combined Class A+B+C (mm) | D8: 12230 | F8: FY2025 10-K combined diluted weighted-average share count (Class A + B + C). Basic shares outstanding by class were A 6,671mm / B 849mm / C 5,559mm = 13,079mm; the diluted weighted-average figure of 12,230mm used here is lower, reflecting the weighted-average convention and buyback timing during the year.
B9: Fiscal year end | D9: December 31 (calendar year)
B10: Share class basis note | D10: Combined A+B+C diluted count drives per-share value; GOOGL (Class A) is the quoted price basis used for upside/(downside).
B12: 2. Balance Sheet Items (as of 12/31/2025 10-K, latest available)
B13: Cash & cash equivalents | D13: 30700
B14: Marketable securities | D14: 96100
B15: Total cash & investments | D15: =SUM(D13:D14)
B16: Total debt (long-term debt) | D16: 46500 | F16: FY2025 10-K; LT debt rose from $10.9B (FY24) to $46.5B (FY25) on 2025-26 bond issuance
B17: Non-marketable equity securities (Other Bets investments) | D17: 68687 | F17: FY2025 10-K; includes marks on Waymo, Anthropic and other Other Bets stakes
B18: % of non-marketable securities included in equity bridge (haircut toggle) | D18: 1 | F18: Default 100% (no haircut) - securities carried at fair value under ASU 2016-01 mark-to-market
B19: Minority interest | D19: 0
B20: Net debt | D20: =D16-D15+D19 | F20: Negative = net cash position
B22: 3. Operating Drivers - FY2026E-FY2030E
D23: FY2026E | E23: FY2027E | F23: FY2028E | G23: FY2029E | H23: FY2030E
B24: Revenue growth % | D24: 0.16 | E24: 0.14 | F24: 0.12 | G24: 0.11 | H24: 0.1 | I24: AI/Cloud-led growth fading toward mid-teens then low-double-digits as base scales
B25: EBIT margin % | D25: 0.29 | E25: 0.28 | F25: 0.285 | G25: 0.295 | H25: 0.305 | I25: Near-term dip on opex/D&A step-up from capex ramp, recovering as AI infra monetizes
B26: D&A % of revenue | D26: 0.155 | E26: 0.165 | F26: 0.17 | G26: 0.17 | H26: 0.165 | I26: D&A lags capex ramp (2-4Q typical depreciation-start lag); rises off FY25E ~14.6% then plateaus/fades as capex growth decelerates
B27: Capex % of revenue | D27: 0.395 | E27: 0.34 | F27: 0.26 | G27: 0.2 | H27: 0.17 | I27: FY26E calibrated to FY2026 guidance of $180-190B (~39-41% of FY26E revenue); fades toward a steady-state level approaching D&A% by FY2030E as the buildout matures. Faster fade vs. raw guidance run-rate is a judgment call to keep the terminal-year FCF/EBITDA cross-check from diverging further (see TV cross-check notes below).
B28: Net working capital % of revenue | D28: -0.03 | E28: -0.03 | F28: -0.03 | G28: -0.03 | H28: -0.03 | I28: NWC component detail (AR/AP/accrued comp) not available in data pack; held flat at historical-estimate -3.0% of revenue (net current liability position typical of Alphabet's deferred-revenue/payables profile)
B29: Effective tax rate (applied flat across projection) | D29: 0.168 | F29: FY2025 effective tax rate per 10-K/earnings release
B31: 4. Terminal Assumptions
B32: Terminal growth rate (g) | D32: 0.03 | F32: Long-run nominal GDP+ growth judgment for a scaled AI/cloud/advertising franchise
B33: Exit EV/EBITDA multiple | D33: 14 | F33: Approximate current large-cap tech trading multiple; judgment-based, no deal comp in data pack
B34: Discounting convention | D34: End-of-period discounting throughout (no mid-year convention) - required for sensitivity grid algebra to tie to base case.

Sheet DCF
B2: Alphabet Inc. (GOOGL) - DCF Build
B3: ($ in millions unless noted; historicals blue, projections/links formula-driven)
C5: FY2023A | D5: FY2024A | E5: FY2025A | F5: FY2026E | G5: FY2027E | H5: FY2028E | I5: FY2029E | J5: FY2030E
B6: Discount period (n) | F6: =1 | G6: =F6+1 | H6: =G6+1 | I6: =H6+1 | J6: =I6+1
B8: Historical & Projected Operating Build
B9: Revenue | C9: 307394 | D9: 350018 | E9: 402800 | F9: =E9*(1+Assumptions!D24) | G9: =F9*(1+Assumptions!E24) | H9: =G9*(1+Assumptions!F24) | I9: =H9*(1+Assumptions!G24) | J9: =I9*(1+Assumptions!H24)
B10: % growth YoY | D10: =IFERROR(D9/C9-1,"n.m.") | E10: =IFERROR(E9/D9-1,"n.m.") | F10: =IFERROR(F9/E9-1,"n.m.") | G10: =IFERROR(G9/F9-1,"n.m.") | H10: =IFERROR(H9/G9-1,"n.m.") | I10: =IFERROR(I9/H9-1,"n.m.") | J10: =IFERROR(J9/I9-1,"n.m.")
B11: EBIT | C11: 84293 | D11: 112390 | E11: 114000 | F11: =F9*Assumptions!D25 | G11: =G9*Assumptions!E25 | H11: =H9*Assumptions!F25 | I11: =I9*Assumptions!G25 | J11: =J9*Assumptions!H25 | K11: FY2025E: annualized full-year op. income; 9M actual $93.1B + Q4E per data-pack guidance (midpoint of $113-115B range) - flagged estimate pending final 10-K line
B12: EBIT margin % | C12: =C11/C9 | D12: =D11/D9 | E12: =E11/E9 | F12: =Assumptions!D25 | G12: =Assumptions!E25 | H12: =Assumptions!F25 | I12: =Assumptions!G25 | J12: =Assumptions!H25
B13: D&A | C13: 11946 | D13: 15287 | E13: 59000 | F13: =F9*Assumptions!D26 | G13: =G9*Assumptions!E26 | H13: =H9*Assumptions!F26 | I13: =I9*Assumptions!G26 | J13: =J9*Assumptions!H26 | K13: FY2025E: annualized from 9-month actual $44.4B (data pack); reflects post-capex-ramp D&A step-up ('D&A lags capex ramp')
B14: EBITDA | C14: =C11+C13 | D14: =D11+D13 | E14: =E11+E13 | F14: =F11+F13 | G14: =G11+G13 | H14: =H11+H13 | I14: =I11+I13 | J14: =J11+J13
B15: Less: Capex | C15: 32251 | D15: 52535 | E15: 75000 | F15: =F9*Assumptions!D27 | G15: =G9*Assumptions!E27 | H15: =H9*Assumptions!F27 | I15: =I9*Assumptions!G27 | J15: =J9*Assumptions!H27 | K15: FY2025 marked as estimate in data pack pending final 10-K CF statement line
B16: Net working capital balance | C16: -9221.8 | D16: -10500.5 | E16: -12084 | F16: =F9*Assumptions!D28 | G16: =G9*Assumptions!E28 | H16: =H9*Assumptions!F28 | I16: =I9*Assumptions!G28 | J16: =J9*Assumptions!H28 | K16: NWC component detail (AR/AP/accrued comp) unavailable in data pack; estimated at -3.0% of revenue (Alphabet's typically net-current-liability profile from deferred revenue & payables)
B17: Change in NWC (increase)/decrease | D17: =D16-C16 | E17: =E16-D16 | F17: =F16-E16 | G17: =G16-F16 | H17: =H16-G16 | I17: =I16-H16 | J17: =J16-I16
B19: Unlevered Free Cash Flow Build (FY2026E-FY2030E)
B20: EBIT | F20: =F11 | G20: =G11 | H20: =H11 | I20: =I11 | J20: =J11
B21: Less: Cash taxes @ effective rate | F21: =F20*Assumptions!$D$29 | G21: =G20*Assumptions!$D$29 | H21: =H20*Assumptions!$D$29 | I21: =I20*Assumptions!$D$29 | J21: =J20*Assumptions!$D$29
B22: NOPAT | F22: =F20-F21 | G22: =G20-G21 | H22: =H20-H21 | I22: =I20-I21 | J22: =J20-J21
B23: Plus: D&A | F23: =F13 | G23: =G13 | H23: =H13 | I23: =I13 | J23: =J13
B24: Less: Capex | F24: =F15 | G24: =G15 | H24: =H15 | I24: =I15 | J24: =J15
B25: Less: Change in NWC | F25: =F17 | G25: =G17 | H25: =H17 | I25: =I17 | J25: =J17
B26: Unlevered Free Cash Flow | F26: =F22+F23-F24-F25 | G26: =G22+G23-G24-G25 | H26: =H22+H23-H24-H25 | I26: =I22+I23-I24-I25 | J26: =J22+J23-J24-J25
B27: PV factor @ WACC | F27: =1/(1+WACC!$D$28)^F6 | G27: =1/(1+WACC!$D$28)^G6 | H27: =1/(1+WACC!$D$28)^H6 | I27: =1/(1+WACC!$D$28)^I6 | J27: =1/(1+WACC!$D$28)^J6
B28: PV of Unlevered FCF | F28: =F26*F27 | G28: =G26*G27 | H28: =H26*H27 | I28: =I26*I27 | J28: =J26*J27
B30: Sum of PV of explicit UFCF (FY2026E-FY2030E) | D30: =SUM(F28:J28)
B32: Terminal Value - Gordon Growth Method
B33: Terminal growth rate (g) | D33: =Assumptions!$D$32
B34: Terminal-year (FY2030E) Unlevered FCF | D34: =J26
B35: Terminal value (Gordon) | D35: =D34*(1+D33)/(WACC!$D$28-D33)
B36: PV of terminal value (Gordon) | D36: =D35*J27
B37: Cross-check: implied exit EV/EBITDA (Gordon) | D37: =D35/D41 | F37: Directionally cross-checks the input exit multiple; note the AI-capex supercycle depresses terminal FCF/EBITDA conversion vs. a normalized mature company, so this implied multiple runs meaningfully below the 14.0x market-multiple input by construction - a known limitation of a 5yr-explicit Gordon TV during a capex supercycle, not a modeling error.
B39: Terminal Value - Exit Multiple Method
B40: Exit EV/EBITDA multiple | D40: =Assumptions!$D$33
B41: Terminal-year (FY2030E) EBITDA | D41: =J14
B42: Terminal value (Exit Multiple) | D42: =D41*D40
B43: PV of terminal value (Exit Multiple) | D43: =D42*J27
B44: Cross-check: implied terminal growth (Exit Multiple) | D44: =(WACC!$D$28*D42-D34)/(D42+D34) | F44: Directionally cross-checks the terminal growth input; runs above it for the same FCF-conversion reason noted at the Gordon cross-check above.
B46: Enterprise Value to Equity Value Bridge & Implied Share Price
D47: Gordon Growth | F47: Exit Multiple
B48: Enterprise value | D48: =D30+D36 | F48: =D30+D43
...

Sheet WACC
B2: Alphabet Inc. (GOOGL) - WACC Build
B3: (CAPM cost of equity; market-value capital structure weights)
B5: Cost of Equity (CAPM)
B6: Risk-free rate (10Y U.S. Treasury) | D6: 0.0474 | F6: 10Y UST yield, as of 8/21/2026 (Advisor Perspectives)
B7: Levered beta | D7: 1.05 | F7: Fallback per spec/data pack - live 5yr monthly beta not accessible in source search; widely-cited Damodaran-consistent estimate
B8: Equity risk premium (ERP) | D8: 0.05 | F8: 5.00% per master spec (Damodaran / Duff & Phelps convention, spec-permitted range 4.5%-5.5%); harmonized across all four DCF workbooks in this suite, which share the same Aug-2026 valuation date. Damodaran's July-2026 implied ERP of 4.45% is an alternative read but sits below the spec range; at 4.45% Ke falls ~6bp x beta and the implied Gordon price rises modestly.
B9: Cost of equity (Ke) = Rf + Beta x ERP | D9: =D6+D7*D8
B11: Cost of Debt
B12: Risk-free rate (link) | D12: =D6
B13: Credit spread assumption (AA+ rated) | D13: 0.006 | F13: No live Alphabet bond yield or interest-expense/avg-debt figure in data pack; spread judgment for a high-grade (AA+) mega-cap issuer
B14: Pre-tax cost of debt (Kd) | D14: =D12+D13
B15: Effective tax rate | D15: =Assumptions!$D$29
B16: After-tax cost of debt | D16: =D14*(1-D15)
B18: Capital Structure Weights (Market Value)
B19: Share price | D19: =Assumptions!$D$7
B20: Diluted shares outstanding (mm) | D20: =Assumptions!$D$8
B21: Market capitalization | D21: =D19*D20
B22: Total debt | D22: =Assumptions!$D$16
B23: Total capitalization (D+E) | D23: =D21+D22
B24: E / (D+E) | D24: =D21/D23
B25: D / (D+E) | D25: =D22/D23
B27: WACC
B28: WACC = Ke x E/(D+E) + Kd(at) x D/(D+E) | D28: =D9*D24+D16*D25
B29: WACC sanity: Alphabet's minimal leverage (D/(D+E) < 2%) means WACC sits close to the CAPM cost of equity - expected for a net-cash mega-cap.

Sheet Sensitivity
B2: Alphabet Inc. (GOOGL) - Sensitivity Grids
B3: (implied share price; live algebraic re-derivation, no Data Tables)
B5: Grid A: WACC (rows) x Terminal Growth g (cols) -> Implied Share Price (Gordon Growth)
B6: =DCF!D53 | C6: <- base case (Gordon) | D6: =Assumptions!$D$32+(-0.01) | E6: =Assumptions!$D$32+(-0.005) | F6: =Assumptions!$D$32+(0.0) | G6: =Assumptions!$D$32+(0.005) | H6: =Assumptions!$D$32+(0.01)
B7: =WACC!$D$28+(-0.015) | D7: =(SUMPRODUCT(DCF!$F$26:$J$26,1/(1+$B7)^DCF!$F$6:$J$6)+(DCF!$D$34*(1+D$6))/($B7-D$6)/(1+$B7)^DCF!$J$6-DCF!$D$49+DCF!$D$50)/DCF!$D$52 | E7: =(SUMPRODUCT(DCF!$F$26:$J$26,1/(1+$B7)^DCF!$F$6:$J$6)+(DCF!$D$34*(1+E$6))/($B7-E$6)/(1+$B7)^DCF!$J$6-DCF!$D$49+DCF!$D$50)/DCF!$D$52 | F7: =(SUMPRODUCT(DCF!$F$26:$J$26,1/(1+$B7)^DCF!$F$6:$J$6)+(DCF!$D$34*(1+F$6))/($B7-F$6)/(1+$B7)^DCF!$J$6-DCF!$D$49+DCF!$D$50)/DCF!$D$52 | G7: =(SUMPRODUCT(DCF!$F$26:$J$26,1/(1+$B7)^DCF!$F$6:$J$6)+(DCF!$D$34*(1+G$6))/($B7-G$6)/(1+$B7)^DCF!$J$6-DCF!$D$49+DCF!$D$50)/DCF!$D$52 | H7: =(SUMPRODUCT(DCF!$F$26:$J$26,1/(1+$B7)^DCF!$F$6:$J$6)+(DCF!$D$34*(1+H$6))/($B7-H$6)/(1+$B7)^DCF!$J$6-DCF!$D$49+DCF!$D$50)/DCF!$D$52
B8: =WACC!$D$28+(-0.01) | D8: =(SUMPRODUCT(DCF!$F$26:$J$26,1/(1+$B8)^DCF!$F$6:$J$6)+(DCF!$D$34*(1+D$6))/($B8-D$6)/(1+$B8)^DCF!$J$6-DCF!$D$49+DCF!$D$50)/DCF!$D$52 | E8: =(SUMPRODUCT(DCF!$F$26:$J$26,1/(1+$B8)^DCF!$F$6:$J$6)+(DCF!$D$34*(1+E$6))/($B8-E$6)/(1+$B8)^DCF!$J$6-DCF!$D$49+DCF!$D$50)/DCF!$D$52 | F8: =(SUMPRODUCT(DCF!$F$26:$J$26,1/(1+$B8)^DCF!$F$6:$J$6)+(DCF!$D$34*(1+F$6))/($B8-F$6)/(1+$B8)^DCF!$J$6-DCF!$D$49+DCF!$D$50)/DCF!$D$52 | G8: =(SUMPRODUCT(DCF!$F$26:$J$26,1/(1+$B8)^DCF!$F$6:$J$6)+(DCF!$D$34*(1+G$6))/($B8-G$6)/(1+$B8)^DCF!$J$6-DCF!$D$49+DCF!$D$50)/DCF!$D$52 | H8: =(SUMPRODUCT(DCF!$F$26:$J$26,1/(1+$B8)^DCF!$F$6:$J$6)+(DCF!$D$34*(1+H$6))/($B8-H$6)/(1+$B8)^DCF!$J$6-DCF!$D$49+DCF!$D$50)/DCF!$D$52
B9: =WACC!$D$28+(-0.005) | D9: =(SUMPRODUCT(DCF!$F$26:$J$26,1/(1+$B9)^DCF!$F$6:$J$6)+(DCF!$D$34*(1+D$6))/($B9-D$6)/(1+$B9)^DCF!$J$6-DCF!$D$49+DCF!$D$50)/DCF!$D$52 | E9: =(SUMPRODUCT(DCF!$F$26:$J$26,1/(1+$B9)^DCF!$F$6:$J$6)+(DCF!$D$34*(1+E$6))/($B9-E$6)/(1+$B9)^DCF!$J$6-DCF!$D$49+DCF!$D$50)/DCF!$D$52 | F9: =(SUMPRODUCT(DCF!$F$26:$J$26,1/(1+$B9)^DCF!$F$6:$J$6)+(DCF!$D$34*(1+F$6))/($B9-F$6)/(1+$B9)^DCF!$J$6-DCF!$D$49+DCF!$D$50)/DCF!$D$52 | G9: =(SUMPRODUCT(DCF!$F$26:$J$26,1/(1+$B9)^DCF!$F$6:$J$6)+(DCF!$D$34*(1+G$6))/($B9-G$6)/(1+$B9)^DCF!$J$6-DCF!$D$49+DCF!$D$50)/DCF!$D$52 | H9: =(SUMPRODUCT(DCF!$F$26:$J$26,1/(1+$B9)^DCF!$F$6:$J$6)+(DCF!$D$34*(1+H$6))/($B9-H$6)/(1+$B9)^DCF!$J$6-DCF!$D$49+DCF!$D$50)/DCF!$D$52
B10: =WACC!$D$28+(0.0) | D10: =(SUMPRODUCT(DCF!$F$26:$J$26,1/(1+$B10)^DCF!$F$6:$J$6)+(DCF!$D$34*(1+D$6))/($B10-D$6)/(1+$B10)^DCF!$J$6-DCF!$D$49+DCF!$D$50)/DCF!$D$52 | E10: =(SUMPRODUCT(DCF!$F$26:$J$26,1/(1+$B10)^DCF!$F$6:$J$6)+(DCF!$D$34*(1+E$6))/($B10-E$6)/(1+$B10)^DCF!$J$6-DCF!$D$49+DCF!$D$50)/DCF!$D$52 | F10: =(SUMPRODUCT(DCF!$F$26:$J$26,1/(1+$B10)^DCF!$F$6:$J$6)+(DCF!$D$34*(1+F$6))/($B10-F$6)/(1+$B10)^DCF!$J$6-DCF!$D$49+DCF!$D$50)/DCF!$D$52 | G10: =(SUMPRODUCT(DCF!$F$26:$J$26,1/(1+$B10)^DCF!$F$6:$J$6)+(DCF!$D$34*(1+G$6))/($B10-G$6)/(1+$B10)^DCF!$J$6-DCF!$D$49+DCF!$D$50)/DCF!$D$52 | H10: =(SUMPRODUCT(DCF!$F$26:$J$26,1/(1+$B10)^DCF!$F$6:$J$6)+(DCF!$D$34*(1+H$6))/($B10-H$6)/(1+$B10)^DCF!$J$6-DCF!$D$49+DCF!$D$50)/DCF!$D$52
B11: =WACC!$D$28+(0.005) | D11: =(SUMPRODUCT(DCF!$F$26:$J$26,1/(1+$B11)^DCF!$F$6:$J$6)+(DCF!$D$34*(1+D$6))/($B11-D$6)/(1+$B11)^DCF!$J$6-DCF!$D$49+DCF!$D$50)/DCF!$D$52 | E11: =(SUMPRODUCT(DCF!$F$26:$J$26,1/(1+$B11)^DCF!$F$6:$J$6)+(DCF!$D$34*(1+E$6))/($B11-E$6)/(1+$B11)^DCF!$J$6-DCF!$D$49+DCF!$D$50)/DCF!$D$52 | F11: =(SUMPRODUCT(DCF!$F$26:$J$26,1/(1+$B11)^DCF!$F$6:$J$6)+(DCF!$D$34*(1+F$6))/($B11-F$6)/(1+$B11)^DCF!$J$6-DCF!$D$49+DCF!$D$50)/DCF!$D$52 | G11: =(SUMPRODUCT(DCF!$F$26:$J$26,1/(1+$B11)^DCF!$F$6:$J$6)+(DCF!$D$34*(1+G$6))/($B11-G$6)/(1+$B11)^DCF!$J$6-DCF!$D$49+DCF!$D$50)/DCF!$D$52 | H11: =(SUMPRODUCT(DCF!$F$26:$J$26,1/(1+$B11)^DCF!$F$6:$J$6)+(DCF!$D$34*(1+H$6))/($B11-H$6)/(1+$B11)^DCF!$J$6-DCF!$D$49+DCF!$D$50)/DCF!$D$52
B12: =WACC!$D$28+(0.01) | D12: =(SUMPRODUCT(DCF!$F$26:$J$26,1/(1+$B12)^DCF!$F$6:$J$6)+(DCF!$D$34*(1+D$6))/($B12-D$6)/(1+$B12)^DCF!$J$6-DCF!$D$49+DCF!$D$50)/DCF!$D$52 | E12: =(SUMPRODUCT(DCF!$F$26:$J$26,1/(1+$B12)^DCF!$F$6:$J$6)+(DCF!$D$34*(1+E$6))/($B12-E$6)/(1+$B12)^DCF!$J$6-DCF!$D$49+DCF!$D$50)/DCF!$D$52 | F12: =(SUMPRODUCT(DCF!$F$26:$J$26,1/(1+$B12)^DCF!$F$6:$J$6)+(DCF!$D$34*(1+F$6))/($B12-F$6)/(1+$B12)^DCF!$J$6-DCF!$D$49+DCF!$D$50)/DCF!$D$52 | G12: =(SUMPRODUCT(DCF!$F$26:$J$26,1/(1+$B12)^DCF!$F$6:$J$6)+(DCF!$D$34*(1+G$6))/($B12-G$6)/(1+$B12)^DCF!$J$6-DCF!$D$49+DCF!$D$50)/DCF!$D$52 | H12: =(SUMPRODUCT(DCF!$F$26:$J$26,1/(1+$B12)^DCF!$F$6:$J$6)+(DCF!$D$34*(1+H$6))/($B12-H$6)/(1+$B12)^DCF!$J$6-DCF!$D$49+DCF!$D$50)/DCF!$D$52
B13: =WACC!$D$28+(0.015) | D13: =(SUMPRODUCT(DCF!$F$26:$J$26,1/(1+$B13)^DCF!$F$6:$J$6)+(DCF!$D$34*(1+D$6))/($B13-D$6)/(1+$B13)^DCF!$J$6-DCF!$D$49+DCF!$D$50)/DCF!$D$52 | E13: =(SUMPRODUCT(DCF!$F$26:$J$26,1/(1+$B13)^DCF!$F$6:$J$6)+(DCF!$D$34*(1+E$6))/($B13-E$6)/(1+$B13)^DCF!$J$6-DCF!$D$49+DCF!$D$50)/DCF!$D$52 | F13: =(SUMPRODUCT(DCF!$F$26:$J$26,1/(1+$B13)^DCF!$F$6:$J$6)+(DCF!$D$34*(1+F$6))/($B13-F$6)/(1+$B13)^DCF!$J$6-DCF!$D$49+DCF!$D$50)/DCF!$D$52 | G13: =(SUMPRODUCT(DCF!$F$26:$J$26,1/(1+$B13)^DCF!$F$6:$J$6)+(DCF!$D$34*(1+G$6))/($B13-G$6)/(1+$B13)^DCF!$J$6-DCF!$D$49+DCF!$D$50)/DCF!$D$52 | H13: =(SUMPRODUCT(DCF!$F$26:$J$26,1/(1+$B13)^DCF!$F$6:$J$6)+(DCF!$D$34*(1+H$6))/($B13-H$6)/(1+$B13)^DCF!$J$6-DCF!$D$49+DCF!$D$50)/DCF!$D$52
B15: Check: center cell - base case implied price (Gordon) (must = 0.00) | D15: =ROUND(F10-DCF!D53,2)
B18: Grid B: WACC (rows) x Exit EV/EBITDA Multiple (cols) -> Implied Share Price (Exit Multiple)
B19: =DCF!F53 | C19: <- base case (Exit Multiple) | D19: =Assumptions!$D$33+(-2.0) | E19: =Assumptions!$D$33+(-1.0) | F19: =Assumptions!$D$33+(0.0) | G19: =Assumptions!$D$33+(1.0) | H19: =Assumptions!$D$33+(2.0)
B20: =WACC!$D$28+(-0.015) | D20: =(SUMPRODUCT(DCF!$F$26:$J$26,1/(1+$B20)^DCF!$F$6:$J$6)+DCF!$D$41*D$19/(1+$B20)^DCF!$J$6-DCF!$D$49+DCF!$D$50)/DCF!$D$52 | E20: =(SUMPRODUCT(DCF!$F$26:$J$26,1/(1+$B20)^DCF!$F$6:$J$6)+DCF!$D$41*E$19/(1+$B20)^DCF!$J$6-DCF!$D$49+DCF!$D$50)/DCF!$D$52 | F20: =(SUMPRODUCT(DCF!$F$26:$J$26,1/(1+$B20)^DCF!$F$6:$J$6)+DCF!$D$41*F$19/(1+$B20)^DCF!$J$6-DCF!$D$49+DCF!$D$50)/DCF!$D$52 | G20: =(SUMPRODUCT(DCF!$F$26:$J$26,1/(1+$B20)^DCF!$F$6:$J$6)+DCF!$D$41*G$19/(1+$B20)^DCF!$J$6-DCF!$D$49+DCF!$D$50)/DCF!$D$52 | H20: =(SUMPRODUCT(DCF!$F$26:$J$26,1/(1+$B20)^DCF!$F$6:$J$6)+DCF!$D$41*H$19/(1+$B20)^DCF!$J$6-DCF!$D$49+DCF!$D$50)/DCF!$D$52
B21: =WACC!$D$28+(-0.01) | D21: =(SUMPRODUCT(DCF!$F$26:$J$26,1/(1+$B21)^DCF!$F$6:$J$6)+DCF!$D$41*D$19/(1+$B21)^DCF!$J$6-DCF!$D$49+DCF!$D$50)/DCF!$D$52 | E21: =(SUMPRODUCT(DCF!$F$26:$J$26,1/(1+$B21)^DCF!$F$6:$J$6)+DCF!$D$41*E$19/(1+$B21)^DCF!$J$6-DCF!$D$49+DCF!$D$50)/DCF!$D$52 | F21: =(SUMPRODUCT(DCF!$F$26:$J$26,1/(1+$B21)^DCF!$F$6:$J$6)+DCF!$D$41*F$19/(1+$B21)^DCF!$J$6-DCF!$D$49+DCF!$D$50)/DCF!$D$52 | G21: =(SUMPRODUCT(DCF!$F$26:$J$26,1/(1+$B21)^DCF!$F$6:$J$6)+DCF!$D$41*G$19/(1+$B21)^DCF!$J$6-DCF!$D$49+DCF!$D$50)/DCF!$D$52 | H21: =(SUMPRODUCT(DCF!$F$26:$J$26,1/(1+$B21)^DCF!$F$6:$J$6)+DCF!$D$41*H$19/(1+$B21)^DCF!$J$6-DCF!$D$49+DCF!$D$50)/DCF!$D$52
B22: =WACC!$D$28+(-0.005) | D22: =(SUMPRODUCT(DCF!$F$26:$J$26,1/(1+$B22)^DCF!$F$6:$J$6)+DCF!$D$41*D$19/(1+$B22)^DCF!$J$6-DCF!$D$49+DCF!$D$50)/DCF!$D$52 | E22: =(SUMPRODUCT(DCF!$F$26:$J$26,1/(1+$B22)^DCF!$F$6:$J$6)+DCF!$D$41*E$19/(1+$B22)^DCF!$J$6-DCF!$D$49+DCF!$D$50)/DCF!$D$52 | F22: =(SUMPRODUCT(DCF!$F$26:$J$26,1/(1+$B22)^DCF!$F$6:$J$6)+DCF!$D$41*F$19/(1+$B22)^DCF!$J$6-DCF!$D$49+DCF!$D$50)/DCF!$D$52 | G22: =(SUMPRODUCT(DCF!$F$26:$J$26,1/(1+$B22)^DCF!$F$6:$J$6)+DCF!$D$41*G$19/(1+$B22)^DCF!$J$6-DCF!$D$49+DCF!$D$50)/DCF!$D$52 | H22: =(SUMPRODUCT(DCF!$F$26:$J$26,1/(1+$B22)^DCF!$F$6:$J$6)+DCF!$D$41*H$19/(1+$B22)^DCF!$J$6-DCF!$D$49+DCF!$D$50)/DCF!$D$52
B23: =WACC!$D$28+(0.0) | D23: =(SUMPRODUCT(DCF!$F$26:$J$26,1/(1+$B23)^DCF!$F$6:$J$6)+DCF!$D$41*D$19/(1+$B23)^DCF!$J$6-DCF!$D$49+DCF!$D$50)/DCF!$D$52 | E23: =(SUMPRODUCT(DCF!$F$26:$J$26,1/(1+$B23)^DCF!$F$6:$J$6)+DCF!$D$41*E$19/(1+$B23)^DCF!$J$6-DCF!$D$49+DCF!$D$50)/DCF!$D$52 | F23: =(SUMPRODUCT(DCF!$F$26:$J$26,1/(1+$B23)^DCF!$F$6:$J$6)+DCF!$D$41*F$19/(1+$B23)^DCF!$J$6-DCF!$D$49+DCF!$D$50)/DCF!$D$52 | G23: =(SUMPRODUCT(DCF!$F$26:$J$26,1/(1+$B23)^DCF!$F$6:$J$6)+DCF!$D$41*G$19/(1+$B23)^DCF!$J$6-DCF!$D$49+DCF!$D$50)/DCF!$D$52 | H23: =(SUMPRODUCT(DCF!$F$26:$J$26,1/(1+$B23)^DCF!$F$6:$J$6)+DCF!$D$41*H$19/(1+$B23)^DCF!$J$6-DCF!$D$49+DCF!$D$50)/DCF!$D$52
B24: =WACC!$D$28+(0.005) | D24: =(SUMPRODUCT(DCF!$F$26:$J$26,1/(1+$B24)^DCF!$F$6:$J$6)+DCF!$D$41*D$19/(1+$B24)^DCF!$J$6-DCF!$D$49+DCF!$D$50)/DCF!$D$52 | E24: =(SUMPRODUCT(DCF!$F$26:$J$26,1/(1+$B24)^DCF!$F$6:$J$6)+DCF!$D$41*E$19/(1+$B24)^DCF!$J$6-DCF!$D$49+DCF!$D$50)/DCF!$D$52 | F24: =(SUMPRODUCT(DCF!$F$26:$J$26,1/(1+$B24)^DCF!$F$6:$J$6)+DCF!$D$41*F$19/(1+$B24)^DCF!$J$6-DCF!$D$49+DCF!$D$50)/DCF!$D$52 | G24: =(SUMPRODUCT(DCF!$F$26:$J$26,1/(1+$B24)^DCF!$F$6:$J$6)+DCF!$D$41*G$19/(1+$B24)^DCF!$J$6-DCF!$D$49+DCF!$D$50)/DCF!$D$52 | H24: =(SUMPRODUCT(DCF!$F$26:$J$26,1/(1+$B24)^DCF!$F$6:$J$6)+DCF!$D$41*H$19/(1+$B24)^DCF!$J$6-DCF!$D$49+DCF!$D$50)/DCF!$D$52
B25: =WACC!$D$28+(0.01) | D25: =(SUMPRODUCT(DCF!$F$26:$J$26,1/(1+$B25)^DCF!$F$6:$J$6)+DCF!$D$41*D$19/(1+$B25)^DCF!$J$6-DCF!$D$49+DCF!$D$50)/DCF!$D$52 | E25: =(SUMPRODUCT(DCF!$F$26:$J$26,1/(1+$B25)^DCF!$F$6:$J$6)+DCF!$D$41*E$19/(1+$B25)^DCF!$J$6-DCF!$D$49+DCF!$D$50)/DCF!$D$52 | F25: =(SUMPRODUCT(DCF!$F$26:$J$26,1/(1+$B25)^DCF!$F$6:$J$6)+DCF!$D$41*F$19/(1+$B25)^DCF!$J$6-DCF!$D$49+DCF!$D$50)/DCF!$D$52 | G25: =(SUMPRODUCT(DCF!$F$26:$J$26,1/(1+$B25)^DCF!$F$6:$J$6)+DCF!$D$41*G$19/(1+$B25)^DCF!$J$6-DCF!$D$49+DCF!$D$50)/DCF!$D$52 | H25: =(SUMPRODUCT(DCF!$F$26:$J$26,1/(1+$B25)^DCF!$F$6:$J$6)+DCF!$D$41*H$19/(1+$B25)^DCF!$J$6-DCF!$D$49+DCF!$D$50)/DCF!$D$52
B26: =WACC!$D$28+(0.015) | D26: =(SUMPRODUCT(DCF!$F$26:$J$26,1/(1+$B26)^DCF!$F$6:$J$6)+DCF!$D$41*D$19/(1+$B26)^DCF!$J$6-DCF!$D$49+DCF!$D$50)/DCF!$D$52 | E26: =(SUMPRODUCT(DCF!$F$26:$J$26,1/(1+$B26)^DCF!$F$6:$J$6)+DCF!$D$41*E$19/(1+$B26)^DCF!$J$6-DCF!$D$49+DCF!$D$50)/DCF!$D$52 | F26: =(SUMPRODUCT(DCF!$F$26:$J$26,1/(1+$B26)^DCF!$F$6:$J$6)+DCF!$D$41*F$19/(1+$B26)^DCF!$J$6-DCF!$D$49+DCF!$D$50)/DCF!$D$52 | G26: =(SUMPRODUCT(DCF!$F$26:$J$26,1/(1+$B26)^DCF!$F$6:$J$6)+DCF!$D$41*G$19/(1+$B26)^DCF!$J$6-DCF!$D$49+DCF!$D$50)/DCF!$D$52 | H26: =(SUMPRODUCT(DCF!$F$26:$J$26,1/(1+$B26)^DCF!$F$6:$J$6)+DCF!$D$41*H$19/(1+$B26)^DCF!$J$6-DCF!$D$49+DCF!$D$50)/DCF!$D$52
B28: Check: center cell - base case implied price (Exit Multiple) (must = 0.00) | D28: =ROUND(F23-DCF!F53,2)
B30: WACC steps: +/-150bp in 50bp increments. Terminal growth steps: +/-1.0% in 0.5% increments. Exit multiple steps: +/-2.0x in 1.0x increments. Grids rebuild the valuation algebraically from the DCF UFCF row for every cell (no Excel Data Tables, no circularity).
