Workbook

Sheet Cover
B2: Microsoft Corporation (MSFT)
B3: Discounted Cash Flow Analysis
B4: Prepared by: Akul Veauli
B5: Date: August 23, 2026
B7: Model Description
B8: Five-year discounted cash flow valuation of Microsoft Corporation (NASDAQ: MSFT), FYE June 30. Projects unlevered free cash flow FY2026E-FY2030E off driver-based revenue growth, EBIT margin, D&A, capex, and working-capital assumptions; discounts at a CAPM-derived WACC; and computes terminal value under both a Gordon Growth perpetuity and an exit EV/EBITDA multiple, cross-checked against each other. Implied per-share value is bridged from enterprise value and compared against the actual trading price.
B13: Color-Code Legend
B14: Hardcoded input | C14: 123.4
B15: Formula (same sheet) | C15: =1+1
B16: Link from another tab | C16: =Assumptions!D7
B18: Table of Contents
B19: Cover | C19: This page
B20: Assumptions | C20: All blue-input operating, balance-sheet, and terminal assumptions
B21: DCF | C21: Historicals, projections, UFCF build, terminal value, EV-to-equity bridge
B22: WACC | C22: CAPM cost of equity, cost of debt, capital-structure weights, WACC
B23: Sensitivity | C23: Live two-way sensitivity grids (WACC x g; WACC x exit multiple)
B25: Key Outputs
B26: Metric | C26: Value
B27: Implied share price - Gordon Growth | C27: =DCF!D50
B28: Implied share price - Exit Multiple | C28: =DCF!F50
B29: Implied enterprise value (avg. of methods, $mm) | C29: =AVERAGE(DCF!D45,DCF!F45)
B30: Actual share price (8/23/26) | C30: =DCF!D51
B31: Implied upside / (downside) % (avg. of methods) | C31: =AVERAGE(DCF!D50,DCF!F50)/DCF!D51-1
B32: WACC | C32: =WACC!D25
B34: Sources
B35: [1] MSFT FY2025 10-K (filed 7/30/2025, SEC accession 0000950170-25-100235)
B36: [2] MSFT FY2024 10-K (filed 8/27/2024, SEC accession 0000950170-24-087843)
B37: [3] MSFT FY2023 10-K (filed 7/25/2023, SEC accession 0000950170-23-035122)
B38: [4] MSFT 10-Q as of 9/30/2025 (debt note, SEC accession 0000950170-25-061046)
B39: [5] Market data: Investing.com / Yahoo Finance, closing price as of 8/23/2026
B40: [6] 10Y UST yield: FRED / TradingEconomics, as of 8/21/2026
B41: [7] Equity risk premium: Damodaran / Duff & Phelps convention

Sheet Assumptions
B2: Microsoft Corporation (MSFT) - DCF Assumptions
B3: ($ in millions, except per-share data and percentages; FYE June 30)
B5: 1. Valuation Setup
B6: Valuation date | D6: Aug 23, 2026
B7: Actual share price ($) | D7: 483.24 | E7: Closing price 8/23/26 (Investing.com / Yahoo Finance)
B8: Diluted shares outstanding (mm) | D8: 7462 | E8: FY2025 10-K, weighted-avg diluted shares (FYE 6/30/25)
B9: Fiscal year end | D9: June 30
B11: 2. Balance Sheet Items ($mm, FY2025 10-K)
B12: Cash & cash equivalents | D12: 68000 | E12: FY2025 10-K balance sheet (~$68.0B, 6/30/25)
B13: Short-term investments | D13: 26565 | E13: FY2025 10-K; combined w/ cash = $94.565B reported
B14: Total cash & investments | D14: =SUM(D12:D13)
B15: Current portion of long-term debt | D15: 9227 | E15: FY2025 10-K debt note / 10-Q as of 9/30/25
B16: Long-term debt | D16: 40150 | E16: FY2025 10-K debt note (6/30/25)
B17: Total debt | D17: =SUM(D15:D16)
B18: Non-operating assets / equity investments | D18: 0 | E18: Not material for MSFT; set to 0
B19: Minority interest | D19: 0 | E19: None reported
B20: Net debt / (net cash) | D20: =D17-D14-D18
B21: Lease liabilities excluded from net debt: MSFT reports ~$57.5B of total lease obligations, but these are predominantly OPERATING leases (carried within Other long-term liabilities per the FY2025 10-K). Operating-lease rent is already expensed within the EBIT/EBITDA base used above, so capitalizing these liabilities into net debt would double-count the lease burden. Finance-lease principal repayments run only ~$0.3B/yr (FY2025 cash flow statement), implying a small finance-lease balance. Sensitivity: adding the full $57.5B to debt would move net debt from $(45,188)mm net cash to $12,323mm and reduce implied value by roughly $7.70/share on both methods.
B23: 3. Operating Drivers - FY2026E to FY2030E
D24: FY2026E | E24: FY2027E | F24: FY2028E | G24: FY2029E | H24: FY2030E
B25: Revenue growth % | D25: 0.14 | E25: 0.12 | F25: 0.1 | G25: 0.09 | H25: 0.08 | I25: Estimate: fade from FY25 consensus (~14-16%) toward long-run ~8%
B26: EBIT margin % | D26: 0.46 | E26: 0.465 | F26: 0.47 | G26: 0.47 | H26: 0.47 | I26: Estimate: gradual expansion from FY25A 45.6% on cloud mix, plateauing ~47%
B27: D&A % of revenue | D27: 0.125 | E27: 0.12 | F27: 0.115 | G27: 0.11 | H27: 0.105 | I27: Estimate: moderating from FY25A 12.1% as capex growth decelerates
B28: Capex % of revenue | D28: 0.23 | E28: 0.21 | F28: 0.19 | G28: 0.17 | H28: 0.15 | I28: Estimate: AI/cloud buildout peaks near-term (FY25A 22.9%), fades post-2027
B29: NWC % of revenue | D29: 0.03 | E29: 0.03 | F29: 0.03 | G29: 0.03 | H29: 0.03 | I29: Held flat at 3.0%, rounded down from the 3-yr historical average of ~3.2% (FY23 4.36%, FY24 2.26%, FY25 2.84%); NWC is a small, volatile swing factor for MSFT
B30: Tax rate (flat, all years) | D30: 0.19 | E30: FY2025 effective tax rate ~19.1% (estimate pending final 10-K footnote)
B32: 4. Terminal Assumptions
B33: Terminal growth rate (g) | D33: 0.025 | E33: ~long-run nominal GDP growth
B34: Exit EV/EBITDA multiple | D34: 20 | E34: Base case per comparable mega-cap software/cloud multiples
B35: End-of-period discounting throughout (no mid-year convention) - consistent with live sensitivity grids.

Sheet DCF
B2: Microsoft Corporation (MSFT) - DCF Analysis
B3: ($ in millions, except per-share data; FYE June 30)
B5: ($mm) | C5: FY2023A | D5: FY2024A | E5: FY2025A | F5: FY2026E | G5: FY2027E | H5: FY2028E | I5: FY2029E | J5: FY2030E
B6: Discount period | F6: 1 | G6: =F6+1 | H6: =G6+1 | I6: =H6+1 | J6: =I6+1
B8: Revenue | C8: 211915 | D8: 245122 | E8: 281724 | F8: =E8*(1+Assumptions!D25) | G8: =F8*(1+Assumptions!E25) | H8: =G8*(1+Assumptions!F25) | I8: =H8*(1+Assumptions!G25) | J8: =I8*(1+Assumptions!H25)
B9: Revenue growth % | D9: =D8/C8-1 | E9: =E8/D8-1 | F9: =F8/E8-1 | G9: =G8/F8-1 | H9: =H8/G8-1 | I9: =I8/H8-1 | J9: =J8/I8-1
B10: EBIT | C10: 88523 | D10: 109433 | E10: 128528 | F10: =F8*Assumptions!D26 | G10: =G8*Assumptions!E26 | H10: =H8*Assumptions!F26 | I10: =I8*Assumptions!G26 | J10: =J8*Assumptions!H26
B11: EBIT margin % | C11: =C10/C8 | D11: =D10/D8 | E11: =E10/E8 | F11: =Assumptions!D26 | G11: =Assumptions!E26 | H11: =Assumptions!F26 | I11: =Assumptions!G26 | J11: =Assumptions!H26
B12: D&A | C12: 13861 | D12: 22287 | E12: 34153 | F12: =F8*Assumptions!D27 | G12: =G8*Assumptions!E27 | H12: =H8*Assumptions!F27 | I12: =I8*Assumptions!G27 | J12: =J8*Assumptions!H27
B13: EBITDA | C13: =C10+C12 | D13: =D10+D12 | E13: =E10+E12 | F13: =F10+F12 | G13: =G10+G12 | H13: =H10+H12 | I13: =I10+I12 | J13: =J10+J12
B14: Less: Capex | C14: 28110 | D14: 44480 | E14: 64550 | F14: =F8*Assumptions!D28 | G14: =G8*Assumptions!E28 | H14: =H8*Assumptions!F28 | I14: =I8*Assumptions!G28 | J14: =J8*Assumptions!H28
B15: NWC balance | C15: 9235 | D15: 5534 | E15: 8011 | F15: =F8*Assumptions!D29 | G15: =G8*Assumptions!E29 | H15: =H8*Assumptions!F29 | I15: =I8*Assumptions!G29 | J15: =J8*Assumptions!H29 | K15: NWC = (AR+Inventory+Other CA) - (AP+Accrued Comp+Unearned Rev+Other CL), ex-cash/ex-debt; historical estimate from 10-K line items
B16: Increase/(Decrease) in NWC | D16: =D15-C15 | E16: =E15-D15 | F16: =F15-E15 | G16: =G15-F15 | H16: =H15-G15 | I16: =I15-H15 | J16: =J15-I15
B18: Unlevered Free Cash Flow Build (FY2026E–FY2030E)
B19: EBIT | F19: =F10 | G19: =G10 | H19: =H10 | I19: =I10 | J19: =J10
B20: Less: Cash taxes on EBIT | F20: =-F19*Assumptions!$D$30 | G20: =-G19*Assumptions!$D$30 | H20: =-H19*Assumptions!$D$30 | I20: =-I19*Assumptions!$D$30 | J20: =-J19*Assumptions!$D$30
B21: NOPAT | F21: =F19+F20 | G21: =G19+G20 | H21: =H19+H20 | I21: =I19+I20 | J21: =J19+J20
B22: Plus: D&A | F22: =F12 | G22: =G12 | H22: =H12 | I22: =I12 | J22: =J12
B23: Less: Capex | F23: =-F14 | G23: =-G14 | H23: =-H14 | I23: =-I14 | J23: =-J14
B24: Less: Increase in NWC | F24: =-F16 | G24: =-G16 | H24: =-H16 | I24: =-I16 | J24: =-J16
B25: Unlevered Free Cash Flow | F25: =F21+F22+F23+F24 | G25: =G21+G22+G23+G24 | H25: =H21+H22+H23+H24 | I25: =I21+I22+I23+I24 | J25: =J21+J22+J23+J24
B26: PV factor | F26: =1/(1+WACC!$D$25)^F6 | G26: =1/(1+WACC!$D$25)^G6 | H26: =1/(1+WACC!$D$25)^H6 | I26: =1/(1+WACC!$D$25)^I6 | J26: =1/(1+WACC!$D$25)^J6
B27: PV of Unlevered FCF | F27: =F25*F26 | G27: =G25*G26 | H27: =H25*H26 | I27: =I25*I26 | J27: =J25*J26
B28: Sum of PV of Explicit UFCF (FY26E–FY30E) | D28: =SUM(F27:J27)
B30: Terminal Value
B31: Terminal Unlevered FCF (FY2030E) | D31: =J25
B32: Terminal growth rate (g) | D32: =Assumptions!D33
B33: Terminal Value - Gordon Growth | D33: =D31*(1+D32)/(WACC!$D$25-D32)
B34: PV of Terminal Value - Gordon | D34: =D33*J26
B35: Implied Exit EV/EBITDA (Gordon) - cross-check 1 | D35: =D33/J13
B37: Terminal EBITDA (FY2030E) | D37: =J13
B38: Exit EV/EBITDA multiple | D38: =Assumptions!D34
B39: Terminal Value - Exit Multiple | D39: =D37*D38
B40: PV of Terminal Value - Exit Multiple | D40: =D39*J26
B41: Implied Terminal Growth (g) - cross-check 2 | D41: =(WACC!$D$25*D39-D31)/(D39+D31)
B42: Cross-checks: Gordon-implied exit multiple (D35) should bracket sensibly around the exit-multiple assumption (D38); exit-multiple-implied g (D41) should bracket sensibly around the terminal-growth assumption (D32).
B44: Enterprise Value → Equity Value Bridge | D44: Gordon Growth Method | F44: Exit Multiple Method
B45: Enterprise Value | D45: =$D$28+D34 | F45: =$D$28+D40
B46: Less: Net Debt / (Net Cash) | D46: =Assumptions!D20 | F46: =D46
B47: Plus: Non-operating Assets | D47: =Assumptions!D18 | F47: =D47
...

Sheet WACC
B2: Microsoft Corporation (MSFT) - WACC Build
B3: (CAPM cost of equity; capital-structure weighted)
B5: Cost of Equity (CAPM)
B6: Risk-free rate (10Y UST) | D6: 0.0474 | E6: 10Y UST constant maturity, as of 8/21/26 (FRED / TradingEconomics)
B7: Levered beta | D7: 1.04 | E7: 5Y monthly beta, Investing.com, as of Aug 2026
B8: Equity risk premium | D8: 0.05 | E8: Damodaran / Duff & Phelps convention, base case (range 4.5%-5.5%)
B9: Cost of Equity | D9: =D6+D7*D8
B11: Cost of Debt
B12: Pre-tax cost of debt | D12: 0.045 | E12: Weighted-avg coupon ~4.52% per FY25 10-K debt note / 10-Q as of 9/30/25
B13: Tax rate | D13: =Assumptions!D30
B14: After-tax cost of debt | D14: =D12*(1-D13)
B16: Capital Structure Weights
B17: Share price | D17: =Assumptions!D7
B18: Diluted shares outstanding (mm) | D18: =Assumptions!D8
B19: Market capitalization of equity ($mm) | D19: =D17*D18
B20: Total debt ($mm) | D20: =Assumptions!D17
B21: Total capital (D+E) ($mm) | D21: =D19+D20
B22: Weight of equity, E/(D+E) | D22: =D19/D21
B23: Weight of debt, D/(D+E) | D23: =D20/D21
B25: WACC | D25: =D22*D9+D23*D14
B26: WACC sanity: MSFT's minimal leverage (D/(D+E) ~1%) means WACC sits close to the CAPM cost of equity. Interest computed on beginning-of-period balances convention n/a (no revolving debt schedule in this DCF).

Sheet Sensitivity
B2: Microsoft Corporation (MSFT) - Sensitivity Analysis
B3: Live algebraic re-derivation grids (no Excel Data Tables); end-of-period discounting throughout
B5: Grid Step Sizes (blue inputs)
B6: WACC step | D6: 0.005
B7: Terminal growth (g) step | D7: 0.005
B8: Exit multiple step | D8: 1
B10: Grid A: WACC (rows) x Terminal Growth g (cols) → Implied Share Price (Gordon Growth Method)
B11: Implied Price → | C11: =DCF!D50 | D11: =E11-$D$7 | E11: =F11-$D$7 | F11: =Assumptions!D33 | G11: =F11+$D$7 | H11: =G11+$D$7
C12: =C13-$D$6 | D12: =(SUMPRODUCT(DCF!$F$25:$J$25,1/(1+$C12)^DCF!$F$6:$J$6)+(DCF!$D$57*(1+D$11))/($C12-D$11)/(1+$C12)^DCF!$J$6-DCF!$D$55)/DCF!$D$56 | E12: =(SUMPRODUCT(DCF!$F$25:$J$25,1/(1+$C12)^DCF!$F$6:$J$6)+(DCF!$D$57*(1+E$11))/($C12-E$11)/(1+$C12)^DCF!$J$6-DCF!$D$55)/DCF!$D$56 | F12: =(SUMPRODUCT(DCF!$F$25:$J$25,1/(1+$C12)^DCF!$F$6:$J$6)+(DCF!$D$57*(1+F$11))/($C12-F$11)/(1+$C12)^DCF!$J$6-DCF!$D$55)/DCF!$D$56 | G12: =(SUMPRODUCT(DCF!$F$25:$J$25,1/(1+$C12)^DCF!$F$6:$J$6)+(DCF!$D$57*(1+G$11))/($C12-G$11)/(1+$C12)^DCF!$J$6-DCF!$D$55)/DCF!$D$56 | H12: =(SUMPRODUCT(DCF!$F$25:$J$25,1/(1+$C12)^DCF!$F$6:$J$6)+(DCF!$D$57*(1+H$11))/($C12-H$11)/(1+$C12)^DCF!$J$6-DCF!$D$55)/DCF!$D$56
C13: =C14-$D$6 | D13: =(SUMPRODUCT(DCF!$F$25:$J$25,1/(1+$C13)^DCF!$F$6:$J$6)+(DCF!$D$57*(1+D$11))/($C13-D$11)/(1+$C13)^DCF!$J$6-DCF!$D$55)/DCF!$D$56 | E13: =(SUMPRODUCT(DCF!$F$25:$J$25,1/(1+$C13)^DCF!$F$6:$J$6)+(DCF!$D$57*(1+E$11))/($C13-E$11)/(1+$C13)^DCF!$J$6-DCF!$D$55)/DCF!$D$56 | F13: =(SUMPRODUCT(DCF!$F$25:$J$25,1/(1+$C13)^DCF!$F$6:$J$6)+(DCF!$D$57*(1+F$11))/($C13-F$11)/(1+$C13)^DCF!$J$6-DCF!$D$55)/DCF!$D$56 | G13: =(SUMPRODUCT(DCF!$F$25:$J$25,1/(1+$C13)^DCF!$F$6:$J$6)+(DCF!$D$57*(1+G$11))/($C13-G$11)/(1+$C13)^DCF!$J$6-DCF!$D$55)/DCF!$D$56 | H13: =(SUMPRODUCT(DCF!$F$25:$J$25,1/(1+$C13)^DCF!$F$6:$J$6)+(DCF!$D$57*(1+H$11))/($C13-H$11)/(1+$C13)^DCF!$J$6-DCF!$D$55)/DCF!$D$56
C14: =C15-$D$6 | D14: =(SUMPRODUCT(DCF!$F$25:$J$25,1/(1+$C14)^DCF!$F$6:$J$6)+(DCF!$D$57*(1+D$11))/($C14-D$11)/(1+$C14)^DCF!$J$6-DCF!$D$55)/DCF!$D$56 | E14: =(SUMPRODUCT(DCF!$F$25:$J$25,1/(1+$C14)^DCF!$F$6:$J$6)+(DCF!$D$57*(1+E$11))/($C14-E$11)/(1+$C14)^DCF!$J$6-DCF!$D$55)/DCF!$D$56 | F14: =(SUMPRODUCT(DCF!$F$25:$J$25,1/(1+$C14)^DCF!$F$6:$J$6)+(DCF!$D$57*(1+F$11))/($C14-F$11)/(1+$C14)^DCF!$J$6-DCF!$D$55)/DCF!$D$56 | G14: =(SUMPRODUCT(DCF!$F$25:$J$25,1/(1+$C14)^DCF!$F$6:$J$6)+(DCF!$D$57*(1+G$11))/($C14-G$11)/(1+$C14)^DCF!$J$6-DCF!$D$55)/DCF!$D$56 | H14: =(SUMPRODUCT(DCF!$F$25:$J$25,1/(1+$C14)^DCF!$F$6:$J$6)+(DCF!$D$57*(1+H$11))/($C14-H$11)/(1+$C14)^DCF!$J$6-DCF!$D$55)/DCF!$D$56
C15: =WACC!D25 | D15: =(SUMPRODUCT(DCF!$F$25:$J$25,1/(1+$C15)^DCF!$F$6:$J$6)+(DCF!$D$57*(1+D$11))/($C15-D$11)/(1+$C15)^DCF!$J$6-DCF!$D$55)/DCF!$D$56 | E15: =(SUMPRODUCT(DCF!$F$25:$J$25,1/(1+$C15)^DCF!$F$6:$J$6)+(DCF!$D$57*(1+E$11))/($C15-E$11)/(1+$C15)^DCF!$J$6-DCF!$D$55)/DCF!$D$56 | F15: =(SUMPRODUCT(DCF!$F$25:$J$25,1/(1+$C15)^DCF!$F$6:$J$6)+(DCF!$D$57*(1+F$11))/($C15-F$11)/(1+$C15)^DCF!$J$6-DCF!$D$55)/DCF!$D$56 | G15: =(SUMPRODUCT(DCF!$F$25:$J$25,1/(1+$C15)^DCF!$F$6:$J$6)+(DCF!$D$57*(1+G$11))/($C15-G$11)/(1+$C15)^DCF!$J$6-DCF!$D$55)/DCF!$D$56 | H15: =(SUMPRODUCT(DCF!$F$25:$J$25,1/(1+$C15)^DCF!$F$6:$J$6)+(DCF!$D$57*(1+H$11))/($C15-H$11)/(1+$C15)^DCF!$J$6-DCF!$D$55)/DCF!$D$56
C16: =C15+$D$6 | D16: =(SUMPRODUCT(DCF!$F$25:$J$25,1/(1+$C16)^DCF!$F$6:$J$6)+(DCF!$D$57*(1+D$11))/($C16-D$11)/(1+$C16)^DCF!$J$6-DCF!$D$55)/DCF!$D$56 | E16: =(SUMPRODUCT(DCF!$F$25:$J$25,1/(1+$C16)^DCF!$F$6:$J$6)+(DCF!$D$57*(1+E$11))/($C16-E$11)/(1+$C16)^DCF!$J$6-DCF!$D$55)/DCF!$D$56 | F16: =(SUMPRODUCT(DCF!$F$25:$J$25,1/(1+$C16)^DCF!$F$6:$J$6)+(DCF!$D$57*(1+F$11))/($C16-F$11)/(1+$C16)^DCF!$J$6-DCF!$D$55)/DCF!$D$56 | G16: =(SUMPRODUCT(DCF!$F$25:$J$25,1/(1+$C16)^DCF!$F$6:$J$6)+(DCF!$D$57*(1+G$11))/($C16-G$11)/(1+$C16)^DCF!$J$6-DCF!$D$55)/DCF!$D$56 | H16: =(SUMPRODUCT(DCF!$F$25:$J$25,1/(1+$C16)^DCF!$F$6:$J$6)+(DCF!$D$57*(1+H$11))/($C16-H$11)/(1+$C16)^DCF!$J$6-DCF!$D$55)/DCF!$D$56
C17: =C16+$D$6 | D17: =(SUMPRODUCT(DCF!$F$25:$J$25,1/(1+$C17)^DCF!$F$6:$J$6)+(DCF!$D$57*(1+D$11))/($C17-D$11)/(1+$C17)^DCF!$J$6-DCF!$D$55)/DCF!$D$56 | E17: =(SUMPRODUCT(DCF!$F$25:$J$25,1/(1+$C17)^DCF!$F$6:$J$6)+(DCF!$D$57*(1+E$11))/($C17-E$11)/(1+$C17)^DCF!$J$6-DCF!$D$55)/DCF!$D$56 | F17: =(SUMPRODUCT(DCF!$F$25:$J$25,1/(1+$C17)^DCF!$F$6:$J$6)+(DCF!$D$57*(1+F$11))/($C17-F$11)/(1+$C17)^DCF!$J$6-DCF!$D$55)/DCF!$D$56 | G17: =(SUMPRODUCT(DCF!$F$25:$J$25,1/(1+$C17)^DCF!$F$6:$J$6)+(DCF!$D$57*(1+G$11))/($C17-G$11)/(1+$C17)^DCF!$J$6-DCF!$D$55)/DCF!$D$56 | H17: =(SUMPRODUCT(DCF!$F$25:$J$25,1/(1+$C17)^DCF!$F$6:$J$6)+(DCF!$D$57*(1+H$11))/($C17-H$11)/(1+$C17)^DCF!$J$6-DCF!$D$55)/DCF!$D$56
C18: =C17+$D$6 | D18: =(SUMPRODUCT(DCF!$F$25:$J$25,1/(1+$C18)^DCF!$F$6:$J$6)+(DCF!$D$57*(1+D$11))/($C18-D$11)/(1+$C18)^DCF!$J$6-DCF!$D$55)/DCF!$D$56 | E18: =(SUMPRODUCT(DCF!$F$25:$J$25,1/(1+$C18)^DCF!$F$6:$J$6)+(DCF!$D$57*(1+E$11))/($C18-E$11)/(1+$C18)^DCF!$J$6-DCF!$D$55)/DCF!$D$56 | F18: =(SUMPRODUCT(DCF!$F$25:$J$25,1/(1+$C18)^DCF!$F$6:$J$6)+(DCF!$D$57*(1+F$11))/($C18-F$11)/(1+$C18)^DCF!$J$6-DCF!$D$55)/DCF!$D$56 | G18: =(SUMPRODUCT(DCF!$F$25:$J$25,1/(1+$C18)^DCF!$F$6:$J$6)+(DCF!$D$57*(1+G$11))/($C18-G$11)/(1+$C18)^DCF!$J$6-DCF!$D$55)/DCF!$D$56 | H18: =(SUMPRODUCT(DCF!$F$25:$J$25,1/(1+$C18)^DCF!$F$6:$J$6)+(DCF!$D$57*(1+H$11))/($C18-H$11)/(1+$C18)^DCF!$J$6-DCF!$D$55)/DCF!$D$56
B20: Check: center cell − base Gordon price (must be 0.00) | D20: =ROUND(F15-DCF!D50,2)
B22: Implied Price → | C22: =DCF!F50 | D22: =E22-$D$8 | E22: =F22-$D$8 | F22: =Assumptions!D34 | G22: =F22+$D$8 | H22: =G22+$D$8
B23: Grid B: WACC (rows) x Exit EV/EBITDA Multiple (cols) → Implied Share Price (Exit Multiple Method)
C24: =C25-$D$6 | D24: =(SUMPRODUCT(DCF!$F$25:$J$25,1/(1+$C24)^DCF!$F$6:$J$6)+DCF!$D$58*D$22/(1+$C24)^DCF!$J$6-DCF!$D$55)/DCF!$D$56 | E24: =(SUMPRODUCT(DCF!$F$25:$J$25,1/(1+$C24)^DCF!$F$6:$J$6)+DCF!$D$58*E$22/(1+$C24)^DCF!$J$6-DCF!$D$55)/DCF!$D$56 | F24: =(SUMPRODUCT(DCF!$F$25:$J$25,1/(1+$C24)^DCF!$F$6:$J$6)+DCF!$D$58*F$22/(1+$C24)^DCF!$J$6-DCF!$D$55)/DCF!$D$56 | G24: =(SUMPRODUCT(DCF!$F$25:$J$25,1/(1+$C24)^DCF!$F$6:$J$6)+DCF!$D$58*G$22/(1+$C24)^DCF!$J$6-DCF!$D$55)/DCF!$D$56 | H24: =(SUMPRODUCT(DCF!$F$25:$J$25,1/(1+$C24)^DCF!$F$6:$J$6)+DCF!$D$58*H$22/(1+$C24)^DCF!$J$6-DCF!$D$55)/DCF!$D$56
C25: =C26-$D$6 | D25: =(SUMPRODUCT(DCF!$F$25:$J$25,1/(1+$C25)^DCF!$F$6:$J$6)+DCF!$D$58*D$22/(1+$C25)^DCF!$J$6-DCF!$D$55)/DCF!$D$56 | E25: =(SUMPRODUCT(DCF!$F$25:$J$25,1/(1+$C25)^DCF!$F$6:$J$6)+DCF!$D$58*E$22/(1+$C25)^DCF!$J$6-DCF!$D$55)/DCF!$D$56 | F25: =(SUMPRODUCT(DCF!$F$25:$J$25,1/(1+$C25)^DCF!$F$6:$J$6)+DCF!$D$58*F$22/(1+$C25)^DCF!$J$6-DCF!$D$55)/DCF!$D$56 | G25: =(SUMPRODUCT(DCF!$F$25:$J$25,1/(1+$C25)^DCF!$F$6:$J$6)+DCF!$D$58*G$22/(1+$C25)^DCF!$J$6-DCF!$D$55)/DCF!$D$56 | H25: =(SUMPRODUCT(DCF!$F$25:$J$25,1/(1+$C25)^DCF!$F$6:$J$6)+DCF!$D$58*H$22/(1+$C25)^DCF!$J$6-DCF!$D$55)/DCF!$D$56
C26: =C27-$D$6 | D26: =(SUMPRODUCT(DCF!$F$25:$J$25,1/(1+$C26)^DCF!$F$6:$J$6)+DCF!$D$58*D$22/(1+$C26)^DCF!$J$6-DCF!$D$55)/DCF!$D$56 | E26: =(SUMPRODUCT(DCF!$F$25:$J$25,1/(1+$C26)^DCF!$F$6:$J$6)+DCF!$D$58*E$22/(1+$C26)^DCF!$J$6-DCF!$D$55)/DCF!$D$56 | F26: =(SUMPRODUCT(DCF!$F$25:$J$25,1/(1+$C26)^DCF!$F$6:$J$6)+DCF!$D$58*F$22/(1+$C26)^DCF!$J$6-DCF!$D$55)/DCF!$D$56 | G26: =(SUMPRODUCT(DCF!$F$25:$J$25,1/(1+$C26)^DCF!$F$6:$J$6)+DCF!$D$58*G$22/(1+$C26)^DCF!$J$6-DCF!$D$55)/DCF!$D$56 | H26: =(SUMPRODUCT(DCF!$F$25:$J$25,1/(1+$C26)^DCF!$F$6:$J$6)+DCF!$D$58*H$22/(1+$C26)^DCF!$J$6-DCF!$D$55)/DCF!$D$56
C27: =WACC!D25 | D27: =(SUMPRODUCT(DCF!$F$25:$J$25,1/(1+$C27)^DCF!$F$6:$J$6)+DCF!$D$58*D$22/(1+$C27)^DCF!$J$6-DCF!$D$55)/DCF!$D$56 | E27: =(SUMPRODUCT(DCF!$F$25:$J$25,1/(1+$C27)^DCF!$F$6:$J$6)+DCF!$D$58*E$22/(1+$C27)^DCF!$J$6-DCF!$D$55)/DCF!$D$56 | F27: =(SUMPRODUCT(DCF!$F$25:$J$25,1/(1+$C27)^DCF!$F$6:$J$6)+DCF!$D$58*F$22/(1+$C27)^DCF!$J$6-DCF!$D$55)/DCF!$D$56 | G27: =(SUMPRODUCT(DCF!$F$25:$J$25,1/(1+$C27)^DCF!$F$6:$J$6)+DCF!$D$58*G$22/(1+$C27)^DCF!$J$6-DCF!$D$55)/DCF!$D$56 | H27: =(SUMPRODUCT(DCF!$F$25:$J$25,1/(1+$C27)^DCF!$F$6:$J$6)+DCF!$D$58*H$22/(1+$C27)^DCF!$J$6-DCF!$D$55)/DCF!$D$56
C28: =C27+$D$6 | D28: =(SUMPRODUCT(DCF!$F$25:$J$25,1/(1+$C28)^DCF!$F$6:$J$6)+DCF!$D$58*D$22/(1+$C28)^DCF!$J$6-DCF!$D$55)/DCF!$D$56 | E28: =(SUMPRODUCT(DCF!$F$25:$J$25,1/(1+$C28)^DCF!$F$6:$J$6)+DCF!$D$58*E$22/(1+$C28)^DCF!$J$6-DCF!$D$55)/DCF!$D$56 | F28: =(SUMPRODUCT(DCF!$F$25:$J$25,1/(1+$C28)^DCF!$F$6:$J$6)+DCF!$D$58*F$22/(1+$C28)^DCF!$J$6-DCF!$D$55)/DCF!$D$56 | G28: =(SUMPRODUCT(DCF!$F$25:$J$25,1/(1+$C28)^DCF!$F$6:$J$6)+DCF!$D$58*G$22/(1+$C28)^DCF!$J$6-DCF!$D$55)/DCF!$D$56 | H28: =(SUMPRODUCT(DCF!$F$25:$J$25,1/(1+$C28)^DCF!$F$6:$J$6)+DCF!$D$58*H$22/(1+$C28)^DCF!$J$6-DCF!$D$55)/DCF!$D$56
C29: =C28+$D$6 | D29: =(SUMPRODUCT(DCF!$F$25:$J$25,1/(1+$C29)^DCF!$F$6:$J$6)+DCF!$D$58*D$22/(1+$C29)^DCF!$J$6-DCF!$D$55)/DCF!$D$56 | E29: =(SUMPRODUCT(DCF!$F$25:$J$25,1/(1+$C29)^DCF!$F$6:$J$6)+DCF!$D$58*E$22/(1+$C29)^DCF!$J$6-DCF!$D$55)/DCF!$D$56 | F29: =(SUMPRODUCT(DCF!$F$25:$J$25,1/(1+$C29)^DCF!$F$6:$J$6)+DCF!$D$58*F$22/(1+$C29)^DCF!$J$6-DCF!$D$55)/DCF!$D$56 | G29: =(SUMPRODUCT(DCF!$F$25:$J$25,1/(1+$C29)^DCF!$F$6:$J$6)+DCF!$D$58*G$22/(1+$C29)^DCF!$J$6-DCF!$D$55)/DCF!$D$56 | H29: =(SUMPRODUCT(DCF!$F$25:$J$25,1/(1+$C29)^DCF!$F$6:$J$6)+DCF!$D$58*H$22/(1+$C29)^DCF!$J$6-DCF!$D$55)/DCF!$D$56
C30: =C29+$D$6 | D30: =(SUMPRODUCT(DCF!$F$25:$J$25,1/(1+$C30)^DCF!$F$6:$J$6)+DCF!$D$58*D$22/(1+$C30)^DCF!$J$6-DCF!$D$55)/DCF!$D$56 | E30: =(SUMPRODUCT(DCF!$F$25:$J$25,1/(1+$C30)^DCF!$F$6:$J$6)+DCF!$D$58*E$22/(1+$C30)^DCF!$J$6-DCF!$D$55)/DCF!$D$56 | F30: =(SUMPRODUCT(DCF!$F$25:$J$25,1/(1+$C30)^DCF!$F$6:$J$6)+DCF!$D$58*F$22/(1+$C30)^DCF!$J$6-DCF!$D$55)/DCF!$D$56 | G30: =(SUMPRODUCT(DCF!$F$25:$J$25,1/(1+$C30)^DCF!$F$6:$J$6)+DCF!$D$58*G$22/(1+$C30)^DCF!$J$6-DCF!$D$55)/DCF!$D$56 | H30: =(SUMPRODUCT(DCF!$F$25:$J$25,1/(1+$C30)^DCF!$F$6:$J$6)+DCF!$D$58*H$22/(1+$C30)^DCF!$J$6-DCF!$D$55)/DCF!$D$56
B32: Check: center cell − base exit-multiple price (must be 0.00) | D32: =ROUND(F27-DCF!F50,2)
