Workbook

Sheet Cover
B2: Apple Inc. (AAPL)
B3: Discounted Cash Flow Analysis
B4: Prepared by: Akul Veauli | Date: August 23, 2026
B6: Five-year unlevered DCF for Apple Inc. (NASDAQ: AAPL), FYE last Saturday of September. Projects a mature, mid-single-digit revenue growth path with modest EBIT margin expansion from Services mix shift, discounts unlevered free cash flow at a CAPM-derived WACC, and cross-checks terminal value via both the Gordon Growth and Exit EV/EBITDA Multiple methods. Net debt reflects AAPL's large gross cash/investments position AND large gross debt load (both ~$110-130B), including long-term marketable securities treated as cash-like.
B9: Color Code Legend
B10: 309.35 | C10: Blue font / yellow fill = hardcoded input
B11: =B10*1 | C11: Black font = formula (same sheet)
B12: =Assumptions!D7 | C12: Green font = link from another tab
B14: Table of Contents
B15: Cover
B16: Assumptions
B17: DCF
B18: WACC
B19: Sensitivity
B21: Key Outputs
B22: Implied Share Price (Gordon Growth) | D22: =DCF!D60
B23: Implied Share Price (Exit Multiple) | D23: =DCF!F60
B24: Enterprise Value - Gordon ($mm) | D24: =DCF!D56
B25: Actual Share Price | D25: =Assumptions!D7
B26: Implied Upside/(Downside) - Gordon | D26: =DCF!D62
B29: Sources: Apple Inc. FY2023, FY2024, FY2025 Form 10-K (SEC EDGAR); FY2025 8-K earnings release; StockAnalysis.com; MacroTrends; FinBox; GuruFocus; FinCharts. Market data as of Aug 21, 2026.
B30: FLAGGED ESTIMATES: FY2023A/FY2024A SBC (extrapolated from FY2025A actual); FY2023A/FY2024A NWC (held at FY2025A ratio, itemized BS detail unavailable); Cash/ST-investments split (residual of reported aggregate).

Sheet Assumptions
B2: Apple Inc. (AAPL) - DCF Assumptions
B3: ($ in millions, except per-share data, percentages, and multiples)
B5: 1. Valuation Setup
B6: Valuation Date | D6: Aug 21, 2026 | F6: As-of date for market inputs
B7: Actual Share Price ($) | D7: 309.35 | F7: Close, Aug 21, 2026 - Yahoo/Google Finance
B8: Diluted Shares Outstanding (mm) | D8: 14715 | F8: Latest 10-Q/cover, ~Aug 2026 - FinCharts
B9: Fiscal Year-End | D9: Last Saturday of September; FY2025 = Sep 27, 2025
B11: 2. Balance Sheet Items ($mm) - FY2025 10-K / Latest Available
B12: Cash & Equivalents + ST Marketable Securities | D12: 36620 | F12: Residual = Total Cash & Investments ($132,420) less LT securities below; components not separately disclosed with precision
B13: Long-term Marketable Securities (cash-like) | D13: 95800 | F13: AAPL's LT investment portfolio (Treasuries/corp bonds); treated as cash-like per model spec. ~Q1 FY2026 basis
B14: Total Cash & Investments | D14: =D12+D13 | F14: Check: ties to FY2025 10-K reported aggregate of ~$132.4B
B15: Total Debt (Reported) | D15: 112377 | F15: FY2025 10-K / StockAnalysis
B16: Long-term Debt | D16: 78328 | F16: FY2025 10-K (down 8.66% YoY)
B17: Short-term Borrowings (residual) | D17: =D15-D16 | F17: Commercial paper + current portion of term debt = Total Debt less LT Debt
B18: Non-Operating Assets / Equity Investments | D18: 0 | F18: Immaterial / already captured within marketable securities above
B19: Minority Interest | D19: 0
B20: Net Debt / (Net Cash) | D20: =D15-D14 | F20: Negative = net cash position; ties to FY2025 10-K net cash of ~$20.0B
B22: 3. Operating Drivers, FY2026E–FY2030E
D23: FY2026E | E23: FY2027E | F23: FY2028E | G23: FY2029E | H23: FY2030E
B24: Revenue Growth % | D24: 0.04 | E24: 0.05 | F24: 0.045 | G24: 0.04 | H24: 0.035 | I24: Mature mid-single-digit growth; modest fade from FY27 product cycle peak
B25: EBIT Margin % | D25: 0.323 | E25: 0.326 | F25: 0.329 | G25: 0.331 | H25: 0.333 | I25: Gradual expansion from FY25A 32.0% via Services mix shift
B26: D&A % of Revenue | D26: 0.0285 | E26: 0.0285 | F26: 0.0285 | G26: 0.0285 | H26: 0.0285
B27: Capex % of Revenue | D27: 0.03 | E27: 0.03 | F27: 0.03 | G27: 0.03 | H27: 0.03
B28: NWC % of Revenue | D28: -0.1739 | E28: -0.1739 | F28: -0.1739 | G28: -0.1739 | H28: -0.1739 | I28: Held flat at FY2025A ratio (structurally negative NWC - AAPL is payables-funded)
B29: Tax Rate (applies all years) | D29: 0.155 | E29: Effective rate per FY2025 10-K ~15.6%, held flat; statutory federal 21% fallback if needed
B31: 4. Terminal Assumptions
B32: Terminal Growth Rate (g) | F32: 0.03 | G32: Below 10Y UST (4.74%); long-run nominal GDP-like rate
B33: Exit EV/EBITDA Multiple | F33: 13 | G33: Below AAPL's own trading multiple; deliberately conservative cross-check
B34: End-of-period discounting throughout (no mid-year convention).
B36: Sources: AAPL FY2023-FY2025 10-Ks (SEC EDGAR); FY2025 8-K earnings release; StockAnalysis.com; MacroTrends; FinBox; GuruFocus; FinCharts.

Sheet DCF
B2: Apple Inc. (AAPL) - Discounted Cash Flow Analysis
B3: ($ in millions, except per-share data)
C5: FY2023A | D5: FY2024A | E5: FY2025A | F5: FY2026E | G5: FY2027E | H5: FY2028E | I5: FY2029E | J5: FY2030E
B6: Discount Period | F6: 1 | G6: =F6+1 | H6: =G6+1 | I6: =H6+1 | J6: =I6+1
B8: Historical & Projected Operating Build ($mm)
B9: Revenue | C9: 383285 | D9: 391035 | E9: 416161 | F9: =E9*(1+Assumptions!$D$24) | G9: =F9*(1+Assumptions!$E$24) | H9: =G9*(1+Assumptions!$F$24) | I9: =H9*(1+Assumptions!$G$24) | J9: =I9*(1+Assumptions!$H$24)
B10: Revenue Growth % | D10: =D9/C9-1 | E10: =E9/D9-1 | F10: =Assumptions!$D$24 | G10: =Assumptions!$E$24 | H10: =Assumptions!$F$24 | I10: =Assumptions!$G$24 | J10: =Assumptions!$H$24
B11: EBIT | C11: 114301 | D11: 123216 | E11: 133050 | F11: =F9*Assumptions!$D$25 | G11: =G9*Assumptions!$E$25 | H11: =H9*Assumptions!$F$25 | I11: =I9*Assumptions!$G$25 | J11: =J9*Assumptions!$H$25
B12: EBIT Margin % | C12: =C11/C9 | D12: =D11/D9 | E12: =E11/E9 | F12: =Assumptions!$D$25 | G12: =Assumptions!$E$25 | H12: =Assumptions!$F$25 | I12: =Assumptions!$G$25 | J12: =Assumptions!$H$25
B13: D&A | C13: 11519 | D13: 11445 | E13: 11698 | F13: =F9*Assumptions!$D$26 | G13: =G9*Assumptions!$E$26 | H13: =H9*Assumptions!$F$26 | I13: =I9*Assumptions!$G$26 | J13: =J9*Assumptions!$H$26
B14: EBITDA | C14: =C11+C13 | D14: =D11+D13 | E14: =E11+E13 | F14: =F11+F13 | G14: =G11+G13 | H14: =H11+H13 | I14: =I11+I13 | J14: =J11+J13
B15: Less: Capex | C15: 10959 | D15: 9447 | E15: 12715 | F15: =F9*Assumptions!$D$27 | G15: =G9*Assumptions!$E$27 | H15: =H9*Assumptions!$F$27 | I15: =I9*Assumptions!$G$27 | J15: =J9*Assumptions!$H$27
B16: Net Working Capital (operating, ex-vendor non-trade recv.) | C16: -66648.3 | D16: -67995.9 | E16: -72365 | F16: =F9*Assumptions!$D$28 | G16: =G9*Assumptions!$E$28 | H16: =H9*Assumptions!$F$28 | I16: =I9*Assumptions!$G$28 | J16: =J9*Assumptions!$H$28
B17: NWC = AR + Inventory − AP − Accrued Liabilities. FY2025A computed from FY2025 10-K ($39,777 AR + $5,718 Inv − $69,860 AP − ~$48,000 accrued). Vendor non-trade receivables ($33.2B) deliberately EXCLUDED from NWC per explorer advisory - it is a supplier-financing conduit, not true operating working capital, and including it would double-count against AAPL's elevated AP. FY2023A/FY2024A NWC are ESTIMATES (held at FY2025A ratio to revenue; itemized BS detail not available for those years).
B18: AAPL exhibits structurally negative net working capital (funded by suppliers) - a well-known feature of its business model, not a model error.
B19: (Increase)/Decrease in NWC | F19: =E16-F16 | G19: =F16-G16 | H19: =G16-H16 | I19: =H16-I16 | J19: =I16-J16
B20: Shown as source/(use) of cash: NWC becoming more negative each year is a SOURCE of cash (positive here).
B22: Memo: Stock-Based Compensation (SBC, $mm) - not added back below | C22: 12000 | D22: 12500 | E22: 12860
B23: FLAG: FY2023A/FY2024A SBC are ESTIMATES extrapolated from the FY2025A actual ($12.86B, GuruFocus/FinBox); only FY2025A is a disclosed figure. SBC is not separately added back in the UFCF build below - EBIT already reflects SBC as an operating expense; no incremental non-cash adjustment is applied (a deliberate, conservative convention flagged for reviewer discretion).
B25: Unlevered Free Cash Flow Build ($mm) - FY2026E–FY2030E
B26: EBIT | F26: =F11 | G26: =G11 | H26: =H11 | I26: =I11 | J26: =J11
B27: Less: Cash Taxes @ Tax Rate | F27: =F26*Assumptions!$D$29 | G27: =G26*Assumptions!$D$29 | H27: =H26*Assumptions!$D$29 | I27: =I26*Assumptions!$D$29 | J27: =J26*Assumptions!$D$29
B28: NOPAT | F28: =F26-F27 | G28: =G26-G27 | H28: =H26-H27 | I28: =I26-I27 | J28: =J26-J27
B29: Plus: D&A | F29: =F13 | G29: =G13 | H29: =H13 | I29: =I13 | J29: =J13
B30: Less: Capex | F30: =F15 | G30: =G15 | H30: =H15 | I30: =I15 | J30: =J15
B31: Less: (Increase)/Decrease in NWC add-back | F31: =F19 | G31: =G19 | H31: =H19 | I31: =I19 | J31: =J19
B32: Unlevered Free Cash Flow | F32: =F28+F29-F30+F31 | G32: =G28+G29-G30+G31 | H32: =H28+H29-H30+H31 | I32: =I28+I29-I30+I31 | J32: =J28+J29-J30+J31
B33: PV Factor | F33: =1/(1+WACC!$D$25)^F6 | G33: =1/(1+WACC!$D$25)^G6 | H33: =1/(1+WACC!$D$25)^H6 | I33: =1/(1+WACC!$D$25)^I6 | J33: =1/(1+WACC!$D$25)^J6
B34: PV of Unlevered FCF | F34: =F32*F33 | G34: =G32*G33 | H34: =H32*H33 | I34: =I32*I33 | J34: =J32*J33
B36: Sum of PV of Explicit UFCF (FY2026E–FY2030E) | F36: =SUM(F34:J34)
B38: Terminal Value
B39: Terminal Value - Gordon Growth Method
B40: Terminal-Year Unlevered FCF (FY2030E) | F40: =J32
B41: Terminal Value (Gordon) | F41: =F40*(1+Assumptions!$F$32)/(WACC!$D$25-Assumptions!$F$32)
B42: PV of Terminal Value (Gordon) | F42: =F41*J33
B43: Implied Exit EV/EBITDA (cross-check) | F43: =F41/J14
B45: Terminal Value - Exit Multiple Method
B46: Terminal-Year EBITDA (FY2030E) | F46: =J14
B47: Terminal Value (Exit Multiple) | F47: =F46*Assumptions!$F$33
B48: PV of Terminal Value (Exit Multiple) | F48: =F47*J33
...

Sheet WACC
B2: Apple Inc. (AAPL) - WACC Build
B3: ($ in millions, except per-share data)
B5: Cost of Equity (CAPM)
B6: Risk-Free Rate (10Y UST) | D6: 0.0474 | F6: 10Y UST, Aug 21, 2026 - Trading Economics/CNBC
B7: Levered Beta | D7: 0.95 | F7: Observed beta, Aug 2026: AlphaSpread 0.95, GuruFocus 0.93 (8/10/26), Yahoo 1.086, MacroAxis 0.73 - median of non-outlier set = 0.95. Spec fallback 1.10 used only where observed data is unavailable (cf. MSFT 1.04, NVDA 1.98 observed). Conservative alternative: beta 1.10 -> WACC 10.08%, Gordon price ~$124.77.
B8: Equity Risk Premium | D8: 0.05 | F8: Damodaran / Duff & Phelps convention; fallback per spec (Damodaran implicit ~4.5-5.5%)
B9: Cost of Equity (Ke) | D9: =D6+D7*D8
B11: Cost of Debt
B12: Pre-Tax Cost of Debt | D12: 0.045 | F12: AAA-implied long-term bond yield given AAPL's strong credit profile (~rf + 25-50bp)
B13: Tax Rate | D13: =Assumptions!$D$29
B14: After-Tax Cost of Debt | D14: =D12*(1-D13)
B16: Capital Structure Weights
B17: Share Price ($) | D17: =Assumptions!$D$7
B18: Diluted Shares (mm) | D18: =Assumptions!$D$8
B19: Market Cap = Equity Value (E) | D19: =D17*D18
B20: Total Debt (D) | D20: =Assumptions!$D$15
B21: D + E | D21: =D19+D20
B22: E / (D+E) | D22: =D19/D21
B23: D / (D+E) | D23: =D20/D21
B25: WACC | D25: =D22*D9+D23*D14
B26: WACC sanity: sits above the risk-free rate, reflecting near-100% equity weight given AAPL's minimal net leverage (net cash position).
B27: Interest computed on beginning-of-period balances / static capital structure - no iterative calc, no circularity.

Sheet Sensitivity
B2: Apple Inc. (AAPL) - DCF Sensitivity Grids
B3: Implied share price ($); live algebraic re-derivation, no Data Tables
B5: Grid A - Implied Share Price: WACC (rows) × Terminal Growth g (cols) - Gordon Growth Method
B6: Corner cell = base-case implied price (Gordon), green-linked to DCF!D60
B7: =DCF!$D$60 | C7: =$E$7+(-0.01) | D7: =$E$7+(-0.005) | E7: =Assumptions!$F$32 | F7: =$E$7+(0.005) | G7: =$E$7+(0.01)
B8: =$B$11+(-0.015) | C8: =(SUMPRODUCT(DCF!$F$32:$J$32,1/(1+$B8)^DCF!$F$6:$J$6)+(DCF!$J$32*(1+C$7))/($B8-C$7)/(1+$B8)^DCF!$J$6-Assumptions!$D$20)/Assumptions!$D$8 | D8: =(SUMPRODUCT(DCF!$F$32:$J$32,1/(1+$B8)^DCF!$F$6:$J$6)+(DCF!$J$32*(1+D$7))/($B8-D$7)/(1+$B8)^DCF!$J$6-Assumptions!$D$20)/Assumptions!$D$8 | E8: =(SUMPRODUCT(DCF!$F$32:$J$32,1/(1+$B8)^DCF!$F$6:$J$6)+(DCF!$J$32*(1+E$7))/($B8-E$7)/(1+$B8)^DCF!$J$6-Assumptions!$D$20)/Assumptions!$D$8 | F8: =(SUMPRODUCT(DCF!$F$32:$J$32,1/(1+$B8)^DCF!$F$6:$J$6)+(DCF!$J$32*(1+F$7))/($B8-F$7)/(1+$B8)^DCF!$J$6-Assumptions!$D$20)/Assumptions!$D$8 | G8: =(SUMPRODUCT(DCF!$F$32:$J$32,1/(1+$B8)^DCF!$F$6:$J$6)+(DCF!$J$32*(1+G$7))/($B8-G$7)/(1+$B8)^DCF!$J$6-Assumptions!$D$20)/Assumptions!$D$8
B9: =$B$11+(-0.01) | C9: =(SUMPRODUCT(DCF!$F$32:$J$32,1/(1+$B9)^DCF!$F$6:$J$6)+(DCF!$J$32*(1+C$7))/($B9-C$7)/(1+$B9)^DCF!$J$6-Assumptions!$D$20)/Assumptions!$D$8 | D9: =(SUMPRODUCT(DCF!$F$32:$J$32,1/(1+$B9)^DCF!$F$6:$J$6)+(DCF!$J$32*(1+D$7))/($B9-D$7)/(1+$B9)^DCF!$J$6-Assumptions!$D$20)/Assumptions!$D$8 | E9: =(SUMPRODUCT(DCF!$F$32:$J$32,1/(1+$B9)^DCF!$F$6:$J$6)+(DCF!$J$32*(1+E$7))/($B9-E$7)/(1+$B9)^DCF!$J$6-Assumptions!$D$20)/Assumptions!$D$8 | F9: =(SUMPRODUCT(DCF!$F$32:$J$32,1/(1+$B9)^DCF!$F$6:$J$6)+(DCF!$J$32*(1+F$7))/($B9-F$7)/(1+$B9)^DCF!$J$6-Assumptions!$D$20)/Assumptions!$D$8 | G9: =(SUMPRODUCT(DCF!$F$32:$J$32,1/(1+$B9)^DCF!$F$6:$J$6)+(DCF!$J$32*(1+G$7))/($B9-G$7)/(1+$B9)^DCF!$J$6-Assumptions!$D$20)/Assumptions!$D$8
B10: =$B$11+(-0.005) | C10: =(SUMPRODUCT(DCF!$F$32:$J$32,1/(1+$B10)^DCF!$F$6:$J$6)+(DCF!$J$32*(1+C$7))/($B10-C$7)/(1+$B10)^DCF!$J$6-Assumptions!$D$20)/Assumptions!$D$8 | D10: =(SUMPRODUCT(DCF!$F$32:$J$32,1/(1+$B10)^DCF!$F$6:$J$6)+(DCF!$J$32*(1+D$7))/($B10-D$7)/(1+$B10)^DCF!$J$6-Assumptions!$D$20)/Assumptions!$D$8 | E10: =(SUMPRODUCT(DCF!$F$32:$J$32,1/(1+$B10)^DCF!$F$6:$J$6)+(DCF!$J$32*(1+E$7))/($B10-E$7)/(1+$B10)^DCF!$J$6-Assumptions!$D$20)/Assumptions!$D$8 | F10: =(SUMPRODUCT(DCF!$F$32:$J$32,1/(1+$B10)^DCF!$F$6:$J$6)+(DCF!$J$32*(1+F$7))/($B10-F$7)/(1+$B10)^DCF!$J$6-Assumptions!$D$20)/Assumptions!$D$8 | G10: =(SUMPRODUCT(DCF!$F$32:$J$32,1/(1+$B10)^DCF!$F$6:$J$6)+(DCF!$J$32*(1+G$7))/($B10-G$7)/(1+$B10)^DCF!$J$6-Assumptions!$D$20)/Assumptions!$D$8
B11: =WACC!$D$25 | C11: =(SUMPRODUCT(DCF!$F$32:$J$32,1/(1+$B11)^DCF!$F$6:$J$6)+(DCF!$J$32*(1+C$7))/($B11-C$7)/(1+$B11)^DCF!$J$6-Assumptions!$D$20)/Assumptions!$D$8 | D11: =(SUMPRODUCT(DCF!$F$32:$J$32,1/(1+$B11)^DCF!$F$6:$J$6)+(DCF!$J$32*(1+D$7))/($B11-D$7)/(1+$B11)^DCF!$J$6-Assumptions!$D$20)/Assumptions!$D$8 | E11: =(SUMPRODUCT(DCF!$F$32:$J$32,1/(1+$B11)^DCF!$F$6:$J$6)+(DCF!$J$32*(1+E$7))/($B11-E$7)/(1+$B11)^DCF!$J$6-Assumptions!$D$20)/Assumptions!$D$8 | F11: =(SUMPRODUCT(DCF!$F$32:$J$32,1/(1+$B11)^DCF!$F$6:$J$6)+(DCF!$J$32*(1+F$7))/($B11-F$7)/(1+$B11)^DCF!$J$6-Assumptions!$D$20)/Assumptions!$D$8 | G11: =(SUMPRODUCT(DCF!$F$32:$J$32,1/(1+$B11)^DCF!$F$6:$J$6)+(DCF!$J$32*(1+G$7))/($B11-G$7)/(1+$B11)^DCF!$J$6-Assumptions!$D$20)/Assumptions!$D$8
B12: =$B$11+(0.005) | C12: =(SUMPRODUCT(DCF!$F$32:$J$32,1/(1+$B12)^DCF!$F$6:$J$6)+(DCF!$J$32*(1+C$7))/($B12-C$7)/(1+$B12)^DCF!$J$6-Assumptions!$D$20)/Assumptions!$D$8 | D12: =(SUMPRODUCT(DCF!$F$32:$J$32,1/(1+$B12)^DCF!$F$6:$J$6)+(DCF!$J$32*(1+D$7))/($B12-D$7)/(1+$B12)^DCF!$J$6-Assumptions!$D$20)/Assumptions!$D$8 | E12: =(SUMPRODUCT(DCF!$F$32:$J$32,1/(1+$B12)^DCF!$F$6:$J$6)+(DCF!$J$32*(1+E$7))/($B12-E$7)/(1+$B12)^DCF!$J$6-Assumptions!$D$20)/Assumptions!$D$8 | F12: =(SUMPRODUCT(DCF!$F$32:$J$32,1/(1+$B12)^DCF!$F$6:$J$6)+(DCF!$J$32*(1+F$7))/($B12-F$7)/(1+$B12)^DCF!$J$6-Assumptions!$D$20)/Assumptions!$D$8 | G12: =(SUMPRODUCT(DCF!$F$32:$J$32,1/(1+$B12)^DCF!$F$6:$J$6)+(DCF!$J$32*(1+G$7))/($B12-G$7)/(1+$B12)^DCF!$J$6-Assumptions!$D$20)/Assumptions!$D$8
B13: =$B$11+(0.01) | C13: =(SUMPRODUCT(DCF!$F$32:$J$32,1/(1+$B13)^DCF!$F$6:$J$6)+(DCF!$J$32*(1+C$7))/($B13-C$7)/(1+$B13)^DCF!$J$6-Assumptions!$D$20)/Assumptions!$D$8 | D13: =(SUMPRODUCT(DCF!$F$32:$J$32,1/(1+$B13)^DCF!$F$6:$J$6)+(DCF!$J$32*(1+D$7))/($B13-D$7)/(1+$B13)^DCF!$J$6-Assumptions!$D$20)/Assumptions!$D$8 | E13: =(SUMPRODUCT(DCF!$F$32:$J$32,1/(1+$B13)^DCF!$F$6:$J$6)+(DCF!$J$32*(1+E$7))/($B13-E$7)/(1+$B13)^DCF!$J$6-Assumptions!$D$20)/Assumptions!$D$8 | F13: =(SUMPRODUCT(DCF!$F$32:$J$32,1/(1+$B13)^DCF!$F$6:$J$6)+(DCF!$J$32*(1+F$7))/($B13-F$7)/(1+$B13)^DCF!$J$6-Assumptions!$D$20)/Assumptions!$D$8 | G13: =(SUMPRODUCT(DCF!$F$32:$J$32,1/(1+$B13)^DCF!$F$6:$J$6)+(DCF!$J$32*(1+G$7))/($B13-G$7)/(1+$B13)^DCF!$J$6-Assumptions!$D$20)/Assumptions!$D$8
B14: =$B$11+(0.015) | C14: =(SUMPRODUCT(DCF!$F$32:$J$32,1/(1+$B14)^DCF!$F$6:$J$6)+(DCF!$J$32*(1+C$7))/($B14-C$7)/(1+$B14)^DCF!$J$6-Assumptions!$D$20)/Assumptions!$D$8 | D14: =(SUMPRODUCT(DCF!$F$32:$J$32,1/(1+$B14)^DCF!$F$6:$J$6)+(DCF!$J$32*(1+D$7))/($B14-D$7)/(1+$B14)^DCF!$J$6-Assumptions!$D$20)/Assumptions!$D$8 | E14: =(SUMPRODUCT(DCF!$F$32:$J$32,1/(1+$B14)^DCF!$F$6:$J$6)+(DCF!$J$32*(1+E$7))/($B14-E$7)/(1+$B14)^DCF!$J$6-Assumptions!$D$20)/Assumptions!$D$8 | F14: =(SUMPRODUCT(DCF!$F$32:$J$32,1/(1+$B14)^DCF!$F$6:$J$6)+(DCF!$J$32*(1+F$7))/($B14-F$7)/(1+$B14)^DCF!$J$6-Assumptions!$D$20)/Assumptions!$D$8 | G14: =(SUMPRODUCT(DCF!$F$32:$J$32,1/(1+$B14)^DCF!$F$6:$J$6)+(DCF!$J$32*(1+G$7))/($B14-G$7)/(1+$B14)^DCF!$J$6-Assumptions!$D$20)/Assumptions!$D$8
B16: Check: Center Cell − DCF Gordon Implied Price (must = 0.00) | C16: =ROUND(E11-DCF!$D$60,2)
B18: Grid B - Implied Share Price: WACC (rows) × Exit EV/EBITDA Multiple (cols) - Exit Multiple Method
B19: Corner cell = base-case implied price (Exit Multiple), green-linked to DCF!F60
B20: =DCF!$F$60 | C20: =$E$20+(-2.0) | D20: =$E$20+(-1.0) | E20: =Assumptions!$F$33 | F20: =$E$20+(1.0) | G20: =$E$20+(2.0)
B21: =$B$24+(-0.015) | C21: =(SUMPRODUCT(DCF!$F$32:$J$32,1/(1+$B21)^DCF!$F$6:$J$6)+DCF!$J$14*C$20/(1+$B21)^DCF!$J$6-Assumptions!$D$20)/Assumptions!$D$8 | D21: =(SUMPRODUCT(DCF!$F$32:$J$32,1/(1+$B21)^DCF!$F$6:$J$6)+DCF!$J$14*D$20/(1+$B21)^DCF!$J$6-Assumptions!$D$20)/Assumptions!$D$8 | E21: =(SUMPRODUCT(DCF!$F$32:$J$32,1/(1+$B21)^DCF!$F$6:$J$6)+DCF!$J$14*E$20/(1+$B21)^DCF!$J$6-Assumptions!$D$20)/Assumptions!$D$8 | F21: =(SUMPRODUCT(DCF!$F$32:$J$32,1/(1+$B21)^DCF!$F$6:$J$6)+DCF!$J$14*F$20/(1+$B21)^DCF!$J$6-Assumptions!$D$20)/Assumptions!$D$8 | G21: =(SUMPRODUCT(DCF!$F$32:$J$32,1/(1+$B21)^DCF!$F$6:$J$6)+DCF!$J$14*G$20/(1+$B21)^DCF!$J$6-Assumptions!$D$20)/Assumptions!$D$8
B22: =$B$24+(-0.01) | C22: =(SUMPRODUCT(DCF!$F$32:$J$32,1/(1+$B22)^DCF!$F$6:$J$6)+DCF!$J$14*C$20/(1+$B22)^DCF!$J$6-Assumptions!$D$20)/Assumptions!$D$8 | D22: =(SUMPRODUCT(DCF!$F$32:$J$32,1/(1+$B22)^DCF!$F$6:$J$6)+DCF!$J$14*D$20/(1+$B22)^DCF!$J$6-Assumptions!$D$20)/Assumptions!$D$8 | E22: =(SUMPRODUCT(DCF!$F$32:$J$32,1/(1+$B22)^DCF!$F$6:$J$6)+DCF!$J$14*E$20/(1+$B22)^DCF!$J$6-Assumptions!$D$20)/Assumptions!$D$8 | F22: =(SUMPRODUCT(DCF!$F$32:$J$32,1/(1+$B22)^DCF!$F$6:$J$6)+DCF!$J$14*F$20/(1+$B22)^DCF!$J$6-Assumptions!$D$20)/Assumptions!$D$8 | G22: =(SUMPRODUCT(DCF!$F$32:$J$32,1/(1+$B22)^DCF!$F$6:$J$6)+DCF!$J$14*G$20/(1+$B22)^DCF!$J$6-Assumptions!$D$20)/Assumptions!$D$8
B23: =$B$24+(-0.005) | C23: =(SUMPRODUCT(DCF!$F$32:$J$32,1/(1+$B23)^DCF!$F$6:$J$6)+DCF!$J$14*C$20/(1+$B23)^DCF!$J$6-Assumptions!$D$20)/Assumptions!$D$8 | D23: =(SUMPRODUCT(DCF!$F$32:$J$32,1/(1+$B23)^DCF!$F$6:$J$6)+DCF!$J$14*D$20/(1+$B23)^DCF!$J$6-Assumptions!$D$20)/Assumptions!$D$8 | E23: =(SUMPRODUCT(DCF!$F$32:$J$32,1/(1+$B23)^DCF!$F$6:$J$6)+DCF!$J$14*E$20/(1+$B23)^DCF!$J$6-Assumptions!$D$20)/Assumptions!$D$8 | F23: =(SUMPRODUCT(DCF!$F$32:$J$32,1/(1+$B23)^DCF!$F$6:$J$6)+DCF!$J$14*F$20/(1+$B23)^DCF!$J$6-Assumptions!$D$20)/Assumptions!$D$8 | G23: =(SUMPRODUCT(DCF!$F$32:$J$32,1/(1+$B23)^DCF!$F$6:$J$6)+DCF!$J$14*G$20/(1+$B23)^DCF!$J$6-Assumptions!$D$20)/Assumptions!$D$8
B24: =WACC!$D$25 | C24: =(SUMPRODUCT(DCF!$F$32:$J$32,1/(1+$B24)^DCF!$F$6:$J$6)+DCF!$J$14*C$20/(1+$B24)^DCF!$J$6-Assumptions!$D$20)/Assumptions!$D$8 | D24: =(SUMPRODUCT(DCF!$F$32:$J$32,1/(1+$B24)^DCF!$F$6:$J$6)+DCF!$J$14*D$20/(1+$B24)^DCF!$J$6-Assumptions!$D$20)/Assumptions!$D$8 | E24: =(SUMPRODUCT(DCF!$F$32:$J$32,1/(1+$B24)^DCF!$F$6:$J$6)+DCF!$J$14*E$20/(1+$B24)^DCF!$J$6-Assumptions!$D$20)/Assumptions!$D$8 | F24: =(SUMPRODUCT(DCF!$F$32:$J$32,1/(1+$B24)^DCF!$F$6:$J$6)+DCF!$J$14*F$20/(1+$B24)^DCF!$J$6-Assumptions!$D$20)/Assumptions!$D$8 | G24: =(SUMPRODUCT(DCF!$F$32:$J$32,1/(1+$B24)^DCF!$F$6:$J$6)+DCF!$J$14*G$20/(1+$B24)^DCF!$J$6-Assumptions!$D$20)/Assumptions!$D$8
B25: =$B$24+(0.005) | C25: =(SUMPRODUCT(DCF!$F$32:$J$32,1/(1+$B25)^DCF!$F$6:$J$6)+DCF!$J$14*C$20/(1+$B25)^DCF!$J$6-Assumptions!$D$20)/Assumptions!$D$8 | D25: =(SUMPRODUCT(DCF!$F$32:$J$32,1/(1+$B25)^DCF!$F$6:$J$6)+DCF!$J$14*D$20/(1+$B25)^DCF!$J$6-Assumptions!$D$20)/Assumptions!$D$8 | E25: =(SUMPRODUCT(DCF!$F$32:$J$32,1/(1+$B25)^DCF!$F$6:$J$6)+DCF!$J$14*E$20/(1+$B25)^DCF!$J$6-Assumptions!$D$20)/Assumptions!$D$8 | F25: =(SUMPRODUCT(DCF!$F$32:$J$32,1/(1+$B25)^DCF!$F$6:$J$6)+DCF!$J$14*F$20/(1+$B25)^DCF!$J$6-Assumptions!$D$20)/Assumptions!$D$8 | G25: =(SUMPRODUCT(DCF!$F$32:$J$32,1/(1+$B25)^DCF!$F$6:$J$6)+DCF!$J$14*G$20/(1+$B25)^DCF!$J$6-Assumptions!$D$20)/Assumptions!$D$8
B26: =$B$24+(0.01) | C26: =(SUMPRODUCT(DCF!$F$32:$J$32,1/(1+$B26)^DCF!$F$6:$J$6)+DCF!$J$14*C$20/(1+$B26)^DCF!$J$6-Assumptions!$D$20)/Assumptions!$D$8 | D26: =(SUMPRODUCT(DCF!$F$32:$J$32,1/(1+$B26)^DCF!$F$6:$J$6)+DCF!$J$14*D$20/(1+$B26)^DCF!$J$6-Assumptions!$D$20)/Assumptions!$D$8 | E26: =(SUMPRODUCT(DCF!$F$32:$J$32,1/(1+$B26)^DCF!$F$6:$J$6)+DCF!$J$14*E$20/(1+$B26)^DCF!$J$6-Assumptions!$D$20)/Assumptions!$D$8 | F26: =(SUMPRODUCT(DCF!$F$32:$J$32,1/(1+$B26)^DCF!$F$6:$J$6)+DCF!$J$14*F$20/(1+$B26)^DCF!$J$6-Assumptions!$D$20)/Assumptions!$D$8 | G26: =(SUMPRODUCT(DCF!$F$32:$J$32,1/(1+$B26)^DCF!$F$6:$J$6)+DCF!$J$14*G$20/(1+$B26)^DCF!$J$6-Assumptions!$D$20)/Assumptions!$D$8
B27: =$B$24+(0.015) | C27: =(SUMPRODUCT(DCF!$F$32:$J$32,1/(1+$B27)^DCF!$F$6:$J$6)+DCF!$J$14*C$20/(1+$B27)^DCF!$J$6-Assumptions!$D$20)/Assumptions!$D$8 | D27: =(SUMPRODUCT(DCF!$F$32:$J$32,1/(1+$B27)^DCF!$F$6:$J$6)+DCF!$J$14*D$20/(1+$B27)^DCF!$J$6-Assumptions!$D$20)/Assumptions!$D$8 | E27: =(SUMPRODUCT(DCF!$F$32:$J$32,1/(1+$B27)^DCF!$F$6:$J$6)+DCF!$J$14*E$20/(1+$B27)^DCF!$J$6-Assumptions!$D$20)/Assumptions!$D$8 | F27: =(SUMPRODUCT(DCF!$F$32:$J$32,1/(1+$B27)^DCF!$F$6:$J$6)+DCF!$J$14*F$20/(1+$B27)^DCF!$J$6-Assumptions!$D$20)/Assumptions!$D$8 | G27: =(SUMPRODUCT(DCF!$F$32:$J$32,1/(1+$B27)^DCF!$F$6:$J$6)+DCF!$J$14*G$20/(1+$B27)^DCF!$J$6-Assumptions!$D$20)/Assumptions!$D$8
B29: Check: Center Cell − DCF Exit Multiple Implied Price (must = 0.00) | C29: =ROUND(E24-DCF!$F$60,2)
