Workbook

Sheet Cover
B2: NVIDIA Corporation (NVDA) - Discounted Cash Flow Analysis
B3: Prepared by: Akul Veauli | Date: August 23, 2026
B5: This workbook presents a 7-year explicit-period discounted cash flow (DCF) valuation of NVIDIA Corporation (NASDAQ: NVDA). Given NVDA's hypergrowth AI data-center cycle, the model uses a 7-year explicit fade (vs. the standard 5-year template) with fully flexible, explicit driver rows for revenue growth, EBIT margin, D&A, capex and net working capital, allowing the user to stress-test the pace and shape of normalization from cyclically elevated FY2024-26 margins toward a mature terminal state. Terminal value is cross-checked via both the Gordon Growth and Exit Multiple methods.
B8: Color Code Legend
B9: Blue = hardcoded input | C9: 1
B10: Black = formula (same sheet) | C10: =C9*2
B11: Green = link from another tab | C11: =Assumptions!$D$7
B13: Table of Contents
B14: Cover | C14: This tab - overview, key outputs, legend, sources
B15: Assumptions | C15: All blue inputs: valuation setup, balance sheet, NWC build, 7-yr operating drivers, terminal assumptions, rationale
B16: DCF | C16: Historical & projected operating build, UFCF, terminal value (both methods), EV-to-equity bridge
B17: WACC | C17: CAPM cost of equity, cost of debt, capital-structure weights, WACC
B18: Sensitivity | C18: Two live 7×5 sensitivity grids (WACC×g and WACC×exit multiple)
B20: Key Outputs
B21: Implied Share Price - Gordon Growth ($) | C21: =DCF!$D$65
B22: Implied Share Price - Exit Multiple ($) | C22: =DCF!$F$65
B23: Enterprise Value - Gordon ($mm) | C23: =DCF!$D$60
B24: Enterprise Value - Exit Multiple ($mm) | C24: =DCF!$F$60
B25: Actual Share Price, as of Aug 21, 2026 ($) | C25: =DCF!$D$66
B26: Implied Upside / (Downside) - Gordon | C26: =DCF!$D$67
B27: Implied Upside / (Downside) - Exit Multiple | C27: =DCF!$F$67
B28: WACC | C28: =WACC!$D$26
B30: Key Judgment Calls for Reviewer
B31: Terminal value methods diverge materially: Gordon (g=3.0%) implies ~6.8x terminal EV/EBITDA; Exit Multiple (18.0x) implies ~9.9% perpetual growth. Read the $97-$179 implied-price range these methods produce as a genuine uncertainty band for a still-abnormal-margin hypergrowth name at a 7-year horizon (see Assumptions row 48, DCF row 54).
B32: NWC redefinition: the raw Current-Assets − Current-Liabilities figure from the FY2026 10-K is $93.4B (43.3% of revenue) but double-counts NVDA's large cash balance. The model uses Operating NWC (AR+Inv−AP−Accrued) = $28.7B (13.3% of revenue) instead - see Assumptions row 46.
B33: FY2024 D&A ($1.5B, DCF!C14) is a low-confidence estimate, not a directly sourced 10-K figure - see DCF cell note N14.
B34: Revenue growth and EBIT margin fade paths (Assumptions rows 30-31) are the single highest-leverage judgment calls in the model; both are explicit, flexible driver rows designed to be stress-tested directly.
B36: Sources
B37: NVDA FY2024-26 10-Ks (SEC EDGAR); StockAnalysis.com financials; MacroTrends D&A history; FinBox effective tax rate.
B38: GuruFocus / Macroaxis beta (Aug 2026); Yahoo Finance / StockAnalysis market price & shares (as of Aug 21, 2026).
B39: Simply Wall St FY2027 consensus revenue ($391.3B); Trading Economics / CNBC 10Y UST (4.74%, Aug 21, 2026).
B40: Damodaran equity risk premium convention (fallback 5.0% per spec).

Sheet Assumptions
B2: NVIDIA Corporation (NVDA) - DCF Model Assumptions
B3: ($ in millions, except per-share data and %'s; FYE = last Sunday of January)
B5: 1. Valuation Setup
B6: Valuation date | D6: Aug 21, 2026
B7: Actual share price ($) | D7: 216.17 | N7: NVDA close, Aug 21, 2026 (StockAnalysis / Yahoo Finance)
B8: Diluted shares outstanding (mm) | D8: 24220 | N8: Latest cover / 10-Q count, Aug 2026 (~ basic; diluted not materially different)
B9: Fiscal year-end | D9: Last Sunday of January; "FY2026" = year ended Jan 25, 2026 (fiscal label runs ~1 yr ahead of calendar)
B11: 2. Balance Sheet Items (FY2026 10-K, as of Jan 25, 2026)
B12: Cash & cash equivalents + short-term investments ($mm) | D12: 62556 | N12: FY2026 10-K balance sheet (StockAnalysis / SEC EDGAR)
B13: Short-term debt ($mm) | D13: 999 | N13: FY2026 10-K balance sheet (SEC EDGAR): current portion of debt = $999mm (actual reported figure, not a placeholder)
B14: Long-term debt & other long-term obligations ($mm) | D14: 10413 | N14: Plug to reported total debt of $11,412mm (StockAnalysis): FY2026 10-K LT debt $7,469mm + other LT obligations/finance leases ~$2,944mm
B15: Total debt ($mm) | D15: =D13+D14
B16: Minority interest ($mm) | D16: 0
B17: Non-operating investments ($mm) | D17: 0
B18: Net debt / (net cash) ($mm) | D18: =D15-D12 | N18: Negative = net cash position ($51,144mm net cash per FY2026 10-K, consistent with reported figure)
B20: 3. Operating NWC Components - FY2026A Historical Basis
B21: Accounts receivable ($mm) | D21: 38466 | N21: FY2026 10-K balance sheet detail (SEC EDGAR / StockAnalysis)
B22: Inventory ($mm) | D22: 21403
B23: Accounts payable ($mm) | D23: 9812
B24: Accrued & other current liabilities ($mm) | D24: 21352
B25: Operating NWC balance ($mm) = AR + Inv − AP − Accrued | D25: =D21+D22-D23-D24 | N25: See Note (row 46 below): deliberately excludes cash/investments from current assets, unlike the naive 43.3% figure sometimes quoted.
B26: NWC % of FY2026A revenue | D26: =D25/DCF!$E$10
B28: 4. Operating Drivers - FY2027E–FY2033E (7-Year Explicit Fade)
B29: Driver / Fiscal Year | D29: FY2027E | E29: FY2028E | F29: FY2029E | G29: FY2030E | H29: FY2031E | I29: FY2032E | J29: FY2033E
B30: Revenue growth % (fade driver) | D30: 0.8122 | E30: 0.3 | F30: 0.18 | G30: 0.14 | H30: 0.12 | I30: 0.11 | J30: 0.1
B31: EBIT margin % (fade driver) | D31: 0.6 | E31: 0.58 | F31: 0.55 | G31: 0.52 | H31: 0.5 | I31: 0.48 | J31: 0.46
B32: D&A % of revenue | D32: 0.018 | E32: 0.022 | F32: 0.026 | G32: 0.03 | H32: 0.032 | I32: 0.034 | J32: 0.035
B33: Capex % of revenue | D33: 0.04 | E33: 0.045 | F33: 0.045 | G33: 0.04 | H33: 0.038 | I33: 0.035 | J33: 0.035
B34: NWC % of revenue (fade driver) | D34: 0.14 | E34: 0.145 | F34: 0.14 | G34: 0.13 | H34: 0.12 | I34: 0.11 | J34: 0.11 | L34: Terminal year (FY2033E) held FLAT at the prior year's 11.0% rather than continuing the fade: the Gordon perpetuity assumes steady state, and a still-falling NWC ratio in the terminal year produces an artificially low (here, zero) terminal working-capital investment, overstating terminal FCF and TV.
B36: Tax rate (flat, all projection years) | D36: 0.17 | N36: FY2024-26 actual rates 11.3% / 13.6% / 16.6% (discrete IRS benefit rolled off); stabilizing near 16-17%.
B38: 5. Terminal Assumptions
B39: Terminal growth rate (g) | D39: 0.03 | N39: Upper end of spec-allowable range (up to 3.0%) given NVDA's structurally higher secular growth vs. mature mega-caps.
B40: Exit EV/EBITDA multiple | D40: 18 | N40: Approx. large-cap AI-semiconductor multiple; wide sensitivity range applied given valuation dispersion.
B41: Discounting convention | D41: End-of-period discounting throughout (no mid-year convention).
B43: 6. Key Assumption Rationale - Margin, Growth & NWC Normalization
B44: Revenue: FY2027E growth of 81.2% is anchored to consensus revenue of $391.3B (Simply Wall St, Aug 2026); thereafter growth fades steeply (30% → 18% → 14% → 12% → 11% → 10%) as the AI data-center capex supercycle normalizes and year-over-year comparisons become progressively harder. Growth/margin fade reflects normalization of the AI capex cycle.
B45: EBIT margin: FY2024-26 margins of 54.1% / 62.4% / 60.3% reflect a supply-constrained, pricing-power-favorable environment (structural GPU shortage). We fade margins toward the mid-40s% by FY2033E as competition (custom ASICs from hyperscalers, AMD MI-series) and capacity expansion normalize pricing over the cycle. This fade path is a flexible, explicit driver (row 31) - flex it directly to stress bull/bear durability cases.
B46: NWC: a naive Current-Assets-minus-Current-Liabilities calculation on the FY2026 10-K produces $93.4B, or 43.3% of revenue - an unusually high ratio flagged by the data explorer. This naive figure is misleading because NVDA's current assets include its large cash & short-term investments balance; since cash is already captured separately in the EV-to-equity bridge (net debt), including it in NWC would double-count cash. We instead define Operating NWC = AR + Inventory − AP − Accrued liabilities (excludes cash & debt), which is $28.7B, or 13.3% of FY2026A revenue - in line with the semiconductor-peer norm of 10-20% cited by the explorer. Only one historical data point (FY2026) is available; FY2024-25 balance-sheet detail was not sourced, so no historical trend can be shown for this ratio (data limitation, flagged).
B47: D&A / Capex: FY2024 D&A of ~$1.5B (DCF!C14) is a LOW-CONFIDENCE ESTIMATE - not directly sourced from a detailed FY2024 cash-flow statement line, but extrapolated from the FY2025-26 trend (MacroTrends). Use FY2025-26 as the primary historical reference. Capex intensity is projected to rise (data-center infrastructure buildout, 4.0%→4.5% of revenue) before moderating as growth decelerates; the D&A ratio rises with a lag (1.8%→3.5%) to track the capex ramp converting into depreciation over a ~5-6 year asset life.
B48: Terminal value cross-check tension (see DCF rows 39-54): the Gordon Growth method (g=3.0%, WACC~14.6%) implies a terminal EV/EBITDA of only ~6.8x, while the Exit Multiple method (18.0x) implies a terminal growth rate of ~9.9% - far above a credible perpetuity rate. This wide bracket is a genuine, common finding for still-abnormal-margin hypergrowth names at a 7-year horizon and should be read as bounding significant valuation uncertainty, not as a modeling error. See DCF tab note (row 54) and Cover tab 'Key Judgment Calls'.

Sheet DCF
B2: NVIDIA Corporation (NVDA) - Discounted Cash Flow
B3: ($ in millions, except per-share data; FYE = last Sunday of January)
B4: Fiscal-year labels run ~1 year ahead of the calendar year (e.g. "FY2027E" = year ending Jan 2027).
B5: Fiscal Year | C5: FY2024A (Jan-24) | D5: FY2025A (Jan-25) | E5: FY2026A (Jan-26) | F5: FY2027E (Jan-27) | G5: FY2028E (Jan-28) | H5: FY2029E (Jan-29) | I5: FY2030E (Jan-30) | J5: FY2031E (Jan-31) | K5: FY2032E (Jan-32) | L5: FY2033E (Jan-33)
B6: Discount Period | F6: 1 | G6: =F6+1 | H6: =G6+1 | I6: =H6+1 | J6: =I6+1 | K6: =J6+1 | L6: =K6+1
B8: Historical & Projected Operating Build
B9: Revenue growth % | D9: =D10/C10-1 | E9: =E10/D10-1 | F9: =Assumptions!D30 | G9: =Assumptions!E30 | H9: =Assumptions!F30 | I9: =Assumptions!G30 | J9: =Assumptions!H30 | K9: =Assumptions!I30 | L9: =Assumptions!J30
B10: Revenue ($mm) | C10: 60922 | D10: 130497 | E10: 215938 | F10: =E10*(1+F9) | G10: =F10*(1+G9) | H10: =G10*(1+H9) | I10: =H10*(1+I9) | J10: =I10*(1+J9) | K10: =J10*(1+K9) | L10: =K10*(1+L9)
B11: EBIT margin % | C11: =C12/C10 | D11: =D12/D10 | E11: =E12/E10 | F11: =Assumptions!D31 | G11: =Assumptions!E31 | H11: =Assumptions!F31 | I11: =Assumptions!G31 | J11: =Assumptions!H31 | K11: =Assumptions!I31 | L11: =Assumptions!J31
B12: EBIT ($mm) | C12: 32972 | D12: 81453 | E12: 130387 | F12: =F10*F11 | G12: =G10*G11 | H12: =H10*H11 | I12: =I10*I11 | J12: =J10*J11 | K12: =K10*K11 | L12: =L10*L11
B13: D&A % of revenue | C13: =C14/C10 | D13: =D14/D10 | E13: =E14/E10 | F13: =Assumptions!D32 | G13: =Assumptions!E32 | H13: =Assumptions!F32 | I13: =Assumptions!G32 | J13: =Assumptions!H32 | K13: =Assumptions!I32 | L13: =Assumptions!J32
B14: D&A ($mm) | C14: 1511 | D14: 1864 | E14: 2843 | F14: =F10*F13 | G14: =G10*G13 | H14: =H10*H13 | I14: =I10*I13 | J14: =J10*J13 | K14: =K10*K13 | L14: =L10*L13 | N14: LOW-CONFIDENCE ESTIMATE: not directly sourced from FY2024 CF statement; extrapolated from FY2025-26 trend (MacroTrends). Use FY2025-26 as primary reference.
B15: EBITDA ($mm) | C15: =C12+C14 | D15: =D12+D14 | E15: =E12+E14 | F15: =F12+F14 | G15: =G12+G14 | H15: =H12+H14 | I15: =I12+I14 | J15: =J12+J14 | ... L15: =L12+L14
B16: Capex % of revenue | C16: =C17/C10 | D16: =D17/D10 | E16: =E17/E10 | F16: =Assumptions!D33 | G16: =Assumptions!E33 | H16: =Assumptions!F33 | I16: =Assumptions!G33 | J16: =Assumptions!H33 | K16: =Assumptions!I33 | L16: =Assumptions!J33
B17: Less: Capex ($mm) | C17: 1069 | D17: 3236 | E17: 6042 | F17: =F10*F16 | G17: =G10*G16 | H17: =H10*H16 | I17: =I10*I16 | J17: =J10*J16 | K17: =K10*K16 | L17: =L10*L16
B18: Operating Net Working Capital (excl. cash & debt - see Assumptions note 46)
B19: Accounts receivable ($mm) | C19: n/a | D19: n/a | E19: =Assumptions!$D$21
B20: Inventory ($mm) | C20: n/a | D20: n/a | E20: =Assumptions!$D$22
B21: Less: Accounts payable ($mm) | C21: n/a | D21: n/a | E21: =Assumptions!$D$23
B22: Less: Accrued & other current liabilities ($mm) | C22: n/a | D22: n/a | E22: =Assumptions!$D$24
B23: NWC % of revenue | C23: n/a | D23: n/a | E23: =Assumptions!$D$26 | F23: =Assumptions!D34 | G23: =Assumptions!E34 | H23: =Assumptions!F34 | I23: =Assumptions!G34 | J23: =Assumptions!H34 | K23: =Assumptions!I34 | L23: =Assumptions!J34
B24: Operating NWC balance ($mm) | C24: n/a | D24: n/a | E24: =Assumptions!$D$25 | F24: =F10*F23 | G24: =G10*G23 | H24: =H10*H23 | I24: =I10*I23 | J24: =J10*J23 | K24: =K10*K23 | L24: =L10*L23
B25: (Increase) / decrease in NWC - Δ NWC ($mm) | F25: =F24-E24 | G25: =G24-F24 | H25: =H24-G24 | I25: =I24-H24 | J25: =J24-I24 | K25: =K24-J24 | L25: =L24-K24
B27: Unlevered Free Cash Flow Build (FY2027E–FY2033E)
B28: EBIT ($mm) | F28: =F12 | G28: =G12 | H28: =H12 | I28: =I12 | J28: =J12 | K28: =K12 | L28: =L12
B29: Less: Cash taxes | F29: =F28*Assumptions!$D$36 | G29: =G28*Assumptions!$D$36 | H29: =H28*Assumptions!$D$36 | I29: =I28*Assumptions!$D$36 | J29: =J28*Assumptions!$D$36 | K29: =K28*Assumptions!$D$36 | L29: =L28*Assumptions!$D$36
B30: NOPAT | F30: =F28-F29 | G30: =G28-G29 | H30: =H28-H29 | I30: =I28-I29 | J30: =J28-J29 | K30: =K28-K29 | L30: =L28-L29
B31: Plus: D&A | F31: =F14 | G31: =G14 | H31: =H14 | I31: =I14 | J31: =J14 | K31: =K14 | L31: =L14
B32: Less: Capex | F32: =F17 | G32: =G17 | H32: =H17 | I32: =I17 | J32: =J17 | K32: =K17 | L32: =L17
B33: Less: Δ NWC | F33: =F25 | G33: =G25 | H33: =H25 | I33: =I25 | J33: =J25 | K33: =K25 | L33: =L25
B34: Unlevered Free Cash Flow ($mm) | F34: =F30+F31-F32-F33 | G34: =G30+G31-G32-G33 | H34: =H30+H31-H32-H33 | I34: =I30+I31-I32-I33 | J34: =J30+J31-J32-J33 | K34: =K30+K31-K32-K33 | L34: =L30+L31-L32-L33
B35: PV factor @ WACC | F35: =1/(1+WACC!$D$26)^F6 | G35: =1/(1+WACC!$D$26)^G6 | H35: =1/(1+WACC!$D$26)^H6 | I35: =1/(1+WACC!$D$26)^I6 | J35: =1/(1+WACC!$D$26)^J6 | K35: =1/(1+WACC!$D$26)^K6 | L35: =1/(1+WACC!$D$26)^L6
B36: PV of Unlevered FCF ($mm) | F36: =F34*F35 | G36: =G34*G35 | H36: =H34*H35 | I36: =I34*I35 | J36: =J34*J35 | K36: =K34*K35 | L36: =L34*L35
B37: Cumulative PV of Explicit FCF (FY2027E–FY2033E) | D37: =SUM(F36:L36)
B39: Terminal Value - Gordon Growth Method
B40: Terminal-year Unlevered FCF ($mm) | D40: =L34
B41: Terminal growth rate (g) | D41: =Assumptions!$D$39
B42: WACC | D42: =WACC!$D$26
B43: Terminal Value (Gordon) ($mm) | D43: =D40*(1+D41)/(D42-D41)
B44: PV of Terminal Value (Gordon) ($mm) | D44: =D43/(1+D42)^L6
...

Sheet WACC
B2: NVIDIA Corporation (NVDA) - WACC Build
B3: (CAPM cost of equity; rates in %)
B5: Cost of Equity (CAPM)
B6: Risk-free rate (10Y UST) | D6: 0.0474 | F6: As of Aug 21, 2026 (Trading Economics / CNBC)
B7: Levered beta | D7: 1.98 | F7: Current 5Y-monthly beta, Aug 2026 (GuruFocus 1.98 / Macroaxis 2.21); spec fallback 1.70 if unavailable
B8: Equity risk premium | D8: 0.05 | F8: Damodaran / Duff & Phelps convention; spec fallback 5.0%
B9: Cost of equity = rf + β × ERP | D9: =D6+D7*D8
B11: Cost of Debt
B12: Pre-tax cost of debt | D12: 0.055 | F12: Estimated single-A credit spread over 10Y UST; NVDA carries minimal debt ($11.4B) with no actively traded benchmark bond used for a precise YTM.
B13: Tax rate | D13: =Assumptions!$D$36
B14: After-tax cost of debt | D14: =D12*(1-D13)
B16: Capital Structure Weights
B17: Share price ($) | D17: =Assumptions!$D$7
B18: Diluted shares (mm) | D18: =Assumptions!$D$8
B19: Market capitalization ($mm) | D19: =D17*D18
B20: Total debt ($mm) | D20: =Assumptions!$D$15
B21: Total capital ($mm) | D21: =D19+D20
B22: E / (D+E) | D22: =D19/D21
B23: D / (D+E) | D23: =D20/D21
B25: WACC
B26: WACC = E/(D+E)×Ke + D/(D+E)×Kd(after-tax) | D26: =D22*D9+D23*D14
B27: WACC sanity note | D27: NVDA is ~99.8% equity-financed; WACC is effectively the CAPM cost of equity given negligible net leverage.

Sheet Sensitivity
B2: NVIDIA Corporation (NVDA) - DCF Sensitivity Grids
B3: (Algebraic re-derivation per cell; fully live; end-of-period discounting; $ = implied share price)
B5: Grid A - WACC (rows) × Terminal Growth g (cols) → Implied Share Price (Gordon Growth)
B6: Each cell rebuilds EV/equity live from DCF!$F$34:$L$34 (explicit UFCF) and Gordon TV using the row's WACC and column's g. Corner cell (C7) ties to the base-case Gordon price on the DCF tab.
B7: WACC \ g | C7: =DCF!$D$65 | D7: =F7-0.01 | E7: =F7-0.005 | F7: =Assumptions!$D$39 | G7: =F7+0.005 | H7: =F7+0.01
C8: =$C$11-0.015 | D8: =(SUMPRODUCT(DCF!$F$34:$L$34,1/(1+$C8)^DCF!$F$6:$L$6)+(DCF!$L$34*(1+D$7))/($C8-D$7)/(1+$C8)^DCF!$L$6-DCF!$D$61)/DCF!$D$64 | E8: =(SUMPRODUCT(DCF!$F$34:$L$34,1/(1+$C8)^DCF!$F$6:$L$6)+(DCF!$L$34*(1+E$7))/($C8-E$7)/(1+$C8)^DCF!$L$6-DCF!$D$61)/DCF!$D$64 | F8: =(SUMPRODUCT(DCF!$F$34:$L$34,1/(1+$C8)^DCF!$F$6:$L$6)+(DCF!$L$34*(1+F$7))/($C8-F$7)/(1+$C8)^DCF!$L$6-DCF!$D$61)/DCF!$D$64 | G8: =(SUMPRODUCT(DCF!$F$34:$L$34,1/(1+$C8)^DCF!$F$6:$L$6)+(DCF!$L$34*(1+G$7))/($C8-G$7)/(1+$C8)^DCF!$L$6-DCF!$D$61)/DCF!$D$64 | H8: =(SUMPRODUCT(DCF!$F$34:$L$34,1/(1+$C8)^DCF!$F$6:$L$6)+(DCF!$L$34*(1+H$7))/($C8-H$7)/(1+$C8)^DCF!$L$6-DCF!$D$61)/DCF!$D$64
C9: =$C$11-0.01 | D9: =(SUMPRODUCT(DCF!$F$34:$L$34,1/(1+$C9)^DCF!$F$6:$L$6)+(DCF!$L$34*(1+D$7))/($C9-D$7)/(1+$C9)^DCF!$L$6-DCF!$D$61)/DCF!$D$64 | E9: =(SUMPRODUCT(DCF!$F$34:$L$34,1/(1+$C9)^DCF!$F$6:$L$6)+(DCF!$L$34*(1+E$7))/($C9-E$7)/(1+$C9)^DCF!$L$6-DCF!$D$61)/DCF!$D$64 | F9: =(SUMPRODUCT(DCF!$F$34:$L$34,1/(1+$C9)^DCF!$F$6:$L$6)+(DCF!$L$34*(1+F$7))/($C9-F$7)/(1+$C9)^DCF!$L$6-DCF!$D$61)/DCF!$D$64 | G9: =(SUMPRODUCT(DCF!$F$34:$L$34,1/(1+$C9)^DCF!$F$6:$L$6)+(DCF!$L$34*(1+G$7))/($C9-G$7)/(1+$C9)^DCF!$L$6-DCF!$D$61)/DCF!$D$64 | H9: =(SUMPRODUCT(DCF!$F$34:$L$34,1/(1+$C9)^DCF!$F$6:$L$6)+(DCF!$L$34*(1+H$7))/($C9-H$7)/(1+$C9)^DCF!$L$6-DCF!$D$61)/DCF!$D$64
C10: =$C$11-0.005 | D10: =(SUMPRODUCT(DCF!$F$34:$L$34,1/(1+$C10)^DCF!$F$6:$L$6)+(DCF!$L$34*(1+D$7))/($C10-D$7)/(1+$C10)^DCF!$L$6-DCF!$D$61)/DCF!$D$64 | E10: =(SUMPRODUCT(DCF!$F$34:$L$34,1/(1+$C10)^DCF!$F$6:$L$6)+(DCF!$L$34*(1+E$7))/($C10-E$7)/(1+$C10)^DCF!$L$6-DCF!$D$61)/DCF!$D$64 | F10: =(SUMPRODUCT(DCF!$F$34:$L$34,1/(1+$C10)^DCF!$F$6:$L$6)+(DCF!$L$34*(1+F$7))/($C10-F$7)/(1+$C10)^DCF!$L$6-DCF!$D$61)/DCF!$D$64 | G10: =(SUMPRODUCT(DCF!$F$34:$L$34,1/(1+$C10)^DCF!$F$6:$L$6)+(DCF!$L$34*(1+G$7))/($C10-G$7)/(1+$C10)^DCF!$L$6-DCF!$D$61)/DCF!$D$64 | H10: =(SUMPRODUCT(DCF!$F$34:$L$34,1/(1+$C10)^DCF!$F$6:$L$6)+(DCF!$L$34*(1+H$7))/($C10-H$7)/(1+$C10)^DCF!$L$6-DCF!$D$61)/DCF!$D$64
C11: =WACC!$D$26 | D11: =(SUMPRODUCT(DCF!$F$34:$L$34,1/(1+$C11)^DCF!$F$6:$L$6)+(DCF!$L$34*(1+D$7))/($C11-D$7)/(1+$C11)^DCF!$L$6-DCF!$D$61)/DCF!$D$64 | E11: =(SUMPRODUCT(DCF!$F$34:$L$34,1/(1+$C11)^DCF!$F$6:$L$6)+(DCF!$L$34*(1+E$7))/($C11-E$7)/(1+$C11)^DCF!$L$6-DCF!$D$61)/DCF!$D$64 | F11: =(SUMPRODUCT(DCF!$F$34:$L$34,1/(1+$C11)^DCF!$F$6:$L$6)+(DCF!$L$34*(1+F$7))/($C11-F$7)/(1+$C11)^DCF!$L$6-DCF!$D$61)/DCF!$D$64 | G11: =(SUMPRODUCT(DCF!$F$34:$L$34,1/(1+$C11)^DCF!$F$6:$L$6)+(DCF!$L$34*(1+G$7))/($C11-G$7)/(1+$C11)^DCF!$L$6-DCF!$D$61)/DCF!$D$64 | H11: =(SUMPRODUCT(DCF!$F$34:$L$34,1/(1+$C11)^DCF!$F$6:$L$6)+(DCF!$L$34*(1+H$7))/($C11-H$7)/(1+$C11)^DCF!$L$6-DCF!$D$61)/DCF!$D$64
C12: =$C$11+0.005 | D12: =(SUMPRODUCT(DCF!$F$34:$L$34,1/(1+$C12)^DCF!$F$6:$L$6)+(DCF!$L$34*(1+D$7))/($C12-D$7)/(1+$C12)^DCF!$L$6-DCF!$D$61)/DCF!$D$64 | E12: =(SUMPRODUCT(DCF!$F$34:$L$34,1/(1+$C12)^DCF!$F$6:$L$6)+(DCF!$L$34*(1+E$7))/($C12-E$7)/(1+$C12)^DCF!$L$6-DCF!$D$61)/DCF!$D$64 | F12: =(SUMPRODUCT(DCF!$F$34:$L$34,1/(1+$C12)^DCF!$F$6:$L$6)+(DCF!$L$34*(1+F$7))/($C12-F$7)/(1+$C12)^DCF!$L$6-DCF!$D$61)/DCF!$D$64 | G12: =(SUMPRODUCT(DCF!$F$34:$L$34,1/(1+$C12)^DCF!$F$6:$L$6)+(DCF!$L$34*(1+G$7))/($C12-G$7)/(1+$C12)^DCF!$L$6-DCF!$D$61)/DCF!$D$64 | H12: =(SUMPRODUCT(DCF!$F$34:$L$34,1/(1+$C12)^DCF!$F$6:$L$6)+(DCF!$L$34*(1+H$7))/($C12-H$7)/(1+$C12)^DCF!$L$6-DCF!$D$61)/DCF!$D$64
C13: =$C$11+0.01 | D13: =(SUMPRODUCT(DCF!$F$34:$L$34,1/(1+$C13)^DCF!$F$6:$L$6)+(DCF!$L$34*(1+D$7))/($C13-D$7)/(1+$C13)^DCF!$L$6-DCF!$D$61)/DCF!$D$64 | E13: =(SUMPRODUCT(DCF!$F$34:$L$34,1/(1+$C13)^DCF!$F$6:$L$6)+(DCF!$L$34*(1+E$7))/($C13-E$7)/(1+$C13)^DCF!$L$6-DCF!$D$61)/DCF!$D$64 | F13: =(SUMPRODUCT(DCF!$F$34:$L$34,1/(1+$C13)^DCF!$F$6:$L$6)+(DCF!$L$34*(1+F$7))/($C13-F$7)/(1+$C13)^DCF!$L$6-DCF!$D$61)/DCF!$D$64 | G13: =(SUMPRODUCT(DCF!$F$34:$L$34,1/(1+$C13)^DCF!$F$6:$L$6)+(DCF!$L$34*(1+G$7))/($C13-G$7)/(1+$C13)^DCF!$L$6-DCF!$D$61)/DCF!$D$64 | H13: =(SUMPRODUCT(DCF!$F$34:$L$34,1/(1+$C13)^DCF!$F$6:$L$6)+(DCF!$L$34*(1+H$7))/($C13-H$7)/(1+$C13)^DCF!$L$6-DCF!$D$61)/DCF!$D$64
C14: =$C$11+0.015 | D14: =(SUMPRODUCT(DCF!$F$34:$L$34,1/(1+$C14)^DCF!$F$6:$L$6)+(DCF!$L$34*(1+D$7))/($C14-D$7)/(1+$C14)^DCF!$L$6-DCF!$D$61)/DCF!$D$64 | E14: =(SUMPRODUCT(DCF!$F$34:$L$34,1/(1+$C14)^DCF!$F$6:$L$6)+(DCF!$L$34*(1+E$7))/($C14-E$7)/(1+$C14)^DCF!$L$6-DCF!$D$61)/DCF!$D$64 | F14: =(SUMPRODUCT(DCF!$F$34:$L$34,1/(1+$C14)^DCF!$F$6:$L$6)+(DCF!$L$34*(1+F$7))/($C14-F$7)/(1+$C14)^DCF!$L$6-DCF!$D$61)/DCF!$D$64 | G14: =(SUMPRODUCT(DCF!$F$34:$L$34,1/(1+$C14)^DCF!$F$6:$L$6)+(DCF!$L$34*(1+G$7))/($C14-G$7)/(1+$C14)^DCF!$L$6-DCF!$D$61)/DCF!$D$64 | H14: =(SUMPRODUCT(DCF!$F$34:$L$34,1/(1+$C14)^DCF!$F$6:$L$6)+(DCF!$L$34*(1+H$7))/($C14-H$7)/(1+$C14)^DCF!$L$6-DCF!$D$61)/DCF!$D$64
B16: Check: center cell − DCF base case (must be 0.00) | D16: =ROUND(F11-DCF!$D$65,2)
B18: Grid B - WACC (rows) × Exit EV/EBITDA Multiple (cols) → Implied Share Price (Exit Multiple)
B19: Each cell rebuilds EV/equity live from DCF!$F$34:$L$34 and terminal EBITDA (DCF!$L$15) × the column's exit multiple. Corner cell (C20) ties to the base-case exit-multiple price on the DCF tab.
B20: WACC \ Multiple | C20: =DCF!$F$65 | D20: =F20-4 | E20: =F20-2 | F20: =Assumptions!$D$40 | G20: =F20+2 | H20: =F20+4
C21: =$C$24-0.015 | D21: =(SUMPRODUCT(DCF!$F$34:$L$34,1/(1+$C21)^DCF!$F$6:$L$6)+(DCF!$L$15*D$20)/(1+$C21)^DCF!$L$6-DCF!$D$61)/DCF!$D$64 | E21: =(SUMPRODUCT(DCF!$F$34:$L$34,1/(1+$C21)^DCF!$F$6:$L$6)+(DCF!$L$15*E$20)/(1+$C21)^DCF!$L$6-DCF!$D$61)/DCF!$D$64 | F21: =(SUMPRODUCT(DCF!$F$34:$L$34,1/(1+$C21)^DCF!$F$6:$L$6)+(DCF!$L$15*F$20)/(1+$C21)^DCF!$L$6-DCF!$D$61)/DCF!$D$64 | G21: =(SUMPRODUCT(DCF!$F$34:$L$34,1/(1+$C21)^DCF!$F$6:$L$6)+(DCF!$L$15*G$20)/(1+$C21)^DCF!$L$6-DCF!$D$61)/DCF!$D$64 | H21: =(SUMPRODUCT(DCF!$F$34:$L$34,1/(1+$C21)^DCF!$F$6:$L$6)+(DCF!$L$15*H$20)/(1+$C21)^DCF!$L$6-DCF!$D$61)/DCF!$D$64
C22: =$C$24-0.01 | D22: =(SUMPRODUCT(DCF!$F$34:$L$34,1/(1+$C22)^DCF!$F$6:$L$6)+(DCF!$L$15*D$20)/(1+$C22)^DCF!$L$6-DCF!$D$61)/DCF!$D$64 | E22: =(SUMPRODUCT(DCF!$F$34:$L$34,1/(1+$C22)^DCF!$F$6:$L$6)+(DCF!$L$15*E$20)/(1+$C22)^DCF!$L$6-DCF!$D$61)/DCF!$D$64 | F22: =(SUMPRODUCT(DCF!$F$34:$L$34,1/(1+$C22)^DCF!$F$6:$L$6)+(DCF!$L$15*F$20)/(1+$C22)^DCF!$L$6-DCF!$D$61)/DCF!$D$64 | G22: =(SUMPRODUCT(DCF!$F$34:$L$34,1/(1+$C22)^DCF!$F$6:$L$6)+(DCF!$L$15*G$20)/(1+$C22)^DCF!$L$6-DCF!$D$61)/DCF!$D$64 | H22: =(SUMPRODUCT(DCF!$F$34:$L$34,1/(1+$C22)^DCF!$F$6:$L$6)+(DCF!$L$15*H$20)/(1+$C22)^DCF!$L$6-DCF!$D$61)/DCF!$D$64
C23: =$C$24-0.005 | D23: =(SUMPRODUCT(DCF!$F$34:$L$34,1/(1+$C23)^DCF!$F$6:$L$6)+(DCF!$L$15*D$20)/(1+$C23)^DCF!$L$6-DCF!$D$61)/DCF!$D$64 | E23: =(SUMPRODUCT(DCF!$F$34:$L$34,1/(1+$C23)^DCF!$F$6:$L$6)+(DCF!$L$15*E$20)/(1+$C23)^DCF!$L$6-DCF!$D$61)/DCF!$D$64 | F23: =(SUMPRODUCT(DCF!$F$34:$L$34,1/(1+$C23)^DCF!$F$6:$L$6)+(DCF!$L$15*F$20)/(1+$C23)^DCF!$L$6-DCF!$D$61)/DCF!$D$64 | G23: =(SUMPRODUCT(DCF!$F$34:$L$34,1/(1+$C23)^DCF!$F$6:$L$6)+(DCF!$L$15*G$20)/(1+$C23)^DCF!$L$6-DCF!$D$61)/DCF!$D$64 | H23: =(SUMPRODUCT(DCF!$F$34:$L$34,1/(1+$C23)^DCF!$F$6:$L$6)+(DCF!$L$15*H$20)/(1+$C23)^DCF!$L$6-DCF!$D$61)/DCF!$D$64
C24: =WACC!$D$26 | D24: =(SUMPRODUCT(DCF!$F$34:$L$34,1/(1+$C24)^DCF!$F$6:$L$6)+(DCF!$L$15*D$20)/(1+$C24)^DCF!$L$6-DCF!$D$61)/DCF!$D$64 | E24: =(SUMPRODUCT(DCF!$F$34:$L$34,1/(1+$C24)^DCF!$F$6:$L$6)+(DCF!$L$15*E$20)/(1+$C24)^DCF!$L$6-DCF!$D$61)/DCF!$D$64 | F24: =(SUMPRODUCT(DCF!$F$34:$L$34,1/(1+$C24)^DCF!$F$6:$L$6)+(DCF!$L$15*F$20)/(1+$C24)^DCF!$L$6-DCF!$D$61)/DCF!$D$64 | G24: =(SUMPRODUCT(DCF!$F$34:$L$34,1/(1+$C24)^DCF!$F$6:$L$6)+(DCF!$L$15*G$20)/(1+$C24)^DCF!$L$6-DCF!$D$61)/DCF!$D$64 | H24: =(SUMPRODUCT(DCF!$F$34:$L$34,1/(1+$C24)^DCF!$F$6:$L$6)+(DCF!$L$15*H$20)/(1+$C24)^DCF!$L$6-DCF!$D$61)/DCF!$D$64
C25: =$C$24+0.005 | D25: =(SUMPRODUCT(DCF!$F$34:$L$34,1/(1+$C25)^DCF!$F$6:$L$6)+(DCF!$L$15*D$20)/(1+$C25)^DCF!$L$6-DCF!$D$61)/DCF!$D$64 | E25: =(SUMPRODUCT(DCF!$F$34:$L$34,1/(1+$C25)^DCF!$F$6:$L$6)+(DCF!$L$15*E$20)/(1+$C25)^DCF!$L$6-DCF!$D$61)/DCF!$D$64 | F25: =(SUMPRODUCT(DCF!$F$34:$L$34,1/(1+$C25)^DCF!$F$6:$L$6)+(DCF!$L$15*F$20)/(1+$C25)^DCF!$L$6-DCF!$D$61)/DCF!$D$64 | G25: =(SUMPRODUCT(DCF!$F$34:$L$34,1/(1+$C25)^DCF!$F$6:$L$6)+(DCF!$L$15*G$20)/(1+$C25)^DCF!$L$6-DCF!$D$61)/DCF!$D$64 | H25: =(SUMPRODUCT(DCF!$F$34:$L$34,1/(1+$C25)^DCF!$F$6:$L$6)+(DCF!$L$15*H$20)/(1+$C25)^DCF!$L$6-DCF!$D$61)/DCF!$D$64
C26: =$C$24+0.01 | D26: =(SUMPRODUCT(DCF!$F$34:$L$34,1/(1+$C26)^DCF!$F$6:$L$6)+(DCF!$L$15*D$20)/(1+$C26)^DCF!$L$6-DCF!$D$61)/DCF!$D$64 | E26: =(SUMPRODUCT(DCF!$F$34:$L$34,1/(1+$C26)^DCF!$F$6:$L$6)+(DCF!$L$15*E$20)/(1+$C26)^DCF!$L$6-DCF!$D$61)/DCF!$D$64 | F26: =(SUMPRODUCT(DCF!$F$34:$L$34,1/(1+$C26)^DCF!$F$6:$L$6)+(DCF!$L$15*F$20)/(1+$C26)^DCF!$L$6-DCF!$D$61)/DCF!$D$64 | G26: =(SUMPRODUCT(DCF!$F$34:$L$34,1/(1+$C26)^DCF!$F$6:$L$6)+(DCF!$L$15*G$20)/(1+$C26)^DCF!$L$6-DCF!$D$61)/DCF!$D$64 | H26: =(SUMPRODUCT(DCF!$F$34:$L$34,1/(1+$C26)^DCF!$F$6:$L$6)+(DCF!$L$15*H$20)/(1+$C26)^DCF!$L$6-DCF!$D$61)/DCF!$D$64
C27: =$C$24+0.015 | D27: =(SUMPRODUCT(DCF!$F$34:$L$34,1/(1+$C27)^DCF!$F$6:$L$6)+(DCF!$L$15*D$20)/(1+$C27)^DCF!$L$6-DCF!$D$61)/DCF!$D$64 | E27: =(SUMPRODUCT(DCF!$F$34:$L$34,1/(1+$C27)^DCF!$F$6:$L$6)+(DCF!$L$15*E$20)/(1+$C27)^DCF!$L$6-DCF!$D$61)/DCF!$D$64 | F27: =(SUMPRODUCT(DCF!$F$34:$L$34,1/(1+$C27)^DCF!$F$6:$L$6)+(DCF!$L$15*F$20)/(1+$C27)^DCF!$L$6-DCF!$D$61)/DCF!$D$64 | G27: =(SUMPRODUCT(DCF!$F$34:$L$34,1/(1+$C27)^DCF!$F$6:$L$6)+(DCF!$L$15*G$20)/(1+$C27)^DCF!$L$6-DCF!$D$61)/DCF!$D$64 | H27: =(SUMPRODUCT(DCF!$F$34:$L$34,1/(1+$C27)^DCF!$F$6:$L$6)+(DCF!$L$15*H$20)/(1+$C27)^DCF!$L$6-DCF!$D$61)/DCF!$D$64
B29: Check: center cell − DCF base case (must be 0.00) | D29: =ROUND(F24-DCF!$F$65,2)
