Workbook
Name Company_Name: [1]DCF!$C$3

Sheet Income Statement
A1: Income Statement | B1: Ledgers | C1: 2011 | D1: 2012 | E1: 2013 | F1: 2014 | G1: 2015 | H1: - | I1: 2016 | J1: 2017 | K1: 2018 | L1: 2019 | M1: 2020
A3: Revenue | C3: Historical Period | I3: Projection period | Z3: graph
B4: ESC licence | C4: ='5b. Forecasts and Assumptions'!D5 -> 878220 | D4: ='5b. Forecasts and Assumptions'!E5 -> 1400064.8 | E4: ='5b. Forecasts and Assumptions'!F5 -> 1747657.8 | F4: ='5b. Forecasts and Assumptions'!G5 -> 1526175 | G4: ='5b. Forecasts and Assumptions'!H5 -> 1481996.2 | I4: ='5b. Forecasts and Assumptions'!I5 -> 1645492.3 | J4: ='5b. Forecasts and Assumptions'!J5 -> 1827025.5 | K4: ='5b. Forecasts and Assumptions'!K5 -> 2028585.8 | L4: ='5b. Forecasts and Assumptions'!L5 -> 2252382.4 | M4: ='5b. Forecasts and Assumptions'!M5 -> 2500868.7
B5: ESC accounting | C5: ='5b. Forecasts and Assumptions'!D6 -> 11913.156 | D5: ='5b. Forecasts and Assumptions'!E6 -> 80894.448 | E5: ='5b. Forecasts and Assumptions'!F6 -> 192392.53 | F5: ='5b. Forecasts and Assumptions'!G6 -> 521443.12 | G5: ='5b. Forecasts and Assumptions'!H6 -> 472653.72 | I5: ='5b. Forecasts and Assumptions'!I6 -> 564042.36 | J5: ='5b. Forecasts and Assumptions'!J6 -> 673101.19 | K5: ='5b. Forecasts and Assumptions'!K6 -> 803246.79 | L5: ='5b. Forecasts and Assumptions'!L6 -> 958556.33 | M5: ='5b. Forecasts and Assumptions'!M6 -> 1143895.3 | AA5: 0 | AB5: 1 | AC5: 2 | AD5: 3 | AE5: 4 | AF5: 5
B6: ESC maintenance | C6: ='5b. Forecasts and Assumptions'!D7 -> 2816730 | D6: ='5b. Forecasts and Assumptions'!E7 -> 2875635 | E6: ='5b. Forecasts and Assumptions'!F7 -> 3025575 | F6: ='5b. Forecasts and Assumptions'!G7 -> 3132675 | G6: ='5b. Forecasts and Assumptions'!H7 -> 3213000 | I6: ='5b. Forecasts and Assumptions'!I7 -> 3298707.6 | J6: ='5b. Forecasts and Assumptions'!J7 -> 3386701.6 | K6: ='5b. Forecasts and Assumptions'!K7 -> 3477042.7 | L6: ='5b. Forecasts and Assumptions'!L7 -> 3569793.8 | M6: ='5b. Forecasts and Assumptions'!M7 -> 3665019 | AA6: =G22 -> 3017554.1 | AB6: =I22 -> 3286596.8 | AC6: =J22 -> 4225351.3 | AD6: =K22 -> 4995287.8 | AE6: =L22 -> 5980202.5 | AF6: =M22 -> 7242363.1
B7: ESC one-time training | C7: ='5b. Forecasts and Assumptions'!D8 -> 134577.4 | D7: ='5b. Forecasts and Assumptions'!E8 -> 194847.55 | E7: ='5b. Forecasts and Assumptions'!F8 -> 270085.62 | F7: ='5b. Forecasts and Assumptions'!G8 -> 290624.05 | G7: ='5b. Forecasts and Assumptions'!H8 -> 363220.98 | I7: ='5b. Forecasts and Assumptions'!I8 -> 443007.1 | J7: ='5b. Forecasts and Assumptions'!J8 -> 540319.25 | K7: ='5b. Forecasts and Assumptions'!K8 -> 563223.66 | L7: ='5b. Forecasts and Assumptions'!L8 -> 587098.99 | M7: ='5b. Forecasts and Assumptions'!M8 -> 611986.41
B8: ESC mobile | C8: ='5b. Forecasts and Assumptions'!D9 -> 137599.5 | D8: ='5b. Forecasts and Assumptions'!E9 -> 352450.95 | E8: ='5b. Forecasts and Assumptions'!F9 -> 843574.51 | F8: ='5b. Forecasts and Assumptions'!G9 -> 1344867 | G8: ='5b. Forecasts and Assumptions'!H9 -> 1758684.7 | I8: ='5b. Forecasts and Assumptions'!I9 -> 2251116.4 | J8: ='5b. Forecasts and Assumptions'!J9 -> 2881429 | K8: ='5b. Forecasts and Assumptions'!K9 -> 3688229.2 | L8: ='5b. Forecasts and Assumptions'!L9 -> 4720933.3 | M8: ='5b. Forecasts and Assumptions'!M9 -> 6042794.7
B9: Total revenue | C9: =SUM(C4:C8) -> 3979040.1 | D9: =SUM(D4:D8) -> 4903892.7 | E9: =SUM(E4:E8) -> 6079285.5 | F9: =SUM(F4:F8) -> 6815784.2 | G9: =SUM(G4:G8) -> 7289555.7 | I9: =SUM(I4:I8) -> 8202365.9 | J9: =SUM(J4:J8) -> 9308576.6 | K9: =SUM(K4:K8) -> 10560328 | L9: =SUM(L4:L8) -> 12088765 | M9: =SUM(M4:M8) -> 13964564
D10: 0.2324311 | E10: 0.23968566 | F10: 0.12114889 | G10: 0.069510929 | I10: =+(I9/G9)-1 -> 0.12522165 | J10: =+(J9/I9)-1 -> 0.13486484 | K10: =+(K9/J9)-1 -> 0.13447293 | L10: =+(L9/K9)-1 -> 0.14473383 | M10: =+(M9/L9)-1 -> 0.1551688
A11: Expenses
B12: Support salaries | C12: ='5b. Forecasts and Assumptions'!D13 -> 603269.36 | D12: ='5b. Forecasts and Assumptions'!E13 -> 701859.2 | E12: ='5b. Forecasts and Assumptions'!F13 -> 791712.73 | F12: ='5b. Forecasts and Assumptions'!G13 -> 953778.01 | G12: ='5b. Forecasts and Assumptions'!H13 -> 957886.64 | I12: ='5b. Forecasts and Assumptions'!I13 -> 1050690.2 | J12: ='5b. Forecasts and Assumptions'!J13 -> 1152484.9 | K12: ='5b. Forecasts and Assumptions'!K13 -> 1264141.9 | L12: ='5b. Forecasts and Assumptions'!L13 -> 1386616.6 | M12: ='5b. Forecasts and Assumptions'!M13 -> 1520957.1
B13: Marketing | C13: ='5b. Forecasts and Assumptions'!D14 -> 368127.29 | D13: ='5b. Forecasts and Assumptions'!E14 -> 515472.97 | E13: ='5b. Forecasts and Assumptions'!F14 -> 660000 | F13: ='5b. Forecasts and Assumptions'!G14 -> 577108.15 | G13: ='5b. Forecasts and Assumptions'!H14 -> 570000 | I13: ='5b. Forecasts and Assumptions'!I14 -> 622085.71 | J13: ='5b. Forecasts and Assumptions'!J14 -> 678930.93 | K13: ='5b. Forecasts and Assumptions'!K14 -> 740970.58 | L13: ='5b. Forecasts and Assumptions'!L14 -> 808679.31 | M13: ='5b. Forecasts and Assumptions'!M14 -> 882575.16
B14: Sales payroll and commission | C14: ='5b. Forecasts and Assumptions'!D15 -> 522386.06 | D14: ='5b. Forecasts and Assumptions'!E15 -> 689351.82 | E14: ='5b. Forecasts and Assumptions'!F15 -> 791111.52 | F14: ='5b. Forecasts and Assumptions'!G15 -> 1102722.7 | G14: ='5b. Forecasts and Assumptions'!H15 -> 1107575.7 | I14: ='5b. Forecasts and Assumptions'!I15 -> 1287211.1 | J14: ='5b. Forecasts and Assumptions'!J15 -> 1495981.3 | K14: ='5b. Forecasts and Assumptions'!K15 -> 1738611.4 | L14: ='5b. Forecasts and Assumptions'!L15 -> 2020593.2 | M14: ='5b. Forecasts and Assumptions'!M15 -> 2348309.1
B15: Development | C15: ='5b. Forecasts and Assumptions'!D16 -> 540000 | D15: ='5b. Forecasts and Assumptions'!E16 -> 526800 | E15: ='5b. Forecasts and Assumptions'!F16 -> 660000 | F15: ='5b. Forecasts and Assumptions'!G16 -> 520097.47 | G15: ='5b. Forecasts and Assumptions'!H16 -> 504000 | I15: ='5b. Forecasts and Assumptions'!I16 -> 497093.28 | J15: ='5b. Forecasts and Assumptions'!J16 -> 490281.21 | K15: ='5b. Forecasts and Assumptions'!K16 -> 483562.49 | L15: ='5b. Forecasts and Assumptions'!L16 -> 476935.84 | M15: ='5b. Forecasts and Assumptions'!M16 -> 470400
B16: Admin payroll | C16: ='5b. Forecasts and Assumptions'!D17 -> 86680.812 | D16: ='5b. Forecasts and Assumptions'!E17 -> 84998.796 | E16: ='5b. Forecasts and Assumptions'!F17 -> 49596.468 | F16: ='5b. Forecasts and Assumptions'!G17 -> 94807.464 | G16: ='5b. Forecasts and Assumptions'!H17 -> 73716.288 | I16: ='5b. Forecasts and Assumptions'!I17 -> 77959.966 | J16: ='5b. Forecasts and Assumptions'!J17 -> 77959.966 | K16: ='5b. Forecasts and Assumptions'!K17 -> 77959.966 | L16: ='5b. Forecasts and Assumptions'!L17 -> 77959.966 | M16: ='5b. Forecasts and Assumptions'!M17 -> 77959.966
B17: Dean's salary | C17: ='5b. Forecasts and Assumptions'!D18 -> 180000 | D17: ='5b. Forecasts and Assumptions'!E18 -> 180000 | E17: ='5b. Forecasts and Assumptions'!F18 -> 180000 | F17: ='5b. Forecasts and Assumptions'!G18 -> 180000 | G17: ='5b. Forecasts and Assumptions'!H18 -> 180000 | I17: ='5b. Forecasts and Assumptions'!I18 -> 180000 | J17: ='5b. Forecasts and Assumptions'!J18 -> 180000 | K17: ='5b. Forecasts and Assumptions'!K18 -> 180000 | L17: ='5b. Forecasts and Assumptions'!L18 -> 180000 | M17: ='5b. Forecasts and Assumptions'!M18 -> 180000
B18: Other Salaries | C18: 105000 | D18: =C18 -> 105000 | E18: =D18 -> 105000 | F18: =E18 -> 105000 | G18: =F18 -> 105000 | I18: =G18 -> 105000 | J18: =Table28[[#This Row],[2016]] -> 105000 | K18: =I18 -> 105000 | L18: =J18 -> 105000 | M18: =K18 -> 105000
B19: Overhead and Other | C19: ='5b. Forecasts and Assumptions'!D19 -> 476374.39 | D19: ='5b. Forecasts and Assumptions'!E19 -> 540330.95 | E19: ='5b. Forecasts and Assumptions'!F19 -> 594289.96 | F19: ='5b. Forecasts and Assumptions'!G19 -> 777118.33 | G19: ='5b. Forecasts and Assumptions'!H19 -> 773822.89 | I19: ='5b. Forecasts and Assumptions'!I19+260000 -> 1095728.7 | J19: ='5b. Forecasts and Assumptions'!J19 -> 902587.02 | K19: ='5b. Forecasts and Assumptions'!K19 -> 974793.98 | L19: ='5b. Forecasts and Assumptions'!L19 -> 1052777.5 | M19: ='5b. Forecasts and Assumptions'!M19 -> 1136999.7
B20: Total expenses | C20: =SUM(C12:C19) -> 2881837.9 | D20: =SUM(D12:D19) -> 3343813.7 | E20: =SUM(E12:E19) -> 3831710.7 | F20: =SUM(F12:F19) -> 4310632.1 | G20: =SUM(G12:G19) -> 4272001.5 | I20: =SUM(I12:I19) -> 4915769 | J20: =SUM(J12:J19) -> 5083225.3 | K20: =SUM(K12:K19) -> 5565040.3 | L20: =SUM(L12:L19) -> 6108562.4 | M20: =SUM(M12:M19) -> 6722201
A22: EBITDA | C22: =C9-C20 -> 1097202.1 | D22: =D9-D20 -> 1560079 | E22: =E9-E20 -> 2247574.8 | F22: =F9-F20 -> 2505152 | G22: =G9-G20 -> 3017554.1 | I22: =+I9-I20 -> 3286596.8 | J22: =+J9-J20 -> 4225351.3 | K22: =+K9-K20 -> 4995287.8 | L22: =+L9-L20 -> 5980202.5 | M22: =+M9-M20 -> 7242363.1
A23: EBITDA margin | C23: =C22/C9 -> 0.27574544 | D23: =D22/D9 -> 0.31813073 | E23: =E22/E9 -> 0.36971035 | F23: =F22/F9 -> 0.36755155 | G23: =G22/G9 -> 0.41395584 | I23: =+I22/I9 -> 0.40068889 | J23: =+J22/J9 -> 0.45392023 | K23: =+K22/K9 -> 0.47302392 | L23: =+L22/L9 -> 0.49469094 | M23: =+M22/M9 -> 0.51862436
A25: Depreciation and amortization | C25: 15000 | D25: 15000 | E25: 15000 | F25: 15000 | G25: 15000 | I25: 15000 | J25: 15000 | K25: 15000 | L25: 15000 | M25: 15000
A26: EBIT | C26: =C22-C25 -> 1082202.1 | D26: =D22-D25 -> 1545079 | E26: =E22-E25 -> 2232574.8 | F26: =F22-F25 -> 2490152 | G26: =G22-G25 -> 3002554.1 | I26: =I22-I25 -> 3271596.8 | J26: =J22-J25 -> 4210351.3 | K26: =K22-K25 -> 4980287.8 | L26: =L22-L25 -> 5965202.5 | M26: =M22-M25 -> 7227363.1
A27: % margin | C27: =+C26/C9 -> 0.27197568 | D27: =+D26/D9 -> 0.31507193 | E27: =+E26/E9 -> 0.36724296 | F27: =+F26/F9 -> 0.36535078 | G27: =+G26/G9 -> 0.4118981 | I27: =+I26/I9 -> 0.39886015 | J27: =+J26/J9 -> 0.45230882 | K27: =+K26/K9 -> 0.47160351 | L27: =+L26/L9 -> 0.49345012 | M27: =+M26/M9 -> 0.51755021
A28: Interest expense
A29: EBT | C29: =SUM(C26,C28) -> 1082202.1 | D29: =SUM(D26,D28) -> 1545079 | E29: =SUM(E26,E28) -> 2232574.8 | F29: =SUM(F26,F28) -> 2490152 | G29: =SUM(G26,G28) -> 3002554.1 | I29: =+I26-I28 -> 3271596.8 | J29: =+J26-J28 -> 4210351.3 | K29: =+K26-K28 -> 4980287.8 | L29: =+L26-L28 -> 5965202.5 | M29: =+M26-M28 -> 7227363.1
A30: Income tax expense | C30: =C29*0.45 -> 486990.96 | D30: =D29*0.45 -> 695285.53 | E30: =E29*0.45 -> 1004658.7 | F30: =F29*0.45 -> 1120568.4 | G30: =G29*0.45 -> 1351149.4 | I30: =0.45*I29 -> 1472218.6 | J30: =0.45*J29 -> 1894658.1 | K30: =0.45*K29 -> 2241129.5 | L30: =0.45*L29 -> 2684341.1 | M30: =0.45*M29 -> 3252313.4
A31: Net income | C31: =C29-C30 -> 595211.17 | D31: =D29-D30 -> 849793.43 | E31: =E29-E30 -> 1227916.1 | F31: =F29-F30 -> 1369583.6 | G31: =G29-G30 -> 1651404.8 | I31: =I29-I30 -> 1799378.3 | J31: =J29-J30 -> 2315693.2 | K31: =K29-K30 -> 2739158.3 | L31: =L29-L30 -> 3280861.4 | M31: =M29-M30 -> 3975049.7
H42: valuation | I42: =I22*5.1 -> 16761644 | J42: at 5.1x multiple
H43: explination is on docs

Sheet Cashflow Statement
A2: dESCO Cash‑Flow Statement (Indirect) | B2: 2016 | C2: 2017 | D2: 2018 | E2: 2019 | F2: 2020
A3: Net Income | B3: ='Income Statement'!I31 -> 1799378.3 | C3: ='Income Statement'!J31 -> 2315693.2 | D3: ='Income Statement'!K31 -> 2739158.3 | E3: ='Income Statement'!L31 -> 3280861.4 | F3: ='Income Statement'!M31 -> 3975049.7
A4: D&A | B4: ='Income Statement'!I25 -> 15000 | C4: ='Income Statement'!J25 -> 15000 | D4: ='Income Statement'!K25 -> 15000 | E4: ='Income Statement'!L25 -> 15000 | F4: ='Income Statement'!M25 -> 15000
A5: (Gain)/Loss on disposals
A6: ΔA/R | B6: =-('Balance Sheet'!B6-728955.6) -> -91280.986 | C6: =-('Balance Sheet'!F6 - 'Balance Sheet'!B6) -> -110621.07 | D6: =-('Balance Sheet'!J6 - 'Balance Sheet'!F6) -> -125175.15 | E6: =-('Balance Sheet'!N6 - 'Balance Sheet'!J6) -> -152843.68 | F6: =-('Balance Sheet'!R6 - 'Balance Sheet'!N6) -> -187579.92
A7: ΔA/P | C7: =( 'Balance Sheet'!F20-'Balance Sheet'!B20 ) -> -42932.566 | D7: =( 'Balance Sheet'!J20-'Balance Sheet'!F20 ) -> 38258.366 | E7: =('Balance Sheet'!N20 - 'Balance Sheet'!J20) -> 41719.681 | F7: =('Balance Sheet'!R20- 'Balance Sheet'!N20) -> 45474.664
A8: ΔDeferred Rev | B8: =('Balance Sheet'!B21-1250000) -> 0 | C8: =('Balance Sheet'!F21-'Balance Sheet'!B21) -> 144402.2 | D8: =('Balance Sheet'!J21-'Balance Sheet'!F21) -> 188055.82 | E8: =('Balance Sheet'!N21-'Balance Sheet'!J21) -> 212797.76 | F8: =('Balance Sheet'!R21-'Balance Sheet'!N21) -> 578720.11
A9: ΔAccrued Liabilities | B9: 0 | C9: =('Balance Sheet'!F22-'Balance Sheet'!B22) -> 0 | D9: =('Balance Sheet'!J22-'Balance Sheet'!F22) -> 0 | E9: =('Balance Sheet'!N22-'Balance Sheet'!J22) -> 0 | F9: =('Balance Sheet'!R22-'Balance Sheet'!N22) -> 0
A10: Net Cash from operating | B10: =SUM(B3:B9) -> 1723097.3 | C10: =SUM(C3:C9) -> 2321541.8 | D10: =SUM(D3:D9) -> 2855297.3 | E10: =SUM(E3:E9) -> 3397535.1 | F10: =SUM(F3:F9) -> 4426664.6
A12: Cap-ex | B12: 0 | C12: 0 | D12: 0 | E12: 0 | F12: 0
A13: ΔLong-term investments | B13: 0 | C13: =- ( 'Balance Sheet'!F11 - 'Balance Sheet'!B11 ) -> 0 | D13: =- ( 'Balance Sheet'!J11 - 'Balance Sheet'!F11 ) -> 0 | E13: =- ( 'Balance Sheet'!N11 - 'Balance Sheet'!J11 ) -> 0 | F13: =- ( 'Balance Sheet'!R11 - 'Balance Sheet'!N11 ) -> 0
A14: Net cash from investing | B14: =SUM(B12:B13) -> 0 | C14: =SUM(C12:C13) -> 0 | D14: =SUM(D12:D13) -> 0 | E14: =SUM(E12:E13) -> 0 | F14: =SUM(F12:F13) -> 0
A16: Loan Repayment | B16: =-('5.c Amortization&Covenants'!E17) -> -821649.21 | C16: =-('5.c Amortization&Covenants'!E18) -> -821649.21 | D16: =-('5.c Amortization&Covenants'!E19) -> -1643298.4 | E16: =-('5.c Amortization&Covenants'!E20) -> -1643298.4 | F16: =-('5.c Amortization&Covenants'!E21) -> -1643298.4
A17: Dividends/Equity
A18: Net cash from Financing | B18: =SUM(B16:B17) -> -821649.21 | C18: =SUM(C16:C17) -> -821649.21 | D18: =SUM(D16:D17) -> -1643298.4 | E18: =SUM(E16:E17) -> -1643298.4 | F18: =SUM(F16:F17) -> -1643298.4
A20: Net Change in cash | B20: =B10 + B14 + B18 -> 901448.07 | C20: =C10 + C14 + C18 -> 1499892.5 | D20: =D10 + D14 + D18 -> 1211998.9 | E20: =E10 + E14 + E18 -> 1754236.7 | F20: =F10 + F14 + F18 -> 2783366.1
A21: Opening cash balance | B21: 500000 | C21: =B22 -> 1401448.1 | D21: =C22 -> 2901340.6 | E21: =D22 -> 4113339.5 | F21: =E22 -> 5867576.2
A22: Closing cash balance | B22: =B21 + B20 -> 1401448.1 | C22: =C21 + C20 -> 2901340.6 | D22: =D21 + D20 -> 4113339.5 | E22: =E21 + E20 -> 5867576.2 | F22: =F21 + F20 -> 8650942.4

Sheet Balance Sheet
A1: dEsco Corp Projected balance sheets
A2: Year end 2016 | E2: Year end 2017 | I2: Year end 2018 | M2: Year end 2019 | Q2: Year end 2020
A3: ASSETS | B3: 2016 | E3: ASSETS | F3: 2017 | I3: ASSETS | J3: 2018 | M3: ASSETS | N3: 2019 | Q3: ASSETS | R3: 2020
A4: Current Assets | E4: Current Assets | I4: Current Assets | M4: Current Assets | Q4: Current Assets
A5: Cash | B5: 500000 | E5: Cash | F5: ='Cashflow Statement'!C22 -> 2901340.6 | I5: Cash | J5: ='Cashflow Statement'!D22 -> 4113339.5 | M5: Cash | N5: ='Cashflow Statement'!E22 -> 5867576.2 | Q5: Cash | R5: ='Cashflow Statement'!F22 -> 8650942.4
A6: A/R | B6: =(0.1*'Income Statement'!I9) -> 820236.59 | E6: A/R | F6: =0.1*'Income Statement'!J9 -> 930857.66 | I6: A/R | J6: =0.1*'Income Statement'!K9 -> 1056032.8 | M6: A/R | N6: =+'Income Statement'!L9*0.1 -> 1208876.5 | Q6: A/R | R6: =+'Income Statement'!M9*0.1 -> 1396456.4
A7: Total Current Assets | B7: =SUM(B5:B6) -> 1320236.6 | E7: Total Current Assets | F7: =SUM(F5:F6) -> 3832198.3 | I7: Total Current Assets | J7: =SUM(J5:J6) -> 5169372.3 | M7: Total Current Assets | N7: =SUM(N5:N6) -> 7076452.7 | Q7: Total Current Assets | R7: =SUM(R5:R6) -> 10047399
A9: Non-Current Assets | E9: Non-Current Assets | I9: Non-Current Assets | M9: Non-Current Assets | Q9: Non-Current Assets
A10: PPE | B10: 100000 | E10: PPE | F10: =+B10-'Income Statement'!I25 -> 85000 | I10: PPE | J10: =+F10-'Income Statement'!M25 -> 70000 | M10: PPE | N10: =+J10-'Income Statement'!K25 -> 55000 | Q10: PPE | R10: =+N10-'Income Statement'!M25 -> 40000
A11: Long Term Investments | E11: Long Term Investments | I11: Long Term Investments | M11: Long Term Investments | Q11: Long Term Investments
A12: Licensing Software | B12: 5000000 | E12: Licensing Software | F12: 5000000 | I12: Licensing Software | J12: 5000000 | M12: Licensing Software | N12: 5000000 | Q12: Licensing Software | R12: 5000000
A13: Goodwill | B13: =D42-B5-B6-B10-B12 -> 10341407 | E13: Goodwill | F13: =+B13 -> 10341407 | I13: Goodwill | J13: =+F13 -> 10341407 | M13: Goodwill | N13: =+J13 -> 10341407 | Q13: Goodwill | R13: =+N13 -> 10341407
A14: Total Non-Current Assets | B14: =SUM(B10:B13) -> 15441407 | E14: Total Non-Current Assets | F14: =SUM(F10:F13) -> 15426407 | I14: Total Non-Current Assets | J14: =SUM(J10:J13) -> 15411407 | M14: Total Non-Current Assets | N14: =SUM(N10:N13) -> 15396407 | Q14: Total Non-Current Assets | R14: =SUM(R10:R13) -> 15381407
A16: Total Assets | B16: =+B14+B7 -> 16761644 | E16: Total Assets | F16: =+F14+F7 -> 19258606 | I16: Total Assets | J16: =+J14+J7 -> 20580780 | M16: Total Assets | N16: =+N14+N7 -> 22472860 | Q16: Total Assets | R16: =+R14+R7 -> 25428806
A18: LIABILITIES AND SHAREHOLDER'S | B18: EQUITY | E18: LIABILITIES AND SHAREHOLDER'S | F18: EQUITY | I18: LIABILITIES AND SHAREHOLDER'S | J18: EQUITY | M18: LIABILITIES AND SHAREHOLDER'S | N18: EQUITY | Q18: LIABILITIES AND SHAREHOLDER'S | R18: EQUITY
A19: Current Liabilities | E19: Current Liabilities | I19: Current Liabilities | M19: Current Liabilities | Q19: Current Liabilities
A20: A/P | B20: =(Table28[[#This Row],[2016]]-'Income Statement'!I12-'Income Statement'!I14-'Income Statement'!I16-'Income Statement'!I17-'Income Statement'!I18)*0.3 -> 664472.31 | E20: A/P | F20: =(Table28[[#This Row],[2017]]-'Income Statement'!J12-'Income Statement'!J14-'Income Statement'!J16-'Income Statement'!J17-'Income Statement'!J18)*0.3 -> 621539.75 | I20: A/P | J20: =(Table28[[#This Row],[2018]]-'Income Statement'!K12-'Income Statement'!K14-'Income Statement'!K16-'Income Statement'!K17-'Income Statement'!K18)*0.3 -> 659798.11 | M20: A/P | N20: =(Table28[[#This Row],[2019]]-'Income Statement'!L12-'Income Statement'!L14-'Income Statement'!L16-'Income Statement'!L17-'Income Statement'!L18)*0.3 -> 701517.79 | Q20: A/P | R20: =(Table28[[#This Row],[2020]]-'Income Statement'!M18-'Income Statement'!M17-'Income Statement'!M16-'Income Statement'!M14-'Income Statement'!M12)*0.3 -> 746992.46
A21: Deferred Revenue | B21: 1250000 | E21: Deferred Revenue | F21: =0.17*'Income Statement'!I9 -> 1394402.2 | I21: Deferred Revenue | J21: =0.17*'Income Statement'!J9 -> 1582458 | M21: Deferred Revenue | N21: =0.17*'Income Statement'!K9 -> 1795255.8 | Q21: Deferred Revenue | R21: =0.17*'Income Statement'!M9 -> 2373975.9
A22: Acrrued liabilities | E22: Acrrued liabilities | I22: Acrrued liabilities | M22: Acrrued liabilities | Q22: Acrrued liabilities
A24: Non-Current Liabilites | E24: Non-Current Liabilites | I24: Non-Current Liabilites | M24: Non-Current Liabilites | Q24: Non-Current Liabilites
A25: Long term Debt | B25: ='5.c Amortization&Covenants'!P17 -> 6573193.7 | E25: Long term Debt | F25: ='5.c Amortization&Covenants'!P18 -> 5751544.5 | I25: Long term Debt | J25: ='5.c Amortization&Covenants'!P19 -> 4929895.3 | M25: Long term Debt | N25: ='5.c Amortization&Covenants'!P20 -> 3286596.8 | Q25: Long term Debt | R25: ='5.c Amortization&Covenants'!P21 -> 1643298.4
A27: Total Liabilites | B27: =B20+B21+B25 -> 8487666 | E27: Total Liabilites | F27: =F20+F21+F25+F22 -> 7767486.4 | I27: Total Liabilites | J27: =J20+J21+J25+J22 -> 7172151.4 | M27: Total Liabilites | N27: =N20+N21+N25+N22 -> 5783370.4 | Q27: Total Liabilites | R27: =R20+R21+R25+R22 -> 4764266.8
A29: Shareholder's Equity | E29: Shareholder's Equity | I29: Shareholder's Equity | M29: Shareholder's Equity | Q29: Shareholder's Equity
A30: Common Shareholder's Equity | B30: =B16-B27-B31 -> 6474599.6 | E30: Common Shareholder's Equity | F30: =F16-F27-F31 -> 7376047.7 | I30: Common Shareholder's Equity | J30: =J16-J27-J31 -> 6554398.5 | M30: Common Shareholder's Equity | N30: =N16-N27-N31 -> 6554398.5 | Q30: Common Shareholder's Equity | R30: =R16-R27-R31 -> 10529448
A31: Retained Earnings | B31: =+'Income Statement'!I31 -> 1799378.3 | E31: Retained Earnings | F31: =+'Income Statement'!J31+B31 -> 4115071.5 | I31: Retained Earnings | J31: =+'Income Statement'!K31+F31 -> 6854229.8 | M31: Retained Earnings | N31: =+J31+'Income Statement'!L31 -> 10135091 | Q31: Retained Earnings | R31: =+N31 -> 10135091
A33: Total Liabilities and Shareholder's Equity | B33: =+B30+B27+B31 -> 16761644 | E33: Total Liabilities and Shareholder's Equity | F33: =+F30+F27+F31 -> 19258606 | I33: Total Liabilities and Shareholder's Equity | J33: =+J30+J27+J31 -> 20580780 | M33: Total Liabilities and Shareholder's Equity | N33: =+N30+N27+N31 -> 22472860 | Q33: Total Liabilities and Shareholder's Equity | R33: =+R30+R27+R31 -> 25428806
B42: Valuation at 5.1x EBITDA multiple | D42: ='Income Statement'!I22*5.1 -> 16761644

Sheet 5.a Sources & Uses
A2: Year end 2016 | F2: Year end 2017 | K2: Year end 2018 | P2: Year end 2019 | U2: Year end 2020
A3: Sources | B3: Amount | C3: Uses | D3: Amount: | F3: Sources | G3: Amount | H3: Uses | I3: Amount: | K3: Sources | L3: Amount | M3: Uses | N3: Amount: | P3: Sources | Q3: Amount | R3: Uses | S3: Amount: | U3: Sources | V3: Amount | W3: Uses | X3: Amount:
A4: Long-term Debt | B4: ='Balance Sheet'!B25 -> 6573193.7 | C4: Cash | D4: ='Balance Sheet'!B5 -> 500000 | F4: Long-term Debt | G4: ='Balance Sheet'!F25 -> 5751544.5 | H4: Cash | I4: ='Balance Sheet'!F5 -> 2901340.6 | K4: Long-term Debt | L4: ='Balance Sheet'!J25 -> 4929895.3 | M4: Cash | N4: ='Balance Sheet'!J5 -> 4113339.5 | P4: Long-term Debt | Q4: ='Balance Sheet'!N25 -> 3286596.8 | R4: Cash | S4: ='Balance Sheet'!N5 -> 5867576.2 | U4: Long-term Debt | V4: ='Balance Sheet'!R25 -> 1643298.4 | W4: Cash | X4: ='Balance Sheet'!R5 -> 8650942.4
A5: Deferred Revenue | B5: ='Balance Sheet'!B21 -> 1250000 | C5: Accounts Receivable | D5: ='Balance Sheet'!B6 -> 820236.59 | F5: Deferred Revenue | G5: ='Balance Sheet'!F21 -> 1394402.2 | H5: Accounts Receivable | I5: ='Balance Sheet'!F6 -> 930857.66 | K5: Deferred Revenue | L5: ='Balance Sheet'!J21 -> 1582458 | M5: Accounts Receivable | N5: ='Balance Sheet'!J6 -> 1056032.8 | P5: Deferred Revenue | Q5: ='Balance Sheet'!N21 -> 1795255.8 | R5: Accounts Receivable | S5: ='Balance Sheet'!N6 -> 1208876.5 | U5: Deferred Revenue | V5: ='Balance Sheet'!R21 -> 2373975.9 | W5: Accounts Receivable | X5: ='Balance Sheet'!R6 -> 1396456.4
A6: Common Shareholder's Equity | B6: ='Balance Sheet'!B30 -> 6474599.6 | C6: PPE | D6: ='Balance Sheet'!B10 -> 100000 | F6: Common Shareholder's Equity | G6: ='Balance Sheet'!F30 -> 7376047.7 | H6: PPE | I6: ='Balance Sheet'!F10 -> 85000 | K6: Common Shareholder's Equity | L6: ='Balance Sheet'!J30 -> 6554398.5 | M6: PPE | N6: ='Balance Sheet'!J10 -> 70000 | P6: Common Shareholder's Equity | Q6: ='Balance Sheet'!N30 -> 6554398.5 | R6: PPE | S6: ='Balance Sheet'!N10 -> 55000 | U6: Common Shareholder's Equity | V6: ='Balance Sheet'!R30 -> 10529448 | W6: PPE | X6: ='Balance Sheet'!R10 -> 40000
A7: Retained Earnings | B7: ='Balance Sheet'!B31 -> 1799378.3 | C7: Licensing Software | D7: ='Balance Sheet'!B12 -> 5000000 | F7: Retained Earnings | G7: ='Balance Sheet'!F31 -> 4115071.5 | H7: Licensing Software | I7: ='Balance Sheet'!F12 -> 5000000 | K7: Retained Earnings | L7: ='Balance Sheet'!J31 -> 6854229.8 | M7: Licensing Software | N7: ='Balance Sheet'!J12 -> 5000000 | P7: Retained Earnings | Q7: ='Balance Sheet'!N31 -> 10135091 | R7: Licensing Software | S7: ='Balance Sheet'!N12 -> 5000000 | U7: Retained Earnings | V7: ='Balance Sheet'!R31 -> 10135091 | W7: Licensing Software | X7: ='Balance Sheet'!R12 -> 5000000
A8: Accounts Payable | B8: ='Balance Sheet'!B20 -> 664472.31 | C8: Goodwill | D8: ='Balance Sheet'!B13 -> 10341407 | F8: Accounts Payable | G8: ='Balance Sheet'!F20 -> 621539.75 | H8: Goodwill | I8: ='Balance Sheet'!F13 -> 10341407 | K8: Accounts Payable | L8: ='Balance Sheet'!J20 -> 659798.11 | M8: Goodwill | N8: ='Balance Sheet'!J13 -> 10341407 | P8: Accounts Payable | Q8: ='Balance Sheet'!N20 -> 701517.79 | R8: Goodwill | S8: ='Balance Sheet'!N13 -> 10341407 | U8: Accounts Payable | V8: ='Balance Sheet'!R20 -> 746992.46 | W8: Goodwill | X8: ='Balance Sheet'!R13 -> 10341407
A9: Total Sources | B9: =SUM(B3:B8) -> 16761644 | C9: Total Uses | D9: =SUM(D3:D8) -> 16761644 | F9: Total Sources | G9: =SUM(G3:G8) -> 19258606 | H9: Total Uses | I9: =SUM(I3:I8) -> 19258606 | K9: Total Sources | L9: =SUM(L3:L8) -> 20580780 | M9: Total Uses | N9: =SUM(N3:N8) -> 20580780 | P9: Total Sources | Q9: =SUM(Q3:Q8) -> 22472860 | R9: Total Uses | S9: =SUM(S3:S8) -> 22472860 | U9: Total Sources | V9: =SUM(V3:V8) -> 25428806 | W9: Total Uses | X9: =SUM(X3:X8) -> 25428806

Sheet 5b. Forecasts and Assumptions
B2: Rev & Exp Forecasts | C2: Ledgers | D2: 2011 | E2: 2012 | F2: 2013 | G2: 2014 | H2: 2015 | I2: 2016 | J2: 2017 | K2: 2018 | L2: 2019 | M2: 2020
B4: Revenue | D4: Historical Period | I4: Projection Period
C5: ESC licence | D5: =D26*D39 -> 878220 | E5: =E26*E39 -> 1400064.8 | F5: =F26*F39 -> 1747657.8 | G5: =G26*G39 -> 1526175 | H5: =H26*H39 -> 1481996.2 | I5: =I26*I39 -> 1645492.3 | J5: =J26*J39 -> 1827025.5 | K5: =K26*K39 -> 2028585.8 | ... M5: =M26*M39 -> 2500868.7
C6: ESC accounting | D6: =D27*D40 -> 11913.156 | E6: =E27*E40 -> 80894.448 | F6: =F27*F40 -> 192392.53 | G6: =G27*G40 -> 521443.12 | H6: =H27*H40 -> 472653.72 | I6: =I27*I40 -> 564042.36 | J6: =J27*J40 -> 673101.19 | K6: =K27*K40 -> 803246.79 | ... M6: =M27*M40 -> 1143895.3
C7: ESC maintenance | D7: =D28*D41 -> 2816730 | E7: =E28*E41 -> 2875635 | F7: =F28*F41 -> 3025575 | G7: =G28*G41 -> 3132675 | H7: =H28*H41 -> 3213000 | I7: =I28*I41 -> 3298707.6 | J7: =J28*J41 -> 3386701.6 | K7: =K28*K41 -> 3477042.7 | ... M7: =M28*M41 -> 3665019
C8: ESC one-time training | D8: 134577.4 | E8: 194847.55 | F8: 270085.62 | G8: 290624.05 | H8: 363220.98 | I8: =I35*I43 -> 443007.1 | J8: =J35*J43 -> 540319.25 | K8: =K35*K43 -> 563223.66 | L8: =L35*L43 -> 587098.99 | M8: =M35*M43 -> 611986.41
C9: ESC mobile | D9: 137599.5 | E9: 352450.95 | F9: 843574.51 | G9: 1344867 | H9: =H32*12*H42 -> 1758684.7 | I9: =I32*12*I42 -> 2251116.4 | J9: =J32*12*J42 -> 2881429 | K9: =K32*12*K42 -> 3688229.2 | L9: =L32*12*L42 -> 4720933.3 | M9: =M32*12*M42 -> 6042794.7
C10: Total revenue | D10: =SUM(D5:D9) -> 3979040.1 | E10: =SUM(E5:E9) -> 4903892.7 | F10: =SUM(F5:F9) -> 6079285.5 | G10: =SUM(G5:G9) -> 6815784.2 | H10: =SUM(H5:H9) -> 7289555.7 | I10: =SUM(I5:I9) -> 8202365.9 | J10: =SUM(J5:J9) -> 9308576.6 | K10: =SUM(K5:K9) -> 10560328 | ... M10: =SUM(M5:M9) -> 13964564
E11: =E10/D10-1 -> 0.2324311 | F11: =F10/E10-1 -> 0.23968566 | G11: =G10/F10-1 -> 0.12114889 | H11: =H10/G10-1 -> 0.069510929 | I11: =I10/H10-1 -> 0.12522165 | J11: =J10/I10-1 -> 0.13486484 | K11: =K10/J10-1 -> 0.13447293 | L11: =L10/K10-1 -> 0.14473383 | M11: =M10/L10-1 -> 0.1551688
B12: Expenses | N12: CAGR Growth Rate | O12: Comments
C13: Support salaries | D13: 603269.36 | E13: 701859.2 | F13: 791712.73 | G13: 953778.01 | H13: 957886.64 | I13: =H13*(1+$N$13) -> 1050690.2 | J13: =I13*(1+$N$13) -> 1152484.9 | K13: =J13*(1+$N$13) -> 1264141.9 | L13: =K13*(1+$N$13) -> 1386616.6 | M13: =L13*(1+$N$13) -> 1520957.1 | N13: =(H13/D13)^0.2-1 -> 0.096883666 | O13: CAGR formula, due to it being the standard growth rate formula
C14: Marketing | D14: 368127.29 | E14: 515472.97 | F14: 660000 | G14: 577108.15 | H14: 570000 | I14: =H14*(1+$N$14) -> 622085.71 | J14: =I14*(1+$N$14) -> 678930.93 | K14: =J14*(1+$N$14) -> 740970.58 | L14: =K14*(1+$N$14) -> 808679.31 | M14: =L14*(1+$N$14) -> 882575.16 | N14: =(H14/D14)^0.2-1 -> 0.091378437 | O14: CAGR formula, due to it being the standard growth rate formula
C15: Sales payroll and commission | D15: 522386.06 | E15: 689351.82 | F15: 791111.52 | G15: 1102722.7 | H15: 1107575.7 | I15: =H15*(1+$N$15) -> 1287211.1 | J15: =I15*(1+$N$15) -> 1495981.3 | K15: =J15*(1+$N$15) -> 1738611.4 | L15: =K15*(1+$N$15) -> 2020593.2 | M15: =L15*(1+$N$15) -> 2348309.1 | N15: =(H15/D15)^0.2-1 -> 0.16218795 | O15: CAGR formula, due to it being the standard growth rate formula
C16: Development | D16: 540000 | E16: 526800 | F16: 660000 | G16: 520097.47 | H16: 504000 | I16: =H16*(1+$N$16) -> 497093.28 | J16: =I16*(1+$N$16) -> 490281.21 | K16: =J16*(1+$N$16) -> 483562.49 | L16: =K16*(1+$N$16) -> 476935.84 | M16: =L16*(1+$N$16) -> 470400 | N16: =(H16/D16)^0.2-1 -> -0.01370381 | O16: CAGR formula, due to it being the standard growth rate formula
C17: Admin payroll | D17: 86680.812 | E17: 84998.796 | F17: 49596.468 | G17: 94807.464 | H17: 73716.288 | I17: =AVERAGE(D17:H17) -> 77959.966 | J17: =I17 -> 77959.966 | K17: =J17 -> 77959.966 | L17: =K17 -> 77959.966 | M17: =L17 -> 77959.966 | N17: average | O17: Took the average due to a highly fluctuating rate
C18: Dean's salary | D18: 180000 | E18: 180000 | F18: 180000 | G18: 180000 | H18: 180000 | I18: 180000 | J18: 180000 | K18: 180000 | L18: 180000 | M18: 180000 | N18: 0 | O18: No growth at all, thus 0% growth rate
C19: Overhead | D19: 476374.39 | E19: 540330.95 | F19: 594289.96 | G19: 777118.33 | H19: 773822.89 | I19: =H19*(1+$N$19) -> 835728.72 | J19: =I19*(1+$N$19) -> 902587.02 | K19: =J19*(1+$N$19) -> 974793.98 | L19: =K19*(1+$N$19) -> 1052777.5 | M19: =L19*(1+$N$19) -> 1136999.7 | N19: 0.08 | O19: High growth rate in overhead
C20: Total expenses | D20: =SUM(D13:D19) -> 2776837.9 | E20: =SUM(E13:E19) -> 3238813.7 | F20: =SUM(F13:F19) -> 3726710.7 | G20: =SUM(G13:G19) -> 4205632.1 | H20: =SUM(H13:H19) -> 4167001.5 | I20: =SUM(I13:I19) -> 4550769 | J20: =SUM(J13:J19) -> 4978225.3 | K20: =SUM(K13:K19) -> 5460040.3 | ... M20: =SUM(M13:M19) -> 6617201
B22: EBITDA | D22: =D10-D20 -> 1202202.1 | E22: =E10-E20 -> 1665079 | F22: =F10-F20 -> 2352574.8 | G22: =G10-G20 -> 2610152 | H22: =H10-H20 -> 3122554.1 | I22: =I10-I20 -> 3651596.8 | J22: =J10-J20 -> 4330351.3 | K22: =K10-K20 -> 5100287.8 | ... M22: =M10-M20 -> 7347363.1
B23: EBITDA margin | D23: =D22/D10 -> 0.30213371 | E23: =E22/E10 -> 0.33954229 | F23: =F22/F10 -> 0.38698212 | G23: =G22/G10 -> 0.38295697 | H23: =H22/H10 -> 0.42836001 | I23: =I22/I10 -> 0.44518824 | J23: =J22/J10 -> 0.46520015 | K23: =K22/K10 -> 0.48296679 | ... M23: =M22/M10 -> 0.52614339
C24: CAGR BASE | Q24: Assumptions
B25: Units | Q25: No expenses are capitalized
C26: ESC licences | D26: 210 | E26: 330.75 | F26: 430.5 | G26: 399 | H26: 393.75 | I26: =H26*(1+$N$26) -> 446.49934 | J26: =I26*(1+$N$26) -> 506.31533 | K26: =J26*(1+$N$26) -> 574.14466 | L26: =K26*(1+$N$26) -> 651.06086 | M26: =L26*(1+$N$26) -> 738.28125 | N26: =(H26/D26)^0.2-1 -> 0.13396658 | O26: CAGR formula, due to it being the standard growth rate formula | Q26: Tax rate of 45%
C27: ESC accounting | D27: 2.8314096 | E27: 19.606498 | F27: 39.768107 | G27: 131.25 | H27: 115.5 | I27: =H27*(1+$N$27) -> 138.6 | J27: =I27*(1+$N$27) -> 166.32 | K27: =J27*(1+$N$27) -> 199.584 | L27: =K27*(1+$N$27) -> 239.5008 | M27: =L27*(1+$N$27) -> 287.40096 | N27: 0.2 | O27: We used 20% as a reasonable forecasted growth rate | Q27: Opening 2015 deferred revenue balance of $1,250,000
C28: ESC maintenance customers | D28: 2761.5 | E28: 2819.25 | F28: 2966.25 | G28: 3071.25 | H28: 3150 | I28: =H28*(1+$N$28) -> 3234.0271 | J28: =I28*(1+$N$28) -> 3320.2956 | K28: =J28*(1+$N$28) -> 3408.8654 | L28: =K28*(1+$N$28) -> 3499.7978 | M28: =L28*(1+$N$28) -> 3593.1559 | N28: =(H28/D28)^0.2-1 -> 0.02667527 | O28: CAGR formula, due to it being the standard growth rate formula | Q28: Cash to remain in the business post transaction of $500,000
C29: ESC maintenance customers lost | D29: 250 | E29: 260 | F29: 270 | G29: 280 | H29: 300 | I29: =H29*(1+$N$29) -> 311.14119 | J29: =I29*(1+$N$29) -> 322.69613 | K29: =J29*(1+$N$29) -> 334.68019 | L29: =K29*(1+$N$29) -> 347.1093 | M29: =L29*(1+$N$29) -> 360 | N29: =(H29/D29)^0.2-1 -> 0.037137289 | O29: CAGR formula, due to it being the standard growth rate formula | Q29: Opening 2015 PP&E of $100,000
C30: ESC maintenance churn rate | D30: =D29/D28 -> 0.090530509 | E30: =E29/E28 -> 0.092223109 | F30: =F29/F28 -> 0.09102402 | G30: =G29/G28 -> 0.091168091 | H30: =H29/H28 -> 0.095238095 | I30: =N30 -> 0.092021405 | J30: =I30 -> 0.092021405 | K30: =J30 -> 0.092021405 | L30: =K30 -> 0.092021405 | M30: =L30 -> 0.092021405 | N30: =GEOMEAN(D30:H30) -> 0.092021405 | O30: Geomean as a way to represent as a % | Q30: Average annual depreciation of $15,000
B31: change bold | C31: ESC mobile customers | D31: =D32/5 -> 152.88833 | E31: =E32/6 -> 326.34347 | F31: =F32/7 -> 669.50358 | G31: =G32/7.5 -> 996.19778 | H31: =H32/8 -> 1197.3616 | I31: =H31*(1+$N$31) -> 1436.8339 | J31: =I31*(1+$N$31) -> 1724.2007 | K31: =J31*(1+$N$31) -> 2069.0408 | L31: =K31*(1+$N$31) -> 2482.849 | M31: =L31*(1+$N$31) -> 2979.4188 | N31: 0.2 | O31: We used 20% as a reasonable forecasted growth rate | Q31: Average A/R 10% of revenue
B32: look at admin payroll look at growth rate of sales payroll and comission, development | C32: ESC mobile users | D32: 764.44167 | E32: 1958.0608 | F32: 4686.5251 | G32: 7471.4833 | H32: 9578.8928 | I32: =H32*(1+$N$32) -> 12260.983 | J32: =I32*(1+$N$32) -> 15694.058 | K32: =J32*(1+$N$32) -> 20088.394 | L32: =K32*(1+$N$32) -> 25713.145 | M32: =L32*(1+$N$32) -> 32912.825 | N32: 0.28 | O32: We used 28% as a reasonable forecasted growth rate | Q32: Average A/P 30% of non-payroll expenses
C33: ESC mobile users lost | D33: =D32*6.1% -> 46.630942 | E33: =E32*6.2% -> 121.39977 | F33: =F32*6.3% -> 295.25108 | G33: =G32*6.2% -> 463.23197 | H33: =H32*6% -> 574.73357 | I33: =H33*(1+$N$33) -> 712.66962 | J33: =I33*(1+$N$33) -> 883.71033 | K33: =J33*(1+$N$33) -> 1095.8008 | L33: =K33*(1+$N$33) -> 1358.793 | M33: =L33*(1+$N$33) -> 1684.9033 | N33: 0.24 | O33: We used 24% as a reasonable forecasted growth rate | Q33: VP of Marketing makes $70,000 per year
C34: ESC mobile churn rate | D34: =D33/D32 -> 0.061 | E34: =E33/E32 -> 0.062 | F34: =F33/F32 -> 0.063 | G34: =G33/G32 -> 0.062 | H34: =H33/H32 -> 0.06 | I34: =N34 -> 0.061591531 | J34: =I34 -> 0.061591531 | K34: =J34 -> 0.061591531 | L34: =K34 -> 0.061591531 | M34: =L34 -> 0.061591531 | N34: =GEOMEAN(D34:H34) -> 0.061591531 | O34: Geomean as a way to represent as a % | Q34: Overhead consists of rent, insurance, utilities, benefits
C35: ESC training customers | D35: =D8/D43 -> 94.241877 | E35: =E8/E43 -> 131.74277 | F35: =F8/F43 -> 220.65819 | G35: =G8/G43 -> 219.17349 | H35: =H8/H43 -> 263.77704 | I35: =H35*(1+$N$35) -> 324.06759 | J35: =I35*(1+$N$35) -> 398.13853 | K35: =J35*(1+0.05) -> 418.04546 | L35: =K35*(1+0.05) -> 438.94773 | M35: =L35*(1+0.05) -> 460.89512 | N35: =(H35/D35)^0.2-1 -> 0.22856634 | O35: CAGR formula, due to it being the standard growth rate formula | Q35: Sales rep salaries are $35,000 per year
C36: Total number of employees | D36: 22 | E36: 22 | F36: 24 | G36: 28 | H36: 33 | I36: =H36*(1+$N$36) -> 35.787568 | J36: =I36*(1+$N$36) -> 38.810608 | K36: =J36*(1+$N$36) -> 42.089009 | L36: =K36*(1+$N$36) -> 45.644342 | M36: =L36*(1+$N$36) -> 49.5 | N36: =(H36/D36)^0.2-1 -> 0.084471771 | O36: CAGR formula, due to it being the standard growth rate formula | Q36: Non payroll marketing spend is on sales leads which have a ~20% chance of closing into a sale
Q37: Estimated transaction fees of $200k for legal, $50k for accounting, and $10k for technical due diligence
B38: Pricing
C39: Avg. ESC licence $ per customer | D39: 4182 | E39: 4233 | F39: 4059.6 | G39: 3825 | H39: 3763.8 | I39: =H39*(1+$N$39) -> 3685.3186 | J39: =I39*(1+$N$39) -> 3608.4737 | K39: =J39*(1+$N$39) -> 3533.2311 | L39: =K39*(1+$N$39) -> 3459.5574 | M39: =L39*(1+$N$39) -> 3387.42 | N39: =(H39/D39)^0.2-1 -> -0.020851638 | O39: CAGR formula, due to it being the standard growth rate formula
C40: Avg. ESC accounting $ per customer | D40: 4207.5 | E40: 4125.9 | F40: 4837.86 | G40: 3972.9 | H40: 4092.24 | I40: =H40*(1+$N$40) -> 4069.5697 | J40: =I40*(1+$N$40) -> 4047.025 | K40: =J40*(1+$N$40) -> 4024.6052 | L40: =K40*(1+$N$40) -> 4002.3095 | M40: =L40*(1+$N$40) -> 3980.1374 | N40: =(H40/D40)^0.2-1 -> -0.0055398282 | O40: CAGR formula, due to it being the standard growth rate formula
C41: ESC maintenance $ per customer | D41: 1020 | E41: 1020 | F41: 1020 | G41: 1020 | H41: 1020 | I41: =H41*(1+$N$41) -> 1020 | J41: =I41*(1+$N$41) -> 1020 | K41: =J41*(1+$N$41) -> 1020 | L41: =K41*(1+$N$41) -> 1020 | M41: =L41*(1+$N$41) -> 1020 | N41: =(H41/D41)^0.2-1 -> 0 | O41: CAGR formula, due to it being the standard growth rate formula
C42: ESC mobile $ per customer per month | D42: 15.3 | E42: 15.3 | F42: 15.3 | G42: 15.3 | H42: 15.3 | I42: =H42 -> 15.3 | J42: =I42 -> 15.3 | K42: =J42 -> 15.3 | L42: =K42 -> 15.3 | M42: =L42 -> 15.3 | N42: =(H42/D42)^0.2-1 -> 0 | O42: CAGR formula, due to it being the standard growth rate formula
C43: ESC training $ per customer | D43: 1428 | E43: 1479 | F43: 1224 | G43: 1326 | H43: 1377 | I43: =H43*(1+$N$43) -> 1367.0207 | J43: =I43*(1+$N$43) -> 1357.1137 | K43: =J43*(1+$N$43) -> 1347.2785 | L43: =K43*(1+$N$43) -> 1337.5146 | M43: =L43*(1+$N$43) -> 1327.8214 | N43: =(H43/D43)^0.2-1 -> -0.0072471407 | O43: CAGR formula, due to it being the standard growth rate formula

Sheet 5.c Amortization&Covenants
B2: Debt Package | C2: Year | D2: Beginning Debt ($M) | E2: Total Payment | F2: Principle Payment | G2: Interest Expense | H2: Ending Debt ($M) | I2: Interest Rate | N2: Debt Package | O2: Year | P2: Debt | Q2: Ebitda | R2: Debt/Ebitda | S2: DEBT/EBITDA Covenant | T2: Fixed Charge Coverage | U2: FCC Limit | V2: Debt/EBITDA BREACH | W2: FCC Breach | Z2: INCOME TAXES
B3: Avid Option 1 | C3: 1 | D3: ='5.d IRR and COC Forecasts'!$F3 -> 3286596.8 | E3: =D3*0.125 -> 410824.61 | F3: =E3-G3 -> 256765.38 | G3: =((H3+D3)/2)*I3 -> 154059.23 | H3: =D3-E3 -> 2875772.2 | I3: ='5.d IRR and COC Forecasts'!$D3 -> 0.05 | N3: Avid Option 1 | O3: 1 | P3: =Table2[[#This Row],[Beginning Debt ($M)]] -> 3286596.8 | Q3: ='Income Statement'!I22 -> 3286596.8 | R3: =P3/Q3 -> 1 | S3: 3 | T3: {=('5.c Amortization&Covenants'!Q3-INDEX('Income Statement'!I30:M30,ROW()-2))/'5.c Amortization&Covenants'!E3} -> 4.4164304 | U3: 1.25 | V3: =IF(Table1[[#This Row],[DEBT/EBITDA Covenant]]>Table1[[#This Row],[Debt/Ebitda]]," ", "Breach") | W3: =IF(Table1[[#This Row],[FCC Limit]]<Table1[[#This Row],[Fixed Charge Coverage]]," ", "Breach") | Z3: 1435320.1
B4: Avid Option 1 | C4: 2 | D4: =H3 -> 2875772.2 | E4: =D3*0.125 -> 410824.61 | F4: =E4-G4 -> 277306.61 | G4: =((H4+D4)/2)*I4 -> 133518 | H4: =D4-E4 -> 2464947.6 | I4: =I3 -> 0.05 | N4: Avid Option 1 | O4: 2 | P4: =Table2[[#This Row],[Beginning Debt ($M)]] -> 2875772.2 | Q4: ='Income Statement'!J22 -> 4225351.3 | R4: =P4/Q4 -> 0.68059957 | S4: =S3 -> 3 | T4: =(Q4-Z4)/E4 -> 5.7589495 | U4: 1.25 | V4: =IF(Table1[[#This Row],[FCC Limit]]<Table1[[#This Row],[Fixed Charge Coverage]]," ", "Breach") | W4: =IF(Table1[[#This Row],[DEBT/EBITDA Covenant]]>Table1[[#This Row],[Debt/Ebitda]]," ", "Breach") | Z4: 1859433.1
B5: Avid Option 1 | C5: 3 | D5: =H4 -> 2464947.6 | E5: =D3*0.25 -> 821649.21 | F5: =E5-G5 -> 718943.06 | G5: =((H5+D5)/2)*I5 -> 102706.15 | H5: =D5-E5 -> 1643298.4 | I5: =I4 -> 0.05 | N5: Avid Option 1 | O5: 3 | P5: =Table2[[#This Row],[Beginning Debt ($M)]] -> 2464947.6 | Q5: ='Income Statement'!K22 -> 4995287.8 | R5: =P5/Q5 -> 0.49345458 | S5: =S4 -> 3 | T5: =(Q5-Z5)/E5 -> 3.5204543 | U5: 1.25 | V5: =IF(Table1[[#This Row],[FCC Limit]]<Table1[[#This Row],[Fixed Charge Coverage]]," ", "Breach") | W5: =IF(Table1[[#This Row],[DEBT/EBITDA Covenant]]>Table1[[#This Row],[Debt/Ebitda]]," ", "Breach") | Z5: 2102709.4
B6: Avid Option 1 | C6: 4 | D6: =H5 -> 1643298.4 | E6: =D3*0.25 -> 821649.21 | F6: =E6-G6 -> 760025.52 | G6: =((H6+D6)/2)*I6 -> 61623.691 | H6: =D6-E6 -> 821649.21 | I6: =I5 -> 0.05 | N6: Avid Option 1 | O6: 4 | P6: =Table2[[#This Row],[Beginning Debt ($M)]] -> 1643298.4 | Q6: ='Income Statement'!L22 -> 5980202.5 | R6: =P6/Q6 -> 0.27478976 | S6: =S5 -> 3 | T6: =(Q6-Z6)/E6 -> 4.2053892 | U6: 1.25 | V6: =IF(Table1[[#This Row],[FCC Limit]]<Table1[[#This Row],[Fixed Charge Coverage]]," ", "Breach") | W6: =IF(Table1[[#This Row],[DEBT/EBITDA Covenant]]>Table1[[#This Row],[Debt/Ebitda]]," ", "Breach") | Z6: 2524847.8
B7: Avid Option 1 | C7: 5 | D7: =H6 -> 821649.21 | E7: =D3*0.25 -> 821649.21 | F7: =E7-G7 -> 801107.98 | G7: =((H7+D7)/2)*I7 -> 20541.23 | H7: =D7-E7 -> 0 | I7: =I6 -> 0.05 | N7: Avid Option 1 | O7: 5 | P7: =Table2[[#This Row],[Beginning Debt ($M)]] -> 821649.21 | Q7: ='Income Statement'!M22 -> 7242363.1 | R7: =P7/Q7 -> 0.11345043 | S7: =S6 -> 3 | T7: =(Q7-Z7)/E7 -> 5.2088919 | U7: 1.25 | V7: =IF(Table1[[#This Row],[FCC Limit]]<Table1[[#This Row],[Fixed Charge Coverage]]," ", "Breach") | Z7: 2962481.2
B9: Debt Package | C9: Year | D9: Beginning Debt ($M) | E9: Total Payment | F9: Principle Payment | G9: Interest Expense | H9: Ending Debt ($M) | I9: Interest Rate | N9: Debt Package | O9: Year | P9: Debt | Q9: Ebitda | R9: Debt/Ebitda | S9: Covenant | T9: Fixed Charge Coverage | U9: FCC Limit | V9: Debt/EBITDA BREACH | W9: FCC Breach
B10: Avid Option 2 | C10: 1 | D10: ='5.d IRR and COC Forecasts'!F4 -> 4929895.3 | E10: =D10*0.125 -> 616236.91 | F10: =E10-G10 -> 362039.18 | G10: =((H10+D10)/2)*I10 -> 254197.72 | H10: =D10-E10 -> 4313658.4 | I10: ='5.d IRR and COC Forecasts'!D4 -> 0.055 | N10: Avid Option 2 | O10: 1 | P10: =Table4[[#This Row],[Beginning Debt ($M)]] -> 4929895.3 | Q10: =Q3 -> 3286596.8 | R10: =P10/Q10 -> 1.5 | S10: 3 | T10: =(Q10-Z3)/E10 -> 3.004164 | U10: 1.25 | V10: =IF(Table8[[#This Row],[Covenant]]>Table8[[#This Row],[Debt/Ebitda]]," ", "Breach") | W10: =IF(Table8[[#This Row],[FCC Limit]]<Table8[[#This Row],[Fixed Charge Coverage]]," ", "Breach")
B11: Avid Option 2 | C11: 2 | D11: =H10 -> 4313658.4 | E11: =D10*0.125 -> 616236.91 | F11: =E11-G11 -> 395932.21 | G11: =((H11+D11)/2)*I11 -> 220304.69 | H11: =D11-E11 -> 3697421.4 | I11: =I10 -> 0.055 | N11: Avid Option 2 | O11: 2 | P11: =Table4[[#This Row],[Beginning Debt ($M)]] -> 4313658.4 | Q11: =Q4 -> 4225351.3 | R11: =P11/Q11 -> 1.0208993 | S11: =S10 -> 3 | T11: =(Q11-Z4)/E11 -> 3.8392996 | U11: 1.25 | V11: =IF(Table8[[#This Row],[Covenant]]>Table8[[#This Row],[Debt/Ebitda]]," ", "Breach") | W11: =IF(Table8[[#This Row],[FCC Limit]]<Table8[[#This Row],[Fixed Charge Coverage]]," ", "Breach")
B12: Avid Option 2 | C12: 3 | D12: =H11 -> 3697421.4 | E12: =D10*0.25 -> 1232473.8 | F12: =E12-G12 -> 1063008.7 | G12: =((H12+D12)/2)*I12 -> 169465.15 | H12: =D12-E12 -> 2464947.6 | I12: =I11 -> 0.055 | N12: Avid Option 2 | O12: 3 | P12: =Table4[[#This Row],[Beginning Debt ($M)]] -> 3697421.4 | Q12: =Q5 -> 4995287.8 | R12: =P12/Q12 -> 0.74018186 | S12: =S11 -> 3 | T12: =(Q12-Z5)/E12 -> 2.3469695 | U12: 1.25 | V12: =IF(Table8[[#This Row],[Covenant]]>Table8[[#This Row],[Debt/Ebitda]]," ", "Breach") | W12: =IF(Table8[[#This Row],[FCC Limit]]<Table8[[#This Row],[Fixed Charge Coverage]]," ", "Breach")
B13: Avid Option 2 | C13: 4 | D13: =H12 -> 2464947.6 | E13: =D10*0.25 -> 1232473.8 | F13: =E13-G13 -> 1130794.7 | G13: =((H13+D13)/2)*I13 -> 101679.09 | H13: =D13-E13 -> 1232473.8 | I13: =I12 -> 0.055 | N13: Avid Option 2 | O13: 4 | P13: =Table4[[#This Row],[Beginning Debt ($M)]] -> 2464947.6 | Q13: =Q6 -> 5980202.5 | R13: =P13/Q13 -> 0.41218465 | S13: =S12 -> 3 | T13: =(Q13-Z6)/E13 -> 2.8035928 | U13: 1.25 | V13: =IF(Table8[[#This Row],[Covenant]]>Table8[[#This Row],[Debt/Ebitda]]," ", "Breach") | W13: =IF(Table8[[#This Row],[FCC Limit]]<Table8[[#This Row],[Fixed Charge Coverage]]," ", "Breach")
B14: Avid Option 2 | C14: 5 | D14: =H13 -> 1232473.8 | E14: =D10*0.25 -> 1232473.8 | F14: =E14-G14 -> 1198580.8 | G14: =((H14+D14)/2)*I14 -> 33893.03 | H14: =D14-E14 -> 0 | I14: =I13 -> 0.055 | N14: Avid Option 2 | O14: 5 | P14: =Table4[[#This Row],[Beginning Debt ($M)]] -> 1232473.8 | Q14: =Q7 -> 7242363.1 | R14: =P14/Q14 -> 0.17017565 | S14: =S13 -> 3 | T14: =(Q14-Z7)/E14 -> 3.4725946 | U14: 1.25 | V14: =IF(Table8[[#This Row],[Covenant]]>Table8[[#This Row],[Debt/Ebitda]]," ", "Breach") | W14: =IF(Table8[[#This Row],[FCC Limit]]<Table8[[#This Row],[Fixed Charge Coverage]]," ", "Breach")
B16: Debt Package | C16: Year | D16: Beginning Debt ($M) | E16: Total Payment | F16: Principle Payment | G16: Interest Expense | H16: Ending Debt ($M) | I16: Interest Rate | N16: Debt Package | O16: Year | P16: Debt | Q16: Ebitda | R16: Debt/Ebitda | S16: Covenant | T16: Fixed Charge Coverage | U16: FCC Limit | V16: Debt/EBITDA BREACH | W16: FCC Breach
B17: Avid Option 3 | C17: 1 | D17: ='5.d IRR and COC Forecasts'!F5 -> 6573193.7 | E17: =D17*0.125 -> 821649.21 | F17: =E17-G17 -> 451907.07 | G17: =((H17+D17)/2)*I17 -> 369742.14 | H17: =D17-E17 -> 5751544.5 | I17: ='5.d IRR and COC Forecasts'!D5 -> 0.06 | N17: Avid Option 3 | O17: 1 | P17: =Table5[[#This Row],[Beginning Debt ($M)]] -> 6573193.7 | Q17: =Q10 -> 3286596.8 | R17: =P17/Q17 -> 2 | S17: 3 | T17: =(Q17-Z3)/E17 -> 2.253123 | U17: 1.25 | V17: =IF(Table16[[#This Row],[Covenant]]>Table16[[#This Row],[Debt/Ebitda]]," ", "Breach")
B18: Avid Option 3 | C18: 2 | D18: =H17 -> 5751544.5 | E18: =D17*0.125 -> 821649.21 | F18: =E18-G18 -> 501206.02 | G18: =((H18+D18)/2)*I18 -> 320443.19 | H18: =D18-E18 -> 4929895.3 | I18: =I17 -> 0.06 | N18: Avid Option 3 | O18: 2 | P18: =Table5[[#This Row],[Beginning Debt ($M)]] -> 5751544.5 | Q18: =Q11 -> 4225351.3 | R18: =P18/Q18 -> 1.3611991 | S18: =S17 -> 3 | T18: =(Q18-Z4)/E18 -> 2.8794747 | U18: 1.25 | V18: =IF(Table16[[#This Row],[Covenant]]>Table16[[#This Row],[Debt/Ebitda]]," ", "Breach")
B19: Avid Option 3 | C19: 3 | D19: =H18 -> 4929895.3 | E19: =D17*0.25 -> 1643298.4 | F19: =E19-G19 -> 1396803.7 | G19: =((H19+D19)/2)*I19 -> 246494.76 | H19: =D19-E19 -> 3286596.8 | I19: =I18 -> 0.06 | N19: Avid Option 3 | O19: 3 | P19: =Table5[[#This Row],[Beginning Debt ($M)]] -> 4929895.3 | Q19: =Q12 -> 4995287.8 | R19: =P19/Q19 -> 0.98690915 | S19: =S18 -> 3 | T19: =(Q19-Z5)/E19 -> 1.7602271 | U19: 1.25 | V19: =IF(Table16[[#This Row],[Covenant]]>Table16[[#This Row],[Debt/Ebitda]]," ", "Breach") | X19: So we select this one as highest IRR and no breaches forecasted
B20: Avid Option 3 | C20: 4 | D20: =H19 -> 3286596.8 | E20: =D17*0.25 -> 1643298.4 | F20: =E20-G20 -> 1495401.6 | G20: =((H20+D20)/2)*I20 -> 147896.86 | H20: =D20-E20 -> 1643298.4 | I20: =I19 -> 0.06 | N20: Avid Option 3 | O20: 4 | P20: =Table5[[#This Row],[Beginning Debt ($M)]] -> 3286596.8 | Q20: =Q13 -> 5980202.5 | R20: =P20/Q20 -> 0.54957953 | S20: =S19 -> 3 | T20: =(Q20-Z6)/E20 -> 2.1026946 | U20: 1.25 | V20: =IF(Table16[[#This Row],[Covenant]]>Table16[[#This Row],[Debt/Ebitda]]," ", "Breach")
B21: Avid Option 3 | C21: 5 | D21: =H20 -> 1643298.4 | E21: =D17*0.25 -> 1643298.4 | F21: =E21-G21 -> 1593999.5 | G21: =((H21+D21)/2)*I21 -> 49298.953 | H21: =D21-E21 -> 0 | I21: =I20 -> 0.06 | N21: Avid Option 3 | O21: 5 | P21: =Table5[[#This Row],[Beginning Debt ($M)]] -> 1643298.4 | Q21: =Q14 -> 7242363.1 | R21: =P21/Q21 -> 0.22690086 | S21: =S20 -> 3 | T21: =(Q21-Z7)/E21 -> 2.604446 | U21: 1.25 | V21: =IF(Table16[[#This Row],[Covenant]]>Table16[[#This Row],[Debt/Ebitda]]," ", "Breach")
B23: Debt Package | C23: Year | D23: Beginning Debt ($M) | E23: Total Payment | F23: Principle Payment | G23: Interest Expense | H23: Ending Debt ($M) | I23: Interest Rate | N23: Debt Package | O23: Year | P23: Debt | Q23: Ebitda | R23: Debt/Ebitda | S23: Covenant | T23: Fixed Charge Coverage | U23: FCC Limit | V23: Debt/EBITDA BREACH | W23: FCC Breach
B24: Avid Option 4 | C24: 1 | D24: ='5.d IRR and COC Forecasts'!F6 -> 8216492.1 | E24: =D24*0.125 -> 1027061.5 | F24: =E24-G24 -> 526369.03 | G24: =((H24+D24)/2)*I24 -> 500692.49 | H24: =D24-E24 -> 7189430.6 | I24: ='5.d IRR and COC Forecasts'!D6 -> 0.065 | N24: Avid Option 4 | O24: 1 | P24: =Table6[[#This Row],[Beginning Debt ($M)]] -> 8216492.1 | Q24: =Q17 -> 3286596.8 | R24: =P24/Q24 -> 2.5 | S24: 3 | T24: =(Q24-Z3)/E24 -> 1.8024984 | U24: 1.25 | V24: =IF(Table17[[#This Row],[Covenant]]>Table17[[#This Row],[Debt/Ebitda]]," ", "Breach") | W24: =IF(Table17[[#This Row],[FCC Limit]]<Table17[[#This Row],[Fixed Charge Coverage]]," ", "Breach")
B25: Avid Option 4 | C25: 2 | D25: =H24 -> 7189430.6 | E25: =D24*0.125 -> 1027061.5 | F25: =E25-G25 -> 593128.02 | G25: =((H25+D25)/2)*I25 -> 433933.49 | H25: =D25-E25 -> 6162369.1 | I25: =I24 -> 0.065 | N25: Avid Option 4 | O25: 2 | P25: =Table6[[#This Row],[Beginning Debt ($M)]] -> 7189430.6 | Q25: =Q18 -> 4225351.3 | R25: =P25/Q25 -> 1.7014989 | S25: =S24 -> 3 | T25: =(Q25-Z4)/E25 -> 2.3035798 | U25: 1.25 | V25: =IF(Table17[[#This Row],[Covenant]]>Table17[[#This Row],[Debt/Ebitda]]," ", "Breach") | W25: =IF(Table17[[#This Row],[FCC Limit]]<Table17[[#This Row],[Fixed Charge Coverage]]," ", "Breach")
B26: Avid Option 4 | C26: 3 | D26: =H25 -> 6162369.1 | E26: =D24*0.25 -> 2054123 | F26: =E26-G26 -> 1720328 | G26: =((H26+D26)/2)*I26 -> 333794.99 | H26: =D26-E26 -> 4108246.1 | I26: =I25 -> 0.065 | N26: Avid Option 4 | O26: 3 | P26: =Table6[[#This Row],[Beginning Debt ($M)]] -> 6162369.1 | Q26: =Q19 -> 4995287.8 | R26: =P26/Q26 -> 1.2336364 | S26: =S25 -> 3 | T26: 1.2 | U26: 1.25 | V26: =IF(Table17[[#This Row],[Covenant]]>Table17[[#This Row],[Debt/Ebitda]]," ", "Breach") | W26: =IF(Table17[[#This Row],[FCC Limit]]<Table17[[#This Row],[Fixed Charge Coverage]]," ", "Breach") -> Breach
B27: Avid Option 4 | C27: 4 | D27: =H26 -> 4108246.1 | E27: =D24*0.25 -> 2054123 | F27: =E27-G27 -> 1853846 | G27: =((H27+D27)/2)*I27 -> 200277 | H27: =D27-E27 -> 2054123 | I27: =I26 -> 0.065 | N27: Avid Option 4 | O27: 4 | P27: =Table6[[#This Row],[Beginning Debt ($M)]] -> 4108246.1 | Q27: =Q20 -> 5980202.5 | R27: =P27/Q27 -> 0.68697441 | S27: =S26 -> 3 | T27: =(Q27-Z6)/E27 -> 1.6821557 | U27: 1.25 | V27: =IF(Table17[[#This Row],[Covenant]]>Table17[[#This Row],[Debt/Ebitda]]," ", "Breach") | W27: =IF(Table17[[#This Row],[FCC Limit]]<Table17[[#This Row],[Fixed Charge Coverage]]," ", "Breach")
B28: Avid Option 4 | C28: 5 | D28: =H27 -> 2054123 | E28: =D24*0.25 -> 2054123 | F28: =E28-G28 -> 1987364 | G28: =((H28+D28)/2)*I28 -> 66758.998 | H28: =D28-E28 -> 0 | I28: =I27 -> 0.065 | N28: Avid Option 4 | O28: 5 | P28: =Table6[[#This Row],[Beginning Debt ($M)]] -> 2054123 | Q28: =Q21 -> 7242363.1 | R28: =P28/Q28 -> 0.28362608 | S28: =S27 -> 3 | T28: =(Q28-Z7)/E28 -> 2.0835568 | U28: 1.25 | V28: =IF(Table17[[#This Row],[Covenant]]>Table17[[#This Row],[Debt/Ebitda]]," ", "Breach") | W28: =IF(Table17[[#This Row],[FCC Limit]]<Table17[[#This Row],[Fixed Charge Coverage]]," ", "Breach")
B30: Debt Package | C30: Year | D30: Beginning Debt ($M) | E30: Total Payment | F30: Principle Payment | G30: Interest Expense | H30: Ending Debt ($M) | I30: Interest Rate | N30: Debt Package | O30: Year | P30: Debt | Q30: Ebitda | R30: Debt/Ebitda | S30: Covenant | T30: Fixed Charge Coverage | U30: FCC Limit | V30: Debt/EBITDA BREACH | W30: FCC Breach
B31: Avid Option 5 | C31: 1 | D31: ='5.d IRR and COC Forecasts'!F7 -> 9859790.5 | E31: =D31*0.125 -> 1232473.8 | F31: =E31-G31 -> 585425.06 | G31: =((H31+D31)/2)*I31 -> 647048.75 | H31: =D31-E31 -> 8627316.7 | I31: ='5.d IRR and COC Forecasts'!D7 -> 0.07 | N31: Avid Option 5 | O31: 1 | P31: =Table10[[#This Row],[Beginning Debt ($M)]] -> 9859790.5 | Q31: =Q24 -> 3286596.8 | R31: =P31/Q31 -> 3 | S31: 3 | T31: =(Q31-Z3)/E31 -> 1.502082 | U31: 1.25 | V31: =IF(Table18[[#This Row],[Covenant]]>Table18[[#This Row],[Debt/Ebitda]]," ", "Breach") -> Breach | W31: =IF(Table18[[#This Row],[FCC Limit]]<Table18[[#This Row],[Fixed Charge Coverage]]," ", "Breach")
B32: Avid Option 5 | C32: 2 | D32: =H31 -> 8627316.7 | E32: =D31*0.125 -> 1232473.8 | F32: =E32-G32 -> 671698.23 | G32: =((H32+D32)/2)*I32 -> 560775.59 | H32: =D32-E32 -> 7394842.9 | I32: =I31 -> 0.07 | N32: Avid Option 5 | O32: 2 | P32: =Table10[[#This Row],[Beginning Debt ($M)]] -> 8627316.7 | Q32: =Q25 -> 4225351.3 | R32: =P32/Q32 -> 2.0417987 | S32: =S31 -> 3 | T32: =(Q32-Z4)/E32 -> 1.9196498 | U32: 1.25 | V32: =IF(Table18[[#This Row],[Covenant]]>Table18[[#This Row],[Debt/Ebitda]]," ", "Breach") | W32: =IF(Table18[[#This Row],[FCC Limit]]<Table18[[#This Row],[Fixed Charge Coverage]]," ", "Breach")
B33: Avid Option 5 | C33: 3 | D33: =H32 -> 7394842.9 | E33: =D31*0.25 -> 2464947.6 | F33: =E33-G33 -> 2033581.8 | G33: =((H33+D33)/2)*I33 -> 431365.84 | H33: =D33-E33 -> 4929895.3 | I33: =I32 -> 0.07 | N33: Avid Option 5 | O33: 3 | P33: =Table10[[#This Row],[Beginning Debt ($M)]] -> 7394842.9 | Q33: =Q26 -> 4995287.8 | R33: =P33/Q33 -> 1.4803637 | S33: =S32 -> 3 | T33: =(Q33-Z5)/E33 -> 1.1734848 | U33: 1.25 | V33: =IF(Table18[[#This Row],[Covenant]]>Table18[[#This Row],[Debt/Ebitda]]," ", "Breach") | W33: =IF(Table18[[#This Row],[FCC Limit]]<Table18[[#This Row],[Fixed Charge Coverage]]," ", "Breach") -> Breach
B34: Avid Option 5 | C34: 4 | D34: =H33 -> 4929895.3 | E34: =D31*0.25 -> 2464947.6 | F34: =E34-G34 -> 2206128.1 | G34: =((H34+D34)/2)*I34 -> 258819.5 | H34: =D34-E34 -> 2464947.6 | I34: =I33 -> 0.07 | N34: Avid Option 5 | O34: 4 | P34: =Table10[[#This Row],[Beginning Debt ($M)]] -> 4929895.3 | Q34: =Q27 -> 5980202.5 | R34: =P34/Q34 -> 0.82436929 | S34: =S33 -> 3 | T34: =(Q34-Z6)/E34 -> 1.4017964 | U34: 1.25 | V34: =IF(Table18[[#This Row],[Covenant]]>Table18[[#This Row],[Debt/Ebitda]]," ", "Breach") | W34: =IF(Table18[[#This Row],[FCC Limit]]<Table18[[#This Row],[Fixed Charge Coverage]]," ", "Breach")
B35: Avid Option 5 | C35: 5 | D35: =H34 -> 2464947.6 | E35: =D31*0.25 -> 2464947.6 | F35: =E35-G35 -> 2378674.5 | G35: =((H35+D35)/2)*I35 -> 86273.167 | H35: =D35-E35 -> 0 | I35: =I34 -> 0.07 | N35: Avid Option 5 | O35: 5 | P35: =Table10[[#This Row],[Beginning Debt ($M)]] -> 2464947.6 | Q35: =Q28 -> 7242363.1 | R35: =P35/Q35 -> 0.34035129 | S35: =S34 -> 3 | T35: =(Q35-Z7)/E35 -> 1.7362973 | U35: 1.25 | V35: =IF(Table18[[#This Row],[Covenant]]>Table18[[#This Row],[Debt/Ebitda]]," ", "Breach") | W35: =IF(Table18[[#This Row],[FCC Limit]]<Table18[[#This Row],[Fixed Charge Coverage]]," ", "Breach")
B37: Debt Package | C37: Year | D37: Beginning Debt ($M) | E37: Total Payment | F37: Principle Payment | G37: Interest Expense | H37: Ending Debt ($M) | I37: Interest Rate | N37: Debt Package | O37: Year | P37: Debt | Q37: Ebitda | R37: Debt/Ebitda | S37: Covenant | T37: Fixed Charge Coverage | U37: FCC Limit | V37: Debt/EBITDA BREACH | W37: FCC Breach
B38: Saratoga Option 1 | C38: 1 | D38: ='5.d IRR and COC Forecasts'!F8 -> 6573193.7 | G38: =((H38+D38)/2)*I38 -> 591587.43 | H38: =D38-Table11[[#This Row],[Total Payment]] -> 6573193.7 | I38: ='5.d IRR and COC Forecasts'!D8 -> 0.09 | N38: Saratoga Option 1 | O38: 1 | P38: =Table11[[#This Row],[Beginning Debt ($M)]] -> 6573193.7 | Q38: =Q31 -> 3286596.8 | R38: =P38/Q38 -> 2 | S38: 4 | T38: =(Q38-Z3)/(F38+G38) -> 3.1293375 | U38: 1.1 | V38: =IF(Table19[[#This Row],[Covenant]]>Table19[[#This Row],[Debt/Ebitda]]," ", "Breach") | W38: =IF(Table19[[#This Row],[FCC Limit]]<Table19[[#This Row],[Fixed Charge Coverage]]," ", "Breach")
B39: Saratoga Option 1 | C39: 2 | D39: ='5.d IRR and COC Forecasts'!F9 -> 8216492.1 | G39: =((H39+D39)/2)*I39 -> 739484.29 | H39: =D39-Table11[[#This Row],[Total Payment]] -> 8216492.1 | I39: =I38 -> 0.09 | N39: Saratoga Option 1 | O39: 2 | P39: =Table11[[#This Row],[Beginning Debt ($M)]] -> 8216492.1 | Q39: =Q32 -> 4225351.3 | R39: =P39/Q39 -> 1.9445702 | S39: 3.5 | T39: =(Q39-Z4)/(F39+G39) -> 3.1994164 | U39: 1.25 | V39: =IF(Table19[[#This Row],[Covenant]]>Table19[[#This Row],[Debt/Ebitda]]," ", "Breach") | W39: =IF(Table19[[#This Row],[FCC Limit]]<Table19[[#This Row],[Fixed Charge Coverage]]," ", "Breach")
B40: Saratoga Option 1 | C40: 3 | D40: ='5.d IRR and COC Forecasts'!F10 -> 9859790.5 | E40: =D38*0.1 -> 657319.37 | F40: =E40-G40 -> -200482.41 | G40: =((H40+D40)/2)*I40 -> 857801.78 | H40: =D40-Table11[[#This Row],[Total Payment]] -> 9202471.2 | I40: =I39 -> 0.09 | N40: Saratoga Option 1 | O40: 3 | P40: =Table11[[#This Row],[Beginning Debt ($M)]] -> 9859790.5 | Q40: =Q33 -> 4995287.8 | R40: =P40/Q40 -> 1.9738183 | S40: 3 | T40: =(Q40-Z5)/(F40+G40) -> 4.4005678 | U40: 1.5 | V40: =IF(Table19[[#This Row],[Covenant]]>Table19[[#This Row],[Debt/Ebitda]]," ", "Breach") | W40: =IF(Table19[[#This Row],[FCC Limit]]<Table19[[#This Row],[Fixed Charge Coverage]]," ", "Breach")
B41: Saratoga Option 1 | C41: 4 | D41: ='5.d IRR and COC Forecasts'!F11 -> 11503089 | E41: =D38*0.15 -> 985979.05 | F41: =E41-G41 -> -4929.8953 | G41: =((H41+D41)/2)*I41 -> 990908.95 | H41: =D41-Table11[[#This Row],[Total Payment]] -> 10517110 | I41: =I40 -> 0.09 | N41: Saratoga Option 1 | O41: 4 | P41: =Table11[[#This Row],[Beginning Debt ($M)]] -> 11503089 | Q41: =Q34 -> 5980202.5 | R41: =P41/Q41 -> 1.9235283 | S41: 2.5 | T41: =(Q41-Z6)/(F41+G41) -> 3.504491 | U41: 2 | V41: =IF(Table19[[#This Row],[Covenant]]>Table19[[#This Row],[Debt/Ebitda]]," ", "Breach") | W41: =IF(Table19[[#This Row],[FCC Limit]]<Table19[[#This Row],[Fixed Charge Coverage]]," ", "Breach")
B42: Saratoga Option 1 | C42: 5 | D42: ='5.d IRR and COC Forecasts'!F12 -> 13146387 | E42: =D38*0.75 -> 4929895.3 | F42: =E42-G42 -> 3968565.7 | G42: =((H42+D42)/2)*I42 -> 961329.58 | H42: =D42-Table11[[#This Row],[Total Payment]] -> 8216492.1 | I42: =I41 -> 0.09 | N42: Saratoga Option 1 | O42: 5 | P42: =Table11[[#This Row],[Beginning Debt ($M)]] -> 13146387 | Q42: =Q35 -> 7242363.1 | R42: =P42/Q42 -> 1.8152069 | S42: 2 | T42: =(Q42-Z7)/(F42+G42) -> 0.86814865 | U42: 2.5 | V42: =IF(Table19[[#This Row],[Covenant]]>Table19[[#This Row],[Debt/Ebitda]]," ", "Breach") | W42: =IF(Table19[[#This Row],[FCC Limit]]<Table19[[#This Row],[Fixed Charge Coverage]]," ", "Breach") -> Breach
B44: Debt Package | C44: Year | D44: Beginning Debt ($M) | E44: Total Payment | F44: Principle Payment | G44: Interest Expense | H44: Ending Debt ($M) | I44: Interest Rate | N44: Debt Package | O44: Year | P44: Debt | Q44: Ebitda | R44: Debt/Ebitda | S44: Covenant | T44: Fixed Charge Coverage | U44: FCC Limit | V44: Debt/EBITDA BREACH | W44: FCC Breach
B45: Saratoga Option 2 | C45: 1 | D45: ='5.d IRR and COC Forecasts'!F9 -> 8216492.1 | G45: =((H45+D45)/2)*I45 -> 821649.21 | H45: =D45-E45 -> 8216492.1 | I45: ='5.d IRR and COC Forecasts'!D9 -> 0.1 | N45: Saratoga Option 2 | O45: 1 | P45: =Table12[[#This Row],[Beginning Debt ($M)]] -> 8216492.1 | Q45: =Q38 -> 3286596.8 | R45: =P45/Q45 -> 2.5 | S45: 4 | T45: =(Q45-Z3)/(F45+G45) -> 2.253123 | U45: 1.1 | V45: =IF(Table20[[#This Row],[Covenant]]>Table20[[#This Row],[Debt/Ebitda]]," ", "Breach") | W45: =IF(Table20[[#This Row],[FCC Limit]]<Table20[[#This Row],[Fixed Charge Coverage]]," ", "Breach")
B46: Saratoga Option 2 | C46: 2 | D46: =H45 -> 8216492.1 | G46: =((H46+D46)/2)*I46 -> 821649.21 | H46: =D46-E46 -> 8216492.1 | I46: =I45 -> 0.1 | N46: Saratoga Option 2 | O46: 2 | P46: =Table12[[#This Row],[Beginning Debt ($M)]] -> 8216492.1 | Q46: =Q39 -> 4225351.3 | R46: =P46/Q46 -> 1.9445702 | S46: 3.5 | T46: =(Q46-Z4)/(F46+G46) -> 2.8794747 | U46: 1.25 | V46: =IF(Table20[[#This Row],[Covenant]]>Table20[[#This Row],[Debt/Ebitda]]," ", "Breach") | W46: =IF(Table20[[#This Row],[FCC Limit]]<Table20[[#This Row],[Fixed Charge Coverage]]," ", "Breach")
B47: Saratoga Option 2 | C47: 3 | D47: =H46 -> 8216492.1 | E47: =D45*0.1 -> 821649.21 | F47: =E47-G47 -> 41082.461 | G47: =((H47+D47)/2)*I47 -> 780566.75 | H47: =D47-E47 -> 7394842.9 | I47: =I46 -> 0.1 | N47: Saratoga Option 2 | O47: 3 | P47: =Table12[[#This Row],[Beginning Debt ($M)]] -> 8216492.1 | Q47: =Q40 -> 4995287.8 | R47: =P47/Q47 -> 1.6448486 | S47: 3 | T47: =(Q47-Z5)/(F47+G47) -> 3.5204543 | U47: 1.5 | V47: =IF(Table20[[#This Row],[Covenant]]>Table20[[#This Row],[Debt/Ebitda]]," ", "Breach") | W47: =IF(Table20[[#This Row],[FCC Limit]]<Table20[[#This Row],[Fixed Charge Coverage]]," ", "Breach")
...

Sheet 5.d IRR and COC Forecasts
L1: ASSUMING 5.1 AT EXIT
