Workbook

Sheet Read Me
B2: Distribution Waterfall Model
B3: Project Longhorn - Mid-Market Buyout Co-Investment (Illustrative)
B5: Prepared by: | C5: Akul Veauli
B6: Date: | C6: 46256
B8: Model Purpose
B9: This workbook is an original, fictional illustration of a private-equity 4-tier American (deal-by-deal) distribution waterfall with a GP catch-up, built for a single hypothetical co-investment ("Project Longhorn"). It models the underlying company's cash flows from entry to a Year-5 exit, then cascades those cash flows through the four waterfall tiers - return of capital, preferred return, GP catch-up, and carried-interest split - to determine LP and GP distributions, IRR, and MOIC. All figures are illustrative and not connected to any real fund, sponsor, or transaction.
B16: Color Key / Convention
B17: Blue font | C17: Hard-coded input - change these to run different scenarios.
B18: Black font | C18: Calculated with a live Excel formula - do not overwrite.
B19: Navy header bar | C19: Section header / tab title band.
B20: Light-blue band | C20: Sub-section header within a tab.
B22: Tab Guide
B23: Read Me | C23: This page: purpose, conventions, and navigation.
B24: Assumptions | C24: All deal, company, and waterfall-term inputs in one place.
B25: Deal Cash Flows | C25: Underlying company EBITDA, FCF, debt paydown, and resulting total equity cash flow by year (0–5).
B26: Waterfall | C26: The four-tier deal-by-deal cascade: Return of Capital, Preferred Return, GP Catch-Up, Carry Split.
B27: Returns Summary | C27: LP / GP contributed, distributed, profit, IRR, MOIC, and an effective-carry check.
B28: Sensitivity | C28: Closed-form grids of exit proceeds / gross MOIC across exit multiple and EBITDA growth.
B30: Waterfall Mechanics Notes
B31: • Preferred return (8%, simple, accrued annually on unreturned capital) accrues to LP and GP pro-rata on their own unreturned capital balances; both classes receive Tier 2 pref before any catch-up occurs. This is a standard (though not universal) treatment - some deals pay pref to LP only.
B32: • GP catch-up target uses the standard formula: cumulative catch-up target = [carry % / (1 - carry %)] × cumulative Tier 2 (preferred return) distributions paid to date (LP + GP combined). GP receives 100% of available cash until this target is met, capped by cash actually available (MIN formula) so the model never over-distributes.
B33: • All tiers cascade using MIN / MAX formulas so a tier can never distribute more than the cash remaining after the prior tier, and balances (unreturned capital, unpaid pref) can never go negative.
B34: • Amounts throughout are in $ millions ($M) unless a cell's number format states otherwise.

Sheet Assumptions
B2: Assumptions - Project Longhorn
B3: All inputs in blue; all calculated cells in black. Dollar amounts in $ millions ($M).
B5: Deal & Capitalization
B6: Total Equity Invested ($M) | C6: 150
B7: LP Commitment % | C7: 0.9
B8: GP Commitment % | C8: 0.1
B9: LP Commitment ($M) | C9: =Assumptions!$C$6*Assumptions!$C$7
B10: GP Commitment ($M) | C10: =Assumptions!$C$6*Assumptions!$C$8
B11: Investment Timing | C11: End of Year 0
B12: Exit Timing | C12: End of Year 5
B14: Company & Operating Assumptions
B15: Entry EBITDA ($M) | C15: 28
B16: Entry EV / EBITDA Multiple (x) | C16: 8.5
B17: Entry Net Debt ($M) | C17: 88
B18: Entry Enterprise Value ($M) | C18: =Assumptions!$C$15*Assumptions!$C$16
B19: EBITDA Growth Rate (%/yr) | C19: 0.08
B20: FCF Conversion (% of EBITDA) | C20: 0.45
B21: Exit EV / EBITDA Multiple (x) | C21: 8
B22: Interim Dividend - Year 3 ($M) | C22: 8
B23: Interim Dividend - Year 4 ($M) | C23: 10
B25: Waterfall Terms
B26: Preferred Return Rate (annual, simple on unreturned capital) | C26: 0.08
B27: GP Catch-Up % | C27: 1
B28: Carried Interest % (GP, Tier 4) | C28: 0.2
B29: LP Residual % (Tier 4) | C29: =1-Assumptions!$C$28
B31: Note: Tier 2 preferred return is paid to LP and GP pro-rata on their own unreturned capital (standard treatment used in this model - see Read Me). Tier 3 GP catch-up target = [Carry % / (1 − Carry %)] × cumulative Tier 2 distributions (LP+GP).

Sheet Deal Cash Flows
B2: Deal Cash Flows - Project Longhorn (Underlying Company)
B3: Amounts in $ millions ($M). Investment at end of Year 0; exit at end of Year 5.
B5: Year | C5: Year 0 | D5: Year 1 | E5: Year 2 | F5: Year 3 | G5: Year 4 | H5: Year 5
B6: Operating Roll-Forward
B7: EBITDA ($M) | C7: =Assumptions!$C$15 | D7: =C7*(1+Assumptions!$C$19) | E7: =D7*(1+Assumptions!$C$19) | F7: =E7*(1+Assumptions!$C$19) | G7: =F7*(1+Assumptions!$C$19) | H7: =G7*(1+Assumptions!$C$19)
B8: Free Cash Flow ($M) [= EBITDA × FCF Conversion] | C8: =0 | D8: =D7*Assumptions!$C$20 | E8: =E7*Assumptions!$C$20 | F8: =F7*Assumptions!$C$20 | G8: =G7*Assumptions!$C$20 | H8: =H7*Assumptions!$C$20
B9: Debt Schedule
B10: Beginning Net Debt ($M) | C10: =Assumptions!$C$17 | D10: =C12 | E10: =D12 | F10: =E12 | G10: =F12 | H10: =G12
B11: Debt Paydown ($M) [= FCF − Dividend] | C11: =0 | D11: =D8-D14 | E11: =E8-E14 | F11: =F8-F14 | G11: =G8-G14 | H11: =H8-H14
B12: Ending Net Debt ($M) | C12: =C10 | D12: =MAX(0,D10-D11) | E12: =MAX(0,E10-E11) | F12: =MAX(0,F10-F11) | G12: =MAX(0,G10-G11) | H12: =MAX(0,H10-H11)
B14: Interim Dividend Paid ($M) | C14: =0 | D14: =0 | E14: =0 | F14: =Assumptions!$C$22 | G14: =Assumptions!$C$23 | H14: =0
B15: Exit
B16: Exit Enterprise Value ($M) [= Exit Multiple × Year 5 EBITDA] | C16: =0 | D16: =0 | E16: =0 | F16: =0 | G16: =0 | H16: =Assumptions!$C$21*H7
B17: Exit Equity Proceeds ($M) [= Exit EV − Ending Net Debt] | C17: =0 | D17: =0 | E17: =0 | F17: =0 | G17: =0 | H17: =H16-H12
B18: Total Equity Cash Flow
B19: Total Equity Cash Flow ($M) | C19: =-Assumptions!$C$6 | D19: =0 | E19: =0 | F19: =F14 | G19: =G14 | H19: =H14+H17

Sheet Waterfall
B2: Waterfall - 4-Tier American (Deal-by-Deal) Cascade
B3: Amounts in $ millions ($M). Cascades top to bottom; MIN/MAX formulas prevent over-distribution.
B5: Year | C5: Year 0 | D5: Year 1 | E5: Year 2 | F5: Year 3 | G5: Year 4 | H5: Year 5
B6: Capital Contributions & Cash Available
B7: LP Contribution ($M) | C7: =Assumptions!$C$9 | D7: =0 | E7: =0 | F7: =0 | G7: =0 | H7: =0
B8: GP Contribution ($M) | C8: =Assumptions!$C$10 | D8: =0 | E8: =0 | F8: =0 | G8: =0 | H8: =0
B9: Cash Available for Distribution ($M) | C9: =MAX('Deal Cash Flows'!C19,0) | D9: =MAX('Deal Cash Flows'!D19,0) | E9: =MAX('Deal Cash Flows'!E19,0) | F9: =MAX('Deal Cash Flows'!F19,0) | G9: =MAX('Deal Cash Flows'!G19,0) | H9: =MAX('Deal Cash Flows'!H19,0)
B11: TIER 1 - Return of Capital (pro-rata 90/10 until fully returned)
B12: LP Unreturned Capital - Beginning ($M) | C12: =0 | D12: =C17 | E12: =D17 | F12: =E17 | G12: =F17 | H12: =G17
B13: GP Unreturned Capital - Beginning ($M) | C13: =0 | D13: =C18 | E13: =D18 | F13: =E18 | G13: =F18 | H13: =G18
B14: Tier 1 Distributable ($M) | C14: =MIN(C9,C12+C13) | D14: =MIN(D9,D12+D13) | E14: =MIN(E9,E12+E13) | F14: =MIN(F9,F12+F13) | G14: =MIN(G9,G12+G13) | H14: =MIN(H9,H12+H13)
B15: Tier 1 Distribution - LP ($M) | C15: =IF((C12+C13)=0,0,C14*C12/(C12+C13)) | D15: =IF((D12+D13)=0,0,D14*D12/(D12+D13)) | E15: =IF((E12+E13)=0,0,E14*E12/(E12+E13)) | F15: =IF((F12+F13)=0,0,F14*F12/(F12+F13)) | G15: =IF((G12+G13)=0,0,G14*G12/(G12+G13)) | H15: =IF((H12+H13)=0,0,H14*H12/(H12+H13))
B16: Tier 1 Distribution - GP ($M) | C16: =C14-C15 | D16: =D14-D15 | E16: =E14-E15 | F16: =F14-F15 | G16: =G14-G15 | H16: =H14-H15
B17: LP Unreturned Capital - Ending ($M) | C17: =C12+C7-C15 | D17: =D12+D7-D15 | E17: =E12+E7-E15 | F17: =F12+F7-F15 | G17: =G12+G7-G15 | H17: =H12+H7-H15
B18: GP Unreturned Capital - Ending ($M) | C18: =C13+C8-C16 | D18: =D13+D8-D16 | E18: =E13+E8-E16 | F18: =F13+F8-F16 | G18: =G13+G8-G16 | H18: =H13+H8-H16
B19: Remaining Cash after Tier 1 ($M) | C19: =C9-C14 | D19: =D9-D14 | E19: =E9-E14 | F19: =F9-F14 | G19: =G9-G14 | H19: =H9-H14
B21: TIER 2 - Preferred Return (8% annually compounded, pro-rata LP/GP on unreturned capital)
B22: LP Pref Accrual - This Year ($M) | C22: =C12*Assumptions!$C$26 | D22: =D12*Assumptions!$C$26 | E22: =E12*Assumptions!$C$26 | F22: =F12*Assumptions!$C$26 | G22: =G12*Assumptions!$C$26 | H22: =H12*Assumptions!$C$26
B23: GP Pref Accrual - This Year ($M) | C23: =C13*Assumptions!$C$26 | D23: =D13*Assumptions!$C$26 | E23: =E13*Assumptions!$C$26 | F23: =F13*Assumptions!$C$26 | G23: =G13*Assumptions!$C$26 | H23: =H13*Assumptions!$C$26
B24: LP Unpaid Pref - Beginning ($M) | C24: =0 | D24: =C31 | E24: =D31 | F24: =E31 | G24: =F31 | H24: =G31
B25: GP Unpaid Pref - Beginning ($M) | C25: =0 | D25: =C32 | E25: =D32 | F25: =E32 | G25: =F32 | H25: =G32
B26: LP Pref Available (Beginning + Accrual) ($M) | C26: =C24+C22 | D26: =D24+D22 | E26: =E24+E22 | F26: =F24+F22 | G26: =G24+G22 | H26: =H24+H22
B27: GP Pref Available (Beginning + Accrual) ($M) | C27: =C25+C23 | D27: =D25+D23 | E27: =E25+E23 | F27: =F25+F23 | G27: =G25+G23 | H27: =H25+H23
B28: Tier 2 Distributable ($M) | C28: =MIN(C19,C26+C27) | D28: =MIN(D19,D26+D27) | E28: =MIN(E19,E26+E27) | F28: =MIN(F19,F26+F27) | G28: =MIN(G19,G26+G27) | H28: =MIN(H19,H26+H27)
B29: Tier 2 Distribution - LP ($M) | C29: =IF((C26+C27)=0,0,C28*C26/(C26+C27)) | D29: =IF((D26+D27)=0,0,D28*D26/(D26+D27)) | E29: =IF((E26+E27)=0,0,E28*E26/(E26+E27)) | F29: =IF((F26+F27)=0,0,F28*F26/(F26+F27)) | G29: =IF((G26+G27)=0,0,G28*G26/(G26+G27)) | H29: =IF((H26+H27)=0,0,H28*H26/(H26+H27))
B30: Tier 2 Distribution - GP ($M) | C30: =C28-C29 | D30: =D28-D29 | E30: =E28-E29 | F30: =F28-F29 | G30: =G28-G29 | H30: =H28-H29
B31: LP Unpaid Pref - Ending ($M) | C31: =C26-C29 | D31: =D26-D29 | E31: =E26-E29 | F31: =F26-F29 | G31: =G26-G29 | H31: =H26-H29
B32: GP Unpaid Pref - Ending ($M) | C32: =C27-C30 | D32: =D27-D30 | E32: =E27-E30 | F32: =F27-F30 | G32: =G27-G30 | H32: =H27-H30
B33: Remaining Cash after Tier 2 ($M) | C33: =C19-C28 | D33: =D19-D28 | E33: =E19-E28 | F33: =F19-F28 | G33: =G19-G28 | H33: =H19-H28
B34: Cumulative Tier 2 Distributed - Total ($M) | C34: =C28 | D34: =C34+D28 | E34: =D34+E28 | F34: =E34+F28 | G34: =F34+G28 | H34: =G34+H28
B35: Cumulative Tier 2 Distributed - LP ($M) | C35: =C29 | D35: =C35+D29 | E35: =D35+E29 | F35: =E35+F29 | G35: =F35+G29 | H35: =G35+H29
B37: TIER 3 - GP Catch-Up (100% to GP until target profit share reached)
B38: Cumulative GP Catch-Up Target ($M) | C38: =(Assumptions!$C$28/(1-Assumptions!$C$28))*C34 | D38: =(Assumptions!$C$28/(1-Assumptions!$C$28))*D34 | E38: =(Assumptions!$C$28/(1-Assumptions!$C$28))*E34 | F38: =(Assumptions!$C$28/(1-Assumptions!$C$28))*F34 | G38: =(Assumptions!$C$28/(1-Assumptions!$C$28))*G34 | H38: =(Assumptions!$C$28/(1-Assumptions!$C$28))*H34
B39: Cumulative GP Catch-Up Paid - Beginning ($M) | C39: =0 | D39: =C41 | E39: =D41 | F39: =E41 | G39: =F41 | H39: =G41
B40: Tier 3 Distribution - GP Catch-Up ($M) | C40: =MIN(C33,MAX(0,C38-C39))*Assumptions!$C$27 | D40: =MIN(D33,MAX(0,D38-D39))*Assumptions!$C$27 | E40: =MIN(E33,MAX(0,E38-E39))*Assumptions!$C$27 | F40: =MIN(F33,MAX(0,F38-F39))*Assumptions!$C$27 | G40: =MIN(G33,MAX(0,G38-G39))*Assumptions!$C$27 | H40: =MIN(H33,MAX(0,H38-H39))*Assumptions!$C$27
B41: Cumulative GP Catch-Up Paid - Ending ($M) | C41: =C39+C40 | D41: =D39+D40 | E41: =E39+E40 | F41: =F39+F40 | G41: =G39+G40 | H41: =H39+H40
B42: Remaining Cash after Tier 3 ($M) | C42: =C33-C40 | D42: =D33-D40 | E42: =E33-E40 | F42: =F33-F40 | G42: =G33-G40 | H42: =H33-H40
B44: TIER 4 - Carried Interest Split (80% LP / 20% GP of residual cash)
B45: Tier 4 Distributable ($M) | C45: =C42 | D45: =D42 | E45: =E42 | F45: =F42 | G45: =G42 | H45: =H42
B46: Tier 4 Distribution - LP (80%) ($M) | C46: =C45*Assumptions!$C$29 | D46: =D45*Assumptions!$C$29 | E46: =E45*Assumptions!$C$29 | F46: =F45*Assumptions!$C$29 | G46: =G45*Assumptions!$C$29 | H46: =H45*Assumptions!$C$29
...

Sheet Returns Summary
B2: Returns Summary
B3: Amounts in $ millions ($M). IRR computed on annual net cash flow (Year 0–5).
B5: LP / GP Net Cash Flow by Year (for IRR)
B6: Year | C6: Year 0 | D6: Year 1 | E6: Year 2 | F6: Year 3 | G6: Year 4 | H6: Year 5
B7: LP Net Cash Flow ($M) | C7: =-Waterfall!C7+Waterfall!C50 | D7: =-Waterfall!D7+Waterfall!D50 | E7: =-Waterfall!E7+Waterfall!E50 | F7: =-Waterfall!F7+Waterfall!F50 | G7: =-Waterfall!G7+Waterfall!G50 | H7: =-Waterfall!H7+Waterfall!H50
B8: GP Net Cash Flow ($M) | C8: =-Waterfall!C8+Waterfall!C51 | D8: =-Waterfall!D8+Waterfall!D51 | E8: =-Waterfall!E8+Waterfall!E51 | F8: =-Waterfall!F8+Waterfall!F51 | G8: =-Waterfall!G8+Waterfall!G51 | H8: =-Waterfall!H8+Waterfall!H51
B9: Whole-Deal Net Cash Flow ($M) | C9: ='Deal Cash Flows'!C19 | D9: ='Deal Cash Flows'!D19 | E9: ='Deal Cash Flows'!E19 | F9: ='Deal Cash Flows'!F19 | G9: ='Deal Cash Flows'!G19 | H9: ='Deal Cash Flows'!H19
B11: LP / GP Returns
C13: Contributed | D13: Tier 1 (ROC) | E13: Tier 2 (Pref) | F13: Tier 3 (Catch-Up) | G13: Tier 4 (Carry) | H13: Total Distributed | I13: Profit | J13: IRR | K13: MOIC (x)
B14: LP | C14: =SUM(Waterfall!C7:H7) | D14: =SUM(Waterfall!C15:H15) | E14: =SUM(Waterfall!C29:H29) | F14: =0 | G14: =SUM(Waterfall!C46:H46) | H14: =D14+E14+F14+G14 | I14: =H14-C14 | J14: =IRR(C7:H7) | K14: =H14/C14
B15: GP | C15: =SUM(Waterfall!C8:H8) | D15: =SUM(Waterfall!C16:H16) | E15: =SUM(Waterfall!C30:H30) | F15: =SUM(Waterfall!C40:H40) | G15: =SUM(Waterfall!C47:H47) | H15: =D15+E15+F15+G15 | I15: =H15-C15 | J15: =IRR(C8:H8) | K15: =H15/C15
B16: Whole Deal (Gross) | C16: =Assumptions!$C$6 | D16: =D14+D15 | E16: =E14+E15 | F16: =F14+F15 | G16: =G14+G15 | H16: =H14+H15 | I16: =H16-C16 | J16: =IRR(C9:H9) | K16: =H16/C16
B19: Effective Carry Check (GP Profit Capture)
B20: GP Profit ($M) | C20: =I15
B21: Total Deal Profit ($M) | C21: =I16
B22: Effective % of Profit Captured by GP | C22: =C20/C21
B23: Stated Carried Interest % | C23: =Assumptions!$C$28
B24: The effective % captured by GP exceeds the stated 20% carry because the GP also earns a preferred return and return of capital on its own 10% capital commitment, in addition to carry on residual profit - this is expected and not an error in the cascade.

Sheet Sensitivity
B2: Sensitivity - Closed-Form Exit Proceeds & Gross MOIC
B3: Closed-form grids (not Excel Data Tables): vary Exit EV/EBITDA multiple and EBITDA growth rate. LP net IRR/MOIC (after the waterfall) are on the Returns Summary tab - these grids show whole-deal gross figures only.
B5: Grid 1 - Exit Equity Proceeds ($M)
B6: Growth \ Exit Mult. | C6: 7 | D6: 7.5 | E6: 8 | F6: 8.5 | G6: 9
B7: 0.04 | C7: =C$6*Assumptions!$C$15*(1+$B7)^5-(Assumptions!$C$17-Assumptions!$C$20*Assumptions!$C$15*((1+$B7)^1+(1+$B7)^2+(1+$B7)^3+(1+$B7)^4+(1+$B7)^5)+Assumptions!$C$22+Assumptions!$C$23) | D7: =D$6*Assumptions!$C$15*(1+$B7)^5-(Assumptions!$C$17-Assumptions!$C$20*Assumptions!$C$15*((1+$B7)^1+(1+$B7)^2+(1+$B7)^3+(1+$B7)^4+(1+$B7)^5)+Assumptions!$C$22+Assumptions!$C$23) | E7: =E$6*Assumptions!$C$15*(1+$B7)^5-(Assumptions!$C$17-Assumptions!$C$20*Assumptions!$C$15*((1+$B7)^1+(1+$B7)^2+(1+$B7)^3+(1+$B7)^4+(1+$B7)^5)+Assumptions!$C$22+Assumptions!$C$23) | F7: =F$6*Assumptions!$C$15*(1+$B7)^5-(Assumptions!$C$17-Assumptions!$C$20*Assumptions!$C$15*((1+$B7)^1+(1+$B7)^2+(1+$B7)^3+(1+$B7)^4+(1+$B7)^5)+Assumptions!$C$22+Assumptions!$C$23) | G7: =G$6*Assumptions!$C$15*(1+$B7)^5-(Assumptions!$C$17-Assumptions!$C$20*Assumptions!$C$15*((1+$B7)^1+(1+$B7)^2+(1+$B7)^3+(1+$B7)^4+(1+$B7)^5)+Assumptions!$C$22+Assumptions!$C$23)
B8: 0.06 | C8: =C$6*Assumptions!$C$15*(1+$B8)^5-(Assumptions!$C$17-Assumptions!$C$20*Assumptions!$C$15*((1+$B8)^1+(1+$B8)^2+(1+$B8)^3+(1+$B8)^4+(1+$B8)^5)+Assumptions!$C$22+Assumptions!$C$23) | D8: =D$6*Assumptions!$C$15*(1+$B8)^5-(Assumptions!$C$17-Assumptions!$C$20*Assumptions!$C$15*((1+$B8)^1+(1+$B8)^2+(1+$B8)^3+(1+$B8)^4+(1+$B8)^5)+Assumptions!$C$22+Assumptions!$C$23) | E8: =E$6*Assumptions!$C$15*(1+$B8)^5-(Assumptions!$C$17-Assumptions!$C$20*Assumptions!$C$15*((1+$B8)^1+(1+$B8)^2+(1+$B8)^3+(1+$B8)^4+(1+$B8)^5)+Assumptions!$C$22+Assumptions!$C$23) | F8: =F$6*Assumptions!$C$15*(1+$B8)^5-(Assumptions!$C$17-Assumptions!$C$20*Assumptions!$C$15*((1+$B8)^1+(1+$B8)^2+(1+$B8)^3+(1+$B8)^4+(1+$B8)^5)+Assumptions!$C$22+Assumptions!$C$23) | G8: =G$6*Assumptions!$C$15*(1+$B8)^5-(Assumptions!$C$17-Assumptions!$C$20*Assumptions!$C$15*((1+$B8)^1+(1+$B8)^2+(1+$B8)^3+(1+$B8)^4+(1+$B8)^5)+Assumptions!$C$22+Assumptions!$C$23)
B9: 0.08 | C9: =C$6*Assumptions!$C$15*(1+$B9)^5-(Assumptions!$C$17-Assumptions!$C$20*Assumptions!$C$15*((1+$B9)^1+(1+$B9)^2+(1+$B9)^3+(1+$B9)^4+(1+$B9)^5)+Assumptions!$C$22+Assumptions!$C$23) | D9: =D$6*Assumptions!$C$15*(1+$B9)^5-(Assumptions!$C$17-Assumptions!$C$20*Assumptions!$C$15*((1+$B9)^1+(1+$B9)^2+(1+$B9)^3+(1+$B9)^4+(1+$B9)^5)+Assumptions!$C$22+Assumptions!$C$23) | E9: =E$6*Assumptions!$C$15*(1+$B9)^5-(Assumptions!$C$17-Assumptions!$C$20*Assumptions!$C$15*((1+$B9)^1+(1+$B9)^2+(1+$B9)^3+(1+$B9)^4+(1+$B9)^5)+Assumptions!$C$22+Assumptions!$C$23) | F9: =F$6*Assumptions!$C$15*(1+$B9)^5-(Assumptions!$C$17-Assumptions!$C$20*Assumptions!$C$15*((1+$B9)^1+(1+$B9)^2+(1+$B9)^3+(1+$B9)^4+(1+$B9)^5)+Assumptions!$C$22+Assumptions!$C$23) | G9: =G$6*Assumptions!$C$15*(1+$B9)^5-(Assumptions!$C$17-Assumptions!$C$20*Assumptions!$C$15*((1+$B9)^1+(1+$B9)^2+(1+$B9)^3+(1+$B9)^4+(1+$B9)^5)+Assumptions!$C$22+Assumptions!$C$23)
B10: 0.1 | C10: =C$6*Assumptions!$C$15*(1+$B10)^5-(Assumptions!$C$17-Assumptions!$C$20*Assumptions!$C$15*((1+$B10)^1+(1+$B10)^2+(1+$B10)^3+(1+$B10)^4+(1+$B10)^5)+Assumptions!$C$22+Assumptions!$C$23) | D10: =D$6*Assumptions!$C$15*(1+$B10)^5-(Assumptions!$C$17-Assumptions!$C$20*Assumptions!$C$15*((1+$B10)^1+(1+$B10)^2+(1+$B10)^3+(1+$B10)^4+(1+$B10)^5)+Assumptions!$C$22+Assumptions!$C$23) | E10: =E$6*Assumptions!$C$15*(1+$B10)^5-(Assumptions!$C$17-Assumptions!$C$20*Assumptions!$C$15*((1+$B10)^1+(1+$B10)^2+(1+$B10)^3+(1+$B10)^4+(1+$B10)^5)+Assumptions!$C$22+Assumptions!$C$23) | F10: =F$6*Assumptions!$C$15*(1+$B10)^5-(Assumptions!$C$17-Assumptions!$C$20*Assumptions!$C$15*((1+$B10)^1+(1+$B10)^2+(1+$B10)^3+(1+$B10)^4+(1+$B10)^5)+Assumptions!$C$22+Assumptions!$C$23) | G10: =G$6*Assumptions!$C$15*(1+$B10)^5-(Assumptions!$C$17-Assumptions!$C$20*Assumptions!$C$15*((1+$B10)^1+(1+$B10)^2+(1+$B10)^3+(1+$B10)^4+(1+$B10)^5)+Assumptions!$C$22+Assumptions!$C$23)
B11: 0.12 | C11: =C$6*Assumptions!$C$15*(1+$B11)^5-(Assumptions!$C$17-Assumptions!$C$20*Assumptions!$C$15*((1+$B11)^1+(1+$B11)^2+(1+$B11)^3+(1+$B11)^4+(1+$B11)^5)+Assumptions!$C$22+Assumptions!$C$23) | D11: =D$6*Assumptions!$C$15*(1+$B11)^5-(Assumptions!$C$17-Assumptions!$C$20*Assumptions!$C$15*((1+$B11)^1+(1+$B11)^2+(1+$B11)^3+(1+$B11)^4+(1+$B11)^5)+Assumptions!$C$22+Assumptions!$C$23) | E11: =E$6*Assumptions!$C$15*(1+$B11)^5-(Assumptions!$C$17-Assumptions!$C$20*Assumptions!$C$15*((1+$B11)^1+(1+$B11)^2+(1+$B11)^3+(1+$B11)^4+(1+$B11)^5)+Assumptions!$C$22+Assumptions!$C$23) | F11: =F$6*Assumptions!$C$15*(1+$B11)^5-(Assumptions!$C$17-Assumptions!$C$20*Assumptions!$C$15*((1+$B11)^1+(1+$B11)^2+(1+$B11)^3+(1+$B11)^4+(1+$B11)^5)+Assumptions!$C$22+Assumptions!$C$23) | G11: =G$6*Assumptions!$C$15*(1+$B11)^5-(Assumptions!$C$17-Assumptions!$C$20*Assumptions!$C$15*((1+$B11)^1+(1+$B11)^2+(1+$B11)^3+(1+$B11)^4+(1+$B11)^5)+Assumptions!$C$22+Assumptions!$C$23)
B13: Grid 2 - Gross Deal MOIC (x) [= (Exit Proceeds + Div Yr3 + Div Yr4) / Total Equity]
B14: Growth \ Exit Mult. | C14: 7 | D14: 7.5 | E14: 8 | F14: 8.5 | G14: 9
B15: 0.04 | C15: =(C7+Assumptions!$C$22+Assumptions!$C$23)/Assumptions!$C$6 | D15: =(D7+Assumptions!$C$22+Assumptions!$C$23)/Assumptions!$C$6 | E15: =(E7+Assumptions!$C$22+Assumptions!$C$23)/Assumptions!$C$6 | F15: =(F7+Assumptions!$C$22+Assumptions!$C$23)/Assumptions!$C$6 | G15: =(G7+Assumptions!$C$22+Assumptions!$C$23)/Assumptions!$C$6
B16: 0.06 | C16: =(C8+Assumptions!$C$22+Assumptions!$C$23)/Assumptions!$C$6 | D16: =(D8+Assumptions!$C$22+Assumptions!$C$23)/Assumptions!$C$6 | E16: =(E8+Assumptions!$C$22+Assumptions!$C$23)/Assumptions!$C$6 | F16: =(F8+Assumptions!$C$22+Assumptions!$C$23)/Assumptions!$C$6 | G16: =(G8+Assumptions!$C$22+Assumptions!$C$23)/Assumptions!$C$6
B17: 0.08 | C17: =(C9+Assumptions!$C$22+Assumptions!$C$23)/Assumptions!$C$6 | D17: =(D9+Assumptions!$C$22+Assumptions!$C$23)/Assumptions!$C$6 | E17: =(E9+Assumptions!$C$22+Assumptions!$C$23)/Assumptions!$C$6 | F17: =(F9+Assumptions!$C$22+Assumptions!$C$23)/Assumptions!$C$6 | G17: =(G9+Assumptions!$C$22+Assumptions!$C$23)/Assumptions!$C$6
B18: 0.1 | C18: =(C10+Assumptions!$C$22+Assumptions!$C$23)/Assumptions!$C$6 | D18: =(D10+Assumptions!$C$22+Assumptions!$C$23)/Assumptions!$C$6 | E18: =(E10+Assumptions!$C$22+Assumptions!$C$23)/Assumptions!$C$6 | F18: =(F10+Assumptions!$C$22+Assumptions!$C$23)/Assumptions!$C$6 | G18: =(G10+Assumptions!$C$22+Assumptions!$C$23)/Assumptions!$C$6
B19: 0.12 | C19: =(C11+Assumptions!$C$22+Assumptions!$C$23)/Assumptions!$C$6 | D19: =(D11+Assumptions!$C$22+Assumptions!$C$23)/Assumptions!$C$6 | E19: =(E11+Assumptions!$C$22+Assumptions!$C$23)/Assumptions!$C$6 | F19: =(F11+Assumptions!$C$22+Assumptions!$C$23)/Assumptions!$C$6 | G19: =(G11+Assumptions!$C$22+Assumptions!$C$23)/Assumptions!$C$6
B21: Closed-form derivation: with a constant FCF-conversion rate and no debt-floor binding, ending net debt at exit = Entry Net Debt − FCF-Conversion × EBITDA0 × Σ(1+g)^t for t=1..5 + Dividends (Yr3+Yr4). Exit equity proceeds = Exit Multiple × EBITDA0 × (1+g)^5 − Ending Net Debt. Base case (8.0x, 8% growth) should tie to the Deal Cash Flows tab.
