Workbook

Sheet Cover
B2: Hilton Hotels Corporation - LBO Analysis
B3: Blackstone Group acquisition, announced July 3, 2007 / closed October 2007
B5: Prepared by: Akul Veauli
B6: Date: August 23, 2026
B8: Leveraged buyout model of Hilton Hotels Corporation by The Blackstone Group, structured at deal vintage (FY2006 financials, announced deal terms, 2007 rate environment). Models the transaction as underwritten in mid-2007 - pre-crisis operating assumptions, ~14.6x entry EV/EBITDA on the model's $25,525mm TEV (~14.9x on the ~$26.0B headline TEV commonly quoted), ~11.7x entry net leverage - and separately documents the actual outcome, which diverged sharply from the underwriting case due to the 2008-09 Global Financial Crisis before ultimately becoming the most profitable PE deal in history.
B12: Color-code legend
B13: Blue = hardcoded input
B14: Black = formula (same sheet)
B15: Green = link from another tab
B17: Table of contents
B18: Cover
B19: Assumptions
... B26: Key outputs
B27: Transaction EV ($mm) | C27: =Assumptions!C12 -> 25525
B28: Entry EV / EBITDA | C28: =Assumptions!C14 -> 14.585714
B29: Sponsor equity invested ($mm) | C29: ='Sources-Uses'!D13 -> 6105.5
B30: Entry net leverage (Net Debt/EBITDA) | C30: ='Sources-Uses'!D30 -> 11.685714
B31: Modeled 5-yr IRR / MOIC (vintage case) | C31: =Returns!E14 -> -0.17490952 | D31: =Returns!E13 -> 0.38239118
B32: Actual outcome: MOIC / holding period | C32: ~3.0x | D32: ~11 years
B34: Actual Outcome (Post-Deal History) - Explorer-Verified Summary
B35: Jul 2007: Blackstone announces acquisition of Hilton at $47.50/share cash, ~40% premium, ~$26.0B TEV (~14.9x FY2006 EBITDA).
B36: Oct 2007: Deal closes at the peak of the credit cycle - ~$20.5-20.8B of debt (CMBS/mortgage $7.6B, 2nd lien $1.0B, Mezz I-III
B37: $12.2B), ~$5.6-5.7B sponsor equity from Blackstone and co-investors. Entry net leverage ~11.7x EBITDA - extremely aggressive.
B38: 2008-09: Global Financial Crisis collapses lodging RevPAR 15-20%; Blackstone marks its equity down ~70% (~$5.6B to ~$1.7B book).
B39: Apr 2010: Consensual debt restructuring - Blackstone repurchases $1.8B of mezzanine debt at a 45% discount (paying $819mm),
B40: converts $2.1B of junior mezzanine into preferred equity, extends maturities to Nov 2015, and injects ~$819mm of new equity.
B41: Net effect: ~$3.9-4.0B of debt reduction; total debt falls from ~$20.5B to ~$16.5B.
B42: Dec 2013: Hilton Worldwide IPOs at $20.00/share (largest hotel IPO in history), raising ~$2.35B; Blackstone retains ~73% of its stake.
B43: 2014-2018: Hilton stock appreciates from $20 to ~$110+ as lodging fully recovers and Hilton executes an asset-light growth strategy.
B44: May 2018: Blackstone completes its final exit. Total realized profit ~$14.0B on ~$5.6B invested - approximately 3.0x MOIC over an
B45: ~11-year hold (~15-17% IRR) - reported at the time as the most profitable private equity deal in history, despite the deal being
... B51: study (2018, debt tranche detail). See Returns tab S3 for detailed model-vs-actual comparison and flagged estimates.

Sheet Assumptions
B2: Assumptions
B3: ($ in millions, except per-share data and rates)
B5: 1. Transaction Assumptions
B6: Announcement date | C6: July 3, 2007
B7: Close date | C7: October 2007
B8: Offer price / share | C8: 47.5 | D8: 40% premium to unaffected price
B9: Fully diluted shares (mm) [EST.] | C9: 390 | D9: Estimated from equity value / offer price - not explicitly confirmed in deal docs
B10: Equity purchase price | C10: =C8*C9 -> 18525
B11: Plus: refinanced net debt assumed | C11: 7000 | D11: Pre-existing Hilton net debt at close
B12: Transaction Enterprise Value (TEV) | C12: =C10+C11 -> 25525
B13: LTM / FY2006 Adj. EBITDA at entry | C13: 1750 | D13: Midpoint of $1,740-1,765mm guidance range
B14: Implied entry EV / EBITDA | C14: =C12/C13 -> 14.585714
B15: Transaction fees (% of TEV) | C15: 0.02
B16: Financing fees (% of total debt) | C16: 0.025
B17: Financing fee amortization tenor (yrs) | C17: 7 | D17: Straight-line, non-cash addback
B19: 2. Debt Tranches
B20: Tranche | C20: Amount ($mm) | D20: Spread (bps) | E20: LIBOR (entry) | F20: All-in Rate | G20: Mand. Amort %/yr | H20: Cash-pay? | I20: % of Total
B21: 3M LIBOR assumption (2007 vintage, entry pricing) | D21: 0.0536 | G21: Fed H.15, July 2007
B22: Senior Mortgage (CMBS) | C22: 7600 | D22: 150 | E22: =$D$21 -> 0.0536 | F22: =E22+D22/10000 -> 0.0686 | G22: 0.02 | H22: N | I22: =C22/$C$28 -> 0.36538462
B23: 2nd Lien Notes | C23: 1000 | D23: 250 | E23: =$D$21 -> 0.0536 | F23: =E23+D23/10000 -> 0.0786 | G23: 0.02 | H23: N | I23: =C23/$C$28 -> 0.048076923
B24: Mezzanine I | C24: 4500 | D24: 300 | E24: =$D$21 -> 0.0536 | F24: =E24+D24/10000 -> 0.0836 | G24: 0 | H24: N | I24: =C24/$C$28 -> 0.21634615
B25: Mezzanine II | C25: 3900 | D25: 350 | E25: =$D$21 -> 0.0536 | F25: =E25+D25/10000 -> 0.0886 | G25: 0 | H25: N | I25: =C25/$C$28 -> 0.1875
B26: Mezzanine III | C26: 3800 | D26: 500 | E26: =$D$21 -> 0.0536 | F26: =E26+D26/10000 -> 0.1036 | G26: 0 | H26: N | I26: =C26/$C$28 -> 0.18269231
B27: Revolver (undrawn at close) | C27: 1000 | D27: 275 | E27: =$D$21 -> 0.0536 | F27: =E27+D27/10000 -> 0.0811 | G27: 0 | H27: N | I27: n/a (undrawn)
B28: Total Funded Debt at Close (excl. undrawn $1,000mm revolver) | C28: =SUM(C22:C26) -> 20800 | I28: =1 -> 1
B29: Memo: Total Committed Debt (incl. $1,000mm revolver capacity) | C29: =C28+C27 -> 21800
B30: Blended weighted-average rate on funded debt (entry) | C30: =SUMPRODUCT(C22:C26,F22:F26)/C28 -> 0.082470192
B31: Weighted-average mandatory amort %/yr (funded debt) | C31: =SUMPRODUCT(C22:C26,G22:G26)/C28 -> 0.0082692308
B33: Leverage & financing-fee calcs below use FUNDED debt only (excl. undrawn revolver), matching standard
B34: LBO convention and the ~11.7x net-leverage figure cited in deal research (source: Oxford SBS case study).
B36: NOTE [ESTIMATE]: Tranche spreads (2nd lien, Mezz I-III) are estimates from 2007 market comps; actual
B37: commitment-letter pricing not publicly located. Senior CMBS L+150 / 2nd lien L+250 / Mezz L+300-500
B38: per Oxford Said Business School case study fallback (total debt ~$20.8B matches ~$20.5-20.8B confirmed).
B40: 3. Operating Drivers, FY2007E-FY2013E (Deal-Vintage Projection)
B41: Driver | C41: FY2007E | D41: FY2008E | E41: FY2009E | F41: FY2010E | G41: FY2011E | H41: FY2012E | I41: FY2013E
B42: Revenue growth % (vintage view: pre-crisis momentum -> GFC collapse -> recovery) | C42: 0.06 | D42: 0.05 | E42: -0.16 | F42: -0.06 | G42: 0.07 | H42: 0.08 | I42: 0.07
B43: EBITDA margin % | C43: 0.215 | D43: 0.2 | E43: 0.185 | F43: 0.19 | G43: 0.205 | H43: 0.215 | I43: 0.22
B44: D&A % of revenue [EST. baseline ~$305mm FY06] | C44: 0.038 | D44: 0.038 | E44: 0.038 | F44: 0.038 | G44: 0.038 | H44: 0.038 | I44: 0.038
B45: Capex % of revenue [EST. ~6.5-8.0% hotels, crisis-year cuts] | C45: 0.075 | D45: 0.065 | E45: 0.04 | F45: 0.045 | G45: 0.06 | H45: 0.07 | I45: 0.075
B46: Net working capital % of revenue (applied to change in revenue) | C46: 0.01 | D46: 0.01 | E46: 0.01 | F46: 0.01 | G46: 0.01 | H46: 0.01 | I46: 0.01
...

Sheet Sources-Uses
B2: Sources & Uses
B3: ($ in millions, at close - October 2007)
B5: Sources
D6: Amount | E6: % Total
B7: Senior Mortgage (CMBS) | D7: =Assumptions!C22 -> 7600 | E7: =D7/D$14 -> 0.28247013
B8: 2nd Lien Notes | D8: =Assumptions!C23 -> 1000 | E8: =D8/D$14 -> 0.037167122
B9: Mezzanine I | D9: =Assumptions!C24 -> 4500 | E9: =D9/D$14 -> 0.16725205
B10: Mezzanine II | D10: =Assumptions!C25 -> 3900 | E10: =D10/D$14 -> 0.14495178
B11: Mezzanine III | D11: =Assumptions!C26 -> 3800 | E11: =D11/D$14 -> 0.14123506
B12: Revolver ($1,000mm committed, undrawn at close) | D12: =0 -> 0 | E12: =D12/D$14 -> 0
B13: Sponsor Equity (Blackstone + co-investors) [PLUG] | D13: =D23-SUM(D7:D12) -> 6105.5 | E13: =D13/D$14 -> 0.22692386
B14: Total Sources | D14: =SUM(D7:D13) -> 26905.5
B16: Uses
D17: Amount | E17: % Total
B18: Equity Purchase Price | D18: =Assumptions!C10 -> 18525 | E18: =D18/D$23 -> 0.68852093
B19: Refinance Existing Net Debt | D19: =Assumptions!C11 -> 7000 | E19: =D19/D$23 -> 0.26016985
B20: Transaction Fees | D20: =Assumptions!C12*Assumptions!C15 -> 510.5 | E20: =D20/D$23 -> 0.018973816
B21: Financing Fees (capitalized, amortized 7 yrs) | D21: =Assumptions!C28*Assumptions!C16 -> 520 | E21: =D21/D$23 -> 0.019326903
B22: Cash to Balance Sheet | D22: 350 | E22: =D22/D$23 -> 0.013008493
B23: Total Uses | D23: =SUM(D18:D22) -> 26905.5
B25: Check: Sources - Uses (must = 0.0) | D25: =ROUND(D14-D23,3) -> 0
B27: Memo
B28: Sponsor equity % of total capitalization | D28: =D13/D14 -> 0.22692386
B29: Gross Debt / EBITDA at close | D29: =Assumptions!C28/Assumptions!C13 -> 11.885714
B30: Net Debt / EBITDA at close | D30: =(Assumptions!C28-D22)/Assumptions!C13 -> 11.685714
B32: Memo: reported sponsor equity check ~$5.6-6.5B (Blackstone ~$5.2B + limited partner co-investors
B33: ~$0.4-0.5B) per Blackstone press release / DEFM14A - plug above should fall in this range.

Sheet Model
B2: Operating Model & Free Cash Flow
B3: ($ in millions)
B5: Historical & Projected Operating Results
D6: FY2004A | E6: FY2005A | F6: FY2006A | G6: FY2007E | H6: FY2008E | I6: FY2009E | J6: FY2010E | K6: FY2011E | L6: FY2012E | M6: FY2013E
B7: Revenue | D7: 4150 | E7: 4437 | F7: 8162 | G7: =F7*(1+G8) -> 8651.72 | H7: =G7*(1+H8) -> 9084.306 | I7: =H7*(1+I8) -> 7630.817 | J7: =I7*(1+J8) -> 7172.968 | K7: =J7*(1+K8) -> 7675.0758 | L7: =K7*(1+L8) -> 8289.0818 | M7: =L7*(1+M8) -> 8869.3176
B8: Revenue growth % | E8: =E7/D7-1 -> 0.069156627 | F8: =F7/E7-1 -> 0.83953121 | G8: =Assumptions!C$42 -> 0.06 | H8: =Assumptions!D$42 -> 0.05 | I8: =Assumptions!E$42 -> -0.16 | J8: =Assumptions!F$42 -> -0.06 | K8: =Assumptions!G$42 -> 0.07 | L8: =Assumptions!H$42 -> 0.08 | M8: =Assumptions!I$42 -> 0.07
B9: Adjusted EBITDA | D9: n.a. | E9: 1140 | F9: 1750 | G9: =G7*G10 -> 1860.1198 | H9: =H7*H10 -> 1816.8612 | I9: =I7*I10 -> 1411.7012 | J9: =J7*J10 -> 1362.8639 | K9: =K7*K10 -> 1573.3905 | L9: =L7*L10 -> 1782.1526 | M9: =M7*M10 -> 1951.2499
B10: EBITDA margin % | E10: =E9/E7 -> 0.25693036 | F10: =F9/F7 -> 0.21440823 | G10: =Assumptions!C$43 -> 0.215 | H10: =Assumptions!D$43 -> 0.2 | I10: =Assumptions!E$43 -> 0.185 | J10: =Assumptions!F$43 -> 0.19 | K10: =Assumptions!G$43 -> 0.205 | L10: =Assumptions!H$43 -> 0.215 | M10: =Assumptions!I$43 -> 0.22
B11: D&A [FY05/06 estimated] | D11: n.a. | E11: 305 | F11: 305 | G11: =G7*Assumptions!C$44 -> 328.76536 | H11: =H7*Assumptions!D$44 -> 345.20363 | I11: =I7*Assumptions!E$44 -> 289.97105 | J11: =J7*Assumptions!F$44 -> 272.57278 | K11: =K7*Assumptions!G$44 -> 291.65288 | L11: =L7*Assumptions!H$44 -> 314.98511 | M11: =M7*Assumptions!I$44 -> 337.03407
B12: EBIT | E12: =E9-E11 -> 835 | F12: =F9-F11 -> 1445 | G12: =G9-G11 -> 1531.3544 | H12: =H9-H11 -> 1471.6576 | I12: =I9-I11 -> 1121.7301 | J12: =J9-J11 -> 1090.2911 | K12: =K9-K11 -> 1281.7377 | L12: =L9-L11 -> 1467.1675 | M12: =M9-M11 -> 1614.2158
B13: Less: Interest expense (post-LBO, green from DebtSchedule) | G13: =DebtSchedule!D$75 -> 1640.5 | H13: =DebtSchedule!E$75 -> 1236.6365 | I13: =DebtSchedule!F$75 -> 926.88453 | J13: =DebtSchedule!G$75 -> 922.32256 | K13: =DebtSchedule!H$75 -> 920.41155 | L13: =DebtSchedule!I$75 -> 918.60926 | M13: =DebtSchedule!J$75 -> 1121.7978
B14: Plus: Interest income | G14: =DebtSchedule!D$8*Assumptions!$C$48 -> 7 | H14: =DebtSchedule!E$8*Assumptions!$C$48 -> 2 | I14: =DebtSchedule!F$8*Assumptions!$C$48 -> 2 | J14: =DebtSchedule!G$8*Assumptions!$C$48 -> 2 | K14: =DebtSchedule!H$8*Assumptions!$C$48 -> 2 | L14: =DebtSchedule!I$8*Assumptions!$C$48 -> 2 | M14: =DebtSchedule!J$8*Assumptions!$C$48 -> 2
B15: Less: Financing fee amortization (non-cash) | G15: ='Sources-Uses'!$D$21/Assumptions!$C$17 -> 74.285714 | H15: ='Sources-Uses'!$D$21/Assumptions!$C$17 -> 74.285714 | I15: ='Sources-Uses'!$D$21/Assumptions!$C$17 -> 74.285714 | J15: ='Sources-Uses'!$D$21/Assumptions!$C$17 -> 74.285714 | K15: ='Sources-Uses'!$D$21/Assumptions!$C$17 -> 74.285714 | L15: ='Sources-Uses'!$D$21/Assumptions!$C$17 -> 74.285714 | M15: ='Sources-Uses'!$D$21/Assumptions!$C$17 -> 74.285714
B16: EBT | G16: =G12-G13+G14-G15 -> -176.43127 | H16: =H12-H13+H14-H15 -> 162.73536 | I16: =I12-I13+I14-I15 -> 122.55986 | J16: =J12-J13+J14-J15 -> 95.682867 | K16: =K12-K13+K14-K15 -> 289.04039 | L16: =L12-L13+L14-L15 -> 476.27252 | M16: =M12-M13+M14-M15 -> 420.13226
B17: Taxes | G17: =MAX(0,G16)*Assumptions!$C$47 -> 0 | H17: =MAX(0,H16)*Assumptions!$C$47 -> 56.957378 | I17: =MAX(0,I16)*Assumptions!$C$47 -> 42.895951 | J17: =MAX(0,J16)*Assumptions!$C$47 -> 33.489003 | K17: =MAX(0,K16)*Assumptions!$C$47 -> 101.16414 | L17: =MAX(0,L16)*Assumptions!$C$47 -> 166.69538 | M17: =MAX(0,M16)*Assumptions!$C$47 -> 147.04629
B18: Net Income (reported) | D18: n.a. | E18: n.a. | F18: 572 | G18: =G16-G17 -> -176.43127 | H18: =H16-H17 -> 105.77799 | I18: =I16-I17 -> 79.663909 | J18: =J16-J17 -> 62.193863 | K18: =K16-K17 -> 187.87626 | L18: =L16-L17 -> 309.57714 | M18: =M16-M17 -> 273.08597
B20: Free Cash Flow
B21: Net Income | G21: =G18 -> -176.43127 | H21: =H18 -> 105.77799 | I21: =I18 -> 79.663909 | J21: =J18 -> 62.193863 | K21: =K18 -> 187.87626 | L21: =L18 -> 309.57714 | M21: =M18 -> 273.08597
B22: Plus: D&A | G22: =G11 -> 328.76536 | H22: =H11 -> 345.20363 | I22: =I11 -> 289.97105 | J22: =J11 -> 272.57278 | K22: =K11 -> 291.65288 | L22: =L11 -> 314.98511 | M22: =M11 -> 337.03407
B23: Plus: Financing fee amortization (non-cash) | G23: =G15 -> 74.285714 | H23: =H15 -> 74.285714 | I23: =I15 -> 74.285714 | J23: =J15 -> 74.285714 | K23: =K15 -> 74.285714 | L23: =L15 -> 74.285714 | M23: =M15 -> 74.285714
B24: Less: Capital expenditures | G24: =G7*Assumptions!C$45 -> 648.879 | H24: =H7*Assumptions!D$45 -> 590.47989 | I24: =I7*Assumptions!E$45 -> 305.23268 | J24: =J7*Assumptions!F$45 -> 322.78356 | K24: =K7*Assumptions!G$45 -> 460.50455 | L24: =L7*Assumptions!H$45 -> 580.23573 | M24: =M7*Assumptions!I$45 -> 665.19882
B25: Less: Increase in net working capital | G25: =(G7-F7)*Assumptions!C$46 -> 4.8972 | H25: =(H7-G7)*Assumptions!D$46 -> 4.32586 | I25: =(I7-H7)*Assumptions!E$46 -> -14.53489 | J25: =(J7-I7)*Assumptions!F$46 -> -4.5784902 | K25: =(K7-J7)*Assumptions!G$46 -> 5.0210776 | L25: =(L7-K7)*Assumptions!H$46 -> 6.1400606 | M25: =(M7-L7)*Assumptions!I$46 -> 5.8023573
B26: Cash available for debt paydown (pre-mandatory) | G26: =G21+G22+G23-G24-G25 -> -427.1564 | H26: =H21+H22+H23-H24-H25 -> -69.538421 | I26: =I21+I22+I23-I24-I25 -> 153.22288 | J26: =J21+J22+J23-J24-J25 -> 90.847292 | K26: =K21+K22+K23-K24-K25 -> 88.289225 | L26: =L21+L22+L23-L24-L25 -> 112.47217 | M26: =M21+M22+M23-M24-M25 -> 13.404578
B27: Memo: Pre-financing (unlevered) FCF - for leverage sensitivity | G27: =G12*(1-Assumptions!$C$47)+G11-G24-G25 -> 670.36955 | H27: =H12*(1-Assumptions!$C$47)+H11-H24-H25 -> 706.9753 | I27: =I12*(1-Assumptions!$C$47)+I11-I24-I25 -> 728.39782 | J27: =J12*(1-Assumptions!$C$47)+J11-J24-J25 -> 663.05695 | K27: =K12*(1-Assumptions!$C$47)+K11-K24-K25 -> 659.25673 | L27: =L12*(1-Assumptions!$C$47)+L11-L24-L25 -> 682.26819 | M27: =M12*(1-Assumptions!$C$47)+M11-M24-M25 -> 715.27316
B28: Credit Metrics (post-LBO capital structure; n/a for historicals)
G29: FY2007E | H29: FY2008E | I29: FY2009E | J29: FY2010E | K29: FY2011E | L29: FY2012E | M29: FY2013E
B30: Total Debt | G30: =DebtSchedule!D$71 -> 20977.156 | H30: =DebtSchedule!E$71 -> 21046.695 | I30: =DebtSchedule!F$71 -> 20893.472 | J30: =DebtSchedule!G$71 -> 20802.625 | K30: =DebtSchedule!H$71 -> 20714.335 | L30: =DebtSchedule!I$71 -> 20601.863 | M30: =DebtSchedule!J$71 -> 20588.459
B31: Total Debt / EBITDA | G31: =IFERROR(G30/G9,"n.m.") -> 11.277315 | H31: =IFERROR(H30/H9,"n.m.") -> 11.584096 | I31: =IFERROR(I30/I9,"n.m.") -> 14.800209 | J31: =IFERROR(J30/J9,"n.m.") -> 15.263904 | K31: =IFERROR(K30/K9,"n.m.") -> 13.165413 | L31: =IFERROR(L30/L9,"n.m.") -> 11.560101 | M31: =IFERROR(M30/M9,"n.m.") -> 10.551421
B32: Net Debt | G32: =DebtSchedule!D$74 -> 20877.156 | H32: =DebtSchedule!E$74 -> 20946.695 | I32: =DebtSchedule!F$74 -> 20793.472 | J32: =DebtSchedule!G$74 -> 20702.625 | K32: =DebtSchedule!H$74 -> 20614.335 | L32: =DebtSchedule!I$74 -> 20501.863 | M32: =DebtSchedule!J$74 -> 20488.459
B33: Net Debt / EBITDA | G33: =IFERROR(G32/G9,"n.m.") -> 11.223555 | H33: =IFERROR(H32/H9,"n.m.") -> 11.529056 | I33: =IFERROR(I32/I9,"n.m.") -> 14.729372 | J33: =IFERROR(J32/J9,"n.m.") -> 15.19053 | K33: =IFERROR(K32/K9,"n.m.") -> 13.101855 | L33: =IFERROR(L32/L9,"n.m.") -> 11.503989 | M33: =IFERROR(M32/M9,"n.m.") -> 10.500172
B34: Cash Interest Expense | G34: =G13 -> 1640.5 | H34: =H13 -> 1236.6365 | I34: =I13 -> 926.88453 | J34: =J13 -> 922.32256 | K34: =K13 -> 920.41155 | L34: =L13 -> 918.60926 | M34: =M13 -> 1121.7978
B35: EBITDA / Cash Interest | G35: =IFERROR(G9/G34,"n.m.") -> 1.1338737 | H35: =IFERROR(H9/H34,"n.m.") -> 1.4691958 | I35: =IFERROR(I9/I34,"n.m.") -> 1.5230604 | J35: =IFERROR(J9/J34,"n.m.") -> 1.4776435 | K35: =IFERROR(K9/K34,"n.m.") -> 1.7094424 | L35: =IFERROR(L9/L34,"n.m.") -> 1.9400551 | M35: =IFERROR(M9/M34,"n.m.") -> 1.7393953
B36: (EBITDA - Capex) / Cash Interest | G36: =IFERROR((G9-G24)/G34,"n.m.") -> 0.73833636 | H36: =IFERROR((H9-H24)/H34,"n.m.") -> 0.9917072 | I36: =IFERROR((I9-I24)/I34,"n.m.") -> 1.1937501 | J36: =IFERROR((J9-J24)/J34,"n.m.") -> 1.1276753 | K36: =IFERROR((K9-K24)/K34,"n.m.") -> 1.2091178 | L36: =IFERROR((L9-L24)/L34,"n.m.") -> 1.3084093 | M36: =IFERROR((M9-M24)/M34,"n.m.") -> 1.1464196
B38: Entry net leverage of ~11.7x EBITDA (see Sources-Uses memo) is the headline risk metric of this deal:
B39: extremely aggressive even by 2007 standards, and the primary reason the capital structure required a 2010
B40: restructuring once FY2008-09 EBITDA collapsed (see Cover / Returns 'Actual Outcome' commentary).

Sheet DebtSchedule
B2: Debt Schedule
B3: ($ in millions) - interest on beginning-of-period balances; cash sweep at period end; no circularity
B5: Cash Flow & Sweep Waterfall
D6: FY2007E | E6: FY2008E | F6: FY2009E | G6: FY2010E | H6: FY2011E | I6: FY2012E | J6: FY2013E
B7: Cash available for debt paydown (pre-mandatory) | D7: =Model!G26 -> -427.1564 | E7: =Model!H26 -> -69.538421 | F7: =Model!I26 -> 153.22288 | G7: =Model!J26 -> 90.847292 | H7: =Model!K26 -> 88.289225 | I7: =Model!L26 -> 112.47217 | J7: =Model!M26 -> 13.404578
B8: Beginning cash balance | D8: ='Sources-Uses'!$D$22 -> 350 | E8: =D73 -> 100 | F8: =E73 -> 100 | G8: =F73 -> 100 | H8: =G73 -> 100 | I8: =H73 -> 100 | J8: =I73 -> 100
B9: Less: total mandatory amortization | D9: =SUM(D27,D36,D45,D54,D63) -> 172 | E9: =SUM(E27,E36,E45,E54,E63) -> 172 | F9: =SUM(F27,F36,F45,F54,F63) -> 172 | G9: =SUM(G27,G36,G45,G54,G63) -> 172 | H9: =SUM(H27,H36,H45,H54,H63) -> 172 | I9: =SUM(I27,I36,I45,I54,I63) -> 172 | J9: =SUM(J27,J36,J45,J54,J63) -> 172
B10: Cash before discretionary sweep / revolver | D10: =D8+D7-D9 -> -249.1564 | E10: =E8+E7-E9 -> -141.53842 | F10: =F8+F7-F9 -> 81.222879 | G10: =G8+G7-G9 -> 18.847292 | H10: =H8+H7-H9 -> 16.289225 | I10: =I8+I7-I9 -> 40.47217 | J10: =J8+J7-J9 -> -58.595422
B11: Minimum cash requirement | D11: =Assumptions!$C$59 -> 100 | E11: =Assumptions!$C$59 -> 100 | F11: =Assumptions!$C$59 -> 100 | G11: =Assumptions!$C$59 -> 100 | H11: =Assumptions!$C$59 -> 100 | I11: =Assumptions!$C$59 -> 100 | J11: =Assumptions!$C$59 -> 100
B12: Revolver draw (shortfall) | D12: =MAX(0,D11-D10) -> 349.1564 | E12: =MAX(0,E11-E10) -> 241.53842 | F12: =MAX(0,F11-F10) -> 18.777121 | G12: =MAX(0,G11-G10) -> 81.152708 | H12: =MAX(0,H11-H10) -> 83.710775 | I12: =MAX(0,I11-I10) -> 59.52783 | J12: =MAX(0,J11-J10) -> 158.59542
B13: Cash available for sweep (gross pool) | D13: =MAX(0,D10-D11)*Assumptions!$C$60 -> 0 | E13: =MAX(0,E10-E11)*Assumptions!$C$60 -> 0 | F13: =MAX(0,F10-F11)*Assumptions!$C$60 -> 0 | G13: =MAX(0,G10-G11)*Assumptions!$C$60 -> 0 | H13: =MAX(0,H10-H11)*Assumptions!$C$60 -> 0 | I13: =MAX(0,I10-I11)*Assumptions!$C$60 -> 0 | J13: =MAX(0,J10-J11)*Assumptions!$C$60 -> 0
B15: Revolver ($1,000mm committed, undrawn at close)
D16: FY2007E | E16: FY2008E | F16: FY2009E | G16: FY2010E | H16: FY2011E | I16: FY2012E | J16: FY2013E
B17: Opening balance | D17: =0 -> 0 | E17: =D20 -> 349.1564 | F17: =E20 -> 590.69482 | G17: =F20 -> 609.47194 | H17: =G20 -> 690.62465 | I17: =H20 -> 774.33542 | J17: =I20 -> 833.86325
B18: Draw | D18: =D12 -> 349.1564 | E18: =E12 -> 241.53842 | F18: =F12 -> 18.777121 | G18: =G12 -> 81.152708 | H18: =H12 -> 83.710775 | I18: =I12 -> 59.52783 | J18: =J12 -> 158.59542
B19: Repayment (1st priority in sweep) | D19: =MIN(D13,D17) -> 0 | E19: =MIN(E13,E17) -> 0 | F19: =MIN(F13,F17) -> 0 | G19: =MIN(G13,G17) -> 0 | H19: =MIN(H13,H17) -> 0 | I19: =MIN(I13,I17) -> 0 | J19: =MIN(J13,J17) -> 0
B20: Closing balance | D20: =D17+D18-D19 -> 349.1564 | E20: =E17+E18-E19 -> 590.69482 | F20: =F17+F18-F19 -> 609.47194 | G20: =G17+G18-G19 -> 690.62465 | H20: =H17+H18-H19 -> 774.33542 | I20: =I17+I18-I19 -> 833.86325 | J20: =J17+J18-J19 -> 992.45868
B21: Interest expense (on opening balance) | D21: =D17*(Assumptions!C$52+Assumptions!$D$27/10000) -> 0 | E21: =E17*(Assumptions!D$52+Assumptions!$D$27/10000) -> 20.076493 | F21: =F17*(Assumptions!E$52+Assumptions!$D$27/10000) -> 25.10453 | G21: =G17*(Assumptions!F$52+Assumptions!$D$27/10000) -> 25.902558 | H21: =H17*(Assumptions!G$52+Assumptions!$D$27/10000) -> 29.351548 | I21: =I17*(Assumptions!H$52+Assumptions!$D$27/10000) -> 32.909256 | J21: =J17*(Assumptions!I$52+Assumptions!$D$27/10000) -> 43.777821
B22: Remaining sweep cash after revolver repay | D22: =D13-D19 -> 0 | E22: =E13-E19 -> 0 | F22: =F13-F19 -> 0 | G22: =G13-G19 -> 0 | H22: =H13-H19 -> 0 | I22: =I13-I19 -> 0 | J22: =J13-J19 -> 0
B24: Senior Mortgage (CMBS)
D25: FY2007E | E25: FY2008E | F25: FY2009E | G25: FY2010E | H25: FY2011E | I25: FY2012E | J25: FY2013E
B26: Opening balance | D26: =Assumptions!$C$22 -> 7600 | E26: =D29 -> 7448 | F26: =E29 -> 7296 | G26: =F29 -> 7144 | H26: =G29 -> 6992 | I26: =H29 -> 6840 | J26: =I29 -> 6688
B27: Mandatory amortization | D27: =MIN(D26,Assumptions!$C$22*Assumptions!$G$22) -> 152 | E27: =MIN(E26,Assumptions!$C$22*Assumptions!$G$22) -> 152 | F27: =MIN(F26,Assumptions!$C$22*Assumptions!$G$22) -> 152 | G27: =MIN(G26,Assumptions!$C$22*Assumptions!$G$22) -> 152 | H27: =MIN(H26,Assumptions!$C$22*Assumptions!$G$22) -> 152 | I27: =MIN(I26,Assumptions!$C$22*Assumptions!$G$22) -> 152 | J27: =MIN(J26,Assumptions!$C$22*Assumptions!$G$22) -> 152
B28: Cash sweep | D28: =MIN(D22,D26-D27) -> 0 | E28: =MIN(E22,E26-E27) -> 0 | F28: =MIN(F22,F26-F27) -> 0 | G28: =MIN(G22,G26-G27) -> 0 | H28: =MIN(H22,H26-H27) -> 0 | I28: =MIN(I22,I26-I27) -> 0 | J28: =MIN(J22,J26-J27) -> 0
B29: Closing balance | D29: =D26-D27-D28 -> 7448 | E29: =E26-E27-E28 -> 7296 | F29: =F26-F27-F28 -> 7144 | G29: =G26-G27-G28 -> 6992 | H29: =H26-H27-H28 -> 6840 | I29: =I26-I27-I28 -> 6688 | J29: =J26-J27-J28 -> 6536
B30: Interest expense (on opening balance) | D30: =D26*(Assumptions!C$52+Assumptions!$D$22/10000) -> 494 | E30: =E26*(Assumptions!D$52+Assumptions!$D$22/10000) -> 335.16 | F30: =F26*(Assumptions!E$52+Assumptions!$D$22/10000) -> 218.88 | G30: =G26*(Assumptions!F$52+Assumptions!$D$22/10000) -> 214.32 | H30: =H26*(Assumptions!G$52+Assumptions!$D$22/10000) -> 209.76 | I30: =I26*(Assumptions!H$52+Assumptions!$D$22/10000) -> 205.2 | J30: =J26*(Assumptions!I$52+Assumptions!$D$22/10000) -> 267.52
B31: Remaining sweep cash after this tranche | D31: =D22-D28 -> 0 | E31: =E22-E28 -> 0 | F31: =F22-F28 -> 0 | G31: =G22-G28 -> 0 | H31: =H22-H28 -> 0 | I31: =I22-I28 -> 0 | J31: =J22-J28 -> 0
B33: 2nd Lien Notes
D34: FY2007E | E34: FY2008E | F34: FY2009E | G34: FY2010E | H34: FY2011E | I34: FY2012E | J34: FY2013E
B35: Opening balance | D35: =Assumptions!$C$23 -> 1000 | E35: =D38 -> 980 | F35: =E38 -> 960 | G35: =F38 -> 940 | H35: =G38 -> 920 | I35: =H38 -> 900 | J35: =I38 -> 880
B36: Mandatory amortization | D36: =MIN(D35,Assumptions!$C$23*Assumptions!$G$23) -> 20 | E36: =MIN(E35,Assumptions!$C$23*Assumptions!$G$23) -> 20 | F36: =MIN(F35,Assumptions!$C$23*Assumptions!$G$23) -> 20 | G36: =MIN(G35,Assumptions!$C$23*Assumptions!$G$23) -> 20 | H36: =MIN(H35,Assumptions!$C$23*Assumptions!$G$23) -> 20 | I36: =MIN(I35,Assumptions!$C$23*Assumptions!$G$23) -> 20 | J36: =MIN(J35,Assumptions!$C$23*Assumptions!$G$23) -> 20
B37: Cash sweep | D37: =MIN(D31,D35-D36) -> 0 | E37: =MIN(E31,E35-E36) -> 0 | F37: =MIN(F31,F35-F36) -> 0 | G37: =MIN(G31,G35-G36) -> 0 | H37: =MIN(H31,H35-H36) -> 0 | I37: =MIN(I31,I35-I36) -> 0 | J37: =MIN(J31,J35-J36) -> 0
B38: Closing balance | D38: =D35-D36-D37 -> 980 | E38: =E35-E36-E37 -> 960 | F38: =F35-F36-F37 -> 940 | G38: =G35-G36-G37 -> 920 | H38: =H35-H36-H37 -> 900 | I38: =I35-I36-I37 -> 880 | J38: =J35-J36-J37 -> 860
B39: Interest expense (on opening balance) | D39: =D35*(Assumptions!C$52+Assumptions!$D$23/10000) -> 75 | E39: =E35*(Assumptions!D$52+Assumptions!$D$23/10000) -> 53.9 | F39: =F35*(Assumptions!E$52+Assumptions!$D$23/10000) -> 38.4 | G39: =G35*(Assumptions!F$52+Assumptions!$D$23/10000) -> 37.6 | H39: =H35*(Assumptions!G$52+Assumptions!$D$23/10000) -> 36.8 | I39: =I35*(Assumptions!H$52+Assumptions!$D$23/10000) -> 36 | J39: =J35*(Assumptions!I$52+Assumptions!$D$23/10000) -> 44
B40: Remaining sweep cash after this tranche | D40: =D31-D37 -> 0 | E40: =E31-E37 -> 0 | F40: =F31-F37 -> 0 | G40: =G31-G37 -> 0 | H40: =H31-H37 -> 0 | I40: =I31-I37 -> 0 | J40: =J31-J37 -> 0
B42: Mezzanine I
D43: FY2007E | E43: FY2008E | F43: FY2009E | G43: FY2010E | H43: FY2011E | I43: FY2012E | J43: FY2013E
B44: Opening balance | D44: =Assumptions!$C$24 -> 4500 | E44: =D47 -> 4500 | F44: =E47 -> 4500 | G44: =F47 -> 4500 | H44: =G47 -> 4500 | I44: =H47 -> 4500 | J44: =I47 -> 4500
B45: Mandatory amortization | D45: =MIN(D44,Assumptions!$C$24*Assumptions!$G$24) -> 0 | E45: =MIN(E44,Assumptions!$C$24*Assumptions!$G$24) -> 0 | F45: =MIN(F44,Assumptions!$C$24*Assumptions!$G$24) -> 0 | G45: =MIN(G44,Assumptions!$C$24*Assumptions!$G$24) -> 0 | H45: =MIN(H44,Assumptions!$C$24*Assumptions!$G$24) -> 0 | I45: =MIN(I44,Assumptions!$C$24*Assumptions!$G$24) -> 0 | J45: =MIN(J44,Assumptions!$C$24*Assumptions!$G$24) -> 0
B46: Cash sweep | D46: =MIN(D40,D44-D45) -> 0 | E46: =MIN(E40,E44-E45) -> 0 | F46: =MIN(F40,F44-F45) -> 0 | G46: =MIN(G40,G44-G45) -> 0 | H46: =MIN(H40,H44-H45) -> 0 | I46: =MIN(I40,I44-I45) -> 0 | J46: =MIN(J40,J44-J45) -> 0
...

Sheet Returns
B2: Returns
B3: ($ in millions, except multiples) - deal-vintage underwriting case
B5: 1. Exit Analysis - Vintage Model (3 / 5 / 7 Year Holds)
D6: Year 3 (FY2009E) | E6: Year 5 (FY2011E) | F6: Year 7 (FY2013E)
B7: Exit EBITDA | D7: =Model!I$9 -> 1411.7012 | E7: =Model!K$9 -> 1573.3905 | F7: =Model!M$9 -> 1951.2499
B8: Exit EV / EBITDA multiple | D8: =Assumptions!$C$58 -> 14.585714 | E8: =Assumptions!$C$58 -> 14.585714 | F8: =Assumptions!$C$58 -> 14.585714
B9: Exit Enterprise Value | D9: =D7*D8 -> 20590.67 | E9: =E7*E8 -> 22949.025 | F9: =F7*F8 -> 28460.373
B10: Less: Net Debt at Exit | D10: =DebtSchedule!F$74 -> 20793.472 | E10: =DebtSchedule!H$74 -> 20614.335 | F10: =DebtSchedule!J$74 -> 20488.459
B11: Equity Value at Exit | D11: =D9-D10 -> -202.80228 | E11: =E9-E10 -> 2334.6894 | F11: =F9-F10 -> 7971.9144
B12: Sponsor Equity Invested | D12: ='Sources-Uses'!$D$13 -> 6105.5 | E12: ='Sources-Uses'!$D$13 -> 6105.5 | F12: ='Sources-Uses'!$D$13 -> 6105.5
B13: MOIC | D13: =D11/D12 -> -0.033216326 | E13: =E11/E12 -> 0.38239118 | F13: =F11/F12 -> 1.3056939
B14: IRR (closed-form: MOIC^(1/yrs)-1) | D14: =IFERROR(IF(D13<=0,"n.m.",D13^(1/3)-1),"n.m.") -> n.m. | E14: =IFERROR(IF(E13<=0,"n.m.",E13^(1/5)-1),"n.m.") -> -0.17490952 | F14: =IFERROR(IF(F13<=0,"n.m.",F13^(1/7)-1),"n.m.") -> 0.038840254
B16: IRR cross-check (5-yr case), dated cash flow via IRR():
C17: Year 0 | D17: Year 1 | E17: Year 2 | F17: Year 3 | G17: Year 4 | H17: Year 5
B18: Dated cash flow (Year0 = equity out, Year5 = equity in) | C18: =-E12 -> -6105.5 | D18: 0 | E18: 0 | F18: 0 | G18: 0 | H18: =E11 -> 2334.6894
B19: IRR() cross-check | C19: =IRR(C18:H18) -> -0.17490952 | D19: Check vs closed-form (col E above): | E19: =ROUND(C19-E14,4) -> 0
B21: 2a. Sensitivity: Entry x Exit EV/EBITDA Multiple -> 5-Year MOIC & IRR
B23: Fixed-$ debt structure: entry/exit multiple flex sponsor equity only; debt schedule is invariant.
B25: 5-Year MOIC grid
B26: Entry (rows) x Exit (cols) | C26: =E13 -> 0.38239118 | D26: =Assumptions!$C$58+(-2) -> 12.585714 | E26: =Assumptions!$C$58+(-1) -> 13.585714 | F26: =Assumptions!$C$58+(0) -> 14.585714 | G26: =Assumptions!$C$58+(1) -> 15.585714 | H26: =Assumptions!$C$58+(2) -> 16.585714
C27: =Assumptions!$C$14+(-1.5) -> 13.085714 | D27: =(D$26*Model!$K$9-DebtSchedule!$H$74)/($C27*Assumptions!$C$13+$C27*Assumptions!$C$13*Assumptions!$C$15+Assumptions!$C$28*Assumptions!$C$16+'Sources-Uses'!$D$22-Assumptions!$C$28) -> -0.23689956 | E27: =(E$26*Model!$K$9-DebtSchedule!$H$74)/($C27*Assumptions!$C$13+$C27*Assumptions!$C$13*Assumptions!$C$15+Assumptions!$C$28*Assumptions!$C$16+'Sources-Uses'!$D$22-Assumptions!$C$28) -> 0.22208251 | F27: =(F$26*Model!$K$9-DebtSchedule!$H$74)/($C27*Assumptions!$C$13+$C27*Assumptions!$C$13*Assumptions!$C$15+Assumptions!$C$28*Assumptions!$C$16+'Sources-Uses'!$D$22-Assumptions!$C$28) -> 0.68106458 | G27: =(G$26*Model!$K$9-DebtSchedule!$H$74)/($C27*Assumptions!$C$13+$C27*Assumptions!$C$13*Assumptions!$C$15+Assumptions!$C$28*Assumptions!$C$16+'Sources-Uses'!$D$22-Assumptions!$C$28) -> 1.1400466 | H27: =(H$26*Model!$K$9-DebtSchedule!$H$74)/($C27*Assumptions!$C$13+$C27*Assumptions!$C$13*Assumptions!$C$15+Assumptions!$C$28*Assumptions!$C$16+'Sources-Uses'!$D$22-Assumptions!$C$28) -> 1.5990287
C28: =Assumptions!$C$14+(-1) -> 13.585714 | D28: =(D$26*Model!$K$9-DebtSchedule!$H$74)/($C28*Assumptions!$C$13+$C28*Assumptions!$C$13*Assumptions!$C$15+Assumptions!$C$28*Assumptions!$C$16+'Sources-Uses'!$D$22-Assumptions!$C$28) -> -0.18796243 | E28: =(E$26*Model!$K$9-DebtSchedule!$H$74)/($C28*Assumptions!$C$13+$C28*Assumptions!$C$13*Assumptions!$C$15+Assumptions!$C$28*Assumptions!$C$16+'Sources-Uses'!$D$22-Assumptions!$C$28) -> 0.17620619 | F28: =(F$26*Model!$K$9-DebtSchedule!$H$74)/($C28*Assumptions!$C$13+$C28*Assumptions!$C$13*Assumptions!$C$15+Assumptions!$C$28*Assumptions!$C$16+'Sources-Uses'!$D$22-Assumptions!$C$28) -> 0.54037481 | G28: =(G$26*Model!$K$9-DebtSchedule!$H$74)/($C28*Assumptions!$C$13+$C28*Assumptions!$C$13*Assumptions!$C$15+Assumptions!$C$28*Assumptions!$C$16+'Sources-Uses'!$D$22-Assumptions!$C$28) -> 0.90454343 | H28: =(H$26*Model!$K$9-DebtSchedule!$H$74)/($C28*Assumptions!$C$13+$C28*Assumptions!$C$13*Assumptions!$C$15+Assumptions!$C$28*Assumptions!$C$16+'Sources-Uses'!$D$22-Assumptions!$C$28) -> 1.2687121
C29: =Assumptions!$C$14+(-0.5) -> 14.085714 | D29: =(D$26*Model!$K$9-DebtSchedule!$H$74)/($C29*Assumptions!$C$13+$C29*Assumptions!$C$13*Assumptions!$C$15+Assumptions!$C$28*Assumptions!$C$16+'Sources-Uses'!$D$22-Assumptions!$C$28) -> -0.15578202 | E29: =(E$26*Model!$K$9-DebtSchedule!$H$74)/($C29*Assumptions!$C$13+$C29*Assumptions!$C$13*Assumptions!$C$15+Assumptions!$C$28*Assumptions!$C$16+'Sources-Uses'!$D$22-Assumptions!$C$28) -> 0.14603853 | F29: =(F$26*Model!$K$9-DebtSchedule!$H$74)/($C29*Assumptions!$C$13+$C29*Assumptions!$C$13*Assumptions!$C$15+Assumptions!$C$28*Assumptions!$C$16+'Sources-Uses'!$D$22-Assumptions!$C$28) -> 0.44785908 | G29: =(G$26*Model!$K$9-DebtSchedule!$H$74)/($C29*Assumptions!$C$13+$C29*Assumptions!$C$13*Assumptions!$C$15+Assumptions!$C$28*Assumptions!$C$16+'Sources-Uses'!$D$22-Assumptions!$C$28) -> 0.74967963 | H29: =(H$26*Model!$K$9-DebtSchedule!$H$74)/($C29*Assumptions!$C$13+$C29*Assumptions!$C$13*Assumptions!$C$15+Assumptions!$C$28*Assumptions!$C$16+'Sources-Uses'!$D$22-Assumptions!$C$28) -> 1.0515002
C30: =Assumptions!$C$14+(0) -> 14.585714 | D30: =(D$26*Model!$K$9-DebtSchedule!$H$74)/($C30*Assumptions!$C$13+$C30*Assumptions!$C$13*Assumptions!$C$15+Assumptions!$C$28*Assumptions!$C$16+'Sources-Uses'!$D$22-Assumptions!$C$28) -> -0.13300986 | E30: =(E$26*Model!$K$9-DebtSchedule!$H$74)/($C30*Assumptions!$C$13+$C30*Assumptions!$C$13*Assumptions!$C$15+Assumptions!$C$28*Assumptions!$C$16+'Sources-Uses'!$D$22-Assumptions!$C$28) -> 0.12469066 | F30: =(F$26*Model!$K$9-DebtSchedule!$H$74)/($C30*Assumptions!$C$13+$C30*Assumptions!$C$13*Assumptions!$C$15+Assumptions!$C$28*Assumptions!$C$16+'Sources-Uses'!$D$22-Assumptions!$C$28) -> 0.38239118 | G30: =(G$26*Model!$K$9-DebtSchedule!$H$74)/($C30*Assumptions!$C$13+$C30*Assumptions!$C$13*Assumptions!$C$15+Assumptions!$C$28*Assumptions!$C$16+'Sources-Uses'!$D$22-Assumptions!$C$28) -> 0.64009171 | H30: =(H$26*Model!$K$9-DebtSchedule!$H$74)/($C30*Assumptions!$C$13+$C30*Assumptions!$C$13*Assumptions!$C$15+Assumptions!$C$28*Assumptions!$C$16+'Sources-Uses'!$D$22-Assumptions!$C$28) -> 0.89779223
C31: =Assumptions!$C$14+(0.5) -> 15.085714 | D31: =(D$26*Model!$K$9-DebtSchedule!$H$74)/($C31*Assumptions!$C$13+$C31*Assumptions!$C$13*Assumptions!$C$15+Assumptions!$C$28*Assumptions!$C$16+'Sources-Uses'!$D$22-Assumptions!$C$28) -> -0.11604626 | E31: =(E$26*Model!$K$9-DebtSchedule!$H$74)/($C31*Assumptions!$C$13+$C31*Assumptions!$C$13*Assumptions!$C$15+Assumptions!$C$28*Assumptions!$C$16+'Sources-Uses'!$D$22-Assumptions!$C$28) -> 0.10878806 | F31: =(F$26*Model!$K$9-DebtSchedule!$H$74)/($C31*Assumptions!$C$13+$C31*Assumptions!$C$13*Assumptions!$C$15+Assumptions!$C$28*Assumptions!$C$16+'Sources-Uses'!$D$22-Assumptions!$C$28) -> 0.33362237 | G31: =(G$26*Model!$K$9-DebtSchedule!$H$74)/($C31*Assumptions!$C$13+$C31*Assumptions!$C$13*Assumptions!$C$15+Assumptions!$C$28*Assumptions!$C$16+'Sources-Uses'!$D$22-Assumptions!$C$28) -> 0.55845669 | H31: =(H$26*Model!$K$9-DebtSchedule!$H$74)/($C31*Assumptions!$C$13+$C31*Assumptions!$C$13*Assumptions!$C$15+Assumptions!$C$28*Assumptions!$C$16+'Sources-Uses'!$D$22-Assumptions!$C$28) -> 0.783291
C32: =Assumptions!$C$14+(1) -> 15.585714 | D32: =(D$26*Model!$K$9-DebtSchedule!$H$74)/($C32*Assumptions!$C$13+$C32*Assumptions!$C$13*Assumptions!$C$15+Assumptions!$C$28*Assumptions!$C$16+'Sources-Uses'!$D$22-Assumptions!$C$28) -> -0.10292018 | E32: =(E$26*Model!$K$9-DebtSchedule!$H$74)/($C32*Assumptions!$C$13+$C32*Assumptions!$C$13*Assumptions!$C$15+Assumptions!$C$28*Assumptions!$C$16+'Sources-Uses'!$D$22-Assumptions!$C$28) -> 0.096482966 | F32: =(F$26*Model!$K$9-DebtSchedule!$H$74)/($C32*Assumptions!$C$13+$C32*Assumptions!$C$13*Assumptions!$C$15+Assumptions!$C$28*Assumptions!$C$16+'Sources-Uses'!$D$22-Assumptions!$C$28) -> 0.29588611 | G32: =(G$26*Model!$K$9-DebtSchedule!$H$74)/($C32*Assumptions!$C$13+$C32*Assumptions!$C$13*Assumptions!$C$15+Assumptions!$C$28*Assumptions!$C$16+'Sources-Uses'!$D$22-Assumptions!$C$28) -> 0.49528926 | H32: =(H$26*Model!$K$9-DebtSchedule!$H$74)/($C32*Assumptions!$C$13+$C32*Assumptions!$C$13*Assumptions!$C$15+Assumptions!$C$28*Assumptions!$C$16+'Sources-Uses'!$D$22-Assumptions!$C$28) -> 0.69469241
C33: =Assumptions!$C$14+(1.5) -> 16.085714 | D33: =(D$26*Model!$K$9-DebtSchedule!$H$74)/($C33*Assumptions!$C$13+$C33*Assumptions!$C$13*Assumptions!$C$15+Assumptions!$C$28*Assumptions!$C$16+'Sources-Uses'!$D$22-Assumptions!$C$28) -> -0.092461767 | E33: =(E$26*Model!$K$9-DebtSchedule!$H$74)/($C33*Assumptions!$C$13+$C33*Assumptions!$C$13*Assumptions!$C$15+Assumptions!$C$28*Assumptions!$C$16+'Sources-Uses'!$D$22-Assumptions!$C$28) -> 0.086678679 | F33: =(F$26*Model!$K$9-DebtSchedule!$H$74)/($C33*Assumptions!$C$13+$C33*Assumptions!$C$13*Assumptions!$C$15+Assumptions!$C$28*Assumptions!$C$16+'Sources-Uses'!$D$22-Assumptions!$C$28) -> 0.26581912 | G33: =(G$26*Model!$K$9-DebtSchedule!$H$74)/($C33*Assumptions!$C$13+$C33*Assumptions!$C$13*Assumptions!$C$15+Assumptions!$C$28*Assumptions!$C$16+'Sources-Uses'!$D$22-Assumptions!$C$28) -> 0.44495957 | H33: =(H$26*Model!$K$9-DebtSchedule!$H$74)/($C33*Assumptions!$C$13+$C33*Assumptions!$C$13*Assumptions!$C$15+Assumptions!$C$28*Assumptions!$C$16+'Sources-Uses'!$D$22-Assumptions!$C$28) -> 0.62410002
B35: 5-Year IRR grid
B36: Entry (rows) x Exit (cols) | C36: =E14 -> -0.17490952 | D36: =Assumptions!$C$58+(-2) -> 12.585714 | E36: =Assumptions!$C$58+(-1) -> 13.585714 | F36: =Assumptions!$C$58+(0) -> 14.585714 | G36: =Assumptions!$C$58+(1) -> 15.585714 | H36: =Assumptions!$C$58+(2) -> 16.585714
C37: =Assumptions!$C$14+(-1.5) -> 13.085714 | D37: =IFERROR(IF(((D$36*Model!$K$9-DebtSchedule!$H$74)/($C37*Assumptions!$C$13+$C37*Assumptions!$C$13*Assumptions!$C$15+Assumptions!$C$28*Assumptions!$C$16+'Sources-Uses'!$D$22-Assumptions!$C$28))<=0,"n.m.",((D$36*Model!$K$9-DebtSchedule!$H$74)/($C37*Assumptions!$C$13+$C37*Assumptions!$C$13*Assumptions!$C$15+Assumptions!$C$28*Assumptions!$C$16+'Sources-Uses'!$D$22-Assumptions!$C$28))^(1/5)-1),"n.m.") -> n.m. | E37: =IFERROR(IF(((E$36*Model!$K$9-DebtSchedule!$H$74)/($C37*Assumptions!$C$13+$C37*Assumptions!$C$13*Assumptions!$C$15+Assumptions!$C$28*Assumptions!$C$16+'Sources-Uses'!$D$22-Assumptions!$C$28))<=0,"n.m.",((E$36*Model!$K$9-DebtSchedule!$H$74)/($C37*Assumptions!$C$13+$C37*Assumptions!$C$13*Assumptions!$C$15+Assumptions!$C$28*Assumptions!$C$16+'Sources-Uses'!$D$22-Assumptions!$C$28))^(1/5)-1),"n.m.") -> -0.25987875 | F37: =IFERROR(IF(((F$36*Model!$K$9-DebtSchedule!$H$74)/($C37*Assumptions!$C$13+$C37*Assumptions!$C$13*Assumptions!$C$15+Assumptions!$C$28*Assumptions!$C$16+'Sources-Uses'!$D$22-Assumptions!$C$28))<=0,"n.m.",((F$36*Model!$K$9-DebtSchedule!$H$74)/($C37*Assumptions!$C$13+$C37*Assumptions!$C$13*Assumptions!$C$15+Assumptions!$C$28*Assumptions!$C$16+'Sources-Uses'!$D$22-Assumptions!$C$28))^(1/5)-1),"n.m.") -> -0.073943128 | G37: =IFERROR(IF(((G$36*Model!$K$9-DebtSchedule!$H$74)/($C37*Assumptions!$C$13+$C37*Assumptions!$C$13*Assumptions!$C$15+Assumptions!$C$28*Assumptions!$C$16+'Sources-Uses'!$D$22-Assumptions!$C$28))<=0,"n.m.",((G$36*Model!$K$9-DebtSchedule!$H$74)/($C37*Assumptions!$C$13+$C37*Assumptions!$C$13*Assumptions!$C$15+Assumptions!$C$28*Assumptions!$C$16+'Sources-Uses'!$D$22-Assumptions!$C$28))^(1/5)-1),"n.m.") -> 0.026560441 | H37: =IFERROR(IF(((H$36*Model!$K$9-DebtSchedule!$H$74)/($C37*Assumptions!$C$13+$C37*Assumptions!$C$13*Assumptions!$C$15+Assumptions!$C$28*Assumptions!$C$16+'Sources-Uses'!$D$22-Assumptions!$C$28))<=0,"n.m.",((H$36*Model!$K$9-DebtSchedule!$H$74)/($C37*Assumptions!$C$13+$C37*Assumptions!$C$13*Assumptions!$C$15+Assumptions!$C$28*Assumptions!$C$16+'Sources-Uses'!$D$22-Assumptions!$C$28))^(1/5)-1),"n.m.") -> 0.098427134
C38: =Assumptions!$C$14+(-1) -> 13.585714 | D38: =IFERROR(IF(((D$36*Model!$K$9-DebtSchedule!$H$74)/($C38*Assumptions!$C$13+$C38*Assumptions!$C$13*Assumptions!$C$15+Assumptions!$C$28*Assumptions!$C$16+'Sources-Uses'!$D$22-Assumptions!$C$28))<=0,"n.m.",((D$36*Model!$K$9-DebtSchedule!$H$74)/($C38*Assumptions!$C$13+$C38*Assumptions!$C$13*Assumptions!$C$15+Assumptions!$C$28*Assumptions!$C$16+'Sources-Uses'!$D$22-Assumptions!$C$28))^(1/5)-1),"n.m.") -> n.m. | E38: =IFERROR(IF(((E$36*Model!$K$9-DebtSchedule!$H$74)/($C38*Assumptions!$C$13+$C38*Assumptions!$C$13*Assumptions!$C$15+Assumptions!$C$28*Assumptions!$C$16+'Sources-Uses'!$D$22-Assumptions!$C$28))<=0,"n.m.",((E$36*Model!$K$9-DebtSchedule!$H$74)/($C38*Assumptions!$C$13+$C38*Assumptions!$C$13*Assumptions!$C$15+Assumptions!$C$28*Assumptions!$C$16+'Sources-Uses'!$D$22-Assumptions!$C$28))^(1/5)-1),"n.m.") -> -0.29335021 | F38: =IFERROR(IF(((F$36*Model!$K$9-DebtSchedule!$H$74)/($C38*Assumptions!$C$13+$C38*Assumptions!$C$13*Assumptions!$C$15+Assumptions!$C$28*Assumptions!$C$16+'Sources-Uses'!$D$22-Assumptions!$C$28))<=0,"n.m.",((F$36*Model!$K$9-DebtSchedule!$H$74)/($C38*Assumptions!$C$13+$C38*Assumptions!$C$13*Assumptions!$C$15+Assumptions!$C$28*Assumptions!$C$16+'Sources-Uses'!$D$22-Assumptions!$C$28))^(1/5)-1),"n.m.") -> -0.1158234 | G38: =IFERROR(IF(((G$36*Model!$K$9-DebtSchedule!$H$74)/($C38*Assumptions!$C$13+$C38*Assumptions!$C$13*Assumptions!$C$15+Assumptions!$C$28*Assumptions!$C$16+'Sources-Uses'!$D$22-Assumptions!$C$28))<=0,"n.m.",((G$36*Model!$K$9-DebtSchedule!$H$74)/($C38*Assumptions!$C$13+$C38*Assumptions!$C$13*Assumptions!$C$15+Assumptions!$C$28*Assumptions!$C$16+'Sources-Uses'!$D$22-Assumptions!$C$28))^(1/5)-1),"n.m.") -> -0.019865029 | H38: =IFERROR(IF(((H$36*Model!$K$9-DebtSchedule!$H$74)/($C38*Assumptions!$C$13+$C38*Assumptions!$C$13*Assumptions!$C$15+Assumptions!$C$28*Assumptions!$C$16+'Sources-Uses'!$D$22-Assumptions!$C$28))<=0,"n.m.",((H$36*Model!$K$9-DebtSchedule!$H$74)/($C38*Assumptions!$C$13+$C38*Assumptions!$C$13*Assumptions!$C$15+Assumptions!$C$28*Assumptions!$C$16+'Sources-Uses'!$D$22-Assumptions!$C$28))^(1/5)-1),"n.m.") -> 0.048751545
C39: =Assumptions!$C$14+(-0.5) -> 14.085714 | D39: =IFERROR(IF(((D$36*Model!$K$9-DebtSchedule!$H$74)/($C39*Assumptions!$C$13+$C39*Assumptions!$C$13*Assumptions!$C$15+Assumptions!$C$28*Assumptions!$C$16+'Sources-Uses'!$D$22-Assumptions!$C$28))<=0,"n.m.",((D$36*Model!$K$9-DebtSchedule!$H$74)/($C39*Assumptions!$C$13+$C39*Assumptions!$C$13*Assumptions!$C$15+Assumptions!$C$28*Assumptions!$C$16+'Sources-Uses'!$D$22-Assumptions!$C$28))^(1/5)-1),"n.m.") -> n.m. | E39: =IFERROR(IF(((E$36*Model!$K$9-DebtSchedule!$H$74)/($C39*Assumptions!$C$13+$C39*Assumptions!$C$13*Assumptions!$C$15+Assumptions!$C$28*Assumptions!$C$16+'Sources-Uses'!$D$22-Assumptions!$C$28))<=0,"n.m.",((E$36*Model!$K$9-DebtSchedule!$H$74)/($C39*Assumptions!$C$13+$C39*Assumptions!$C$13*Assumptions!$C$15+Assumptions!$C$28*Assumptions!$C$16+'Sources-Uses'!$D$22-Assumptions!$C$28))^(1/5)-1),"n.m.") -> -0.31939758 | F39: =IFERROR(IF(((F$36*Model!$K$9-DebtSchedule!$H$74)/($C39*Assumptions!$C$13+$C39*Assumptions!$C$13*Assumptions!$C$15+Assumptions!$C$28*Assumptions!$C$16+'Sources-Uses'!$D$22-Assumptions!$C$28))<=0,"n.m.",((F$36*Model!$K$9-DebtSchedule!$H$74)/($C39*Assumptions!$C$13+$C39*Assumptions!$C$13*Assumptions!$C$15+Assumptions!$C$28*Assumptions!$C$16+'Sources-Uses'!$D$22-Assumptions!$C$28))^(1/5)-1),"n.m.") -> -0.14841446 | G39: =IFERROR(IF(((G$36*Model!$K$9-DebtSchedule!$H$74)/($C39*Assumptions!$C$13+$C39*Assumptions!$C$13*Assumptions!$C$15+Assumptions!$C$28*Assumptions!$C$16+'Sources-Uses'!$D$22-Assumptions!$C$28))<=0,"n.m.",((G$36*Model!$K$9-DebtSchedule!$H$74)/($C39*Assumptions!$C$13+$C39*Assumptions!$C$13*Assumptions!$C$15+Assumptions!$C$28*Assumptions!$C$16+'Sources-Uses'!$D$22-Assumptions!$C$28))^(1/5)-1),"n.m.") -> -0.055993158 | H39: =IFERROR(IF(((H$36*Model!$K$9-DebtSchedule!$H$74)/($C39*Assumptions!$C$13+$C39*Assumptions!$C$13*Assumptions!$C$15+Assumptions!$C$28*Assumptions!$C$16+'Sources-Uses'!$D$22-Assumptions!$C$28))<=0,"n.m.",((H$36*Model!$K$9-DebtSchedule!$H$74)/($C39*Assumptions!$C$13+$C39*Assumptions!$C$13*Assumptions!$C$15+Assumptions!$C$28*Assumptions!$C$16+'Sources-Uses'!$D$22-Assumptions!$C$28))^(1/5)-1),"n.m.") -> 0.010094184
C40: =Assumptions!$C$14+(0) -> 14.585714 | D40: =IFERROR(IF(((D$36*Model!$K$9-DebtSchedule!$H$74)/($C40*Assumptions!$C$13+$C40*Assumptions!$C$13*Assumptions!$C$15+Assumptions!$C$28*Assumptions!$C$16+'Sources-Uses'!$D$22-Assumptions!$C$28))<=0,"n.m.",((D$36*Model!$K$9-DebtSchedule!$H$74)/($C40*Assumptions!$C$13+$C40*Assumptions!$C$13*Assumptions!$C$15+Assumptions!$C$28*Assumptions!$C$16+'Sources-Uses'!$D$22-Assumptions!$C$28))^(1/5)-1),"n.m.") -> n.m. | E40: =IFERROR(IF(((E$36*Model!$K$9-DebtSchedule!$H$74)/($C40*Assumptions!$C$13+$C40*Assumptions!$C$13*Assumptions!$C$15+Assumptions!$C$28*Assumptions!$C$16+'Sources-Uses'!$D$22-Assumptions!$C$28))<=0,"n.m.",((E$36*Model!$K$9-DebtSchedule!$H$74)/($C40*Assumptions!$C$13+$C40*Assumptions!$C$13*Assumptions!$C$15+Assumptions!$C$28*Assumptions!$C$16+'Sources-Uses'!$D$22-Assumptions!$C$28))^(1/5)-1),"n.m.") -> -0.34057291 | F40: =IFERROR(IF(((F$36*Model!$K$9-DebtSchedule!$H$74)/($C40*Assumptions!$C$13+$C40*Assumptions!$C$13*Assumptions!$C$15+Assumptions!$C$28*Assumptions!$C$16+'Sources-Uses'!$D$22-Assumptions!$C$28))<=0,"n.m.",((F$36*Model!$K$9-DebtSchedule!$H$74)/($C40*Assumptions!$C$13+$C40*Assumptions!$C$13*Assumptions!$C$15+Assumptions!$C$28*Assumptions!$C$16+'Sources-Uses'!$D$22-Assumptions!$C$28))^(1/5)-1),"n.m.") -> -0.17490952 | G40: =IFERROR(IF(((G$36*Model!$K$9-DebtSchedule!$H$74)/($C40*Assumptions!$C$13+$C40*Assumptions!$C$13*Assumptions!$C$15+Assumptions!$C$28*Assumptions!$C$16+'Sources-Uses'!$D$22-Assumptions!$C$28))<=0,"n.m.",((G$36*Model!$K$9-DebtSchedule!$H$74)/($C40*Assumptions!$C$13+$C40*Assumptions!$C$13*Assumptions!$C$15+Assumptions!$C$28*Assumptions!$C$16+'Sources-Uses'!$D$22-Assumptions!$C$28))^(1/5)-1),"n.m.") -> -0.085363687 | H40: =IFERROR(IF(((H$36*Model!$K$9-DebtSchedule!$H$74)/($C40*Assumptions!$C$13+$C40*Assumptions!$C$13*Assumptions!$C$15+Assumptions!$C$28*Assumptions!$C$16+'Sources-Uses'!$D$22-Assumptions!$C$28))<=0,"n.m.",((H$36*Model!$K$9-DebtSchedule!$H$74)/($C40*Assumptions!$C$13+$C40*Assumptions!$C$13*Assumptions!$C$15+Assumptions!$C$28*Assumptions!$C$16+'Sources-Uses'!$D$22-Assumptions!$C$28))^(1/5)-1),"n.m.") -> -0.021332496
C41: =Assumptions!$C$14+(0.5) -> 15.085714 | D41: =IFERROR(IF(((D$36*Model!$K$9-DebtSchedule!$H$74)/($C41*Assumptions!$C$13+$C41*Assumptions!$C$13*Assumptions!$C$15+Assumptions!$C$28*Assumptions!$C$16+'Sources-Uses'!$D$22-Assumptions!$C$28))<=0,"n.m.",((D$36*Model!$K$9-DebtSchedule!$H$74)/($C41*Assumptions!$C$13+$C41*Assumptions!$C$13*Assumptions!$C$15+Assumptions!$C$28*Assumptions!$C$16+'Sources-Uses'!$D$22-Assumptions!$C$28))^(1/5)-1),"n.m.") -> n.m. | E41: =IFERROR(IF(((E$36*Model!$K$9-DebtSchedule!$H$74)/($C41*Assumptions!$C$13+$C41*Assumptions!$C$13*Assumptions!$C$15+Assumptions!$C$28*Assumptions!$C$16+'Sources-Uses'!$D$22-Assumptions!$C$28))<=0,"n.m.",((E$36*Model!$K$9-DebtSchedule!$H$74)/($C41*Assumptions!$C$13+$C41*Assumptions!$C$13*Assumptions!$C$15+Assumptions!$C$28*Assumptions!$C$16+'Sources-Uses'!$D$22-Assumptions!$C$28))^(1/5)-1),"n.m.") -> -0.35832334 | F41: =IFERROR(IF(((F$36*Model!$K$9-DebtSchedule!$H$74)/($C41*Assumptions!$C$13+$C41*Assumptions!$C$13*Assumptions!$C$15+Assumptions!$C$28*Assumptions!$C$16+'Sources-Uses'!$D$22-Assumptions!$C$28))<=0,"n.m.",((F$36*Model!$K$9-DebtSchedule!$H$74)/($C41*Assumptions!$C$13+$C41*Assumptions!$C$13*Assumptions!$C$15+Assumptions!$C$28*Assumptions!$C$16+'Sources-Uses'!$D$22-Assumptions!$C$28))^(1/5)-1),"n.m.") -> -0.19711927 | G41: =IFERROR(IF(((G$36*Model!$K$9-DebtSchedule!$H$74)/($C41*Assumptions!$C$13+$C41*Assumptions!$C$13*Assumptions!$C$15+Assumptions!$C$28*Assumptions!$C$16+'Sources-Uses'!$D$22-Assumptions!$C$28))<=0,"n.m.",((G$36*Model!$K$9-DebtSchedule!$H$74)/($C41*Assumptions!$C$13+$C41*Assumptions!$C$13*Assumptions!$C$15+Assumptions!$C$28*Assumptions!$C$16+'Sources-Uses'!$D$22-Assumptions!$C$28))^(1/5)-1),"n.m.") -> -0.10998383 | H41: =IFERROR(IF(((H$36*Model!$K$9-DebtSchedule!$H$74)/($C41*Assumptions!$C$13+$C41*Assumptions!$C$13*Assumptions!$C$15+Assumptions!$C$28*Assumptions!$C$16+'Sources-Uses'!$D$22-Assumptions!$C$28))<=0,"n.m.",((H$36*Model!$K$9-DebtSchedule!$H$74)/($C41*Assumptions!$C$13+$C41*Assumptions!$C$13*Assumptions!$C$15+Assumptions!$C$28*Assumptions!$C$16+'Sources-Uses'!$D$22-Assumptions!$C$28))^(1/5)-1),"n.m.") -> -0.047676223
C42: =Assumptions!$C$14+(1) -> 15.585714 | D42: =IFERROR(IF(((D$36*Model!$K$9-DebtSchedule!$H$74)/($C42*Assumptions!$C$13+$C42*Assumptions!$C$13*Assumptions!$C$15+Assumptions!$C$28*Assumptions!$C$16+'Sources-Uses'!$D$22-Assumptions!$C$28))<=0,"n.m.",((D$36*Model!$K$9-DebtSchedule!$H$74)/($C42*Assumptions!$C$13+$C42*Assumptions!$C$13*Assumptions!$C$15+Assumptions!$C$28*Assumptions!$C$16+'Sources-Uses'!$D$22-Assumptions!$C$28))^(1/5)-1),"n.m.") -> n.m. | E42: =IFERROR(IF(((E$36*Model!$K$9-DebtSchedule!$H$74)/($C42*Assumptions!$C$13+$C42*Assumptions!$C$13*Assumptions!$C$15+Assumptions!$C$28*Assumptions!$C$16+'Sources-Uses'!$D$22-Assumptions!$C$28))<=0,"n.m.",((E$36*Model!$K$9-DebtSchedule!$H$74)/($C42*Assumptions!$C$13+$C42*Assumptions!$C$13*Assumptions!$C$15+Assumptions!$C$28*Assumptions!$C$16+'Sources-Uses'!$D$22-Assumptions!$C$28))^(1/5)-1),"n.m.") -> -0.37354464 | F42: =IFERROR(IF(((F$36*Model!$K$9-DebtSchedule!$H$74)/($C42*Assumptions!$C$13+$C42*Assumptions!$C$13*Assumptions!$C$15+Assumptions!$C$28*Assumptions!$C$16+'Sources-Uses'!$D$22-Assumptions!$C$28))<=0,"n.m.",((F$36*Model!$K$9-DebtSchedule!$H$74)/($C42*Assumptions!$C$13+$C42*Assumptions!$C$13*Assumptions!$C$15+Assumptions!$C$28*Assumptions!$C$16+'Sources-Uses'!$D$22-Assumptions!$C$28))^(1/5)-1),"n.m.") -> -0.21616452 | G42: =IFERROR(IF(((G$36*Model!$K$9-DebtSchedule!$H$74)/($C42*Assumptions!$C$13+$C42*Assumptions!$C$13*Assumptions!$C$15+Assumptions!$C$28*Assumptions!$C$16+'Sources-Uses'!$D$22-Assumptions!$C$28))<=0,"n.m.",((G$36*Model!$K$9-DebtSchedule!$H$74)/($C42*Assumptions!$C$13+$C42*Assumptions!$C$13*Assumptions!$C$15+Assumptions!$C$28*Assumptions!$C$16+'Sources-Uses'!$D$22-Assumptions!$C$28))^(1/5)-1),"n.m.") -> -0.13109603 | H42: =IFERROR(IF(((H$36*Model!$K$9-DebtSchedule!$H$74)/($C42*Assumptions!$C$13+$C42*Assumptions!$C$13*Assumptions!$C$15+Assumptions!$C$28*Assumptions!$C$16+'Sources-Uses'!$D$22-Assumptions!$C$28))<=0,"n.m.",((H$36*Model!$K$9-DebtSchedule!$H$74)/($C42*Assumptions!$C$13+$C42*Assumptions!$C$13*Assumptions!$C$15+Assumptions!$C$28*Assumptions!$C$16+'Sources-Uses'!$D$22-Assumptions!$C$28))^(1/5)-1),"n.m.") -> -0.070266434
C43: =Assumptions!$C$14+(1.5) -> 16.085714 | D43: =IFERROR(IF(((D$36*Model!$K$9-DebtSchedule!$H$74)/($C43*Assumptions!$C$13+$C43*Assumptions!$C$13*Assumptions!$C$15+Assumptions!$C$28*Assumptions!$C$16+'Sources-Uses'!$D$22-Assumptions!$C$28))<=0,"n.m.",((D$36*Model!$K$9-DebtSchedule!$H$74)/($C43*Assumptions!$C$13+$C43*Assumptions!$C$13*Assumptions!$C$15+Assumptions!$C$28*Assumptions!$C$16+'Sources-Uses'!$D$22-Assumptions!$C$28))^(1/5)-1),"n.m.") -> n.m. | E43: =IFERROR(IF(((E$36*Model!$K$9-DebtSchedule!$H$74)/($C43*Assumptions!$C$13+$C43*Assumptions!$C$13*Assumptions!$C$15+Assumptions!$C$28*Assumptions!$C$16+'Sources-Uses'!$D$22-Assumptions!$C$28))<=0,"n.m.",((E$36*Model!$K$9-DebtSchedule!$H$74)/($C43*Assumptions!$C$13+$C43*Assumptions!$C$13*Assumptions!$C$15+Assumptions!$C$28*Assumptions!$C$16+'Sources-Uses'!$D$22-Assumptions!$C$28))^(1/5)-1),"n.m.") -> -0.3868278 | F43: =IFERROR(IF(((F$36*Model!$K$9-DebtSchedule!$H$74)/($C43*Assumptions!$C$13+$C43*Assumptions!$C$13*Assumptions!$C$15+Assumptions!$C$28*Assumptions!$C$16+'Sources-Uses'!$D$22-Assumptions!$C$28))<=0,"n.m.",((F$36*Model!$K$9-DebtSchedule!$H$74)/($C43*Assumptions!$C$13+$C43*Assumptions!$C$13*Assumptions!$C$15+Assumptions!$C$28*Assumptions!$C$16+'Sources-Uses'!$D$22-Assumptions!$C$28))^(1/5)-1),"n.m.") -> -0.23278472 | G43: =IFERROR(IF(((G$36*Model!$K$9-DebtSchedule!$H$74)/($C43*Assumptions!$C$13+$C43*Assumptions!$C$13*Assumptions!$C$15+Assumptions!$C$28*Assumptions!$C$16+'Sources-Uses'!$D$22-Assumptions!$C$28))<=0,"n.m.",((G$36*Model!$K$9-DebtSchedule!$H$74)/($C43*Assumptions!$C$13+$C43*Assumptions!$C$13*Assumptions!$C$15+Assumptions!$C$28*Assumptions!$C$16+'Sources-Uses'!$D$22-Assumptions!$C$28))^(1/5)-1),"n.m.") -> -0.14951999 | H43: =IFERROR(IF(((H$36*Model!$K$9-DebtSchedule!$H$74)/($C43*Assumptions!$C$13+$C43*Assumptions!$C$13*Assumptions!$C$15+Assumptions!$C$28*Assumptions!$C$16+'Sources-Uses'!$D$22-Assumptions!$C$28))<=0,"n.m.",((H$36*Model!$K$9-DebtSchedule!$H$74)/($C43*Assumptions!$C$13+$C43*Assumptions!$C$13*Assumptions!$C$15+Assumptions!$C$28*Assumptions!$C$16+'Sources-Uses'!$D$22-Assumptions!$C$28))^(1/5)-1),"n.m.") -> -0.089980206
B45: 2b. Sensitivity: Entry Leverage (turns) x Exit EV/EBITDA -> 5-Year IRR
B47: Net debt at exit DOES depend on entry leverage here; powered by Support-tab mini debt models.
B48: Actual deal leverage was ~11.7x EBITDA (bottom row) - far outside typical LBO underwriting norms.
B50: Leverage turns (rows) x Exit multiple (cols) | C50: =E14 -> -0.17490952 | D50: =Assumptions!$C$58+(-2) -> 12.585714 | E50: =Assumptions!$C$58+(-1) -> 13.585714 | F50: =Assumptions!$C$58+(0) -> 14.585714 | G50: =Assumptions!$C$58+(1) -> 15.585714 | H50: =Assumptions!$C$58+(2) -> 16.585714
...

Sheet Support
B2: Support - Leverage Sensitivity Mini Debt Models
B3: ($ in millions) - feeds Returns leverage x exit-multiple grid
B5: Each block: opening debt = turns x entry EBITDA; interest = opening x blended entry rate;
B6: paydown = MIN(MAX(pre-financing FCF - after-tax interest,0), opening); closing = opening - paydown.
B7: Pre-financing FCF (green-linked from Model row 27) is leverage-independent by construction.
B9: Leverage scenario: 6.0x entry Debt/EBITDA
D10: FY2007E | E10: FY2008E | F10: FY2009E | G10: FY2010E | H10: FY2011E
B11: Leverage turns (input) | D11: 6
B12: Opening debt | D12: =$D$11*Assumptions!$C$13 -> 10500 | E12: =D16 -> 10392.49 | F12: =E16 -> 10242.61 | G12: =F16 -> 10063.274 | H12: =G16 -> 9939.6649
B13: Interest expense (opening x blended entry rate) | D13: =D12*Assumptions!$C$30 -> 865.93702 | E13: =E12*Assumptions!$C$30 -> 857.07061 | F13: =F12*Assumptions!$C$30 -> 844.71003 | G13: =G12*Assumptions!$C$30 -> 829.92013 | H13: =H12*Assumptions!$C$30 -> 819.72608
B14: Pre-financing FCF (green from Model) | D14: =Model!G$27 -> 670.36955 | E14: =Model!H$27 -> 706.9753 | F14: =Model!I$27 -> 728.39782 | G14: =Model!J$27 -> 663.05695 | H14: =Model!K$27 -> 659.25673
B15: Debt paydown | D15: =MIN(MAX(D14-D13*(1-Assumptions!$C$47),0),D12) -> 107.51048 | E15: =MIN(MAX(E14-E13*(1-Assumptions!$C$47),0),E12) -> 149.8794 | F15: =MIN(MAX(F14-F13*(1-Assumptions!$C$47),0),F12) -> 179.33631 | G15: =MIN(MAX(G14-G13*(1-Assumptions!$C$47),0),G12) -> 123.60887 | H15: =MIN(MAX(H14-H13*(1-Assumptions!$C$47),0),H12) -> 126.43478
B16: Closing debt | D16: =D12-D15 -> 10392.49 | E16: =E12-E15 -> 10242.61 | F16: =F12-F15 -> 10063.274 | G16: =G12-G15 -> 9939.6649 | H16: =H12-H15 -> 9813.2302
B18: Leverage scenario: 8.0x entry Debt/EBITDA
D19: FY2007E | E19: FY2008E | F19: FY2009E | G19: FY2010E | H19: FY2011E
B20: Leverage turns (input) | D20: 8
B21: Opening debt | D21: =$D$20*Assumptions!$C$13 -> 14000 | E21: =D25 -> 14000 | F21: =E25 -> 14000 | G21: =F25 -> 14000 | H21: =G25 -> 14000
B22: Interest expense (opening x blended entry rate) | D22: =D21*Assumptions!$C$30 -> 1154.5827 | E22: =E21*Assumptions!$C$30 -> 1154.5827 | F22: =F21*Assumptions!$C$30 -> 1154.5827 | G22: =G21*Assumptions!$C$30 -> 1154.5827 | H22: =H21*Assumptions!$C$30 -> 1154.5827
B23: Pre-financing FCF (green from Model) | D23: =Model!G$27 -> 670.36955 | E23: =Model!H$27 -> 706.9753 | F23: =Model!I$27 -> 728.39782 | G23: =Model!J$27 -> 663.05695 | H23: =Model!K$27 -> 659.25673
B24: Debt paydown | D24: =MIN(MAX(D23-D22*(1-Assumptions!$C$47),0),D21) -> 0 | E24: =MIN(MAX(E23-E22*(1-Assumptions!$C$47),0),E21) -> 0 | F24: =MIN(MAX(F23-F22*(1-Assumptions!$C$47),0),F21) -> 0 | G24: =MIN(MAX(G23-G22*(1-Assumptions!$C$47),0),G21) -> 0 | H24: =MIN(MAX(H23-H22*(1-Assumptions!$C$47),0),H21) -> 0
B25: Closing debt | D25: =D21-D24 -> 14000 | E25: =E21-E24 -> 14000 | F25: =F21-F24 -> 14000 | G25: =G21-G24 -> 14000 | H25: =H21-H24 -> 14000
B27: Leverage scenario: 9.5x entry Debt/EBITDA
D28: FY2007E | E28: FY2008E | F28: FY2009E | G28: FY2010E | H28: FY2011E
B29: Leverage turns (input) | D29: 9.5
B30: Opening debt | D30: =$D$29*Assumptions!$C$13 -> 16625 | E30: =D34 -> 16625 | F30: =E34 -> 16625 | G30: =F34 -> 16625 | H30: =G34 -> 16625
B31: Interest expense (opening x blended entry rate) | D31: =D30*Assumptions!$C$30 -> 1371.0669 | E31: =E30*Assumptions!$C$30 -> 1371.0669 | F31: =F30*Assumptions!$C$30 -> 1371.0669 | G31: =G30*Assumptions!$C$30 -> 1371.0669 | H31: =H30*Assumptions!$C$30 -> 1371.0669
B32: Pre-financing FCF (green from Model) | D32: =Model!G$27 -> 670.36955 | E32: =Model!H$27 -> 706.9753 | F32: =Model!I$27 -> 728.39782 | G32: =Model!J$27 -> 663.05695 | H32: =Model!K$27 -> 659.25673
B33: Debt paydown | D33: =MIN(MAX(D32-D31*(1-Assumptions!$C$47),0),D30) -> 0 | E33: =MIN(MAX(E32-E31*(1-Assumptions!$C$47),0),E30) -> 0 | F33: =MIN(MAX(F32-F31*(1-Assumptions!$C$47),0),F30) -> 0 | G33: =MIN(MAX(G32-G31*(1-Assumptions!$C$47),0),G30) -> 0 | H33: =MIN(MAX(H32-H31*(1-Assumptions!$C$47),0),H30) -> 0
B34: Closing debt | D34: =D30-D33 -> 16625 | E34: =E30-E33 -> 16625 | F34: =F30-F33 -> 16625 | G34: =G30-G33 -> 16625 | H34: =H30-H33 -> 16625
B36: Leverage scenario: 11.0x entry Debt/EBITDA
D37: FY2007E | E37: FY2008E | F37: FY2009E | G37: FY2010E | H37: FY2011E
B38: Leverage turns (input) | D38: 11
B39: Opening debt | D39: =$D$38*Assumptions!$C$13 -> 19250 | E39: =D43 -> 19250 | F39: =E43 -> 19250 | G39: =F43 -> 19250 | H39: =G43 -> 19250
B40: Interest expense (opening x blended entry rate) | D40: =D39*Assumptions!$C$30 -> 1587.5512 | E40: =E39*Assumptions!$C$30 -> 1587.5512 | F40: =F39*Assumptions!$C$30 -> 1587.5512 | G40: =G39*Assumptions!$C$30 -> 1587.5512 | H40: =H39*Assumptions!$C$30 -> 1587.5512
B41: Pre-financing FCF (green from Model) | D41: =Model!G$27 -> 670.36955 | E41: =Model!H$27 -> 706.9753 | F41: =Model!I$27 -> 728.39782 | G41: =Model!J$27 -> 663.05695 | H41: =Model!K$27 -> 659.25673
B42: Debt paydown | D42: =MIN(MAX(D41-D40*(1-Assumptions!$C$47),0),D39) -> 0 | E42: =MIN(MAX(E41-E40*(1-Assumptions!$C$47),0),E39) -> 0 | F42: =MIN(MAX(F41-F40*(1-Assumptions!$C$47),0),F39) -> 0 | G42: =MIN(MAX(G41-G40*(1-Assumptions!$C$47),0),G39) -> 0 | H42: =MIN(MAX(H41-H40*(1-Assumptions!$C$47),0),H39) -> 0
B43: Closing debt | D43: =D39-D42 -> 19250 | E43: =E39-E42 -> 19250 | F43: =F39-F42 -> 19250 | G43: =G39-G42 -> 19250 | H43: =H39-H42 -> 19250
B45: Leverage scenario: 11.7x entry Debt/EBITDA (actual deal)
D46: FY2007E | E46: FY2008E | F46: FY2009E | G46: FY2010E | H46: FY2011E
B47: Leverage turns (input) | D47: 11.7
...
