Workbook

Sheet Cover
B2: Twitter, Inc. (X Corp.) - Leveraged Buyout Model
B3: ($ in millions, except per-share data, unless noted)
B4: Deal: Elon Musk / X Holdings acquisition of Twitter, Inc. - announced April 25, 2022; closed October 27, 2022
B5: Prepared by: Akul Veauli
B6: Date: August 23, 2026
B8: Model description: Two-scenario LBO of Twitter's $44B take-private by Elon Musk. Scenario 1 models the deal-vintage plan (management case at signing: stable ad revenue, margin recovery via cost discipline). Scenario 2 models the actual post-close path (advertiser exodus, ~50% revenue decline in 2023, ~80% headcount reduction, partial 2024-25 recovery, and the March 2025 all-stock merger into xAI as the exit marker). The entry multiple on FY2021 Adjusted EBITDA of $682mm is ~67x EV/EBITDA (~64.6x on an equity-value- only basis per press reports) - a pathological multiple that is the central pedagogical point of this model, alongside sub-1.0x early interest coverage.
B11: Color-code legend
B12: 123.4 (hardcoded input) | C12: Blue font / yellow fill = hardcoded assumption
B13: "=B12*2" (same-sheet formula) | C13: Black font = formula referencing same tab
B14: "='Assumptions'!B12" (cross-tab link) | C14: Green font = formula linking from another tab
B17: Table of contents
B18: Cover
B19: Assumptions
B20: Sources-Uses
B21: Model
B22: DebtSchedule
B23: Returns
B24: Support
B26: Key outputs
B27: Entry EV / FY2021 Adj. EBITDA (actual $682mm base) | D27: ='Assumptions'!D23
B28: Entry EV / FY2021 Revenue | D28: ='Assumptions'!D24
B29: Total new debt financing | D29: ='Sources-Uses'!D10
B30: Sources & Uses check (must = 0.000) | D30: ='Sources-Uses'!D16
B31: BASE CASE (active scen., full waterfall) - Year-5 IRR | D31: ='Returns'!E16
B32: BASE CASE (active scen., full waterfall) - Year-5 MOIC | D32: ='Returns'!E15
B33: Scenario 1 (Plan) - Year-5 IRR / MOIC | D33: ='Returns'!E31
B34: Scenario 2 (Actual) - Year-5 IRR / MOIC | D34: ='Returns'!E42
B36: Sources: Twitter FY2019-FY2021 10-Ks (SEC EDGAR); Twitter Q2 2022 10-Q; Twitter DEFM14A (filed 9/2/2022); April 2022 debt commitment letter exhibits; press reports (CNBC, Reuters, Yahoo Finance, Forbes) for post-close actuals and the March 2025 xAI/X merger. See DealNotes section below and Assumptions tab notes for line-by-line citations.
B39: DealNotes - Actual Outcome (2022-2025)
B40: Oct 27, 2022: Deal closed at $54.20/share, ~$44.0B equity value, funded with ~$35.1B equity (Musk ~$27.7B, co-investors ~$7.1B incl. Oracle/Ellison, Sequoia, Binance, Qatar Holding, Fidelity; plus $1.89B Kingdom Holding share rollover) and a new $13.0B debt package ($6.5B TLB, $3.0B secured bridge, $3.0B unsecured bridge, $0.5B RCF).
B41: Nov 2022-Q1 2023: ~50% of staff cut in the first week, reaching ~80% total headcount reduction (~7,500 -> ~1,500) by mid-2023; major advertisers (Disney, Apple, VW/Audi/Ford et al.) paused spend, driving a severe revenue decline.
B42: FY2023 revenue fell to an estimated ~$2.5B (-51% vs. FY2021's $5.08B) as the advertiser exodus outpaced subscription and cost-cutting gains; FY2024 roughly flat to modestly down (~$2.5B); FY2025 shows the first recovery, to ~$2.9B.
B43: Interest burden on the $13B package (~$1.15-1.5B/yr at blended ~9-10% all-in) exceeded operating EBITDA in the early years -- interest coverage fell below 1.0x, the central credit story of this deal.
B44: Fidelity, a minority co-investor, marked its stake down as much as ~-79% (Sept 2024 trough) before a partial recovery to roughly -70% to -75% by late 2024/early 2025 on renewed AI-driven optimism around Musk's ventures.
B45: Jan-Feb 2025: banks that had held the unsyndicated bridge facilities finally sold ~$8.7B of term debt near par at a 9.5% fixed yield -- a striking turnaround from the deep distress of 2023-24.
B46: March 28, 2025: X (Twitter) was acquired by Musk's xAI in an all-stock transaction valuing X at ~$33B equity / ~$45B enterprise value (implying ~$12B of net debt), combined with xAI's ~$80B valuation into a >$110B entity. This model uses the $45B EV / $33B equity marks as the actual-path exit reference point.
B47: Net result vs. the $44.0B entry equity value: the March 2025 mark of ~$33B equity implies roughly a 0.75-0.95x MOIC on total invested equity depending on exact allocation -- a value-destructive outcome on paper, though Musk retains control of the combined AI-and-social entity and argues the strategic option value is understated by the cash marks alone.

Sheet Assumptions
B2: Assumptions
B3: ($ in millions, except per-share data and rates)
B5: 1. Transaction Assumptions
B6: Announcement date | D6: April 25, 2022
B7: Close date | D7: October 27, 2022
B8: Offer price per share ($) | D8: 54.2
B9: Fully diluted shares outstanding (mm) | D9: 809 | F9: Implied from $44.0B / $54.20 per DEFM14A framing
B10: Equity purchase price | D10: =D8*D9
B12: Existing Twitter debt at close (converts + senior notes) | D12: 4250 | F12: FY2021 10-K: $3,559mm converts + $694mm senior notes, rounded
B13: Existing Twitter cash at close | D13: 2186 | F13: FY2021 10-K balance sheet, 12/31/2021
B14: Net debt assumed / refinanced | D14: =D12-D13
B15: Transaction Enterprise Value | D15: =D10+D14
B17: Transaction fees (% of equity purchase price) | D17: 0.02
B18: Financing fees (% of total debt raised) | D18: 0.025
B19: Financing fee amortization tenor (years) | D19: 7
B21: FY2021 Adjusted EBITDA (actual) | D21: 682 | F21: Earnings release; NOT the $1.2-1.4B often cited for later post-cost-cut years
B22: FY2021 Revenue (actual) | D22: 5080 | F22: FY2021 10-K
B23: Entry EV / FY2021 Adj. EBITDA | D23: =D15/D21
B24: Entry EV / FY2021 Revenue | D24: =D15/D22
B25: Note: ~67x EV/EBITDA (EV incl. net debt; press reports cite ~64.6x on an equity-value-only basis) is a pathological entry multiple, not a modeling error -- it is the central point of this deal. EV/Revenue is shown as the more meaningful entry metric.
B27: 2. Debt Financing Package ($13.0bn, fixed dollar tranches funded at close)
B28: 3-month SOFR at close | D28: 0.0305 | F28: NY Fed, late Oct 2022 (vs. ~0.28% when commitment letters signed in April 2022)
B30: Tranche | C30: Amount ($mm) | D30: Spread (bps) | E30: Base rate | F30: All-in rate | G30: Mand. amort %/yr | H30: Cash-pay?
B31: Term Loan B (senior secured, 1st lien) | C31: 6500 | D31: 0.0475 | E31: =$D$28 | F31: =D31+E31 | G31: 0.01 | H31: Cash-pay
B32: Secured bridge (1st lien, funded as term debt) | C32: 3000 | D32: 0.0495 | E32: =$D$28 | F32: =D32+E32 | G32: 0 | H32: Cash-pay | I32: S+450 plus escalation, simplified to a fixed blended blue spread ~8.0-8.5% all-in
B33: Unsecured bridge (2nd lien, fixed-rate cap) | C33: 3000 | D33: n/a | E33: n/a | F33: 0.1175 | G33: 0 | H33: Cash-pay | I33: Fixed 11.75% cap rate per commitment letter, not SOFR-linked
B34: Revolving credit facility (undrawn at close) | C34: 500 | D34: 0.0425 | E34: =$D$28 | F34: =D34+E34 | G34: 0 | H34: Cash-pay | I34: Capacity shown; draw is the model's revolver-draw plug, not funded at close
B35: Total committed debt package (incl. undrawn revolver capacity) | C35: =SUM(C31:C34)
B36: Blended weighted-average all-in rate (committed package) | C36: =SUMPRODUCT(C31:C34,F31:F34)/C35
B37: Total FUNDED debt at close (excl. undrawn revolver) | C37: =SUM(C31:C33)
B38: Blended weighted-average all-in rate (funded debt) | C38: =SUMPRODUCT(C31:C33,F31:F33)/C37
B39: Leverage, the Support mini debt models and the Returns sensitivity grids all run off FUNDED debt and the funded-debt blended rate (standard LBO convention); the $13.0bn figure quoted throughout the deal narrative is the committed package including the undrawn $500mm revolver.
B41: 3. Operating Drivers -- Scenario Toggle (CHOOSE)
B42: Scenario switch (1 = Deal-Vintage Plan, 2 = Actual Path) | D42: 2
B43: Active scenario name | D43: =CHOOSE(D42,"Scenario 1: Deal-Vintage Plan","Scenario 2: Actual Path")
B44: Interest is computed on beginning-of-period debt balances (Master Spec Sec.5) -- no circularity, no iterative calc required.
C47: FY2021A | D47: FY2022A | E47: FY2023E | F47: FY2024E | G47: FY2025E | H47: FY2026E | I47: FY2027E | J47: FY2028E | K47: FY2029E
B48: FY2022A revenue growth % YoY (actual, transition year -- both scenarios) | D48: -0.24 | L48: Est.: partial-year advertiser exodus post Oct-2022 close; not scenario-dependent (already realized)
B49: Revenue growth % YoY -- Scenario 1 (Plan) | E49: 0.02 | F49: 0.05 | G49: 0.07 | H49: 0.08 | I49: 0.08 | J49: 0.07 | K49: 0.06
B50: Revenue growth % YoY -- Scenario 2 (Actual) | E50: -0.34 | F50: -0.02 | G50: 0.16 | H50: 0.06 | I50: 0.05 | J50: 0.05 | K50: 0.05
...

Sheet Sources-Uses
B2: Sources & Uses
B3: ($ in millions)
B5: Sources | F5: Uses
B6: Term Loan B | D6: ='Assumptions'!C31 | F6: Equity purchase price | H6: ='Assumptions'!D10
B7: Secured bridge | D7: ='Assumptions'!C32 | F7: Refinance existing net debt | H7: ='Assumptions'!D14
B8: Unsecured bridge | D8: ='Assumptions'!C33 | F8: Transaction fees | H8: ='Assumptions'!D10*'Assumptions'!D17
B9: Revolver draw at close | D9: 0 | F9: Financing fees | H9: =D10*'Assumptions'!D18
B10: Total new debt financing | D10: =SUM(D6:D9) | F10: Cash to balance sheet | H10: 0
F11: Total Uses | H11: =SUM(H6:H10)
B12: Sponsor equity (plug) | D12: =H11-D10
B13: Total Sources | D13: =D10+D12
B16: Check: Total Sources - Total Uses (must = 0.000) | D16: =ROUND(D13-H11,3)
B18: Sponsor equity % of total capitalization | D18: =D12/D13
B19: Total debt / FY2021 Adj. EBITDA at close | D19: =D10/'Assumptions'!D21
B21: Memo: Actual Reported Equity Roster (Oct 2022, per press reports)
B22: Elon Musk (cash + margin loan, later unwound) | D22: 27700
B23: Co-investors -- new money (Oracle/Ellison, Sequoia, Binance, Qatar Holding, Fidelity, other) | D23: 7100
B24: Kingdom Holding Company (Saudi PIF-linked) -- rollover of existing stake, no new cash | D24: 1890
B25: Total reported equity (memo) | D25: =SUM(D22:D24)
B26: Memo only -- reported equity roster sums to ~$36.7bn (Musk + co-investors + Kingdom rollover) vs. the model's plug above because press figures are rounded and the Kingdom rollover was a share exchange, not incremental cash funding the Uses shown here.

Sheet Model
B2: Model - Operating Projections & Free Cash Flow
B3: ($ in millions; active scenario per Assumptions!D42 switch)
B4: ="Active scenario: "&Assumptions!D43
C6: FY2021A | D6: FY2022A | E6: FY2023E | F6: FY2024E | G6: FY2025E | H6: FY2026E | I6: FY2027E | J6: FY2028E | K6: FY2029E
B7: Revenue growth % YoY | D7: =Assumptions!D48 | E7: =Assumptions!E52 | F7: =Assumptions!F52 | G7: =Assumptions!G52 | H7: =Assumptions!H52 | I7: =Assumptions!I52 | J7: =Assumptions!J52 | K7: =Assumptions!K52
B8: Revenue | C8: =Assumptions!D22 | D8: =C8*(1+D7) | E8: =D8*(1+E7) | F8: =E8*(1+F7) | G8: =F8*(1+G7) | H8: =G8*(1+H7) | I8: =H8*(1+I7) | J8: =I8*(1+J7) | K8: =J8*(1+K7)
B9: EBITDA margin % | C9: =Assumptions!D21/Assumptions!D22 | D9: =Assumptions!D54 | E9: =Assumptions!E58 | F9: =Assumptions!F58 | G9: =Assumptions!G58 | H9: =Assumptions!H58 | I9: =Assumptions!I58 | J9: =Assumptions!J58 | K9: =Assumptions!K58
B10: Adjusted EBITDA | C10: =C8*C9 | D10: =D8*D9 | E10: =E8*E9 | F10: =F8*F9 | G10: =G8*G9 | H10: =H8*H9 | I10: =I8*I9 | J10: =J8*J9 | K10: =K8*K9
B11: D&A | E11: =-E8*Assumptions!E60 | F11: =-F8*Assumptions!F60 | G11: =-G8*Assumptions!G60 | H11: =-H8*Assumptions!H60 | I11: =-I8*Assumptions!I60 | J11: =-J8*Assumptions!J60 | K11: =-K8*Assumptions!K60
B12: Financing fee amortization | E12: =-'Sources-Uses'!$H$9/Assumptions!$D$19 | F12: =-'Sources-Uses'!$H$9/Assumptions!$D$19 | G12: =-'Sources-Uses'!$H$9/Assumptions!$D$19 | H12: =-'Sources-Uses'!$H$9/Assumptions!$D$19 | I12: =-'Sources-Uses'!$H$9/Assumptions!$D$19 | J12: =-'Sources-Uses'!$H$9/Assumptions!$D$19 | K12: =-'Sources-Uses'!$H$9/Assumptions!$D$19
B13: EBIT | E13: =E10+E11+E12 | F13: =F10+F11+F12 | G13: =G10+G11+G12 | H13: =H10+H11+H12 | I13: =I10+I11+I12 | J13: =J10+J11+J12 | K13: =K10+K11+K12
B14: Less: cash interest expense (from DebtSchedule) | E14: =-DebtSchedule!E59 | F14: =-DebtSchedule!F59 | G14: =-DebtSchedule!G59 | H14: =-DebtSchedule!H59 | I14: =-DebtSchedule!I59 | J14: =-DebtSchedule!J59 | K14: =-DebtSchedule!K59
B15: Plus: interest income on beginning cash | E15: =DebtSchedule!E39*Assumptions!$D$71 | F15: =DebtSchedule!F39*Assumptions!$D$71 | G15: =DebtSchedule!G39*Assumptions!$D$71 | H15: =DebtSchedule!H39*Assumptions!$D$71 | I15: =DebtSchedule!I39*Assumptions!$D$71 | J15: =DebtSchedule!J39*Assumptions!$D$71 | K15: =DebtSchedule!K39*Assumptions!$D$71
B16: Pre-tax income (EBT) | E16: =E13+E14+E15 | F16: =F13+F14+F15 | G16: =G13+G14+G15 | H16: =H13+H14+H15 | I16: =I13+I14+I15 | J16: =J13+J14+J15 | K16: =K13+K14+K15
B17: Cash taxes (NOL-adjusted) | E17: =-MAX(E16,0)*Assumptions!E63 | F17: =-MAX(F16,0)*Assumptions!F63 | G17: =-MAX(G16,0)*Assumptions!G63 | H17: =-MAX(H16,0)*Assumptions!H63 | I17: =-MAX(I16,0)*Assumptions!I63 | J17: =-MAX(J16,0)*Assumptions!J63 | K17: =-MAX(K16,0)*Assumptions!K63
B18: Net income | E18: =E16+E17 | F18: =F16+F17 | G18: =G16+G17 | H18: =H16+H17 | I18: =I16+I17 | J18: =J16+J17 | K18: =K16+K17
B20: Free Cash Flow Build (pre-financing; feeds DebtSchedule cash sweep)
B21: Net income | E21: =E18 | F21: =F18 | G21: =G18 | H21: =H18 | I21: =I18 | J21: =J18 | K21: =K18
B22: Plus: D&A (non-cash) | E22: =-E11 | F22: =-F11 | G22: =-G11 | H22: =-H11 | I22: =-I11 | J22: =-J11 | K22: =-K11
B23: Plus: financing fee amortization (non-cash) | E23: =-E12 | F23: =-F12 | G23: =-G12 | H23: =-H12 | I23: =-I12 | J23: =-J12 | K23: =-K12
B24: Less: capital expenditures | E24: =-E8*Assumptions!E61 | F24: =-F8*Assumptions!F61 | G24: =-G8*Assumptions!G61 | H24: =-H8*Assumptions!H61 | I24: =-I8*Assumptions!I61 | J24: =-J8*Assumptions!J61 | K24: =-K8*Assumptions!K61
B25: Less: increase in net working capital | E25: =-MAX(E8-D8,0)*Assumptions!E62 | F25: =-MAX(F8-E8,0)*Assumptions!F62 | G25: =-MAX(G8-F8,0)*Assumptions!G62 | H25: =-MAX(H8-G8,0)*Assumptions!H62 | I25: =-MAX(I8-H8,0)*Assumptions!I62 | J25: =-MAX(J8-I8,0)*Assumptions!J62 | K25: =-MAX(K8-J8,0)*Assumptions!K62
B26: Cash available for debt paydown (pre-mandatory) | E26: =E21+E22+E23+E24+E25 | F26: =F21+F22+F23+F24+F25 | G26: =G21+G22+G23+G24+G25 | H26: =H21+H22+H23+H24+H25 | I26: =I21+I22+I23+I24+I25 | J26: =J21+J22+J23+J24+J25 | K26: =K21+K22+K23+K24+K25
B28: Credit Metrics
B29: Total debt / Adj. EBITDA | E29: =IFERROR(DebtSchedule!E57/E10,"n.m.") | F29: =IFERROR(DebtSchedule!F57/F10,"n.m.") | G29: =IFERROR(DebtSchedule!G57/G10,"n.m.") | H29: =IFERROR(DebtSchedule!H57/H10,"n.m.") | I29: =IFERROR(DebtSchedule!I57/I10,"n.m.") | J29: =IFERROR(DebtSchedule!J57/J10,"n.m.") | K29: =IFERROR(DebtSchedule!K57/K10,"n.m.")
B30: Net debt / Adj. EBITDA | E30: =IFERROR(DebtSchedule!E58/E10,"n.m.") | F30: =IFERROR(DebtSchedule!F58/F10,"n.m.") | G30: =IFERROR(DebtSchedule!G58/G10,"n.m.") | H30: =IFERROR(DebtSchedule!H58/H10,"n.m.") | I30: =IFERROR(DebtSchedule!I58/I10,"n.m.") | J30: =IFERROR(DebtSchedule!J58/J10,"n.m.") | K30: =IFERROR(DebtSchedule!K58/K10,"n.m.")
B31: Adj. EBITDA / cash interest expense (coverage) | E31: =IFERROR(E10/DebtSchedule!E59,"n.m.") | F31: =IFERROR(F10/DebtSchedule!F59,"n.m.") | G31: =IFERROR(G10/DebtSchedule!G59,"n.m.") | H31: =IFERROR(H10/DebtSchedule!H59,"n.m.") | I31: =IFERROR(I10/DebtSchedule!I59,"n.m.") | J31: =IFERROR(J10/DebtSchedule!J59,"n.m.") | K31: =IFERROR(K10/DebtSchedule!K59,"n.m.")
B32: (Adj. EBITDA - capex) / cash interest expense | E32: =IFERROR((E10+E24)/DebtSchedule!E59,"n.m.") | F32: =IFERROR((F10+F24)/DebtSchedule!F59,"n.m.") | G32: =IFERROR((G10+G24)/DebtSchedule!G59,"n.m.") | H32: =IFERROR((H10+H24)/DebtSchedule!H59,"n.m.") | I32: =IFERROR((I10+I24)/DebtSchedule!I59,"n.m.") | J32: =IFERROR((J10+J24)/DebtSchedule!J59,"n.m.") | K32: =IFERROR((K10+K24)/DebtSchedule!K59,"n.m.")
B33: Credit metrics populate once DebtSchedule totals are available (see formulas added after DebtSchedule build).
B35: Interest income is earned on beginning-of-period cash balances at the money-market rate on the Assumptions tab (blue input); immaterial to results given the low cash balances carried throughout.

Sheet DebtSchedule
B2: Debt Schedule - Mandatory Amortization & Cash Sweep
B3: ($ in millions; interest computed on beginning-of-period balances -- no circularity, no iterative calc)
D6: At Close | E6: FY2023E | F6: FY2024E | G6: FY2025E | H6: FY2026E | I6: FY2027E | J6: FY2028E | K6: FY2029E
B8: Cash Available for Debt Service
B9: Cash available for debt paydown (pre-mandatory) | E9: =Model!E26 | F9: =Model!F26 | G9: =Model!G26 | H9: =Model!H26 | I9: =Model!I26 | J9: =Model!J26 | K9: =Model!K26
B11: Term Loan B
B12: Opening balance | D12: ='Assumptions'!C31 | E12: =D16 | F12: =E16 | G12: =F16 | H12: =G16 | I12: =H16 | J12: =I16 | K12: =J16
B13: Interest expense (beginning balance x rate) | D13: =0 | E13: =E12*'Assumptions'!$F$31 | F13: =F12*'Assumptions'!$F$31 | G13: =G12*'Assumptions'!$F$31 | H13: =H12*'Assumptions'!$F$31 | I13: =I12*'Assumptions'!$F$31 | J13: =J12*'Assumptions'!$F$31 | K13: =K12*'Assumptions'!$F$31
B14: Mandatory amortization | D14: =0 | E14: =MIN(E12,'Assumptions'!$C$31*'Assumptions'!$G$31) | F14: =MIN(F12,'Assumptions'!$C$31*'Assumptions'!$G$31) | G14: =MIN(G12,'Assumptions'!$C$31*'Assumptions'!$G$31) | H14: =MIN(H12,'Assumptions'!$C$31*'Assumptions'!$G$31) | I14: =MIN(I12,'Assumptions'!$C$31*'Assumptions'!$G$31) | J14: =MIN(J12,'Assumptions'!$C$31*'Assumptions'!$G$31) | K14: =MIN(K12,'Assumptions'!$C$31*'Assumptions'!$G$31)
B15: Cash sweep | D15: =0 | E15: =E49 | F15: =F49 | G15: =G49 | H15: =H49 | I15: =I49 | J15: =J49 | K15: =K49
B16: Closing balance | D16: =D12 | E16: =E12-E14-E15 | F16: =F12-F14-F15 | G16: =G12-G14-G15 | H16: =H12-H14-H15 | I16: =I12-I14-I15 | J16: =J12-J14-J15 | K16: =K12-K14-K15
B18: Secured Bridge
B19: Opening balance | D19: ='Assumptions'!C32 | E19: =D23 | F19: =E23 | G19: =F23 | H19: =G23 | I19: =H23 | J19: =I23 | K19: =J23
B20: Interest expense (beginning balance x rate) | D20: =0 | E20: =E19*'Assumptions'!$F$32 | F20: =F19*'Assumptions'!$F$32 | G20: =G19*'Assumptions'!$F$32 | H20: =H19*'Assumptions'!$F$32 | I20: =I19*'Assumptions'!$F$32 | J20: =J19*'Assumptions'!$F$32 | K20: =K19*'Assumptions'!$F$32
B21: Mandatory amortization | D21: =0 | E21: =MIN(E19,'Assumptions'!$C$32*'Assumptions'!$G$32) | F21: =MIN(F19,'Assumptions'!$C$32*'Assumptions'!$G$32) | G21: =MIN(G19,'Assumptions'!$C$32*'Assumptions'!$G$32) | H21: =MIN(H19,'Assumptions'!$C$32*'Assumptions'!$G$32) | I21: =MIN(I19,'Assumptions'!$C$32*'Assumptions'!$G$32) | J21: =MIN(J19,'Assumptions'!$C$32*'Assumptions'!$G$32) | K21: =MIN(K19,'Assumptions'!$C$32*'Assumptions'!$G$32)
B22: Cash sweep | D22: =0 | E22: =E51 | F22: =F51 | G22: =G51 | H22: =H51 | I22: =I51 | J22: =J51 | K22: =K51
B23: Closing balance | D23: =D19 | E23: =E19-E21-E22 | F23: =F19-F21-F22 | G23: =G19-G21-G22 | H23: =H19-H21-H22 | I23: =I19-I21-I22 | J23: =J19-J21-J22 | K23: =K19-K21-K22
B25: Unsecured Bridge
B26: Opening balance | D26: ='Assumptions'!C33 | E26: =D30 | F26: =E30 | G26: =F30 | H26: =G30 | I26: =H30 | J26: =I30 | K26: =J30
B27: Interest expense (beginning balance x fixed rate) | D27: =0 | E27: =E26*'Assumptions'!$F$33 | F27: =F26*'Assumptions'!$F$33 | G27: =G26*'Assumptions'!$F$33 | H27: =H26*'Assumptions'!$F$33 | I27: =I26*'Assumptions'!$F$33 | J27: =J26*'Assumptions'!$F$33 | K27: =K26*'Assumptions'!$F$33
B28: Mandatory amortization | D28: =0 | E28: =MIN(E26,'Assumptions'!$C$33*'Assumptions'!$G$33) | F28: =MIN(F26,'Assumptions'!$C$33*'Assumptions'!$G$33) | G28: =MIN(G26,'Assumptions'!$C$33*'Assumptions'!$G$33) | H28: =MIN(H26,'Assumptions'!$C$33*'Assumptions'!$G$33) | I28: =MIN(I26,'Assumptions'!$C$33*'Assumptions'!$G$33) | J28: =MIN(J26,'Assumptions'!$C$33*'Assumptions'!$G$33) | K28: =MIN(K26,'Assumptions'!$C$33*'Assumptions'!$G$33)
B29: Cash sweep | D29: =0 | E29: =E53 | F29: =F53 | G29: =G53 | H29: =H53 | I29: =I53 | J29: =J53 | K29: =K53
B30: Closing balance | D30: =D26 | E30: =E26-E28-E29 | F30: =F26-F28-F29 | G30: =G26-G28-G29 | H30: =H26-H28-H29 | I30: =I26-I28-I29 | J30: =J26-J28-J29 | K30: =K26-K28-K29
B32: Revolving Credit Facility (undrawn at close; plug)
B33: Opening balance | D33: =0 | E33: =D36 | F33: =E36 | G33: =F36 | H33: =G36 | I33: =H36 | J33: =I36 | K33: =J36
B34: Interest expense (beginning balance x rate) | D34: =0 | E34: =E33*'Assumptions'!$F$34 | F34: =F33*'Assumptions'!$F$34 | G34: =G33*'Assumptions'!$F$34 | H34: =H33*'Assumptions'!$F$34 | I34: =I33*'Assumptions'!$F$34 | J34: =J33*'Assumptions'!$F$34 | K34: =K33*'Assumptions'!$F$34
B35: Draw / (repayment) | D35: =0 | E35: =E46-E47 | F35: =F46-F47 | G35: =G46-G47 | H35: =H46-H47 | I35: =I46-I47 | J35: =J46-J47 | K35: =K46-K47
B36: Closing balance | D36: =D33 | E36: =E33+E35 | F36: =F33+F35 | G36: =G33+G35 | H36: =H33+H35 | I36: =I33+I35 | J36: =J33+J35 | K36: =K33+K35
B38: Cash Sweep Waterfall & Cash Balance Roll-Forward
B39: Opening cash balance | D39: =0 | E39: =D55 | F39: =E55 | G39: =F55 | H39: =G55 | I39: =H55 | J39: =I55 | K39: =J55
B40: Plus: cash available for debt paydown | D40: =0 | E40: =Model!E26 | F40: =Model!F26 | G40: =Model!G26 | H40: =Model!H26 | I40: =Model!I26 | J40: =Model!J26 | K40: =Model!K26
B41: Less: total mandatory amortization | D41: =0 | E41: =E14+E21+E28 | F41: =F14+F21+F28 | G41: =G14+G21+G28 | H41: =H14+H21+H28 | I41: =I14+I21+I28 | J41: =J14+J21+J28 | K41: =K14+K21+K28
B42: Cash before discretionary sweep / draw | D42: ='Sources-Uses'!H10 | E42: =E39+E40-E41 | F42: =F39+F40-F41 | G42: =G39+G40-G41 | H42: =H39+H40-H41 | I42: =I39+I40-I41 | J42: =J39+J40-J41 | K42: =K39+K40-K41
B43: Minimum cash balance | D43: ='Assumptions'!D69 | E43: ='Assumptions'!$D$69 | F43: ='Assumptions'!$D$69 | G43: ='Assumptions'!$D$69 | H43: ='Assumptions'!$D$69 | I43: ='Assumptions'!$D$69 | J43: ='Assumptions'!$D$69 | K43: ='Assumptions'!$D$69
B44: Cash sweep % | D44: ='Assumptions'!$D$70 | E44: ='Assumptions'!$D$70 | F44: ='Assumptions'!$D$70 | G44: ='Assumptions'!$D$70 | H44: ='Assumptions'!$D$70 | I44: ='Assumptions'!$D$70 | J44: ='Assumptions'!$D$70 | K44: ='Assumptions'!$D$70
B45: Cash available for sweep | D45: =0 | E45: =MAX(0,E42-E43)*E44 | F45: =MAX(0,F42-F43)*F44 | G45: =MAX(0,G42-G43)*G44 | H45: =MAX(0,H42-H43)*H44 | I45: =MAX(0,I42-I43)*I44 | J45: =MAX(0,J42-J43)*J44 | K45: =MAX(0,K42-K43)*K44
B46: Shortfall requiring revolver draw | D46: =0 | E46: =MAX(0,E43-E42) | F46: =MAX(0,F43-F42) | G46: =MAX(0,G43-G42) | H46: =MAX(0,H43-H42) | I46: =MAX(0,I43-I42) | J46: =MAX(0,J43-J42) | K46: =MAX(0,K43-K42)
B47: Applied: RCF repayment | D47: =0 | E47: =MIN(E45,E33) | F47: =MIN(F45,F33) | G47: =MIN(G45,G33) | H47: =MIN(H45,H33) | I47: =MIN(I45,I33) | J47: =MIN(J45,J33) | K47: =MIN(K45,K33)
B48: Remaining sweep pool | D48: =0 | E48: =E45-E47 | F48: =F45-F47 | G48: =G45-G47 | H48: =H45-H47 | I48: =I45-I47 | J48: =J45-J47 | K48: =K45-K47
B49: Applied: TLB sweep | D49: =0 | E49: =MIN(E48,E12-E14) | F49: =MIN(F48,F12-F14) | G49: =MIN(G48,G12-G14) | H49: =MIN(H48,H12-H14) | I49: =MIN(I48,I12-I14) | J49: =MIN(J48,J12-J14) | K49: =MIN(K48,K12-K14)
...

Sheet Returns
B2: Returns - Exit Analysis, Sensitivities & Actual-Outcome Comparison
B3: ($ in millions, except per-turn and per-share figures)
B5: Basis note: the BASE CASE table immediately below is driven by the full 4-tranche DebtSchedule waterfall (mandatory amortisation + cash sweep + revolver draws) for the scenario selected by the Assumptions toggle -- these are the headline returns. The two scenario tables that follow use the Support-tab single blended-rate mini debt model (master spec Sec.4.2 architecture) so that BOTH scenarios can be shown side-by-side off one toggle setting; that simplification pauses paydown rather than drawing the revolver when FCF falls short of interest, so its net debt at exit runs LOWER (returns slightly more favourable) than the full waterfall in the early, cash-short years. The reconciliation rows beneath the base-case table quantify that gap. The sensitivity grids further below are Support-driven by design (master spec Sec.4.2 requires a leverage-independent FCF row for grid re-derivation).
B7: BASE CASE (Active Scenario) - Exit Analysis on Full DebtSchedule Waterfall
B8: Exit year | D8: Year 3 | E8: Year 5 | F8: Year 7
B9: Exit EBITDA | D9: =Model!G10 | E9: =Model!I10 | F9: =Model!K10
B10: Exit EV / EBITDA multiple | D10: ='Assumptions'!$D$68 | E10: ='Assumptions'!$D$68 | F10: ='Assumptions'!$D$68
B11: Exit enterprise value | D11: =D9*D10 | E11: =E9*E10 | F11: =F9*F10
B12: Less: net debt at exit | D12: =DebtSchedule!G58 | E12: =DebtSchedule!I58 | F12: =DebtSchedule!K58
B13: Equity value at exit | D13: =D11-D12 | E13: =E11-E12 | F13: =F11-F12
B14: Sponsor equity invested (entry) | D14: ='Sources-Uses'!$D$12 | E14: ='Sources-Uses'!$D$12 | F14: ='Sources-Uses'!$D$12
B15: MOIC | D15: =IFERROR(D13/D14,"n.m.") | E15: =IFERROR(E13/E14,"n.m.") | F15: =IFERROR(F13/F14,"n.m.")
B16: IRR (closed-form, single flow) | D16: =IFERROR((D15)^(1/3)-1,"n.m.") | E16: =IFERROR((E15)^(1/5)-1,"n.m.") | F16: =IFERROR((F15)^(1/7)-1,"n.m.")
B18: Memo: active scenario | D18: ='Assumptions'!D43
B19: Reconciliation: net debt at exit, full waterfall less Support mini-model (Scenario 2 basis) | D19: =DebtSchedule!G58-Support!G32 | E19: =DebtSchedule!I58-Support!I32 | F19: =DebtSchedule!K58-Support!K32
B20: A positive reconciliation figure is the amount by which the simplified Support mini-model understates net debt at exit (and therefore overstates equity value and MOIC) relative to the full 4-tranche waterfall. It is driven entirely by revolver draws that the mini-model does not make.
B22: Scenario 1: Deal-Vintage Plan - Exit Analysis
B23: Exit year | D23: Year 3 | E23: Year 5 | F23: Year 7
B24: Exit EBITDA | D24: =Support!G12 | E24: =Support!I12 | F24: =Support!K12
B25: Exit EV / EBITDA multiple | D25: ='Assumptions'!$D$66 | E25: ='Assumptions'!$D$66 | F25: ='Assumptions'!$D$66
B26: Exit enterprise value | D26: =D24*D25 | E26: =E24*E25 | F26: =F24*F25
B27: Less: net debt at exit | D27: =Support!G19 | E27: =Support!I19 | F27: =Support!K19
B28: Equity value at exit | D28: =D26-D27 | E28: =E26-E27 | F28: =F26-F27
B29: Sponsor equity invested (entry) | D29: ='Sources-Uses'!$D$12 | E29: ='Sources-Uses'!$D$12 | F29: ='Sources-Uses'!$D$12
B30: MOIC | D30: =IFERROR(D28/D29,"n.m.") | E30: =IFERROR(E28/E29,"n.m.") | F30: =IFERROR(F28/F29,"n.m.")
B31: IRR (closed-form, single flow) | D31: =IFERROR((D30)^(1/3)-1,"n.m.") | E31: =IFERROR((E30)^(1/5)-1,"n.m.") | F31: =IFERROR((F30)^(1/7)-1,"n.m.")
B33: Scenario 2: Actual Path - Exit Analysis
B34: Exit year | D34: Year 3 | E34: Year 5 | F34: Year 7
B35: Exit EBITDA | D35: =Support!G25 | E35: =Support!I25 | F35: =Support!K25
B36: Exit EV / EBITDA multiple | D36: ='Assumptions'!$D$67 | E36: ='Assumptions'!$D$67 | F36: ='Assumptions'!$D$67
B37: Exit enterprise value | D37: =D35*D36 | E37: =E35*E36 | F37: =F35*F36
B38: Less: net debt at exit | D38: =Support!G32 | E38: =Support!I32 | F38: =Support!K32
B39: Equity value at exit | D39: =D37-D38 | E39: =E37-E38 | F39: =F37-F38
B40: Sponsor equity invested (entry) | D40: ='Sources-Uses'!$D$12 | E40: ='Sources-Uses'!$D$12 | F40: ='Sources-Uses'!$D$12
B41: MOIC | D41: =IFERROR(D39/D40,"n.m.") | E41: =IFERROR(E39/E40,"n.m.") | F41: =IFERROR(F39/F40,"n.m.")
B42: IRR (closed-form, single flow) | D42: =IFERROR((D41)^(1/3)-1,"n.m.") | E42: =IFERROR((E41)^(1/5)-1,"n.m.") | F42: =IFERROR((F41)^(1/7)-1,"n.m.")
B44: Cross-check: Scenario 2, Year 5 IRR via IRR() over dated flow vector
B45: Year 0 (outflow) | D45: =-'Sources-Uses'!$D$12 | E45: 0 | F45: 0 | G45: 0 | H45: 0 | I45: =Support!I25*'Assumptions'!$D$67-Support!I32
B46: IRR() cross-check | D46: =IRR(D45:I45) | F46: vs. closed-form: | G46: =E42
B48: Sensitivity Grid A & B: Entry Multiple x Exit Multiple -> Year-5 MOIC / IRR (Scenario 2)
...

Sheet Support
B2: Support - Scenario & Leverage-Sensitivity Mini Debt Models
B3: ($ in millions; simplified single blended-rate debt models per Master Spec Sec.4.2)
E6: FY2023E | F6: FY2024E | G6: FY2025E | H6: FY2026E | I6: FY2027E | J6: FY2028E | K6: FY2029E
B8: Scenario Mini-Model: Scenario 1 -- Deal-Vintage Plan
B9: Revenue growth % YoY | E9: =Assumptions!E49 | F9: =Assumptions!F49 | G9: =Assumptions!G49 | H9: =Assumptions!H49 | I9: =Assumptions!I49 | J9: =Assumptions!J49 | K9: =Assumptions!K49
B10: Revenue | E10: =Model!D8*(1+E9) | F10: =E10*(1+F9) | G10: =F10*(1+G9) | H10: =G10*(1+H9) | I10: =H10*(1+I9) | J10: =I10*(1+J9) | K10: =J10*(1+K9)
B11: EBITDA margin % | E11: =Assumptions!E55 | F11: =Assumptions!F55 | G11: =Assumptions!G55 | H11: =Assumptions!H55 | I11: =Assumptions!I55 | J11: =Assumptions!J55 | K11: =Assumptions!K55
B12: EBITDA | E12: =E10*E11 | F12: =F10*F11 | G12: =G10*G11 | H12: =H10*H11 | I12: =I10*I11 | J12: =J10*J11 | K12: =K10*K11
B13: Less: capex | E13: =-E10*Assumptions!E61 | F13: =-F10*Assumptions!F61 | G13: =-G10*Assumptions!G61 | H13: =-H10*Assumptions!H61 | I13: =-I10*Assumptions!I61 | J13: =-J10*Assumptions!J61 | K13: =-K10*Assumptions!K61
B14: Less: cash taxes (NOL-adjusted, pre-interest approx.) | E14: =-MAX(E12+E13,0)*Assumptions!E63 | F14: =-MAX(F12+F13,0)*Assumptions!F63 | G14: =-MAX(G12+G13,0)*Assumptions!G63 | H14: =-MAX(H12+H13,0)*Assumptions!H63 | I14: =-MAX(I12+I13,0)*Assumptions!I63 | J14: =-MAX(J12+J13,0)*Assumptions!J63 | K14: =-MAX(K12+K13,0)*Assumptions!K63
B15: Pre-financing free cash flow | E15: =E12+E13+E14 | F15: =F12+F13+F14 | G15: =G12+G13+G14 | H15: =H12+H13+H14 | I15: =I12+I13+I14 | J15: =J12+J13+J14 | K15: =K12+K13+K14
B16: Total debt -- opening | E16: ='Assumptions'!$C$37 | F16: =E19 | G16: =F19 | H16: =G19 | I16: =H19 | J16: =I19 | K16: =J19
B17: Interest @ blended rate | E17: =E16*'Assumptions'!$C$38 | F17: =F16*'Assumptions'!$C$38 | G17: =G16*'Assumptions'!$C$38 | H17: =H16*'Assumptions'!$C$38 | I17: =I16*'Assumptions'!$C$38 | J17: =J16*'Assumptions'!$C$38 | K17: =K16*'Assumptions'!$C$38
B18: Paydown (sweep, capped at opening) | E18: =MIN(MAX(E15-E17,0),E16) | F18: =MIN(MAX(F15-F17,0),F16) | G18: =MIN(MAX(G15-G17,0),G16) | H18: =MIN(MAX(H15-H17,0),H16) | I18: =MIN(MAX(I15-I17,0),I16) | J18: =MIN(MAX(J15-J17,0),J16) | K18: =MIN(MAX(K15-K17,0),K16)
B19: Total debt -- closing | E19: =E16-E18 | F19: =F16-F18 | G19: =G16-G18 | H19: =H16-H18 | I19: =I16-I18 | J19: =J16-J18 | K19: =K16-K18
B21: Scenario Mini-Model: Scenario 2 -- Actual Path
B22: Revenue growth % YoY | E22: =Assumptions!E50 | F22: =Assumptions!F50 | G22: =Assumptions!G50 | H22: =Assumptions!H50 | I22: =Assumptions!I50 | J22: =Assumptions!J50 | K22: =Assumptions!K50
B23: Revenue | E23: =Model!D8*(1+E22) | F23: =E23*(1+F22) | G23: =F23*(1+G22) | H23: =G23*(1+H22) | I23: =H23*(1+I22) | J23: =I23*(1+J22) | K23: =J23*(1+K22)
B24: EBITDA margin % | E24: =Assumptions!E56 | F24: =Assumptions!F56 | G24: =Assumptions!G56 | H24: =Assumptions!H56 | I24: =Assumptions!I56 | J24: =Assumptions!J56 | K24: =Assumptions!K56
B25: EBITDA | E25: =E23*E24 | F25: =F23*F24 | G25: =G23*G24 | H25: =H23*H24 | I25: =I23*I24 | J25: =J23*J24 | K25: =K23*K24
B26: Less: capex | E26: =-E23*Assumptions!E61 | F26: =-F23*Assumptions!F61 | G26: =-G23*Assumptions!G61 | H26: =-H23*Assumptions!H61 | I26: =-I23*Assumptions!I61 | J26: =-J23*Assumptions!J61 | K26: =-K23*Assumptions!K61
B27: Less: cash taxes (NOL-adjusted, pre-interest approx.) | E27: =-MAX(E25+E26,0)*Assumptions!E63 | F27: =-MAX(F25+F26,0)*Assumptions!F63 | G27: =-MAX(G25+G26,0)*Assumptions!G63 | H27: =-MAX(H25+H26,0)*Assumptions!H63 | I27: =-MAX(I25+I26,0)*Assumptions!I63 | J27: =-MAX(J25+J26,0)*Assumptions!J63 | K27: =-MAX(K25+K26,0)*Assumptions!K63
B28: Pre-financing free cash flow | E28: =E25+E26+E27 | F28: =F25+F26+F27 | G28: =G25+G26+G27 | H28: =H25+H26+H27 | I28: =I25+I26+I27 | J28: =J25+J26+J27 | K28: =K25+K26+K27
B29: Total debt -- opening | E29: ='Assumptions'!$C$37 | F29: =E32 | G29: =F32 | H29: =G32 | I29: =H32 | J29: =I32 | K29: =J32
B30: Interest @ blended rate | E30: =E29*'Assumptions'!$C$38 | F30: =F29*'Assumptions'!$C$38 | G30: =G29*'Assumptions'!$C$38 | H30: =H29*'Assumptions'!$C$38 | I30: =I29*'Assumptions'!$C$38 | J30: =J29*'Assumptions'!$C$38 | K30: =K29*'Assumptions'!$C$38
B31: Paydown (sweep, capped at opening) | E31: =MIN(MAX(E28-E30,0),E29) | F31: =MIN(MAX(F28-F30,0),F29) | G31: =MIN(MAX(G28-G30,0),G29) | H31: =MIN(MAX(H28-H30,0),H29) | I31: =MIN(MAX(I28-I30,0),I29) | J31: =MIN(MAX(J28-J30,0),J29) | K31: =MIN(MAX(K28-K30,0),K29)
B32: Total debt -- closing | E32: =E29-E31 | F32: =F29-F31 | G32: =G29-G31 | H32: =H29-H31 | I32: =I29-I31 | J32: =J29-J31 | K32: =K29-K31
B34: Scenario mini-models use a single blended-rate, whole-debt-balance simplification (master spec Sec.4.2 leverage-sensitivity pattern) rather than the full 4-tranche waterfall on DebtSchedule -- this lets Returns show both scenarios' outcomes at Years 3/5/7 side-by-side without duplicating the detailed schedule. The detailed DebtSchedule tab (4 tranches, mandatory amort + cash sweep + revolver) always reflects the ACTIVE scenario selected by the Assumptions!D42 toggle.
B37: Leverage Sensitivity Mini Debt Models (Actual-Path FCF, 5 leverage scenarios)
B38: Each block: opening debt = leverage turns x FY2021 Adj. EBITDA; interest = opening x blended rate; FCF is leverage-independent (Scenario 2 pre-financing FCF above); paydown = MIN(FCF-interest,opening).
B39: Leverage = 4.0x FY2021 EBITDA
B40: Debt -- opening | E40: =4.0*'Assumptions'!$D$21 | F40: =E43 | G40: =F43 | H40: =G43 | I40: =H43 | J40: =I43 | K40: =J43
B41: Interest @ blended rate | E41: =E40*'Assumptions'!$C$38 | F41: =F40*'Assumptions'!$C$38 | G41: =G40*'Assumptions'!$C$38 | H41: =H40*'Assumptions'!$C$38 | I41: =I40*'Assumptions'!$C$38 | J41: =J40*'Assumptions'!$C$38 | K41: =K40*'Assumptions'!$C$38
B42: Paydown | E42: =MIN(MAX(E28-E41,0),E40) | F42: =MIN(MAX(F28-F41,0),F40) | G42: =MIN(MAX(G28-G41,0),G40) | H42: =MIN(MAX(H28-H41,0),H40) | I42: =MIN(MAX(I28-I41,0),I40) | J42: =MIN(MAX(J28-J41,0),J40) | K42: =MIN(MAX(K28-K41,0),K40)
B43: Debt -- closing | E43: =E40-E42 | F43: =F40-F42 | G43: =G40-G42 | H43: =H40-H42 | I43: =I40-I42 | J43: =J40-J42 | K43: =K40-K42
B45: Leverage = 6.0x FY2021 EBITDA
B46: Debt -- opening | E46: =6.0*'Assumptions'!$D$21 | F46: =E49 | G46: =F49 | H46: =G49 | I46: =H49 | J46: =I49 | K46: =J49
B47: Interest @ blended rate | E47: =E46*'Assumptions'!$C$38 | F47: =F46*'Assumptions'!$C$38 | G47: =G46*'Assumptions'!$C$38 | H47: =H46*'Assumptions'!$C$38 | I47: =I46*'Assumptions'!$C$38 | J47: =J46*'Assumptions'!$C$38 | K47: =K46*'Assumptions'!$C$38
B48: Paydown | E48: =MIN(MAX(E28-E47,0),E46) | F48: =MIN(MAX(F28-F47,0),F46) | G48: =MIN(MAX(G28-G47,0),G46) | H48: =MIN(MAX(H28-H47,0),H46) | I48: =MIN(MAX(I28-I47,0),I46) | J48: =MIN(MAX(J28-J47,0),J46) | K48: =MIN(MAX(K28-K47,0),K46)
B49: Debt -- closing | E49: =E46-E48 | F49: =F46-F48 | G49: =G46-G48 | H49: =H46-H48 | I49: =I46-I48 | J49: =J46-J48 | K49: =K46-K48
...
