Workbook

Sheet Cover
B2: Broadcom Inc. / VMware, Inc. - Merger Model (Cash-or-Stock Election)
B3: ($ in millions, except per-share data, unless noted)
B4: Deal: Broadcom (AVGO) acquisition of VMware (VMW) - announced May 26, 2022; closed November 22, 2023
B5: Prepared by: Akul Veauli
B6: Date: August 23, 2026
B8: Model description: Cash-or-stock election merger model for Broadcom's acquisition of VMware. VMware shareholders elected $142.50 cash OR 0.2520 AVGO shares per share, with aggregate proration to a 50%/50% cash/stock mix (actual outcome skewed slightly stock-heavy at 52.1% stock / 47.9% cash due to election oversubscription toward stock, since AVGO shares appreciated well above the fixed cash price between signing and close). The Assumptions tab models the election/proration mechanics explicitly as a live block. Financing uses $28.4B of new term loans (SOFR + 112.5-162.5bps across tranches) to fund the cash consideration; VMware's ~$8.25B of senior notes are assumed (not refinanced). Purchase price allocation is anchored to AVGO's actual FY2024 10-K disclosure (~$79.6B net consideration, ~$35-36B identifiable intangibles, ~$43-45B goodwill). Synergies are phased toward management's stated target of ~$8.5B VMware EBITDA within 3 years (from a ~$4.7B adjusted EBITDA base).
B11: Color-code legend
B12: 123.4 (hardcoded input) | C12: Blue font / yellow fill = hardcoded assumption
B13: B12*2 (same-sheet formula, e.g.) | C13: Black font = formula referencing same tab
B14: 'Assumptions'!B12 (cross-tab link, e.g.) | C14: Green font = formula linking from another tab
B17: Table of contents
B18: Cover
B19: Assumptions
B20: Acquirer
B21: Target
B22: Synergies
B23: PPA-Financing
B24: ProForma
B25: Contribution
B26: Sensitivity
B28: Key outputs
B29: Blended consideration / VMW share | D29: ='Assumptions'!D23
B30: Equity purchase price (aggregate) | D30: ='Assumptions'!D27
B31: Total new AVGO term loans | D31: ='PPA-Financing'!D8
B32: Goodwill created | D32: ='PPA-Financing'!D25
B33: FY2024E accretion / (dilution) % | D33: ='ProForma'!D29
B34: Yr-1 breakeven pre-tax synergies | D34: ='ProForma'!D32
B36: Sources: AVGO FY2021-FY2023 10-Ks (Oct/Nov FYE, SEC EDGAR); VMware FY2022-FY2024 10-Ks (Jan/Feb FYE); AVGO/VMware merger agreement and press release (May 26, 2022); AVGO $28.4B term loan commitment press release (Aug 17, 2023); close announcement / proration results (Nov 22, 2023); AVGO FY2024 10-K (filed Dec 2024) Note 3 business combination for actual purchase price allocation. AVGO share prices at announcement (~$530-535) and close (~$980-985) are flagged estimates pending exact closing-date quotes; intangible useful lives are estimated within 10-K disclosed ranges (software 5-15yr, customer relationships 10-20yr) pending the fully itemized Note 3 schedule.
B39: DealNotes - Actual Outcome (2022-2024)
B40: May 26, 2022: Deal announced at ~$61B headline equity value; AVGO stock ~$530-535. VMW shareholders offered $142.50 cash OR 0.2520 AVGO shares per share, aggregate proration to 50% cash / 50% stock.
B41: 18-month regulatory review (EU, UK, and especially China's SAMR) delayed closing well past the original 12-month target, injecting material deal-completion risk into VMW's stock, which traded at a persistent spread to terms.
B42: Nov 22, 2023: Deal closed. AVGO stock had risen to ~$980-985, making the stock election worth ~$247/share vs. the fixed $142.50 cash option -- a ~73% spread. Stock election was oversubscribed; final proration was 52.1% stock / 47.9% cash (vs. the theoretical 50/50 midpoint), reflecting the cap on aggregate stock consideration.
B43: Total purchase consideration at close: $86,290mm gross ($53,398mm AVGO stock + $30,788mm cash + ~$2,104mm assumed equity awards), less $6,642mm VMware cash acquired = $79,648mm net consideration per AVGO's FY2024 10-K.
B44: AVGO funded the cash portion with $28.4B of new term loans (Term A-2 $10.7B @ SOFR+112.5bps, Term A-3 $10.7B @ SOFR+125.0bps, Term A-5 $7.0B @ SOFR+162.5bps), materially increasing leverage; VMware's ~$8.25B senior notes were assumed rather than refinanced.
B45: Actual PPA (FY2024 10-K, Note 3): goodwill of approximately $43-45B and identifiable intangible assets of approximately $35-36B (developed technology, customer relationships, trade names), driving a large incremental annual intangible amortization charge that pressures GAAP (though not non-GAAP) earnings for years.
B46: Post-close, Broadcom moved aggressively on VMware's commercial model: shifting perpetual-license customers to subscription, raising prices, and cutting costs/headcount. VMware revenue re-accelerated and the Software segment reported gross margins above 70%, with synergy realization tracking ahead of the 3-year $8.5B EBITDA target.
B47: Shareholders who elected stock captured a large windfall as AVGO shares roughly tripled from announcement through 2024, illustrating the asymmetric payoff of the stock election in a rising-acquirer-price deal -- the opposite risk profile from a falling-acquirer-price stock-election deal.

Sheet Assumptions
B2: Assumptions - Deal Terms, Election/Proration, Financing, PPA
B3: ($ in millions, except per-share and rate data)
B5: 1. Deal Terms & Target Shares
B6: VMW fully-diluted shares outstanding at close (mm) | D6: 430 | F6: Per VMW 10-K cover / close 8-K (approx.)
B7: Cash election value per VMW share ($) | D7: 142.5 | F7: Fixed per merger agreement, May 26, 2022
B8: Stock election exchange ratio (AVGO sh. / VMW sh.) | D8: 0.252 | F8: Fixed per merger agreement
B9: AVGO share price at announcement (5/25/2022 close) [FLAGGED EST.] | D9: 532 | F9: Estimated range $530-535; exact close not confirmed in source data
B10: AVGO share price at close (11/22/2023) [FLAGGED EST.] | D10: 981 | F10: Estimated range $980-985; drives model's blended value/share
B11: Headline deal value at announcement ($mm) [memo] | D11: 61000 | F11: Announced framing, ~$61B
B13: 2. Election / Proration Mechanics (explicit, live)
B14: % of VMW shares electing cash (pre-proration, blue input) | D14: 0.65 | F14: Illustrative election skew before proration caps it to 50/50 aggregate
B15: % of VMW shares electing stock (pre-proration, formula) | D15: =1-D14
B16: Aggregate proration target: % cash of total consideration | D16: 0.5 | F16: Merger agreement: 50%/50% aggregate proration
B17: Aggregate proration target: % stock of total consideration | D17: =1-D16
B18: Actual outcome: % stock of aggregate consideration (memo) | D18: 0.521 | F18: Per close 8-K: 52.1% stock / 47.9% cash (stock oversubscribed)
B19: Actual outcome: % cash of aggregate consideration (memo, formula) | D19: =1-D18
B20: VMW shares receiving cash consideration (mm) - modeled 50/50 | D20: =D6*D16
B21: VMW shares receiving stock consideration (mm) - modeled 50/50 | D21: =D6*D17
C22: Check: prorated shares tie to total FD shares (0.000) | D22: =ROUND(D20+D21-D6,3)
B23: Blended consideration value per VMW share ($, formula) | D23: =D16*D7+D17*D8*D10 | F23: Formula: 50%xCash + 50%xStockRatioxAVGO price at close
B24: Total cash consideration needed ($mm, formula) | D24: =D20*D7
B25: Total new AVGO shares issued (mm, formula) | D25: =D21*D8
B26: Total stock consideration fair value ($mm, formula) | D26: =D25*D10
B27: Equity purchase price (aggregate, $mm, formula) | D27: =D24+D26 | F27: Ties to actual $86,290mm gross consideration region (incl. assumed awards, not modeled here)
C28: Check: equity purchase price = shares x blended value (0.000) | D28: =ROUND(D27-D6*D23,3)
B30: 3. Financing
B31: Cash from AVGO balance sheet used to fund deal ($mm) | D31: 2400 | F31: Balance of cash consideration beyond new term loans
B32: New term loans raised ($mm, formula = cash consid. - BS cash) | D32: =D24-D31 | F32: Ties to $28.4B actual term loan commitment (Aug 2023 press release)
B33: Reference SOFR at close (blue, mid-2023 level) [FLAGGED EST.] | D33: 0.0533 | F33: ~5.33% mid-2023; exact SOFR fixing on close date not confirmed
B34: Weighted-avg spread across Term A-2/A-3/A-5 tranches (bps, blue) | D34: 0.0135 | F34: Wtd avg of 112.5/125.0/162.5bps across $10.7B/$10.7B/$7.0B tranches ~135bps
B35: All-in blended new-debt rate (formula = SOFR + spread) | D35: =D33+D34
B36: Foregone interest rate on cash used from balance sheet | D36: 0.045 | F36: Money-market / short-term investment yield, 2023
B37: VMW debt assumed at close ($mm, not refinanced) | D37: 8250 | F37: VMW senior notes assumed, toggle = assume (not refi)
B38: Blended coupon on assumed VMW notes | D38: 0.038 | F38: VMW senior notes blended coupon, per 10-K debt footnote
B39: Financing + advisory fees ($mm) | D39: 500 | F39: Estimated arrangement/advisory fees, expensed at close
B41: 4. Purchase Price Allocation Inputs
B42: VMW book equity acquired ($mm, blue, at close balance sheet) | D42: 4200 | F42: Estimated VMW stockholders' equity at close per 10-K trend
B43: VMW existing goodwill written off ($mm, blue) | D43: 4600 | F43: VMW pre-deal goodwill (Dell spin-off era), written off at close
B44: Identifiable intangible assets recognized ($mm, blue - anchored to actual PPA) | D44: 35500 | F44: AVGO FY2024 10-K Note 3 actual: ~$35-36B (developed tech, customer relationships, trade names)
B45: Blended intangible useful life (years, blue) [FLAGGED EST.] | D45: 11 | F45: Blend of disclosed ranges: software 5-15yr, customer relationships 10-20yr
...

Sheet Acquirer
B2: Acquirer - Broadcom Inc. (AVGO) Standalone
B3: ($ in millions, except per-share data; AVGO fiscal year ends late October)
B5: Broadcom Standalone Financials
B6: Fiscal Year | D6: FY2021A | E6: FY2022A | F6: FY2023A | G6: FY2024E | H6: FY2025E | I6: FY2026E | J6: FY2027E | K6: FY2028E
B7: Revenue | D7: 27500 | E7: 33200 | F7: 35820 | G7: =F7*(1+G8) | H7: =G7*(1+H8) | I7: =H7*(1+I8) | J7: =I7*(1+J8) | K7: =J7*(1+K8)
B8: Revenue growth % (projection, blue) | G8: 0.09 | H8: 0.085 | I8: 0.08 | J8: 0.075 | K8: 0.07
B9: Adj. EBITDA margin % (blue for hist memo / proj drivers) | D9: 0.594 | E9: 0.62939759 | F9: 0.63009492 | G9: 0.635 | H9: 0.635 | I9: 0.635 | J9: 0.635 | K9: 0.635
B10: Adj. EBITDA | D10: =D7*D9 | E10: =E7*E9 | F10: =F7*F9 | G10: =G7*G9 | H10: =H7*H9 | I10: =I7*I9 | J10: =J7*J9 | K10: =K7*K9
B11: D&A incl. existing intangible amortization | D11: 1450 | E11: 1650 | F11: 2000 | G11: 2100 | H11: 2150 | I11: 2200 | J11: 2250 | K11: 2300
B12: EBIT (EBITDA - D&A) | D12: =D10-D11 | E12: =E10-E11 | F12: =F10-F11 | G12: =G10-G11 | H12: =H10-H11 | I12: =I10-I11 | J12: =J10-J11 | K12: =K10-K11
B13: Interest expense, standalone debt (blue rate x const. debt) | D13: 700 | E13: 1350 | F13: 1500 | G13: 250 | H13: 250 | I13: 250 | J13: 250 | K13: 250 | L13: Standalone pre-deal debt service; deal debt modeled on ProForma tab
B14: EBT | D14: =D12-D13 | E14: =E12-E13 | F14: =F12-F13 | G14: =G12-G13 | H14: =H12-H13 | I14: =I12-I13 | J14: =J12-J13 | K14: =K12-K13
B15: Tax rate (blue) | D15: 0.13 | E15: 0.13 | F15: 0.13 | G15: 0.14 | H15: 0.14 | I15: 0.14 | J15: 0.14 | K15: 0.14 | L15: AVGO effective rate historically low due to tax credits/foreign mix
B16: Taxes | D16: =D14*D15 | E16: =E14*E15 | F16: =F14*F15 | G16: =G14*G15 | H16: =H14*H15 | I16: =I14*I15 | J16: =J14*J15 | K16: =K14*K15
B17: Net income | D17: =D14-D16 | E17: =E14-E16 | F17: =F14-F16 | G17: =G14-G16 | H17: =H14-H16 | I17: =I14-I16 | J17: =J14-J16 | K17: =K14-K16
B18: Diluted shares outstanding (mm, blue) | D18: 463 | E18: 445 | F18: 424 | G18: 470 | H18: 470 | I18: 470 | J18: 470 | K18: 470 | L18: Standalone shares only; deal shares added on ProForma tab
B19: Standalone diluted EPS | D19: =D17/D18 | E19: =E17/E18 | F19: =F17/F18 | G19: =G17/G18 | H19: =H17/H18 | I19: =I17/I18 | J19: =J17/J18 | K19: =K17/K18
B21: Balance sheet memo at FY2023 close (pre-VMware)
B22: Cash & equivalents ($mm, blue) | D22: 14189
B23: Total debt ($mm, blue, pre-deal) | D23: 40357 | F23: AVGO pre-deal debt load (includes existing IG bonds); grows with $28.4B new term loans post-close

Sheet Target
B2: Target - VMware, Inc. (VMW) Standalone
B3: ($ in millions, except per-share data; VMW fiscal year ends ~Feb, pre-close)
B5: VMware Standalone Financials
B6: Fiscal Year | D6: FY2022A | E6: FY2023A | F6: FY2024A(pre-close) | G6: FY2024E | H6: FY2025E | I6: FY2026E | J6: FY2027E | K6: FY2028E
B7: Revenue | D7: 12851 | E7: 13350 | F7: 13700 | G7: =F7*(1+G8) | H7: =G7*(1+H8) | I7: =H7*(1+I8) | J7: =I7*(1+J8) | K7: =J7*(1+K8)
B8: Revenue growth % (projection, blue - price hikes + subscription shift) | G8: 0.06 | H8: 0.07 | I8: 0.08 | J8: 0.09 | K8: 0.1
B9: Non-GAAP operating margin % (blue, hist memo / proj driver) | D9: 0.30581278 | E9: 0.28014981 | F9: 0.3 | G9: 0.34 | H9: 0.35 | I9: 0.36 | J9: 0.37 | K9: 0.38 | L9: Margin expansion driven by AVGO's post-close pricing/cost actions toward $8.5B EBITDA target
B10: EBITDA (proxy = non-GAAP operating income + D&A add-back simplified to op income here) | D10: =D7*D9 | E10: =E7*E9 | F10: =F7*F9 | G10: =G7*G9 | H10: =H7*H9 | I10: =I7*I9 | J10: =J7*J9 | K10: =K7*K9
B11: D&A | D11: 650 | E11: 700 | F11: 720 | G11: 750 | H11: 750 | I11: 750 | J11: 750 | K11: 750
B12: EBIT (EBITDA - D&A) | D12: =D10-D11 | E12: =E10-E11 | F12: =F10-F11 | G12: =G10-G11 | H12: =H10-H11 | I12: =I10-I11 | J12: =J10-J11 | K12: =K10-K11
B13: Interest expense (standalone senior notes, blue rate x const. debt) | D13: 350 | E13: 350 | F13: 350 | G13: ='Assumptions'!D37*'Assumptions'!D38 | H13: ='Assumptions'!D37*'Assumptions'!D38 | I13: ='Assumptions'!D37*'Assumptions'!D38 | J13: ='Assumptions'!D37*'Assumptions'!D38 | K13: ='Assumptions'!D37*'Assumptions'!D38
B14: EBT | D14: =D12-D13 | E14: =E12-E13 | F14: =F12-F13 | G14: =G12-G13 | H14: =H12-H13 | I14: =I12-I13 | J14: =J12-J13 | K14: =K12-K13
B15: Tax rate (blue) | D15: 0.21 | E15: 0.21 | F15: 0.21 | G15: 0.21 | H15: 0.21 | I15: 0.21 | J15: 0.21 | K15: 0.21
B16: Taxes | D16: =D14*D15 | E16: =E14*E15 | F16: =F14*F15 | G16: =G14*G15 | H16: =H14*H15 | I16: =I14*I15 | J16: =J14*J15 | K16: =K14*K15
B17: Net income | D17: =D14-D16 | E17: =E14-E16 | F17: =F14-F16 | G17: =G14-G16 | H17: =H14-H16 | I17: =I14-I16 | J17: =J14-J16 | K17: =K14-K16
B18: Diluted shares outstanding (mm, blue) | D18: 437 | E18: 430 | F18: 430 | G18: 430 | H18: 430 | I18: 430 | J18: 430 | K18: 430
B19: Standalone diluted EPS | D19: =D17/D18 | E19: =E17/E18 | F19: =F17/F18 | G19: =G17/G18 | H19: =H17/H18 | I19: =I17/I18 | J19: =J17/J18 | K19: =K17/K18
B21: Balance sheet memo at close
B22: Cash & equivalents ($mm, blue - cash acquired by AVGO) | D22: 6642
B23: Gross debt / senior notes ($mm, blue) | D23: 8250
B24: Note: VMW fiscal calendar (~Feb FYE) shown without restatement to AVGO's Oct FYE; projection years FY2024E-FY2028E are treated as combined post-close periods aligned to AVGO's fiscal calendar.

Sheet Synergies
B2: Synergies - Path to $8.5B VMware EBITDA Target
B3: ($ in millions)
B5: Synergy Build
B6: Fiscal Year | D6: FY2024E | E6: FY2025E | F6: FY2026E | G6: FY2027E | H6: FY2028E
B7: Run-rate cost synergy target ($mm, blue) | D7: 3500 | E7: =$D$7 | F7: =$D$7 | G7: =$D$7 | H7: =$D$7 | I7: Consistent with VMW EBITDA moving from ~$4.7B base toward ~$8.5B target within 3 years
B8: Phase-in % of run-rate (blue: 40/70/100/100/100%) | D8: 0.4 | E8: 0.7 | F8: 1 | G8: 1 | H8: 1
B9: Cost synergies realized, pre-tax ($mm, formula) | D9: =D7*D8 | E9: =E7*E8 | F9: =F7*F8 | G9: =G7*G8 | H9: =H7*H8
B10: Revenue synergy uplift % of VMW revenue (blue, price increases) | D10: 0.01 | E10: 0.02 | F10: 0.03 | G10: 0.03 | H10: 0.03
B11: Revenue synergies ($mm, formula, green-linked to Target revenue) | D11: =D10*Target!G7 | E11: =E10*Target!H7 | F11: =F10*Target!I7 | G11: =G10*Target!J7 | H11: =H10*Target!K7
B12: Incremental margin on revenue synergies (blue) | D12: 0.7 | E12: 0.7 | F12: 0.7 | G12: 0.7 | H12: 0.7
B13: Revenue synergy EBITDA contribution ($mm, formula) | D13: =D11*D12 | E13: =E11*E12 | F13: =F11*F12 | G13: =G11*G12 | H13: =H11*H12
B14: One-time integration costs ($mm, blue, yr1-2 only, expensed) | D14: 600 | E14: 300 | F14: 0 | G14: 0 | H14: 0
B15: Total pre-tax synergy benefit, net of integration costs ($mm) | D15: =D9+D13-D14 | E15: =E9+E13-E14 | F15: =F9+F13-F14 | G15: =G9+G13-G14 | H15: =H9+H13-H14
B16: Total after-tax synergy benefit ($mm, formula) | D16: =D15*(1-'Assumptions'!D48) | E16: =E15*(1-'Assumptions'!D48) | F16: =F15*(1-'Assumptions'!D48) | G16: =G15*(1-'Assumptions'!D48) | H16: =H15*(1-'Assumptions'!D48)
B18: Memo: VMware EBITDA Path to $8.5B Target
B19: VMW adj. EBITDA base, pre-deal (blue, ~FY2022 memo) | D19: 4700
B20: 3-year target VMW EBITDA (blue, management guidance) | D20: 8500
B21: Implied VMW EBITDA (base + phased synergies), FY2024E-FY2028E | D21: =Target!G10+D9+D13 | E21: =Target!H10+E9+E13 | F21: =Target!I10+F9+F13 | G21: =Target!J10+G9+G13 | H21: =Target!K10+H9+H13 | I21: Yr3 (FY2026E) column should approach the $8.5B target

Sheet PPA-Financing
B2: PPA & Financing - Sources & Uses, Goodwill Build, Financing Effects
B3: ($ in millions)
B5: Sources & Uses
B6: Sources
B7: Cash from AVGO balance sheet | D7: ='Assumptions'!D31
B8: New term loans ($28.4B target) | D8: ='Assumptions'!D32
B9: AVGO stock issued to VMW sellers | D9: ='Assumptions'!D26
B10: Incremental new-debt draw to fund financing + advisory fees | D10: ='Assumptions'!D39
B11: Total sources | D11: =SUM(D7:D10)
B13: Uses
B14: Equity purchase price (cash + stock consideration) | D14: ='Assumptions'!D27
B15: Financing + advisory fees | D15: ='Assumptions'!D39
B16: Total uses | D16: =D14+D15
B17: Check: Sources - Uses (must = 0.000) | D17: =ROUND((D11)-(D14+D15),3)
B19: Goodwill Build (Waterfall)
B20: Equity purchase price | D20: ='Assumptions'!D27
B21: Less: VMW book equity acquired | D21: =-'Assumptions'!D42
B22: Plus: VMW existing goodwill written off (add back to step-up base) | D22: ='Assumptions'!D43
B23: Less: identifiable intangible step-up recognized | D23: =-'Assumptions'!D44
B24: Plus: deferred tax liability created on step-up | D24: ='Assumptions'!D50
B25: New goodwill created | D25: =SUM(D20:D24) | F25: Modeled ~$56.1B vs. AVGO FY2024 10-K actual ~$43-45B -- see simplification note below
B27: GOODWILL SIMPLIFICATION (read with the waterfall above): this model's residual goodwill computes to approximately $56.1B, versus the approximately $43-45B actually recorded in AVGO's FY2024 10-K Note 3. The gap is a deliberate simplification of the waterfall, not a calculation error, and comes from three sources. (1) The model's uses base is the GROSS equity purchase price (approximately $83.8B of cash + stock consideration), whereas the actual PPA allocates approximately $79.6B of consideration NET of the approximately $6.6B of VMware cash acquired. (2) This waterfall recognizes only two acquired-balance-sheet items -- book equity and the write-off of pre-deal goodwill -- and does not step up or separately identify the approximately $8.5B of other tangible net assets acquired (PP&E, receivables, inventory, other), so their fair value falls into the residual instead of being carved out of it. (3) The full deferred tax liability of intangibles x 21% (approximately $7.5B) is added to goodwill, whereas the actual PPA nets the acquired deferred tax positions, NOLs and credits against it. Adjusting for those three items brings the residual back into the disclosed approximately $43-45B region. Goodwill is not amortized, so this difference does NOT affect the pro forma EPS or accretion/(dilution) results anywhere in this model -- those are driven by the identifiable intangible balance (blue input, calibrated to the actual approximately $35-36B) and its amortization life.
B29: Financing Effects per Year
B30: Fiscal Year | D30: FY2024E | E30: FY2025E | F30: FY2026E | G30: FY2027E | H30: FY2028E
B31: New term loan interest expense ($mm) | D31: ='Assumptions'!D32*'Assumptions'!D35 | E31: ='Assumptions'!D32*'Assumptions'!D35 | F31: ='Assumptions'!D32*'Assumptions'!D35 | G31: ='Assumptions'!D32*'Assumptions'!D35 | H31: ='Assumptions'!D32*'Assumptions'!D35
B32: Foregone interest income on BS cash used ($mm) | D32: ='Assumptions'!D31*'Assumptions'!D36 | E32: ='Assumptions'!D31*'Assumptions'!D36 | F32: ='Assumptions'!D31*'Assumptions'!D36 | G32: ='Assumptions'!D31*'Assumptions'!D36 | H32: ='Assumptions'!D31*'Assumptions'!D36
B33: Financing fee amortization ($mm, straight-line over 5yr tenor) | D33: ='Assumptions'!D39/5 | E33: ='Assumptions'!D39/5 | F33: ='Assumptions'!D39/5 | G33: ='Assumptions'!D39/5 | H33: ='Assumptions'!D39/5
B34: Interest on assumed VMW debt ($mm) | D34: ='Assumptions'!D37*'Assumptions'!D38 | E34: ='Assumptions'!D37*'Assumptions'!D38 | F34: ='Assumptions'!D37*'Assumptions'!D38 | G34: ='Assumptions'!D37*'Assumptions'!D38 | H34: ='Assumptions'!D37*'Assumptions'!D38
B35: Incremental intangible amortization ($mm) | D35: ='Assumptions'!D46 | E35: ='Assumptions'!D46 | F35: ='Assumptions'!D46 | G35: ='Assumptions'!D46 | H35: ='Assumptions'!D46

Sheet ProForma
B2: Pro Forma Combined - Accretion/(Dilution) Analysis
B3: ($ in millions, except per-share data)
B5: Fiscal Year | D5: FY2024E | E5: FY2025E | F5: FY2026E | G5: FY2027E | H5: FY2028E
B6: Revenue & EBITDA
B7: Combined revenue (Acquirer + Target + revenue synergies) | D7: =Acquirer!G7+Target!G7+Synergies!D11 | E7: =Acquirer!H7+Target!H7+Synergies!E11 | F7: =Acquirer!I7+Target!I7+Synergies!F11 | G7: =Acquirer!J7+Target!J7+Synergies!G11 | H7: =Acquirer!K7+Target!K7+Synergies!H11
B8: Combined EBITDA (Acq + Tgt EBITDA + cost & rev synergies - integration costs) | D8: =Acquirer!G10+Target!G10+Synergies!D15 | E8: =Acquirer!H10+Target!H10+Synergies!E15 | F8: =Acquirer!I10+Target!I10+Synergies!F15 | G8: =Acquirer!J10+Target!J10+Synergies!G15 | H8: =Acquirer!K10+Target!K10+Synergies!H15
B9: Combined D&A (Acq + Tgt, excl. new intangible amort) | D9: =Acquirer!G11+Target!G11 | E9: =Acquirer!H11+Target!H11 | F9: =Acquirer!I11+Target!I11 | G9: =Acquirer!J11+Target!J11 | H9: =Acquirer!K11+Target!K11
B10: New incremental intangible amortization (from PPA) | D10: ='PPA-Financing'!D35 | E10: ='PPA-Financing'!E35 | F10: ='PPA-Financing'!F35 | G10: ='PPA-Financing'!G35 | H10: ='PPA-Financing'!H35
B11: Pro forma EBIT | D11: =D8-D9-D10 | E11: =E8-E9-E10 | F11: =F8-F9-F10 | G11: =G8-G9-G10 | H11: =H8-H9-H10
B13: Interest & Taxes
B14: Acquirer standalone interest expense | D14: =Acquirer!G13 | E14: =Acquirer!H13 | F14: =Acquirer!I13 | G14: =Acquirer!J13 | H14: =Acquirer!K13
B15: Interest on assumed VMW debt | D15: ='PPA-Financing'!D34 | E15: ='PPA-Financing'!E34 | F15: ='PPA-Financing'!F34 | G15: ='PPA-Financing'!G34 | H15: ='PPA-Financing'!H34
B16: New term loan interest expense | D16: ='PPA-Financing'!D31 | E16: ='PPA-Financing'!E31 | F16: ='PPA-Financing'!F31 | G16: ='PPA-Financing'!G31 | H16: ='PPA-Financing'!H31
B17: Foregone interest income on BS cash used | D17: ='PPA-Financing'!D32 | E17: ='PPA-Financing'!E32 | F17: ='PPA-Financing'!F32 | G17: ='PPA-Financing'!G32 | H17: ='PPA-Financing'!H32
B18: Financing fee amortization | D18: ='PPA-Financing'!D33 | E18: ='PPA-Financing'!E33 | F18: ='PPA-Financing'!F33 | G18: ='PPA-Financing'!G33 | H18: ='PPA-Financing'!H33
B19: Total interest & financing expense | D19: =D14+D15+D16+D17+D18 | E19: =E14+E15+E16+E17+E18 | F19: =F14+F15+F16+F17+F18 | G19: =G14+G15+G16+G17+G18 | H19: =H14+H15+H16+H17+H18
B20: Pro forma EBT | D20: =D11-D19 | E20: =E11-E19 | F20: =F11-F19 | G20: =G11-G19 | H20: =H11-H19
B21: Taxes at blended rate | D21: =D20*'Assumptions'!D48 | E21: =E20*'Assumptions'!D48 | F21: =F20*'Assumptions'!D48 | G21: =G20*'Assumptions'!D48 | H21: =H20*'Assumptions'!D48
B22: Pro forma net income | D22: =D20-D21 | E22: =E20-E21 | F22: =F20-F21 | G22: =G20-G21 | H22: =H20-H21
B24: Shares & EPS / Accretion-Dilution
B25: Pro forma diluted shares (Acquirer standalone + new shares issued) | D25: =Acquirer!G18+'Assumptions'!D25 | E25: =Acquirer!H18+'Assumptions'!D25 | F25: =Acquirer!I18+'Assumptions'!D25 | G25: =Acquirer!J18+'Assumptions'!D25 | H25: =Acquirer!K18+'Assumptions'!D25
B26: Pro forma diluted EPS | D26: =D22/D25 | E26: =E22/E25 | F26: =F22/F25 | G26: =G22/G25 | H26: =H22/H25
B27: Acquirer standalone diluted EPS (memo) | D27: =Acquirer!G19 | E27: =Acquirer!H19 | F27: =Acquirer!I19 | G27: =Acquirer!J19 | H27: =Acquirer!K19
B28: Accretion / (dilution), $ per share | D28: =D26-D27 | E28: =E26-E27 | F28: =F26-F27 | G28: =G26-G27 | H28: =H26-H27
B29: Accretion / (dilution), % | D29: =D26/D27-1 | E29: =E26/E27-1 | F29: =F26/F27-1 | G29: =G26/G27-1 | H29: =H26/H27-1
B31: Breakeven Synergies (Year 1, FY2024E)
B32: Breakeven run-rate cost synergies, pre-tax (Yr-1) ($mm) | D32: =(D27*D25-(D22-Synergies!D9*(1-'Assumptions'!D48)))/((1-'Assumptions'!D48)*Synergies!D8)
B33: Cross-check: plug breakeven into accretion formula -> should be ~0.000 | D33: =ROUND((((D22-Synergies!D9*(1-'Assumptions'!D48))+D32*(1-'Assumptions'!D48)*Synergies!D8)/D25)/D27-1,3)
B35: Memo: Pro Forma Leverage
B36: Opening net debt (Acq BS debt + new term loans + assumed VMW debt - Acq BS cash) | D36: =Acquirer!D23+'Assumptions'!D32+'Assumptions'!D37-Acquirer!D22 | E36: =D36-0.5*E22 | F36: =E36-0.5*F22 | G36: =F36-0.5*G22 | H36: =G36-0.5*H22 | I36: Simple sweep: 50% of pro forma NI used for debt paydown (blue % embedded)
B37: Pro forma net debt / EBITDA | D37: =D36/D8 | E37: =E36/E8 | F37: =F36/F8 | G37: =G36/G8 | H37: =H36/H8

Sheet Contribution
B2: Contribution Analysis - FY2024E (Yr-1)
B3: ($ in millions)
D5: Acquirer (AVGO) | E5: Target (VMW) | F5: Combined | G5: Acquirer % | H5: Target %
B6: Revenue | D6: =Acquirer!G7 | E6: =Target!G7 | F6: =D6+E6 | G6: =D6/F6 | H6: =E6/F6
B7: EBITDA | D7: =Acquirer!G10 | E7: =Target!G10 | F7: =D7+E7 | G7: =D7/F7 | H7: =E7/F7
B8: EBIT | D8: =Acquirer!G12 | E8: =Target!G12 | F8: =D8+E8 | G8: =D8/F8 | H8: =E8/F8
B9: Net income | D9: =Acquirer!G17 | E9: =Target!G17 | F9: =D9+E9 | G9: =D9/F9 | H9: =E9/F9
B11: Contribution vs. Pro Forma Ownership
B12: Acquirer (AVGO) legacy holders' % of pro forma shares | D12: =Acquirer!G18/ProForma!D25
B13: Target (VMW) former holders' % of pro forma shares (stock electors only) | D13: ='Assumptions'!D25/ProForma!D25 | F13: Only stock-elected VMW shares convert to AVGO shares; cash electors hold no pro forma equity
B14: Delta: AVGO ownership % vs. AVGO NI contribution % (net income basis) | D14: =D12-G9 | F14: Positive = acquirer holders own more of pro forma co. than their earnings contribution

Sheet Sensitivity
B2: Sensitivity - Election Mix & Synergies; Premium & Synergies
B3: Output = FY2024E (Yr-1) accretion/(dilution) %; all cells live formulas
B5: Helper Assumptions (drive both grids)
B6: Base VMW FD shares (mm) | D6: ='Assumptions'!D6
B7: Base cash election value ($) | D7: ='Assumptions'!D7
B8: Base stock exchange ratio | D8: ='Assumptions'!D8
B9: AVGO price at close | D9: ='Assumptions'!D10
B10: Acquirer standalone NI, FY2024E ($mm) | D10: =Acquirer!G17
B11: Target standalone NI, FY2024E ($mm) | D11: =Target!G17
B12: Acquirer standalone shares, FY2024E (mm) | D12: =Acquirer!G18
B13: Acquirer standalone EPS, FY2024E ($) | D13: =D10/D12
B14: Yr-1 phase-in % of run-rate synergies | D14: =Synergies!D8
B15: Tax rate | D15: ='Assumptions'!D48
B16: New-debt all-in rate | D16: ='Assumptions'!D35
B17: Foregone cash yield rate | D17: ='Assumptions'!D36
B18: BS cash used to fund deal ($mm) | D18: ='Assumptions'!D31
B19: Other fixed financing costs (assumed debt int. + fee amort + intang amort), $mm | D19: ='PPA-Financing'!D34+'PPA-Financing'!D33+'PPA-Financing'!D35
B20: Combined EBITDA-level synergy pretax base run-rate ($mm) | D20: =Synergies!D7
B21: EBIT other combined (Acq+Tgt EBIT excl. new debt effects), $mm | D21: =Acquirer!G12+Target!G12-Acquirer!G13 | I21: EBIT of both standalones less acquirer's own standalone interest (kept constant across grids)
B22: Fixed synergy component (revenue synergy EBITDA - integration costs), $mm | D22: =Synergies!D13-Synergies!D14 | I22: Held fixed while the grid shocks only the run-rate cost synergy target, so grid total pre-tax synergy = shocked_runratexphase + this fixed component, exactly reproducing Synergies!total_pretax at base case
B23: Algebraic model (both grids): ProFormaNI(mix,syn) = [EBITother + syn_pretax] - IntAssumed - NewDebt(cashneeded)xrate - ForegoneCashYield - OtherFixedFin, all x(1-tax); Shares(mix) = AcqShares + StockShares(mix)/AcqPrice-based-conversion. Cell = ProFormaNI/Shares / AcqEPS - 1.
B25: GRID 1: % Cash Election (rows, aggregate proration) x Run-rate Synergies (cols)
C26: =ProForma!D29 | D26: 1500 | E26: 2500 | F26: 3500 | G26: 4500 | H26: 5500
B27: 0.3 | D27: =((($D$21+D$26*$D$14+$D$22)-$D$19-(($D$6*$B27*$D$7-$D$18)*$D$16)-($D$18*$D$17))*(1-$D$15))/($D$12+($D$6*(1-$B27)*$D$8))/$D$13-1 | E27: =((($D$21+E$26*$D$14+$D$22)-$D$19-(($D$6*$B27*$D$7-$D$18)*$D$16)-($D$18*$D$17))*(1-$D$15))/($D$12+($D$6*(1-$B27)*$D$8))/$D$13-1 | F27: =((($D$21+F$26*$D$14+$D$22)-$D$19-(($D$6*$B27*$D$7-$D$18)*$D$16)-($D$18*$D$17))*(1-$D$15))/($D$12+($D$6*(1-$B27)*$D$8))/$D$13-1 | G27: =((($D$21+G$26*$D$14+$D$22)-$D$19-(($D$6*$B27*$D$7-$D$18)*$D$16)-($D$18*$D$17))*(1-$D$15))/($D$12+($D$6*(1-$B27)*$D$8))/$D$13-1 | H27: =((($D$21+H$26*$D$14+$D$22)-$D$19-(($D$6*$B27*$D$7-$D$18)*$D$16)-($D$18*$D$17))*(1-$D$15))/($D$12+($D$6*(1-$B27)*$D$8))/$D$13-1
B28: 0.4 | D28: =((($D$21+D$26*$D$14+$D$22)-$D$19-(($D$6*$B28*$D$7-$D$18)*$D$16)-($D$18*$D$17))*(1-$D$15))/($D$12+($D$6*(1-$B28)*$D$8))/$D$13-1 | E28: =((($D$21+E$26*$D$14+$D$22)-$D$19-(($D$6*$B28*$D$7-$D$18)*$D$16)-($D$18*$D$17))*(1-$D$15))/($D$12+($D$6*(1-$B28)*$D$8))/$D$13-1 | F28: =((($D$21+F$26*$D$14+$D$22)-$D$19-(($D$6*$B28*$D$7-$D$18)*$D$16)-($D$18*$D$17))*(1-$D$15))/($D$12+($D$6*(1-$B28)*$D$8))/$D$13-1 | G28: =((($D$21+G$26*$D$14+$D$22)-$D$19-(($D$6*$B28*$D$7-$D$18)*$D$16)-($D$18*$D$17))*(1-$D$15))/($D$12+($D$6*(1-$B28)*$D$8))/$D$13-1 | H28: =((($D$21+H$26*$D$14+$D$22)-$D$19-(($D$6*$B28*$D$7-$D$18)*$D$16)-($D$18*$D$17))*(1-$D$15))/($D$12+($D$6*(1-$B28)*$D$8))/$D$13-1
B29: 0.5 | D29: =((($D$21+D$26*$D$14+$D$22)-$D$19-(($D$6*$B29*$D$7-$D$18)*$D$16)-($D$18*$D$17))*(1-$D$15))/($D$12+($D$6*(1-$B29)*$D$8))/$D$13-1 | E29: =((($D$21+E$26*$D$14+$D$22)-$D$19-(($D$6*$B29*$D$7-$D$18)*$D$16)-($D$18*$D$17))*(1-$D$15))/($D$12+($D$6*(1-$B29)*$D$8))/$D$13-1 | F29: =((($D$21+F$26*$D$14+$D$22)-$D$19-(($D$6*$B29*$D$7-$D$18)*$D$16)-($D$18*$D$17))*(1-$D$15))/($D$12+($D$6*(1-$B29)*$D$8))/$D$13-1 | G29: =((($D$21+G$26*$D$14+$D$22)-$D$19-(($D$6*$B29*$D$7-$D$18)*$D$16)-($D$18*$D$17))*(1-$D$15))/($D$12+($D$6*(1-$B29)*$D$8))/$D$13-1 | H29: =((($D$21+H$26*$D$14+$D$22)-$D$19-(($D$6*$B29*$D$7-$D$18)*$D$16)-($D$18*$D$17))*(1-$D$15))/($D$12+($D$6*(1-$B29)*$D$8))/$D$13-1
B30: 0.6 | D30: =((($D$21+D$26*$D$14+$D$22)-$D$19-(($D$6*$B30*$D$7-$D$18)*$D$16)-($D$18*$D$17))*(1-$D$15))/($D$12+($D$6*(1-$B30)*$D$8))/$D$13-1 | E30: =((($D$21+E$26*$D$14+$D$22)-$D$19-(($D$6*$B30*$D$7-$D$18)*$D$16)-($D$18*$D$17))*(1-$D$15))/($D$12+($D$6*(1-$B30)*$D$8))/$D$13-1 | F30: =((($D$21+F$26*$D$14+$D$22)-$D$19-(($D$6*$B30*$D$7-$D$18)*$D$16)-($D$18*$D$17))*(1-$D$15))/($D$12+($D$6*(1-$B30)*$D$8))/$D$13-1 | G30: =((($D$21+G$26*$D$14+$D$22)-$D$19-(($D$6*$B30*$D$7-$D$18)*$D$16)-($D$18*$D$17))*(1-$D$15))/($D$12+($D$6*(1-$B30)*$D$8))/$D$13-1 | H30: =((($D$21+H$26*$D$14+$D$22)-$D$19-(($D$6*$B30*$D$7-$D$18)*$D$16)-($D$18*$D$17))*(1-$D$15))/($D$12+($D$6*(1-$B30)*$D$8))/$D$13-1
B31: 0.7 | D31: =((($D$21+D$26*$D$14+$D$22)-$D$19-(($D$6*$B31*$D$7-$D$18)*$D$16)-($D$18*$D$17))*(1-$D$15))/($D$12+($D$6*(1-$B31)*$D$8))/$D$13-1 | E31: =((($D$21+E$26*$D$14+$D$22)-$D$19-(($D$6*$B31*$D$7-$D$18)*$D$16)-($D$18*$D$17))*(1-$D$15))/($D$12+($D$6*(1-$B31)*$D$8))/$D$13-1 | F31: =((($D$21+F$26*$D$14+$D$22)-$D$19-(($D$6*$B31*$D$7-$D$18)*$D$16)-($D$18*$D$17))*(1-$D$15))/($D$12+($D$6*(1-$B31)*$D$8))/$D$13-1 | G31: =((($D$21+G$26*$D$14+$D$22)-$D$19-(($D$6*$B31*$D$7-$D$18)*$D$16)-($D$18*$D$17))*(1-$D$15))/($D$12+($D$6*(1-$B31)*$D$8))/$D$13-1 | H31: =((($D$21+H$26*$D$14+$D$22)-$D$19-(($D$6*$B31*$D$7-$D$18)*$D$16)-($D$18*$D$17))*(1-$D$15))/($D$12+($D$6*(1-$B31)*$D$8))/$D$13-1
B32: 0.8 | D32: =((($D$21+D$26*$D$14+$D$22)-$D$19-(($D$6*$B32*$D$7-$D$18)*$D$16)-($D$18*$D$17))*(1-$D$15))/($D$12+($D$6*(1-$B32)*$D$8))/$D$13-1 | E32: =((($D$21+E$26*$D$14+$D$22)-$D$19-(($D$6*$B32*$D$7-$D$18)*$D$16)-($D$18*$D$17))*(1-$D$15))/($D$12+($D$6*(1-$B32)*$D$8))/$D$13-1 | F32: =((($D$21+F$26*$D$14+$D$22)-$D$19-(($D$6*$B32*$D$7-$D$18)*$D$16)-($D$18*$D$17))*(1-$D$15))/($D$12+($D$6*(1-$B32)*$D$8))/$D$13-1 | G32: =((($D$21+G$26*$D$14+$D$22)-$D$19-(($D$6*$B32*$D$7-$D$18)*$D$16)-($D$18*$D$17))*(1-$D$15))/($D$12+($D$6*(1-$B32)*$D$8))/$D$13-1 | H32: =((($D$21+H$26*$D$14+$D$22)-$D$19-(($D$6*$B32*$D$7-$D$18)*$D$16)-($D$18*$D$17))*(1-$D$15))/($D$12+($D$6*(1-$B32)*$D$8))/$D$13-1
B33: 0.9 | D33: =((($D$21+D$26*$D$14+$D$22)-$D$19-(($D$6*$B33*$D$7-$D$18)*$D$16)-($D$18*$D$17))*(1-$D$15))/($D$12+($D$6*(1-$B33)*$D$8))/$D$13-1 | E33: =((($D$21+E$26*$D$14+$D$22)-$D$19-(($D$6*$B33*$D$7-$D$18)*$D$16)-($D$18*$D$17))*(1-$D$15))/($D$12+($D$6*(1-$B33)*$D$8))/$D$13-1 | F33: =((($D$21+F$26*$D$14+$D$22)-$D$19-(($D$6*$B33*$D$7-$D$18)*$D$16)-($D$18*$D$17))*(1-$D$15))/($D$12+($D$6*(1-$B33)*$D$8))/$D$13-1 | G33: =((($D$21+G$26*$D$14+$D$22)-$D$19-(($D$6*$B33*$D$7-$D$18)*$D$16)-($D$18*$D$17))*(1-$D$15))/($D$12+($D$6*(1-$B33)*$D$8))/$D$13-1 | H33: =((($D$21+H$26*$D$14+$D$22)-$D$19-(($D$6*$B33*$D$7-$D$18)*$D$16)-($D$18*$D$17))*(1-$D$15))/($D$12+($D$6*(1-$B33)*$D$8))/$D$13-1
B34: Check: center cell (50% cash, $3,500mm synergy) ties to ProForma base case | D34: =ROUND(F29-ProForma!D29,3)
B36: GRID 2: % Cash Consideration Mix (rows) x Run-rate Synergies (cols) - alternate cut
B37: Output = FY2024E accretion/(dilution) % | C37: =ProForma!D29 | D37: 1500 | E37: 2500 | F37: 3500 | G37: 4500 | H37: 5500
B38: 0 | D38: =((($D$21+D$37*$D$14+$D$22)-$D$19-(($D$6*$B38*$D$7-$D$18)*$D$16)-($D$18*$D$17))*(1-$D$15))/($D$12+($D$6*(1-$B38)*$D$8))/$D$13-1 | E38: =((($D$21+E$37*$D$14+$D$22)-$D$19-(($D$6*$B38*$D$7-$D$18)*$D$16)-($D$18*$D$17))*(1-$D$15))/($D$12+($D$6*(1-$B38)*$D$8))/$D$13-1 | F38: =((($D$21+F$37*$D$14+$D$22)-$D$19-(($D$6*$B38*$D$7-$D$18)*$D$16)-($D$18*$D$17))*(1-$D$15))/($D$12+($D$6*(1-$B38)*$D$8))/$D$13-1 | G38: =((($D$21+G$37*$D$14+$D$22)-$D$19-(($D$6*$B38*$D$7-$D$18)*$D$16)-($D$18*$D$17))*(1-$D$15))/($D$12+($D$6*(1-$B38)*$D$8))/$D$13-1 | H38: =((($D$21+H$37*$D$14+$D$22)-$D$19-(($D$6*$B38*$D$7-$D$18)*$D$16)-($D$18*$D$17))*(1-$D$15))/($D$12+($D$6*(1-$B38)*$D$8))/$D$13-1
B39: 0.25 | D39: =((($D$21+D$37*$D$14+$D$22)-$D$19-(($D$6*$B39*$D$7-$D$18)*$D$16)-($D$18*$D$17))*(1-$D$15))/($D$12+($D$6*(1-$B39)*$D$8))/$D$13-1 | E39: =((($D$21+E$37*$D$14+$D$22)-$D$19-(($D$6*$B39*$D$7-$D$18)*$D$16)-($D$18*$D$17))*(1-$D$15))/($D$12+($D$6*(1-$B39)*$D$8))/$D$13-1 | F39: =((($D$21+F$37*$D$14+$D$22)-$D$19-(($D$6*$B39*$D$7-$D$18)*$D$16)-($D$18*$D$17))*(1-$D$15))/($D$12+($D$6*(1-$B39)*$D$8))/$D$13-1 | G39: =((($D$21+G$37*$D$14+$D$22)-$D$19-(($D$6*$B39*$D$7-$D$18)*$D$16)-($D$18*$D$17))*(1-$D$15))/($D$12+($D$6*(1-$B39)*$D$8))/$D$13-1 | H39: =((($D$21+H$37*$D$14+$D$22)-$D$19-(($D$6*$B39*$D$7-$D$18)*$D$16)-($D$18*$D$17))*(1-$D$15))/($D$12+($D$6*(1-$B39)*$D$8))/$D$13-1
B40: 0.5 | D40: =((($D$21+D$37*$D$14+$D$22)-$D$19-(($D$6*$B40*$D$7-$D$18)*$D$16)-($D$18*$D$17))*(1-$D$15))/($D$12+($D$6*(1-$B40)*$D$8))/$D$13-1 | E40: =((($D$21+E$37*$D$14+$D$22)-$D$19-(($D$6*$B40*$D$7-$D$18)*$D$16)-($D$18*$D$17))*(1-$D$15))/($D$12+($D$6*(1-$B40)*$D$8))/$D$13-1 | F40: =((($D$21+F$37*$D$14+$D$22)-$D$19-(($D$6*$B40*$D$7-$D$18)*$D$16)-($D$18*$D$17))*(1-$D$15))/($D$12+($D$6*(1-$B40)*$D$8))/$D$13-1 | G40: =((($D$21+G$37*$D$14+$D$22)-$D$19-(($D$6*$B40*$D$7-$D$18)*$D$16)-($D$18*$D$17))*(1-$D$15))/($D$12+($D$6*(1-$B40)*$D$8))/$D$13-1 | H40: =((($D$21+H$37*$D$14+$D$22)-$D$19-(($D$6*$B40*$D$7-$D$18)*$D$16)-($D$18*$D$17))*(1-$D$15))/($D$12+($D$6*(1-$B40)*$D$8))/$D$13-1
B41: 0.75 | D41: =((($D$21+D$37*$D$14+$D$22)-$D$19-(($D$6*$B41*$D$7-$D$18)*$D$16)-($D$18*$D$17))*(1-$D$15))/($D$12+($D$6*(1-$B41)*$D$8))/$D$13-1 | E41: =((($D$21+E$37*$D$14+$D$22)-$D$19-(($D$6*$B41*$D$7-$D$18)*$D$16)-($D$18*$D$17))*(1-$D$15))/($D$12+($D$6*(1-$B41)*$D$8))/$D$13-1 | F41: =((($D$21+F$37*$D$14+$D$22)-$D$19-(($D$6*$B41*$D$7-$D$18)*$D$16)-($D$18*$D$17))*(1-$D$15))/($D$12+($D$6*(1-$B41)*$D$8))/$D$13-1 | G41: =((($D$21+G$37*$D$14+$D$22)-$D$19-(($D$6*$B41*$D$7-$D$18)*$D$16)-($D$18*$D$17))*(1-$D$15))/($D$12+($D$6*(1-$B41)*$D$8))/$D$13-1 | H41: =((($D$21+H$37*$D$14+$D$22)-$D$19-(($D$6*$B41*$D$7-$D$18)*$D$16)-($D$18*$D$17))*(1-$D$15))/($D$12+($D$6*(1-$B41)*$D$8))/$D$13-1
B42: 1 | D42: =((($D$21+D$37*$D$14+$D$22)-$D$19-(($D$6*$B42*$D$7-$D$18)*$D$16)-($D$18*$D$17))*(1-$D$15))/($D$12+($D$6*(1-$B42)*$D$8))/$D$13-1 | E42: =((($D$21+E$37*$D$14+$D$22)-$D$19-(($D$6*$B42*$D$7-$D$18)*$D$16)-($D$18*$D$17))*(1-$D$15))/($D$12+($D$6*(1-$B42)*$D$8))/$D$13-1 | F42: =((($D$21+F$37*$D$14+$D$22)-$D$19-(($D$6*$B42*$D$7-$D$18)*$D$16)-($D$18*$D$17))*(1-$D$15))/($D$12+($D$6*(1-$B42)*$D$8))/$D$13-1 | G42: =((($D$21+G$37*$D$14+$D$22)-$D$19-(($D$6*$B42*$D$7-$D$18)*$D$16)-($D$18*$D$17))*(1-$D$15))/($D$12+($D$6*(1-$B42)*$D$8))/$D$13-1 | H42: =((($D$21+H$37*$D$14+$D$22)-$D$19-(($D$6*$B42*$D$7-$D$18)*$D$16)-($D$18*$D$17))*(1-$D$15))/($D$12+($D$6*(1-$B42)*$D$8))/$D$13-1
B43: Check: center cell (50% cash, $3,500mm synergy) ties to ProForma base case | D43: =ROUND(F40-ProForma!D29,3)
B45: GRID 3: Cash Election Premium (vs. $142.50 base, rows) x Run-rate Synergies (cols)
...
