Workbook

Sheet Cover
B2: The Walt Disney Company / 21st Century Fox - Merger Model
B3: ($ in millions, except per-share data, unless noted)
B4: Deal: Disney acquisition of 21st Century Fox's entertainment assets ('acquired perimeter') for $38.00/share, $71.3B equity value (~$85.1B EV incl. assumed net debt); amended agreement signed June 20, 2018; closed March 20, 2019.
B5: Prepared by: Akul Veauli
B6: Date: August 23, 2026
B8: Model description: Accretion/dilution merger model for Disney's acquisition of 21st Century Fox's film & TV studio, cable networks (ex-Fox News/FS1/FBC/RSNs), and international businesses - the 'acquired perimeter' remaining after Fox's spin-off of 'New Fox' (Fox Corporation: Fox News, Fox Broadcasting, FS1, regional sports networks) into RemainCo immediately prior to close. Target financials are carved out as Total 21CF less RemainCo pro forma. Consideration is 50% cash / 50% stock, subject to a collar on the exchange ratio (0.4517x base, executed within the collar at close). New debt funds the cash consideration net of balance-sheet cash used. Includes purchase price allocation (goodwill & intangible step-up with incremental amortization), $2.0B run-rate cost synergies phased in over 4 years, 5-year pro forma EPS accretion/dilution, breakeven synergies, contribution analysis, and live premium x synergies / consideration-mix sensitivity grids.
B12: Color-code legend
B13: 38.00 (hardcoded input) | C13: Blue font / yellow fill = hardcoded assumption
B14: e.g. B12*2 (same-sheet formula) | C14: Black font = formula referencing same tab
B15: e.g. Assumptions!B12 (cross-tab link) | C15: Green font = formula linking from another tab
B18: Table of contents
B19: Cover
B20: Assumptions
B21: Acquirer
B22: Target
B23: Synergies
B24: PPA-Financing
B25: ProForma
B26: Contribution
B27: Sensitivity
B29: Key outputs
B30: Offer price per Fox share | D30: =Assumptions!D6
B31: Premium to unaffected price | D31: =Assumptions!D8
B32: Equity purchase price | D32: =Assumptions!D10
B33: Actual disclosed exchange ratio (collar) | D33: =Assumptions!D22
B34: New goodwill created | D34: ='PPA-Financing'!D26
B35: FY2019E accretion/(dilution) % | D35: =ProForma!G25
B36: FY2020E accretion/(dilution) % | D36: =ProForma!H25
B37: Breakeven run-rate synergies (pre-tax, Yr1) | D37: =ProForma!G27
B39: Sources: Disney FY2018 10-K (filed 11/21/2018, SEC CIK 1744489); 21st Century Fox FY2018 10-K (filed 10/5/2018, SEC CIK 1308161); Disney/Fox amended merger agreement & press release (6/20/2018); Fox Corporation Form 10 and Disney 8-K/A pro forma exhibits (RemainCo carve-out, March 2019); Disney 8-K12B exchange-ratio/VWAP exhibit (3/2019). See Assumptions and Target tabs for line-by-line flagged estimates.
B42: DealNotes - Data Gaps & Assumption Choices (flagged by research)
B43: RemainCo ('New Fox') FY2018 pro forma EBITDA is disclosed only as a $2.0-2.8B range in available search results; this model uses the midpoint $2.4B as a blue input, with the full range shown as a sensitivity note on the Target tab. RemainCo revenue of $10.2B is used directly (single point estimate available).
B44: Target (acquired-perimeter) FY2016-17 history is not separately disclosed pre-carve-out; this model holds the RemainCo revenue/EBITDA share of Total 21CF constant at the FY2018 ratio for FY2016-17, then derives the acquired perimeter as Total-21CF-less-RemainCo in each historical year (visible carve-out block on Target tab).
B45: Disney FY2016-17 D&A and FY2018 cash/debt detail were not returned in full precision by the research pass; D&A is estimated at a stable ~8.5% of revenue (consistent with FY2018 approximate op-income-to-EBITDA bridge) and FY2018 net debt is estimated at ~$17.1B total debt less ~$4.0B cash (~$13.1B net) - both flagged blue inputs, adjustable.
B46: Deal advisory + financing fees are not quantified in the S-4/proxy excerpts retrieved; this model uses a conservative fallback of 0.75% of equity purchase price for advisory fees and 0.5% of new debt for financing fees, both blue inputs, expensed at close (add-back memo only, not run through the 5-yr P&L).
B47: New-debt blended coupon uses the fallback 2019 single-A industrial yield of 4.00% (Disney was upper-single-A / high-BBB rated pre-deal); intangible step-up amortization life uses the deal-model convention of 15 years straight-line, allocation 40% of premium-over-book to identifiable intangibles (customer relationships, trademarks, content library), remainder to goodwill, with a DTL toggle (default ON) at the 21% blended rate.

Sheet Assumptions
B2: Assumptions
B3: ($ in millions, except per-share and per-share-price data, unless noted)
B5: 1. Deal Terms
B6: Offer price per Fox share ($ cash or Disney stock) | D6: 38 | E6: Amended merger agreement, 6/20/2018 press release
B7: Target unaffected share price ($) | D7: 26 | E7: FLAGGED: pre-rumor ~11/2/2017 level, disclosed range $25-26; midpoint used
B8: Premium to unaffected price | D8: =D6/D7-1
B9: Target fully-diluted shares, deal-level (mm) | D9: 1876 | E9: Implied by $71.3B equity value / $38.00 per S-4 disclosure
B10: Equity purchase price ($mm) | D10: =D6*D9 | E10: Check: ties to disclosed $71.3B
B11: Assumed net debt of Fox at close ($mm) | D11: 13800 | E11: S-4 pro forma disclosure, ~$13.8B
B12: Total enterprise value ($mm) | D12: =D10+D11 | E12: Check: ties to disclosed ~$85.1B
B14: 2. Consideration Mix & Exchange Mechanics
B15: % Cash consideration | D15: 0.5 | E15: 50/50 aggregate proration per amended agreement
B16: % Stock consideration | D16: =1-D15
B17: Cash consideration ($mm) | D17: =D10*D15 | E17: Check: ties to disclosed $35.7B
B18: Stock consideration ($mm) | D18: =D10*D16
B19: Acquirer (Disney) share price at close ($) | D19: 114.75 | E19: 3/18/2019 close, last trading day pre-close (3/20/2019)
B20: New Disney shares issued (mm) | D20: =D18/D19 | E20: Equals stock consideration $ / Disney price; check vs. disclosed 343mm
B21: Implied blended exchange ratio (memo, Disney sh / Fox sh) | D21: =D20/D9
B22: Actual disclosed exchange ratio (stock electors, per collar) | D22: 0.4517 | E22: Collar band $93.53-$114.32 Disney VWAP; fixed at 0.4517 within band (steps to 0.3324 above / 0.4063 below). Differs from the memo blended ratio above because only shareholders electing stock receive the full per-share ratio; this model uses the dollar-based 50/50 split for P&L purposes, consistent with the master-spec grid architecture.
B23: Hulu / RSN divestiture treatment | D23: Memo only | E23: Not separately modeled; immaterial to combined P&L for this model's purposes
B25: 3. Financing
B26: Cash consideration funded from Disney balance sheet ($mm) | D26: 0 | E26: Model assumes cash consideration fully debt-funded, per disclosed $35.7B bridge
B27: New debt raised ($mm) | D27: =D17-D26
B28: Blended new-debt interest rate | D28: 0.04 | E28: Fallback: 2019 single-A industrial bond yield, 3.5%-4.0% range
B29: Foregone interest rate on cash used | D29: 0.02 | E29: Opportunity cost, short-term investment yield
B30: Advisory fees (% of equity purchase price) | D30: 0.0075 | E30: FLAGGED: not quantified in retrieved S-4 excerpts; fallback 0.5%-1.5% range, midpoint-low used
B31: Advisory fees ($mm) | D31: =D10*D30
B32: Financing fees (% of new debt) | D32: 0.005 | E32: FLAGGED estimate on $35.7B bridge/notes; fallback 0.5%-1.0% range
B33: Financing fees ($mm) | D33: =D27*D32
B34: Financing fee amortization life (yrs) | D34: 5
B35: Financing fee amortization / yr ($mm) | D35: =D33/D34
B37: 4. Purchase Price Allocation (PPA) Inputs
B38: Target book equity acquired ($mm) | D38: 15000 | E38: FLAGGED: acquired-perimeter carve-out book equity not separately disclosed; estimate
B39: Existing target goodwill written off ($mm) | D39: 2000 | E39: FLAGGED estimate; existing 21CF goodwill allocable to acquired perimeter
B40: Intangible step-up (% of premium-over-book) | D40: 0.4 | E40: Deal-model convention; identifiable intangibles (content library, trademarks, relationships)
B41: Intangible step-up amortization life (yrs) | D41: 15
B42: Deferred tax liability (DTL) toggle on step-up (1=on, 0=off) | D42: 1 | E42: DTL = intangible step-up x tax rate, added to goodwill
B44: 5. Other
B45: Blended tax rate | D45: 0.21 | E45: US federal statutory rate post-TCJA (2018+)
B46: EPS accretion/dilution modeled years | D46: FY2019E-FY2023E
...

Sheet Acquirer
B2: Acquirer - The Walt Disney Company (Standalone)
B3: ($ in millions, except per-share data; FYE September)
D5: FY2016A | E5: FY2017A | F5: FY2018A | G5: FY2019E | H5: FY2020E | I5: FY2021E | J5: FY2022E | K5: FY2023E
B6: Revenue | D6: 54100 | E6: 55100 | F6: 59400 | G6: =F6*(1+G7) | H6: =G6*(1+H7) | I6: =H6*(1+I7) | J6: =I6*(1+J7) | K6: =J6*(1+K7)
B7: Revenue growth % | D7: n/a | E7: =E6/D6-1 | F7: =F6/E6-1 | G7: 0.08 | H7: 0.06 | I7: 0.05 | J7: 0.05 | K7: 0.05
B8: EBITDA | D8: 19398.5 | E8: 19483.5 | F8: 20749 | G8: =G6*G9 | H8: =H6*H9 | I8: =I6*I9 | J8: =J6*J9 | K8: =K6*K9
B9: EBITDA margin % | D9: =D8/D6 | E9: =E8/E6 | F9: =F8/F6 | G9: 0.35 | H9: 0.35 | I9: 0.35 | J9: 0.35 | K9: 0.35
B10: D&A | D10: 4598.5 | E10: 4683.5 | F10: 5049 | G10: =G6*G11 | H10: =H6*H11 | I10: =I6*I11 | J10: =J6*J11 | K10: =K6*K11
B11: D&A % of revenue | D11: =D10/D6 | E11: =E10/E6 | F11: =F10/F6 | G11: 0.085 | H11: 0.085 | I11: 0.085 | J11: 0.085 | K11: 0.085
B12: EBIT | D12: =D8-D10 | E12: =E8-E10 | F12: =F8-F10 | G12: =G8-G10 | H12: =H8-H10 | I12: =I8-I10 | J12: =J8-J10 | K12: =K8-K10
B13: Interest expense | D13: =$D22*$D23 | E13: =$D22*$D23 | F13: =$D22*$D23 | G13: =$D22*$D23 | H13: =$D22*$D23 | I13: =$D22*$D23 | J13: =$D22*$D23 | K13: =$D22*$D23
B14: EBT | D14: =D12-D13 | E14: =E12-E13 | F14: =F12-F13 | G14: =G12-G13 | H14: =H12-H13 | I14: =I12-I13 | J14: =J12-J13 | K14: =K12-K13
B15: Taxes | D15: =D14-D16 | E15: =E14-E16 | F15: =F14-F16 | G15: =G14*Assumptions!$D45 | H15: =H14*Assumptions!$D45 | I15: =I14*Assumptions!$D45 | J15: =J14*Assumptions!$D45 | K15: =K14*Assumptions!$D45
B16: Net income | D16: 12400 | E16: 12600 | F16: 12600 | G16: =G14-G15 | H16: =H14-H15 | I16: =I14-I15 | J16: =J14-J15 | K16: =K14-K15
B17: Diluted shares outstanding (mm) | D17: 1509 | E17: 1499 | F17: 1489 | G17: =F17 | H17: =G17 | I17: =H17 | J17: =I17 | K17: =J17
B18: Standalone diluted EPS | D18: =D16/D17 | E18: =E16/E17 | F18: =F16/F17 | G18: =G16/G17 | H18: =H16/H17 | I18: =I16/I17 | J18: =J16/J17 | K18: =K16/K17
B21: Standalone debt assumptions (for interest expense)
B22: Disney standalone debt, constant ($mm) | D22: 17100 | E22: FLAGGED estimate: FY2018 total debt reference (~$17.1B, mid-2018 disclosure)
B23: Disney standalone debt rate | D23: 0.035 | E23: FLAGGED estimate: consistent with A-rated cost of debt pre-deal
B25: Revenue growth % driver (projection years, blue)
B26: FY19E-23E growth assumption row -> | E26: Set directly on the Revenue growth % row above for FY2019E-FY2023E
B28: Note: Historical D&A is estimated at ~8.5% of revenue (not separately disclosed at this precision in retrieved 10-K excerpts) - FLAGGED. Historical EBITDA = disclosed operating income + estimated D&A. Historical interest expense/taxes are formula-derived (EBT less reported net income) given actual effective tax rates shifted materially around the FY2018 TCJA transition.

Sheet Target
B2: Target - 21st Century Fox 'Acquired Perimeter' (Carved from RemainCo)
B3: ($ in millions, except per-share data; FYE June; RemainCo carve-out shown for FY2016A-FY2018A only)
D5: FY2016A | E5: FY2017A | F5: FY2018A | G5: FY2019E | H5: FY2020E | I5: FY2021E | J5: FY2022E | K5: FY2023E
B6: A. Historical Carve-Out: Total 21CF less RemainCo ('New Fox') Pro Forma
B7: Total 21st Century Fox revenue (reported) | D7: 27326 | E7: 28500 | F7: 30400
B8: Total 21st Century Fox EBITDA (op. income + est. D&A) | D8: 8459.34 | E8: 8865 | F8: 9036
B9: Less: RemainCo ('New Fox') pro forma revenue | D9: =D7*(F9/F7) | E9: =E7*(F9/F7) | F9: 10200 | K9: Pro forma disclosure, S-4/Form 10 exhibits
B10: Less: RemainCo ('New Fox') pro forma EBITDA | D10: =D8*(F10/F8) | E10: =E8*(F10/F8) | F10: 2400 | K10: FLAGGED: midpoint of disclosed $2.0-2.8B range
B11: Equals Acquired perimeter revenue (carve-out) | D11: =D7-D9 | E11: =E7-E9 | F11: =F7-F9
B12: Equals Acquired perimeter EBITDA (carve-out) | D12: =D8-D10 | E12: =E8-E10 | F12: =F8-F10
B13: Note: RemainCo FY2018 EBITDA disclosed only as a $2.0-2.8B range; midpoint $2.4B used above (blue input, cell F10). RemainCo FY2016-17 revenue/EBITDA held at FY2018 ratio to Total 21CF (no separate pre-close carve-out disclosure). Total 21CF EBITDA = disclosed operating income + estimated D&A (~9% of revenue, FLAGGED, segment D&A not separately disclosed).
B15: B. Target (Acquired Perimeter) Standalone Projection
B16: Revenue | D16: =D11 | E16: =E11 | F16: =F11 | G16: =F16*(1+G17) | H16: =G16*(1+H17) | I16: =H16*(1+I17) | J16: =I16*(1+J17) | K16: =J16*(1+K17)
B17: Revenue growth % | D17: n/a | E17: =E16/D16-1 | F17: =F16/E16-1 | G17: 0.06 | H17: 0.05 | I17: 0.045 | J17: 0.04 | K17: 0.04
B18: EBITDA | D18: =D12 | E18: =E12 | F18: =F12 | G18: =G16*G19 | H18: =H16*H19 | I18: =I16*I19 | J18: =J16*J19 | K18: =K16*K19
B19: EBITDA margin % | D19: =D18/D16 | E19: =E18/E16 | F19: =F18/F16 | G19: 0.33 | H19: 0.33 | I19: 0.335 | J19: 0.335 | K19: 0.335
B20: D&A | D20: =D16*D21 | E20: =E16*E21 | F20: =F16*F21 | G20: =G16*G21 | H20: =H16*H21 | I20: =I16*I21 | J20: =J16*J21 | K20: =K16*K21
B21: D&A % of revenue | D21: 0.09 | E21: 0.09 | F21: 0.09 | G21: 0.09 | H21: 0.09 | I21: 0.09 | J21: 0.09 | K21: 0.09
B22: EBIT | D22: =D18-D20 | E22: =E18-E20 | F22: =F18-F20 | G22: =G18-G20 | H22: =H18-H20 | I22: =I18-I20 | J22: =J18-J20 | K22: =K18-K20
B23: Interest expense | D23: =$D32*$D33 | E23: =$D32*$D33 | F23: =$D32*$D33 | G23: =$D32*$D33 | H23: =$D32*$D33 | I23: =$D32*$D33 | J23: =$D32*$D33 | K23: =$D32*$D33
B24: EBT | D24: =D22-D23 | E24: =E22-E23 | F24: =F22-F23 | G24: =G22-G23 | H24: =H22-H23 | I24: =I22-I23 | J24: =J22-J23 | K24: =K22-K23
B25: Taxes | D25: =D24*Assumptions!$D45 | E25: =E24*Assumptions!$D45 | F25: =F24*Assumptions!$D45 | G25: =G24*Assumptions!$D45 | H25: =H24*Assumptions!$D45 | I25: =I24*Assumptions!$D45 | J25: =J24*Assumptions!$D45 | K25: =K24*Assumptions!$D45
B26: Net income | D26: =D24-D25 | E26: =E24-E25 | F26: =F24-F25 | G26: =G24-G25 | H26: =H24-H25 | I26: =I24-I25 | J26: =J24-J25 | K26: =K24-K25
B27: Deal-level FD shares (memo, mm) | D27: =Assumptions!$D9 | E27: =Assumptions!$D9 | F27: =Assumptions!$D9 | G27: =Assumptions!$D9 | H27: =Assumptions!$D9 | I27: =Assumptions!$D9 | J27: =Assumptions!$D9 | K27: =Assumptions!$D9
B28: Analytical standalone EPS (memo, not a reported Fox metric) | D28: =D26/D27 | E28: =E26/E27 | F28: =F26/F27 | G28: =G26/G27 | H28: =H26/H27 | I28: =I26/I27 | J28: =J26/J27 | K28: =K26/K27
B31: Target standalone debt assumptions (for interest expense)
B32: Target debt, constant ($mm) | D32: =Assumptions!$D11 | E32: Equals assumed net debt of Fox at close, per Assumptions tab
B33: Target debt rate | D33: 0.045 | E33: FLAGGED estimate: slightly above Disney's cost of debt, reflecting Fox credit profile

Sheet Synergies
B2: Synergies
B3: ($ in millions; PROJ years only, FY2019E-FY2023E)
D5: FY2016A | E5: FY2017A | F5: FY2018A | G5: FY2019E | H5: FY2020E | I5: FY2021E | J5: FY2022E | K5: FY2023E
B6: Run-rate cost synergies, fully phased-in ($mm) | D6: 2000 | E6: Deal-announced target, per press release; constant across FY2019E-FY2023E
B7: Phase-in % of run-rate cost synergies | G7: 0.25 | H7: 0.5 | I7: 0.75 | J7: 1 | K7: 1
B8: Cost synergies realized, pre-tax ($mm) | G8: =$D6*G7 | H8: =$D6*H7 | I8: =$D6*I7 | J8: =$D6*J7 | K8: =$D6*K7
B10: Revenue synergies, run-rate ($mm) | D10: 0 | E10: Not quantified in deal documents; base case = 0 per spec guidance
B11: Revenue synergy phase-in % | G11: 0.25 | H11: 0.5 | I11: 0.75 | J11: 1 | K11: 1
B12: Revenue synergy incremental margin % | D12: 0.3 | E12: Memo assumption; not used while revenue synergies = 0
B13: Revenue synergies realized, top-line $ impact ($mm) | G13: =$D10*G11 | H13: =$D10*H11 | I13: =$D10*I11 | J13: =$D10*J11 | K13: =$D10*K11
B14: Revenue synergies realized, pre-tax EBITDA impact ($mm) | G14: =G13*$D12 | H14: =H13*$D12 | I14: =I13*$D12 | J14: =J13*$D12 | K14: =K13*$D12
B16: One-time integration costs, pre-tax ($mm) | G16: 400 | H16: 300 | I16: 0 | J16: 0 | K16: 0
B17: FLAGGED estimate: severance, systems integration, consolidation, expensed in FY2019E-FY2020E
B19: Total pre-tax synergy impact to EBITDA ($mm) | G19: =G8+G14-G16 | H19: =H8+H14-H16 | I19: =I8+I14-I16 | J19: =J8+J14-J16 | K19: =K8+K14-K16
B20: Total after-tax synergy impact ($mm) | G20: =G19*(1-Assumptions!$D45) | H20: =H19*(1-Assumptions!$D45) | I20: =I19*(1-Assumptions!$D45) | J20: =J19*(1-Assumptions!$D45) | K20: =K19*(1-Assumptions!$D45)

Sheet PPA-Financing
B2: PPA & Financing
B3: ($ in millions, unless noted)
B5: 1. Sources & Uses of Funds
B6: Uses:
B7: Equity purchase price for acquired perimeter | D7: =Assumptions!$D10
B8: Advisory fees | D8: =Assumptions!$D31
B9: Financing fees | D9: =Assumptions!$D33
B10: Total uses | D10: =SUM(D7:D9)
B12: Sources:
B13: Cash from Disney balance sheet | D13: =Assumptions!$D26
B14: Stock issued to Fox sellers (at value) | D14: =Assumptions!$D18
B15: New debt raised (plug, incl. fees) | D15: =D10-D13-D14
B16: Total sources | D16: =SUM(D13:D15)
B17: Check: Total sources - Total uses (must = 0.0) | D17: =ROUND(D16-D10,2)
B19: 2. Goodwill Build (Purchase Price Allocation Waterfall)
B20: Equity purchase price | D20: =Assumptions!$D10
B21: Less: Target book equity acquired | D21: =-Assumptions!$D38
B22: Add: Existing target goodwill written off | D22: =Assumptions!$D39
B23: Equals Premium over adjusted net asset value | D23: =D20+D21+D22
B24: Less: Intangible step-up (% of premium, per Assumptions) | D24: =-D23*Assumptions!$D40
B25: Add: Deferred tax liability (DTL) created on step-up | D25: =-D24*Assumptions!$D45*Assumptions!$D42
B26: Equals New goodwill created | D26: =D23+D24+D25
B27: Intangible step-up asset, gross ($mm, positive) | D27: =-D24
B29: 3. Financing & Amortization Effects per Year (FY2019E-FY2023E)
D30: FY2019E | E30: FY2020E | F30: FY2021E | G30: FY2022E | H30: FY2023E
B31: New-debt interest expense | D31: =$D15*Assumptions!$D28 | E31: =$D15*Assumptions!$D28 | F31: =$D15*Assumptions!$D28 | G31: =$D15*Assumptions!$D28 | H31: =$D15*Assumptions!$D28
B32: Foregone interest income on cash used | D32: =$D13*Assumptions!$D29 | E32: =$D13*Assumptions!$D29 | F32: =$D13*Assumptions!$D29 | G32: =$D13*Assumptions!$D29 | H32: =$D13*Assumptions!$D29
B33: Financing fee amortization | D33: =Assumptions!$D35 | E33: =Assumptions!$D35 | F33: =Assumptions!$D35 | G33: =Assumptions!$D35 | H33: =Assumptions!$D35
B34: New intangible amortization | D34: =$D27/Assumptions!$D41 | E34: =$D27/Assumptions!$D41 | F34: =$D27/Assumptions!$D41 | G34: =$D27/Assumptions!$D41 | H34: =$D27/Assumptions!$D41
B36: Note: 'New debt raised' above (Sources & Uses) is inclusive of advisory + financing fees and is the figure driving pro forma interest expense; Assumptions!D27 shows a simplified memo (cash consideration less BS cash only, excluding fees) for reference against the disclosed ~$35.7B cash/bridge figure.

Sheet ProForma
B2: ProForma - Combined Company Accretion / (Dilution)
B3: ($ in millions, except per-share data; FY2019E-FY2023E)
G5: FY2019E | H5: FY2020E | I5: FY2021E | J5: FY2022E | K5: FY2023E
B6: Target debt refinance toggle (1=refi at Disney rate, 0=assume Fox's own rate) | D6: 1
B8: Revenue (Acquirer + Target + revenue synergies) | G8: =Acquirer!G6+Target!G16+Synergies!G13 | H8: =Acquirer!H6+Target!H16+Synergies!H13 | I8: =Acquirer!I6+Target!I16+Synergies!I13 | J8: =Acquirer!J6+Target!J16+Synergies!J13 | K8: =Acquirer!K6+Target!K16+Synergies!K13
B9: EBITDA (Acquirer + Target + cost synergies - integration + rev. syn. EBITDA impact) | G9: =Acquirer!G8+Target!G18+Synergies!G19 | H9: =Acquirer!H8+Target!H18+Synergies!H19 | I9: =Acquirer!I8+Target!I18+Synergies!I19 | J9: =Acquirer!J8+Target!J18+Synergies!J19 | K9: =Acquirer!K8+Target!K18+Synergies!K19
B10: Combined D&A (Acquirer + Target) | G10: =Acquirer!G10+Target!G20 | H10: =Acquirer!H10+Target!H20 | I10: =Acquirer!I10+Target!I20 | J10: =Acquirer!J10+Target!J20 | K10: =Acquirer!K10+Target!K20
B11: New intangible amortization (from PPA step-up) | G11: ='PPA-Financing'!D34 | H11: ='PPA-Financing'!E34 | I11: ='PPA-Financing'!F34 | J11: ='PPA-Financing'!G34 | K11: ='PPA-Financing'!H34
B12: EBIT | G12: =G9-G10-G11 | H12: =H9-H10-H11 | I12: =I9-I10-I11 | J12: =J9-J10-J11 | K12: =K9-K10-K11
B13: Acquirer standalone interest expense | G13: =Acquirer!G13 | H13: =Acquirer!H13 | I13: =Acquirer!I13 | J13: =Acquirer!J13 | K13: =Acquirer!K13
B14: Target interest expense (per refinance toggle) | G14: =IF($D6=1,Target!$D32*Assumptions!$D28,Target!G23) | H14: =IF($D6=1,Target!$D32*Assumptions!$D28,Target!H23) | I14: =IF($D6=1,Target!$D32*Assumptions!$D28,Target!I23) | J14: =IF($D6=1,Target!$D32*Assumptions!$D28,Target!J23) | K14: =IF($D6=1,Target!$D32*Assumptions!$D28,Target!K23)
B15: New-debt interest expense | G15: ='PPA-Financing'!D31 | H15: ='PPA-Financing'!E31 | I15: ='PPA-Financing'!F31 | J15: ='PPA-Financing'!G31 | K15: ='PPA-Financing'!H31
B16: Foregone interest income on cash used | G16: ='PPA-Financing'!D32 | H16: ='PPA-Financing'!E32 | I16: ='PPA-Financing'!F32 | J16: ='PPA-Financing'!G32 | K16: ='PPA-Financing'!H32
B17: Total interest expense | G17: =G13+G14+G15+G16 | H17: =H13+H14+H15+H16 | I17: =I13+I14+I15+I16 | J17: =J13+J14+J15+J16 | K17: =K13+K14+K15+K16
B18: EBT | G18: =G12-G17 | H18: =H12-H17 | I18: =I12-I17 | J18: =J12-J17 | K18: =K12-K17
B19: Taxes | G19: =G18*Assumptions!$D45 | H19: =H18*Assumptions!$D45 | I19: =I18*Assumptions!$D45 | J19: =J18*Assumptions!$D45 | K19: =K18*Assumptions!$D45
B20: Pro forma net income | G20: =G18-G19 | H20: =H18-H19 | I20: =I18-I19 | J20: =J18-J19 | K20: =K18-K19
B21: Pro forma diluted shares (Acquirer standalone + new shares issued) | G21: =Acquirer!G17+Assumptions!$D20 | H21: =Acquirer!H17+Assumptions!$D20 | I21: =Acquirer!I17+Assumptions!$D20 | J21: =Acquirer!J17+Assumptions!$D20 | K21: =Acquirer!K17+Assumptions!$D20
B22: Pro forma diluted EPS | G22: =G20/G21 | H22: =H20/H21 | I22: =I20/I21 | J22: =J20/J21 | K22: =K20/K21
B23: Acquirer standalone diluted EPS (memo) | G23: =Acquirer!G18 | H23: =Acquirer!H18 | I23: =Acquirer!I18 | J23: =Acquirer!J18 | K23: =Acquirer!K18
B24: Accretion / (dilution), $ per share | G24: =G22-G23 | H24: =H22-H23 | I24: =I22-I23 | J24: =J22-J23 | K24: =K22-K23
B25: Accretion / (dilution), % | G25: =G22/G23-1 | H25: =H22/H23-1 | I25: =I22/I23-1 | J25: =J22/J23-1 | K25: =K22/K23-1
B27: Breakeven run-rate cost synergies, pre-tax (FY2019E only) | G27: =(Acquirer!G18*G21/(1-Assumptions!$D45)-(G18-Synergies!G8))/Synergies!G7
B28: Check: accretion at breakeven synergies (must = 0.0000) | G28: =ROUND(((G18-Synergies!G8+G27*Synergies!G7)*(1-Assumptions!$D45))/G21-Acquirer!G18,4)
B30: Memo: Pro Forma Leverage (simple debt-paydown sweep)
B31: Net debt, beginning of year | G31: =Acquirer!$D22+Assumptions!$D11+'PPA-Financing'!$D15-Assumptions!$D26 | H31: =G33 | I31: =H33 | J31: =I33 | K31: =J33
B32: Less: debt paydown (sweep % x pro forma NI) | G32: =Assumptions!$D47*G20 | H32: =Assumptions!$D47*H20 | I32: =Assumptions!$D47*I20 | J32: =Assumptions!$D47*J20 | K32: =Assumptions!$D47*K20
B33: Net debt, end of year | G33: =G31-G32 | H33: =H31-H32 | I33: =I31-I32 | J33: =J31-J32 | K33: =K31-K32
B34: Net debt / EBITDA (x) | G34: =G33/G9 | H34: =H33/H9 | I34: =I33/I9 | J34: =J33/J9 | K34: =K33/K9

Sheet Contribution
B2: Contribution Analysis
B3: ($ in millions; FY2019E, first full pro forma year)
B5: Metric | C5: Acquirer (Disney) | D5: Target (Fox perimeter) | E5: Combined | F5: Acquirer % | G5: Target %
B6: Revenue | C6: =Acquirer!G6 | D6: =Target!G16 | E6: =C6+D6 | F6: =C6/E6 | G6: =D6/E6
B8: EBITDA | C8: =Acquirer!G8 | D8: =Target!G18 | E8: =C8+D8 | F8: =C8/E8 | G8: =D8/E8
B10: EBIT | C10: =Acquirer!G12 | D10: =Target!G22 | E10: =C10+D10 | F10: =C10/E10 | G10: =D10/E10
B12: Net income | C12: =Acquirer!G16 | D12: =Target!G26 | E12: =C12+D12 | F12: =C12/E12 | G12: =D12/E12
B14: Ownership Split vs. Economic Contribution (Net Income)
B15: Pro forma shares owned by Acquirer legacy holders | C15: =Acquirer!G17 | F15: =C15/ProForma!G21
B16: Pro forma shares issued to Target (Fox) holders | C16: =Assumptions!D20 | F16: =C16/ProForma!G21
B18: Contribution vs. ownership delta - Acquirer (NI% - Ownership%) | C18: =F12-F15
B19: Contribution vs. ownership delta - Target (NI% - Ownership%) | C19: =G12-F16
B21: Interpretation: a positive delta for Target means Fox shareholders receive a larger share of pro forma net income than their share of pro forma equity (i.e., Disney holders are diluted on an economic-contribution basis, before synergies); Disney's cost/revenue synergies and Fox's typically higher-margin content assets are the offsetting considerations.

Sheet Sensitivity
B2: Sensitivity
B3: FY2019E accretion / (dilution) %; live algebraic re-derivation grids (no Data Tables)
B5: Grid 1 - Offer Price Shock (vs. $38.00 base) x Run-Rate Cost Synergies -> FY2019E Accretion/(Dilution) %
B6: Corner (check, ties to ProForma FY2019E) | C6: =ROUND(R11-ProForma!G25,4)
B7: Offer price delta (rows) \ Synergies (cols) | C7: Offer price ($) | D7: Equity price | E7: Cash consid. | F7: Stock consid. | G7: New shares | H7: Total new debt | I7: Premium over NAV | J7: Intangible step-up | K7: Intang. amort/yr | L7: New-debt interest | M7: Foregone interest | N7: Interest, total | O7: PF shares, total | P7: 0 | Q7: 1000 | R7: 2000 | S7: 3000 | T7: 4000
B8: -0.2 | C8: =Assumptions!D6*(1+$B8) | D8: =C8*Assumptions!D9 | E8: =D8*Assumptions!D15 | F8: =D8*Assumptions!D16 | G8: =F8/Assumptions!D19 | H8: =(E8-Assumptions!D26)*(1+Assumptions!D32)+D8*Assumptions!D30 | I8: =D8-Assumptions!D38+Assumptions!D39 | J8: =I8*Assumptions!D40 | K8: =J8/Assumptions!D41 | L8: =H8*Assumptions!D28 | M8: =Assumptions!D26*Assumptions!D29 | N8: =Acquirer!G13+IF(ProForma!D6=1,Target!D32*Assumptions!D28,Target!G23)+L8+M8 | O8: =Acquirer!G17+G8 | P8: =(((Acquirer!G8+Target!G18+P$7*Synergies!G7-Synergies!G16)-Acquirer!G10-Target!G20-K8)-N8)*(1-Assumptions!D45)/O8/Acquirer!G18-1 | Q8: =(((Acquirer!G8+Target!G18+Q$7*Synergies!G7-Synergies!G16)-Acquirer!G10-Target!G20-K8)-N8)*(1-Assumptions!D45)/O8/Acquirer!G18-1 | R8: =(((Acquirer!G8+Target!G18+R$7*Synergies!G7-Synergies!G16)-Acquirer!G10-Target!G20-K8)-N8)*(1-Assumptions!D45)/O8/Acquirer!G18-1 | S8: =(((Acquirer!G8+Target!G18+S$7*Synergies!G7-Synergies!G16)-Acquirer!G10-Target!G20-K8)-N8)*(1-Assumptions!D45)/O8/Acquirer!G18-1 | T8: =(((Acquirer!G8+Target!G18+T$7*Synergies!G7-Synergies!G16)-Acquirer!G10-Target!G20-K8)-N8)*(1-Assumptions!D45)/O8/Acquirer!G18-1
B9: -0.1333 | C9: =Assumptions!D6*(1+$B9) | D9: =C9*Assumptions!D9 | E9: =D9*Assumptions!D15 | F9: =D9*Assumptions!D16 | G9: =F9/Assumptions!D19 | H9: =(E9-Assumptions!D26)*(1+Assumptions!D32)+D9*Assumptions!D30 | I9: =D9-Assumptions!D38+Assumptions!D39 | J9: =I9*Assumptions!D40 | K9: =J9/Assumptions!D41 | L9: =H9*Assumptions!D28 | M9: =Assumptions!D26*Assumptions!D29 | N9: =Acquirer!G13+IF(ProForma!D6=1,Target!D32*Assumptions!D28,Target!G23)+L9+M9 | O9: =Acquirer!G17+G9 | P9: =(((Acquirer!G8+Target!G18+P$7*Synergies!G7-Synergies!G16)-Acquirer!G10-Target!G20-K9)-N9)*(1-Assumptions!D45)/O9/Acquirer!G18-1 | Q9: =(((Acquirer!G8+Target!G18+Q$7*Synergies!G7-Synergies!G16)-Acquirer!G10-Target!G20-K9)-N9)*(1-Assumptions!D45)/O9/Acquirer!G18-1 | R9: =(((Acquirer!G8+Target!G18+R$7*Synergies!G7-Synergies!G16)-Acquirer!G10-Target!G20-K9)-N9)*(1-Assumptions!D45)/O9/Acquirer!G18-1 | S9: =(((Acquirer!G8+Target!G18+S$7*Synergies!G7-Synergies!G16)-Acquirer!G10-Target!G20-K9)-N9)*(1-Assumptions!D45)/O9/Acquirer!G18-1 | T9: =(((Acquirer!G8+Target!G18+T$7*Synergies!G7-Synergies!G16)-Acquirer!G10-Target!G20-K9)-N9)*(1-Assumptions!D45)/O9/Acquirer!G18-1
B10: -0.0667 | C10: =Assumptions!D6*(1+$B10) | D10: =C10*Assumptions!D9 | E10: =D10*Assumptions!D15 | F10: =D10*Assumptions!D16 | G10: =F10/Assumptions!D19 | H10: =(E10-Assumptions!D26)*(1+Assumptions!D32)+D10*Assumptions!D30 | I10: =D10-Assumptions!D38+Assumptions!D39 | J10: =I10*Assumptions!D40 | K10: =J10/Assumptions!D41 | L10: =H10*Assumptions!D28 | M10: =Assumptions!D26*Assumptions!D29 | N10: =Acquirer!G13+IF(ProForma!D6=1,Target!D32*Assumptions!D28,Target!G23)+L10+M10 | O10: =Acquirer!G17+G10 | P10: =(((Acquirer!G8+Target!G18+P$7*Synergies!G7-Synergies!G16)-Acquirer!G10-Target!G20-K10)-N10)*(1-Assumptions!D45)/O10/Acquirer!G18-1 | Q10: =(((Acquirer!G8+Target!G18+Q$7*Synergies!G7-Synergies!G16)-Acquirer!G10-Target!G20-K10)-N10)*(1-Assumptions!D45)/O10/Acquirer!G18-1 | R10: =(((Acquirer!G8+Target!G18+R$7*Synergies!G7-Synergies!G16)-Acquirer!G10-Target!G20-K10)-N10)*(1-Assumptions!D45)/O10/Acquirer!G18-1 | S10: =(((Acquirer!G8+Target!G18+S$7*Synergies!G7-Synergies!G16)-Acquirer!G10-Target!G20-K10)-N10)*(1-Assumptions!D45)/O10/Acquirer!G18-1 | T10: =(((Acquirer!G8+Target!G18+T$7*Synergies!G7-Synergies!G16)-Acquirer!G10-Target!G20-K10)-N10)*(1-Assumptions!D45)/O10/Acquirer!G18-1
B11: 0 | C11: =Assumptions!D6*(1+$B11) | D11: =C11*Assumptions!D9 | E11: =D11*Assumptions!D15 | F11: =D11*Assumptions!D16 | G11: =F11/Assumptions!D19 | H11: =(E11-Assumptions!D26)*(1+Assumptions!D32)+D11*Assumptions!D30 | I11: =D11-Assumptions!D38+Assumptions!D39 | J11: =I11*Assumptions!D40 | K11: =J11/Assumptions!D41 | L11: =H11*Assumptions!D28 | M11: =Assumptions!D26*Assumptions!D29 | N11: =Acquirer!G13+IF(ProForma!D6=1,Target!D32*Assumptions!D28,Target!G23)+L11+M11 | O11: =Acquirer!G17+G11 | P11: =(((Acquirer!G8+Target!G18+P$7*Synergies!G7-Synergies!G16)-Acquirer!G10-Target!G20-K11)-N11)*(1-Assumptions!D45)/O11/Acquirer!G18-1 | Q11: =(((Acquirer!G8+Target!G18+Q$7*Synergies!G7-Synergies!G16)-Acquirer!G10-Target!G20-K11)-N11)*(1-Assumptions!D45)/O11/Acquirer!G18-1 | R11: =(((Acquirer!G8+Target!G18+R$7*Synergies!G7-Synergies!G16)-Acquirer!G10-Target!G20-K11)-N11)*(1-Assumptions!D45)/O11/Acquirer!G18-1 | S11: =(((Acquirer!G8+Target!G18+S$7*Synergies!G7-Synergies!G16)-Acquirer!G10-Target!G20-K11)-N11)*(1-Assumptions!D45)/O11/Acquirer!G18-1 | T11: =(((Acquirer!G8+Target!G18+T$7*Synergies!G7-Synergies!G16)-Acquirer!G10-Target!G20-K11)-N11)*(1-Assumptions!D45)/O11/Acquirer!G18-1
B12: 0.0667 | C12: =Assumptions!D6*(1+$B12) | D12: =C12*Assumptions!D9 | E12: =D12*Assumptions!D15 | F12: =D12*Assumptions!D16 | G12: =F12/Assumptions!D19 | H12: =(E12-Assumptions!D26)*(1+Assumptions!D32)+D12*Assumptions!D30 | I12: =D12-Assumptions!D38+Assumptions!D39 | J12: =I12*Assumptions!D40 | K12: =J12/Assumptions!D41 | L12: =H12*Assumptions!D28 | M12: =Assumptions!D26*Assumptions!D29 | N12: =Acquirer!G13+IF(ProForma!D6=1,Target!D32*Assumptions!D28,Target!G23)+L12+M12 | O12: =Acquirer!G17+G12 | P12: =(((Acquirer!G8+Target!G18+P$7*Synergies!G7-Synergies!G16)-Acquirer!G10-Target!G20-K12)-N12)*(1-Assumptions!D45)/O12/Acquirer!G18-1 | Q12: =(((Acquirer!G8+Target!G18+Q$7*Synergies!G7-Synergies!G16)-Acquirer!G10-Target!G20-K12)-N12)*(1-Assumptions!D45)/O12/Acquirer!G18-1 | R12: =(((Acquirer!G8+Target!G18+R$7*Synergies!G7-Synergies!G16)-Acquirer!G10-Target!G20-K12)-N12)*(1-Assumptions!D45)/O12/Acquirer!G18-1 | S12: =(((Acquirer!G8+Target!G18+S$7*Synergies!G7-Synergies!G16)-Acquirer!G10-Target!G20-K12)-N12)*(1-Assumptions!D45)/O12/Acquirer!G18-1 | T12: =(((Acquirer!G8+Target!G18+T$7*Synergies!G7-Synergies!G16)-Acquirer!G10-Target!G20-K12)-N12)*(1-Assumptions!D45)/O12/Acquirer!G18-1
B13: 0.1333 | C13: =Assumptions!D6*(1+$B13) | D13: =C13*Assumptions!D9 | E13: =D13*Assumptions!D15 | F13: =D13*Assumptions!D16 | G13: =F13/Assumptions!D19 | H13: =(E13-Assumptions!D26)*(1+Assumptions!D32)+D13*Assumptions!D30 | I13: =D13-Assumptions!D38+Assumptions!D39 | J13: =I13*Assumptions!D40 | K13: =J13/Assumptions!D41 | L13: =H13*Assumptions!D28 | M13: =Assumptions!D26*Assumptions!D29 | N13: =Acquirer!G13+IF(ProForma!D6=1,Target!D32*Assumptions!D28,Target!G23)+L13+M13 | O13: =Acquirer!G17+G13 | P13: =(((Acquirer!G8+Target!G18+P$7*Synergies!G7-Synergies!G16)-Acquirer!G10-Target!G20-K13)-N13)*(1-Assumptions!D45)/O13/Acquirer!G18-1 | Q13: =(((Acquirer!G8+Target!G18+Q$7*Synergies!G7-Synergies!G16)-Acquirer!G10-Target!G20-K13)-N13)*(1-Assumptions!D45)/O13/Acquirer!G18-1 | R13: =(((Acquirer!G8+Target!G18+R$7*Synergies!G7-Synergies!G16)-Acquirer!G10-Target!G20-K13)-N13)*(1-Assumptions!D45)/O13/Acquirer!G18-1 | S13: =(((Acquirer!G8+Target!G18+S$7*Synergies!G7-Synergies!G16)-Acquirer!G10-Target!G20-K13)-N13)*(1-Assumptions!D45)/O13/Acquirer!G18-1 | T13: =(((Acquirer!G8+Target!G18+T$7*Synergies!G7-Synergies!G16)-Acquirer!G10-Target!G20-K13)-N13)*(1-Assumptions!D45)/O13/Acquirer!G18-1
B14: 0.2 | C14: =Assumptions!D6*(1+$B14) | D14: =C14*Assumptions!D9 | E14: =D14*Assumptions!D15 | F14: =D14*Assumptions!D16 | G14: =F14/Assumptions!D19 | H14: =(E14-Assumptions!D26)*(1+Assumptions!D32)+D14*Assumptions!D30 | I14: =D14-Assumptions!D38+Assumptions!D39 | J14: =I14*Assumptions!D40 | K14: =J14/Assumptions!D41 | L14: =H14*Assumptions!D28 | M14: =Assumptions!D26*Assumptions!D29 | N14: =Acquirer!G13+IF(ProForma!D6=1,Target!D32*Assumptions!D28,Target!G23)+L14+M14 | O14: =Acquirer!G17+G14 | P14: =(((Acquirer!G8+Target!G18+P$7*Synergies!G7-Synergies!G16)-Acquirer!G10-Target!G20-K14)-N14)*(1-Assumptions!D45)/O14/Acquirer!G18-1 | Q14: =(((Acquirer!G8+Target!G18+Q$7*Synergies!G7-Synergies!G16)-Acquirer!G10-Target!G20-K14)-N14)*(1-Assumptions!D45)/O14/Acquirer!G18-1 | R14: =(((Acquirer!G8+Target!G18+R$7*Synergies!G7-Synergies!G16)-Acquirer!G10-Target!G20-K14)-N14)*(1-Assumptions!D45)/O14/Acquirer!G18-1 | S14: =(((Acquirer!G8+Target!G18+S$7*Synergies!G7-Synergies!G16)-Acquirer!G10-Target!G20-K14)-N14)*(1-Assumptions!D45)/O14/Acquirer!G18-1 | T14: =(((Acquirer!G8+Target!G18+T$7*Synergies!G7-Synergies!G16)-Acquirer!G10-Target!G20-K14)-N14)*(1-Assumptions!D45)/O14/Acquirer!G18-1
B17: Grid 2 - % Cash Consideration (offer price fixed at $38.00) x Run-Rate Cost Synergies -> FY2019E Accretion/(Dilution) %
B18: Corner (check, ties to ProForma FY2019E) | C18: =ROUND(M22-ProForma!G25,4)
B19: % Cash consideration (rows) \ Synergies (cols) | C19: Cash consid. | D19: Stock consid. | E19: New shares | F19: Total new debt | G19: New-debt interest | H19: Foregone interest | I19: Interest, total | J19: PF shares, total | K19: 0 | L19: 1000 | M19: 2000 | N19: 3000 | O19: 4000
B20: 0 | C20: =Assumptions!D10*$B20 | D20: =Assumptions!D10*(1-$B20) | E20: =D20/Assumptions!D19 | F20: =(C20-Assumptions!D26)*(1+Assumptions!D32)+Assumptions!D10*Assumptions!D30 | G20: =F20*Assumptions!D28 | H20: =Assumptions!D26*Assumptions!D29 | I20: =Acquirer!G13+IF(ProForma!D6=1,Target!D32*Assumptions!D28,Target!G23)+G20+H20 | J20: =Acquirer!G17+E20 | K20: =(((Acquirer!G8+Target!G18+K$19*Synergies!G7-Synergies!G16)-Acquirer!G10-Target!G20-'PPA-Financing'!D34)-I20)*(1-Assumptions!D45)/J20/Acquirer!G18-1 | L20: =(((Acquirer!G8+Target!G18+L$19*Synergies!G7-Synergies!G16)-Acquirer!G10-Target!G20-'PPA-Financing'!D34)-I20)*(1-Assumptions!D45)/J20/Acquirer!G18-1 | M20: =(((Acquirer!G8+Target!G18+M$19*Synergies!G7-Synergies!G16)-Acquirer!G10-Target!G20-'PPA-Financing'!D34)-I20)*(1-Assumptions!D45)/J20/Acquirer!G18-1 | N20: =(((Acquirer!G8+Target!G18+N$19*Synergies!G7-Synergies!G16)-Acquirer!G10-Target!G20-'PPA-Financing'!D34)-I20)*(1-Assumptions!D45)/J20/Acquirer!G18-1 | O20: =(((Acquirer!G8+Target!G18+O$19*Synergies!G7-Synergies!G16)-Acquirer!G10-Target!G20-'PPA-Financing'!D34)-I20)*(1-Assumptions!D45)/J20/Acquirer!G18-1
B21: 0.25 | C21: =Assumptions!D10*$B21 | D21: =Assumptions!D10*(1-$B21) | E21: =D21/Assumptions!D19 | F21: =(C21-Assumptions!D26)*(1+Assumptions!D32)+Assumptions!D10*Assumptions!D30 | G21: =F21*Assumptions!D28 | H21: =Assumptions!D26*Assumptions!D29 | I21: =Acquirer!G13+IF(ProForma!D6=1,Target!D32*Assumptions!D28,Target!G23)+G21+H21 | J21: =Acquirer!G17+E21 | K21: =(((Acquirer!G8+Target!G18+K$19*Synergies!G7-Synergies!G16)-Acquirer!G10-Target!G20-'PPA-Financing'!D34)-I21)*(1-Assumptions!D45)/J21/Acquirer!G18-1 | L21: =(((Acquirer!G8+Target!G18+L$19*Synergies!G7-Synergies!G16)-Acquirer!G10-Target!G20-'PPA-Financing'!D34)-I21)*(1-Assumptions!D45)/J21/Acquirer!G18-1 | M21: =(((Acquirer!G8+Target!G18+M$19*Synergies!G7-Synergies!G16)-Acquirer!G10-Target!G20-'PPA-Financing'!D34)-I21)*(1-Assumptions!D45)/J21/Acquirer!G18-1 | N21: =(((Acquirer!G8+Target!G18+N$19*Synergies!G7-Synergies!G16)-Acquirer!G10-Target!G20-'PPA-Financing'!D34)-I21)*(1-Assumptions!D45)/J21/Acquirer!G18-1 | O21: =(((Acquirer!G8+Target!G18+O$19*Synergies!G7-Synergies!G16)-Acquirer!G10-Target!G20-'PPA-Financing'!D34)-I21)*(1-Assumptions!D45)/J21/Acquirer!G18-1
B22: 0.5 | C22: =Assumptions!D10*$B22 | D22: =Assumptions!D10*(1-$B22) | E22: =D22/Assumptions!D19 | F22: =(C22-Assumptions!D26)*(1+Assumptions!D32)+Assumptions!D10*Assumptions!D30 | G22: =F22*Assumptions!D28 | H22: =Assumptions!D26*Assumptions!D29 | I22: =Acquirer!G13+IF(ProForma!D6=1,Target!D32*Assumptions!D28,Target!G23)+G22+H22 | J22: =Acquirer!G17+E22 | K22: =(((Acquirer!G8+Target!G18+K$19*Synergies!G7-Synergies!G16)-Acquirer!G10-Target!G20-'PPA-Financing'!D34)-I22)*(1-Assumptions!D45)/J22/Acquirer!G18-1 | L22: =(((Acquirer!G8+Target!G18+L$19*Synergies!G7-Synergies!G16)-Acquirer!G10-Target!G20-'PPA-Financing'!D34)-I22)*(1-Assumptions!D45)/J22/Acquirer!G18-1 | M22: =(((Acquirer!G8+Target!G18+M$19*Synergies!G7-Synergies!G16)-Acquirer!G10-Target!G20-'PPA-Financing'!D34)-I22)*(1-Assumptions!D45)/J22/Acquirer!G18-1 | N22: =(((Acquirer!G8+Target!G18+N$19*Synergies!G7-Synergies!G16)-Acquirer!G10-Target!G20-'PPA-Financing'!D34)-I22)*(1-Assumptions!D45)/J22/Acquirer!G18-1 | O22: =(((Acquirer!G8+Target!G18+O$19*Synergies!G7-Synergies!G16)-Acquirer!G10-Target!G20-'PPA-Financing'!D34)-I22)*(1-Assumptions!D45)/J22/Acquirer!G18-1
B23: 0.75 | C23: =Assumptions!D10*$B23 | D23: =Assumptions!D10*(1-$B23) | E23: =D23/Assumptions!D19 | F23: =(C23-Assumptions!D26)*(1+Assumptions!D32)+Assumptions!D10*Assumptions!D30 | G23: =F23*Assumptions!D28 | H23: =Assumptions!D26*Assumptions!D29 | I23: =Acquirer!G13+IF(ProForma!D6=1,Target!D32*Assumptions!D28,Target!G23)+G23+H23 | J23: =Acquirer!G17+E23 | K23: =(((Acquirer!G8+Target!G18+K$19*Synergies!G7-Synergies!G16)-Acquirer!G10-Target!G20-'PPA-Financing'!D34)-I23)*(1-Assumptions!D45)/J23/Acquirer!G18-1 | L23: =(((Acquirer!G8+Target!G18+L$19*Synergies!G7-Synergies!G16)-Acquirer!G10-Target!G20-'PPA-Financing'!D34)-I23)*(1-Assumptions!D45)/J23/Acquirer!G18-1 | M23: =(((Acquirer!G8+Target!G18+M$19*Synergies!G7-Synergies!G16)-Acquirer!G10-Target!G20-'PPA-Financing'!D34)-I23)*(1-Assumptions!D45)/J23/Acquirer!G18-1 | N23: =(((Acquirer!G8+Target!G18+N$19*Synergies!G7-Synergies!G16)-Acquirer!G10-Target!G20-'PPA-Financing'!D34)-I23)*(1-Assumptions!D45)/J23/Acquirer!G18-1 | O23: =(((Acquirer!G8+Target!G18+O$19*Synergies!G7-Synergies!G16)-Acquirer!G10-Target!G20-'PPA-Financing'!D34)-I23)*(1-Assumptions!D45)/J23/Acquirer!G18-1
B24: 1 | C24: =Assumptions!D10*$B24 | D24: =Assumptions!D10*(1-$B24) | E24: =D24/Assumptions!D19 | F24: =(C24-Assumptions!D26)*(1+Assumptions!D32)+Assumptions!D10*Assumptions!D30 | G24: =F24*Assumptions!D28 | H24: =Assumptions!D26*Assumptions!D29 | I24: =Acquirer!G13+IF(ProForma!D6=1,Target!D32*Assumptions!D28,Target!G23)+G24+H24 | J24: =Acquirer!G17+E24 | K24: =(((Acquirer!G8+Target!G18+K$19*Synergies!G7-Synergies!G16)-Acquirer!G10-Target!G20-'PPA-Financing'!D34)-I24)*(1-Assumptions!D45)/J24/Acquirer!G18-1 | L24: =(((Acquirer!G8+Target!G18+L$19*Synergies!G7-Synergies!G16)-Acquirer!G10-Target!G20-'PPA-Financing'!D34)-I24)*(1-Assumptions!D45)/J24/Acquirer!G18-1 | M24: =(((Acquirer!G8+Target!G18+M$19*Synergies!G7-Synergies!G16)-Acquirer!G10-Target!G20-'PPA-Financing'!D34)-I24)*(1-Assumptions!D45)/J24/Acquirer!G18-1 | N24: =(((Acquirer!G8+Target!G18+N$19*Synergies!G7-Synergies!G16)-Acquirer!G10-Target!G20-'PPA-Financing'!D34)-I24)*(1-Assumptions!D45)/J24/Acquirer!G18-1 | O24: =(((Acquirer!G8+Target!G18+O$19*Synergies!G7-Synergies!G16)-Acquirer!G10-Target!G20-'PPA-Financing'!D34)-I24)*(1-Assumptions!D45)/J24/Acquirer!G18-1
B27: Architecture note: each grid cell algebraically rebuilds FY2019E pro forma EPS from the operating model's fixed FY2019E EBITDA/D&A/interest building blocks plus the row/column shocked inputs (offer price or cash %, and run-rate synergies) - fully live, no Excel Data Tables. Grid 1 re-derives goodwill/intangible step-up and its amortization per row since offer price changes purchase price; Grid 2 holds the PPA constant (fixed at base offer price) and only re-derives the cash/stock/debt/share-count split, per the master-spec architecture.
