Workbook

Sheet Inputs
C3: Case # | D3: =DCF!D5 -> 1
C4: Associated Case | D4: =DCF!D6 -> Base | E4: numbers in millions except per share data
C6: Selected: Base Case | D6: 2021 | E6: 2022 | F6: 2023 | I6: 2024 | J6: 2025 | K6: 2026 | L6: 2027 | M6: 2028
C8: Revenue Growth | D8: =CHOOSE($D$3,D24,D40,D55) -> n.a. | E8: =CHOOSE($D$3,E24,E40,E55) -> 0.18155971 | F8: =CHOOSE($D$3,F24,F40,F55) -> 0.12189756 | G8: =CHOOSE($D$3,G24,G40,G55) -> 0 | H8: =CHOOSE($D$3,H24,H40,H55) -> 0 | I8: =CHOOSE($D$3,I24,I40,I55) -> 0.1 | J8: =CHOOSE($D$3,J24,J40,J55) -> 0.1 | K8: =CHOOSE($D$3,K24,K40,K55) -> 0.1 | ... M8: =CHOOSE($D$3,M24,M40,M55) -> 0.1
C9: Cost of Revenue as a % of Revenue | D9: =CHOOSE($D$3,D25,D41,D56) -> 0.617 | E9: =CHOOSE($D$3,E25,E41,E56) -> 0.623 | F9: =CHOOSE($D$3,F25,F41,F56) -> 0.589 | G9: =CHOOSE($D$3,G25,G41,G56) -> 0 | H9: =CHOOSE($D$3,H25,H41,H56) -> 0 | I9: =CHOOSE($D$3,I25,I41,I56) -> 0.612 | J9: =CHOOSE($D$3,J25,J41,J56) -> 0.612 | K9: =CHOOSE($D$3,K25,K41,K56) -> 0.612 | ... M9: =CHOOSE($D$3,M25,M41,M56) -> 0.612
C10: SG&A Expenses as a % of Revenue | D10: =CHOOSE($D$3,D26,D42,D57) -> 0.209339 | E10: =CHOOSE($D$3,E26,E42,E57) -> 0.204847 | F10: =CHOOSE($D$3,F26,F42,F57) -> 0.218481 | G10: =CHOOSE($D$3,G26,G42,G57) -> 0 | H10: =CHOOSE($D$3,H26,H42,H57) -> 0 | I10: =CHOOSE($D$3,I26,I42,I57) -> 0.21 | J10: =CHOOSE($D$3,J26,J42,J57) -> 0.21 | K10: =CHOOSE($D$3,K26,K42,K57) -> 0.21 | ... M10: =CHOOSE($D$3,M26,M42,M57) -> 0.21
C11: R&D Expenses as a % of Revenue | D11: =CHOOSE($D$3,D27,D43,D58) -> 0.01974 | E11: =CHOOSE($D$3,E27,E43,E58) -> 0.031931095 | F11: =CHOOSE($D$3,F27,F43,F58) -> 0.031183341 | G11: =CHOOSE($D$3,G27,G43,G58) -> 0 | H11: =CHOOSE($D$3,H27,H43,H58) -> 0 | I11: =CHOOSE($D$3,I27,I43,I58) -> 0.0279 | J11: =CHOOSE($D$3,J27,J43,J58) -> 0.0279 | K11: =CHOOSE($D$3,K27,K43,K58) -> 0.0279 | ... M11: =CHOOSE($D$3,M27,M43,M58) -> 0.0279
C12: Other OpEx as a % of Revenue | D12: =CHOOSE($D$3,D28,D44,D59) -> 0.010481443 | E12: =CHOOSE($D$3,E28,E44,E59) -> 0.020763 | F12: =CHOOSE($D$3,F28,F44,F59) -> 0.021908 | G12: =CHOOSE($D$3,G28,G44,G59) -> 0 | H12: =CHOOSE($D$3,H28,H44,H59) -> 0 | I12: =CHOOSE($D$3,I28,I44,I59) -> 0.017704481 | J12: =CHOOSE($D$3,J28,J44,J59) -> 0.017704481 | K12: =CHOOSE($D$3,K28,K44,K59) -> 0.017704481 | ... M12: =CHOOSE($D$3,M28,M44,M59) -> 0.017704481
C13: Implied Tax Rate | D13: =CHOOSE($D$3,D29,D45,D60) -> 0.149049 | E13: =CHOOSE($D$3,E29,E45,E60) -> 0.154041 | F13: =CHOOSE($D$3,F29,F45,F60) -> 0.135 | G13: =CHOOSE($D$3,G29,G45,G60) -> 0 | H13: =CHOOSE($D$3,H29,H45,H60) -> 0 | I13: =CHOOSE($D$3,I29,I45,I60) -> 0.14600158 | J13: =CHOOSE($D$3,J29,J45,J60) -> 0.14600158 | K13: =CHOOSE($D$3,K29,K45,K60) -> 0.14600158 | ... M13: =CHOOSE($D$3,M29,M45,M60) -> 0.14600158
C14: D&A as a % of Revenue | D14: =CHOOSE($D$3,D30,D46,D61) -> 0.044039 | E14: =CHOOSE($D$3,E30,E46,E61) -> 0.039262 | F14: =CHOOSE($D$3,F30,F46,F61) -> 0.043331 | G14: =CHOOSE($D$3,G30,G46,G61) -> 0 | H14: =CHOOSE($D$3,H30,H46,H61) -> 0 | I14: =CHOOSE($D$3,I30,I46,I61) -> 0.042208539 | J14: =CHOOSE($D$3,J30,J46,J61) -> 0.042208539 | K14: =CHOOSE($D$3,K30,K46,K61) -> 0.042208539 | ... M14: =CHOOSE($D$3,M30,M46,M61) -> 0.042208539
C15: CAPEX as a % of Revenue | D15: =CHOOSE($D$3,D31,D47,D62) -> 0.016045 | E15: =CHOOSE($D$3,E31,E47,E62) -> 0.015777 | F15: =CHOOSE($D$3,F31,F47,F62) -> 0.021759 | G15: =CHOOSE($D$3,G31,G47,G62) -> 0 | H15: =CHOOSE($D$3,H31,H47,H62) -> 0 | I15: =CHOOSE($D$3,I31,I47,I62) -> 0.017856599 | J15: =CHOOSE($D$3,J31,J47,J62) -> 0.017856599 | K15: =CHOOSE($D$3,K31,K47,K62) -> 0.017856599 | ... M15: =CHOOSE($D$3,M31,M47,M62) -> 0.017856599
C16: Net Working as a % of Revenue | D16: =CHOOSE($D$3,D32,D48,D63) -> 0 | E16: =CHOOSE($D$3,E32,E48,E63) -> 0.199271 | F16: =CHOOSE($D$3,F32,F48,F63) -> 0.184674 | G16: =CHOOSE($D$3,G32,G48,G63) -> 0 | H16: =CHOOSE($D$3,H32,H48,H63) -> 0 | I16: =CHOOSE($D$3,I32,I48,I63) -> 0.12418744 | J16: =CHOOSE($D$3,J32,J48,J63) -> 0.12418744 | K16: =CHOOSE($D$3,K32,K48,K63) -> 0.12418744 | ... M16: =CHOOSE($D$3,M32,M48,M63) -> 0.12418744
C17: Debt growth rate | D17: =CHOOSE($D$3,D33,D49,D64) -> 0 | E17: =CHOOSE($D$3,E33,E49,E64) -> 0.083292 | F17: =CHOOSE($D$3,F33,F49,F64) -> 0.64368 | G17: =CHOOSE($D$3,G33,G49,G64) -> 0 | H17: =CHOOSE($D$3,H33,H49,H64) -> 0 | I17: =CHOOSE($D$3,I33,I49,I64) -> 0.21205112 | J17: =CHOOSE($D$3,J33,J49,J64) -> 0.21205112 | K17: =CHOOSE($D$3,K33,K49,K64) -> 0.21205112 | ... M17: =CHOOSE($D$3,M33,M49,M64) -> 0.21205112
C18: Interest Expense as a % of Debt | D18: =CHOOSE($D$3,D34,D50,D65) -> 0 | E18: =CHOOSE($D$3,E34,E50,E65) -> 0.028808 | F18: =CHOOSE($D$3,F34,F50,F65) -> 0.044587 | G18: =CHOOSE($D$3,G34,G50,G65) -> 0 | H18: =CHOOSE($D$3,H34,H50,H65) -> 0 | I18: =CHOOSE($D$3,I34,I50,I65) -> 0.02429798 | J18: =CHOOSE($D$3,J34,J50,J65) -> 0.02429798 | K18: =CHOOSE($D$3,K34,K50,K65) -> 0.02429798 | ... M18: =CHOOSE($D$3,M34,M50,M65) -> 0.02429798 | N18: 0
C19: Debt to EBITDA | D19: =CHOOSE($D$3,D35,D51,D66) -> 0 | E19: =CHOOSE($D$3,E35,E51,E66) -> 1.9528 | F19: =CHOOSE($D$3,F35,F51,F66) -> 2.4436 | G19: =CHOOSE($D$3,G35,G51,G66) -> 0 | H19: =CHOOSE($D$3,H35,H51,H66) -> 0 | I19: =CHOOSE($D$3,I35,I51,I66) -> 2.1887712 | J19: =CHOOSE($D$3,J35,J51,J66) -> 2.1887712 | K19: =CHOOSE($D$3,K35,K51,K66) -> 2.1887712 | ... M19: =CHOOSE($D$3,M35,M51,M66) -> 2.1887712
C22: Base Case | D22: 2021 | E22: 2022 | F22: 2023 | I22: 2024 | J22: 2025 | K22: 2026 | L22: 2027 | M22: 2028
O23: calculated geo mean growth for these numbers then forecasted out at the average for the rest 5 years
C24: Revenue Growth | D24: n.a. | E24: =Revenue!E18 -> 0.18155971 | F24: =Revenue!F18 -> 0.12189756 | I24: =Revenue!I22 -> 0.1 | J24: =Revenue!J22 -> 0.1 | K24: =Revenue!K22 -> 0.1 | L24: =Revenue!L22 -> 0.1 | M24: =Revenue!M22 -> 0.1
C25: Cost of Revenue as a % of Revenue | D25: 0.617 | E25: 0.623 | F25: 0.589 | I25: 0.612 | J25: 0.612 | K25: 0.612 | L25: 0.612 | M25: 0.612
C26: SG&A Expenses as a % of Revenue | D26: 0.209339 | E26: 0.204847 | F26: 0.218481 | I26: 0.21 | J26: 0.21 | K26: 0.21 | L26: 0.21 | M26: 0.21
C27: R&D Expenses as a % of Revenue | D27: 0.01974 | E27: 0.031931095 | F27: 0.031183341 | I27: 0.0279 | J27: 0.0279 | K27: 0.0279 | L27: 0.0279 | M27: 0.0279
C28: Other OpEx as a % of Revenue | D28: 0.010481443 | E28: 0.020763 | F28: 0.021908 | I28: {=GEOMEAN(1 + D28:F28) - 1} -> 0.017704481 | J28: =I28 -> 0.017704481 | K28: =J28 -> 0.017704481 | L28: =K28 -> 0.017704481 | M28: =L28 -> 0.017704481
C29: Implied Tax Rate | D29: 0.149049 | E29: 0.154041 | F29: 0.135 | I29: {=GEOMEAN(1 + D29:F29) - 1} -> 0.14600158 | J29: =I29 -> 0.14600158 | K29: =J29 -> 0.14600158 | L29: =K29 -> 0.14600158 | M29: =L29 -> 0.14600158
C30: D&A as a % of Revenue | D30: 0.044039 | E30: 0.039262 | F30: 0.043331 | I30: {=GEOMEAN(1 + D30:F30) - 1} -> 0.042208539 | J30: =I30 -> 0.042208539 | K30: =J30 -> 0.042208539 | L30: =K30 -> 0.042208539 | M30: =L30 -> 0.042208539
C31: CAPEX as a % of Revenue | D31: 0.016045 | E31: 0.015777 | F31: 0.021759 | I31: {=GEOMEAN(1 + D31:F31) - 1} -> 0.017856599 | J31: =I31 -> 0.017856599 | K31: =J31 -> 0.017856599 | L31: =K31 -> 0.017856599 | M31: =L31 -> 0.017856599
C32: Net Working as a % of Revenue | E32: 0.199271 | F32: 0.184674 | I32: {=GEOMEAN(1 + D32:F32) - 1} -> 0.12418744 | J32: =I32 -> 0.12418744 | K32: =J32 -> 0.12418744 | L32: =K32 -> 0.12418744 | M32: =L32 -> 0.12418744
C33: Debt growth rate | E33: 0.083292 | F33: 0.64368 | I33: {=GEOMEAN(1 + D33:F33) - 1} -> 0.21205112 | J33: =I33 -> 0.21205112 | K33: =J33 -> 0.21205112 | L33: =K33 -> 0.21205112 | M33: =L33 -> 0.21205112
C34: Interest Expense as a % of Debt | E34: 0.028808 | F34: 0.044587 | I34: {=GEOMEAN(1 + D34:F34) - 1} -> 0.02429798 | J34: =I34 -> 0.02429798 | K34: =J34 -> 0.02429798 | L34: =K34 -> 0.02429798 | M34: =L34 -> 0.02429798
C35: Debt to EBITDA | E35: 1.9528 | F35: 2.4436 | I35: {=GEOMEAN(1 + E35:F35) - 1} -> 2.1887712 | J35: =I35 -> 2.1887712 | K35: =J35 -> 2.1887712 | L35: =K35 -> 2.1887712 | M35: =L35 -> 2.1887712
C38: Bull Case | D38: 2021 | E38: 2022 | F38: 2023 | I38: 2024 | J38: 2025 | K38: 2026 | L38: 2027 | M38: 2028 | O38: Bull and bear case are manually inputted numbers 7.5% up or 7.5% down from base case besides revenue
C40: Revenue Growth | D40: =D24 -> n.a. | E40: =E24 -> 0.18155971 | F40: =F24 -> 0.12189756 | I40: =Revenue!I31 -> 0.15 | J40: =Revenue!J31 -> 0.15 | K40: =Revenue!K31 -> 0.15 | L40: =Revenue!L31 -> 0.15 | M40: =Revenue!M31 -> 0.15
C41: Cost of Revenue as a % of Revenue | D41: =D25 -> 0.617 | E41: =E25 -> 0.623 | F41: =F25 -> 0.589 | I41: =I25*1.05 -> 0.6426 | J41: =I41 -> 0.6426 | K41: =J41 -> 0.6426 | L41: =K41 -> 0.6426 | M41: =L41 -> 0.6426
C42: SG&A Expenses as a % of Revenue | D42: =D26 -> 0.209339 | E42: =E26 -> 0.204847 | F42: =F26 -> 0.218481 | I42: =I26*1.05 -> 0.2205 | J42: =I42 -> 0.2205 | K42: =J42 -> 0.2205 | L42: =K42 -> 0.2205 | M42: =L42 -> 0.2205
C43: R&D Expenses as a % of Revenue | D43: =D27 -> 0.01974 | E43: =E27 -> 0.031931095 | F43: =F27 -> 0.031183341 | I43: =I27*1.05 -> 0.029295 | J43: =I43 -> 0.029295 | K43: =J43 -> 0.029295 | L43: =K43 -> 0.029295 | M43: =L43 -> 0.029295
C44: Other OpEx as a % of Revenue | D44: =D28 -> 0.010481443 | E44: =E28 -> 0.020763 | F44: =F28 -> 0.021908 | I44: =I28*1.05 -> 0.018589706 | J44: =I44 -> 0.018589706 | K44: =J44 -> 0.018589706 | L44: =K44 -> 0.018589706 | M44: =L44 -> 0.018589706
C45: Implied Tax Rate | D45: =D29 -> 0.149049 | E45: =E29 -> 0.154041 | F45: =F29 -> 0.135 | I45: =I29*1.05 -> 0.15330166 | J45: =I45 -> 0.15330166 | K45: =J45 -> 0.15330166 | L45: =K45 -> 0.15330166 | M45: =L45 -> 0.15330166
C46: D&A as a % of Revenue | D46: =D30 -> 0.044039 | E46: =E30 -> 0.039262 | F46: =F30 -> 0.043331 | I46: =I30*1.05 -> 0.044318966 | J46: =I46 -> 0.044318966 | K46: =J46 -> 0.044318966 | L46: =K46 -> 0.044318966 | M46: =L46 -> 0.044318966
C47: CAPEX as a % of Revenue | D47: =D31 -> 0.016045 | E47: =E31 -> 0.015777 | F47: =F31 -> 0.021759 | I47: =I31*1.05 -> 0.018749429 | J47: =I47 -> 0.018749429 | K47: =J47 -> 0.018749429 | L47: =K47 -> 0.018749429 | M47: =L47 -> 0.018749429
C48: Net Working as a % of Revenue | D48: =D32 -> 0 | E48: =E32 -> 0.199271 | F48: =F32 -> 0.184674 | I48: =I32*1.05 -> 0.13039681 | J48: =I48 -> 0.13039681 | K48: =J48 -> 0.13039681 | L48: =K48 -> 0.13039681 | M48: =L48 -> 0.13039681
C49: Debt growth rate | D49: =D33 -> 0 | E49: =E33 -> 0.083292 | F49: =F33 -> 0.64368 | I49: =I33*1.05 -> 0.22265367 | J49: =I49 -> 0.22265367 | K49: =J49 -> 0.22265367 | L49: =K49 -> 0.22265367 | M49: =L49 -> 0.22265367
...

Sheet Revenue
C3: Case # | D3: =DCF!D5 -> 1 | E3: numbers in millions except per share data
C4: Associated Case | D4: =DCF!D6 -> Base
C6: Selected: Base Case | D6: 2021 | E6: 2022 | F6: 2023 | I6: 2024 | J6: 2025 | K6: 2026 | L6: 2027 | M6: 2028
C8: Product A | D8: =CHOOSE($D$3,D17,D26,D35) -> 2462 | E8: =CHOOSE($D$3,E17,E26,E35) -> 2909 | F8: =CHOOSE($D$3,F17,F26,F35) -> 3263.6 | G8: =CHOOSE($D$3,G17,G26,G35) -> 0 | H8: =CHOOSE($D$3,H17,H26,H35) -> 0 | I8: =CHOOSE($D$3,I17,I26,I35) -> 3589.96 | J8: =CHOOSE($D$3,J17,J26,J35) -> 3948.956 | K8: =CHOOSE($D$3,K17,K26,K35) -> 4343.8516 | ... M8: =CHOOSE($D$3,M17,M26,M35) -> 5256.0604
C9: % Growth | E9: =CHOOSE($D$3,E18,E27,E36) -> 0.18155971 | F9: =CHOOSE($D$3,F18,F27,F36) -> 0.12189756 | G9: =CHOOSE($D$3,G18,G27,G36) -> 0 | H9: =CHOOSE($D$3,H18,H27,H36) -> 0 | I9: =CHOOSE($D$3,I18,I27,I36) -> 0.1 | J9: =CHOOSE($D$3,J18,J27,J36) -> 0.1 | K9: =CHOOSE($D$3,K18,K27,K36) -> 0.1 | L9: =CHOOSE($D$3,L18,L27,L36) -> 0.1 | M9: =CHOOSE($D$3,M18,M27,M36) -> 0.1
C10: Product B IGNORE, THERE IS NO PRODUCT B | D10: =CHOOSE($D$3,D19,D28,D37) -> 0 | E10: =CHOOSE($D$3,E19,E28,E37) -> 0 | F10: =CHOOSE($D$3,F19,F28,F37) -> 0 | G10: =CHOOSE($D$3,G19,G28,G37) -> 0 | H10: =CHOOSE($D$3,H19,H28,H37) -> 0 | I10: =CHOOSE($D$3,I19,I28,I37) -> 0 | J10: =CHOOSE($D$3,J19,J28,J37) -> 0 | K10: =CHOOSE($D$3,K19,K28,K37) -> 0 | ... M10: =CHOOSE($D$3,M19,M28,M37) -> 0
C11: % Growth | E11: =CHOOSE($D$3,E20,E29,E38) -> 0 | F11: =CHOOSE($D$3,F20,F29,F38) -> 0 | G11: =CHOOSE($D$3,G20,G29,G38) -> 0 | H11: =CHOOSE($D$3,H20,H29,H38) -> 0 | I11: =CHOOSE($D$3,I20,I29,I38) -> 0 | J11: =CHOOSE($D$3,J20,J29,J38) -> 0 | K11: =CHOOSE($D$3,K20,K29,K38) -> 0 | L11: =CHOOSE($D$3,L20,L29,L38) -> 0 | M11: =CHOOSE($D$3,M20,M29,M38) -> 0
C12: Consolidated Sales | D12: =CHOOSE($D$3,D21,D30,D39) -> 2462 | E12: =CHOOSE($D$3,E21,E30,E39) -> 2909 | F12: =CHOOSE($D$3,F21,F30,F39) -> 3263.6 | G12: =CHOOSE($D$3,G21,G30,G39) -> 0 | H12: =CHOOSE($D$3,H21,H30,H39) -> 0 | I12: =CHOOSE($D$3,I21,I30,I39) -> 3589.96 | J12: =CHOOSE($D$3,J21,J30,J39) -> 3948.956 | K12: =CHOOSE($D$3,K21,K30,K39) -> 4343.8516 | ... M12: =CHOOSE($D$3,M21,M30,M39) -> 5256.0604
C13: % Growth | E13: =CHOOSE($D$3,E22,E31,E40) -> 0.18155971 | F13: =CHOOSE($D$3,F22,F31,F40) -> 0.12189756 | G13: =CHOOSE($D$3,G22,G31,G40) -> 0 | H13: =CHOOSE($D$3,H22,H31,H40) -> 0 | I13: =CHOOSE($D$3,I22,I31,I40) -> 0.1 | J13: =CHOOSE($D$3,J22,J31,J40) -> 0.1 | K13: =CHOOSE($D$3,K22,K31,K40) -> 0.1 | L13: =CHOOSE($D$3,L22,L31,L40) -> 0.1 | M13: =CHOOSE($D$3,M22,M31,M40) -> 0.1
C15: Base Case | D15: 2021 | E15: 2022 | F15: 2023 | I15: 2024 | J15: 2025 | K15: 2026 | L15: 2027 | M15: 2028
C17: Product A | D17: 2462 | E17: 2909 | F17: 3263.6 | I17: =F17*(1+I18) -> 3589.96 | J17: =I17*(1+J18) -> 3948.956 | K17: =J17*(1+K18) -> 4343.8516 | L17: =K17*(1+L18) -> 4778.2368 | M17: =L17*(1+M18) -> 5256.0604
C18: % Growth | E18: =E17/D17-1 -> 0.18155971 | F18: =F17/E17-1 -> 0.12189756 | I18: 0.1 | J18: 0.1 | K18: 0.1 | L18: 0.1 | M18: 0.1 | N18: 0.03 | O18: Input assumptions here!
C19: Product B | I19: =H19*(1+I20) -> 0 | J19: =I19*(1+J20) -> 0 | K19: =J19*(1+K20) -> 0 | L19: =K19*(1+L20) -> 0 | M19: =L19*(1+M20) -> 0
C20: % Growth | I20: 0 | J20: 0 | K20: 0 | L20: 0 | M20: 0 | N20: 0 | O20: Input assumptions here!
C21: Consolidated Sales | D21: =D17+D19 -> 2462 | E21: =E17+E19 -> 2909 | F21: =F17+F19 -> 3263.6 | G21: =G17+G19 -> 0 | H21: =H17+H19 -> 0 | I21: =I17+I19 -> 3589.96 | J21: =J17+J19 -> 3948.956 | K21: =K17+K19 -> 4343.8516 | ... M21: =M17+M19 -> 5256.0604
C22: % Growth | E22: =E21/D21-1 -> 0.18155971 | F22: =F21/E21-1 -> 0.12189756 | I22: =I21/F21-1 -> 0.1 | J22: =J21/I21-1 -> 0.1 | K22: =K21/J21-1 -> 0.1 | L22: =L21/K21-1 -> 0.1 | M22: =M21/L21-1 -> 0.1
C24: Bull Case | D24: 2021 | E24: 2022 | F24: 2023 | I24: 2024 | J24: 2025 | K24: 2026 | L24: 2027 | M24: 2028
C26: Product A | D26: 2462 | E26: 2909 | F26: 3263.6 | I26: =F26*(1+I27) -> 3753.14 | J26: =I26*(1+J27) -> 4316.111 | K26: =J26*(1+K27) -> 4963.5276 | L26: =K26*(1+L27) -> 5708.0568 | M26: =L26*(1+M27) -> 6564.2653
C27: % Growth | E27: =E26/D26-1 -> 0.18155971 | F27: =F26/E26-1 -> 0.12189756 | I27: 0.15 | J27: 0.15 | K27: 0.15 | L27: 0.15 | M27: 0.15 | O27: Input your assumptions here!
C28: Product B | I28: =H28*(1+I29) -> 0 | J28: =I28*(1+J29) -> 0 | K28: =J28*(1+K29) -> 0 | L28: =K28*(1+L29) -> 0 | M28: =L28*(1+M29) -> 0
C29: % Growth | O29: Input your assumptions here!
C30: Consolidated Sales | D30: =D26+D28 -> 2462 | E30: =E26+E28 -> 2909 | F30: =F26+F28 -> 3263.6 | G30: =G26+G28 -> 0 | H30: =H26+H28 -> 0 | I30: =I26+I28 -> 3753.14 | J30: =J26+J28 -> 4316.111 | K30: =K26+K28 -> 4963.5276 | ... M30: =M26+M28 -> 6564.2653
C31: % Growth | E31: =E30/D30-1 -> 0.18155971 | F31: =F30/E30-1 -> 0.12189756 | I31: =I30/F30-1 -> 0.15 | J31: =J30/I30-1 -> 0.15 | K31: =K30/J30-1 -> 0.15 | L31: =L30/K30-1 -> 0.15 | M31: =M30/L30-1 -> 0.15
C33: Bear Case | D33: 2021 | E33: 2022 | F33: 2023 | I33: 2024 | J33: 2025 | K33: 2026 | L33: 2027 | M33: 2028
C35: Product A | D35: 2462 | E35: 2909 | F35: 3263.6 | I35: =F35*(1+I36) -> 3426.78 | J35: =I35*(1+J36) -> 3598.119 | K35: =J35*(1+K36) -> 3778.025 | L35: =K35*(1+L36) -> 3966.9262 | M35: =L35*(1+M36) -> 4165.2725
C36: % Growth | E36: =E35/D35-1 -> 0.18155971 | F36: =F35/E35-1 -> 0.12189756 | I36: 0.05 | J36: 0.05 | K36: 0.05 | L36: 0.05 | M36: 0.05 | O36: Input your assumptions here!
C37: Product B | I37: =H37*(1+I38) -> 0 | J37: =I37*(1+J38) -> 0 | K37: =J37*(1+K38) -> 0 | L37: =K37*(1+L38) -> 0 | M37: =L37*(1+M38) -> 0
C38: % Growth | N38: -0.5 | O38: Input your assumptions here!
C39: Consolidated Sales | D39: =D35+D37 -> 2462 | E39: =E35+E37 -> 2909 | F39: =F35+F37 -> 3263.6 | G39: =G35+G37 -> 0 | H39: =H35+H37 -> 0 | I39: =I35+I37 -> 3426.78 | J39: =J35+J37 -> 3598.119 | K39: =K35+K37 -> 3778.025 | ... M39: =M35+M37 -> 4165.2725
C40: % Growth | E40: =E39/D39-1 -> 0.18155971 | F40: =F39/E39-1 -> 0.12189756 | I40: =I39/F39-1 -> 0.05 | J40: =J39/I39-1 -> 0.05 | K40: =K39/J39-1 -> 0.05 | L40: =L39/K39-1 -> 0.05 | M40: =M39/L39-1 -> 0.05

Sheet Operation
C3: Operating Items Forecast
C4: numbers in millions except per share data
C5: Selected: Base Case | D5: 2021 | E5: 2022 | F5: 2023 | I5: 2024 | J5: 2025 | K5: 2026 | L5: 2027 | M5: 2028
C7: Revenue | D7: 2462 | E7: 2909 | F7: 3263.6 | I7: =Revenue!I12 -> 3589.96 | J7: =Revenue!J12 -> 3948.956 | K7: =Revenue!K12 -> 4343.8516 | L7: =Revenue!L12 -> 4778.2368 | M7: =Revenue!M12 -> 5256.0604
C8: COGS | D8: 1520.1 | E8: 1812.3 | F8: 1921.5 | I8: =I7*Inputs!I9 -> 2197.0555 | J8: =J7*Inputs!J9 -> 2416.7611 | K8: =K7*Inputs!K9 -> 2658.4372 | L8: =L7*Inputs!L9 -> 2924.2809 | M8: =M7*Inputs!M9 -> 3216.709
C9: Gross Profit | D9: =D7-D8 -> 941.9 | E9: =E7-E8 -> 1096.7 | F9: =F7-F8 -> 1342.1 | I9: =I7-I8 -> 1392.9045 | J9: =J7-J8 -> 1532.1949 | K9: =K7-K8 -> 1685.4144 | L9: =L7-L8 -> 1853.9559 | M9: =M7-M8 -> 2039.3514
C10: Operating Expenses | D10: 586.5 | E10: 656.3 | F10: 754.7 | I10: =I7*(Inputs!I10+Inputs!I11+Inputs!I12) -> 917.60986 | J10: =J7*(Inputs!J10+Inputs!J11+Inputs!J12) -> 1009.3709 | K10: =K7*(Inputs!K10+Inputs!K11+Inputs!K12) -> 1110.3079 | L10: =L7*(Inputs!L10+Inputs!L11+Inputs!L12) -> 1221.3387 | M10: =M7*(Inputs!M10+Inputs!M11+Inputs!M12) -> 1343.4726
C11: EBIT | D11: 355.4 | E11: 440.4 | F11: 587.4 | I11: =I9-I10 -> 475.29462 | J11: =J9-J10 -> 522.82408 | K11: =K9-K10 -> 575.10648 | L11: =L9-L10 -> 632.61713 | M11: =M9-M10 -> 695.87885
C12: Taxes | D12: 47.8 | E12: 72.8 | F12: -67.6 | I12: =I11*Inputs!I13 -> 69.393765 | J12: =J11*Inputs!J13 -> 76.333141 | K12: =K11*Inputs!K13 -> 83.966455 | L12: =L11*Inputs!L13 -> 92.363101 | M12: =M11*Inputs!M13 -> 101.59941 | N12: =N11*Inputs!N13 -> 0
C13: NOPAT | D13: =D11-D12 -> 307.6 | E13: =E11-E12 -> 367.6 | F13: =F11-F12 -> 655 | I13: =I11-I12 -> 405.90085 | J13: =J11-J12 -> 446.49094 | K13: =K11-K12 -> 491.14003 | L13: =L11-L12 -> 540.25403 | M13: =M11-M12 -> 594.27944
C15: Depreciation & Amortization | D15: 108.4 | E15: 114.2 | F15: 141.4 | I15: =I7*Inputs!I14 -> 151.52697 | J15: =J7*Inputs!J14 -> 166.67966 | K15: =K7*Inputs!K14 -> 183.34763 | L15: =L7*Inputs!L14 -> 201.68239 | M15: =M7*Inputs!M14 -> 221.85063
C16: CAPEX | D16: -39.5 | E16: -45.9 | F16: -71 | I16: =I7*Inputs!I15 -> 64.104476 | J16: =J7*Inputs!J15 -> 70.514924 | K16: =K7*Inputs!K15 -> 77.566416 | L16: =L7*Inputs!L15 -> 85.323058 | M16: =M7*Inputs!M15 -> 93.855363
C17: Net Working Capital | D17: 532.8 | E17: 579.7 | F17: 602.5 | I17: =I7*Inputs!I16 -> 445.82795 | J17: =J7*Inputs!J16 -> 490.41075 | K17: =K7*Inputs!K16 -> 539.45182 | L17: =L7*Inputs!L16 -> 593.397 | M17: =M7*Inputs!M16 -> 652.7367
C19: Debt Calculation
C20: got 2021 by solving using 2022 info and getting change in NWC and backsolving to get 2021 NWC
C21: Debt | D21: 2021 | E21: 2022 | F21: 2023 | I21: 2024 | J21: 2025 | K21: 2026 | L21: 2027 | M21: 2028
C23: EBITDA | D23: =D11+D15 -> 463.8 | E23: =E11+E15 -> 554.6 | F23: =F11+F15 -> 728.8 | I23: =I11+I15 -> 626.82158 | J23: =J11+J15 -> 689.50374 | K23: =K11+K15 -> 758.45412 | L23: =L11+L15 -> 834.29953 | M23: =M11+M15 -> 917.72948
C24: Long-Term Debt | D24: 36015 | E24: 30045 | F24: 43520
C25: ST Debt & Current Portion of LT Debt | D25: 3355 | E25: 8995 | F25: 7101
C26: Operating Lease - Debt | D26: 6003 | E26: 6780 | F26: 6683
C27: Finance Lease - Debt | D27: 0 | E27: 0 | F27: 0 | M27: 338018.65
C29: Total Debt | D29: 999.9 | E29: 1083.2 | F29: 1780.7 | I29: =F29-31.9 -> 1748.8 | J29: =I29-37.5 -> 1711.3 | K29: =J29-174.9 -> 1536.4 | L29: =K29-22.5 -> 1513.9 | M29: =L29-387 -> 1126.9
C30: Net Borrowings | E30: =E29-D29 -> 83.3 | F30: =F29-E29 -> 697.5 | I30: =I29-F29 -> -31.9 | J30: =J29-I29 -> -37.5 | K30: =K29-J29 -> -174.9 | L30: =L29-K29 -> -22.5 | M30: =M29-L29 -> -387
C32: Debt Interest Expense | D32: 2044 | E32: 1978 | F32: 1975 | G32: 2262 | H32: 1976
C33: Lease Interest Expense | D33: 323 | E33: 352 | F33: 371 | G33: 337 | H33: 339
C34: Total Interest Expense | D34: 32.3 | E34: 31.2 | F34: 79.4 | I34: =((I29+F29)/2)*0.0515 -> 90.884625 | J34: =((J29+I29)/2)*0.0515 -> 89.097575 | K34: =((K29+J29)/2)*0.0515 -> 83.628275 | L34: =((L29+K29)/2)*0.0515 -> 78.545225 | M34: =((M29+L29)/2)*0.0515 -> 68.0006
I36: calculated total interest expense and debt by using the CDO payback structure given on page 62

Sheet CostofCapital
C3: WACC Schedule
C5: Market Risk Premium | K5: 0.05 | M5: Assumed S&P 500 average return 8% last 10 years
C6: Beta | K6: 1.33 | M6: Got levered beta from yahoo finances current estimation of this companies beta
C7: Adjusted Market Risk Premium | K7: 0.0665
C8: Add: Risk Free Rate of Return | K8: 0.03 | M8: assumed based on 10Tbills
C10: Cost of Equity | K10: 0.0965
C12: Target Debt to Total Capital Ratio | K12: 0.315 | M12: calculated data from 10k
C13: Weighted Cost of Equity | K13: 0.0661
C14: Cost of Debt (weighted average) | K14: 0.0515 | M14: weighted average of debt
C15: Effective Tax Rate | K15: 0.15
C16: After-Tax Cost of Debt | K16: 0.043775
C17: Target Debt to Total Capital Ratio | K17: 0.315
C18: Weighted After-Tax Cost of Debt | K18: 0.0138
C20: WACC | K20: 0.0799

Sheet DCF
D1: #REF!
D2: 0.097265
C3: Scenarios & Other Inputs
C5: Case Number | D5: 1
C6: Selected Case | D6: =IF(D5=1,"Base",IF(D5=2,"Bull","Bear")) -> Base | I6: FCFF
C7: Cost of Equity | D7: =CostofCapital!K10 -> 0.0965 | I7: - Interest Expense * (1-Tax)
C8: Terminal Growth Rate | D8: 0.02 | I8: + Net Borrowing
C9: Comparable EV/EBITDA | D9: 13.3 | E9: got from googling recent comparables. Spirax‑Sarco Engineering is the company I chose with 13.3x EV/EBITDA | I9: FCFE
C10: Target Debt/EBITDA | D10: 6.66
C14: DCF Projections
J16: 1 | K16: 2 | L16: 3 | M16: 4 | N16: 5
C17: Selected Financials - DCF | J17: Forecasted
C18: Base Case | E18: 2021 | F18: 2022 | G18: 2023 | J18: 2024 | K18: 2025 | L18: 2026 | M18: 2027 | N18: 2028
C19: Revenue | E19: =Operation!D7 -> 2462 | F19: =Operation!E7 -> 2909 | G19: =Operation!F7 -> 3263.6 | H19: =Operation!G7 -> 0 | I19: =Operation!H7 -> 0 | J19: =Operation!I7 -> 3589.96 | K19: =Operation!J7 -> 3948.956 | L19: =Operation!K7 -> 4343.8516 | ... N19: =Operation!M7 -> 5256.0604
C20: COGS & Other Expenses | E20: =Operation!D8+Operation!D10 -> 2106.6 | F20: =Operation!E8+Operation!E10 -> 2468.6 | G20: =Operation!F8+Operation!F10 -> 2676.2 | H20: =Operation!G8+Operation!G10 -> 0 | I20: =Operation!H8+Operation!H10 -> 0 | J20: =Operation!I8+Operation!I10 -> 3114.6654 | K20: =Operation!J8+Operation!J10 -> 3426.1319 | L20: =Operation!K8+Operation!K10 -> 3768.7451 | ... N20: =Operation!M8+Operation!M10 -> 4560.1816
C21: EBITDA | E21: =E19-E20+E22 -> 463.8 | F21: =F19-F20+F22 -> 554.6 | G21: =G19-G20+G22 -> 728.8 | H21: =H19-H20+H22 -> 0 | I21: =I19-I20+I22 -> 0 | J21: =J19-J20+J22 -> 626.82158 | K21: =K19-K20+K22 -> 689.50374 | L21: =L19-L20+L22 -> 758.45412 | ... N21: =N19-N20+N22 -> 917.72948
C22: D&A | E22: =Operation!D15 -> 108.4 | F22: =Operation!E15 -> 114.2 | G22: =Operation!F15 -> 141.4 | H22: =Operation!G15 -> 0 | I22: =Operation!H15 -> 0 | J22: =Operation!I15 -> 151.52697 | K22: =Operation!J15 -> 166.67966 | L22: =Operation!K15 -> 183.34763 | ... N22: =Operation!M15 -> 221.85063
C23: EBIT | E23: =E21-E22 -> 355.4 | F23: =F21-F22 -> 440.4 | G23: =G21-G22 -> 587.4 | H23: =H21-H22 -> 0 | I23: =I21-I22 -> 0 | J23: =Operation!I11 -> 475.29462 | K23: =Operation!J11 -> 522.82408 | L23: =Operation!K11 -> 575.10648 | M23: =Operation!L11 -> 632.61713 | N23: =Operation!M11 -> 695.87885
C24: Taxes | E24: =Operation!D12 -> 47.8 | F24: =Operation!E12 -> 72.8 | G24: =Operation!F12 -> -67.6 | H24: =Operation!G12 -> 0 | I24: =Operation!H12 -> 0 | J24: =Operation!I12 -> 69.393765 | K24: =Operation!J12 -> 76.333141 | L24: =Operation!K12 -> 83.966455 | ... N24: =Operation!M12 -> 101.59941
C25: NOPAT | E25: =E23-E24 -> 307.6 | F25: =F23-F24 -> 367.6 | G25: =G23-G24 -> 655 | H25: =H23-H24 -> 0 | I25: =I23-I24 -> 0 | J25: =J23-J24 -> 405.90085 | K25: =K23-K24 -> 446.49094 | L25: =L23-L24 -> 491.14003 | ... N25: =N23-N24 -> 594.27944
C26: (+) D&A | E26: =Operation!D15 -> 108.4 | F26: =Operation!E15 -> 114.2 | G26: =Operation!F15 -> 141.4 | H26: =Operation!G15 -> 0 | I26: =Operation!H15 -> 0 | J26: =Operation!I15 -> 151.52697 | K26: =Operation!J15 -> 166.67966 | L26: =Operation!K15 -> 183.34763 | ... N26: =Operation!M15 -> 221.85063
C27: (-) Change in NWC | E27: 0 | F27: =Operation!E17-Operation!D17 -> 46.9 | G27: =Operation!F17-Operation!E17 -> 22.8 | I27: =Operation!H17-Operation!G17 -> 0 | J27: =Operation!I17-Operation!H17 -> 445.82795 | K27: =Operation!J17-Operation!I17 -> 44.582795 | L27: =Operation!K17-Operation!J17 -> 49.041075 | M27: =Operation!L17-Operation!K17 -> 53.945182 | N27: =Operation!M17-Operation!L17 -> 59.3397
C28: (-) CAPEX | E28: =Operation!D16 -> -39.5 | F28: =Operation!E16 -> -45.9 | G28: =Operation!F16 -> -71 | H28: =Operation!G16 -> 0 | I28: =Operation!H16 -> 0 | J28: =Operation!I16 -> 64.104476 | K28: =Operation!J16 -> 70.514924 | L28: =Operation!K16 -> 77.566416 | ... N28: =Operation!M16 -> 93.855363
C29: Unlevered Free Cash Flow | E29: =E25+E26-E27-E28 -> 455.5 | F29: =F25+F26-F27-F28 -> 480.8 | G29: =G25+G26-G27-G28 -> 844.6 | H29: =H25+H26-H27-H28 -> 0 | I29: =I25+I26-I27-I28 -> 0 | J29: =J25+J26-J27-J28 -> 47.495392 | K29: =K25+K26-K27-K28 -> 498.07288 | L29: =L25+L26-L27-L28 -> 547.88017 | ... N29: =N25+N26-N27-N28 -> 662.935 | P29: Calculate the FCFF here.
C30: (-) After Tax Interest Expense | E30: =Operation!D34*(1-Inputs!D13) -> 27.485717 | F30: =Operation!E34*(1-Inputs!E13) -> 26.393921 | G30: =Operation!F34*(1-Inputs!F13) -> 68.681 | H30: =Operation!G34*(1-Inputs!G13) -> 0 | I30: =Operation!H34*(1-Inputs!H13) -> 0 | J30: =Operation!I34*(1-Inputs!I13) -> 77.615326 | K30: =Operation!J34*(1-Inputs!J13) -> 76.089188 | L30: =Operation!K34*(1-Inputs!K13) -> 71.418415 | ... N30: =Operation!M34*(1-Inputs!M13) -> 58.072405
C31: (+) Net Borrowing | E31: =Operation!D30 -> 0 | F31: =Operation!E30 -> 83.3 | G31: =Operation!F30 -> 697.5 | H31: =Operation!G30 -> 0 | I31: =Operation!H30 -> 0 | J31: =Operation!I30 -> -31.9 | K31: =Operation!J30 -> -37.5 | L31: =Operation!K30 -> -174.9 | ... N31: =Operation!M30 -> -387
C32: Free Cash Flow to Equity | E32: =E29-E30+E31 -> 428.01428 | F32: =F29-F30+F31 -> 537.70608 | G32: =G29-G30+G31 -> 1473.419 | H32: =H29-H30+H31 -> 0 | I32: =I29-I30+I31 -> 0 | J32: =J29-J30+J31 -> -62.019934 | K32: =K29-K30+K31 -> 384.48369 | L32: =L29-L30+L31 -> 301.56175 | ... N32: =N29-N30+N31 -> 217.8626
C33: Discount Factor | E33: =$D$41 -> 0.0965 | F33: =$D$41 -> 0.0965 | G33: =$D$41 -> 0.0965 | J33: =$D$41 -> 0.0965 | K33: =$D$41 -> 0.0965 | L33: =$D$41 -> 0.0965 | M33: =$D$41 -> 0.0965 | N33: =$D$41 -> 0.0965
C34: Discounted FCFE | J34: =J32/(1+J33) -> -56.561728 | K34: =K32/(1+K33)^2 -> 319.78689 | L34: =L32/(1+L33)^3 -> 228.74434 | M34: =M32/(1+M33)^4 -> 354.9438 | N34: =N32/(1+N33)^5 -> 137.44834
C36: Terminal Value Calculation
C38: Terminal Equity Value - Gordon Growth
C39: Terminal Growth Rate | D39: =0.05 -> 0.05
C40: Terminal Year FCFE | D40: =N32*(1+D39) -> 228.75573
C41: Discount Rate | D41: =D7 -> 0.0965
C42: Terminal Value | D42: =D40/(D41-D39) -> 4919.4781 | E42: Use the Gordon Growth Formula and Calculate the Terminal Value here.
C43: Time Period | D43: 5
C44: PV of Terminal Value | D44: =D42/(1+D41)^D43 -> 3103.6722 | E44: Discount the Terminal Value to PV.
C46: Terminal Equity Value - Exit Multiple
C47: Exit Multiple | D47: =D9 -> 13.3
C48: Terminal Year EBITDA | D48: =N21*(1+D39) -> 963.61595
...
