Workbook

Sheet Cover
B2: Precedent Transactions Analysis - Large Tech/Media M&A
B3: ($ in millions, except per-share data and multiples)
B5: Prepared by: Akul Veauli
B6: Date: August 23, 2026
B8: Twelve-deal precedent set (2016-2024) of large tech/media (plus one energy outlier) acquisitions, spanning Microsoft/LinkedIn (2016) through Broadcom/VMware and ExxonMobil/Pioneer (2023). Six deals form a high-confidence core (MSFT/Activision, Salesforce/Slack, AMD/Xilinx, NVDA/Mellanox, MSFT/LinkedIn, Oracle/Cerner); four suite deals (Disney/Fox, Twitter, XOM/Pioneer, Broadcom/VMware) are added for coherence with the wider model suite. Adobe/Figma (terminated, private target) and Amazon/MGM (private, no disclosed financials) are shown as rows but flagged Include=0 and excluded from all summary statistics. Implied valuation ranges are applied to the four DCF subject companies (MSFT, NVDA, AAPL, GOOGL) on the ImpliedVal tab.
B11: Color-Code Legend
B12: 123.4 | C12: <- Blue = hardcoded input (source-cited)
B13: =1+1 -> 2 | C13: <- Black = formula (same sheet)
B14: =Inputs!B6 -> Broadcom / VMware | C14: <- Green = link/formula from another tab
B16: Table of Contents
B17: Cover | C17: This page
B18: Inputs | C18: 12-deal precedent input table (all blue, source-cited)
B19: Precedents | C19: Computed multiples, Include-flag stats blocks, era split
B20: ImpliedVal | C20: Implied valuation for MSFT / NVDA / AAPL / GOOGL
B22: Key Outputs - Core Set (Include=1) Summary Multiples
B23: Metric | C23: Median | D23: 25th pct | E23: 75th pct | F23: # deals incl.
B24: EV / LTM Revenue | C24: =Precedents!C24 -> 6.8622106 | D24: =Precedents!C25 -> 4.7887931 | E24: =Precedents!C22 -> 8.9841207 | F24: =Precedents!C28 -> 10
B25: EV / LTM EBITDA | C25: =Precedents!D24 -> 19.790698 | D25: =Precedents!D25 -> 18.019282 | E25: =Precedents!D22 -> 36.627435 | F25: =Precedents!D28 -> 7
B29: Sources: SEC EDGAR (10-K/10-Q/DEFM14A/S-4/SC 14D-9), company press releases, and public deal announcements for each transaction (see Inputs tab column P for per-deal citations). Market/subject-company data as of August 21-23, 2026 (see E1-E4 data packs).

Sheet Inputs
B2: Inputs - Precedent Transaction Data (all cells blue = hardcoded, source-cited)
B3: ($ in millions except per-share consideration; dates mm/dd/yyyy)
B5: Deal | C5: Acquirer | D5: Target | E5: Announce Date | F5: Close / Term Date | G5: Consideration Form | H5: Transaction EV ($mm) | I5: Equity Value ($mm) | J5: Target LTM Revenue ($mm) | K5: Target LTM EBITDA ($mm) | L5: Target NTM Revenue ($mm) | M5: 1-Day Premium % | N5: Include in Stats? (1/0) | O5: Notes | P5: Source
B6: Broadcom / VMware | C6: Broadcom | D6: VMware, Inc. | E6: 44707 | F6: 11/22/2023 | G6: Cash/stock election, prorated 47.9% cash / 52.1% stock | H6: 79000 | I6: 69000 | J6: 13350 | K6: 4700 | L6: n.a. | M6: n.a. | N6: 1 | O6: EV incl. $8.25B assumed VMW senior notes less $6.6B cash acquired. Premium not computable (proration + collar mechanics; no single unaffected reference price). | P6: AVGO FY2024 10-K Note 3; VMW FY2023 10-K; AVGO/VMW press 5/26/22 & 11/22/23
B7: Microsoft / Activision Blizzard | C7: Microsoft | D7: Activision Blizzard, Inc. | E7: 44579 | F7: 10/13/2023 | G7: 100% cash, $95.00/sh | H7: 68700 | I7: 68700 | J7: 8800 | K7: 1732 | L7: n.a. | M7: 0.462 | N7: 1 | O7: LTM EBITDA derived from ~20.2x reported deal multiple; not directly disclosed in DEFM14A. | P7: SEC DEFM14A 3/21/22; MSFT press 1/18/22; ATVI 10-K FY2021
B8: ExxonMobil / Pioneer Natural Resources Co. | C8: ExxonMobil | D8: Pioneer Natural Resources Co. | E8: 45210 | F8: 5/3/2024 | G8: 100% stock, 2.3234x XOM/PXD exchange ratio | H8: 64500 | I8: 59500 | J8: 19370 | K8: n.a. | L8: n.a. | M8: 0.18 | N8: 1 | O8: Energy-sector outlier vs. tech/media peer set - kept in stats for era comparability per spec. PXD standalone EBITDA not broken out in 10-K DD&A footnote; EV/EBITDA n.m. | P8: XOM/PXD 10-K FY2023; XOM S-4 11/2023; press 10/11/23
B9: Disney / 21st Century Fox | C9: Disney | D9: 21st Century Fox (entertainment assets) | E9: 43083 | F9: 3/20/2019 | G9: 50% cash / 50% stock (amended 6/20/18; ~$38.00/sh equivalent) | H9: 85100 | I9: 71300 | J9: 20200 | K9: 4300 | L9: n.a. | M9: 0.462 | N9: 1 | O9: Target = acquired Fox entertainment assets only (Total 21CF less RemainCo/Fox Corp spin-off). Revenue & EBITDA derived (Total 21CF minus RemainCo pro forma); both flagged ESTIMATE. | P9: Disney S-4; 8-K12B 3/2019; RemainCo pro forma exhibits (SEC 3/2019)
B10: Elon Musk / X Holdings / Twitter | C10: Elon Musk / X Holdings | D10: Twitter, Inc. | E10: 44676 | F10: 10/27/2022 | G10: 100% cash, $54.20/sh | H10: 46064 | I10: 44000 | J10: 5080 | K10: 682 | L10: n.a. | M10: 0.379 | N10: 1 | O10: EV = equity value + existing debt ($4.25B) less cash ($2.19B). FY2021 Adj. EBITDA ($682mm) used 'as-is' -> implies a pathological ~67x EV/EBITDA multiple; shown, not forced to n.m., per spec note. | P10: Twitter 10-K FY2021; DEFM14A 9/2/22; premium vs. 4/1/22 unaffected close ($39.31, widely reported)
B11: Salesforce / Slack Technologies | C11: Salesforce | D11: Slack Technologies, Inc. | E11: 44166 | F11: 7/21/2021 | G11: 64% cash / 36% stock | H11: 27700 | I11: 27700 | J11: 630 | K11: -555 | L11: n.a. | M11: 0.54 | N11: 1 | O11: FY2020 (ended 1/31/21) EBITDA negative; pre-profitability SaaS growth premium. EV/EBITDA n.m. | P11: SEC DEFM14A 1/29/21; Slack 10-K FY2020
B12: AMD / Xilinx | C12: AMD | D12: Xilinx, Inc. | E12: 44131 | F12: 2/14/2022 | G12: 100% stock, 1.7234x AMD/XLNX exchange ratio | H12: 48800 | I12: n.a. | J12: 3000 | K12: n.a. | L12: n.a. | M12: 0.3 | N12: 1 | O12: EBITDA not separately disclosed in S-4 (all-stock deal); EV/EBITDA n.m. Premium range 25-35% reported; midpoint (30%) used. | P12: SEC S-4 10/27/20; XLNX 10-K FY2020 (ended 4/2/20)
B13: Nvidia / Mellanox Technologies | C13: Nvidia | D13: Mellanox Technologies, Ltd. | E13: 43535 | F13: 4/27/2020 | G13: 100% cash, $125.00/sh | H13: 6900 | I13: 6900 | J13: 1450 | K13: 376 | L13: n.a. | M13: 0.143 | N13: 1 | O13: Clean all-cash deal; complete DEFM14A financial detail. | P13: SEC DEFM14A 6/20/19; MLNX 10-K FY2018
B14: Microsoft / LinkedIn Corporation | C14: Microsoft | D14: LinkedIn Corporation | E14: 42534 | F14: 12/8/2016 | G14: 100% cash, $196.00/sh | H14: 26200 | I14: 26200 | J14: 3000 | K14: 780 | L14: n.a. | M14: 0.496 | N14: 1 | O14: Complete SEC DEFM14A financial detail. | P14: SEC DEFM14A 7/22/16; LNKD 10-K FY2015
B15: Adobe / Figma | C15: Adobe | D15: Figma, Inc. | E15: 44819 | F15: TERMINATED 12/18/23 | G15: 50% cash / 50% stock (deal never closed) | H15: 20000 | I15: n.a. | J15: 425 | K15: -869 | L15: n.a. | M15: n.a. | N15: 0 | O15: TERMINATED Dec-2023 (UK CMA / DOJ regulatory opposition; $1B fee paid by Adobe). Figma is private: 'revenue' is an ARR estimate, not GAAP LTM revenue; EBITDA heavily negative (est.). EXCLUDED from stats (Include=0). | P15: Adobe S-4 11/14/22; Adobe termination press 12/18/23
B16: Oracle / Cerner Corporation | C16: Oracle | D16: Cerner Corporation | E16: 44550 | F16: 6/8/2022 | G16: 100% cash, $95.00/sh tender offer | H16: 28300 | I16: 28300 | J16: 5800 | K16: 1600 | L16: n.a. | M16: 0.058 | N16: 1 | O16: Clean tender offer; complete financial detail. | P16: Oracle Tender Offer Statement 12/21/21; Cerner SC 14D-9 1/19/22
B17: Amazon / MGM Holdings Inc. | C17: Amazon | D17: MGM Holdings Inc. | E17: 44707 | F17: 3/17/2023 | G17: 100% cash | H17: 8450 | I17: 8450 | J17: n.a. | K17: n.a. | L17: n.a. | M17: 0.41 | N17: 0 | O17: MGM is private -> no SEC disclosures; revenue/EBITDA unavailable from public sources. EXCLUDED from stats (Include=0). | P17: Amazon press 5/26/22; private deal database estimates (low confidence)
B19: NTM revenue: not disclosed for any of the 12 targets at announcement (deal-date sell-side consensus unavailable in public filings/press for private or newly-announced targets) - column retained per spec, shown 'n.a.' throughout.
B20: 'n.a.' in Target LTM Revenue/EBITDA = not disclosed / not derivable from public sources (never backed into a fabricated number). See Precedents tab for n.m. multiple handling.

Sheet Precedents
B2: Precedents - Computed Multiples & Include-Flag Statistics
B3: (multiples 0.0x; helper columns I-N drive flag-conditional QUARTILE.INC/MEDIAN - see note)
B5: Deal | C5: Announce Year | D5: EV / LTM Revenue | E5: EV / LTM EBITDA | F5: 1-Day Premium % | G5: Include (1/0) | H5: Era | I5: Helper: EV/Rev (incl.) | J5: Helper: EV/EBITDA (incl.) | K5: Helper: EV/Rev 16-19 | L5: Helper: EV/EBITDA 16-19 | M5: Helper: EV/Rev 20-24 | N5: Helper: EV/EBITDA 20-24
B6: =Inputs!B6 -> Broadcom / VMware | C6: =YEAR(Inputs!E6) -> 2022 | D6: =IF(OR(ISTEXT(Inputs!J6),Inputs!J6<=0),"n.m.",Inputs!H6/Inputs!J6) -> 5.917603 | E6: =IF(OR(ISTEXT(Inputs!K6),Inputs!K6<=0),"n.m.",Inputs!H6/Inputs!K6) -> 16.808511 | F6: =Inputs!M6 -> n.a. | G6: =Inputs!N6 -> 1 | H6: =IF(C6<=2019,"2016-19","2020-24") -> 2020-24 | I6: =IF(AND(G6=1,ISNUMBER(D6)),D6,"") -> 5.917603 | J6: =IF(AND(G6=1,ISNUMBER(E6)),E6,"") -> 16.808511 | K6: =IF(AND(G6=1,H6="2016-19",ISNUMBER(D6)),D6,"") | L6: =IF(AND(G6=1,H6="2016-19",ISNUMBER(E6)),E6,"") | M6: =IF(AND(G6=1,H6="2020-24",ISNUMBER(D6)),D6,"") -> 5.917603 | N6: =IF(AND(G6=1,H6="2020-24",ISNUMBER(E6)),E6,"") -> 16.808511
B7: =Inputs!B7 -> Microsoft / Activision Blizzard | C7: =YEAR(Inputs!E7) -> 2022 | D7: =IF(OR(ISTEXT(Inputs!J7),Inputs!J7<=0),"n.m.",Inputs!H7/Inputs!J7) -> 7.8068182 | E7: =IF(OR(ISTEXT(Inputs!K7),Inputs!K7<=0),"n.m.",Inputs!H7/Inputs!K7) -> 39.665127 | F7: =Inputs!M7 -> 0.462 | G7: =Inputs!N7 -> 1 | H7: =IF(C7<=2019,"2016-19","2020-24") -> 2020-24 | I7: =IF(AND(G7=1,ISNUMBER(D7)),D7,"") -> 7.8068182 | J7: =IF(AND(G7=1,ISNUMBER(E7)),E7,"") -> 39.665127 | K7: =IF(AND(G7=1,H7="2016-19",ISNUMBER(D7)),D7,"") | L7: =IF(AND(G7=1,H7="2016-19",ISNUMBER(E7)),E7,"") | M7: =IF(AND(G7=1,H7="2020-24",ISNUMBER(D7)),D7,"") -> 7.8068182 | N7: =IF(AND(G7=1,H7="2020-24",ISNUMBER(E7)),E7,"") -> 39.665127
B8: =Inputs!B8 -> ExxonMobil / Pioneer Natural Resources Co. | C8: =YEAR(Inputs!E8) -> 2023 | D8: =IF(OR(ISTEXT(Inputs!J8),Inputs!J8<=0),"n.m.",Inputs!H8/Inputs!J8) -> 3.3298916 | E8: =IF(OR(ISTEXT(Inputs!K8),Inputs!K8<=0),"n.m.",Inputs!H8/Inputs!K8) -> n.m. | F8: =Inputs!M8 -> 0.18 | G8: =Inputs!N8 -> 1 | H8: =IF(C8<=2019,"2016-19","2020-24") -> 2020-24 | I8: =IF(AND(G8=1,ISNUMBER(D8)),D8,"") -> 3.3298916 | J8: =IF(AND(G8=1,ISNUMBER(E8)),E8,"") | K8: =IF(AND(G8=1,H8="2016-19",ISNUMBER(D8)),D8,"") | L8: =IF(AND(G8=1,H8="2016-19",ISNUMBER(E8)),E8,"") | M8: =IF(AND(G8=1,H8="2020-24",ISNUMBER(D8)),D8,"") -> 3.3298916 | N8: =IF(AND(G8=1,H8="2020-24",ISNUMBER(E8)),E8,"")
B9: =Inputs!B9 -> Disney / 21st Century Fox | C9: =YEAR(Inputs!E9) -> 2017 | D9: =IF(OR(ISTEXT(Inputs!J9),Inputs!J9<=0),"n.m.",Inputs!H9/Inputs!J9) -> 4.2128713 | E9: =IF(OR(ISTEXT(Inputs!K9),Inputs!K9<=0),"n.m.",Inputs!H9/Inputs!K9) -> 19.790698 | F9: =Inputs!M9 -> 0.462 | G9: =Inputs!N9 -> 1 | H9: =IF(C9<=2019,"2016-19","2020-24") -> 2016-19 | I9: =IF(AND(G9=1,ISNUMBER(D9)),D9,"") -> 4.2128713 | J9: =IF(AND(G9=1,ISNUMBER(E9)),E9,"") -> 19.790698 | K9: =IF(AND(G9=1,H9="2016-19",ISNUMBER(D9)),D9,"") -> 4.2128713 | L9: =IF(AND(G9=1,H9="2016-19",ISNUMBER(E9)),E9,"") -> 19.790698 | M9: =IF(AND(G9=1,H9="2020-24",ISNUMBER(D9)),D9,"") | N9: =IF(AND(G9=1,H9="2020-24",ISNUMBER(E9)),E9,"")
B10: =Inputs!B10 -> Elon Musk / X Holdings / Twitter | C10: =YEAR(Inputs!E10) -> 2022 | D10: =IF(OR(ISTEXT(Inputs!J10),Inputs!J10<=0),"n.m.",Inputs!H10/Inputs!J10) -> 9.0677165 | E10: =IF(OR(ISTEXT(Inputs!K10),Inputs!K10<=0),"n.m.",Inputs!H10/Inputs!K10) -> 67.542522 | F10: =Inputs!M10 -> 0.379 | G10: =Inputs!N10 -> 1 | H10: =IF(C10<=2019,"2016-19","2020-24") -> 2020-24 | I10: =IF(AND(G10=1,ISNUMBER(D10)),D10,"") -> 9.0677165 | J10: =IF(AND(G10=1,ISNUMBER(E10)),E10,"") -> 67.542522 | K10: =IF(AND(G10=1,H10="2016-19",ISNUMBER(D10)),D10,"") | L10: =IF(AND(G10=1,H10="2016-19",ISNUMBER(E10)),E10,"") | M10: =IF(AND(G10=1,H10="2020-24",ISNUMBER(D10)),D10,"") -> 9.0677165 | N10: =IF(AND(G10=1,H10="2020-24",ISNUMBER(E10)),E10,"") -> 67.542522
B11: =Inputs!B11 -> Salesforce / Slack Technologies | C11: =YEAR(Inputs!E11) -> 2020 | D11: =IF(OR(ISTEXT(Inputs!J11),Inputs!J11<=0),"n.m.",Inputs!H11/Inputs!J11) -> 43.968254 | E11: =IF(OR(ISTEXT(Inputs!K11),Inputs!K11<=0),"n.m.",Inputs!H11/Inputs!K11) -> n.m. | F11: =Inputs!M11 -> 0.54 | G11: =Inputs!N11 -> 1 | H11: =IF(C11<=2019,"2016-19","2020-24") -> 2020-24 | I11: =IF(AND(G11=1,ISNUMBER(D11)),D11,"") -> 43.968254 | J11: =IF(AND(G11=1,ISNUMBER(E11)),E11,"") | K11: =IF(AND(G11=1,H11="2016-19",ISNUMBER(D11)),D11,"") | L11: =IF(AND(G11=1,H11="2016-19",ISNUMBER(E11)),E11,"") | M11: =IF(AND(G11=1,H11="2020-24",ISNUMBER(D11)),D11,"") -> 43.968254 | N11: =IF(AND(G11=1,H11="2020-24",ISNUMBER(E11)),E11,"")
B12: =Inputs!B12 -> AMD / Xilinx | C12: =YEAR(Inputs!E12) -> 2020 | D12: =IF(OR(ISTEXT(Inputs!J12),Inputs!J12<=0),"n.m.",Inputs!H12/Inputs!J12) -> 16.266667 | E12: =IF(OR(ISTEXT(Inputs!K12),Inputs!K12<=0),"n.m.",Inputs!H12/Inputs!K12) -> n.m. | F12: =Inputs!M12 -> 0.3 | G12: =Inputs!N12 -> 1 | H12: =IF(C12<=2019,"2016-19","2020-24") -> 2020-24 | I12: =IF(AND(G12=1,ISNUMBER(D12)),D12,"") -> 16.266667 | J12: =IF(AND(G12=1,ISNUMBER(E12)),E12,"") | K12: =IF(AND(G12=1,H12="2016-19",ISNUMBER(D12)),D12,"") | L12: =IF(AND(G12=1,H12="2016-19",ISNUMBER(E12)),E12,"") | M12: =IF(AND(G12=1,H12="2020-24",ISNUMBER(D12)),D12,"") -> 16.266667 | N12: =IF(AND(G12=1,H12="2020-24",ISNUMBER(E12)),E12,"")
B13: =Inputs!B13 -> Nvidia / Mellanox Technologies | C13: =YEAR(Inputs!E13) -> 2019 | D13: =IF(OR(ISTEXT(Inputs!J13),Inputs!J13<=0),"n.m.",Inputs!H13/Inputs!J13) -> 4.7586207 | E13: =IF(OR(ISTEXT(Inputs!K13),Inputs!K13<=0),"n.m.",Inputs!H13/Inputs!K13) -> 18.351064 | F13: =Inputs!M13 -> 0.143 | G13: =Inputs!N13 -> 1 | H13: =IF(C13<=2019,"2016-19","2020-24") -> 2016-19 | I13: =IF(AND(G13=1,ISNUMBER(D13)),D13,"") -> 4.7586207 | J13: =IF(AND(G13=1,ISNUMBER(E13)),E13,"") -> 18.351064 | K13: =IF(AND(G13=1,H13="2016-19",ISNUMBER(D13)),D13,"") -> 4.7586207 | L13: =IF(AND(G13=1,H13="2016-19",ISNUMBER(E13)),E13,"") -> 18.351064 | M13: =IF(AND(G13=1,H13="2020-24",ISNUMBER(D13)),D13,"") | N13: =IF(AND(G13=1,H13="2020-24",ISNUMBER(E13)),E13,"")
B14: =Inputs!B14 -> Microsoft / LinkedIn Corporation | C14: =YEAR(Inputs!E14) -> 2016 | D14: =IF(OR(ISTEXT(Inputs!J14),Inputs!J14<=0),"n.m.",Inputs!H14/Inputs!J14) -> 8.7333333 | E14: =IF(OR(ISTEXT(Inputs!K14),Inputs!K14<=0),"n.m.",Inputs!H14/Inputs!K14) -> 33.589744 | F14: =Inputs!M14 -> 0.496 | G14: =Inputs!N14 -> 1 | H14: =IF(C14<=2019,"2016-19","2020-24") -> 2016-19 | I14: =IF(AND(G14=1,ISNUMBER(D14)),D14,"") -> 8.7333333 | J14: =IF(AND(G14=1,ISNUMBER(E14)),E14,"") -> 33.589744 | K14: =IF(AND(G14=1,H14="2016-19",ISNUMBER(D14)),D14,"") -> 8.7333333 | L14: =IF(AND(G14=1,H14="2016-19",ISNUMBER(E14)),E14,"") -> 33.589744 | M14: =IF(AND(G14=1,H14="2020-24",ISNUMBER(D14)),D14,"") | N14: =IF(AND(G14=1,H14="2020-24",ISNUMBER(E14)),E14,"")
B15: =Inputs!B15 -> Adobe / Figma | C15: =YEAR(Inputs!E15) -> 2022 | D15: =IF(OR(ISTEXT(Inputs!J15),Inputs!J15<=0),"n.m.",Inputs!H15/Inputs!J15) -> 47.058824 | E15: =IF(OR(ISTEXT(Inputs!K15),Inputs!K15<=0),"n.m.",Inputs!H15/Inputs!K15) -> n.m. | F15: =Inputs!M15 -> n.a. | G15: =Inputs!N15 -> 0 | H15: =IF(C15<=2019,"2016-19","2020-24") -> 2020-24 | I15: =IF(AND(G15=1,ISNUMBER(D15)),D15,"") | J15: =IF(AND(G15=1,ISNUMBER(E15)),E15,"") | K15: =IF(AND(G15=1,H15="2016-19",ISNUMBER(D15)),D15,"") | L15: =IF(AND(G15=1,H15="2016-19",ISNUMBER(E15)),E15,"") | M15: =IF(AND(G15=1,H15="2020-24",ISNUMBER(D15)),D15,"") | N15: =IF(AND(G15=1,H15="2020-24",ISNUMBER(E15)),E15,"")
B16: =Inputs!B16 -> Oracle / Cerner Corporation | C16: =YEAR(Inputs!E16) -> 2021 | D16: =IF(OR(ISTEXT(Inputs!J16),Inputs!J16<=0),"n.m.",Inputs!H16/Inputs!J16) -> 4.8793103 | E16: =IF(OR(ISTEXT(Inputs!K16),Inputs!K16<=0),"n.m.",Inputs!H16/Inputs!K16) -> 17.6875 | F16: =Inputs!M16 -> 0.058 | G16: =Inputs!N16 -> 1 | H16: =IF(C16<=2019,"2016-19","2020-24") -> 2020-24 | I16: =IF(AND(G16=1,ISNUMBER(D16)),D16,"") -> 4.8793103 | J16: =IF(AND(G16=1,ISNUMBER(E16)),E16,"") -> 17.6875 | K16: =IF(AND(G16=1,H16="2016-19",ISNUMBER(D16)),D16,"") | L16: =IF(AND(G16=1,H16="2016-19",ISNUMBER(E16)),E16,"") | M16: =IF(AND(G16=1,H16="2020-24",ISNUMBER(D16)),D16,"") -> 4.8793103 | N16: =IF(AND(G16=1,H16="2020-24",ISNUMBER(E16)),E16,"") -> 17.6875
B17: =Inputs!B17 -> Amazon / MGM Holdings Inc. | C17: =YEAR(Inputs!E17) -> 2022 | D17: =IF(OR(ISTEXT(Inputs!J17),Inputs!J17<=0),"n.m.",Inputs!H17/Inputs!J17) -> n.m. | E17: =IF(OR(ISTEXT(Inputs!K17),Inputs!K17<=0),"n.m.",Inputs!H17/Inputs!K17) -> n.m. | F17: =Inputs!M17 -> 0.41 | G17: =Inputs!N17 -> 0 | H17: =IF(C17<=2019,"2016-19","2020-24") -> 2020-24 | I17: =IF(AND(G17=1,ISNUMBER(D17)),D17,"") | J17: =IF(AND(G17=1,ISNUMBER(E17)),E17,"") | K17: =IF(AND(G17=1,H17="2016-19",ISNUMBER(D17)),D17,"") | L17: =IF(AND(G17=1,H17="2016-19",ISNUMBER(E17)),E17,"") | M17: =IF(AND(G17=1,H17="2020-24",ISNUMBER(D17)),D17,"") | N17: =IF(AND(G17=1,H17="2020-24",ISNUMBER(E17)),E17,"")
B19: Summary Statistics - Core Set (Include = 1, n = 10 of 12 deals)
B20: Statistic | C20: EV / LTM Revenue | D20: EV / LTM EBITDA
B21: Max | C21: =MAX(I6:I17) -> 43.968254 | D21: =MAX(J6:J17) -> 67.542522
B22: 75th pctile | C22: =_xlfn.QUARTILE.INC(I6:I17,3) -> 8.9841207 | D22: =_xlfn.QUARTILE.INC(J6:J17,3) -> 36.627435
B23: Mean | C23: =AVERAGE(I6:I17) -> 10.894109 | D23: =AVERAGE(J6:J17) -> 30.490738
B24: Median | C24: =MEDIAN(I6:I17) -> 6.8622106 | D24: =MEDIAN(J6:J17) -> 19.790698
B25: 25th pctile | C25: =_xlfn.QUARTILE.INC(I6:I17,1) -> 4.7887931 | D25: =_xlfn.QUARTILE.INC(J6:J17,1) -> 18.019282
B26: Min | C26: =MIN(I6:I17) -> 3.3298916 | D26: =MIN(J6:J17) -> 16.808511
B28: # deals included (n) | C28: =COUNT(I6:I17) -> 10 | D28: =COUNT(J6:J17) -> 7
B30: Median row references (for reviewer QA): 25th/Median/75th EV/LTM EBITDA computed via QUARTILE.INC/MEDIAN over helper column J6:J17 (blank for Include=0 or n.m. rows, which QUARTILE.INC/MEDIAN ignore as text). E9 research recommendation (6-deal core, pre-suite-deal expansion): median EV/EBITDA ~28.6x, median EV/Revenue ~8.3x.
B31: Mean uses AVERAGE over the same Include-flag helper column (Excel's AVERAGE ignores the blank-text '' results), so it also ignores n.m./Include=0 rows.
B33: Secondary Statistics - By Era (Include=1 deals only)
B34: Statistic | C34: EV/Rev 2016-19 | D34: EV/EBITDA 2016-19 | E34: EV/Rev 2020-24 | F34: EV/EBITDA 2020-24
B35: Max | C35: =MAX(K6:K17) -> 8.7333333 | D35: =MAX(L6:L17) -> 33.589744 | E35: =MAX(M6:M17) -> 43.968254 | F35: =MAX(N6:N17) -> 67.542522
B36: 75th pctile | C36: =_xlfn.QUARTILE.INC(K6:K17,3) -> 6.745977 | D36: =_xlfn.QUARTILE.INC(L6:L17,3) -> 26.690221 | E36: =_xlfn.QUARTILE.INC(M6:M17,3) -> 12.667192 | F36: =_xlfn.QUARTILE.INC(N6:N17,3) -> 46.634476
B37: Median | C37: =MEDIAN(K6:K17) -> 4.7586207 | D37: =MEDIAN(L6:L17) -> 19.790698 | E37: =MEDIAN(M6:M17) -> 7.8068182 | F37: =MEDIAN(N6:N17) -> 28.676314
B38: 25th pctile | C38: =_xlfn.QUARTILE.INC(K6:K17,1) -> 4.485746 | D38: =_xlfn.QUARTILE.INC(L6:L17,1) -> 19.070881 | E38: =_xlfn.QUARTILE.INC(M6:M17,1) -> 5.3984567 | F38: =_xlfn.QUARTILE.INC(N6:N17,1) -> 17.467753
B39: Min | C39: =MIN(K6:K17) -> 4.2128713 | D39: =MIN(L6:L17) -> 18.351064 | E39: =MIN(M6:M17) -> 3.3298916 | F39: =MIN(N6:N17) -> 16.808511
B41: Era split shows the multiple regime shift: 2016-19 cohort (LinkedIn, Mellanox, Disney/Fox) vs. 2020-24 cohort (Activision, Slack [rev only], Xilinx [rev only], Cerner, Twitter, XOM/Pioneer, Broadcom/VMware).

Sheet ImpliedVal
B2: ImpliedVal - Precedent-Multiple Implied Valuation of DCF Subjects
B3: ($ in millions except per-share; multiples from Precedents core-set stats block)
B4: Note: precedent multiples embed a control premium (deals above averaged ~30-45% 1-day premium); these ranges sit ABOVE trading-comps (minority-stake) valuations and feed the football-field 'precedent transactions' bar in workbook 10.
B6: MSFT - Microsoft Corporation
B7: Metric | C7: Low (25th) | D7: Mid (Median) | E7: High (75th) | G7: Notes
B8: LTM Revenue ($mm) | C8: 290000 | G8: Per E4 comps data pack (as of 8/21/26).
B9: LTM EBITDA ($mm) | C9: 193800 | G9: Per E4 comps pack (12mo ended 6/30/26, YF); direct figure.
B10: Net Debt ($mm) [debt - cash & inv.] | C10: -36500 | G10: Per E1/E2/E3/E4 data packs; negative = net cash.
B11: Diluted Shares (mm) | C11: 7420
B12: Current Share Price | C12: 483.24 | G12: Close 8/21/26 per E4 comps pack.
B14: Applied EV/LTM EBITDA multiple | C14: =Precedents!D25 -> 18.019282 | D14: =Precedents!D24 -> 19.790698 | E14: =Precedents!D22 -> 36.627435
B15: Implied EV ($mm) | C15: =C14*$C$9 -> 3492136.8 | D15: =D14*$C$9 -> 3835437.2 | E15: =E14*$C$9 -> 7098397
B16: Less: Net Debt ($mm) | C16: =-$C$10 -> 36500 | D16: =-$C$10 -> 36500 | E16: =-$C$10 -> 36500
B17: Implied Equity Value ($mm) | C17: =C15+C16 -> 3528636.8 | D17: =D15+D16 -> 3871937.2 | E17: =E15+E16 -> 7134897
B18: Implied Share Price (EV/EBITDA method) | C18: =C17/$C$11 -> 475.55752 | D18: =D17/$C$11 -> 521.82442 | E18: =E17/$C$11 -> 961.57641
B20: Applied EV/LTM Revenue multiple | C20: =Precedents!C25 -> 4.7887931 | D20: =Precedents!C24 -> 6.8622106 | E20: =Precedents!C22 -> 8.9841207
B21: Implied EV ($mm) | C21: =C20*$C$8 -> 1388750 | D21: =D20*$C$8 -> 1990041.1 | E21: =E20*$C$8 -> 2605395
B22: Less: Net Debt ($mm) | C22: =-$C$10 -> 36500 | D22: =-$C$10 -> 36500 | E22: =-$C$10 -> 36500
B23: Implied Equity Value ($mm) | C23: =C21+C22 -> 1425250 | D23: =D21+D22 -> 2026541.1 | E23: =E21+E22 -> 2641895
B24: Implied Share Price (EV/Revenue method) | C24: =C23/$C$11 -> 192.08221 | D24: =D23/$C$11 -> 273.11874 | E24: =E23/$C$11 -> 356.05054
B25: Memo: Current Share Price | C25: =$C$12 -> 483.24 | D25: =$C$12 -> 483.24 | E25: =$C$12 -> 483.24
B26: Implied Upside/(Downside) vs. Current (EV/EBITDA) | C26: =C18/$C$12-1 -> -0.015897846 | D26: =D18/$C$12-1 -> 0.079845256 | E26: =E18/$C$12-1 -> 0.98985268
B27: Implied Upside/(Downside) vs. Current (EV/Revenue) | C27: =C24/$C$12-1 -> -0.60251177 | D27: =D24/$C$12-1 -> -0.4348176 | E27: =E24/$C$12-1 -> -0.26320143
B30: NVDA - NVIDIA Corporation
B31: Metric | C31: Low (25th) | D31: Mid (Median) | E31: High (75th) | G31: Notes
B32: LTM Revenue ($mm) | C32: 254000 | G32: Per E4 comps data pack (as of 8/21/26).
B33: LTM EBITDA ($mm) | C33: 133230 | G33: Derived: FY2026 Op Income $130,387mm + D&A $2,843mm (LTM proxy).
B34: Net Debt ($mm) [debt - cash & inv.] | C34: -51144 | G34: Per E1/E2/E3/E4 data packs; negative = net cash.
B35: Diluted Shares (mm) | C35: 24200
B36: Current Share Price | C36: 214.72 | G36: Close 8/21/26 per E4 comps pack.
B38: Applied EV/LTM EBITDA multiple | C38: =Precedents!D25 -> 18.019282 | D38: =Precedents!D24 -> 19.790698 | E38: =Precedents!D22 -> 36.627435
B39: Implied EV ($mm) | C39: =C38*$C$33 -> 2400708.9 | D39: =D38*$C$33 -> 2636714.7 | E39: =E38*$C$33 -> 4879873.2
B40: Less: Net Debt ($mm) | C40: =-$C$34 -> 51144 | D40: =-$C$34 -> 51144 | E40: =-$C$34 -> 51144
B41: Implied Equity Value ($mm) | C41: =C39+C40 -> 2451852.9 | D41: =D39+D40 -> 2687858.7 | E41: =E39+E40 -> 4931017.2
B42: Implied Share Price (EV/EBITDA method) | C42: =C41/$C$35 -> 101.31624 | D42: =D41/$C$35 -> 111.06854 | E42: =E41/$C$35 -> 203.76104
B44: Applied EV/LTM Revenue multiple | C44: =Precedents!C25 -> 4.7887931 | D44: =Precedents!C24 -> 6.8622106 | E44: =Precedents!C22 -> 8.9841207
B45: Implied EV ($mm) | C45: =C44*$C$32 -> 1216353.4 | D45: =D44*$C$32 -> 1743001.5 | E45: =E44*$C$32 -> 2281966.7
B46: Less: Net Debt ($mm) | C46: =-$C$34 -> 51144 | D46: =-$C$34 -> 51144 | E46: =-$C$34 -> 51144
B47: Implied Equity Value ($mm) | C47: =C45+C46 -> 1267497.4 | D47: =D45+D46 -> 1794145.5 | E47: =E45+E46 -> 2333110.7
B48: Implied Share Price (EV/Revenue method) | C48: =C47/$C$35 -> 52.375928 | D48: =D47/$C$35 -> 74.138243 | E48: =E47/$C$35 -> 96.409532
...
