Workbook

Sheet Cover Page
B2: SFR and 0 Equity Model
B3: Created By Akul Veauli
B4: On
B5: 45992
B8: For use for potential 0 equity purchases as well as SFR properties with Value add potential or General hold. Multiple adjustable cases are available in the inputs page if you adjust as needed.
C18: = calcuated
C19: = assumptions or inputs

Sheet Inputs & Assumptions
B2: Case Switches | D2: Value, Mortgage, Tax, Growth and Turnover
B4: Market Value | D4: General Assumptions | E4: Annual | F4: Monthly | H4: Pre Value add | I4: Value add
B5: 500000 | D5: US Mortgage Interest Rate | E5: 0.06 | F5: =(1+E5)^(1/12)-1 -> 0.0048675506 | H5: Rent | I5: Rent
D6: CAD Mortgage Interst Rate Annualized | H6: 2300 | I6: =H6*(1+B32) -> 2645
B7: Investment Strategy | D7: Mortgage Term | E7: =F7*12 -> 360 | F7: 30
B8: Renovate | D8: Discount Factor | E8: 0.05 | H8: Property Tax Assumptions
D9: Insurance liability protection | E9: N/A | H9: Texas | I9: 0.02
B10: Case Number | D10: Other Insurance Risks | H10: Ohio | I10: 0.018
B11: 1 | D11: Age of Property | H11: Ontario | I11: 0.009
D12: Month of Purchase
B13: Region | D13: RM | E13: 1200 | F13: 100 | H13: Region | I13: Case Number
B14: 1 | D14: RM Growth % | E14: 0 | F14: 0 | H14: Texas | I14: 1
D15: Utilities | E15: Tenant Pays | F15: Tenant pays | H15: Ohio | I15: 2
B16: Prop Mgmt Case | D16: Utilities Growth % | E16: 0 | F16: 0 | H16: Ontario | I16: 3
B17: Full Time | D17: add utilities section too if possible, not relavent for now but makes it future proof of a model
F18: Per Period | H18: Annual | I18: Annual | J18: Monthly
B19: Purchase Date | D19: Case Number | E19: Mortgage Balance | F19: Mortgage Payments | G19: Closing Costs | H19: Property Tax | I19: Insurance Cost | J19: Insurance Cost
B20: =TODAY() -> 45997 | D20: 1 | E20: 485000 | F20: =E20 * ($F$5 * (1 + $F$5) ^ $E$7) / ((1 + $F$5) ^ $E$7 - 1) -> 2858.4465 | G20: 5000 | H20: =CHOOSE($B$14,$I$9,$I$10,$I$11)*$B$5 -> 10000 | I20: =$B$5*$E$99*CHOOSE($B$14,$E$104,$E$105,$E$106) -> 3000 | J20: =I20/12 -> 250
D21: 2 | E21: 490000 | F21: =E21 * ($F$5 * (1 + $F$5) ^ $E$7) / ((1 + $F$5) ^ $E$7 - 1) -> 2887.915 | G21: 5000 | H21: =CHOOSE($B$14,$I$9,$I$10,$I$11)*$B$5 -> 10000 | I21: =$B$5*$E$99*CHOOSE($B$14,$E$104,$E$105,$E$106) -> 3000 | J21: =I21/12 -> 250
B22: Tax Pay Date | D22: 3 | E22: 495000 | F22: =E22 * ($F$5 * (1 + $F$5) ^ $E$7) / ((1 + $F$5) ^ $E$7 - 1) -> 2917.3836 | G22: 5000 | H22: =CHOOSE($B$14,$I$9,$I$10,$I$11)*$B$5 -> 10000 | I22: =$B$5*$E$99*CHOOSE($B$14,$E$104,$E$105,$E$106) -> 3000 | J22: =I22/12 -> 250
B23: =IF(B20>DATE(YEAR(B20),5,1), DATE(YEAR(B20)+1,5,1), DATE(YEAR(B20),5,1) ) -> 46143 | D23: 4 | E23: 500000 | F23: =E23 * ($F$5 * (1 + $F$5) ^ $E$7) / ((1 + $F$5) ^ $E$7 - 1) -> 2946.8521 | G23: 5000 | H23: =CHOOSE($B$14,$I$9,$I$10,$I$11)*$B$5 -> 10000 | I23: =$B$5*$E$99*CHOOSE($B$14,$E$104,$E$105,$E$106) -> 3000 | J23: =I23/12 -> 250
D24: 5 | E24: 505000 | F24: =E24 * ($F$5 * (1 + $F$5) ^ $E$7) / ((1 + $F$5) ^ $E$7 - 1) -> 2976.3206 | G24: 5000 | H24: =CHOOSE($B$14,$I$9,$I$10,$I$11)*$B$5 -> 10000 | I24: =$B$5*$E$99*CHOOSE($B$14,$E$104,$E$105,$E$106) -> 3000 | J24: =I24/12 -> 250
B25: Lease Start Date | D25: 6 | E25: 510000 | F25: =E25 * ($F$5 * (1 + $F$5) ^ $E$7) / ((1 + $F$5) ^ $E$7 - 1) -> 3005.7891 | G25: 5000 | H25: =CHOOSE($B$14,$I$9,$I$10,$I$11)*$B$5 -> 10000 | I25: =$B$5*$E$99*CHOOSE($B$14,$E$104,$E$105,$E$106) -> 3000 | J25: =I25/12 -> 250
B26: 46054
D27: Property Taxes
B28: Rent Increase Frequency | E28: Year 0 | F28: Year 1 | G28: Year 2 | H28: Year 3 | I28: Year 4 | J28: Year 5
B29: 12 | D29: Tax | E29: 5 | F29: 5 | G29: 5 | H29: 5 | I29: 5 | J29: 5
D30: Tax Growth (%) | E30: - | F30: =IFERROR(F29/E29-1,"-") -> 0 | G30: =IFERROR(G29/F29-1,"-") -> 0 | H30: =IFERROR(H29/G29-1,"-") -> 0 | I30: =IFERROR(I29/H29-1,"-") -> 0 | J30: =IFERROR(J29/I29-1,"-") -> 0
B31: Renovation Factor
B32: 0.15 | D32: Turnover and Vacancy Assumptions
E33: Yearly | F33: Year 1 | G33: Year 2 | H33: Year 3 | I33: Year 4 | J33: Year 5
D34: Turnover
D35: Residential Vacancy
E37: P.A. | G37: P.M.
D38: Growth Rate Assumptions | E38: Property Value | F38: Rent Increase | G38: Property Value | H38: Rent Increase | I38: Rent Change Rules
D39: Texas | E39: 0.03 | F39: 0.03 | G39: =(1+E39)^(1/12)-1 -> 0.0024662698 | H39: =(1+F39)^(1/12)-1 -> 0.0024662698 | I39: No
D40: Ohio | E40: 0.04 | F40: 0.03 | G40: =(1+E40)^(1/12)-1 -> 0.0032737398 | H40: =(1+F40)^(1/12)-1 -> 0.0024662698 | I40: No
D41: Ontario | E41: 0.01 | F41: 0.021 | G41: =(1+E41)^(1/12)-1 -> 0.00082953811 | H41: =(1+F41)^(1/12)-1 -> 0.0017333788 | I41: Every 12m
D43: Land Transfer Tax | E43: State | F43: County | G43: Fed | H43: Total
D44: Texas | E44: 0 | F44: 0 | G44: 0 | H44: =SUM(E44:G44) -> 0
...

Sheet ProForma
B2: Akul Veauli Operating ProForma
K3: Ur moms house
B5: INCOME SUMMARY | F5: Year 1 | G5: Year 2 | H5: Year 3 | I5: Year 4 | J5: Year 5
B6: Turnover
B7: Vanacy
B8: REVENUE | E8: Annual Income | F8: z | G8: 2 | H8: 3 | I8: 4 | J8: 5
C9: Rental Income | F9: =SUM('Monthly Cashflows'!E6:'Monthly Cashflows'!P6) -> 13225 | G9: =SUM('Monthly Cashflows'!Q6:AB6) -> 32136.75 | H9: =SUM('Monthly Cashflows'!AC6:AN6) -> 33100.853 | I9: =SUM('Monthly Cashflows'!AO6:AZ6) -> 34093.878 | J9: =SUM('Monthly Cashflows'!BA6:BL6) -> 35116.694
C10: Interst Income | F10: =SUM('Monthly Cashflows'!E12:P12) -> 0 | G10: =SUM('Monthly Cashflows'!Q12:AB12) -> 0 | H10: =SUM('Monthly Cashflows'!AC12:AN12) -> 0 | I10: =SUM('Monthly Cashflows'!AO12:AZ12) -> 0 | J10: =SUM('Monthly Cashflows'!BA12:BL12) -> 0
B11: EFFECTIVE GROSS INCOME | F11: =F9+F10 -> 13225 | G11: =G9+G10 -> 32136.75 | H11: =H9+H10 -> 33100.853 | I11: =I9+I10 -> 34093.878 | J11: =J9+J10 -> 35116.694
B13: OPERATING EXPENSES
C14: Mortgage | F14: =CHOOSE('Inputs & Assumptions'!B11,'Inputs & Assumptions'!F20,'Inputs & Assumptions'!F21,'Inputs & Assumptions'!F22,'Inputs & Assumptions'!F23,'Inputs & Assumptions'!F24,'Inputs & Assumptions'!F25)*12 -> 34301.358 | G14: =F14 -> 34301.358 | H14: =G14 -> 34301.358 | I14: =H14 -> 34301.358 | J14: =I14 -> 34301.358
C15: Taxes | F15: ='Inputs & Assumptions'!F29 -> 5 | G15: ='Inputs & Assumptions'!G29 -> 5 | H15: ='Inputs & Assumptions'!H29 -> 5 | I15: ='Inputs & Assumptions'!I29 -> 5 | J15: ='Inputs & Assumptions'!J29 -> 5
C16: Insurance | F16: =CHOOSE('Inputs & Assumptions'!B11,'Inputs & Assumptions'!I20,'Inputs & Assumptions'!I21,'Inputs & Assumptions'!I22,'Inputs & Assumptions'!I23,'Inputs & Assumptions'!I24,'Inputs & Assumptions'!I25) -> 3000 | G16: =F16 -> 3000 | H16: =G16 -> 3000 | I16: =H16 -> 3000 | J16: =I16 -> 3000
C17: Vacancy | F17: =SUM('Monthly Cashflows'!E20:P20) -> 0 | G17: =SUM('Monthly Cashflows'!Q20:AB20) -> 0 | H17: =SUM('Monthly Cashflows'!AC20:AN20) -> 0 | I17: =SUM('Monthly Cashflows'!AO20:AZ20) -> 0 | J17: =SUM('Monthly Cashflows'!BA20:BL20) -> 0
C18: Turnover | F18: =SUM('Monthly Cashflows'!E21:P21) -> 0 | G18: =SUM('Monthly Cashflows'!Q21:AB21) -> 0 | H18: =SUM('Monthly Cashflows'!AC21:AN21) -> 0 | I18: =SUM('Monthly Cashflows'!AO21:AZ21) -> 0 | J18: =SUM('Monthly Cashflows'!BA21:BL21) -> 0
C19: R&M | F19: ='Inputs & Assumptions'!E13 -> 1200 | G19: =F19*(1+'Inputs & Assumptions'!$E$14) -> 1200 | H19: =G19*(1+'Inputs & Assumptions'!$E$14) -> 1200 | I19: =H19*(1+'Inputs & Assumptions'!$E$14) -> 1200 | J19: =I19*(1+'Inputs & Assumptions'!$E$14) -> 1200
C20: G & A / Leasing & Marketing | F20: =CHOOSE('Inputs & Assumptions'!$B$14,'Inputs & Assumptions'!E87,'Inputs & Assumptions'!E88,'Inputs & Assumptions'!E89) -> 4900 | G20: =CHOOSE('Inputs & Assumptions'!$B$14,'Inputs & Assumptions'!F87,'Inputs & Assumptions'!F88,'Inputs & Assumptions'!F89) -> 400 | H20: =CHOOSE('Inputs & Assumptions'!$B$14,'Inputs & Assumptions'!G87,'Inputs & Assumptions'!G88,'Inputs & Assumptions'!G89) -> 400 | I20: =CHOOSE('Inputs & Assumptions'!$B$14,'Inputs & Assumptions'!H87,'Inputs & Assumptions'!H88,'Inputs & Assumptions'!H89) -> 400 | J20: =CHOOSE('Inputs & Assumptions'!$B$14,'Inputs & Assumptions'!I87,'Inputs & Assumptions'!I88,'Inputs & Assumptions'!I89) -> 400
C21: Property Management | F21: =SUM('Monthly Cashflows'!E26:P26) -> 1058 | G21: =SUM('Monthly Cashflows'!F26:Q26) -> 1269.6 | H21: =SUM('Monthly Cashflows'!G26:R26) -> 1481.2 | I21: =SUM('Monthly Cashflows'!H26:S26) -> 1692.8 | J21: =SUM('Monthly Cashflows'!I26:T26) -> 1904.4
C22: Other | F22: =SUM('Monthly Cashflows'!E27:P27) -> 0 | G22: =SUM('Monthly Cashflows'!F27:Q27) -> 0 | H22: =SUM('Monthly Cashflows'!G27:R27) -> 0 | I22: =SUM('Monthly Cashflows'!H27:S27) -> 0 | J22: =SUM('Monthly Cashflows'!I27:T27) -> 0
B23: TOTAL OPERATING EXPENSES | F23: =SUM(F14:F21) -> 44464.358 | G23: =+SUM(G14:G21) -> 40175.958 | H23: =+SUM(H14:H21) -> 40387.558 | I23: =+SUM(I14:I21) -> 40599.158 | J23: =+SUM(J14:J21) -> 40810.758
B25: Capital Expneses
C26: Construction | F26: =SUM('Monthly Cashflows'!E19:P19) -> 20051.75 | G26: =SUM('Monthly Cashflows'!Q19:AB19) -> 0 | H26: =SUM('Monthly Cashflows'!AC19:AN19) -> 0 | I26: =SUM('Monthly Cashflows'!AO19:AZ19) -> 0 | J26: =SUM('Monthly Cashflows'!BA19:BL19) -> 0
C27: idk other capex lmao
B28: Total Capex | F28: =SUM(F24:F27) -> 20051.75 | G28: =SUM(G24:G27) -> 0 | H28: =SUM(H24:H27) -> 0 | I28: =SUM(I24:I27) -> 0 | J28: =SUM(J24:J27) -> 0
B29: Net Income | F29: =+F11-F23-F28 -> -51291.108 | G29: =+G11-G23-G28 -> -8039.2083 | H29: =+H11-H23-H28 -> -7286.7058 | I29: =+I11-I23-I28 -> -6505.2802 | J29: =+J11-J23-J28 -> -5694.0639
B31: Total Debt Service | F31: =F14 -> 34301.358 | G31: =G14 -> 34301.358 | H31: =H14 -> 34301.358 | I31: =I14 -> 34301.358 | J31: =J14 -> 34301.358
B32: Total Interest Payment | F32: =SUM('Monthly Cashflows'!E17:P17) -> 28166.636 | G32: =SUM('Monthly Cashflows'!Q17:AB17) -> 27798.553 | H32: =SUM('Monthly Cashflows'!AC17:AN17) -> 27408.385 | I32: =SUM('Monthly Cashflows'!AO17:AZ17) -> 26994.806 | J32: =SUM('Monthly Cashflows'!BA17:BL17) -> 26556.413
B33: Total Principal Payment | F33: =SUM('Monthly Cashflows'!E16:P16) -> 6134.7221 | G33: =SUM('Monthly Cashflows'!Q16:AB16) -> 6502.8054 | H33: =SUM('Monthly Cashflows'!AC16:AN16) -> 6892.9737 | I33: =SUM('Monthly Cashflows'!AO16:AZ16) -> 7306.5521 | J33: =SUM('Monthly Cashflows'!BA16:BL16) -> 7744.9453
B35: INTEREST COVERAGE RATIO | F35: =+F29/F32*-1 -> 1.8209881 | G35: =+G29/G32*-1 -> 0.28919521 | H35: =+H29/H32*-1 -> 0.26585681 | I35: =+I29/I32*-1 -> 0.24098266 | J35: =+J29/J32*-1 -> 0.21441389
B36: DEBT SERVICE COVERAGE RATIO | F36: =+F29/F31*-1 -> 1.4953084 | G36: =+G29/G31*-1 -> 0.23436997 | H36: =+H29/H31*-1 -> 0.21243199 | I36: =+I29/I31*-1 -> 0.1896508 | J36: =+J29/J31*-1 -> 0.16600112
B37: DEBT CAP RATE | F37: =+F29/$E$41 -> -0.10575486 | G37: =+G29/$E$41 -> -0.016575687 | H37: =+H29/$E$41 -> -0.015024136 | I37: =+I29/$E$41 -> -0.013412949 | J37: =+J29/$E$41 -> -0.011740338
B39: FEASIBILITY ANALYSIS
C41: Total Loan Amount | E41: =CHOOSE('Inputs & Assumptions'!B11,'Inputs & Assumptions'!E20,'Inputs & Assumptions'!E21,'Inputs & Assumptions'!E22,'Inputs & Assumptions'!E23,'Inputs & Assumptions'!E24,'Inputs & Assumptions'!E25) -> 485000
C42: Purchase Price | E42: ='Inputs & Assumptions'!B5 -> 500000
C43: Debt to Appraised Value:
C44: Effective Gross Income
B45: Notes:

Sheet Sensitivity
C2: ALL AMOUNTS ANNUAL
B3: Category | C3: 1 | D3: 2 | E3: 3 | F3: 4 | G3: 5
B4: Rent | C4: =SUM('Monthly Cashflows'!E6:'Monthly Cashflows'!P6) -> 13225 | D4: =SUM('Monthly Cashflows'!Q6:AB6) -> 32136.75 | E4: =SUM('Monthly Cashflows'!AC6:AN6) -> 33100.853 | F4: =SUM('Monthly Cashflows'!AO6:AZ6) -> 34093.878 | G4: =SUM('Monthly Cashflows'!BA6:BL6) -> 35116.694
B5: Int income on excess cash | C5: =SUM('Monthly Cashflows'!E12:P12) -> 0 | D5: =SUM('Monthly Cashflows'!Q12:AB12) -> 0 | E5: =SUM('Monthly Cashflows'!AC12:AN12) -> 0 | F5: =SUM('Monthly Cashflows'!AO12:AZ12) -> 0 | G5: =SUM('Monthly Cashflows'!BA12:BL12) -> 0
B7: Mortgage | C7: =CHOOSE('Inputs & Assumptions'!B11,'Inputs & Assumptions'!F20,'Inputs & Assumptions'!F21,'Inputs & Assumptions'!F22,'Inputs & Assumptions'!F23,'Inputs & Assumptions'!F24,'Inputs & Assumptions'!F25)*12 -> 34301.358 | D7: =C7 -> 34301.358 | E7: =D7 -> 34301.358 | F7: =E7 -> 34301.358 | G7: =F7 -> 34301.358
B8: Vacancy & Turnover Costs | C8: =SUM(ProForma!F17:F18) -> 0 | D8: =SUM(ProForma!G17:G18) -> 0 | E8: =SUM(ProForma!H17:H18) -> 0 | F8: =SUM(ProForma!I17:I18) -> 0 | G8: =SUM(ProForma!J17:J18) -> 0
B9: Construction Costs | C9: =SUM('Monthly Cashflows'!E19:P19) -> 20051.75 | D9: =SUM('Monthly Cashflows'!Q19:AB19) -> 0 | E9: =SUM('Monthly Cashflows'!AC19:AN19) -> 0 | F9: =SUM('Monthly Cashflows'!AO19:AZ19) -> 0 | G9: =SUM('Monthly Cashflows'!BA19:BL19) -> 0
B10: Taxes | C10: =ProForma!F15 -> 5 | D10: =ProForma!G15 -> 5 | E10: =ProForma!H15 -> 5 | F10: =ProForma!I15 -> 5 | G10: =ProForma!J15 -> 5
B11: Insurance | C11: =CHOOSE('Inputs & Assumptions'!B11,'Inputs & Assumptions'!I20,'Inputs & Assumptions'!I21,'Inputs & Assumptions'!I22,'Inputs & Assumptions'!I23,'Inputs & Assumptions'!I24,'Inputs & Assumptions'!I25) -> 3000 | D11: =C11 -> 3000 | E11: =D11 -> 3000 | F11: =E11 -> 3000 | G11: =F11 -> 3000
B12: R&M | C12: ='Inputs & Assumptions'!E13 -> 1200 | D12: =C12*('Inputs & Assumptions'!$E$14+1) -> 1200 | E12: =D12*('Inputs & Assumptions'!$E$14+1) -> 1200 | F12: =E12*('Inputs & Assumptions'!$E$14+1) -> 1200 | G12: =F12*('Inputs & Assumptions'!$E$14+1) -> 1200
B13: G & A / Leasing & Marketing | C13: =CHOOSE('Inputs & Assumptions'!$B$14,'Inputs & Assumptions'!E87,'Inputs & Assumptions'!E88,'Inputs & Assumptions'!E89) -> 4900 | D13: =CHOOSE('Inputs & Assumptions'!$B$14,'Inputs & Assumptions'!F87,'Inputs & Assumptions'!F88,'Inputs & Assumptions'!F89) -> 400 | E13: =CHOOSE('Inputs & Assumptions'!$B$14,'Inputs & Assumptions'!G87,'Inputs & Assumptions'!G88,'Inputs & Assumptions'!G89) -> 400 | F13: =CHOOSE('Inputs & Assumptions'!$B$14,'Inputs & Assumptions'!H87,'Inputs & Assumptions'!H88,'Inputs & Assumptions'!H89) -> 400 | G13: =CHOOSE('Inputs & Assumptions'!$B$14,'Inputs & Assumptions'!I87,'Inputs & Assumptions'!I88,'Inputs & Assumptions'!I89) -> 400
B14: Property Management | C14: =SUM('Monthly Cashflows'!E26:P26) -> 1058 | D14: =SUM('Monthly Cashflows'!Q26:AB26) -> 2570.94 | E14: =SUM('Monthly Cashflows'!R26:AC26) -> 2577.288 | F14: =SUM('Monthly Cashflows'!S26:AD26) -> 2583.636 | G14: =SUM('Monthly Cashflows'!T26:AE26) -> 2589.984
B15: Other | C15: =SUM('Monthly Cashflows'!E27:P27) -> 0 | D15: =SUM('Monthly Cashflows'!Q27:AB27) -> 0 | E15: =SUM('Monthly Cashflows'!R27:AC27) -> 0 | F15: =SUM('Monthly Cashflows'!S27:AD27) -> 0 | G15: =SUM('Monthly Cashflows'!T27:AE27) -> 0
B17: Net Annual Cashflows | C17: =C4+C5-SUM(C7:C15) -> -51291.108 | D17: =D4+D5-SUM(D7:D15) -> -9340.5483 | E17: =E4+E5-SUM(E7:E15) -> -8382.7938 | F17: =F4+F5-SUM(F7:F15) -> -7396.1162 | G17: =G4+G5-SUM(G7:G15) -> -6379.6479
B18: NPV | C18: ='Monthly Cashflows'!E31 -> -17528.88

Sheet Monthly Cashflows
E2: Monthly Rent
D3: 0 | E3: 1 | F3: 2 | G3: 3 | H3: 4 | I3: 5 | J3: 6 | K3: 7 | L3: 8 | M3: 9 | N3: 10 | O3: 11 | P3: 12 | Q3: 13 | R3: 14 | S3: 15 | T3: 16 | U3: 17 | V3: 18 | W3: 19 | X3: 20 | Y3: 21 | Z3: 22 | AA3: 23 | AB3: 24 | AC3: 25 | AD3: 26 | AE3: 27 | AF3: 28 | AG3: 29 | AH3: 30 | AI3: 31 | AJ3: 32 | AK3: 33 | AL3: 34 | AM3: 35 | AN3: 36 | AO3: 37 | AP3: 38 | AQ3: 39 | AR3: 40 | AS3: 41 | AT3: 42 | AU3: 43 | AV3: 44 | AW3: 45 | AX3: 46 | AY3: 47 | AZ3: 48 | BA3: 49 | BB3: 50 | BC3: 51 | BD3: 52 | BE3: 53 | BF3: 54 | BG3: 55 | BH3: 56 | BI3: 57 | BJ3: 58 | BK3: 59 | BL3: 60
D4: Year 0 | E4: Year 1 | Q4: Year 2 | AC4: Year 3 | AO4: Year 4 | BA4: Year 5
E5: 1 | F5: 2 | G5: 3 | H5: 4 | I5: 5 | J5: 6 | K5: 7 | L5: 8 | M5: 9 | N5: 10 | O5: 11 | P5: 12 | Q5: 1 | R5: 2 | S5: 3 | T5: 4 | U5: 5 | V5: 6 | W5: 7 | X5: 8 | Y5: 9 | Z5: 10 | AA5: 11 | AB5: 12 | AC5: 1 | AD5: 2 | AE5: 3 | AF5: 4 | AG5: 5 | AH5: 6 | AI5: 7 | AJ5: 8 | AK5: 9 | AL5: 10 | AM5: 11 | AN5: 12 | AO5: 1 | AP5: 2 | AQ5: 3 | AR5: 4 | AS5: 5 | AT5: 6 | AU5: 7 | AV5: 8 | AW5: 9 | AX5: 10 | AY5: 11 | AZ5: 12 | BA5: 1 | BB5: 2 | BC5: 3 | BD5: 4 | BE5: 5 | BF5: 6 | BG5: 7 | BH5: 8 | BI5: 9 | BJ5: 10 | BK5: 11 | BL5: 12
C6: Market Rent | E6: =IF( 'Inputs & Assumptions'!$B$8="Renovate", IF( COLUMN()-COLUMN($E$28) < 'Inputs & Assumptions'!$J$108, "", 'Inputs & Assumptions'!$I$6 * POWER( 1 + CHOOSE('Inputs & Assumptions'!$B$14, 'Inputs & Assumptions'!$F$39, 'Inputs & Assumptions'!$F$40, 'Inputs & Assumptions'!$F$41), INT((COLUMN()-COLUMN($E$28) - 'Inputs & Assumptions'!$J$108) / 'Inputs & Assumptions'!$B$29) ) ), IF( COLUMN()-COLUMN($E$28) < 'Inputs & Assumptions'!$J$102, "", 'Inputs & Assumptions'!$H$6 * POWER( 1 + CHOOSE('Inputs & Assumptions'!$B$14, 'Inputs & Assumptions'!$F$39, 'Inputs & Assumptions'!$F$40, 'Inputs & Assumptions'!$F$41), INT((COLUMN()-COLUMN($E$28) - 'Inputs & Assumptions'!$J$102) / 'Inputs & Assumptions'!$B$29) ) ) ) | F6: =IF( 'Inputs & Assumptions'!$B$8="Renovate", IF( COLUMN()-COLUMN($E$28) < 'Inputs & Assumptions'!$J$108, "", 'Inputs & Assumptions'!$I$6 * POWER( 1 + CHOOSE('Inputs & Assumptions'!$B$14, 'Inputs & Assumptions'!$F$39, 'Inputs & Assumptions'!$F$40, 'Inputs & Assumptions'!$F$41), INT((COLUMN()-COLUMN($E$28) - 'Inputs & Assumptions'!$J$108) / 'Inputs & Assumptions'!$B$29) ) ), IF( COLUMN()-COLUMN($E$28) < 'Inputs & Assumptions'!$J$102, "", 'Inputs & Assumptions'!$H$6 * POWER( 1 + CHOOSE('Inputs & Assumptions'!$B$14, 'Inputs & Assumptions'!$F$39, 'Inputs & Assumptions'!$F$40, 'Inputs & Assumptions'!$F$41), INT((COLUMN()-COLUMN($E$28) - 'Inputs & Assumptions'!$J$102) / 'Inputs & Assumptions'!$B$29) ) ) ) | G6: =IF( 'Inputs & Assumptions'!$B$8="Renovate", IF( COLUMN()-COLUMN($E$28) < 'Inputs & Assumptions'!$J$108, "", 'Inputs & Assumptions'!$I$6 * POWER( 1 + CHOOSE('Inputs & Assumptions'!$B$14, 'Inputs & Assumptions'!$F$39, 'Inputs & Assumptions'!$F$40, 'Inputs & Assumptions'!$F$41), INT((COLUMN()-COLUMN($E$28) - 'Inputs & Assumptions'!$J$108) / 'Inputs & Assumptions'!$B$29) ) ), IF( COLUMN()-COLUMN($E$28) < 'Inputs & Assumptions'!$J$102, "", 'Inputs & Assumptions'!$H$6 * POWER( 1 + CHOOSE('Inputs & Assumptions'!$B$14, 'Inputs & Assumptions'!$F$39, 'Inputs & Assumptions'!$F$40, 'Inputs & Assumptions'!$F$41), INT((COLUMN()-COLUMN($E$28) - 'Inputs & Assumptions'!$J$102) / 'Inputs & Assumptions'!$B$29) ) ) ) | H6: =IF( 'Inputs & Assumptions'!$B$8="Renovate", IF( COLUMN()-COLUMN($E$28) < 'Inputs & Assumptions'!$J$108, "", 'Inputs & Assumptions'!$I$6 * POWER( 1 + CHOOSE('Inputs & Assumptions'!$B$14, 'Inputs & Assumptions'!$F$39, 'Inputs & Assumptions'!$F$40, 'Inputs & Assumptions'!$F$41), INT((COLUMN()-COLUMN($E$28) - 'Inputs & Assumptions'!$J$108) / 'Inputs & Assumptions'!$B$29) ) ), IF( COLUMN()-COLUMN($E$28) < 'Inputs & Assumptions'!$J$102, "", 'Inputs & Assumptions'!$H$6 * POWER( 1 + CHOOSE('Inputs & Assumptions'!$B$14, 'Inputs & Assumptions'!$F$39, 'Inputs & Assumptions'!$F$40, 'Inputs & Assumptions'!$F$41), INT((COLUMN()-COLUMN($E$28) - 'Inputs & Assumptions'!$J$102) / 'Inputs & Assumptions'!$B$29) ) ) ) | I6: =IF( 'Inputs & Assumptions'!$B$8="Renovate", IF( COLUMN()-COLUMN($E$28) < 'Inputs & Assumptions'!$J$108, "", 'Inputs & Assumptions'!$I$6 * POWER( 1 + CHOOSE('Inputs & Assumptions'!$B$14, 'Inputs & Assumptions'!$F$39, 'Inputs & Assumptions'!$F$40, 'Inputs & Assumptions'!$F$41), INT((COLUMN()-COLUMN($E$28) - 'Inputs & Assumptions'!$J$108) / 'Inputs & Assumptions'!$B$29) ) ), IF( COLUMN()-COLUMN($E$28) < 'Inputs & Assumptions'!$J$102, "", 'Inputs & Assumptions'!$H$6 * POWER( 1 + CHOOSE('Inputs & Assumptions'!$B$14, 'Inputs & Assumptions'!$F$39, 'Inputs & Assumptions'!$F$40, 'Inputs & Assumptions'!$F$41), INT((COLUMN()-COLUMN($E$28) - 'Inputs & Assumptions'!$J$102) / 'Inputs & Assumptions'!$B$29) ) ) ) | J6: =IF( 'Inputs & Assumptions'!$B$8="Renovate", IF( COLUMN()-COLUMN($E$28) < 'Inputs & Assumptions'!$J$108, "", 'Inputs & Assumptions'!$I$6 * POWER( 1 + CHOOSE('Inputs & Assumptions'!$B$14, 'Inputs & Assumptions'!$F$39, 'Inputs & Assumptions'!$F$40, 'Inputs & Assumptions'!$F$41), INT((COLUMN()-COLUMN($E$28) - 'Inputs & Assumptions'!$J$108) / 'Inputs & Assumptions'!$B$29) ) ), IF( COLUMN()-COLUMN($E$28) < 'Inputs & Assumptions'!$J$102, "", 'Inputs & Assumptions'!$H$6 * POWER( 1 + CHOOSE('Inputs & Assumptions'!$B$14, 'Inputs & Assumptions'!$F$39, 'Inputs & Assumptions'!$F$40, 'Inputs & Assumptions'!$F$41), INT((COLUMN()-COLUMN($E$28) - 'Inputs & Assumptions'!$J$102) / 'Inputs & Assumptions'!$B$29) ) ) ) | K6: =IF( 'Inputs & Assumptions'!$B$8="Renovate", IF( COLUMN()-COLUMN($E$28) < 'Inputs & Assumptions'!$J$108, "", 'Inputs & Assumptions'!$I$6 * POWER( 1 + CHOOSE('Inputs & Assumptions'!$B$14, 'Inputs & Assumptions'!$F$39, 'Inputs & Assumptions'!$F$40, 'Inputs & Assumptions'!$F$41), INT((COLUMN()-COLUMN($E$28) - 'Inputs & Assumptions'!$J$108) / 'Inputs & Assumptions'!$B$29) ) ), IF( COLUMN()-COLUMN($E$28) < 'Inputs & Assumptions'!$J$102, "", 'Inputs & Assumptions'!$H$6 * POWER( 1 + CHOOSE('Inputs & Assumptions'!$B$14, 'Inputs & Assumptions'!$F$39, 'Inputs & Assumptions'!$F$40, 'Inputs & Assumptions'!$F$41), INT((COLUMN()-COLUMN($E$28) - 'Inputs & Assumptions'!$J$102) / 'Inputs & Assumptions'!$B$29) ) ) ) | L6: =IF( 'Inputs & Assumptions'!$B$8="Renovate", IF( COLUMN()-COLUMN($E$28) < 'Inputs & Assumptions'!$J$108, "", 'Inputs & Assumptions'!$I$6 * POWER( 1 + CHOOSE('Inputs & Assumptions'!$B$14, 'Inputs & Assumptions'!$F$39, 'Inputs & Assumptions'!$F$40, 'Inputs & Assumptions'!$F$41), INT((COLUMN()-COLUMN($E$28) - 'Inputs & Assumptions'!$J$108) / 'Inputs & Assumptions'!$B$29) ) ), IF( COLUMN()-COLUMN($E$28) < 'Inputs & Assumptions'!$J$102, "", 'Inputs & Assumptions'!$H$6 * POWER( 1 + CHOOSE('Inputs & Assumptions'!$B$14, 'Inputs & Assumptions'!$F$39, 'Inputs & Assumptions'!$F$40, 'Inputs & Assumptions'!$F$41), INT((COLUMN()-COLUMN($E$28) - 'Inputs & Assumptions'!$J$102) / 'Inputs & Assumptions'!$B$29) ) ) ) -> 2645 | ... BL6: =IF( 'Inputs & Assumptions'!$B$8="Renovate", IF( COLUMN()-COLUMN($E$28) < 'Inputs & Assumptions'!$J$108, "", 'Inputs & Assumptions'!$I$6 * POWER( 1 + CHOOSE('Inputs & Assumptions'!$B$14, 'Inputs & Assumptions'!$F$39, 'Inputs & Assumptions'!$F$40, 'Inputs & Assumptions'!$F$41), INT((COLUMN()-COLUMN($E$28) - 'Inputs & Assumptions'!$J$108) / 'Inputs & Assumptions'!$B$29) ) ), IF( COLUMN()-COLUMN($E$28) < 'Inputs & Assumptions'!$J$102, "", 'Inputs & Assumptions'!$H$6 * POWER( 1 + CHOOSE('Inputs & Assumptions'!$B$14, 'Inputs & Assumptions'!$F$39, 'Inputs & Assumptions'!$F$40, 'Inputs & Assumptions'!$F$41), INT((COLUMN()-COLUMN($E$28) - 'Inputs & Assumptions'!$J$102) / 'Inputs & Assumptions'!$B$29) ) ) ) -> 2976.9708
C7: Growth % | E7: - | F7: =IFERROR(F6/E6-1,"0") -> 0 | G7: =IFERROR(G6/F6-1,"-") -> - | H7: =IFERROR(H6/G6-1,"-") -> - | I7: =IFERROR(I6/H6-1,"-") -> - | J7: =IFERROR(J6/I6-1,"-") -> - | K7: =IFERROR(K6/J6-1,"-") -> - | L7: =IFERROR(L6/K6-1,"-") -> - | M7: =IFERROR(M6/L6-1,"-") -> 0 | N7: =IFERROR(N6/M6-1,"-") -> 0 | ... BL7: =IFERROR(BL6/BK6-1,"-") -> 0
C9: Property Market Value | E9: ='Inputs & Assumptions'!B5 -> 500000 | F9: =(1+CHOOSE('Inputs & Assumptions'!$B$14,'Inputs & Assumptions'!$G$39,'Inputs & Assumptions'!$G$40,'Inputs & Assumptions'!$G$41))*'Monthly Cashflows'!E9 -> 501233.13 | G9: =(1+CHOOSE('Inputs & Assumptions'!$B$14,'Inputs & Assumptions'!$G$39,'Inputs & Assumptions'!$G$40,'Inputs & Assumptions'!$G$41))*'Monthly Cashflows'!F9 -> 502469.31 | H9: =(1+CHOOSE('Inputs & Assumptions'!$B$14,'Inputs & Assumptions'!$G$39,'Inputs & Assumptions'!$G$40,'Inputs & Assumptions'!$G$41))*'Monthly Cashflows'!G9 -> 503708.54 | I9: =(1+CHOOSE('Inputs & Assumptions'!$B$14,'Inputs & Assumptions'!$G$39,'Inputs & Assumptions'!$G$40,'Inputs & Assumptions'!$G$41))*'Monthly Cashflows'!H9 -> 504950.82 | J9: =(1+CHOOSE('Inputs & Assumptions'!$B$14,'Inputs & Assumptions'!$G$39,'Inputs & Assumptions'!$G$40,'Inputs & Assumptions'!$G$41))*'Monthly Cashflows'!I9 -> 506196.16 | K9: =(1+CHOOSE('Inputs & Assumptions'!$B$14,'Inputs & Assumptions'!$G$39,'Inputs & Assumptions'!$G$40,'Inputs & Assumptions'!$G$41))*'Monthly Cashflows'!J9 -> 507444.58 | L9: =(1+CHOOSE('Inputs & Assumptions'!$B$14,'Inputs & Assumptions'!$G$39,'Inputs & Assumptions'!$G$40,'Inputs & Assumptions'!$G$41))*'Monthly Cashflows'!K9 -> 508696.07 | M9: =(1+CHOOSE('Inputs & Assumptions'!$B$14,'Inputs & Assumptions'!$G$39,'Inputs & Assumptions'!$G$40,'Inputs & Assumptions'!$G$41))*'Monthly Cashflows'!L9 -> 509950.66 | ... BL9: =(1+CHOOSE('Inputs & Assumptions'!$B$14,'Inputs & Assumptions'!$G$39,'Inputs & Assumptions'!$G$40,'Inputs & Assumptions'!$G$41))*'Monthly Cashflows'!BK9 -> 578211.01
C10: Growth % | E10: 0 | F10: =IFERROR(F9/E9-1,"0") -> 0.0024662698 | G10: =IFERROR(G9/F9-1,"-") -> 0.0024662698 | H10: =IFERROR(H9/G9-1,"-") -> 0.0024662698 | I10: =IFERROR(I9/H9-1,"-") -> 0.0024662698 | J10: =IFERROR(J9/I9-1,"-") -> 0.0024662698 | K10: =IFERROR(K9/J9-1,"-") -> 0.0024662698 | L10: =IFERROR(L9/K9-1,"-") -> 0.0024662698 | M10: =IFERROR(M9/L9-1,"-") -> 0.0024662698 | N10: =IFERROR(N9/M9-1,"-") -> 0.0024662698 | ... BL10: =IFERROR(BL9/BK9-1,"-") -> 0.0024662698
C12: Excess cash | E12: 0 | F12: =IF(E29>0,E29,"0") -> 0 | G12: =IF(F29>0,F29,"0") -> 0 | H12: =IF(G29>0,G29,"0") -> 0 | I12: =IF(H29>0,H29,"0") -> 0 | J12: =IF(I29>0,I29,"0") -> 0 | K12: =IF(J29>0,J29,"0") -> 0 | L12: =IF(K29>0,K29,"0") -> 0 | M12: =IF(L29>0,L29,"0") -> 0 | ... BL12: =IF(BK29>0,BK29,"0") -> 0
C13: Growth % | E13: 0 | F13: =IFERROR(F12/E12-1,"0") -> 0 | G13: =IFERROR(G12/F12-1,"0") -> 0 | H13: =IFERROR(H12/G12-1,"0") -> 0 | I13: =IFERROR(I12/H12-1,"0") -> 0 | J13: =IFERROR(J12/I12-1,"0") -> 0 | K13: =IFERROR(K12/J12-1,"0") -> 0 | L13: =IFERROR(L12/K12-1,"0") -> 0 | M13: =IFERROR(M12/L12-1,"0") -> 0 | ... BL13: =IFERROR(BL12/BK12-1,"0") -> 0
C15: Mortgage | E15: =CHOOSE('Inputs & Assumptions'!B11,'Inputs & Assumptions'!F20,'Inputs & Assumptions'!F21,'Inputs & Assumptions'!F22,'Inputs & Assumptions'!F23,'Inputs & Assumptions'!F24,'Inputs & Assumptions'!F25) -> 2858.4465 | F15: =E15 -> 2858.4465 | G15: =F15 -> 2858.4465 | H15: =G15 -> 2858.4465 | I15: =H15 -> 2858.4465 | J15: =I15 -> 2858.4465 | K15: =J15 -> 2858.4465 | L15: =K15 -> 2858.4465 | M15: =L15 -> 2858.4465 | ... BL15: =BK15 -> 2858.4465
C16: Principal | E16: =PPMT('Inputs & Assumptions'!$E$109,'Monthly Cashflows'!E3,'Inputs & Assumptions'!$E$7,(-CHOOSE('Inputs & Assumptions'!$B$11,'Inputs & Assumptions'!$E$20,'Inputs & Assumptions'!$E$21,'Inputs & Assumptions'!$E$22,'Inputs & Assumptions'!$E$23,'Inputs & Assumptions'!$E$24,'Inputs & Assumptions'!$E$25))) -> 497.6845 | F16: =PPMT('Inputs & Assumptions'!$E$109,'Monthly Cashflows'!F3,'Inputs & Assumptions'!$E$7,(-CHOOSE('Inputs & Assumptions'!$B$11,'Inputs & Assumptions'!$E$20,'Inputs & Assumptions'!$E$21,'Inputs & Assumptions'!$E$22,'Inputs & Assumptions'!$E$23,'Inputs & Assumptions'!$E$24,'Inputs & Assumptions'!$E$25))) -> 500.107 | G16: =PPMT('Inputs & Assumptions'!$E$109,'Monthly Cashflows'!G3,'Inputs & Assumptions'!$E$7,(-CHOOSE('Inputs & Assumptions'!$B$11,'Inputs & Assumptions'!$E$20,'Inputs & Assumptions'!$E$21,'Inputs & Assumptions'!$E$22,'Inputs & Assumptions'!$E$23,'Inputs & Assumptions'!$E$24,'Inputs & Assumptions'!$E$25))) -> 502.5413 | H16: =PPMT('Inputs & Assumptions'!$E$109,'Monthly Cashflows'!H3,'Inputs & Assumptions'!$E$7,(-CHOOSE('Inputs & Assumptions'!$B$11,'Inputs & Assumptions'!$E$20,'Inputs & Assumptions'!$E$21,'Inputs & Assumptions'!$E$22,'Inputs & Assumptions'!$E$23,'Inputs & Assumptions'!$E$24,'Inputs & Assumptions'!$E$25))) -> 504.98744 | I16: =PPMT('Inputs & Assumptions'!$E$109,'Monthly Cashflows'!I3,'Inputs & Assumptions'!$E$7,(-CHOOSE('Inputs & Assumptions'!$B$11,'Inputs & Assumptions'!$E$20,'Inputs & Assumptions'!$E$21,'Inputs & Assumptions'!$E$22,'Inputs & Assumptions'!$E$23,'Inputs & Assumptions'!$E$24,'Inputs & Assumptions'!$E$25))) -> 507.4455 | J16: =PPMT('Inputs & Assumptions'!$E$109,'Monthly Cashflows'!J3,'Inputs & Assumptions'!$E$7,(-CHOOSE('Inputs & Assumptions'!$B$11,'Inputs & Assumptions'!$E$20,'Inputs & Assumptions'!$E$21,'Inputs & Assumptions'!$E$22,'Inputs & Assumptions'!$E$23,'Inputs & Assumptions'!$E$24,'Inputs & Assumptions'!$E$25))) -> 509.91551 | K16: =PPMT('Inputs & Assumptions'!$E$109,'Monthly Cashflows'!K3,'Inputs & Assumptions'!$E$7,(-CHOOSE('Inputs & Assumptions'!$B$11,'Inputs & Assumptions'!$E$20,'Inputs & Assumptions'!$E$21,'Inputs & Assumptions'!$E$22,'Inputs & Assumptions'!$E$23,'Inputs & Assumptions'!$E$24,'Inputs & Assumptions'!$E$25))) -> 512.39755 | L16: =PPMT('Inputs & Assumptions'!$E$109,'Monthly Cashflows'!L3,'Inputs & Assumptions'!$E$7,(-CHOOSE('Inputs & Assumptions'!$B$11,'Inputs & Assumptions'!$E$20,'Inputs & Assumptions'!$E$21,'Inputs & Assumptions'!$E$22,'Inputs & Assumptions'!$E$23,'Inputs & Assumptions'!$E$24,'Inputs & Assumptions'!$E$25))) -> 514.89167 | ... BL16: =PPMT('Inputs & Assumptions'!$E$109,'Monthly Cashflows'!BL3,'Inputs & Assumptions'!$E$7,(-CHOOSE('Inputs & Assumptions'!$B$11,'Inputs & Assumptions'!$E$20,'Inputs & Assumptions'!$E$21,'Inputs & Assumptions'!$E$22,'Inputs & Assumptions'!$E$23,'Inputs & Assumptions'!$E$24,'Inputs & Assumptions'!$E$25))) -> 662.78797
C17: Interest | E17: =IPMT('Inputs & Assumptions'!$E$109,'Monthly Cashflows'!E3,'Inputs & Assumptions'!$E$7,(-CHOOSE('Inputs & Assumptions'!$B$11,'Inputs & Assumptions'!$E$20,'Inputs & Assumptions'!$E$21,'Inputs & Assumptions'!$E$22,'Inputs & Assumptions'!$E$23,'Inputs & Assumptions'!$E$24,'Inputs & Assumptions'!$E$25))) -> 2360.762 | F17: =IPMT('Inputs & Assumptions'!$E$109,'Monthly Cashflows'!F3,'Inputs & Assumptions'!$E$7,(-CHOOSE('Inputs & Assumptions'!$B$11,'Inputs & Assumptions'!$E$20,'Inputs & Assumptions'!$E$21,'Inputs & Assumptions'!$E$22,'Inputs & Assumptions'!$E$23,'Inputs & Assumptions'!$E$24,'Inputs & Assumptions'!$E$25))) -> 2358.3395 | G17: =IPMT('Inputs & Assumptions'!$E$109,'Monthly Cashflows'!G3,'Inputs & Assumptions'!$E$7,(-CHOOSE('Inputs & Assumptions'!$B$11,'Inputs & Assumptions'!$E$20,'Inputs & Assumptions'!$E$21,'Inputs & Assumptions'!$E$22,'Inputs & Assumptions'!$E$23,'Inputs & Assumptions'!$E$24,'Inputs & Assumptions'!$E$25))) -> 2355.9052 | H17: =IPMT('Inputs & Assumptions'!$E$109,'Monthly Cashflows'!H3,'Inputs & Assumptions'!$E$7,(-CHOOSE('Inputs & Assumptions'!$B$11,'Inputs & Assumptions'!$E$20,'Inputs & Assumptions'!$E$21,'Inputs & Assumptions'!$E$22,'Inputs & Assumptions'!$E$23,'Inputs & Assumptions'!$E$24,'Inputs & Assumptions'!$E$25))) -> 2353.4591 | I17: =IPMT('Inputs & Assumptions'!$E$109,'Monthly Cashflows'!I3,'Inputs & Assumptions'!$E$7,(-CHOOSE('Inputs & Assumptions'!$B$11,'Inputs & Assumptions'!$E$20,'Inputs & Assumptions'!$E$21,'Inputs & Assumptions'!$E$22,'Inputs & Assumptions'!$E$23,'Inputs & Assumptions'!$E$24,'Inputs & Assumptions'!$E$25))) -> 2351.001 | J17: =IPMT('Inputs & Assumptions'!$E$109,'Monthly Cashflows'!J3,'Inputs & Assumptions'!$E$7,(-CHOOSE('Inputs & Assumptions'!$B$11,'Inputs & Assumptions'!$E$20,'Inputs & Assumptions'!$E$21,'Inputs & Assumptions'!$E$22,'Inputs & Assumptions'!$E$23,'Inputs & Assumptions'!$E$24,'Inputs & Assumptions'!$E$25))) -> 2348.531 | K17: =IPMT('Inputs & Assumptions'!$E$109,'Monthly Cashflows'!K3,'Inputs & Assumptions'!$E$7,(-CHOOSE('Inputs & Assumptions'!$B$11,'Inputs & Assumptions'!$E$20,'Inputs & Assumptions'!$E$21,'Inputs & Assumptions'!$E$22,'Inputs & Assumptions'!$E$23,'Inputs & Assumptions'!$E$24,'Inputs & Assumptions'!$E$25))) -> 2346.049 | L17: =IPMT('Inputs & Assumptions'!$E$109,'Monthly Cashflows'!L3,'Inputs & Assumptions'!$E$7,(-CHOOSE('Inputs & Assumptions'!$B$11,'Inputs & Assumptions'!$E$20,'Inputs & Assumptions'!$E$21,'Inputs & Assumptions'!$E$22,'Inputs & Assumptions'!$E$23,'Inputs & Assumptions'!$E$24,'Inputs & Assumptions'!$E$25))) -> 2343.5548 | ... BL17: =IPMT('Inputs & Assumptions'!$E$109,'Monthly Cashflows'!BL3,'Inputs & Assumptions'!$E$7,(-CHOOSE('Inputs & Assumptions'!$B$11,'Inputs & Assumptions'!$E$20,'Inputs & Assumptions'!$E$21,'Inputs & Assumptions'!$E$22,'Inputs & Assumptions'!$E$23,'Inputs & Assumptions'!$E$24,'Inputs & Assumptions'!$E$25))) -> 2195.6586
C18: Balloon Buy/Sell
C19: Construction Costs | E19: {=_xlfn.MAKEARRAY(1,'Inputs & Assumptions'!$E$62,_xlfn.LAMBDA(_xlpm.r,_xlpm.c,'Inputs & Assumptions'!$J$57))} -> 3341.9583 | F19: 3341.9583 | G19: 3341.9583 | H19: 3341.9583 | I19: 3341.9583 | J19: 3341.9583
C20: Vacancy | E20: =IFERROR((IF('Inputs & Assumptions'!B8="Renovate",'Monthly Cashflows'!#REF!,'Monthly Cashflows'!E6)*'Inputs & Assumptions'!$F$35),"0") -> 0 | F20: =IFERROR((IF('Inputs & Assumptions'!C8="Renovate",'Monthly Cashflows'!#REF!,'Monthly Cashflows'!F6)*'Inputs & Assumptions'!$F$35),"0") -> 0 | G20: =IFERROR((IF('Inputs & Assumptions'!D8="Renovate",'Monthly Cashflows'!#REF!,'Monthly Cashflows'!G6)*'Inputs & Assumptions'!$F$35),"0") -> 0 | H20: =IFERROR((IF('Inputs & Assumptions'!E8="Renovate",'Monthly Cashflows'!#REF!,'Monthly Cashflows'!H6)*'Inputs & Assumptions'!$F$35),"0") -> 0 | I20: =IFERROR((IF('Inputs & Assumptions'!F8="Renovate",'Monthly Cashflows'!#REF!,'Monthly Cashflows'!I6)*'Inputs & Assumptions'!$F$35),"0") -> 0 | J20: =IFERROR((IF('Inputs & Assumptions'!G8="Renovate",'Monthly Cashflows'!#REF!,'Monthly Cashflows'!J6)*'Inputs & Assumptions'!$F$35),"0") -> 0 | K20: =IFERROR((IF('Inputs & Assumptions'!H8="Renovate",'Monthly Cashflows'!#REF!,'Monthly Cashflows'!K6)*'Inputs & Assumptions'!$F$35),"0") -> 0 | L20: =IFERROR((IF('Inputs & Assumptions'!I8="Renovate",'Monthly Cashflows'!#REF!,'Monthly Cashflows'!L6)*'Inputs & Assumptions'!$F$35),"0") -> 0 | ... BL20: =IFERROR((IF('Inputs & Assumptions'!BI8="Renovate",'Monthly Cashflows'!#REF!,'Monthly Cashflows'!BL6)*'Inputs & Assumptions'!$F$35),"0") -> 0
C21: Turnover | E21: =IFERROR((IF('Inputs & Assumptions'!B8="Renovate",'Monthly Cashflows'!#REF!,'Monthly Cashflows'!E6)*'Inputs & Assumptions'!$F$34),"0") -> 0 | F21: =IFERROR((IF('Inputs & Assumptions'!C8="Renovate",'Monthly Cashflows'!#REF!,'Monthly Cashflows'!F6)*'Inputs & Assumptions'!$F$34),"0") -> 0 | G21: =IFERROR((IF('Inputs & Assumptions'!D8="Renovate",'Monthly Cashflows'!#REF!,'Monthly Cashflows'!G6)*'Inputs & Assumptions'!$F$34),"0") -> 0 | H21: =IFERROR((IF('Inputs & Assumptions'!E8="Renovate",'Monthly Cashflows'!#REF!,'Monthly Cashflows'!H6)*'Inputs & Assumptions'!$F$34),"0") -> 0 | I21: =IFERROR((IF('Inputs & Assumptions'!F8="Renovate",'Monthly Cashflows'!#REF!,'Monthly Cashflows'!I6)*'Inputs & Assumptions'!$F$34),"0") -> 0 | J21: =IFERROR((IF('Inputs & Assumptions'!G8="Renovate",'Monthly Cashflows'!#REF!,'Monthly Cashflows'!J6)*'Inputs & Assumptions'!$F$34),"0") -> 0 | K21: =IFERROR((IF('Inputs & Assumptions'!H8="Renovate",'Monthly Cashflows'!#REF!,'Monthly Cashflows'!K6)*'Inputs & Assumptions'!$F$34),"0") -> 0 | L21: =IFERROR((IF('Inputs & Assumptions'!I8="Renovate",'Monthly Cashflows'!#REF!,'Monthly Cashflows'!L6)*'Inputs & Assumptions'!$F$34),"0") -> 0 | ... BL21: =IFERROR((IF('Inputs & Assumptions'!BI8="Renovate",'Monthly Cashflows'!#REF!,'Monthly Cashflows'!BL6)*'Inputs & Assumptions'!$F$34),"0") -> 0
C22: Taxes | E22: {=IF(OR(COLUMN()-COLUMN($E$22) = 'Inputs & Assumptions'!$J$99 + 12 * 0, COLUMN()-COLUMN($E$22) = 'Inputs & Assumptions'!$J$99 + 12 * 1, COLUMN()-COLUMN($E$22) = 'Inputs & Assumptions'!$J$99 + 12 * 2, COLUMN()-COLUMN($E$22) = 'Inputs & Assumptions'!$J$99 + 12 * 3, COLUMN()-COLUMN($E$22) = 'Inputs & Assumptions'!$J$99 + 12 * 4), INDEX('Inputs & Assumptions'!$F$29:$K$29, 1, 1 + INT((COLUMN()-COLUMN($E$22) - 'Inputs & Assumptions'!$J$99)/12)), "" )} | F22: {=IF(OR(COLUMN()-COLUMN($E$22) = 'Inputs & Assumptions'!$J$99 + 12 * 0, COLUMN()-COLUMN($E$22) = 'Inputs & Assumptions'!$J$99 + 12 * 1, COLUMN()-COLUMN($E$22) = 'Inputs & Assumptions'!$J$99 + 12 * 2, COLUMN()-COLUMN($E$22) = 'Inputs & Assumptions'!$J$99 + 12 * 3, COLUMN()-COLUMN($E$22) = 'Inputs & Assumptions'!$J$99 + 12 * 4), INDEX('Inputs & Assumptions'!$F$29:$K$29, 1, 1 + INT((COLUMN()-COLUMN($E$22) - 'Inputs & Assumptions'!$J$99)/12)), "" )} | G22: {=IF(OR(COLUMN()-COLUMN($E$22) = 'Inputs & Assumptions'!$J$99 + 12 * 0, COLUMN()-COLUMN($E$22) = 'Inputs & Assumptions'!$J$99 + 12 * 1, COLUMN()-COLUMN($E$22) = 'Inputs & Assumptions'!$J$99 + 12 * 2, COLUMN()-COLUMN($E$22) = 'Inputs & Assumptions'!$J$99 + 12 * 3, COLUMN()-COLUMN($E$22) = 'Inputs & Assumptions'!$J$99 + 12 * 4), INDEX('Inputs & Assumptions'!$F$29:$K$29, 1, 1 + INT((COLUMN()-COLUMN($E$22) - 'Inputs & Assumptions'!$J$99)/12)), "" )} | H22: {=IF(OR(COLUMN()-COLUMN($E$22) = 'Inputs & Assumptions'!$J$99 + 12 * 0, COLUMN()-COLUMN($E$22) = 'Inputs & Assumptions'!$J$99 + 12 * 1, COLUMN()-COLUMN($E$22) = 'Inputs & Assumptions'!$J$99 + 12 * 2, COLUMN()-COLUMN($E$22) = 'Inputs & Assumptions'!$J$99 + 12 * 3, COLUMN()-COLUMN($E$22) = 'Inputs & Assumptions'!$J$99 + 12 * 4), INDEX('Inputs & Assumptions'!$F$29:$K$29, 1, 1 + INT((COLUMN()-COLUMN($E$22) - 'Inputs & Assumptions'!$J$99)/12)), "" )} | I22: {=IF(OR(COLUMN()-COLUMN($E$22) = 'Inputs & Assumptions'!$J$99 + 12 * 0, COLUMN()-COLUMN($E$22) = 'Inputs & Assumptions'!$J$99 + 12 * 1, COLUMN()-COLUMN($E$22) = 'Inputs & Assumptions'!$J$99 + 12 * 2, COLUMN()-COLUMN($E$22) = 'Inputs & Assumptions'!$J$99 + 12 * 3, COLUMN()-COLUMN($E$22) = 'Inputs & Assumptions'!$J$99 + 12 * 4), INDEX('Inputs & Assumptions'!$F$29:$K$29, 1, 1 + INT((COLUMN()-COLUMN($E$22) - 'Inputs & Assumptions'!$J$99)/12)), "" )} -> 5 | J22: {=IF(OR(COLUMN()-COLUMN($E$22) = 'Inputs & Assumptions'!$J$99 + 12 * 0, COLUMN()-COLUMN($E$22) = 'Inputs & Assumptions'!$J$99 + 12 * 1, COLUMN()-COLUMN($E$22) = 'Inputs & Assumptions'!$J$99 + 12 * 2, COLUMN()-COLUMN($E$22) = 'Inputs & Assumptions'!$J$99 + 12 * 3, COLUMN()-COLUMN($E$22) = 'Inputs & Assumptions'!$J$99 + 12 * 4), INDEX('Inputs & Assumptions'!$F$29:$K$29, 1, 1 + INT((COLUMN()-COLUMN($E$22) - 'Inputs & Assumptions'!$J$99)/12)), "" )} | K22: {=IF(OR(COLUMN()-COLUMN($E$22) = 'Inputs & Assumptions'!$J$99 + 12 * 0, COLUMN()-COLUMN($E$22) = 'Inputs & Assumptions'!$J$99 + 12 * 1, COLUMN()-COLUMN($E$22) = 'Inputs & Assumptions'!$J$99 + 12 * 2, COLUMN()-COLUMN($E$22) = 'Inputs & Assumptions'!$J$99 + 12 * 3, COLUMN()-COLUMN($E$22) = 'Inputs & Assumptions'!$J$99 + 12 * 4), INDEX('Inputs & Assumptions'!$F$29:$K$29, 1, 1 + INT((COLUMN()-COLUMN($E$22) - 'Inputs & Assumptions'!$J$99)/12)), "" )} | L22: {=IF(OR(COLUMN()-COLUMN($E$22) = 'Inputs & Assumptions'!$J$99 + 12 * 0, COLUMN()-COLUMN($E$22) = 'Inputs & Assumptions'!$J$99 + 12 * 1, COLUMN()-COLUMN($E$22) = 'Inputs & Assumptions'!$J$99 + 12 * 2, COLUMN()-COLUMN($E$22) = 'Inputs & Assumptions'!$J$99 + 12 * 3, COLUMN()-COLUMN($E$22) = 'Inputs & Assumptions'!$J$99 + 12 * 4), INDEX('Inputs & Assumptions'!$F$29:$K$29, 1, 1 + INT((COLUMN()-COLUMN($E$22) - 'Inputs & Assumptions'!$J$99)/12)), "" )} | ... BL22: {=IF(OR(COLUMN()-COLUMN($E$22) = 'Inputs & Assumptions'!$J$99 + 12 * 0, COLUMN()-COLUMN($E$22) = 'Inputs & Assumptions'!$J$99 + 12 * 1, COLUMN()-COLUMN($E$22) = 'Inputs & Assumptions'!$J$99 + 12 * 2, COLUMN()-COLUMN($E$22) = 'Inputs & Assumptions'!$J$99 + 12 * 3, COLUMN()-COLUMN($E$22) = 'Inputs & Assumptions'!$J$99 + 12 * 4), INDEX('Inputs & Assumptions'!$F$29:$K$29, 1, 1 + INT((COLUMN()-COLUMN($E$22) - 'Inputs & Assumptions'!$J$99)/12)), "" )}
C23: Insurance | E23: ='Inputs & Assumptions'!J20 -> 250 | F23: =E23 -> 250 | G23: =F23 -> 250 | H23: =G23 -> 250 | I23: =H23 -> 250 | J23: =I23 -> 250 | K23: =J23 -> 250 | L23: =K23 -> 250 | M23: =L23 -> 250 | ... BL23: =BK23 -> 250
C24: R&M | E24: ='Inputs & Assumptions'!F13 -> 100 | F24: =E24 -> 100 | G24: =F24 -> 100 | H24: =G24 -> 100 | I24: =H24 -> 100 | J24: =I24 -> 100 | K24: =J24 -> 100 | L24: =K24 -> 100 | M24: =L24 -> 100 | ... P24: =O24 -> 100 | Q24: =P24*(1+'Inputs & Assumptions'!F14) -> 100 | R24: =Q24 -> 100 | S24: =R24 -> 100 | T24: =S24 -> 100 | U24: =T24 -> 100 | V24: =U24 -> 100 | W24: =V24 -> 100 | X24: =W24 -> 100 | Y24: =X24 -> 100 | ... AB24: =AA24 -> 100 | AC24: =AB24*(1+'Inputs & Assumptions'!F14) -> 100 | AD24: =AC24 -> 100 | AE24: =AD24 -> 100 | AF24: =AE24 -> 100 | AG24: =AF24 -> 100 | AH24: =AG24 -> 100 | AI24: =AH24 -> 100 | AJ24: =AI24 -> 100 | AK24: =AJ24 -> 100 | ... AN24: =AM24 -> 100 | AO24: =AN24*(1+'Inputs & Assumptions'!F14) -> 100 | AP24: =AO24 -> 100 | AQ24: =AP24 -> 100 | AR24: =AQ24 -> 100 | AS24: =AR24 -> 100 | AT24: =AS24 -> 100 | AU24: =AT24 -> 100 | AV24: =AU24 -> 100 | AW24: =AV24 -> 100 | ... AZ24: =AY24 -> 100 | BA24: =AZ24*(1+'Inputs & Assumptions'!F14) -> 100 | BB24: =BA24 -> 100 | BC24: =BB24 -> 100 | BD24: =BC24 -> 100 | BE24: =BD24 -> 100 | BF24: =BE24 -> 100 | BG24: =BF24 -> 100 | BH24: =BG24 -> 100 | BI24: =BH24 -> 100 | ... BL24: =BK24 -> 100
C25: G & A / Leasing & Marketing | E25: =ProForma!F20/12 -> 408.33333 | F25: =E25 -> 408.33333 | G25: =F25 -> 408.33333 | H25: =G25 -> 408.33333 | I25: =H25 -> 408.33333 | J25: =I25 -> 408.33333 | K25: =J25 -> 408.33333 | L25: =K25 -> 408.33333 | M25: =L25 -> 408.33333 | ... P25: =O25 -> 408.33333 | Q25: =ProForma!G20/12 -> 33.333333 | R25: =Q25 -> 33.333333 | S25: =R25 -> 33.333333 | T25: =S25 -> 33.333333 | U25: =T25 -> 33.333333 | V25: =U25 -> 33.333333 | W25: =V25 -> 33.333333 | X25: =W25 -> 33.333333 | Y25: =X25 -> 33.333333 | ... AB25: =AA25 -> 33.333333 | AC25: =ProForma!H20/12 -> 33.333333 | AD25: =AC25 -> 33.333333 | AE25: =AD25 -> 33.333333 | AF25: =AE25 -> 33.333333 | AG25: =AF25 -> 33.333333 | AH25: =AG25 -> 33.333333 | AI25: =AH25 -> 33.333333 | AJ25: =AI25 -> 33.333333 | AK25: =AJ25 -> 33.333333 | ... AN25: =AM25 -> 33.333333 | AO25: =ProForma!I20/12 -> 33.333333 | AP25: =AO25 -> 33.333333 | AQ25: =AP25 -> 33.333333 | AR25: =AQ25 -> 33.333333 | AS25: =AR25 -> 33.333333 | AT25: =AS25 -> 33.333333 | AU25: =AT25 -> 33.333333 | AV25: =AU25 -> 33.333333 | AW25: =AV25 -> 33.333333 | ... AZ25: =AY25 -> 33.333333 | BA25: =ProForma!J20/12 -> 33.333333 | BB25: =BA25 -> 33.333333 | BC25: =BB25 -> 33.333333 | BD25: =BC25 -> 33.333333 | BE25: =BD25 -> 33.333333 | BF25: =BE25 -> 33.333333 | BG25: =BF25 -> 33.333333 | BH25: =BG25 -> 33.333333 | BI25: =BH25 -> 33.333333 | ... BL25: =BK25 -> 33.333333
C26: Property Management | E26: =IFERROR((IF( 'Inputs & Assumptions'!$B$17="", "-", IF( COLUMN()-COLUMN($E$28) < 'Inputs & Assumptions'!$J$102, "", IF( 'Inputs & Assumptions'!$B$17="Lease up", IF( COLUMN()-COLUMN($E$28) = 'Inputs & Assumptions'!$J$102, 'Inputs & Assumptions'!$J$105 * E6, "" ), 'Inputs & Assumptions'!$J$105 * E6 ) ) )),"0") | F26: =IFERROR((IF( 'Inputs & Assumptions'!$B$17="", "-", IF( COLUMN()-COLUMN($E$28) < 'Inputs & Assumptions'!$J$102, "", IF( 'Inputs & Assumptions'!$B$17="Lease up", IF( COLUMN()-COLUMN($E$28) = 'Inputs & Assumptions'!$J$102, 'Inputs & Assumptions'!$J$105 * F6, "" ), 'Inputs & Assumptions'!$J$105 * F6 ) ) )),"0") -> 0 | G26: =IFERROR((IF( 'Inputs & Assumptions'!$B$17="", "-", IF( COLUMN()-COLUMN($E$28) < 'Inputs & Assumptions'!$J$102, "", IF( 'Inputs & Assumptions'!$B$17="Lease up", IF( COLUMN()-COLUMN($E$28) = 'Inputs & Assumptions'!$J$102, 'Inputs & Assumptions'!$J$105 * G6, "" ), 'Inputs & Assumptions'!$J$105 * G6 ) ) )),"0") -> 0 | H26: =IFERROR((IF( 'Inputs & Assumptions'!$B$17="", "-", IF( COLUMN()-COLUMN($E$28) < 'Inputs & Assumptions'!$J$102, "", IF( 'Inputs & Assumptions'!$B$17="Lease up", IF( COLUMN()-COLUMN($E$28) = 'Inputs & Assumptions'!$J$102, 'Inputs & Assumptions'!$J$105 * H6, "" ), 'Inputs & Assumptions'!$J$105 * H6 ) ) )),"0") -> 0 | I26: =IFERROR((IF( 'Inputs & Assumptions'!$B$17="", "-", IF( COLUMN()-COLUMN($E$28) < 'Inputs & Assumptions'!$J$102, "", IF( 'Inputs & Assumptions'!$B$17="Lease up", IF( COLUMN()-COLUMN($E$28) = 'Inputs & Assumptions'!$J$102, 'Inputs & Assumptions'!$J$105 * I6, "" ), 'Inputs & Assumptions'!$J$105 * I6 ) ) )),"0") -> 0 | J26: =IFERROR((IF( 'Inputs & Assumptions'!$B$17="", "-", IF( COLUMN()-COLUMN($E$28) < 'Inputs & Assumptions'!$J$102, "", IF( 'Inputs & Assumptions'!$B$17="Lease up", IF( COLUMN()-COLUMN($E$28) = 'Inputs & Assumptions'!$J$102, 'Inputs & Assumptions'!$J$105 * J6, "" ), 'Inputs & Assumptions'!$J$105 * J6 ) ) )),"0") -> 0 | K26: =IFERROR((IF( 'Inputs & Assumptions'!$B$17="", "-", IF( COLUMN()-COLUMN($E$28) < 'Inputs & Assumptions'!$J$102, "", IF( 'Inputs & Assumptions'!$B$17="Lease up", IF( COLUMN()-COLUMN($E$28) = 'Inputs & Assumptions'!$J$102, 'Inputs & Assumptions'!$J$105 * K6, "" ), 'Inputs & Assumptions'!$J$105 * K6 ) ) )),"0") -> 0 | L26: =IFERROR((IF( 'Inputs & Assumptions'!$B$17="", "-", IF( COLUMN()-COLUMN($E$28) < 'Inputs & Assumptions'!$J$102, "", IF( 'Inputs & Assumptions'!$B$17="Lease up", IF( COLUMN()-COLUMN($E$28) = 'Inputs & Assumptions'!$J$102, 'Inputs & Assumptions'!$J$105 * L6, "" ), 'Inputs & Assumptions'!$J$105 * L6 ) ) )),"0") -> 211.6 | ... BL26: =IFERROR((IF( 'Inputs & Assumptions'!$B$17="", "-", IF( COLUMN()-COLUMN($E$28) < 'Inputs & Assumptions'!$J$102, "", IF( 'Inputs & Assumptions'!$B$17="Lease up", IF( COLUMN()-COLUMN($E$28) = 'Inputs & Assumptions'!$J$102, 'Inputs & Assumptions'!$J$105 * BL6, "" ), 'Inputs & Assumptions'!$J$105 * BL6 ) ) )),"0") -> 238.15766
C27: Other
C29: Monthly Net Cash Flow | E29: =-SUM(E16:E27) -> -6958.7382 | F29: =IFERROR((F6+F12)-(SUM(F16:F27)),"0") -> 0 | G29: =IFERROR((G6+G12)-(SUM(G16:G27)),"0") -> 0 | H29: =IFERROR((H6+H12)-(SUM(H16:H27)),"0") -> 0 | I29: =IFERROR((I6+I12)-(SUM(I16:I27)),"0") -> 0 | J29: =IFERROR((J6+J12)-(SUM(J16:J27)),"0") -> 0 | K29: =IFERROR((K6+K12)-(SUM(K16:K27)),"0") -> 0 | L29: =IFERROR((L6+L12)-(SUM(L16:L27)),"0") -> -1183.3799 | M29: =IFERROR((M6+M12)-(SUM(M16:M27)),"0") -> -1183.3799 | ... BL29: =IFERROR((BL6+BL12)-(SUM(BL16:BL27)),"0") -> -502.96672
C30: DCF | E30: =IFERROR((E29/(1+'Inputs & Assumptions'!$E$8)^'Monthly Cashflows'!E3),"0") -> -6627.3697 | F30: =IFERROR((F29/(1+'Inputs & Assumptions'!$E$8)^'Monthly Cashflows'!F3),"0") -> 0 | G30: =IFERROR((G29/(1+'Inputs & Assumptions'!$E$8)^'Monthly Cashflows'!G3),"0") -> 0 | H30: =IFERROR((H29/(1+'Inputs & Assumptions'!$E$8)^'Monthly Cashflows'!H3),"0") -> 0 | I30: =IFERROR((I29/(1+'Inputs & Assumptions'!$E$8)^'Monthly Cashflows'!I3),"0") -> 0 | J30: =IFERROR((J29/(1+'Inputs & Assumptions'!$E$8)^'Monthly Cashflows'!J3),"0") -> 0 | K30: =IFERROR((K29/(1+'Inputs & Assumptions'!$E$8)^'Monthly Cashflows'!K3),"0") -> 0 | L30: =IFERROR((L29/(1+'Inputs & Assumptions'!$E$8)^'Monthly Cashflows'!L3),"0") -> -800.95807 | ... BL30: =IFERROR((BL29/(1+'Inputs & Assumptions'!$E$8)^'Monthly Cashflows'!BL3),"0") -> -26.926587
C31: NPV | E31: =SUM(E30:BL30)-D18 -> -17528.88
C32: IRR
C33: XIRR
C34: MIRR

Sheet S&U
B2: Sources and Uses
B3: Sources | D3: Uses
B4: Acquisition Loan | C4: 0 | D4: Purchase Price | E4: 0 | F4: fill in the closing costs or whatever
B5: Equity | C5: =E10-C4 -> 25051.75 | D5: Land Transfer Tax | E5: 0 | F5: add when needed but in texas we have none so no need
D6: Closing Costs | E6: =CHOOSE('Inputs & Assumptions'!B11,'Inputs & Assumptions'!G20,'Inputs & Assumptions'!G21,'Inputs & Assumptions'!G22,'Inputs & Assumptions'!G23,'Inputs & Assumptions'!G24,'Inputs & Assumptions'!G25) -> 5000
B7: Total Sources | C7: =+SUM(C4:C6) -> 25051.75 | D7: Total Uses | E7: =+SUM(E4:E6) -> 5000
B8: Fully Funded Loan
B9: Capital Line | C9: =+E9 -> 20051.75 | D9: Capital Expenditures | E9: =SUM(Sensitivity!C9:G9) -> 20051.75
B10: Total Sources | C10: =+C7+C9 -> 45103.5 | D10: Total Uses | E10: =+E7+E9 -> 25051.75
B12: Fully Funded Loan | C12: =+C4+C9 -> 20051.75 | D12: Asset Value | E12: =+E7+E9 -> 25051.75
D13: LTV--> | E13: =+C12/E12 -> 0.80041314
G14: Investment Overview
H15: All-in
G16: Purchase Price | H16: =+E4 -> 0
G17: LTT & Closing Costs | H17: =+E5+E6 -> 5000
G18: Total Purchase Price | H18: =+H16+H17 -> 5000
G19: Add: Capital Expenditures | H19: 0
G20: Total Cost | H20: =+H18+H19 -> 5000
G22: Exit Price (_____% Cap Rate)
G23: 5 Year Net IRR
G25: Exit Price (_____% Cap Rate)
G26: 5 Year Net IRR

Sheet Comps
C2: Market Survey
C3: Address | D3: Property Value | E3: Rent | F3: Finishes
B4: 1
B5: =+B4+1 -> 2
B6: =+B5+1 -> 3
B7: =+B6+1 -> 4
B8: =+B7+1 -> 5
B9: =+B8+1 -> 6
B10: =+B9+1 -> 7
B11: =+B10+1 -> 8
B12: =+B11+1 -> 9
C13: Totals
C21: Sales Comps
C22: Address | D22: City | E22: Date | F22: Value | G22: Units | H22: $/Unit | I22: Cap Rate | J22: R/P

Sheet ProForma Rent expense Summary
B2: Expense | C2: % or $ Value
B3: HOA fees | C3: $100–$800/mo (if applicable)
B4: Property management | C4: 8% of gross monthly rent + leasing fees
B5: Maintenance/repairs | C5: 1% of property value/year OR $100/mo
B6: Insurance (landlord) | C6: $100–$250/mo
B7: Property taxes | C7: 1%–2% (US), 0.6–1% (CA), of value
B8: Vacancy allowance | C8: 5%–8% of rent
B9: Utilities | C9: Tenant Pays ideally
B10: Legal/accounting | C10: $100–$500/year

Sheet Data Validation
C2: Investment Area | E2: Switcher | G2: Case Number | I2: Turnover/Vacancy | K2: Renovation Start Time | M2: Construction Duration | O2: Property Mangement Cases
B3: Texas | C3: 1 | E3: Renovate | G3: 1 | I3: 0 | K3: 0 | M3: 1 | O3: Lease Up
B4: Ohio | C4: 2 | E4: Hold | G4: 2 | I4: 0.01 | K4: 1 | M4: =M3+1 -> 2 | O4: Full Time
B5: Ontario | C5: 3 | G5: 3 | I5: =I4+1% -> 0.02 | K5: =K4+1 -> 2 | M5: =M4+1 -> 3
G6: 4 | I6: =I5+1% -> 0.03 | K6: =K5+1 -> 3 | M6: =M5+1 -> 4
G7: 5 | I7: =I6+1% -> 0.04 | K7: =K6+1 -> 4 | M7: =M6+1 -> 5
G8: 6 | I8: =I7+1% -> 0.05 | K8: =K7+1 -> 5 | M8: =M7+1 -> 6
I9: =I8+1% -> 0.06 | K9: =K8+1 -> 6 | M9: =M8+1 -> 7
I10: =I9+1% -> 0.07 | K10: =K9+1 -> 7 | M10: =M9+1 -> 8
I11: =I10+1% -> 0.08 | K11: =K10+1 -> 8 | M11: =M10+1 -> 9
I12: =I11+1% -> 0.09 | K12: =K11+1 -> 9 | M12: =M11+1 -> 10
I13: =I12+1% -> 0.1 | K13: =K12+1 -> 10 | M13: =M12+1 -> 11
I14: =I13+1% -> 0.11 | K14: =K13+1 -> 11 | M14: =M13+1 -> 12
I15: =I14+1% -> 0.12 | K15: =K14+1 -> 12 | M15: =M14+1 -> 13
I16: =I15+1% -> 0.13 | M16: =M15+1 -> 14
I17: =I16+1% -> 0.14 | M17: =M16+1 -> 15
I18: =I17+1% -> 0.15 | M18: =M17+1 -> 16
I19: =I18+1% -> 0.16 | M19: =M18+1 -> 17
I20: =I19+1% -> 0.17 | M20: =M19+1 -> 18
I21: =I20+1% -> 0.18 | M21: =M20+1 -> 19
I22: =I21+1% -> 0.19 | M22: =M21+1 -> 20
I23: =I22+1% -> 0.2 | M23: =M22+1 -> 21
M24: =M23+1 -> 22
M25: =M24+1 -> 23
M26: =M25+1 -> 24
