Workbook
Name Appreciation: Inputs!$C$36
Name AssessedGrowth: Inputs!$C$25
Name AssessedValueY1: Inputs!$C$24
Name CapexPct: Inputs!$C$30
Name CF_COC_Row: 'Cash Flow'!$C$31:$L$31
Name CF_DS_Row: 'Cash Flow'!$C$25:$L$25
Name CF_DSCR_Row: 'Cash Flow'!$C$30:$L$30
Name CF_NOI_Row: 'Cash Flow'!$C$22:$L$22
Name CF_PTCF_Row: 'Cash Flow'!$C$26:$L$26
Name ClosingCostAmt: Inputs!$C$8
Name ClosingCostPct: Inputs!$C$7
Name CoCPassThresh: Inputs!$C$40
Name CoCWatchThresh: Inputs!$C$41
Name DownAmt: Inputs!$C$13
Name DownPct: Inputs!$C$12
Name DSCRPassThresh: Inputs!$C$42
Name DSCRWatchThresh: Inputs!$C$43
Name EX_EquityMultiple: 'Exit & Returns'!$C$22
Name EX_LeveredIRR: 'Exit & Returns'!$C$20
Name EX_LoanPayoff: 'Exit & Returns'!$C$8
Name EX_NetProceeds: 'Exit & Returns'!$C$9
Name EX_SalePrice: 'Exit & Returns'!$C$6
Name EX_UnleveredIRR: 'Exit & Returns'!$C$21
Name ExitYear: Inputs!$C$35
Name HOAmo: Inputs!$C$32
Name InitialRepairs: Inputs!$C$9
Name InsuranceGrowth: Inputs!$C$28
Name InsuranceY1: Inputs!$C$27
Name InterestRate: Inputs!$C$15
Name LoanAmount: Inputs!$C$14
Name LoanTermYrs: Inputs!$C$16
Name MaintPct: Inputs!$C$29
Name MgmtPct: Inputs!$C$31
Name MonthlyRentY1: Inputs!$C$21
Name OriginationAmt: Inputs!$C$18
Name OriginationPct: Inputs!$C$17
Name PurchasePrice: Inputs!$C$6
Name RentGrowth: Inputs!$C$22
Name SellingCostPct: Inputs!$C$37
Name SV_BreakevenRate: Sensitivity!$C$37
Name SV_BreakevenRent: Sensitivity!$C$36
Name SV_MaxLoanDSCR120: Sensitivity!$C$37
Name SV_MinDownPctDSCR120: Sensitivity!$C$38
Name TaxRate: Inputs!$C$26
Name TotalCashInvested: Inputs!$C$45
Name VacancyPct: Inputs!$C$23

Sheet Dashboard
B2: TEXAS SFR INVESTMENT MODEL
B3: 122 S Gulls Cut, Baytown, TX 77523 | Single-Family Rental Acquisition Analysis
B5: PROPERTY SNAPSHOT
B6: Address | C6: 122 S Gulls Cut, Baytown, TX 77523 (Bay Oaks Harbor) | F6: Beds / Baths | G6: 3 / 2
B7: Square Footage | C7: 1065 | F7: Year Built | G7: 2007
B8: Subdivision | C8: Bay Oaks Harbor Amd | F8: List Price | G8: =PurchasePrice -> 99800
B9: $ / Square Foot | C9: =PurchasePrice/C7 -> 93.70892 | F9: Market Rent (mo.) | G9: =MonthlyRentY1 -> 1550
B11: KEY PERFORMANCE INDICATORS - YEAR 1 / 10-YEAR HOLD
B12: Year-1 Cap Rate | C12: Cash-on-Cash Yr 1 | D12: DSCR Year 1 | E12: Monthly Cash Flow Yr 1 | F12: Breakeven Rent | G12: 10-Yr Levered IRR | H12: 10-Yr Unlevered IRR
B13: =INDEX(CF_NOI_Row,1)/PurchasePrice -> 0.084082565 | C13: =INDEX(CF_COC_Row,1) -> 0.056394207 | D13: =INDEX(CF_DSCR_Row,1) -> 1.3040686 | E13: =INDEX(CF_PTCF_Row,1)/12 -> 163.0521 | F13: =SV_BreakevenRent -> 1321.7636 | G13: =EX_LeveredIRR -> 0.11401212 | H13: =EX_UnleveredIRR -> 0.091750235
B15: Equity Multiple | C15: Year-1 NOI | D15: Projected Sale Price (Exit Yr) | E15: Net Sale Proceeds | F15: Total Cash Invested | G15: Exit Year (toggle)
B16: =EX_EquityMultiple -> 2.4286176 | C16: =INDEX(CF_NOI_Row,1) -> 8391.44 | D16: =EX_SalePrice -> 127752.44 | E16: =EX_NetProceeds -> 53490.868 | F16: =TotalCashInvested -> 34695.5 | G16: =ExitYear -> 10
B18: BUY-BOX VERDICT
B19: Verdict (vs. CoC & DSCR thresholds in Inputs) | D19: =IF(AND(INDEX(CF_COC_Row,1)>=CoCPassThresh,INDEX(CF_DSCR_Row,1)>=DSCRPassThresh),"PASS",IF(AND(INDEX(CF_COC_Row,1)>=CoCWatchThresh,INDEX(CF_DSCR_Row,1)>=DSCRWatchThresh),"WATCH","FAIL")) -> WATCH | F19: Note: at 7.75% financing with conservative rent/tax/insurance inputs, this listing is underwritten to genuinely near/at the buy-box thresholds - see verdict cell for the honest result.
B20: Risk flags: coastal windstorm (TWIA) exposure; neighborhood includes manufactured homes - verify subject construction type and flood zone before offer.
B21: COLOR LEGEND
B22: Blue text = input cell | D22: Black text = calculated formula | F22: Green / Yellow / Red = PASS / WATCH / FAIL vs. buy-box thresholds
B24: ASSUMPTION SOURCES
B25: Listing: HAR.com / Zillow, 122 S Gulls Cut, Baytown, TX 77523, MLS# 13324862, Bay Oaks Harbor Amd, list $99,800, 3bd/2ba/1,065 SF, built 2007 (accessed Aug 2026).
B26: Rent comparables: 8014 Blackcherry Ln $1,800/mo (1,558 SF); 515 Riggs St $1,850/mo (1,482 SF); Baytown median house rent ~$1,580/mo (Zillow/Rentometer, accessed Aug 2026). Subject rent set at $1,550/mo, conservative vs. the ~$1,650 comp-based estimate.
B27: Sale comparables: 2431 Bay Oaks Harbor Dr sold ~$90k-$105k; neighborhood avg list ~$127.5k, median $146/SF vs. subject's ~$94/SF (Zillow/HAR, accessed Aug 2026).
B28: Property tax: sources quoted ~0.68% effective for ZIP 77523, which appears understated for TX; 1.80% used as a conservative estimate (see Inputs tab note).
B29: Insurance: standard homeowners policy + TWIA windstorm coverage assumed given coastal Chambers County exposure.
B30: Mortgage rate: 7.3-7.4% investor 30-yr fixed market range + ~0.4% premium assumed for small-balance loan / possible manufactured-home classification risk.

Sheet Inputs
B2: INPUTS & ASSUMPTIONS
B3: 122 S Gulls Cut, Baytown, TX 77523 | Blue = input, Black = formula
B5: ACQUISITION
B6: Purchase Price | C6: 99800 | D6: HAR.com / Zillow active listing, MLS# 13324862, Bay Oaks Harbor Amd, accessed Aug 2026
B7: Closing Costs (% of price) | C7: 0.015
B8: Closing Costs ($) | C8: =C6*C7 -> 1497
B9: Initial Repairs / Turn Costs | C9: 7500 | D9: Older/smaller coastal housing stock - conservative turn-cost estimate
B11: FINANCING
B12: Down Payment (%) | C12: 0.25
B13: Down Payment ($) | C13: =C6*C12 -> 24950
B14: Loan Amount ($) | C14: =C6-C13 -> 74850
B15: Interest Rate (annual, fixed) | C15: 0.0775 | D15: 7.3-7.4% investor 30-yr fixed market range + ~0.4% premium assumed for small-balance loan / possible manufactured-home classification risk
B16: Loan Term (years) | C16: 30
B17: Loan Origination Fee (%) | C17: 0.01
B18: Loan Origination Fee ($) | C18: =C14*C17 -> 748.5
B20: OPERATIONS
B21: Market Rent, Month 1 ($/mo) | C21: 1550 | D21: Conservative vs comps: 8014 Blackcherry Ln $1,800/mo (1,558 SF); 515 Riggs St $1,850/mo (1,482 SF); Baytown median house rent ~$1,580/mo. $1,550 used, below the ~$1,650 comp-based estimate
B22: Rent Growth (%/yr) | C22: 0.03
B23: Vacancy / Credit Loss (%) | C23: 0.06
B24: Assessed Value, Year 1 ($) | C24: 99800 | D24: Set equal to purchase price at acquisition (Chambers/Harris County appraisal basis)
B25: Assessed Value Growth (%/yr) | C25: 0.03
B26: Property Tax Rate (effective, of assessed value) | C26: 0.018 | D26: Sources quoted ~0.68% effective for ZIP 77523, which looks understated for TX; 1.80% used as the conservative TX effective-rate assumption
B27: Insurance, Year 1 ($/yr) | C27: 2800 | D27: Standard homeowners + TWIA windstorm coverage - coastal Chambers County exposure
B28: Insurance Growth (%/yr) | C28: 0.04
B29: Maintenance (% of collected rent) | C29: 0.1
B30: CapEx Reserve (% of collected rent) | C30: 0.06
B31: Property Management (% of collected rent) | C31: 0.08
B32: HOA Dues ($/mo) | C32: 25 | D32: No HOA/POA confirmed for Bay Oaks Harbor Amd; $25/mo POA placeholder pending verification
B34: EXIT
B35: Exit / Hold Year (toggle 5-10) | C35: 10 | D35: Flexible exit-year toggle
B36: Appreciation (%/yr) | C36: 0.025
B37: Selling Costs (% of sale price) | C37: 0.07
B39: BUY-BOX THRESHOLDS
B40: Cash-on-Cash PASS threshold (>=) | C40: 0.06
B41: Cash-on-Cash WATCH threshold (>=) | C41: 0.03
B42: DSCR PASS threshold (>=) | C42: 1.2
B43: DSCR WATCH threshold (>=) | C43: 1
B45: Total Cash Invested ($) | C45: =C13+C8+C18+C9 -> 34695.5
B47: Sources: HAR.com/Zillow listing detail (MLS# 13324862); Zillow/Rentometer rent comparables; county appraisal district guidance (TX effective rate assumption, see note on tax rate above); investor mortgage-rate market surveys (all accessed Aug 2026).

Sheet Amortization
B2: MONTHLY AMORTIZATION SCHEDULE
B3: 360-month schedule on the investment-property loan, plus annual rollup for the Cash Flow tab
I4: ANNUAL ROLLUP (for Cash Flow & Exit tabs)
B5: Month | C5: Year | D5: Payment | E5: Interest | F5: Principal | G5: Ending Balance | I5: Year | J5: Total Payment | K5: Total Interest | L5: Total Principal | M5: Ending Balance
B6: 1 | C6: =ROUNDUP(B6/12,0) -> 1 | D6: =-PMT(InterestRate/12,LoanTermYrs*12,LoanAmount) -> 536.23457 | E6: =(LoanAmount)*InterestRate/12 -> 483.40625 | F6: =D6-E6 -> 52.828316 | G6: =(LoanAmount)-F6 -> 74797.172 | I6: 1 | J6: =SUMIF($C$6:$C$365,I6,$D$6:$D$365) -> 6434.8148 | K6: =SUMIF($C$6:$C$365,I6,$E$6:$E$365) -> 5777.865 | L6: =SUMIF($C$6:$C$365,I6,$F$6:$F$365) -> 656.94974 | M6: =INDEX($G$6:$G$365,MATCH(I6*12,$B$6:$B$365,0)) -> 74193.05
B7: 2 | C7: =ROUNDUP(B7/12,0) -> 1 | D7: =-PMT(InterestRate/12,LoanTermYrs*12,LoanAmount) -> 536.23457 | E7: =(G6)*InterestRate/12 -> 483.06507 | F7: =D7-E7 -> 53.169499 | G7: =(G6)-F7 -> 74744.002 | I7: 2 | J7: =SUMIF($C$6:$C$365,I7,$D$6:$D$365) -> 6434.8148 | K7: =SUMIF($C$6:$C$365,I7,$E$6:$E$365) -> 5725.1034 | L7: =SUMIF($C$6:$C$365,I7,$F$6:$F$365) -> 709.71134 | M7: =INDEX($G$6:$G$365,MATCH(I7*12,$B$6:$B$365,0)) -> 73483.339
B8: 3 | C8: =ROUNDUP(B8/12,0) -> 1 | D8: =-PMT(InterestRate/12,LoanTermYrs*12,LoanAmount) -> 536.23457 | E8: =(G7)*InterestRate/12 -> 482.72168 | F8: =D8-E8 -> 53.512885 | G8: =(G7)-F8 -> 74690.489 | I8: 3 | J8: =SUMIF($C$6:$C$365,I8,$D$6:$D$365) -> 6434.8148 | K8: =SUMIF($C$6:$C$365,I8,$E$6:$E$365) -> 5668.1044 | L8: =SUMIF($C$6:$C$365,I8,$F$6:$F$365) -> 766.71039 | M8: =INDEX($G$6:$G$365,MATCH(I8*12,$B$6:$B$365,0)) -> 72716.629
B9: 4 | C9: =ROUNDUP(B9/12,0) -> 1 | D9: =-PMT(InterestRate/12,LoanTermYrs*12,LoanAmount) -> 536.23457 | E9: =(G8)*InterestRate/12 -> 482.37608 | F9: =D9-E9 -> 53.858489 | G9: =(G8)-F9 -> 74636.631 | I9: 4 | J9: =SUMIF($C$6:$C$365,I9,$D$6:$D$365) -> 6434.8148 | K9: =SUMIF($C$6:$C$365,I9,$E$6:$E$365) -> 5606.5276 | L9: =SUMIF($C$6:$C$365,I9,$F$6:$F$365) -> 828.2872 | M9: =INDEX($G$6:$G$365,MATCH(I9*12,$B$6:$B$365,0)) -> 71888.341
B10: 5 | C10: =ROUNDUP(B10/12,0) -> 1 | D10: =-PMT(InterestRate/12,LoanTermYrs*12,LoanAmount) -> 536.23457 | E10: =(G9)*InterestRate/12 -> 482.02824 | F10: =D10-E10 -> 54.206325 | G10: =(G9)-F10 -> 74582.424 | I10: 5 | J10: =SUMIF($C$6:$C$365,I10,$D$6:$D$365) -> 6434.8148 | K10: =SUMIF($C$6:$C$365,I10,$E$6:$E$365) -> 5540.0054 | L10: =SUMIF($C$6:$C$365,I10,$F$6:$F$365) -> 894.80943 | M10: =INDEX($G$6:$G$365,MATCH(I10*12,$B$6:$B$365,0)) -> 70993.532
B11: 6 | C11: =ROUNDUP(B11/12,0) -> 1 | D11: =-PMT(InterestRate/12,LoanTermYrs*12,LoanAmount) -> 536.23457 | E11: =(G10)*InterestRate/12 -> 481.67816 | F11: =D11-E11 -> 54.556408 | G11: =(G10)-F11 -> 74527.868 | I11: 6 | J11: =SUMIF($C$6:$C$365,I11,$D$6:$D$365) -> 6434.8148 | K11: =SUMIF($C$6:$C$365,I11,$E$6:$E$365) -> 5468.1405 | L11: =SUMIF($C$6:$C$365,I11,$F$6:$F$365) -> 966.67425 | M11: =INDEX($G$6:$G$365,MATCH(I11*12,$B$6:$B$365,0)) -> 70026.858
B12: 7 | C12: =ROUNDUP(B12/12,0) -> 1 | D12: =-PMT(InterestRate/12,LoanTermYrs*12,LoanAmount) -> 536.23457 | E12: =(G11)*InterestRate/12 -> 481.32581 | F12: =D12-E12 -> 54.908751 | G12: =(G11)-F12 -> 74472.959 | I12: 7 | J12: =SUMIF($C$6:$C$365,I12,$D$6:$D$365) -> 6434.8148 | K12: =SUMIF($C$6:$C$365,I12,$E$6:$E$365) -> 5390.504 | L12: =SUMIF($C$6:$C$365,I12,$F$6:$F$365) -> 1044.3108 | M12: =INDEX($G$6:$G$365,MATCH(I12*12,$B$6:$B$365,0)) -> 68982.547
B13: 8 | C13: =ROUNDUP(B13/12,0) -> 1 | D13: =-PMT(InterestRate/12,LoanTermYrs*12,LoanAmount) -> 536.23457 | E13: =(G12)*InterestRate/12 -> 480.9712 | F13: =D13-E13 -> 55.26337 | G13: =(G12)-F13 -> 74417.696 | I13: 8 | J13: =SUMIF($C$6:$C$365,I13,$D$6:$D$365) -> 6434.8148 | K13: =SUMIF($C$6:$C$365,I13,$E$6:$E$365) -> 5306.6323 | L13: =SUMIF($C$6:$C$365,I13,$F$6:$F$365) -> 1128.1825 | M13: =INDEX($G$6:$G$365,MATCH(I13*12,$B$6:$B$365,0)) -> 67854.364
B14: 9 | C14: =ROUNDUP(B14/12,0) -> 1 | D14: =-PMT(InterestRate/12,LoanTermYrs*12,LoanAmount) -> 536.23457 | E14: =(G13)*InterestRate/12 -> 480.61429 | F14: =D14-E14 -> 55.620279 | G14: =(G13)-F14 -> 74362.076 | I14: 9 | J14: =SUMIF($C$6:$C$365,I14,$D$6:$D$365) -> 6434.8148 | K14: =SUMIF($C$6:$C$365,I14,$E$6:$E$365) -> 5216.0246 | L14: =SUMIF($C$6:$C$365,I14,$F$6:$F$365) -> 1218.7902 | M14: =INDEX($G$6:$G$365,MATCH(I14*12,$B$6:$B$365,0)) -> 66635.574
B15: 10 | C15: =ROUNDUP(B15/12,0) -> 1 | D15: =-PMT(InterestRate/12,LoanTermYrs*12,LoanAmount) -> 536.23457 | E15: =(G14)*InterestRate/12 -> 480.25507 | F15: =D15-E15 -> 55.979494 | G15: =(G14)-F15 -> 74306.096 | I15: 10 | J15: =SUMIF($C$6:$C$365,I15,$D$6:$D$365) -> 6434.8148 | K15: =SUMIF($C$6:$C$365,I15,$E$6:$E$365) -> 5118.1399 | L15: =SUMIF($C$6:$C$365,I15,$F$6:$F$365) -> 1316.6749 | M15: =INDEX($G$6:$G$365,MATCH(I15*12,$B$6:$B$365,0)) -> 65318.899
B16: 11 | C16: =ROUNDUP(B16/12,0) -> 1 | D16: =-PMT(InterestRate/12,LoanTermYrs*12,LoanAmount) -> 536.23457 | E16: =(G15)*InterestRate/12 -> 479.89354 | F16: =D16-E16 -> 56.341028 | G16: =(G15)-F16 -> 74249.755
B17: 12 | C17: =ROUNDUP(B17/12,0) -> 1 | D17: =-PMT(InterestRate/12,LoanTermYrs*12,LoanAmount) -> 536.23457 | E17: =(G16)*InterestRate/12 -> 479.52967 | F17: =D17-E17 -> 56.704897 | G17: =(G16)-F17 -> 74193.05
B18: 13 | C18: =ROUNDUP(B18/12,0) -> 2 | D18: =-PMT(InterestRate/12,LoanTermYrs*12,LoanAmount) -> 536.23457 | E18: =(G17)*InterestRate/12 -> 479.16345 | F18: =D18-E18 -> 57.071116 | G18: =(G17)-F18 -> 74135.979
B19: 14 | C19: =ROUNDUP(B19/12,0) -> 2 | D19: =-PMT(InterestRate/12,LoanTermYrs*12,LoanAmount) -> 536.23457 | E19: =(G18)*InterestRate/12 -> 478.79487 | F19: =D19-E19 -> 57.439701 | G19: =(G18)-F19 -> 74078.539
B20: 15 | C20: =ROUNDUP(B20/12,0) -> 2 | D20: =-PMT(InterestRate/12,LoanTermYrs*12,LoanAmount) -> 536.23457 | E20: =(G19)*InterestRate/12 -> 478.4239 | F20: =D20-E20 -> 57.810665 | G20: =(G19)-F20 -> 74020.729
B21: 16 | C21: =ROUNDUP(B21/12,0) -> 2 | D21: =-PMT(InterestRate/12,LoanTermYrs*12,LoanAmount) -> 536.23457 | E21: =(G20)*InterestRate/12 -> 478.05054 | F21: =D21-E21 -> 58.184026 | G21: =(G20)-F21 -> 73962.545
B22: 17 | C22: =ROUNDUP(B22/12,0) -> 2 | D22: =-PMT(InterestRate/12,LoanTermYrs*12,LoanAmount) -> 536.23457 | E22: =(G21)*InterestRate/12 -> 477.67477 | F22: =D22-E22 -> 58.559798 | G22: =(G21)-F22 -> 73903.985
B23: 18 | C23: =ROUNDUP(B23/12,0) -> 2 | D23: =-PMT(InterestRate/12,LoanTermYrs*12,LoanAmount) -> 536.23457 | E23: =(G22)*InterestRate/12 -> 477.29657 | F23: =D23-E23 -> 58.937996 | G23: =(G22)-F23 -> 73845.047
B24: 19 | C24: =ROUNDUP(B24/12,0) -> 2 | D24: =-PMT(InterestRate/12,LoanTermYrs*12,LoanAmount) -> 536.23457 | E24: =(G23)*InterestRate/12 -> 476.91593 | F24: =D24-E24 -> 59.318638 | G24: =(G23)-F24 -> 73785.728
B25: 20 | C25: =ROUNDUP(B25/12,0) -> 2 | D25: =-PMT(InterestRate/12,LoanTermYrs*12,LoanAmount) -> 536.23457 | E25: =(G24)*InterestRate/12 -> 476.53283 | F25: =D25-E25 -> 59.701737 | G25: =(G24)-F25 -> 73726.027
B26: 21 | C26: =ROUNDUP(B26/12,0) -> 2 | D26: =-PMT(InterestRate/12,LoanTermYrs*12,LoanAmount) -> 536.23457 | E26: =(G25)*InterestRate/12 -> 476.14726 | F26: =D26-E26 -> 60.087311 | G26: =(G25)-F26 -> 73665.939
B27: 22 | C27: =ROUNDUP(B27/12,0) -> 2 | D27: =-PMT(InterestRate/12,LoanTermYrs*12,LoanAmount) -> 536.23457 | E27: =(G26)*InterestRate/12 -> 475.75919 | F27: =D27-E27 -> 60.475375 | G27: =(G26)-F27 -> 73605.464
... B365: 360 | C365: =ROUNDUP(B365/12,0) -> 30 | D365: =-PMT(InterestRate/12,LoanTermYrs*12,LoanAmount) -> 536.23457 | E365: =(G364)*InterestRate/12 -> 3.4409587 | F365: =D365-E365 -> 532.79361 | G365: =(G364)-F365 -> -1.4244961e-10

Sheet Cash Flow
B2: 10-YEAR ANNUAL CASH FLOW
B3: All rows flow from Inputs assumptions and the Amortization annual rollup
B5: ($ unless noted) | C5: Year 1 | D5: Year 2 | E5: Year 3 | F5: Year 4 | G5: Year 5 | H5: Year 6 | I5: Year 7 | J5: Year 8 | K5: Year 9 | L5: Year 10
B7: RENTAL INCOME
B8: Monthly Rent ($/mo) | C8: =MonthlyRentY1*(1+RentGrowth)^(1-1) -> 1550 | D8: =MonthlyRentY1*(1+RentGrowth)^(2-1) -> 1596.5 | E8: =MonthlyRentY1*(1+RentGrowth)^(3-1) -> 1644.395 | F8: =MonthlyRentY1*(1+RentGrowth)^(4-1) -> 1693.7269 | G8: =MonthlyRentY1*(1+RentGrowth)^(5-1) -> 1744.5387 | H8: =MonthlyRentY1*(1+RentGrowth)^(6-1) -> 1796.8748 | I8: =MonthlyRentY1*(1+RentGrowth)^(7-1) -> 1850.7811 | J8: =MonthlyRentY1*(1+RentGrowth)^(8-1) -> 1906.3045 | K8: =MonthlyRentY1*(1+RentGrowth)^(9-1) -> 1963.4936 | L8: =MonthlyRentY1*(1+RentGrowth)^(10-1) -> 2022.3984
B9: Gross Potential Rent (annual) | C9: =C8*12 -> 18600 | D9: =D8*12 -> 19158 | E9: =E8*12 -> 19732.74 | F9: =F8*12 -> 20324.722 | G9: =G8*12 -> 20934.464 | H9: =H8*12 -> 21562.498 | I9: =I8*12 -> 22209.373 | J9: =J8*12 -> 22875.654 | ... L9: =L8*12 -> 24268.781
B10: Vacancy / Credit Loss | C10: =-C9*VacancyPct -> -1116 | D10: =-D9*VacancyPct -> -1149.48 | E10: =-E9*VacancyPct -> -1183.9644 | F10: =-F9*VacancyPct -> -1219.4833 | G10: =-G9*VacancyPct -> -1256.0678 | H10: =-H9*VacancyPct -> -1293.7499 | I10: =-I9*VacancyPct -> -1332.5624 | J10: =-J9*VacancyPct -> -1372.5392 | ... L10: =-L9*VacancyPct -> -1456.1269
B11: Effective Rental Income | C11: =C9+C10 -> 17484 | D11: =D9+D10 -> 18008.52 | E11: =E9+E10 -> 18548.776 | F11: =F9+F10 -> 19105.239 | G11: =G9+G10 -> 19678.396 | H11: =H9+H10 -> 20268.748 | I11: =I9+I10 -> 20876.81 | J11: =J9+J10 -> 21503.115 | ... L11: =L9+L10 -> 22812.654
B13: OPERATING EXPENSES
B14: Property Tax | C14: =-AssessedValueY1*(1+AssessedGrowth)^(1-1)*TaxRate -> -1796.4 | D14: =-AssessedValueY1*(1+AssessedGrowth)^(2-1)*TaxRate -> -1850.292 | E14: =-AssessedValueY1*(1+AssessedGrowth)^(3-1)*TaxRate -> -1905.8008 | F14: =-AssessedValueY1*(1+AssessedGrowth)^(4-1)*TaxRate -> -1962.9748 | G14: =-AssessedValueY1*(1+AssessedGrowth)^(5-1)*TaxRate -> -2021.864 | H14: =-AssessedValueY1*(1+AssessedGrowth)^(6-1)*TaxRate -> -2082.5199 | I14: =-AssessedValueY1*(1+AssessedGrowth)^(7-1)*TaxRate -> -2144.9955 | J14: =-AssessedValueY1*(1+AssessedGrowth)^(8-1)*TaxRate -> -2209.3454 | K14: =-AssessedValueY1*(1+AssessedGrowth)^(9-1)*TaxRate -> -2275.6258 | L14: =-AssessedValueY1*(1+AssessedGrowth)^(10-1)*TaxRate -> -2343.8945
B15: Insurance | C15: =-InsuranceY1*(1+InsuranceGrowth)^(1-1) -> -2800 | D15: =-InsuranceY1*(1+InsuranceGrowth)^(2-1) -> -2912 | E15: =-InsuranceY1*(1+InsuranceGrowth)^(3-1) -> -3028.48 | F15: =-InsuranceY1*(1+InsuranceGrowth)^(4-1) -> -3149.6192 | G15: =-InsuranceY1*(1+InsuranceGrowth)^(5-1) -> -3275.604 | H15: =-InsuranceY1*(1+InsuranceGrowth)^(6-1) -> -3406.6281 | I15: =-InsuranceY1*(1+InsuranceGrowth)^(7-1) -> -3542.8933 | J15: =-InsuranceY1*(1+InsuranceGrowth)^(8-1) -> -3684.609 | K15: =-InsuranceY1*(1+InsuranceGrowth)^(9-1) -> -3831.9933 | L15: =-InsuranceY1*(1+InsuranceGrowth)^(10-1) -> -3985.2731
B16: Maintenance | C16: =-C11*MaintPct -> -1748.4 | D16: =-D11*MaintPct -> -1800.852 | E16: =-E11*MaintPct -> -1854.8776 | F16: =-F11*MaintPct -> -1910.5239 | G16: =-G11*MaintPct -> -1967.8396 | H16: =-H11*MaintPct -> -2026.8748 | I16: =-I11*MaintPct -> -2087.681 | J16: =-J11*MaintPct -> -2150.3115 | ... L16: =-L11*MaintPct -> -2281.2654
B17: CapEx Reserve | C17: =-C11*CapexPct -> -1049.04 | D17: =-D11*CapexPct -> -1080.5112 | E17: =-E11*CapexPct -> -1112.9265 | F17: =-F11*CapexPct -> -1146.3143 | G17: =-G11*CapexPct -> -1180.7038 | H17: =-H11*CapexPct -> -1216.1249 | I17: =-I11*CapexPct -> -1252.6086 | J17: =-J11*CapexPct -> -1290.1869 | ... L17: =-L11*CapexPct -> -1368.7593
B18: Property Management | C18: =-C11*MgmtPct -> -1398.72 | D18: =-D11*MgmtPct -> -1440.6816 | E18: =-E11*MgmtPct -> -1483.902 | F18: =-F11*MgmtPct -> -1528.4191 | G18: =-G11*MgmtPct -> -1574.2717 | H18: =-H11*MgmtPct -> -1621.4998 | I18: =-I11*MgmtPct -> -1670.1448 | J18: =-J11*MgmtPct -> -1720.2492 | ... L18: =-L11*MgmtPct -> -1825.0123
B19: HOA Dues | C19: =-HOAmo*12 -> -300 | D19: =-HOAmo*12 -> -300 | E19: =-HOAmo*12 -> -300 | F19: =-HOAmo*12 -> -300 | G19: =-HOAmo*12 -> -300 | H19: =-HOAmo*12 -> -300 | I19: =-HOAmo*12 -> -300 | J19: =-HOAmo*12 -> -300 | ... L19: =-HOAmo*12 -> -300
B20: Total Operating Expenses | C20: =SUM(C14:C19) -> -9092.56 | D20: =SUM(D14:D19) -> -9384.3368 | E20: =SUM(E14:E19) -> -9685.9869 | F20: =SUM(F14:F19) -> -9997.8513 | G20: =SUM(G14:G19) -> -10320.283 | H20: =SUM(H14:H19) -> -10653.648 | I20: =SUM(I14:I19) -> -10998.323 | J20: =SUM(J14:J19) -> -11354.702 | ... L20: =SUM(L14:L19) -> -12104.205
B22: NET OPERATING INCOME (NOI) | C22: =C11+C20 -> 8391.44 | D22: =D11+D20 -> 8624.1832 | E22: =E11+E20 -> 8862.7887 | F22: =F11+F20 -> 9107.3876 | G22: =G11+G20 -> 9358.113 | H22: =H11+H20 -> 9615.1003 | I22: =I11+I20 -> 9878.4871 | J22: =J11+J20 -> 10148.413 | ... L22: =L11+L20 -> 10708.45
B24: DEBT SERVICE & CASH FLOW
B25: Debt Service (P&I, from Amortization) | C25: =-INDEX(Amortization!$J$6:$J$15,1) -> -6434.8148 | D25: =-INDEX(Amortization!$J$6:$J$15,2) -> -6434.8148 | E25: =-INDEX(Amortization!$J$6:$J$15,3) -> -6434.8148 | F25: =-INDEX(Amortization!$J$6:$J$15,4) -> -6434.8148 | G25: =-INDEX(Amortization!$J$6:$J$15,5) -> -6434.8148 | H25: =-INDEX(Amortization!$J$6:$J$15,6) -> -6434.8148 | I25: =-INDEX(Amortization!$J$6:$J$15,7) -> -6434.8148 | J25: =-INDEX(Amortization!$J$6:$J$15,8) -> -6434.8148 | K25: =-INDEX(Amortization!$J$6:$J$15,9) -> -6434.8148 | L25: =-INDEX(Amortization!$J$6:$J$15,10) -> -6434.8148
B26: Pre-Tax Cash Flow | C26: =C22+C25 -> 1956.6252 | D26: =D22+D25 -> 2189.3684 | E26: =E22+E25 -> 2427.9739 | F26: =F22+F25 -> 2672.5728 | G26: =G22+G25 -> 2923.2982 | H26: =H22+H25 -> 3180.2856 | I26: =I22+I25 -> 3443.6723 | J26: =J22+J25 -> 3713.598 | ... L26: =L22+L25 -> 4273.6349
B27: Cumulative Cash Flow | C27: =C26 -> 1956.6252 | D27: =C27+D26 -> 4145.9936 | E27: =D27+E26 -> 6573.9675 | F27: =E27+F26 -> 9246.5403 | G27: =F27+G26 -> 12169.838 | H27: =G27+H26 -> 15350.124 | I27: =H27+I26 -> 18793.796 | J27: =I27+J26 -> 22507.394 | K27: =J27+K26 -> 26497.599 | L27: =K27+L26 -> 30771.233
B29: COVERAGE & RETURN METRICS
B30: DSCR (NOI / Debt Service) | C30: =C22/-C25 -> 1.3040686 | D30: =D22/-D25 -> 1.340238 | E30: =E22/-E25 -> 1.3773184 | F30: =F22/-F25 -> 1.4153302 | G30: =G22/-G25 -> 1.4542941 | H30: =H22/-H25 -> 1.4942311 | I30: =I22/-I25 -> 1.5351626 | J30: =J22/-J25 -> 1.5771103 | ... L30: =L22/-L25 -> 1.6641426
B31: Cash-on-Cash Return (%) | C31: =C26/TotalCashInvested -> 0.056394207 | D31: =D26/TotalCashInvested -> 0.063102374 | E31: =E26/TotalCashInvested -> 0.069979505 | F31: =F26/TotalCashInvested -> 0.077029378 | G31: =G26/TotalCashInvested -> 0.084255832 | H31: =H26/TotalCashInvested -> 0.091662768 | I31: =I26/TotalCashInvested -> 0.099254148 | J31: =J26/TotalCashInvested -> 0.10703399 | ... L31: =L26/TotalCashInvested -> 0.12317548

Sheet Exit & Returns
B2: EXIT & RETURNS
B3: Sale, loan payoff, levered/unlevered IRR, equity multiple, and return decomposition at the Inputs!ExitYear toggle
B5: SALE ASSUMPTIONS
B6: Sale Price | C6: =PurchasePrice*(1+Appreciation)^ExitYear -> 127752.44
B7: Selling Costs | C7: =-C6*SellingCostPct -> -8942.6706
B8: Loan Payoff at Exit (from Amortization rollup) | C8: =-INDEX(Amortization!$M$6:$M$15,MATCH(ExitYear,Amortization!$I$6:$I$15,0)) -> -65318.899
B9: Net Sale Proceeds | C9: =C6+C7+C8 -> 53490.868
B11: LEVERED EQUITY CASH-FLOW VECTOR
C12: Yr 0 | D12: Yr 1 | E12: Yr 2 | F12: Yr 3 | G12: Yr 4 | H12: Yr 5 | I12: Yr 6 | J12: Yr 7 | K12: Yr 8 | L12: Yr 9 | M12: Yr 10
B13: Levered Equity Cash Flow | C13: =-TotalCashInvested -> -34695.5 | D13: =IF(1>ExitYear,0,IF(1=ExitYear,INDEX(CF_PTCF_Row,1)+C9,INDEX(CF_PTCF_Row,1))) -> 1956.6252 | E13: =IF(2>ExitYear,0,IF(2=ExitYear,INDEX(CF_PTCF_Row,2)+C9,INDEX(CF_PTCF_Row,2))) -> 2189.3684 | F13: =IF(3>ExitYear,0,IF(3=ExitYear,INDEX(CF_PTCF_Row,3)+C9,INDEX(CF_PTCF_Row,3))) -> 2427.9739 | G13: =IF(4>ExitYear,0,IF(4=ExitYear,INDEX(CF_PTCF_Row,4)+C9,INDEX(CF_PTCF_Row,4))) -> 2672.5728 | H13: =IF(5>ExitYear,0,IF(5=ExitYear,INDEX(CF_PTCF_Row,5)+C9,INDEX(CF_PTCF_Row,5))) -> 2923.2982 | I13: =IF(6>ExitYear,0,IF(6=ExitYear,INDEX(CF_PTCF_Row,6)+C9,INDEX(CF_PTCF_Row,6))) -> 3180.2856 | J13: =IF(7>ExitYear,0,IF(7=ExitYear,INDEX(CF_PTCF_Row,7)+C9,INDEX(CF_PTCF_Row,7))) -> 3443.6723 | K13: =IF(8>ExitYear,0,IF(8=ExitYear,INDEX(CF_PTCF_Row,8)+C9,INDEX(CF_PTCF_Row,8))) -> 3713.598 | L13: =IF(9>ExitYear,0,IF(9=ExitYear,INDEX(CF_PTCF_Row,9)+C9,INDEX(CF_PTCF_Row,9))) -> 3990.2043 | M13: =IF(10>ExitYear,0,IF(10=ExitYear,INDEX(CF_PTCF_Row,10)+C9,INDEX(CF_PTCF_Row,10))) -> 57764.502
B15: UNLEVERED (ALL-CASH) CASH-FLOW VECTOR
C16: Yr 0 | D16: Yr 1 | E16: Yr 2 | F16: Yr 3 | G16: Yr 4 | H16: Yr 5 | I16: Yr 6 | J16: Yr 7 | K16: Yr 8 | L16: Yr 9 | M16: Yr 10
B17: Unlevered (All-Cash) Cash Flow | C17: =-(PurchasePrice+ClosingCostAmt+InitialRepairs) -> -108797 | D17: =IF(1>ExitYear,0,IF(1=ExitYear,INDEX(CF_NOI_Row,1)+C6+C7,INDEX(CF_NOI_Row,1))) -> 8391.44 | E17: =IF(2>ExitYear,0,IF(2=ExitYear,INDEX(CF_NOI_Row,2)+C6+C7,INDEX(CF_NOI_Row,2))) -> 8624.1832 | F17: =IF(3>ExitYear,0,IF(3=ExitYear,INDEX(CF_NOI_Row,3)+C6+C7,INDEX(CF_NOI_Row,3))) -> 8862.7887 | G17: =IF(4>ExitYear,0,IF(4=ExitYear,INDEX(CF_NOI_Row,4)+C6+C7,INDEX(CF_NOI_Row,4))) -> 9107.3876 | H17: =IF(5>ExitYear,0,IF(5=ExitYear,INDEX(CF_NOI_Row,5)+C6+C7,INDEX(CF_NOI_Row,5))) -> 9358.113 | I17: =IF(6>ExitYear,0,IF(6=ExitYear,INDEX(CF_NOI_Row,6)+C6+C7,INDEX(CF_NOI_Row,6))) -> 9615.1003 | J17: =IF(7>ExitYear,0,IF(7=ExitYear,INDEX(CF_NOI_Row,7)+C6+C7,INDEX(CF_NOI_Row,7))) -> 9878.4871 | K17: =IF(8>ExitYear,0,IF(8=ExitYear,INDEX(CF_NOI_Row,8)+C6+C7,INDEX(CF_NOI_Row,8))) -> 10148.413 | L17: =IF(9>ExitYear,0,IF(9=ExitYear,INDEX(CF_NOI_Row,9)+C6+C7,INDEX(CF_NOI_Row,9))) -> 10425.019 | M17: =IF(10>ExitYear,0,IF(10=ExitYear,INDEX(CF_NOI_Row,10)+C6+C7,INDEX(CF_NOI_Row,10))) -> 129518.22
B19: RETURN SUMMARY
B20: 10-Yr Levered IRR | C20: =IRR(C13:M13) -> 0.11401212
B21: 10-Yr Unlevered (All-Cash) IRR | C21: =IRR(C17:M17) -> 0.091750235
B22: Equity Multiple (Levered) | C22: =SUM(D13:M13)/-C13 -> 2.4286176
B24: RETURN DECOMPOSITION (Levered, at Exit Year)
B25: Cash Flow Contribution (net of acquisition costs) | C25: =SUM(D13:M13)-C9-(ClosingCostAmt+OriginationAmt+InitialRepairs) -> 21025.733
B26: Principal Paydown Contribution | C26: =LoanAmount+C8 -> 9531.1007
B27: Appreciation Contribution (net of selling costs) | C27: =C6-PurchasePrice+C7 -> 19009.767
B28: Total Profit (check) | C28: =C25+C26+C27 -> 49566.601
B29: Total Profit (independent check: distributions - invested) | C29: =SUM(D13:M13)+C13 -> 49566.601

Sheet Sensitivity
B2: SENSITIVITY & BREAKEVEN
B5: (a) YEAR-1 MONTHLY CASH FLOW - Rent ($/mo) x Interest Rate
B6: Rate \ Rent -> | C6: 2100 | D6: 2200 | E6: 2300 | F6: 2400 | G6: 2500 | H6: 2600 | I6: 2700
B7: 0.065 | C7: =(C$6*(1-VacancyPct))*(1-MaintPct-CapexPct-MgmtPct)-(AssessedValueY1*TaxRate)/12-InsuranceY1/12-HOAmo+PMT($B7/12,LoanTermYrs*12,LoanAmount) -> 619.10375 | D7: =(D$6*(1-VacancyPct))*(1-MaintPct-CapexPct-MgmtPct)-(AssessedValueY1*TaxRate)/12-InsuranceY1/12-HOAmo+PMT($B7/12,LoanTermYrs*12,LoanAmount) -> 690.54375 | E7: =(E$6*(1-VacancyPct))*(1-MaintPct-CapexPct-MgmtPct)-(AssessedValueY1*TaxRate)/12-InsuranceY1/12-HOAmo+PMT($B7/12,LoanTermYrs*12,LoanAmount) -> 761.98375 | F7: =(F$6*(1-VacancyPct))*(1-MaintPct-CapexPct-MgmtPct)-(AssessedValueY1*TaxRate)/12-InsuranceY1/12-HOAmo+PMT($B7/12,LoanTermYrs*12,LoanAmount) -> 833.42375 | G7: =(G$6*(1-VacancyPct))*(1-MaintPct-CapexPct-MgmtPct)-(AssessedValueY1*TaxRate)/12-InsuranceY1/12-HOAmo+PMT($B7/12,LoanTermYrs*12,LoanAmount) -> 904.86375 | H7: =(H$6*(1-VacancyPct))*(1-MaintPct-CapexPct-MgmtPct)-(AssessedValueY1*TaxRate)/12-InsuranceY1/12-HOAmo+PMT($B7/12,LoanTermYrs*12,LoanAmount) -> 976.30375 | I7: =(I$6*(1-VacancyPct))*(1-MaintPct-CapexPct-MgmtPct)-(AssessedValueY1*TaxRate)/12-InsuranceY1/12-HOAmo+PMT($B7/12,LoanTermYrs*12,LoanAmount) -> 1047.7438
B8: 0.0675 | C8: =(C$6*(1-VacancyPct))*(1-MaintPct-CapexPct-MgmtPct)-(AssessedValueY1*TaxRate)/12-InsuranceY1/12-HOAmo+PMT($B8/12,LoanTermYrs*12,LoanAmount) -> 606.73099 | D8: =(D$6*(1-VacancyPct))*(1-MaintPct-CapexPct-MgmtPct)-(AssessedValueY1*TaxRate)/12-InsuranceY1/12-HOAmo+PMT($B8/12,LoanTermYrs*12,LoanAmount) -> 678.17099 | E8: =(E$6*(1-VacancyPct))*(1-MaintPct-CapexPct-MgmtPct)-(AssessedValueY1*TaxRate)/12-InsuranceY1/12-HOAmo+PMT($B8/12,LoanTermYrs*12,LoanAmount) -> 749.61099 | F8: =(F$6*(1-VacancyPct))*(1-MaintPct-CapexPct-MgmtPct)-(AssessedValueY1*TaxRate)/12-InsuranceY1/12-HOAmo+PMT($B8/12,LoanTermYrs*12,LoanAmount) -> 821.05099 | G8: =(G$6*(1-VacancyPct))*(1-MaintPct-CapexPct-MgmtPct)-(AssessedValueY1*TaxRate)/12-InsuranceY1/12-HOAmo+PMT($B8/12,LoanTermYrs*12,LoanAmount) -> 892.49099 | H8: =(H$6*(1-VacancyPct))*(1-MaintPct-CapexPct-MgmtPct)-(AssessedValueY1*TaxRate)/12-InsuranceY1/12-HOAmo+PMT($B8/12,LoanTermYrs*12,LoanAmount) -> 963.93099 | I8: =(I$6*(1-VacancyPct))*(1-MaintPct-CapexPct-MgmtPct)-(AssessedValueY1*TaxRate)/12-InsuranceY1/12-HOAmo+PMT($B8/12,LoanTermYrs*12,LoanAmount) -> 1035.371
B9: 0.07 | C9: =(C$6*(1-VacancyPct))*(1-MaintPct-CapexPct-MgmtPct)-(AssessedValueY1*TaxRate)/12-InsuranceY1/12-HOAmo+PMT($B9/12,LoanTermYrs*12,LoanAmount) -> 594.22775 | D9: =(D$6*(1-VacancyPct))*(1-MaintPct-CapexPct-MgmtPct)-(AssessedValueY1*TaxRate)/12-InsuranceY1/12-HOAmo+PMT($B9/12,LoanTermYrs*12,LoanAmount) -> 665.66775 | E9: =(E$6*(1-VacancyPct))*(1-MaintPct-CapexPct-MgmtPct)-(AssessedValueY1*TaxRate)/12-InsuranceY1/12-HOAmo+PMT($B9/12,LoanTermYrs*12,LoanAmount) -> 737.10775 | F9: =(F$6*(1-VacancyPct))*(1-MaintPct-CapexPct-MgmtPct)-(AssessedValueY1*TaxRate)/12-InsuranceY1/12-HOAmo+PMT($B9/12,LoanTermYrs*12,LoanAmount) -> 808.54775 | G9: =(G$6*(1-VacancyPct))*(1-MaintPct-CapexPct-MgmtPct)-(AssessedValueY1*TaxRate)/12-InsuranceY1/12-HOAmo+PMT($B9/12,LoanTermYrs*12,LoanAmount) -> 879.98775 | H9: =(H$6*(1-VacancyPct))*(1-MaintPct-CapexPct-MgmtPct)-(AssessedValueY1*TaxRate)/12-InsuranceY1/12-HOAmo+PMT($B9/12,LoanTermYrs*12,LoanAmount) -> 951.42775 | I9: =(I$6*(1-VacancyPct))*(1-MaintPct-CapexPct-MgmtPct)-(AssessedValueY1*TaxRate)/12-InsuranceY1/12-HOAmo+PMT($B9/12,LoanTermYrs*12,LoanAmount) -> 1022.8677
B10: 0.0725 | C10: =(C$6*(1-VacancyPct))*(1-MaintPct-CapexPct-MgmtPct)-(AssessedValueY1*TaxRate)/12-InsuranceY1/12-HOAmo+PMT($B10/12,LoanTermYrs*12,LoanAmount) -> 581.59772 | D10: =(D$6*(1-VacancyPct))*(1-MaintPct-CapexPct-MgmtPct)-(AssessedValueY1*TaxRate)/12-InsuranceY1/12-HOAmo+PMT($B10/12,LoanTermYrs*12,LoanAmount) -> 653.03772 | E10: =(E$6*(1-VacancyPct))*(1-MaintPct-CapexPct-MgmtPct)-(AssessedValueY1*TaxRate)/12-InsuranceY1/12-HOAmo+PMT($B10/12,LoanTermYrs*12,LoanAmount) -> 724.47772 | F10: =(F$6*(1-VacancyPct))*(1-MaintPct-CapexPct-MgmtPct)-(AssessedValueY1*TaxRate)/12-InsuranceY1/12-HOAmo+PMT($B10/12,LoanTermYrs*12,LoanAmount) -> 795.91772 | G10: =(G$6*(1-VacancyPct))*(1-MaintPct-CapexPct-MgmtPct)-(AssessedValueY1*TaxRate)/12-InsuranceY1/12-HOAmo+PMT($B10/12,LoanTermYrs*12,LoanAmount) -> 867.35772 | H10: =(H$6*(1-VacancyPct))*(1-MaintPct-CapexPct-MgmtPct)-(AssessedValueY1*TaxRate)/12-InsuranceY1/12-HOAmo+PMT($B10/12,LoanTermYrs*12,LoanAmount) -> 938.79772 | I10: =(I$6*(1-VacancyPct))*(1-MaintPct-CapexPct-MgmtPct)-(AssessedValueY1*TaxRate)/12-InsuranceY1/12-HOAmo+PMT($B10/12,LoanTermYrs*12,LoanAmount) -> 1010.2377
B11: 0.075 | C11: =(C$6*(1-VacancyPct))*(1-MaintPct-CapexPct-MgmtPct)-(AssessedValueY1*TaxRate)/12-InsuranceY1/12-HOAmo+PMT($B11/12,LoanTermYrs*12,LoanAmount) -> 568.84461 | D11: =(D$6*(1-VacancyPct))*(1-MaintPct-CapexPct-MgmtPct)-(AssessedValueY1*TaxRate)/12-InsuranceY1/12-HOAmo+PMT($B11/12,LoanTermYrs*12,LoanAmount) -> 640.28461 | E11: =(E$6*(1-VacancyPct))*(1-MaintPct-CapexPct-MgmtPct)-(AssessedValueY1*TaxRate)/12-InsuranceY1/12-HOAmo+PMT($B11/12,LoanTermYrs*12,LoanAmount) -> 711.72461 | F11: =(F$6*(1-VacancyPct))*(1-MaintPct-CapexPct-MgmtPct)-(AssessedValueY1*TaxRate)/12-InsuranceY1/12-HOAmo+PMT($B11/12,LoanTermYrs*12,LoanAmount) -> 783.16461 | G11: =(G$6*(1-VacancyPct))*(1-MaintPct-CapexPct-MgmtPct)-(AssessedValueY1*TaxRate)/12-InsuranceY1/12-HOAmo+PMT($B11/12,LoanTermYrs*12,LoanAmount) -> 854.60461 | H11: =(H$6*(1-VacancyPct))*(1-MaintPct-CapexPct-MgmtPct)-(AssessedValueY1*TaxRate)/12-InsuranceY1/12-HOAmo+PMT($B11/12,LoanTermYrs*12,LoanAmount) -> 926.04461 | I11: =(I$6*(1-VacancyPct))*(1-MaintPct-CapexPct-MgmtPct)-(AssessedValueY1*TaxRate)/12-InsuranceY1/12-HOAmo+PMT($B11/12,LoanTermYrs*12,LoanAmount) -> 997.48461
B12: 0.0775 | C12: =(C$6*(1-VacancyPct))*(1-MaintPct-CapexPct-MgmtPct)-(AssessedValueY1*TaxRate)/12-InsuranceY1/12-HOAmo+PMT($B12/12,LoanTermYrs*12,LoanAmount) -> 555.9721 | D12: =(D$6*(1-VacancyPct))*(1-MaintPct-CapexPct-MgmtPct)-(AssessedValueY1*TaxRate)/12-InsuranceY1/12-HOAmo+PMT($B12/12,LoanTermYrs*12,LoanAmount) -> 627.4121 | E12: =(E$6*(1-VacancyPct))*(1-MaintPct-CapexPct-MgmtPct)-(AssessedValueY1*TaxRate)/12-InsuranceY1/12-HOAmo+PMT($B12/12,LoanTermYrs*12,LoanAmount) -> 698.8521 | F12: =(F$6*(1-VacancyPct))*(1-MaintPct-CapexPct-MgmtPct)-(AssessedValueY1*TaxRate)/12-InsuranceY1/12-HOAmo+PMT($B12/12,LoanTermYrs*12,LoanAmount) -> 770.2921 | G12: =(G$6*(1-VacancyPct))*(1-MaintPct-CapexPct-MgmtPct)-(AssessedValueY1*TaxRate)/12-InsuranceY1/12-HOAmo+PMT($B12/12,LoanTermYrs*12,LoanAmount) -> 841.7321 | H12: =(H$6*(1-VacancyPct))*(1-MaintPct-CapexPct-MgmtPct)-(AssessedValueY1*TaxRate)/12-InsuranceY1/12-HOAmo+PMT($B12/12,LoanTermYrs*12,LoanAmount) -> 913.1721 | I12: =(I$6*(1-VacancyPct))*(1-MaintPct-CapexPct-MgmtPct)-(AssessedValueY1*TaxRate)/12-InsuranceY1/12-HOAmo+PMT($B12/12,LoanTermYrs*12,LoanAmount) -> 984.6121
B13: 0.08 | C13: =(C$6*(1-VacancyPct))*(1-MaintPct-CapexPct-MgmtPct)-(AssessedValueY1*TaxRate)/12-InsuranceY1/12-HOAmo+PMT($B13/12,LoanTermYrs*12,LoanAmount) -> 542.98388 | D13: =(D$6*(1-VacancyPct))*(1-MaintPct-CapexPct-MgmtPct)-(AssessedValueY1*TaxRate)/12-InsuranceY1/12-HOAmo+PMT($B13/12,LoanTermYrs*12,LoanAmount) -> 614.42388 | E13: =(E$6*(1-VacancyPct))*(1-MaintPct-CapexPct-MgmtPct)-(AssessedValueY1*TaxRate)/12-InsuranceY1/12-HOAmo+PMT($B13/12,LoanTermYrs*12,LoanAmount) -> 685.86388 | F13: =(F$6*(1-VacancyPct))*(1-MaintPct-CapexPct-MgmtPct)-(AssessedValueY1*TaxRate)/12-InsuranceY1/12-HOAmo+PMT($B13/12,LoanTermYrs*12,LoanAmount) -> 757.30388 | G13: =(G$6*(1-VacancyPct))*(1-MaintPct-CapexPct-MgmtPct)-(AssessedValueY1*TaxRate)/12-InsuranceY1/12-HOAmo+PMT($B13/12,LoanTermYrs*12,LoanAmount) -> 828.74388 | H13: =(H$6*(1-VacancyPct))*(1-MaintPct-CapexPct-MgmtPct)-(AssessedValueY1*TaxRate)/12-InsuranceY1/12-HOAmo+PMT($B13/12,LoanTermYrs*12,LoanAmount) -> 900.18388 | I13: =(I$6*(1-VacancyPct))*(1-MaintPct-CapexPct-MgmtPct)-(AssessedValueY1*TaxRate)/12-InsuranceY1/12-HOAmo+PMT($B13/12,LoanTermYrs*12,LoanAmount) -> 971.62388
B15: (b1) TOTAL PROFIT AT EXIT ($) - Appreciation Rate x Exit Year
B16: Appr \ Exit Yr -> | C16: 5 | D16: 6 | E16: 7 | F16: 8 | G16: 9 | H16: 10
B17: 0.02 | C17: =(((MonthlyRentY1*12*(1-VacancyPct))*(((1+RentGrowth)^$B17-1)/RentGrowth))*(1-MaintPct-CapexPct-MgmtPct)-((AssessedValueY1*TaxRate)*(((1+AssessedGrowth)^$B17-1)/AssessedGrowth))-(InsuranceY1*(((1+InsuranceGrowth)^$B17-1)/InsuranceGrowth))-(HOAmo*12*$B17)-((-PMT(InterestRate/12,LoanTermYrs*12,LoanAmount)*12)*$B17))+((PurchasePrice*(1+C$16)^$B17)-((PurchasePrice*(1+C$16)^$B17)*SellingCostPct)-(LoanAmount*(((1+InterestRate/12)^(LoanTermYrs*12)-(1+InterestRate/12)^($B17*12))/((1+InterestRate/12)^(LoanTermYrs*12)-1))))-TotalCashInvested -> -13295.644 | D17: =(((MonthlyRentY1*12*(1-VacancyPct))*(((1+RentGrowth)^$B17-1)/RentGrowth))*(1-MaintPct-CapexPct-MgmtPct)-((AssessedValueY1*TaxRate)*(((1+AssessedGrowth)^$B17-1)/AssessedGrowth))-(InsuranceY1*(((1+InsuranceGrowth)^$B17-1)/InsuranceGrowth))-(HOAmo*12*$B17)-((-PMT(InterestRate/12,LoanTermYrs*12,LoanAmount)*12)*$B17))+((PurchasePrice*(1+D$16)^$B17)-((PurchasePrice*(1+D$16)^$B17)*SellingCostPct)-(LoanAmount*(((1+InterestRate/12)^(LoanTermYrs*12)-(1+InterestRate/12)^($B17*12))/((1+InterestRate/12)^(LoanTermYrs*12)-1))))-TotalCashInvested -> -12998.599 | E17: =(((MonthlyRentY1*12*(1-VacancyPct))*(((1+RentGrowth)^$B17-1)/RentGrowth))*(1-MaintPct-CapexPct-MgmtPct)-((AssessedValueY1*TaxRate)*(((1+AssessedGrowth)^$B17-1)/AssessedGrowth))-(InsuranceY1*(((1+InsuranceGrowth)^$B17-1)/InsuranceGrowth))-(HOAmo*12*$B17)-((-PMT(InterestRate/12,LoanTermYrs*12,LoanAmount)*12)*$B17))+((PurchasePrice*(1+E$16)^$B17)-((PurchasePrice*(1+E$16)^$B17)*SellingCostPct)-(LoanAmount*(((1+InterestRate/12)^(LoanTermYrs*12)-(1+InterestRate/12)^($B17*12))/((1+InterestRate/12)^(LoanTermYrs*12)-1))))-TotalCashInvested -> -12740.546 | F17: =(((MonthlyRentY1*12*(1-VacancyPct))*(((1+RentGrowth)^$B17-1)/RentGrowth))*(1-MaintPct-CapexPct-MgmtPct)-((AssessedValueY1*TaxRate)*(((1+AssessedGrowth)^$B17-1)/AssessedGrowth))-(InsuranceY1*(((1+InsuranceGrowth)^$B17-1)/InsuranceGrowth))-(HOAmo*12*$B17)-((-PMT(InterestRate/12,LoanTermYrs*12,LoanAmount)*12)*$B17))+((PurchasePrice*(1+F$16)^$B17)-((PurchasePrice*(1+F$16)^$B17)*SellingCostPct)-(LoanAmount*(((1+InterestRate/12)^(LoanTermYrs*12)-(1+InterestRate/12)^($B17*12))/((1+InterestRate/12)^(LoanTermYrs*12)-1))))-TotalCashInvested -> -12512.355 | G17: =(((MonthlyRentY1*12*(1-VacancyPct))*(((1+RentGrowth)^$B17-1)/RentGrowth))*(1-MaintPct-CapexPct-MgmtPct)-((AssessedValueY1*TaxRate)*(((1+AssessedGrowth)^$B17-1)/AssessedGrowth))-(InsuranceY1*(((1+InsuranceGrowth)^$B17-1)/InsuranceGrowth))-(HOAmo*12*$B17)-((-PMT(InterestRate/12,LoanTermYrs*12,LoanAmount)*12)*$B17))+((PurchasePrice*(1+G$16)^$B17)-((PurchasePrice*(1+G$16)^$B17)*SellingCostPct)-(LoanAmount*(((1+InterestRate/12)^(LoanTermYrs*12)-(1+InterestRate/12)^($B17*12))/((1+InterestRate/12)^(LoanTermYrs*12)-1))))-TotalCashInvested -> -12307.774 | H17: =(((MonthlyRentY1*12*(1-VacancyPct))*(((1+RentGrowth)^$B17-1)/RentGrowth))*(1-MaintPct-CapexPct-MgmtPct)-((AssessedValueY1*TaxRate)*(((1+AssessedGrowth)^$B17-1)/AssessedGrowth))-(InsuranceY1*(((1+InsuranceGrowth)^$B17-1)/InsuranceGrowth))-(HOAmo*12*$B17)-((-PMT(InterestRate/12,LoanTermYrs*12,LoanAmount)*12)*$B17))+((PurchasePrice*(1+H$16)^$B17)-((PurchasePrice*(1+H$16)^$B17)*SellingCostPct)-(LoanAmount*(((1+InterestRate/12)^(LoanTermYrs*12)-(1+InterestRate/12)^($B17*12))/((1+InterestRate/12)^(LoanTermYrs*12)-1))))-TotalCashInvested -> -12122.337
B18: 0.025 | C18: =(((MonthlyRentY1*12*(1-VacancyPct))*(((1+RentGrowth)^$B18-1)/RentGrowth))*(1-MaintPct-CapexPct-MgmtPct)-((AssessedValueY1*TaxRate)*(((1+AssessedGrowth)^$B18-1)/AssessedGrowth))-(InsuranceY1*(((1+InsuranceGrowth)^$B18-1)/InsuranceGrowth))-(HOAmo*12*$B18)-((-PMT(InterestRate/12,LoanTermYrs*12,LoanAmount)*12)*$B18))+((PurchasePrice*(1+C$16)^$B18)-((PurchasePrice*(1+C$16)^$B18)*SellingCostPct)-(LoanAmount*(((1+InterestRate/12)^(LoanTermYrs*12)-(1+InterestRate/12)^($B18*12))/((1+InterestRate/12)^(LoanTermYrs*12)-1))))-TotalCashInvested -> -12417.531 | D18: =(((MonthlyRentY1*12*(1-VacancyPct))*(((1+RentGrowth)^$B18-1)/RentGrowth))*(1-MaintPct-CapexPct-MgmtPct)-((AssessedValueY1*TaxRate)*(((1+AssessedGrowth)^$B18-1)/AssessedGrowth))-(InsuranceY1*(((1+InsuranceGrowth)^$B18-1)/InsuranceGrowth))-(HOAmo*12*$B18)-((-PMT(InterestRate/12,LoanTermYrs*12,LoanAmount)*12)*$B18))+((PurchasePrice*(1+D$16)^$B18)-((PurchasePrice*(1+D$16)^$B18)*SellingCostPct)-(LoanAmount*(((1+InterestRate/12)^(LoanTermYrs*12)-(1+InterestRate/12)^($B18*12))/((1+InterestRate/12)^(LoanTermYrs*12)-1))))-TotalCashInvested -> -12042.739 | E18: =(((MonthlyRentY1*12*(1-VacancyPct))*(((1+RentGrowth)^$B18-1)/RentGrowth))*(1-MaintPct-CapexPct-MgmtPct)-((AssessedValueY1*TaxRate)*(((1+AssessedGrowth)^$B18-1)/AssessedGrowth))-(InsuranceY1*(((1+InsuranceGrowth)^$B18-1)/InsuranceGrowth))-(HOAmo*12*$B18)-((-PMT(InterestRate/12,LoanTermYrs*12,LoanAmount)*12)*$B18))+((PurchasePrice*(1+E$16)^$B18)-((PurchasePrice*(1+E$16)^$B18)*SellingCostPct)-(LoanAmount*(((1+InterestRate/12)^(LoanTermYrs*12)-(1+InterestRate/12)^($B18*12))/((1+InterestRate/12)^(LoanTermYrs*12)-1))))-TotalCashInvested -> -11716.911 | F18: =(((MonthlyRentY1*12*(1-VacancyPct))*(((1+RentGrowth)^$B18-1)/RentGrowth))*(1-MaintPct-CapexPct-MgmtPct)-((AssessedValueY1*TaxRate)*(((1+AssessedGrowth)^$B18-1)/AssessedGrowth))-(InsuranceY1*(((1+InsuranceGrowth)^$B18-1)/InsuranceGrowth))-(HOAmo*12*$B18)-((-PMT(InterestRate/12,LoanTermYrs*12,LoanAmount)*12)*$B18))+((PurchasePrice*(1+F$16)^$B18)-((PurchasePrice*(1+F$16)^$B18)*SellingCostPct)-(LoanAmount*(((1+InterestRate/12)^(LoanTermYrs*12)-(1+InterestRate/12)^($B18*12))/((1+InterestRate/12)^(LoanTermYrs*12)-1))))-TotalCashInvested -> -11428.605 | G18: =(((MonthlyRentY1*12*(1-VacancyPct))*(((1+RentGrowth)^$B18-1)/RentGrowth))*(1-MaintPct-CapexPct-MgmtPct)-((AssessedValueY1*TaxRate)*(((1+AssessedGrowth)^$B18-1)/AssessedGrowth))-(InsuranceY1*(((1+InsuranceGrowth)^$B18-1)/InsuranceGrowth))-(HOAmo*12*$B18)-((-PMT(InterestRate/12,LoanTermYrs*12,LoanAmount)*12)*$B18))+((PurchasePrice*(1+G$16)^$B18)-((PurchasePrice*(1+G$16)^$B18)*SellingCostPct)-(LoanAmount*(((1+InterestRate/12)^(LoanTermYrs*12)-(1+InterestRate/12)^($B18*12))/((1+InterestRate/12)^(LoanTermYrs*12)-1))))-TotalCashInvested -> -11169.987 | H18: =(((MonthlyRentY1*12*(1-VacancyPct))*(((1+RentGrowth)^$B18-1)/RentGrowth))*(1-MaintPct-CapexPct-MgmtPct)-((AssessedValueY1*TaxRate)*(((1+AssessedGrowth)^$B18-1)/AssessedGrowth))-(InsuranceY1*(((1+InsuranceGrowth)^$B18-1)/InsuranceGrowth))-(HOAmo*12*$B18)-((-PMT(InterestRate/12,LoanTermYrs*12,LoanAmount)*12)*$B18))+((PurchasePrice*(1+H$16)^$B18)-((PurchasePrice*(1+H$16)^$B18)*SellingCostPct)-(LoanAmount*(((1+InterestRate/12)^(LoanTermYrs*12)-(1+InterestRate/12)^($B18*12))/((1+InterestRate/12)^(LoanTermYrs*12)-1))))-TotalCashInvested -> -10935.45
B19: 0.03 | C19: =(((MonthlyRentY1*12*(1-VacancyPct))*(((1+RentGrowth)^$B19-1)/RentGrowth))*(1-MaintPct-CapexPct-MgmtPct)-((AssessedValueY1*TaxRate)*(((1+AssessedGrowth)^$B19-1)/AssessedGrowth))-(InsuranceY1*(((1+InsuranceGrowth)^$B19-1)/InsuranceGrowth))-(HOAmo*12*$B19)-((-PMT(InterestRate/12,LoanTermYrs*12,LoanAmount)*12)*$B19))+((PurchasePrice*(1+C$16)^$B19)-((PurchasePrice*(1+C$16)^$B19)*SellingCostPct)-(LoanAmount*(((1+InterestRate/12)^(LoanTermYrs*12)-(1+InterestRate/12)^($B19*12))/((1+InterestRate/12)^(LoanTermYrs*12)-1))))-TotalCashInvested -> -11531.621 | D19: =(((MonthlyRentY1*12*(1-VacancyPct))*(((1+RentGrowth)^$B19-1)/RentGrowth))*(1-MaintPct-CapexPct-MgmtPct)-((AssessedValueY1*TaxRate)*(((1+AssessedGrowth)^$B19-1)/AssessedGrowth))-(InsuranceY1*(((1+InsuranceGrowth)^$B19-1)/InsuranceGrowth))-(HOAmo*12*$B19)-((-PMT(InterestRate/12,LoanTermYrs*12,LoanAmount)*12)*$B19))+((PurchasePrice*(1+D$16)^$B19)-((PurchasePrice*(1+D$16)^$B19)*SellingCostPct)-(LoanAmount*(((1+InterestRate/12)^(LoanTermYrs*12)-(1+InterestRate/12)^($B19*12))/((1+InterestRate/12)^(LoanTermYrs*12)-1))))-TotalCashInvested -> -11077.649 | E19: =(((MonthlyRentY1*12*(1-VacancyPct))*(((1+RentGrowth)^$B19-1)/RentGrowth))*(1-MaintPct-CapexPct-MgmtPct)-((AssessedValueY1*TaxRate)*(((1+AssessedGrowth)^$B19-1)/AssessedGrowth))-(InsuranceY1*(((1+InsuranceGrowth)^$B19-1)/InsuranceGrowth))-(HOAmo*12*$B19)-((-PMT(InterestRate/12,LoanTermYrs*12,LoanAmount)*12)*$B19))+((PurchasePrice*(1+E$16)^$B19)-((PurchasePrice*(1+E$16)^$B19)*SellingCostPct)-(LoanAmount*(((1+InterestRate/12)^(LoanTermYrs*12)-(1+InterestRate/12)^($B19*12))/((1+InterestRate/12)^(LoanTermYrs*12)-1))))-TotalCashInvested -> -10682.699 | F19: =(((MonthlyRentY1*12*(1-VacancyPct))*(((1+RentGrowth)^$B19-1)/RentGrowth))*(1-MaintPct-CapexPct-MgmtPct)-((AssessedValueY1*TaxRate)*(((1+AssessedGrowth)^$B19-1)/AssessedGrowth))-(InsuranceY1*(((1+InsuranceGrowth)^$B19-1)/InsuranceGrowth))-(HOAmo*12*$B19)-((-PMT(InterestRate/12,LoanTermYrs*12,LoanAmount)*12)*$B19))+((PurchasePrice*(1+F$16)^$B19)-((PurchasePrice*(1+F$16)^$B19)*SellingCostPct)-(LoanAmount*(((1+InterestRate/12)^(LoanTermYrs*12)-(1+InterestRate/12)^($B19*12))/((1+InterestRate/12)^(LoanTermYrs*12)-1))))-TotalCashInvested -> -10333.014 | G19: =(((MonthlyRentY1*12*(1-VacancyPct))*(((1+RentGrowth)^$B19-1)/RentGrowth))*(1-MaintPct-CapexPct-MgmtPct)-((AssessedValueY1*TaxRate)*(((1+AssessedGrowth)^$B19-1)/AssessedGrowth))-(InsuranceY1*(((1+InsuranceGrowth)^$B19-1)/InsuranceGrowth))-(HOAmo*12*$B19)-((-PMT(InterestRate/12,LoanTermYrs*12,LoanAmount)*12)*$B19))+((PurchasePrice*(1+G$16)^$B19)-((PurchasePrice*(1+G$16)^$B19)*SellingCostPct)-(LoanAmount*(((1+InterestRate/12)^(LoanTermYrs*12)-(1+InterestRate/12)^($B19*12))/((1+InterestRate/12)^(LoanTermYrs*12)-1))))-TotalCashInvested -> -10019.161 | H19: =(((MonthlyRentY1*12*(1-VacancyPct))*(((1+RentGrowth)^$B19-1)/RentGrowth))*(1-MaintPct-CapexPct-MgmtPct)-((AssessedValueY1*TaxRate)*(((1+AssessedGrowth)^$B19-1)/AssessedGrowth))-(InsuranceY1*(((1+InsuranceGrowth)^$B19-1)/InsuranceGrowth))-(HOAmo*12*$B19)-((-PMT(InterestRate/12,LoanTermYrs*12,LoanAmount)*12)*$B19))+((PurchasePrice*(1+H$16)^$B19)-((PurchasePrice*(1+H$16)^$B19)*SellingCostPct)-(LoanAmount*(((1+InterestRate/12)^(LoanTermYrs*12)-(1+InterestRate/12)^($B19*12))/((1+InterestRate/12)^(LoanTermYrs*12)-1))))-TotalCashInvested -> -9734.3902
B20: 0.035 | C20: =(((MonthlyRentY1*12*(1-VacancyPct))*(((1+RentGrowth)^$B20-1)/RentGrowth))*(1-MaintPct-CapexPct-MgmtPct)-((AssessedValueY1*TaxRate)*(((1+AssessedGrowth)^$B20-1)/AssessedGrowth))-(InsuranceY1*(((1+InsuranceGrowth)^$B20-1)/InsuranceGrowth))-(HOAmo*12*$B20)-((-PMT(InterestRate/12,LoanTermYrs*12,LoanAmount)*12)*$B20))+((PurchasePrice*(1+C$16)^$B20)-((PurchasePrice*(1+C$16)^$B20)*SellingCostPct)-(LoanAmount*(((1+InterestRate/12)^(LoanTermYrs*12)-(1+InterestRate/12)^($B20*12))/((1+InterestRate/12)^(LoanTermYrs*12)-1))))-TotalCashInvested -> -10637.843 | D20: =(((MonthlyRentY1*12*(1-VacancyPct))*(((1+RentGrowth)^$B20-1)/RentGrowth))*(1-MaintPct-CapexPct-MgmtPct)-((AssessedValueY1*TaxRate)*(((1+AssessedGrowth)^$B20-1)/AssessedGrowth))-(InsuranceY1*(((1+InsuranceGrowth)^$B20-1)/InsuranceGrowth))-(HOAmo*12*$B20)-((-PMT(InterestRate/12,LoanTermYrs*12,LoanAmount)*12)*$B20))+((PurchasePrice*(1+D$16)^$B20)-((PurchasePrice*(1+D$16)^$B20)*SellingCostPct)-(LoanAmount*(((1+InterestRate/12)^(LoanTermYrs*12)-(1+InterestRate/12)^($B20*12))/((1+InterestRate/12)^(LoanTermYrs*12)-1))))-TotalCashInvested -> -10103.236 | E20: =(((MonthlyRentY1*12*(1-VacancyPct))*(((1+RentGrowth)^$B20-1)/RentGrowth))*(1-MaintPct-CapexPct-MgmtPct)-((AssessedValueY1*TaxRate)*(((1+AssessedGrowth)^$B20-1)/AssessedGrowth))-(InsuranceY1*(((1+InsuranceGrowth)^$B20-1)/InsuranceGrowth))-(HOAmo*12*$B20)-((-PMT(InterestRate/12,LoanTermYrs*12,LoanAmount)*12)*$B20))+((PurchasePrice*(1+E$16)^$B20)-((PurchasePrice*(1+E$16)^$B20)*SellingCostPct)-(LoanAmount*(((1+InterestRate/12)^(LoanTermYrs*12)-(1+InterestRate/12)^($B20*12))/((1+InterestRate/12)^(LoanTermYrs*12)-1))))-TotalCashInvested -> -9637.802 | F20: =(((MonthlyRentY1*12*(1-VacancyPct))*(((1+RentGrowth)^$B20-1)/RentGrowth))*(1-MaintPct-CapexPct-MgmtPct)-((AssessedValueY1*TaxRate)*(((1+AssessedGrowth)^$B20-1)/AssessedGrowth))-(InsuranceY1*(((1+InsuranceGrowth)^$B20-1)/InsuranceGrowth))-(HOAmo*12*$B20)-((-PMT(InterestRate/12,LoanTermYrs*12,LoanAmount)*12)*$B20))+((PurchasePrice*(1+F$16)^$B20)-((PurchasePrice*(1+F$16)^$B20)*SellingCostPct)-(LoanAmount*(((1+InterestRate/12)^(LoanTermYrs*12)-(1+InterestRate/12)^($B20*12))/((1+InterestRate/12)^(LoanTermYrs*12)-1))))-TotalCashInvested -> -9225.4501 | G20: =(((MonthlyRentY1*12*(1-VacancyPct))*(((1+RentGrowth)^$B20-1)/RentGrowth))*(1-MaintPct-CapexPct-MgmtPct)-((AssessedValueY1*TaxRate)*(((1+AssessedGrowth)^$B20-1)/AssessedGrowth))-(InsuranceY1*(((1+InsuranceGrowth)^$B20-1)/InsuranceGrowth))-(HOAmo*12*$B20)-((-PMT(InterestRate/12,LoanTermYrs*12,LoanAmount)*12)*$B20))+((PurchasePrice*(1+G$16)^$B20)-((PurchasePrice*(1+G$16)^$B20)*SellingCostPct)-(LoanAmount*(((1+InterestRate/12)^(LoanTermYrs*12)-(1+InterestRate/12)^($B20*12))/((1+InterestRate/12)^(LoanTermYrs*12)-1))))-TotalCashInvested -> -8855.1457 | H20: =(((MonthlyRentY1*12*(1-VacancyPct))*(((1+RentGrowth)^$B20-1)/RentGrowth))*(1-MaintPct-CapexPct-MgmtPct)-((AssessedValueY1*TaxRate)*(((1+AssessedGrowth)^$B20-1)/AssessedGrowth))-(InsuranceY1*(((1+InsuranceGrowth)^$B20-1)/InsuranceGrowth))-(HOAmo*12*$B20)-((-PMT(InterestRate/12,LoanTermYrs*12,LoanAmount)*12)*$B20))+((PurchasePrice*(1+H$16)^$B20)-((PurchasePrice*(1+H$16)^$B20)*SellingCostPct)-(LoanAmount*(((1+InterestRate/12)^(LoanTermYrs*12)-(1+InterestRate/12)^($B20*12))/((1+InterestRate/12)^(LoanTermYrs*12)-1))))-TotalCashInvested -> -8518.9862
B21: 0.04 | C21: =(((MonthlyRentY1*12*(1-VacancyPct))*(((1+RentGrowth)^$B21-1)/RentGrowth))*(1-MaintPct-CapexPct-MgmtPct)-((AssessedValueY1*TaxRate)*(((1+AssessedGrowth)^$B21-1)/AssessedGrowth))-(InsuranceY1*(((1+InsuranceGrowth)^$B21-1)/InsuranceGrowth))-(HOAmo*12*$B21)-((-PMT(InterestRate/12,LoanTermYrs*12,LoanAmount)*12)*$B21))+((PurchasePrice*(1+C$16)^$B21)-((PurchasePrice*(1+C$16)^$B21)*SellingCostPct)-(LoanAmount*(((1+InterestRate/12)^(LoanTermYrs*12)-(1+InterestRate/12)^($B21*12))/((1+InterestRate/12)^(LoanTermYrs*12)-1))))-TotalCashInvested -> -9736.1271 | D21: =(((MonthlyRentY1*12*(1-VacancyPct))*(((1+RentGrowth)^$B21-1)/RentGrowth))*(1-MaintPct-CapexPct-MgmtPct)-((AssessedValueY1*TaxRate)*(((1+AssessedGrowth)^$B21-1)/AssessedGrowth))-(InsuranceY1*(((1+InsuranceGrowth)^$B21-1)/InsuranceGrowth))-(HOAmo*12*$B21)-((-PMT(InterestRate/12,LoanTermYrs*12,LoanAmount)*12)*$B21))+((PurchasePrice*(1+D$16)^$B21)-((PurchasePrice*(1+D$16)^$B21)*SellingCostPct)-(LoanAmount*(((1+InterestRate/12)^(LoanTermYrs*12)-(1+InterestRate/12)^($B21*12))/((1+InterestRate/12)^(LoanTermYrs*12)-1))))-TotalCashInvested -> -9119.412 | E21: =(((MonthlyRentY1*12*(1-VacancyPct))*(((1+RentGrowth)^$B21-1)/RentGrowth))*(1-MaintPct-CapexPct-MgmtPct)-((AssessedValueY1*TaxRate)*(((1+AssessedGrowth)^$B21-1)/AssessedGrowth))-(InsuranceY1*(((1+InsuranceGrowth)^$B21-1)/InsuranceGrowth))-(HOAmo*12*$B21)-((-PMT(InterestRate/12,LoanTermYrs*12,LoanAmount)*12)*$B21))+((PurchasePrice*(1+E$16)^$B21)-((PurchasePrice*(1+E$16)^$B21)*SellingCostPct)-(LoanAmount*(((1+InterestRate/12)^(LoanTermYrs*12)-(1+InterestRate/12)^($B21*12))/((1+InterestRate/12)^(LoanTermYrs*12)-1))))-TotalCashInvested -> -8582.1066 | F21: =(((MonthlyRentY1*12*(1-VacancyPct))*(((1+RentGrowth)^$B21-1)/RentGrowth))*(1-MaintPct-CapexPct-MgmtPct)-((AssessedValueY1*TaxRate)*(((1+AssessedGrowth)^$B21-1)/AssessedGrowth))-(InsuranceY1*(((1+InsuranceGrowth)^$B21-1)/InsuranceGrowth))-(HOAmo*12*$B21)-((-PMT(InterestRate/12,LoanTermYrs*12,LoanAmount)*12)*$B21))+((PurchasePrice*(1+F$16)^$B21)-((PurchasePrice*(1+F$16)^$B21)*SellingCostPct)-(LoanAmount*(((1+InterestRate/12)^(LoanTermYrs*12)-(1+InterestRate/12)^($B21*12))/((1+InterestRate/12)^(LoanTermYrs*12)-1))))-TotalCashInvested -> -8105.7818 | G21: =(((MonthlyRentY1*12*(1-VacancyPct))*(((1+RentGrowth)^$B21-1)/RentGrowth))*(1-MaintPct-CapexPct-MgmtPct)-((AssessedValueY1*TaxRate)*(((1+AssessedGrowth)^$B21-1)/AssessedGrowth))-(InsuranceY1*(((1+InsuranceGrowth)^$B21-1)/InsuranceGrowth))-(HOAmo*12*$B21)-((-PMT(InterestRate/12,LoanTermYrs*12,LoanAmount)*12)*$B21))+((PurchasePrice*(1+G$16)^$B21)-((PurchasePrice*(1+G$16)^$B21)*SellingCostPct)-(LoanAmount*(((1+InterestRate/12)^(LoanTermYrs*12)-(1+InterestRate/12)^($B21*12))/((1+InterestRate/12)^(LoanTermYrs*12)-1))))-TotalCashInvested -> -7677.7889 | H21: =(((MonthlyRentY1*12*(1-VacancyPct))*(((1+RentGrowth)^$B21-1)/RentGrowth))*(1-MaintPct-CapexPct-MgmtPct)-((AssessedValueY1*TaxRate)*(((1+AssessedGrowth)^$B21-1)/AssessedGrowth))-(InsuranceY1*(((1+InsuranceGrowth)^$B21-1)/InsuranceGrowth))-(HOAmo*12*$B21)-((-PMT(InterestRate/12,LoanTermYrs*12,LoanAmount)*12)*$B21))+((PurchasePrice*(1+H$16)^$B21)-((PurchasePrice*(1+H$16)^$B21)*SellingCostPct)-(LoanAmount*(((1+InterestRate/12)^(LoanTermYrs*12)-(1+InterestRate/12)^($B21*12))/((1+InterestRate/12)^(LoanTermYrs*12)-1))))-TotalCashInvested -> -7289.0653
B22: 0.045 | C22: =(((MonthlyRentY1*12*(1-VacancyPct))*(((1+RentGrowth)^$B22-1)/RentGrowth))*(1-MaintPct-CapexPct-MgmtPct)-((AssessedValueY1*TaxRate)*(((1+AssessedGrowth)^$B22-1)/AssessedGrowth))-(InsuranceY1*(((1+InsuranceGrowth)^$B22-1)/InsuranceGrowth))-(HOAmo*12*$B22)-((-PMT(InterestRate/12,LoanTermYrs*12,LoanAmount)*12)*$B22))+((PurchasePrice*(1+C$16)^$B22)-((PurchasePrice*(1+C$16)^$B22)*SellingCostPct)-(LoanAmount*(((1+InterestRate/12)^(LoanTermYrs*12)-(1+InterestRate/12)^($B22*12))/((1+InterestRate/12)^(LoanTermYrs*12)-1))))-TotalCashInvested -> -8826.4013 | D22: =(((MonthlyRentY1*12*(1-VacancyPct))*(((1+RentGrowth)^$B22-1)/RentGrowth))*(1-MaintPct-CapexPct-MgmtPct)-((AssessedValueY1*TaxRate)*(((1+AssessedGrowth)^$B22-1)/AssessedGrowth))-(InsuranceY1*(((1+InsuranceGrowth)^$B22-1)/InsuranceGrowth))-(HOAmo*12*$B22)-((-PMT(InterestRate/12,LoanTermYrs*12,LoanAmount)*12)*$B22))+((PurchasePrice*(1+D$16)^$B22)-((PurchasePrice*(1+D$16)^$B22)*SellingCostPct)-(LoanAmount*(((1+InterestRate/12)^(LoanTermYrs*12)-(1+InterestRate/12)^($B22*12))/((1+InterestRate/12)^(LoanTermYrs*12)-1))))-TotalCashInvested -> -8126.0831 | E22: =(((MonthlyRentY1*12*(1-VacancyPct))*(((1+RentGrowth)^$B22-1)/RentGrowth))*(1-MaintPct-CapexPct-MgmtPct)-((AssessedValueY1*TaxRate)*(((1+AssessedGrowth)^$B22-1)/AssessedGrowth))-(InsuranceY1*(((1+InsuranceGrowth)^$B22-1)/InsuranceGrowth))-(HOAmo*12*$B22)-((-PMT(InterestRate/12,LoanTermYrs*12,LoanAmount)*12)*$B22))+((PurchasePrice*(1+E$16)^$B22)-((PurchasePrice*(1+E$16)^$B22)*SellingCostPct)-(LoanAmount*(((1+InterestRate/12)^(LoanTermYrs*12)-(1+InterestRate/12)^($B22*12))/((1+InterestRate/12)^(LoanTermYrs*12)-1))))-TotalCashInvested -> -7515.5007 | F22: =(((MonthlyRentY1*12*(1-VacancyPct))*(((1+RentGrowth)^$B22-1)/RentGrowth))*(1-MaintPct-CapexPct-MgmtPct)-((AssessedValueY1*TaxRate)*(((1+AssessedGrowth)^$B22-1)/AssessedGrowth))-(InsuranceY1*(((1+InsuranceGrowth)^$B22-1)/InsuranceGrowth))-(HOAmo*12*$B22)-((-PMT(InterestRate/12,LoanTermYrs*12,LoanAmount)*12)*$B22))+((PurchasePrice*(1+F$16)^$B22)-((PurchasePrice*(1+F$16)^$B22)*SellingCostPct)-(LoanAmount*(((1+InterestRate/12)^(LoanTermYrs*12)-(1+InterestRate/12)^($B22*12))/((1+InterestRate/12)^(LoanTermYrs*12)-1))))-TotalCashInvested -> -6973.8751 | G22: =(((MonthlyRentY1*12*(1-VacancyPct))*(((1+RentGrowth)^$B22-1)/RentGrowth))*(1-MaintPct-CapexPct-MgmtPct)-((AssessedValueY1*TaxRate)*(((1+AssessedGrowth)^$B22-1)/AssessedGrowth))-(InsuranceY1*(((1+InsuranceGrowth)^$B22-1)/InsuranceGrowth))-(HOAmo*12*$B22)-((-PMT(InterestRate/12,LoanTermYrs*12,LoanAmount)*12)*$B22))+((PurchasePrice*(1+G$16)^$B22)-((PurchasePrice*(1+G$16)^$B22)*SellingCostPct)-(LoanAmount*(((1+InterestRate/12)^(LoanTermYrs*12)-(1+InterestRate/12)^($B22*12))/((1+InterestRate/12)^(LoanTermYrs*12)-1))))-TotalCashInvested -> -6486.9358 | H22: =(((MonthlyRentY1*12*(1-VacancyPct))*(((1+RentGrowth)^$B22-1)/RentGrowth))*(1-MaintPct-CapexPct-MgmtPct)-((AssessedValueY1*TaxRate)*(((1+AssessedGrowth)^$B22-1)/AssessedGrowth))-(InsuranceY1*(((1+InsuranceGrowth)^$B22-1)/InsuranceGrowth))-(HOAmo*12*$B22)-((-PMT(InterestRate/12,LoanTermYrs*12,LoanAmount)*12)*$B22))+((PurchasePrice*(1+H$16)^$B22)-((PurchasePrice*(1+H$16)^$B22)*SellingCostPct)-(LoanAmount*(((1+InterestRate/12)^(LoanTermYrs*12)-(1+InterestRate/12)^($B22*12))/((1+InterestRate/12)^(LoanTermYrs*12)-1))))-TotalCashInvested -> -6044.4525
B23: 0.05 | C23: =(((MonthlyRentY1*12*(1-VacancyPct))*(((1+RentGrowth)^$B23-1)/RentGrowth))*(1-MaintPct-CapexPct-MgmtPct)-((AssessedValueY1*TaxRate)*(((1+AssessedGrowth)^$B23-1)/AssessedGrowth))-(InsuranceY1*(((1+InsuranceGrowth)^$B23-1)/InsuranceGrowth))-(HOAmo*12*$B23)-((-PMT(InterestRate/12,LoanTermYrs*12,LoanAmount)*12)*$B23))+((PurchasePrice*(1+C$16)^$B23)-((PurchasePrice*(1+C$16)^$B23)*SellingCostPct)-(LoanAmount*(((1+InterestRate/12)^(LoanTermYrs*12)-(1+InterestRate/12)^($B23*12))/((1+InterestRate/12)^(LoanTermYrs*12)-1))))-TotalCashInvested -> -7908.5938 | D23: =(((MonthlyRentY1*12*(1-VacancyPct))*(((1+RentGrowth)^$B23-1)/RentGrowth))*(1-MaintPct-CapexPct-MgmtPct)-((AssessedValueY1*TaxRate)*(((1+AssessedGrowth)^$B23-1)/AssessedGrowth))-(InsuranceY1*(((1+InsuranceGrowth)^$B23-1)/InsuranceGrowth))-(HOAmo*12*$B23)-((-PMT(InterestRate/12,LoanTermYrs*12,LoanAmount)*12)*$B23))+((PurchasePrice*(1+D$16)^$B23)-((PurchasePrice*(1+D$16)^$B23)*SellingCostPct)-(LoanAmount*(((1+InterestRate/12)^(LoanTermYrs*12)-(1+InterestRate/12)^($B23*12))/((1+InterestRate/12)^(LoanTermYrs*12)-1))))-TotalCashInvested -> -7123.157 | E23: =(((MonthlyRentY1*12*(1-VacancyPct))*(((1+RentGrowth)^$B23-1)/RentGrowth))*(1-MaintPct-CapexPct-MgmtPct)-((AssessedValueY1*TaxRate)*(((1+AssessedGrowth)^$B23-1)/AssessedGrowth))-(InsuranceY1*(((1+InsuranceGrowth)^$B23-1)/InsuranceGrowth))-(HOAmo*12*$B23)-((-PMT(InterestRate/12,LoanTermYrs*12,LoanAmount)*12)*$B23))+((PurchasePrice*(1+E$16)^$B23)-((PurchasePrice*(1+E$16)^$B23)*SellingCostPct)-(LoanAmount*(((1+InterestRate/12)^(LoanTermYrs*12)-(1+InterestRate/12)^($B23*12))/((1+InterestRate/12)^(LoanTermYrs*12)-1))))-TotalCashInvested -> -6437.8702 | F23: =(((MonthlyRentY1*12*(1-VacancyPct))*(((1+RentGrowth)^$B23-1)/RentGrowth))*(1-MaintPct-CapexPct-MgmtPct)-((AssessedValueY1*TaxRate)*(((1+AssessedGrowth)^$B23-1)/AssessedGrowth))-(InsuranceY1*(((1+InsuranceGrowth)^$B23-1)/InsuranceGrowth))-(HOAmo*12*$B23)-((-PMT(InterestRate/12,LoanTermYrs*12,LoanAmount)*12)*$B23))+((PurchasePrice*(1+F$16)^$B23)-((PurchasePrice*(1+F$16)^$B23)*SellingCostPct)-(LoanAmount*(((1+InterestRate/12)^(LoanTermYrs*12)-(1+InterestRate/12)^($B23*12))/((1+InterestRate/12)^(LoanTermYrs*12)-1))))-TotalCashInvested -> -5829.5949 | G23: =(((MonthlyRentY1*12*(1-VacancyPct))*(((1+RentGrowth)^$B23-1)/RentGrowth))*(1-MaintPct-CapexPct-MgmtPct)-((AssessedValueY1*TaxRate)*(((1+AssessedGrowth)^$B23-1)/AssessedGrowth))-(InsuranceY1*(((1+InsuranceGrowth)^$B23-1)/InsuranceGrowth))-(HOAmo*12*$B23)-((-PMT(InterestRate/12,LoanTermYrs*12,LoanAmount)*12)*$B23))+((PurchasePrice*(1+G$16)^$B23)-((PurchasePrice*(1+G$16)^$B23)*SellingCostPct)-(LoanAmount*(((1+InterestRate/12)^(LoanTermYrs*12)-(1+InterestRate/12)^($B23*12))/((1+InterestRate/12)^(LoanTermYrs*12)-1))))-TotalCashInvested -> -5282.4304 | H23: =(((MonthlyRentY1*12*(1-VacancyPct))*(((1+RentGrowth)^$B23-1)/RentGrowth))*(1-MaintPct-CapexPct-MgmtPct)-((AssessedValueY1*TaxRate)*(((1+AssessedGrowth)^$B23-1)/AssessedGrowth))-(InsuranceY1*(((1+InsuranceGrowth)^$B23-1)/InsuranceGrowth))-(HOAmo*12*$B23)-((-PMT(InterestRate/12,LoanTermYrs*12,LoanAmount)*12)*$B23))+((PurchasePrice*(1+H$16)^$B23)-((PurchasePrice*(1+H$16)^$B23)*SellingCostPct)-(LoanAmount*(((1+InterestRate/12)^(LoanTermYrs*12)-(1+InterestRate/12)^($B23*12))/((1+InterestRate/12)^(LoanTermYrs*12)-1))))-TotalCashInvested -> -4784.9706
B25: (b2) EQUITY MULTIPLE (x) - Appreciation Rate x Exit Year
B26: Appr \ Exit Yr -> | C26: 5 | D26: 6 | E26: 7 | F26: 8 | G26: 9 | H26: 10
