Workbook

Sheet Summary
B2: 2480 Dundas Street West, Toronto (High Park North)
B3: 14-Unit Hard-Loft Multifamily Acquisition Model
B5: DEAL SNAPSHOT
B6: Property Address | C6: 2480 Dundas Street West, Toronto, ON
B7: Submarket | C7: High Park North
B8: Building Type | C8: Hard-loft / live-work studio & 1BR conversion
B9: Number of Units | C9: 14
B10: Purchase Price | C10: 5985000
B11: Price per Door | C11: =C10/C9
B12: Gross Annual Income (Advertised) | C12: 447113
B13: Gross Rent Multiplier (GRM) | C13: =C10/C12
B15: SOURCES & USES
B16: Closing Cost % (legal, DD, adjustments) | C16: 0.01
B18: USES
B19: Purchase Price | C19: =C10
B20: Ontario Land Transfer Tax (banded) | C20: =MAX(0,MIN(C10,55000))*0.005+MAX(0,MIN(C10,250000)-55000)*0.01+MAX(0,MIN(C10,400000)-250000)*0.015+MAX(0,C10-400000)*0.02
B21: Toronto Municipal Land Transfer Tax (banded) | C21: =MAX(0,MIN(C10,55000))*0.005+MAX(0,MIN(C10,250000)-55000)*0.01+MAX(0,MIN(C10,400000)-250000)*0.015+MAX(0,C10-400000)*0.02
B22: Closing Costs (legal/DD) | C22: =C19*C16
B23: Total Uses | C23: =SUM(C19:C22)
B25: SOURCES
B26: Senior Loan | C26: =Debt!D8
B27: Equity Required | C27: =C23-C26
B28: Loan-to-Cost | C28: =C26/C23
B30: FINANCING SUMMARY
B31: Financing Type | C31: =Debt!D5
B32: Interest Rate | C32: =Debt!D6
B33: Max LTV | C33: =Debt!D7
B34: Loan Amount | C34: =Debt!D8
B35: Amortization (yrs) | C35: =Debt!D9
B36: Term (yrs, balloon at exit) | C36: =Debt!D10
B37: Annual Debt Service (Yr 1) | C37: =Debt!D12
B39: YEAR-1 & STABILIZED METRICS
B40: Year-1 Underwritten NOI | C40: ='Operating Proforma'!C39
B41: Year-1 Cap Rate (Underwritten) | C41: =C40/C10
B42: Year-1 DSCR | C42: =C40/C37
B43: Year-1 Cash-on-Cash Return | C43: =Returns!C29
B44: Stabilized (Yr 5) NOI | C44: ='Operating Proforma'!G39
B45: Stabilized (Yr 5) Cap Rate on Basis | C45: =C44/C10
B47: 5-YEAR RETURNS
B48: 5-Yr Levered IRR | C48: =Returns!D34
...

Sheet Rent Roll
B2: RENT ROLL - 2480 DUNDAS STREET WEST (14 UNITS)
B4: Unit | C4: Unit Type | D4: Approx SF | E4: In-Place Rent ($/mo) | F4: Market Rent ($/mo) | G4: Loss-to-Lease ($/mo) | H4: Annualized In-Place | I4: Annualized Market
B5: 101 | C5: Loft 1BR / Live-Work | D5: 600 | E5: 2400 | F5: =E5*1.03 | G5: =F5-E5 | H5: =E5*12 | I5: =F5*12
B6: 102 | C6: Loft 1BR / Live-Work | D6: 610 | E6: 2450 | F6: =E6*1.03 | G6: =F6-E6 | H6: =E6*12 | I6: =F6*12
B7: 103 | C7: Loft 1BR / Live-Work | D7: 630 | E7: 2500 | F7: =E7*1.03 | G7: =F7-E7 | H7: =E7*12 | I7: =F7*12
B8: 104 | C8: Loft 1BR / Live-Work | D8: 640 | E8: 2550 | F8: =E8*1.03 | G8: =F8-E8 | H8: =E8*12 | I8: =F8*12
B9: 105 | C9: Loft 1BR / Live-Work | D9: 650 | E9: 2600 | F9: =E9*1.03 | G9: =F9-E9 | H9: =E9*12 | I9: =F9*12
B10: 106 | C10: Loft 1BR / Live-Work | D10: 655 | E10: 2620 | F10: =E10*1.03 | G10: =F10-E10 | H10: =E10*12 | I10: =F10*12
B11: 107 | C11: Loft 1BR / Live-Work | D11: 660 | E11: 2650 | F11: =E11*1.03 | G11: =F11-E11 | H11: =E11*12 | I11: =F11*12
B12: 108 | C12: Loft 1BR / Live-Work | D12: 665 | E12: 2680 | F12: =E12*1.03 | G12: =F12-E12 | H12: =E12*12 | I12: =F12*12
B13: 109 | C13: Loft 1BR / Live-Work | D13: 655 | E13: 2700 | F13: =E13*1.03 | G13: =F13-E13 | H13: =E13*12 | I13: =F13*12
B14: 110 | C14: Loft 1BR / Live-Work | D14: 660 | E14: 2720 | F14: =E14*1.03 | G14: =F14-E14 | H14: =E14*12 | I14: =F14*12
B15: 111 | C15: Loft 1BR / Live-Work | D15: 670 | E15: 2750 | F15: =E15*1.03 | G15: =F15-E15 | H15: =E15*12 | I15: =F15*12
B16: 112 | C16: Loft 1BR / Live-Work | D16: 680 | E16: 2800 | F16: =E16*1.03 | G16: =F16-E16 | H16: =E16*12 | I16: =F16*12
... B18: 114 | C18: Loft 1BR / Live-Work | D18: 700 | E18: 2990 | F18: =E18*1.03 | G18: =F18-E18 | H18: =E18*12 | I18: =F18*12
B19: TOTAL / AVG | D19: =SUM(D5:D18) | E19: =AVERAGE(E5:E18) | F19: =AVERAGE(F5:F18) | G19: =AVERAGE(G5:G18) | H19: =SUM(H5:H18) | I19: =SUM(I5:I18)
B21: Rents vary $2,400-$2,990/mo reflecting unit size/light/finish; total annualized in-place approximates the advertised $447,113 gross annual income.

Sheet Operating Proforma
B2: OPERATING PROFORMA - 5-YEAR ANNUAL
C4: Year 1 | D4: Year 2 | E4: Year 3 | F4: Year 4 | G4: Year 5
B6: ASSUMPTIONS
B7: Ontario Rent Guideline (in-place escalation) | C7: 0.021
B8: Tenant Turnover Rate (annual) | C8: 0.15
B9: Market Rent Growth (turnover resets) | C9: 0.03
B10: Premium Loft Reset Rent ($/mo, at turnover) | C10: 2900
B11: Vacancy Rate (Toronto sub-2% mkt; underwritten) | C11: 0.02
B12: Other Income ($/unit/mo - laundry/parking) | C12: 45
B13: Expense Inflation | C13: 0.025
B14: Management Fee (% of EGI) | C14: 0.04
B15: Number of Units | C15: =Summary!C9
B16: Base Annual In-Place GPR (from Rent Roll) | C16: ='Rent Roll'!H19
B18: REVENUE
B19: Retained Fraction (never turned over) | C19: =(1-$C$8)^1 | D19: =(1-$C$8)^2 | E19: =(1-$C$8)^3 | F19: =(1-$C$8)^4 | G19: =(1-$C$8)^5
B20: Turned-Over Fraction (cumulative) | C20: =1-C19 | D20: =1-D19 | E20: =1-E19 | F20: =1-F19 | G20: =1-G19
B21: Stream 1: In-Place Continuing Rent (guideline growth) | C21: =$C$16*C19*(1+$C$7)^1 | D21: =$C$16*D19*(1+$C$7)^2 | E21: =$C$16*E19*(1+$C$7)^3 | F21: =$C$16*F19*(1+$C$7)^4 | G21: =$C$16*G19*(1+$C$7)^5
B22: Stream 2: Turnover Rent (reset to market, grows @ mkt rate) | C22: =$C$15*C20*($C$10*12)*(1+$C$9)^0 | D22: =$C$15*D20*($C$10*12)*(1+$C$9)^1 | E22: =$C$15*E20*($C$10*12)*(1+$C$9)^2 | F22: =$C$15*F20*($C$10*12)*(1+$C$9)^3 | G22: =$C$15*G20*($C$10*12)*(1+$C$9)^4
B23: Gross Potential Rent (GPR) | C23: =C21+C22 | D23: =D21+D22 | E23: =E21+E22 | F23: =F21+F22 | G23: =G21+G22
B24: Less: Vacancy Loss | C24: =-C23*$C$11 | D24: =-D23*$C$11 | E24: =-E23*$C$11 | F24: =-F23*$C$11 | G24: =-G23*$C$11
B25: Other Income | C25: =$C$15*$C$12*12*(1+$C$13)^0 | D25: =$C$15*$C$12*12*(1+$C$13)^1 | E25: =$C$15*$C$12*12*(1+$C$13)^2 | F25: =$C$15*$C$12*12*(1+$C$13)^3 | G25: =$C$15*$C$12*12*(1+$C$13)^4
B26: Effective Gross Income (EGI) | C26: =C23+C24+C25 | D26: =D23+D24+D25 | E26: =E23+E24+E25 | F26: =F23+F24+F25 | G26: =G23+G24+G25
B28: OPERATING EXPENSES
B29: Property Taxes | C29: 52000 | D29: =C29*(1+$C$13) | E29: =D29*(1+$C$13) | F29: =E29*(1+$C$13) | G29: =F29*(1+$C$13)
B30: Insurance | C30: 18000 | D30: =C30*(1+$C$13) | E30: =D30*(1+$C$13) | F30: =E30*(1+$C$13) | G30: =F30*(1+$C$13)
B31: Utilities (landlord-paid) | C31: 22000 | D31: =C31*(1+$C$13) | E31: =D31*(1+$C$13) | F31: =E31*(1+$C$13) | G31: =F31*(1+$C$13)
B32: Repairs & Maintenance | C32: 24000 | D32: =C32*(1+$C$13) | E32: =D32*(1+$C$13) | F32: =E32*(1+$C$13) | G32: =F32*(1+$C$13)
B33: Super / Staff | C33: 16000 | D33: =C33*(1+$C$13) | E33: =D33*(1+$C$13) | F33: =E33*(1+$C$13) | G33: =F33*(1+$C$13)
B34: Misc. / Admin / Reserves | C34: 10000 | D34: =C34*(1+$C$13) | E34: =D34*(1+$C$13) | F34: =E34*(1+$C$13) | G34: =F34*(1+$C$13)
B35: Management Fee (4% of EGI) | C35: =C26*$C$14 | D35: =D26*$C$14 | E35: =E26*$C$14 | F35: =F26*$C$14 | G35: =G26*$C$14
B36: Total Operating Expenses | C36: =SUM(C29:C35) | D36: =SUM(D29:D35) | E36: =SUM(E29:E35) | F36: =SUM(F29:F35) | G36: =SUM(G29:G35)
B37: Opex Ratio (% of EGI) | C37: =C36/C26 | D37: =D36/D26 | E37: =E36/E26 | F37: =F36/F26 | G37: =G36/G26
B38: NET OPERATING INCOME
B39: Net Operating Income (NOI) | C39: =C26-C36 | D39: =D26-D36 | E39: =E26-E36 | F39: =F26-F36 | G39: =G26-G36

Sheet Debt
B2: DEBT SCHEDULE
B4: Financing Toggle (Conventional / CMHC-Insured) | D4: Conventional
B5: Financing Type | D5: =D4
B6: Interest Rate | D6: =IF(D4="Conventional",0.055,0.0445)
B7: Max LTV | D7: =IF(D4="Conventional",0.65,0.75)
B8: Loan Amount | D8: =D7*Summary!C10
B9: Amortization (years) | D9: 30
B10: Term (years, balloon at exit) | D10: 5
B11: Monthly Payment (PMT) | D11: =-PMT(D6/12,D9*12,D8)
B12: Annual Debt Service | D12: =D11*12
B13: Debt Yield (Yr 1 NOI / Loan Amount) | D13: ='Operating Proforma'!C39/D8
B15: ANNUAL AMORTIZATION SCHEDULE
C16: Year 1 | D16: Year 2 | E16: Year 3 | F16: Year 4 | G16: Year 5
B17: Annual Debt Service | C17: =$D$12 | D17: =$D$12 | E17: =$D$12 | F17: =$D$12 | G17: =$D$12
B18: Interest Paid (annual) | C18: =-CUMIPMT($D$6/12,$D$9*12,$D$8,1,12,0) | D18: =-CUMIPMT($D$6/12,$D$9*12,$D$8,13,24,0) | E18: =-CUMIPMT($D$6/12,$D$9*12,$D$8,25,36,0) | F18: =-CUMIPMT($D$6/12,$D$9*12,$D$8,37,48,0) | G18: =-CUMIPMT($D$6/12,$D$9*12,$D$8,49,60,0)
B19: Principal Paid (annual) | C19: =-CUMPRINC($D$6/12,$D$9*12,$D$8,1,12,0) | D19: =-CUMPRINC($D$6/12,$D$9*12,$D$8,13,24,0) | E19: =-CUMPRINC($D$6/12,$D$9*12,$D$8,25,36,0) | F19: =-CUMPRINC($D$6/12,$D$9*12,$D$8,37,48,0) | G19: =-CUMPRINC($D$6/12,$D$9*12,$D$8,49,60,0)
B20: Ending Loan Balance | C20: =$D$8+CUMPRINC($D$6/12,$D$9*12,$D$8,1,12,0) | D20: =$D$8+CUMPRINC($D$6/12,$D$9*12,$D$8,1,24,0) | E20: =$D$8+CUMPRINC($D$6/12,$D$9*12,$D$8,1,36,0) | F20: =$D$8+CUMPRINC($D$6/12,$D$9*12,$D$8,1,48,0) | G20: =$D$8+CUMPRINC($D$6/12,$D$9*12,$D$8,1,60,0)
B21: DSCR (NOI / Debt Service) | C21: ='Operating Proforma'!C39/C17 | D21: ='Operating Proforma'!D39/D17 | E21: ='Operating Proforma'!E39/E17 | F21: ='Operating Proforma'!F39/F17 | G21: ='Operating Proforma'!G39/G17

Sheet Returns
B2: RETURNS - 5-YEAR HOLD
C4: Year 1 | D4: Year 2 | E4: Year 3 | F4: Year 4 | G4: Year 5
B5: OPERATING CASH FLOWS
B6: Initial Equity Investment | C6: =-Summary!C27
B7: NOI | C7: ='Operating Proforma'!C39 | D7: ='Operating Proforma'!D39 | E7: ='Operating Proforma'!E39 | F7: ='Operating Proforma'!F39 | G7: ='Operating Proforma'!G39
B8: Less: Annual Debt Service | C8: =-Debt!C17 | D8: =-Debt!D17 | E8: =-Debt!E17 | F8: =-Debt!F17 | G8: =-Debt!G17
B9: Levered Cash Flow (before exit) | C9: =C7+C8 | D9: =D7+D8 | E9: =E7+E8 | F9: =F7+F8 | G9: =G7+G8
B11: EXIT / REVERSION (END OF YEAR 5)
B12: Exit Cap Rate | C12: 0.0525
B13: Selling Costs (% of gross price) | C13: 0.025
B14: Forward Year-6 NOI (Yr5 NOI x (1+mkt growth)) | C14: =G7*(1+'Operating Proforma'!$C$9)
B15: Gross Sale Price | C15: =C14/C12
B16: Less: Selling Costs | C16: =-C15*C13
B17: Less: Loan Balance at Exit | C17: =-Debt!G20
B18: Net Reversion to Equity (Levered) | C18: =C15+C16+C17
B19: Net Reversion (Unlevered) | C19: =C15+C16
B21: LEVERED EQUITY CASH FLOWS
B23: Levered Equity CF (Yr0, Yr1-5) | C23: =C6 | D23: =C9 | E23: =D9 | F23: =E9 | G23: =F9 | H23: =G9+$C$18
B25: UNLEVERED CASH FLOWS
B26: Unlevered CF (Yr0, Yr1-5) | C26: =-Summary!C23 | D26: =C7 | E26: =D7 | F26: =E7 | G26: =F7 | H26: =G7+$C$19
B28: CASH-ON-CASH BY YEAR
B29: Cash-on-Cash Return | C29: =C9/-$C$6 | D29: =D9/-$C$6 | E29: =E9/-$C$6 | F29: =F9/-$C$6 | G29: =G9/-$C$6
B31: SUMMARY RETURN METRICS
B34: 5-Yr Levered IRR | D34: =IRR(C23:H23)
B35: 5-Yr Unlevered IRR | D35: =IRR(C26:H26)
B36: Levered Equity Multiple | D36: =SUM(D23:H23)/-C23
B37: Unlevered Equity Multiple | D37: =SUM(D26:H26)/-C26

Sheet Sensitivity
B2: SENSITIVITY ANALYSIS
B4: 2-WAY: EXIT CAP RATE x MARKET RENT GROWTH -> LEVERED EQUITY MULTIPLE
B5: Exit Cap \ Mkt Growth | C5: 0.02 | D5: 0.025 | E5: 0.03 | F5: 0.035 | G5: 0.04
B6: 0.0475 | C6: =(SUM(Returns!C9:F9)+(((('Operating Proforma'!$G$21+'Operating Proforma'!$C$15*'Operating Proforma'!$G$20*('Operating Proforma'!$C$10*12)*(1+C$5)^4)*(1-'Operating Proforma'!$C$11)+'Operating Proforma'!$G$25)*(1-'Operating Proforma'!$C$14)-('Operating Proforma'!$G$36-'Operating Proforma'!$G$35))-Debt!$G$17+((((('Operating Proforma'!$G$21+'Operating Proforma'!$C$15*'Operating Proforma'!$G$20*('Operating Proforma'!$C$10*12)*(1+C$5)^4)*(1-'Operating Proforma'!$C$11)+'Operating Proforma'!$G$25)*(1-'Operating Proforma'!$C$14)-('Operating Proforma'!$G$36-'Operating Proforma'!$G$35))*(1+C$5))/$B6)*(1-Returns!$C$13)-Debt!$G$20))/-Returns!$C$6 | D6: =(SUM(Returns!C9:F9)+(((('Operating Proforma'!$G$21+'Operating Proforma'!$C$15*'Operating Proforma'!$G$20*('Operating Proforma'!$C$10*12)*(1+D$5)^4)*(1-'Operating Proforma'!$C$11)+'Operating Proforma'!$G$25)*(1-'Operating Proforma'!$C$14)-('Operating Proforma'!$G$36-'Operating Proforma'!$G$35))-Debt!$G$17+((((('Operating Proforma'!$G$21+'Operating Proforma'!$C$15*'Operating Proforma'!$G$20*('Operating Proforma'!$C$10*12)*(1+D$5)^4)*(1-'Operating Proforma'!$C$11)+'Operating Proforma'!$G$25)*(1-'Operating Proforma'!$C$14)-('Operating Proforma'!$G$36-'Operating Proforma'!$G$35))*(1+D$5))/$B6)*(1-Returns!$C$13)-Debt!$G$20))/-Returns!$C$6 | E6: =(SUM(Returns!C9:F9)+(((('Operating Proforma'!$G$21+'Operating Proforma'!$C$15*'Operating Proforma'!$G$20*('Operating Proforma'!$C$10*12)*(1+E$5)^4)*(1-'Operating Proforma'!$C$11)+'Operating Proforma'!$G$25)*(1-'Operating Proforma'!$C$14)-('Operating Proforma'!$G$36-'Operating Proforma'!$G$35))-Debt!$G$17+((((('Operating Proforma'!$G$21+'Operating Proforma'!$C$15*'Operating Proforma'!$G$20*('Operating Proforma'!$C$10*12)*(1+E$5)^4)*(1-'Operating Proforma'!$C$11)+'Operating Proforma'!$G$25)*(1-'Operating Proforma'!$C$14)-('Operating Proforma'!$G$36-'Operating Proforma'!$G$35))*(1+E$5))/$B6)*(1-Returns!$C$13)-Debt!$G$20))/-Returns!$C$6 | F6: =(SUM(Returns!C9:F9)+(((('Operating Proforma'!$G$21+'Operating Proforma'!$C$15*'Operating Proforma'!$G$20*('Operating Proforma'!$C$10*12)*(1+F$5)^4)*(1-'Operating Proforma'!$C$11)+'Operating Proforma'!$G$25)*(1-'Operating Proforma'!$C$14)-('Operating Proforma'!$G$36-'Operating Proforma'!$G$35))-Debt!$G$17+((((('Operating Proforma'!$G$21+'Operating Proforma'!$C$15*'Operating Proforma'!$G$20*('Operating Proforma'!$C$10*12)*(1+F$5)^4)*(1-'Operating Proforma'!$C$11)+'Operating Proforma'!$G$25)*(1-'Operating Proforma'!$C$14)-('Operating Proforma'!$G$36-'Operating Proforma'!$G$35))*(1+F$5))/$B6)*(1-Returns!$C$13)-Debt!$G$20))/-Returns!$C$6 | G6: =(SUM(Returns!C9:F9)+(((('Operating Proforma'!$G$21+'Operating Proforma'!$C$15*'Operating Proforma'!$G$20*('Operating Proforma'!$C$10*12)*(1+G$5)^4)*(1-'Operating Proforma'!$C$11)+'Operating Proforma'!$G$25)*(1-'Operating Proforma'!$C$14)-('Operating Proforma'!$G$36-'Operating Proforma'!$G$35))-Debt!$G$17+((((('Operating Proforma'!$G$21+'Operating Proforma'!$C$15*'Operating Proforma'!$G$20*('Operating Proforma'!$C$10*12)*(1+G$5)^4)*(1-'Operating Proforma'!$C$11)+'Operating Proforma'!$G$25)*(1-'Operating Proforma'!$C$14)-('Operating Proforma'!$G$36-'Operating Proforma'!$G$35))*(1+G$5))/$B6)*(1-Returns!$C$13)-Debt!$G$20))/-Returns!$C$6
B7: 0.05 | C7: =(SUM(Returns!C9:F9)+(((('Operating Proforma'!$G$21+'Operating Proforma'!$C$15*'Operating Proforma'!$G$20*('Operating Proforma'!$C$10*12)*(1+C$5)^4)*(1-'Operating Proforma'!$C$11)+'Operating Proforma'!$G$25)*(1-'Operating Proforma'!$C$14)-('Operating Proforma'!$G$36-'Operating Proforma'!$G$35))-Debt!$G$17+((((('Operating Proforma'!$G$21+'Operating Proforma'!$C$15*'Operating Proforma'!$G$20*('Operating Proforma'!$C$10*12)*(1+C$5)^4)*(1-'Operating Proforma'!$C$11)+'Operating Proforma'!$G$25)*(1-'Operating Proforma'!$C$14)-('Operating Proforma'!$G$36-'Operating Proforma'!$G$35))*(1+C$5))/$B7)*(1-Returns!$C$13)-Debt!$G$20))/-Returns!$C$6 | D7: =(SUM(Returns!C9:F9)+(((('Operating Proforma'!$G$21+'Operating Proforma'!$C$15*'Operating Proforma'!$G$20*('Operating Proforma'!$C$10*12)*(1+D$5)^4)*(1-'Operating Proforma'!$C$11)+'Operating Proforma'!$G$25)*(1-'Operating Proforma'!$C$14)-('Operating Proforma'!$G$36-'Operating Proforma'!$G$35))-Debt!$G$17+((((('Operating Proforma'!$G$21+'Operating Proforma'!$C$15*'Operating Proforma'!$G$20*('Operating Proforma'!$C$10*12)*(1+D$5)^4)*(1-'Operating Proforma'!$C$11)+'Operating Proforma'!$G$25)*(1-'Operating Proforma'!$C$14)-('Operating Proforma'!$G$36-'Operating Proforma'!$G$35))*(1+D$5))/$B7)*(1-Returns!$C$13)-Debt!$G$20))/-Returns!$C$6 | E7: =(SUM(Returns!C9:F9)+(((('Operating Proforma'!$G$21+'Operating Proforma'!$C$15*'Operating Proforma'!$G$20*('Operating Proforma'!$C$10*12)*(1+E$5)^4)*(1-'Operating Proforma'!$C$11)+'Operating Proforma'!$G$25)*(1-'Operating Proforma'!$C$14)-('Operating Proforma'!$G$36-'Operating Proforma'!$G$35))-Debt!$G$17+((((('Operating Proforma'!$G$21+'Operating Proforma'!$C$15*'Operating Proforma'!$G$20*('Operating Proforma'!$C$10*12)*(1+E$5)^4)*(1-'Operating Proforma'!$C$11)+'Operating Proforma'!$G$25)*(1-'Operating Proforma'!$C$14)-('Operating Proforma'!$G$36-'Operating Proforma'!$G$35))*(1+E$5))/$B7)*(1-Returns!$C$13)-Debt!$G$20))/-Returns!$C$6 | F7: =(SUM(Returns!C9:F9)+(((('Operating Proforma'!$G$21+'Operating Proforma'!$C$15*'Operating Proforma'!$G$20*('Operating Proforma'!$C$10*12)*(1+F$5)^4)*(1-'Operating Proforma'!$C$11)+'Operating Proforma'!$G$25)*(1-'Operating Proforma'!$C$14)-('Operating Proforma'!$G$36-'Operating Proforma'!$G$35))-Debt!$G$17+((((('Operating Proforma'!$G$21+'Operating Proforma'!$C$15*'Operating Proforma'!$G$20*('Operating Proforma'!$C$10*12)*(1+F$5)^4)*(1-'Operating Proforma'!$C$11)+'Operating Proforma'!$G$25)*(1-'Operating Proforma'!$C$14)-('Operating Proforma'!$G$36-'Operating Proforma'!$G$35))*(1+F$5))/$B7)*(1-Returns!$C$13)-Debt!$G$20))/-Returns!$C$6 | G7: =(SUM(Returns!C9:F9)+(((('Operating Proforma'!$G$21+'Operating Proforma'!$C$15*'Operating Proforma'!$G$20*('Operating Proforma'!$C$10*12)*(1+G$5)^4)*(1-'Operating Proforma'!$C$11)+'Operating Proforma'!$G$25)*(1-'Operating Proforma'!$C$14)-('Operating Proforma'!$G$36-'Operating Proforma'!$G$35))-Debt!$G$17+((((('Operating Proforma'!$G$21+'Operating Proforma'!$C$15*'Operating Proforma'!$G$20*('Operating Proforma'!$C$10*12)*(1+G$5)^4)*(1-'Operating Proforma'!$C$11)+'Operating Proforma'!$G$25)*(1-'Operating Proforma'!$C$14)-('Operating Proforma'!$G$36-'Operating Proforma'!$G$35))*(1+G$5))/$B7)*(1-Returns!$C$13)-Debt!$G$20))/-Returns!$C$6
B8: 0.0525 | C8: =(SUM(Returns!C9:F9)+(((('Operating Proforma'!$G$21+'Operating Proforma'!$C$15*'Operating Proforma'!$G$20*('Operating Proforma'!$C$10*12)*(1+C$5)^4)*(1-'Operating Proforma'!$C$11)+'Operating Proforma'!$G$25)*(1-'Operating Proforma'!$C$14)-('Operating Proforma'!$G$36-'Operating Proforma'!$G$35))-Debt!$G$17+((((('Operating Proforma'!$G$21+'Operating Proforma'!$C$15*'Operating Proforma'!$G$20*('Operating Proforma'!$C$10*12)*(1+C$5)^4)*(1-'Operating Proforma'!$C$11)+'Operating Proforma'!$G$25)*(1-'Operating Proforma'!$C$14)-('Operating Proforma'!$G$36-'Operating Proforma'!$G$35))*(1+C$5))/$B8)*(1-Returns!$C$13)-Debt!$G$20))/-Returns!$C$6 | D8: =(SUM(Returns!C9:F9)+(((('Operating Proforma'!$G$21+'Operating Proforma'!$C$15*'Operating Proforma'!$G$20*('Operating Proforma'!$C$10*12)*(1+D$5)^4)*(1-'Operating Proforma'!$C$11)+'Operating Proforma'!$G$25)*(1-'Operating Proforma'!$C$14)-('Operating Proforma'!$G$36-'Operating Proforma'!$G$35))-Debt!$G$17+((((('Operating Proforma'!$G$21+'Operating Proforma'!$C$15*'Operating Proforma'!$G$20*('Operating Proforma'!$C$10*12)*(1+D$5)^4)*(1-'Operating Proforma'!$C$11)+'Operating Proforma'!$G$25)*(1-'Operating Proforma'!$C$14)-('Operating Proforma'!$G$36-'Operating Proforma'!$G$35))*(1+D$5))/$B8)*(1-Returns!$C$13)-Debt!$G$20))/-Returns!$C$6 | E8: =(SUM(Returns!C9:F9)+(((('Operating Proforma'!$G$21+'Operating Proforma'!$C$15*'Operating Proforma'!$G$20*('Operating Proforma'!$C$10*12)*(1+E$5)^4)*(1-'Operating Proforma'!$C$11)+'Operating Proforma'!$G$25)*(1-'Operating Proforma'!$C$14)-('Operating Proforma'!$G$36-'Operating Proforma'!$G$35))-Debt!$G$17+((((('Operating Proforma'!$G$21+'Operating Proforma'!$C$15*'Operating Proforma'!$G$20*('Operating Proforma'!$C$10*12)*(1+E$5)^4)*(1-'Operating Proforma'!$C$11)+'Operating Proforma'!$G$25)*(1-'Operating Proforma'!$C$14)-('Operating Proforma'!$G$36-'Operating Proforma'!$G$35))*(1+E$5))/$B8)*(1-Returns!$C$13)-Debt!$G$20))/-Returns!$C$6 | F8: =(SUM(Returns!C9:F9)+(((('Operating Proforma'!$G$21+'Operating Proforma'!$C$15*'Operating Proforma'!$G$20*('Operating Proforma'!$C$10*12)*(1+F$5)^4)*(1-'Operating Proforma'!$C$11)+'Operating Proforma'!$G$25)*(1-'Operating Proforma'!$C$14)-('Operating Proforma'!$G$36-'Operating Proforma'!$G$35))-Debt!$G$17+((((('Operating Proforma'!$G$21+'Operating Proforma'!$C$15*'Operating Proforma'!$G$20*('Operating Proforma'!$C$10*12)*(1+F$5)^4)*(1-'Operating Proforma'!$C$11)+'Operating Proforma'!$G$25)*(1-'Operating Proforma'!$C$14)-('Operating Proforma'!$G$36-'Operating Proforma'!$G$35))*(1+F$5))/$B8)*(1-Returns!$C$13)-Debt!$G$20))/-Returns!$C$6 | G8: =(SUM(Returns!C9:F9)+(((('Operating Proforma'!$G$21+'Operating Proforma'!$C$15*'Operating Proforma'!$G$20*('Operating Proforma'!$C$10*12)*(1+G$5)^4)*(1-'Operating Proforma'!$C$11)+'Operating Proforma'!$G$25)*(1-'Operating Proforma'!$C$14)-('Operating Proforma'!$G$36-'Operating Proforma'!$G$35))-Debt!$G$17+((((('Operating Proforma'!$G$21+'Operating Proforma'!$C$15*'Operating Proforma'!$G$20*('Operating Proforma'!$C$10*12)*(1+G$5)^4)*(1-'Operating Proforma'!$C$11)+'Operating Proforma'!$G$25)*(1-'Operating Proforma'!$C$14)-('Operating Proforma'!$G$36-'Operating Proforma'!$G$35))*(1+G$5))/$B8)*(1-Returns!$C$13)-Debt!$G$20))/-Returns!$C$6
B9: 0.055 | C9: =(SUM(Returns!C9:F9)+(((('Operating Proforma'!$G$21+'Operating Proforma'!$C$15*'Operating Proforma'!$G$20*('Operating Proforma'!$C$10*12)*(1+C$5)^4)*(1-'Operating Proforma'!$C$11)+'Operating Proforma'!$G$25)*(1-'Operating Proforma'!$C$14)-('Operating Proforma'!$G$36-'Operating Proforma'!$G$35))-Debt!$G$17+((((('Operating Proforma'!$G$21+'Operating Proforma'!$C$15*'Operating Proforma'!$G$20*('Operating Proforma'!$C$10*12)*(1+C$5)^4)*(1-'Operating Proforma'!$C$11)+'Operating Proforma'!$G$25)*(1-'Operating Proforma'!$C$14)-('Operating Proforma'!$G$36-'Operating Proforma'!$G$35))*(1+C$5))/$B9)*(1-Returns!$C$13)-Debt!$G$20))/-Returns!$C$6 | D9: =(SUM(Returns!C9:F9)+(((('Operating Proforma'!$G$21+'Operating Proforma'!$C$15*'Operating Proforma'!$G$20*('Operating Proforma'!$C$10*12)*(1+D$5)^4)*(1-'Operating Proforma'!$C$11)+'Operating Proforma'!$G$25)*(1-'Operating Proforma'!$C$14)-('Operating Proforma'!$G$36-'Operating Proforma'!$G$35))-Debt!$G$17+((((('Operating Proforma'!$G$21+'Operating Proforma'!$C$15*'Operating Proforma'!$G$20*('Operating Proforma'!$C$10*12)*(1+D$5)^4)*(1-'Operating Proforma'!$C$11)+'Operating Proforma'!$G$25)*(1-'Operating Proforma'!$C$14)-('Operating Proforma'!$G$36-'Operating Proforma'!$G$35))*(1+D$5))/$B9)*(1-Returns!$C$13)-Debt!$G$20))/-Returns!$C$6 | E9: =(SUM(Returns!C9:F9)+(((('Operating Proforma'!$G$21+'Operating Proforma'!$C$15*'Operating Proforma'!$G$20*('Operating Proforma'!$C$10*12)*(1+E$5)^4)*(1-'Operating Proforma'!$C$11)+'Operating Proforma'!$G$25)*(1-'Operating Proforma'!$C$14)-('Operating Proforma'!$G$36-'Operating Proforma'!$G$35))-Debt!$G$17+((((('Operating Proforma'!$G$21+'Operating Proforma'!$C$15*'Operating Proforma'!$G$20*('Operating Proforma'!$C$10*12)*(1+E$5)^4)*(1-'Operating Proforma'!$C$11)+'Operating Proforma'!$G$25)*(1-'Operating Proforma'!$C$14)-('Operating Proforma'!$G$36-'Operating Proforma'!$G$35))*(1+E$5))/$B9)*(1-Returns!$C$13)-Debt!$G$20))/-Returns!$C$6 | F9: =(SUM(Returns!C9:F9)+(((('Operating Proforma'!$G$21+'Operating Proforma'!$C$15*'Operating Proforma'!$G$20*('Operating Proforma'!$C$10*12)*(1+F$5)^4)*(1-'Operating Proforma'!$C$11)+'Operating Proforma'!$G$25)*(1-'Operating Proforma'!$C$14)-('Operating Proforma'!$G$36-'Operating Proforma'!$G$35))-Debt!$G$17+((((('Operating Proforma'!$G$21+'Operating Proforma'!$C$15*'Operating Proforma'!$G$20*('Operating Proforma'!$C$10*12)*(1+F$5)^4)*(1-'Operating Proforma'!$C$11)+'Operating Proforma'!$G$25)*(1-'Operating Proforma'!$C$14)-('Operating Proforma'!$G$36-'Operating Proforma'!$G$35))*(1+F$5))/$B9)*(1-Returns!$C$13)-Debt!$G$20))/-Returns!$C$6 | G9: =(SUM(Returns!C9:F9)+(((('Operating Proforma'!$G$21+'Operating Proforma'!$C$15*'Operating Proforma'!$G$20*('Operating Proforma'!$C$10*12)*(1+G$5)^4)*(1-'Operating Proforma'!$C$11)+'Operating Proforma'!$G$25)*(1-'Operating Proforma'!$C$14)-('Operating Proforma'!$G$36-'Operating Proforma'!$G$35))-Debt!$G$17+((((('Operating Proforma'!$G$21+'Operating Proforma'!$C$15*'Operating Proforma'!$G$20*('Operating Proforma'!$C$10*12)*(1+G$5)^4)*(1-'Operating Proforma'!$C$11)+'Operating Proforma'!$G$25)*(1-'Operating Proforma'!$C$14)-('Operating Proforma'!$G$36-'Operating Proforma'!$G$35))*(1+G$5))/$B9)*(1-Returns!$C$13)-Debt!$G$20))/-Returns!$C$6
B10: 0.0575 | C10: =(SUM(Returns!C9:F9)+(((('Operating Proforma'!$G$21+'Operating Proforma'!$C$15*'Operating Proforma'!$G$20*('Operating Proforma'!$C$10*12)*(1+C$5)^4)*(1-'Operating Proforma'!$C$11)+'Operating Proforma'!$G$25)*(1-'Operating Proforma'!$C$14)-('Operating Proforma'!$G$36-'Operating Proforma'!$G$35))-Debt!$G$17+((((('Operating Proforma'!$G$21+'Operating Proforma'!$C$15*'Operating Proforma'!$G$20*('Operating Proforma'!$C$10*12)*(1+C$5)^4)*(1-'Operating Proforma'!$C$11)+'Operating Proforma'!$G$25)*(1-'Operating Proforma'!$C$14)-('Operating Proforma'!$G$36-'Operating Proforma'!$G$35))*(1+C$5))/$B10)*(1-Returns!$C$13)-Debt!$G$20))/-Returns!$C$6 | D10: =(SUM(Returns!C9:F9)+(((('Operating Proforma'!$G$21+'Operating Proforma'!$C$15*'Operating Proforma'!$G$20*('Operating Proforma'!$C$10*12)*(1+D$5)^4)*(1-'Operating Proforma'!$C$11)+'Operating Proforma'!$G$25)*(1-'Operating Proforma'!$C$14)-('Operating Proforma'!$G$36-'Operating Proforma'!$G$35))-Debt!$G$17+((((('Operating Proforma'!$G$21+'Operating Proforma'!$C$15*'Operating Proforma'!$G$20*('Operating Proforma'!$C$10*12)*(1+D$5)^4)*(1-'Operating Proforma'!$C$11)+'Operating Proforma'!$G$25)*(1-'Operating Proforma'!$C$14)-('Operating Proforma'!$G$36-'Operating Proforma'!$G$35))*(1+D$5))/$B10)*(1-Returns!$C$13)-Debt!$G$20))/-Returns!$C$6 | E10: =(SUM(Returns!C9:F9)+(((('Operating Proforma'!$G$21+'Operating Proforma'!$C$15*'Operating Proforma'!$G$20*('Operating Proforma'!$C$10*12)*(1+E$5)^4)*(1-'Operating Proforma'!$C$11)+'Operating Proforma'!$G$25)*(1-'Operating Proforma'!$C$14)-('Operating Proforma'!$G$36-'Operating Proforma'!$G$35))-Debt!$G$17+((((('Operating Proforma'!$G$21+'Operating Proforma'!$C$15*'Operating Proforma'!$G$20*('Operating Proforma'!$C$10*12)*(1+E$5)^4)*(1-'Operating Proforma'!$C$11)+'Operating Proforma'!$G$25)*(1-'Operating Proforma'!$C$14)-('Operating Proforma'!$G$36-'Operating Proforma'!$G$35))*(1+E$5))/$B10)*(1-Returns!$C$13)-Debt!$G$20))/-Returns!$C$6 | F10: =(SUM(Returns!C9:F9)+(((('Operating Proforma'!$G$21+'Operating Proforma'!$C$15*'Operating Proforma'!$G$20*('Operating Proforma'!$C$10*12)*(1+F$5)^4)*(1-'Operating Proforma'!$C$11)+'Operating Proforma'!$G$25)*(1-'Operating Proforma'!$C$14)-('Operating Proforma'!$G$36-'Operating Proforma'!$G$35))-Debt!$G$17+((((('Operating Proforma'!$G$21+'Operating Proforma'!$C$15*'Operating Proforma'!$G$20*('Operating Proforma'!$C$10*12)*(1+F$5)^4)*(1-'Operating Proforma'!$C$11)+'Operating Proforma'!$G$25)*(1-'Operating Proforma'!$C$14)-('Operating Proforma'!$G$36-'Operating Proforma'!$G$35))*(1+F$5))/$B10)*(1-Returns!$C$13)-Debt!$G$20))/-Returns!$C$6 | G10: =(SUM(Returns!C9:F9)+(((('Operating Proforma'!$G$21+'Operating Proforma'!$C$15*'Operating Proforma'!$G$20*('Operating Proforma'!$C$10*12)*(1+G$5)^4)*(1-'Operating Proforma'!$C$11)+'Operating Proforma'!$G$25)*(1-'Operating Proforma'!$C$14)-('Operating Proforma'!$G$36-'Operating Proforma'!$G$35))-Debt!$G$17+((((('Operating Proforma'!$G$21+'Operating Proforma'!$C$15*'Operating Proforma'!$G$20*('Operating Proforma'!$C$10*12)*(1+G$5)^4)*(1-'Operating Proforma'!$C$11)+'Operating Proforma'!$G$25)*(1-'Operating Proforma'!$C$14)-('Operating Proforma'!$G$36-'Operating Proforma'!$G$35))*(1+G$5))/$B10)*(1-Returns!$C$13)-Debt!$G$20))/-Returns!$C$6
B13: 2-WAY: EXIT CAP RATE x MARKET RENT GROWTH -> TOTAL PROFIT ($)
B14: Exit Cap \ Mkt Growth | C14: 0.02 | D14: 0.025 | E14: 0.03 | F14: 0.035 | G14: 0.04
B15: 0.0475 | C15: =(C6-1)*-Returns!$C$6 | D15: =(D6-1)*-Returns!$C$6 | E15: =(E6-1)*-Returns!$C$6 | F15: =(F6-1)*-Returns!$C$6 | G15: =(G6-1)*-Returns!$C$6
B16: 0.05 | C16: =(C7-1)*-Returns!$C$6 | D16: =(D7-1)*-Returns!$C$6 | E16: =(E7-1)*-Returns!$C$6 | F16: =(F7-1)*-Returns!$C$6 | G16: =(G7-1)*-Returns!$C$6
B17: 0.0525 | C17: =(C8-1)*-Returns!$C$6 | D17: =(D8-1)*-Returns!$C$6 | E17: =(E8-1)*-Returns!$C$6 | F17: =(F8-1)*-Returns!$C$6 | G17: =(G8-1)*-Returns!$C$6
B18: 0.055 | C18: =(C9-1)*-Returns!$C$6 | D18: =(D9-1)*-Returns!$C$6 | E18: =(E9-1)*-Returns!$C$6 | F18: =(F9-1)*-Returns!$C$6 | G18: =(G9-1)*-Returns!$C$6
B19: 0.0575 | C19: =(C10-1)*-Returns!$C$6 | D19: =(D10-1)*-Returns!$C$6 | E19: =(E10-1)*-Returns!$C$6 | F19: =(F10-1)*-Returns!$C$6 | G19: =(G10-1)*-Returns!$C$6
B23: 1-WAY: INTEREST RATE x YEAR-1 DSCR
B24: Interest Rate | C24: 0.04 | D24: 0.0475 | E24: 0.055 | F24: 0.0625 | G24: 0.065
B25: Year-1 DSCR | C25: ='Operating Proforma'!$C$39/(-PMT(C24/12,Debt!$D$9*12,Debt!$D$8)*12) | D25: ='Operating Proforma'!$C$39/(-PMT(D24/12,Debt!$D$9*12,Debt!$D$8)*12) | E25: ='Operating Proforma'!$C$39/(-PMT(E24/12,Debt!$D$9*12,Debt!$D$8)*12) | F25: ='Operating Proforma'!$C$39/(-PMT(F24/12,Debt!$D$9*12,Debt!$D$8)*12) | G25: ='Operating Proforma'!$C$39/(-PMT(G24/12,Debt!$D$9*12,Debt!$D$8)*12)
B28: Closed-form sensitivities recompute Year-5 NOI / debt service directly from named assumptions (no Excel What-If Data Tables required); vacancy loss and management fee flex with the grid's rent-growth-driven GPR/EGI (other opex lines held at Year-5 proforma levels). Base case: exit cap 5.25%, market rent growth 3.0%.

Sheet Market Data
B2: MARKET DATA & SOURCES
B4: Metric | C4: Value | D4: Source
B5: Toronto multifamily cap rate range (Q1 2026) | C5: 3.85% - 4.75% | D5: CBRE Canada Cap Rate Survey, Q1 2026
B6: Subject listing advertised cap rate | C6: 6.15% | D6: Listing marketing materials, 2480 Dundas St W
B7: Subject implied opex ratio (advertised) | C7: 17.6% | D7: Derived: advertised opex / advertised GAI
B8: Toronto small multifamily opex ratio benchmark | C8: 32% - 45% of EGI | D8: Industry underwriting norms for <20-unit walk-ups, GTA
B9: Toronto average asking rent, 1BR (market) | C9: ~$2,150/mo | D9: Rentals.ca / Urbanation Toronto Rent Report
B10: Subject in-place average rent (hard-loft premium) | C10: ~$2,660/mo | D10: Derived from advertised GAI of $447,113 / 14 units / 12
B11: Premium loft reset rent assumption (post-turnover) | C11: $2,900/mo | D11: Underwriting assumption - loft/live-work niche premium
B12: Ontario Residential Rent Increase Guideline (2026) | C12: 2.1% | D12: Ontario Ministry of Municipal Affairs and Housing, Rent Increase Guideline
B13: Toronto purpose-built rental vacancy rate | C13: < 2.0% | D13: CMHC Rental Market Report, Toronto CMA
B14: CMHC-insured 5-yr multi-unit mortgage rate (indicative) | C14: ~4.45% | D14: CMHC MLI Select / lender rate sheets, 2026
B15: Conventional 5-yr multi-unit mortgage rate (indicative) | C15: ~5.50% | D15: Chartered bank commercial/multi-res lending desks, 2026
... B19: Market rent growth assumption | C19: 3.0% per annum | D19: Underwriting assumption, informed by CMHC/Urbanation trend data
