Workbook

Sheet Cover
B2: Mega-Cap Tech - Trading Comparables & Football Field
B3: ($ in millions, except per-share data, unless noted)
B4: Subjects: Microsoft (MSFT), NVIDIA (NVDA), Apple (AAPL), Alphabet (GOOGL) - vs. a 10-name comp set
B5: Prepared by: Akul Veauli
B6: Date: August 23, 2026
B8: Model description: Trading comparables analysis of 4 mega-cap tech subjects (MSFT, NVDA, AAPL, GOOGL - the DCF-suite companies) against a 10-name comp set that adds AMZN, META, AVGO, ORCL, CRM, and AMD. The Inputs tab holds all hardcoded market/financial data (as of 8/21/26 close, latest 10-Q/10-K balance-sheet items); the Comps tab spreads EV and equity multiples and computes two summary-statistics blocks (all 10 names, and a peer-only 6-name block that excludes each subject from its own valuation range). The ImpliedVal tab applies the peer-only 25th/median/75th percentile multiples to each subject's NTM metrics to back into an implied share-price range under three methods (EV/EBITDA, EV/Revenue, P/E). The FootballField tab assembles, for each subject, six per-share ranges - 52-week trading range, the three comps-implied ranges, and (as sourced blue inputs transcribed from the completed DCF and Precedent Transactions workbooks, per the master-spec ban on cross-workbook links) the DCF range and the precedent-transactions range - with a data table (the deliverable) plus a presentation-only horizontal bar chart per subject.
B13: Color-code legend
B14: 123.4 (hardcoded input) | C14: Blue font / yellow fill = hardcoded assumption
B15: e.g. D6*E6 (same-sheet formula) | C15: Black font = formula referencing same tab
B16: e.g. 'Inputs'!E6 (cross-tab link) | C16: Green font = formula linking from another tab
B17: 52,100 (estimated/derived input) | C17: Orange font/fill = data-pack gap; value estimated, derived, or judgment-based (see adjacent note)
B20: Table of contents
B21: Cover
B22: Inputs
B23: Comps
B24: ImpliedVal
B25: FootballField
B27: Key outputs - Football Field per-share ranges (low / high)
B28: Subject | C28: Current Price | D28: Comps EV/EBITDA Low-High | E28: DCF Low-High | F28: Precedents Low-High
B29: MSFT | C29: =ImpliedVal!C13 | D29: ="$"&TEXT(ImpliedVal!C19,"0.00")&" - $"&TEXT(ImpliedVal!E19,"0.00") | E29: ="$"&TEXT(FootballField!C12,"0.00")&" - $"&TEXT(FootballField!D12,"0.00") | F29: ="$"&TEXT(FootballField!C13,"0.00")&" - $"&TEXT(FootballField!D13,"0.00")
B30: NVDA | C30: =ImpliedVal!C43 | D30: ="$"&TEXT(ImpliedVal!C49,"0.00")&" - $"&TEXT(ImpliedVal!E49,"0.00") | E30: ="$"&TEXT(FootballField!C22,"0.00")&" - $"&TEXT(FootballField!D22,"0.00") | F30: ="$"&TEXT(FootballField!C23,"0.00")&" - $"&TEXT(FootballField!D23,"0.00")
B31: AAPL | C31: =ImpliedVal!C73 | D31: ="$"&TEXT(ImpliedVal!C79,"0.00")&" - $"&TEXT(ImpliedVal!E79,"0.00") | E31: ="$"&TEXT(FootballField!C32,"0.00")&" - $"&TEXT(FootballField!D32,"0.00") | F31: ="$"&TEXT(FootballField!C33,"0.00")&" - $"&TEXT(FootballField!D33,"0.00")
B32: GOOGL | C32: =ImpliedVal!C103 | D32: ="$"&TEXT(ImpliedVal!C109,"0.00")&" - $"&TEXT(ImpliedVal!E109,"0.00") | E32: ="$"&TEXT(FootballField!C42,"0.00")&" - $"&TEXT(FootballField!D42,"0.00") | F32: ="$"&TEXT(FootballField!C43,"0.00")&" - $"&TEXT(FootballField!D43,"0.00")
B34: Sources: E4-comps.md data pack (incl. GAP-FILL PASS E4b) for all Inputs-tab figures - SEC 10-Q/10-K filings, Yahoo Finance market data (as of 8/21/26), and analyst-consensus aggregators (Seeking Alpha, TipRanks, MacroTrends, GuruFocus) per the source-note column on the Inputs tab. DCF ranges: Akul Veauli - DCF Model (Microsoft/Nvidia/Apple/Alphabet).xlsx implied-price outputs. Precedent ranges: Akul Veauli - Precedent Transactions.xlsx ImpliedVal/Precedents tabs. See Inputs tab source column for line-by-line citations and flagged estimates/data-quality notes. QA PASS 8/23/26: META's LTM revenue/EBITDA/net income/EPS and share count were CORRECTED against Meta's SEC-filed Q3'25-Q2'26 earnings releases - the E4 pack's $115.0B LTM revenue was ~2x low; LTM revenue is now $228,247mm. AMD's $41.31B LTM revenue was independently re-verified against AMD's Q3'25-Q2'26 releases and is exact ($9,246+$10,270+$10,253+$11,536 = $41,305mm). AMD's LTM EBITDA ($3.75B, a wide-range estimate) is now the single weakest data point in the comp set - see the orange-flagged cells and REVIEWER FLAG note on the Inputs tab.

Sheet Inputs
B2: Trading Comps - Mega-Cap Tech + Peers - Company Inputs
B3: ($ in millions except per-share data, share price, and diluted shares in millions; ALL cells this tab are hardcoded inputs)
B4: As-of date (all pricing & 52-week data): August 21, 2026 close. Balance-sheet items: latest 10-Q/10-K per company (see source column). Comp set: MSFT/NVDA/AAPL/GOOGL (DCF-suite subjects) + AMZN/META/AVGO/ORCL/CRM/AMD (peers).
B5: Ticker | C5: Company | D5: FYE | E5: Price (8/21/26) | F5: Diluted Shares (mm) | G5: Cash & Invest. | H5: Total Debt | I5: Minority Interest | J5: LTM Revenue | K5: LTM EBITDA | L5: LTM Net Income | M5: LTM Diluted EPS | N5: NTM Revenue | O5: NTM EBITDA | P5: NTM Diluted EPS | Q5: 52-Wk Low | R5: 52-Wk High | S5: Source / notes (ESTIMATE flags noted in orange)
B6: MSFT | C6: Microsoft Corporation | D6: 6/30 | E6: 483.24 | F6: 7420 | G6: 76800 | H6: 40300 | I6: 500 | J6: 290000 | K6: 193800 | L6: 88000 | M6: 17.93 | N6: 361000 | O6: 241300 | P6: 19.4 | Q6: 349.2 | R6: 553.72 | S6: Price/52wk: Yahoo Finance 8/21/26. Shares/cash/debt: Q4 FY26 10-Q ($20.9B cash+$55.9B ST invest; $40.3B debt). LTM EBITDA $193.8B per Yahoo Finance TTM 6/30/26. NTM rev $361.0B FY27 consensus (13% growth). MI: immaterial, ESTIMATE. NTM EBITDA: ESTIMATE, margin held flat at LTM 66.8% applied to NTM revenue (no consensus EBITDA published).
B7: NVDA | C7: NVIDIA Corporation | D7: 1/31 | E7: 214.72 | F7: 24200 | G7: 50300 | H7: 33500 | I7: 0 | J7: 254000 | K7: 133230 | L7: 60000 | M7: 2.5 | N7: 369400 | O7: 193700 | P7: 8.29 | Q7: 164.07 | R7: 236.54 | S7: Price/52wk: Yahoo Finance 8/21/26. Cash: Q2 FY26 10-Q total liquid $50.3B (cash+ST invest, incl. restricted); ESTIMATE. Debt: ESTIMATE $33.5B post-Q2 subsequent event ($25B IG bond raise June 2026 per E4b; 10-Q reported figure was $8.5B pre-raise). LTM EBITDA $133.23B: ESTIMATE, FY26 op income $130.39B + D&A $2.84B (GuruFocus). NTM EBITDA: ESTIMATE, margin held flat applied to NTM consensus revenue $369.4B / EPS $8.29 (Seeking Alpha).
B8: AAPL | C8: Apple Inc. | D8: 9/30 | E8: 309.35 | F8: 14600 | G8: 132420 | H8: 82300 | I8: 0 | J8: 430000 | K8: 144748 | L8: 110000 | M8: 7.5 | N8: 473000 | O8: 159200 | P8: 8.48 | Q8: 224.69 | R8: 344.57 | S8: Price/52wk: Yahoo Finance 8/21/26. Debt $82.3B per 10-Q filed 7/31/26. Cash: ESTIMATE, backed into from Precedent Transactions workbook net-debt figure (-$50.12B net cash) less reported debt (10-Q did not break out full cash/investments). LTM EBITDA $144.75B: ESTIMATE, FY25 op income $133.05B + D&A $11.70B. NTM revenue/EBITDA/EPS: ESTIMATE, 10% growth applied to LTM (mature-cohort assumption per E4 usage notes; no CY2027 consensus available in source data).
B9: GOOGL | C9: Alphabet Inc. | D9: 12/31 | E9: 344.82 | F9: 12200 | G9: 252600 | H9: 98165 | I9: 0 | J9: 446000 | K9: 140100 | L9: 76000 | M9: 6.23 | N9: 530000 | O9: 166400 | P9: 12.5 | Q9: 205.28 | R9: 408.61 | S9: Price/52wk: Yahoo Finance 8/21/26. Cash $252.6B / debt $98.165B per Q2 10-Q (6/30/26). LTM EBITDA $140.1B: ESTIMATE, Q2 op income $40.8B annualized (~34% op margin on $446B LTM rev) + est. 3-5% D&A. NTM revenue $530B: ESTIMATE, 12% consensus-adjacent growth (Zacks/Seeking Alpha). NTM EBITDA: ESTIMATE, margin held flat. NTM EPS $12.50: ESTIMATE, 8% growth off $11.57 base.
B10: AMZN | C10: Amazon.com, Inc. | D10: 12/31 | E10: 258.63 | F10: 10783 | G10: 123000 | H10: 133000 | I10: 0 | J10: 700000 | K10: 168910 | L10: 63000 | M10: 5.84 | N10: 895000 | O10: 216000 | P10: 7.75 | Q10: 196 | R10: 287.2 | S10: Shares 10.783B per Q2 10-Q (6/30/26). Cash $123.0B / debt $133.0B per 10-Q (source note flags $128.9B debt alt.-figure; table value used). LTM EBITDA $168.91B per MacroTrends TTM 6/30/26 (+25.4% YoY). NTM rev $895B: ESTIMATE 11% growth (Seeking Alpha consensus base $807.7B). NTM EBITDA: ESTIMATE, margin held flat. NTM EPS $7.75: ESTIMATE consensus (alt. $8.50 AWS-upside case not used).
B11: META | C11: Meta Platforms, Inc. | D11: 12/31 | E11: 549.9 | F11: 2566 | G11: 90300 | H11: 83700 | I11: 0 | J11: 228247 | K11: 109656 | L11: 68098 | M11: 26.55 | N11: 267050 | O11: 126104 | P11: 30.27 | Q11: 520.26 | R11: 790.8 | S11: CORRECTED IN QA PASS (8/23/26) -- supersedes E4 data pack. LTM = four reported quarters Q3'25+Q4'25+Q1'26+Q2'26 per Meta's SEC-filed Ex-99.1 earnings releases: revenue $51,242+$59,893+$56,311+$60,801 = $228,247mm. The E4 pack's $115.0B LTM revenue was ~2x low (it approximated H1'26 of $117.1B, not an LTM) and its $47.52B Q2 revenue was also wrong (actual Q2'26 = $60,801mm). LTM EBITDA $109,656mm = LTM operating income $86,927mm + LTM D&A $22,729mm (cash-flow-statement D&A), i.e. the spec's EBIT+D&A definition -- REPORTED, replacing the prior $110.4B GuruFocus/MacroTrends blend. LTM net income $68,098mm; LTM diluted EPS $26.55; diluted wtd-avg shares 2,566mm per Q2'26 release. CAUTION: LTM net income/EPS straddle two large one-off tax items (a $15.93B non-cash OBBBA charge in Q3'25 and an $8.03B benefit in Q1'26), net ~$7.9B understatement vs. a clean tax rate, so P/E multiples for META read high; operating income and EBITDA are unaffected. Cash $90.3B / debt $83.7B per Q2'26 10-Q (6/30/26) -- carried from E4 pack; note the pack cited a Match Group (MTCH) 10-Q URL for these, so the citation is wrong even though the values are consistent with Meta's Q2'26 balance sheet. NTM revenue $267.05B: ESTIMATE, the pack's 17% consensus growth rate re-applied to the CORRECTED LTM base (the pack's $135B NTM was 17% on the erroneous $115B base and would have implied negative growth off corrected LTM). NTM EBITDA $126.10B: ESTIMATE, pack's 15% growth applied to corrected LTM EBITDA. NTM EPS $30.27: ESTIMATE, pack's 14% growth applied to corrected LTM EPS $26.55.
B12: AVGO | C12: Broadcom Inc. | D12: ~11/2 | E12: 368.45 | F12: 4760 | G12: 19630 | H12: 64910 | I12: 0 | J12: 75470 | K12: 52100 | L12: 23090 | M12: 4.85 | N12: 104680 | O12: 72230 | P12: 11.35 | Q12: 287.17 | R12: 495 | S12: Cash $19.63B / debt $64.91B per Q2 FY26 10-Q (E4b gap-fill). LTM revenue $75.47B per MacroTrends (LTM ended 4/30/26). LTM EBITDA $52.1B: ESTIMATE, 69% adj. EBITDA margin (Q2 reported) x LTM revenue. LTM EPS $4.85 / NI: ESTIMATE, derived from Q2 GAAP EPS $1.91 annualized w/ operating leverage. NTM revenue $104.68B / EPS $11.35: 2027 consensus per Seeking Alpha. NTM EBITDA $72.23B: ESTIMATE, 69% margin applied to NTM consensus revenue (E4b gap-fill methodology).
B13: ORCL | C13: Oracle Corporation | D13: 5/31 | E13: 146.47 | F13: 2880 | G13: 5000 | H13: 130900 | I13: 0 | J13: 59000 | K13: 27441 | L13: 11500 | M13: 4 | N13: 89200 | O13: 26000 | P13: 6.34 | Q13: 114.5 | R13: 345.72 | S13: Debt $130.9B per 10-Q (2/28/26). Cash $5.0B: ESTIMATE/PARTIAL - source table flags this as operating cash/liquid reserves only, not full cash+investments (10-Q review needed for complete figure). LTM EBITDA $27.44B: ESTIMATE, GuruFocus LTM (Feb 2026), mixed period basis vs. other balance-sheet dates. NTM revenue $89.2B / EPS $6.34: FY2027 consensus (ending 5/31/27). NTM EBITDA $26.0B: ESTIMATE, midpoint of E4b gap-fill range ($25-27B @ 28-30% margin).
B14: CRM | C14: Salesforce, Inc. | D14: 1/31 | E14: 209.17 | F14: 819 | G14: 11840 | H14: 39300 | I14: 0 | J14: 41525 | K14: 14160 | L14: 2100 | M14: 2.57 | N14: 46050 | O14: 11500 | P14: 14.09 | Q14: 146.32 | R14: 269.11 | S14: Cash $8.94B + ST invest $2.90B = $11.84B / debt $39.3B per Q1 FY27 10-Q (4/30/26, E4b gap-fill). LTM revenue $41.525B / EBITDA $14.16B per FY2026 10-K (ended 1/31/26). NTM revenue $46.05B (midpoint of $45.9-46.2B FY2027 guidance) / EPS $14.09 (midpoint $14.06-14.12). NTM EBITDA $11.5B: ESTIMATE, midpoint of E4b gap-fill range (~$11-12B @ 24-25% margin, TTM basis).
B15: AMD | C15: Advanced Micro Devices, Inc. | D15: ~12/27 (last Sat.) | E15: 473.25 | F15: 1630 | G15: 13110 | H15: 3230 | I15: 0 | J15: 41310 | K15: 3750 | L15: 6930 | M15: 4.25 | N15: 68000 | O15: 16500 | P15: 20 | Q15: 149.22 | R15: 584.73 | S15: REVIEWER FLAG (per build brief): AMD EBITDA is the weakest data point in the comp set. Cash $13.11B (~$10.0B cash + $3.1B ST invest) / debt $3.23B per Q2 2026 10-Q (E4b gap-fill), figure ESTIMATE/approx (source uses '~'). LTM revenue $41.31B confirmed (Q2 2026 10-Q, ended 6/27/26) - NOTE this supersedes an inconsistent $56B figure in the original (pre-gap-fill) E4 pass. RE-VERIFIED IN QA PASS (8/23/26) against AMD's four reported quarterly releases Q3'25-Q2'26: $9,246+$10,270+$10,253+$11,536 = $41,305mm, i.e. $41.31B is exact, not merely approximate. Shelf-life caveat: AMD guided Q3'26 to ~$13B, which on report (early Nov 2026) replaces the $9,246mm Q3'25 quarter and lifts LTM revenue to roughly $45B. LTM EBITDA $3.75B: ESTIMATE, midpoint of E4b's wide $3.5-4.0B range (non-GAAP op-margin based; GAAP op income only ~$2B/qtr with heavy SBC/amortization add-backs - high uncertainty). LTM EPS $4.25 / NI: ESTIMATE, E4b updated post-Q2 range ($4.00-4.50) midpoint (Q2 alone was $1.38 GAAP / $1.66 non-GAAP). NTM revenue $68B consensus ESTIMATE. NTM EBITDA $16.5B: ESTIMATE, midpoint of E4b range ($15-18B @ 22-27% margin). NTM EPS $20.00: ESTIMATE, E4b flags '$20+' per CEO commentary; treated as a point estimate, not a hard consensus figure.
B17: Legend:
B18: Blue / yellow fill | C18: - hardcoded input, directly sourced
B19: Orange / peach fill | C19: - ESTIMATE / derived (data-pack gap-fill, growth/margin assumption, or judgment call - see source column)
B20: Subjects (rows 6-9) = the 4 DCF-suite companies. Peers (rows 10-15) = the 6 additional comp-set names. This split is load-bearing: the Comps tab's peer-only statistics block (feeding ImpliedVal) is a straight range over rows 10-15.

Sheet Comps
B2: Trading Comps - Spread of Multiples
B3: ($ in millions except per-share; multiples 0.0x; all formulas link from Inputs)
B5: Ticker | C5: Company | D5: Price | E5: Market Cap | F5: EV | G5: EV / LTM Rev | H5: EV / NTM Rev | I5: EV / LTM EBITDA | J5: EV / NTM EBITDA | K5: P / LTM E | L5: P / NTM E | M5: LTM EBITDA Margin % | N5: NTM Rev Growth %
B6: =Inputs!B6 | C6: =Inputs!C6 | D6: =Inputs!E6 | E6: =D6*Inputs!F6 | F6: =E6+Inputs!H6+Inputs!I6-Inputs!G6 | G6: =IFERROR(F6/Inputs!J6,"n.m.") | H6: =IFERROR(F6/Inputs!N6,"n.m.") | I6: =IFERROR(F6/Inputs!K6,"n.m.") | J6: =IFERROR(F6/Inputs!O6,"n.m.") | K6: =IFERROR(Inputs!E6/Inputs!M6,"n.m.") | L6: =IFERROR(Inputs!E6/Inputs!P6,"n.m.") | M6: =IFERROR(Inputs!K6/Inputs!J6,"n.m.") | N6: =IFERROR(Inputs!N6/Inputs!J6-1,"n.m.")
B7: =Inputs!B7 | C7: =Inputs!C7 | D7: =Inputs!E7 | E7: =D7*Inputs!F7 | F7: =E7+Inputs!H7+Inputs!I7-Inputs!G7 | G7: =IFERROR(F7/Inputs!J7,"n.m.") | H7: =IFERROR(F7/Inputs!N7,"n.m.") | I7: =IFERROR(F7/Inputs!K7,"n.m.") | J7: =IFERROR(F7/Inputs!O7,"n.m.") | K7: =IFERROR(Inputs!E7/Inputs!M7,"n.m.") | L7: =IFERROR(Inputs!E7/Inputs!P7,"n.m.") | M7: =IFERROR(Inputs!K7/Inputs!J7,"n.m.") | N7: =IFERROR(Inputs!N7/Inputs!J7-1,"n.m.")
B8: =Inputs!B8 | C8: =Inputs!C8 | D8: =Inputs!E8 | E8: =D8*Inputs!F8 | F8: =E8+Inputs!H8+Inputs!I8-Inputs!G8 | G8: =IFERROR(F8/Inputs!J8,"n.m.") | H8: =IFERROR(F8/Inputs!N8,"n.m.") | I8: =IFERROR(F8/Inputs!K8,"n.m.") | J8: =IFERROR(F8/Inputs!O8,"n.m.") | K8: =IFERROR(Inputs!E8/Inputs!M8,"n.m.") | L8: =IFERROR(Inputs!E8/Inputs!P8,"n.m.") | M8: =IFERROR(Inputs!K8/Inputs!J8,"n.m.") | N8: =IFERROR(Inputs!N8/Inputs!J8-1,"n.m.")
B9: =Inputs!B9 | C9: =Inputs!C9 | D9: =Inputs!E9 | E9: =D9*Inputs!F9 | F9: =E9+Inputs!H9+Inputs!I9-Inputs!G9 | G9: =IFERROR(F9/Inputs!J9,"n.m.") | H9: =IFERROR(F9/Inputs!N9,"n.m.") | I9: =IFERROR(F9/Inputs!K9,"n.m.") | J9: =IFERROR(F9/Inputs!O9,"n.m.") | K9: =IFERROR(Inputs!E9/Inputs!M9,"n.m.") | L9: =IFERROR(Inputs!E9/Inputs!P9,"n.m.") | M9: =IFERROR(Inputs!K9/Inputs!J9,"n.m.") | N9: =IFERROR(Inputs!N9/Inputs!J9-1,"n.m.")
B10: =Inputs!B10 | C10: =Inputs!C10 | D10: =Inputs!E10 | E10: =D10*Inputs!F10 | F10: =E10+Inputs!H10+Inputs!I10-Inputs!G10 | G10: =IFERROR(F10/Inputs!J10,"n.m.") | H10: =IFERROR(F10/Inputs!N10,"n.m.") | I10: =IFERROR(F10/Inputs!K10,"n.m.") | J10: =IFERROR(F10/Inputs!O10,"n.m.") | K10: =IFERROR(Inputs!E10/Inputs!M10,"n.m.") | L10: =IFERROR(Inputs!E10/Inputs!P10,"n.m.") | M10: =IFERROR(Inputs!K10/Inputs!J10,"n.m.") | N10: =IFERROR(Inputs!N10/Inputs!J10-1,"n.m.")
B11: =Inputs!B11 | C11: =Inputs!C11 | D11: =Inputs!E11 | E11: =D11*Inputs!F11 | F11: =E11+Inputs!H11+Inputs!I11-Inputs!G11 | G11: =IFERROR(F11/Inputs!J11,"n.m.") | H11: =IFERROR(F11/Inputs!N11,"n.m.") | I11: =IFERROR(F11/Inputs!K11,"n.m.") | J11: =IFERROR(F11/Inputs!O11,"n.m.") | K11: =IFERROR(Inputs!E11/Inputs!M11,"n.m.") | L11: =IFERROR(Inputs!E11/Inputs!P11,"n.m.") | M11: =IFERROR(Inputs!K11/Inputs!J11,"n.m.") | N11: =IFERROR(Inputs!N11/Inputs!J11-1,"n.m.")
B12: =Inputs!B12 | C12: =Inputs!C12 | D12: =Inputs!E12 | E12: =D12*Inputs!F12 | F12: =E12+Inputs!H12+Inputs!I12-Inputs!G12 | G12: =IFERROR(F12/Inputs!J12,"n.m.") | H12: =IFERROR(F12/Inputs!N12,"n.m.") | I12: =IFERROR(F12/Inputs!K12,"n.m.") | J12: =IFERROR(F12/Inputs!O12,"n.m.") | K12: =IFERROR(Inputs!E12/Inputs!M12,"n.m.") | L12: =IFERROR(Inputs!E12/Inputs!P12,"n.m.") | M12: =IFERROR(Inputs!K12/Inputs!J12,"n.m.") | N12: =IFERROR(Inputs!N12/Inputs!J12-1,"n.m.")
B13: =Inputs!B13 | C13: =Inputs!C13 | D13: =Inputs!E13 | E13: =D13*Inputs!F13 | F13: =E13+Inputs!H13+Inputs!I13-Inputs!G13 | G13: =IFERROR(F13/Inputs!J13,"n.m.") | H13: =IFERROR(F13/Inputs!N13,"n.m.") | I13: =IFERROR(F13/Inputs!K13,"n.m.") | J13: =IFERROR(F13/Inputs!O13,"n.m.") | K13: =IFERROR(Inputs!E13/Inputs!M13,"n.m.") | L13: =IFERROR(Inputs!E13/Inputs!P13,"n.m.") | M13: =IFERROR(Inputs!K13/Inputs!J13,"n.m.") | N13: =IFERROR(Inputs!N13/Inputs!J13-1,"n.m.")
B14: =Inputs!B14 | C14: =Inputs!C14 | D14: =Inputs!E14 | E14: =D14*Inputs!F14 | F14: =E14+Inputs!H14+Inputs!I14-Inputs!G14 | G14: =IFERROR(F14/Inputs!J14,"n.m.") | H14: =IFERROR(F14/Inputs!N14,"n.m.") | I14: =IFERROR(F14/Inputs!K14,"n.m.") | J14: =IFERROR(F14/Inputs!O14,"n.m.") | K14: =IFERROR(Inputs!E14/Inputs!M14,"n.m.") | L14: =IFERROR(Inputs!E14/Inputs!P14,"n.m.") | M14: =IFERROR(Inputs!K14/Inputs!J14,"n.m.") | N14: =IFERROR(Inputs!N14/Inputs!J14-1,"n.m.")
B15: =Inputs!B15 | C15: =Inputs!C15 | D15: =Inputs!E15 | E15: =D15*Inputs!F15 | F15: =E15+Inputs!H15+Inputs!I15-Inputs!G15 | G15: =IFERROR(F15/Inputs!J15,"n.m.") | H15: =IFERROR(F15/Inputs!N15,"n.m.") | I15: =IFERROR(F15/Inputs!K15,"n.m.") | J15: =IFERROR(F15/Inputs!O15,"n.m.") | K15: =IFERROR(Inputs!E15/Inputs!M15,"n.m.") | L15: =IFERROR(Inputs!E15/Inputs!P15,"n.m.") | M15: =IFERROR(Inputs!K15/Inputs!J15,"n.m.") | N15: =IFERROR(Inputs!N15/Inputs!J15-1,"n.m.")
B18: Summary Statistics - All 10 (4 Subjects + 6 Peers)
B19: Statistic | G19: EV / LTM Rev | H19: EV / NTM Rev | I19: EV / LTM EBITDA | J19: EV / NTM EBITDA | K19: P / LTM E | L19: P / NTM E | M19: LTM EBITDA Margin % | N19: NTM Rev Growth %
B20: Max | G20: =MAX(G6:G15) | H20: =MAX(H6:H15) | I20: =MAX(I6:I15) | J20: =MAX(J6:J15) | K20: =MAX(K6:K15) | L20: =MAX(L6:L15) | M20: =MAX(M6:M15) | N20: =MAX(N6:N15)
B21: 75th pctile | G21: =_xlfn.QUARTILE.INC(G6:G15,3) | H21: =_xlfn.QUARTILE.INC(H6:H15,3) | I21: =_xlfn.QUARTILE.INC(I6:I15,3) | J21: =_xlfn.QUARTILE.INC(J6:J15,3) | K21: =_xlfn.QUARTILE.INC(K6:K15,3) | L21: =_xlfn.QUARTILE.INC(L6:L15,3) | M21: =_xlfn.QUARTILE.INC(M6:M15,3) | N21: =_xlfn.QUARTILE.INC(N6:N15,3)
B22: Mean | G22: =AVERAGE(G6:G15) | H22: =AVERAGE(H6:H15) | I22: =AVERAGE(I6:I15) | J22: =AVERAGE(J6:J15) | K22: =AVERAGE(K6:K15) | L22: =AVERAGE(L6:L15) | M22: =AVERAGE(M6:M15) | N22: =AVERAGE(N6:N15)
B23: Median | G23: =MEDIAN(G6:G15) | H23: =MEDIAN(H6:H15) | I23: =MEDIAN(I6:I15) | J23: =MEDIAN(J6:J15) | K23: =MEDIAN(K6:K15) | L23: =MEDIAN(L6:L15) | M23: =MEDIAN(M6:M15) | N23: =MEDIAN(N6:N15)
B24: 25th pctile | G24: =_xlfn.QUARTILE.INC(G6:G15,1) | H24: =_xlfn.QUARTILE.INC(H6:H15,1) | I24: =_xlfn.QUARTILE.INC(I6:I15,1) | J24: =_xlfn.QUARTILE.INC(J6:J15,1) | K24: =_xlfn.QUARTILE.INC(K6:K15,1) | L24: =_xlfn.QUARTILE.INC(L6:L15,1) | M24: =_xlfn.QUARTILE.INC(M6:M15,1) | N24: =_xlfn.QUARTILE.INC(N6:N15,1)
B25: Min | G25: =MIN(G6:G15) | H25: =MIN(H6:H15) | I25: =MIN(I6:I15) | J25: =MIN(J6:J15) | K25: =MIN(K6:K15) | L25: =MIN(L6:L15) | M25: =MIN(M6:M15) | N25: =MIN(N6:N15)
B26: n (count) | G26: =COUNT(G6:G15) | H26: =COUNT(H6:H15) | I26: =COUNT(I6:I15) | J26: =COUNT(J6:J15) | K26: =COUNT(K6:K15) | L26: =COUNT(L6:L15) | M26: =COUNT(M6:M15) | N26: =COUNT(N6:N15)
B27: Note: includes the 4 subject companies in their own stats (pragmatic simplification per spec). Use the peer-only block below for ImpliedVal (subject excluded from its own peer range).
B30: Summary Statistics - 6 Pure Peers Only (excl. subjects; basis for ImpliedVal tab)
B31: Statistic | G31: EV / LTM Rev | H31: EV / NTM Rev | I31: EV / LTM EBITDA | J31: EV / NTM EBITDA | K31: P / LTM E | L31: P / NTM E | M31: LTM EBITDA Margin % | N31: NTM Rev Growth %
B32: Max | G32: =MAX(G10:G15) | H32: =MAX(H10:H15) | I32: =MAX(I10:I15) | J32: =MAX(J10:J15) | K32: =MAX(K10:K15) | L32: =MAX(L10:L15) | M32: =MAX(M10:M15) | N32: =MAX(N10:N15)
B33: 75th pctile | G33: =_xlfn.QUARTILE.INC(G10:G15,3) | H33: =_xlfn.QUARTILE.INC(H10:H15,3) | I33: =_xlfn.QUARTILE.INC(I10:I15,3) | J33: =_xlfn.QUARTILE.INC(J10:J15,3) | K33: =_xlfn.QUARTILE.INC(K10:K15,3) | L33: =_xlfn.QUARTILE.INC(L10:L15,3) | M33: =_xlfn.QUARTILE.INC(M10:M15,3) | N33: =_xlfn.QUARTILE.INC(N10:N15,3)
B34: Mean | G34: =AVERAGE(G10:G15) | H34: =AVERAGE(H10:H15) | I34: =AVERAGE(I10:I15) | J34: =AVERAGE(J10:J15) | K34: =AVERAGE(K10:K15) | L34: =AVERAGE(L10:L15) | M34: =AVERAGE(M10:M15) | N34: =AVERAGE(N10:N15)
B35: Median | G35: =MEDIAN(G10:G15) | H35: =MEDIAN(H10:H15) | I35: =MEDIAN(I10:I15) | J35: =MEDIAN(J10:J15) | K35: =MEDIAN(K10:K15) | L35: =MEDIAN(L10:L15) | M35: =MEDIAN(M10:M15) | N35: =MEDIAN(N10:N15)
B36: 25th pctile | G36: =_xlfn.QUARTILE.INC(G10:G15,1) | H36: =_xlfn.QUARTILE.INC(H10:H15,1) | I36: =_xlfn.QUARTILE.INC(I10:I15,1) | J36: =_xlfn.QUARTILE.INC(J10:J15,1) | K36: =_xlfn.QUARTILE.INC(K10:K15,1) | L36: =_xlfn.QUARTILE.INC(L10:L15,1) | M36: =_xlfn.QUARTILE.INC(M10:M15,1) | N36: =_xlfn.QUARTILE.INC(N10:N15,1)
B37: Min | G37: =MIN(G10:G15) | H37: =MIN(H10:H15) | I37: =MIN(I10:I15) | J37: =MIN(J10:J15) | K37: =MIN(K10:K15) | L37: =MIN(L10:L15) | M37: =MIN(M10:M15) | N37: =MIN(N10:N15)
B38: n (count) | G38: =COUNT(G10:G15) | H38: =COUNT(H10:H15) | I38: =COUNT(I10:I15) | J38: =COUNT(J10:J15) | K38: =COUNT(K10:K15) | L38: =COUNT(L10:L15) | M38: =COUNT(M10:M15) | N38: =COUNT(N10:N15)
B39: Peer set = AMZN, META, AVGO, ORCL, CRM, AMD (rows 10-15). This block feeds the ImpliedVal tab so that no subject is valued off a peer range containing itself.

Sheet ImpliedVal
B2: ImpliedVal - Trading-Comps Implied Valuation of the 4 DCF Subjects
B3: ($ in millions except per-share; peer multiples = 6 pure-peer stats block on Comps tab)
B4: Method: applies the peer-only 25th / median / 75th percentile of EV/NTM EBITDA, EV/NTM Revenue, and P/NTM E (Comps tab, peer stats block) to each subject's own NTM metrics. EV/EBITDA and EV/Revenue methods bridge EV -> less net debt -> equity value -> per-share. P/E method solves for price directly.
B6: MSFT - Microsoft Corporation
B7: Metric | C7: Low (25th) | D7: Mid (Median) | E7: High (75th) | G7: Notes
B8: NTM Revenue ($mm) | C8: =Inputs!N6 | G8: Green link from Inputs tab.
B9: NTM EBITDA ($mm) | C9: =Inputs!O6
B10: NTM Diluted EPS | C10: =Inputs!P6
B11: Net Debt ($mm) [debt + MI - cash] | C11: =Inputs!H6+Inputs!I6-Inputs!G6
B12: Diluted Shares (mm) | C12: =Inputs!F6
B13: Current Share Price | C13: =Inputs!E6
B15: Applied EV/NTM EBITDA multiple | C15: =Comps!J36 | D15: =Comps!J35 | E15: =Comps!J33
B16: Implied EV ($mm) | C16: =C15*$C$9 | D16: =D15*$C$9 | E16: =E15*$C$9
B17: Less: Net Debt ($mm) | C17: =-$C$11 | D17: =-$C$11 | E17: =-$C$11
B18: Implied Equity Value ($mm) | C18: =C16+C17 | D18: =D16+D17 | E18: =E16+E17
B19: Implied Share Price (EV/EBITDA method) | C19: =C18/$C$12 | D19: =D18/$C$12 | E19: =E18/$C$12
B21: Applied EV/NTM Revenue multiple | C21: =Comps!H36 | D21: =Comps!H35 | E21: =Comps!H33
B22: Implied EV ($mm) | C22: =C21*$C$8 | D22: =D21*$C$8 | E22: =E21*$C$8
B23: Less: Net Debt ($mm) | C23: =-$C$11 | D23: =-$C$11 | E23: =-$C$11
B24: Implied Equity Value ($mm) | C24: =C22+C23 | D24: =D22+D23 | E24: =E22+E23
B25: Implied Share Price (EV/Revenue method) | C25: =C24/$C$12 | D25: =D24/$C$12 | E25: =E24/$C$12
B27: Applied P/NTM E multiple | C27: =Comps!L36 | D27: =Comps!L35 | E27: =Comps!L33
B28: Implied Share Price (P/E method) | C28: =C27*$C$10 | D28: =D27*$C$10 | E28: =E27*$C$10
B30: Memo: Current Share Price | C30: =$C$13 | D30: =$C$13 | E30: =$C$13
B31: Implied Upside/(Downside) vs. Current (EV/EBITDA) | C31: =C19/$C$13-1 | D31: =D19/$C$13-1 | E31: =E19/$C$13-1
B32: Implied Upside/(Downside) vs. Current (EV/Revenue) | C32: =C25/$C$13-1 | D32: =D25/$C$13-1 | E32: =E25/$C$13-1
B33: Implied Upside/(Downside) vs. Current (P/E) | C33: =C28/$C$13-1 | D33: =D28/$C$13-1 | E33: =E28/$C$13-1
B36: NVDA - NVIDIA Corporation
B37: Metric | C37: Low (25th) | D37: Mid (Median) | E37: High (75th) | G37: Notes
B38: NTM Revenue ($mm) | C38: =Inputs!N7 | G38: Green link from Inputs tab.
B39: NTM EBITDA ($mm) | C39: =Inputs!O7
B40: NTM Diluted EPS | C40: =Inputs!P7
B41: Net Debt ($mm) [debt + MI - cash] | C41: =Inputs!H7+Inputs!I7-Inputs!G7
B42: Diluted Shares (mm) | C42: =Inputs!F7
B43: Current Share Price | C43: =Inputs!E7
B45: Applied EV/NTM EBITDA multiple | C45: =Comps!J36 | D45: =Comps!J35 | E45: =Comps!J33
B46: Implied EV ($mm) | C46: =C45*$C$39 | D46: =D45*$C$39 | E46: =E45*$C$39
B47: Less: Net Debt ($mm) | C47: =-$C$41 | D47: =-$C$41 | E47: =-$C$41
B48: Implied Equity Value ($mm) | C48: =C46+C47 | D48: =D46+D47 | E48: =E46+E47
B49: Implied Share Price (EV/EBITDA method) | C49: =C48/$C$42 | D49: =D48/$C$42 | E49: =E48/$C$42
...

Sheet FootballField
B2: Football Field - Valuation Summary (4 DCF-Suite Subjects)
B3: ($ per share; ranges = low/high across the methods below; current price shown as a reference row/marker)
B4: Rows 1-4 per subject are live formulas linking to this workbook's own Inputs/ImpliedVal tabs. Rows 5-6 (DCF range, Precedent Transactions range) are SOURCED BLUE INPUTS transcribed from the completed DCF and Precedent Transactions workbooks per the master-spec convention that bans cross-workbook links (they break on file move). See the note column for exact source/method on each row.
B6: MSFT - Microsoft Corporation (current price = $483.24)
B7: Range | C7: Low | D7: High | G7: Notes | I7: Low (chart spacer) | J7: Range (High-Low, chart)
B8: 52-Week Trading Range | C8: =Inputs!Q6 | D8: =Inputs!R6 | G8: Green link from Inputs tab (52-wk low/high, as of 8/21/26). | I8: =C8 | J8: =D8-C8
B9: Comps - EV / NTM EBITDA (25th-75th) | C9: =ImpliedVal!C19 | D9: =ImpliedVal!E19 | G9: Green link from ImpliedVal tab (25th/75th implied price, EV/EBITDA method). | I9: =C9 | J9: =D9-C9
B10: Comps - P / NTM E (25th-75th) | C10: =ImpliedVal!C28 | D10: =ImpliedVal!E28 | G10: Green link from ImpliedVal tab (25th/75th implied price, P/E method). | I10: =C10 | J10: =D10-C10
B11: Comps - EV / NTM Revenue (25th-75th) | C11: =ImpliedVal!C25 | D11: =ImpliedVal!E25 | G11: Green link from ImpliedVal tab (25th/75th implied price, EV/Revenue method). | I11: =C11 | J11: =D11-C11
B12: DCF Range (Gordon low / Exit-multiple high) | C12: 246.74 | D12: 514.1 | G12: Source: Akul Veauli - DCF Model (Microsoft Corporation).xlsx - Gordon Growth method (low) / Exit Multiple method (high) implied share price. Sourced blue input per master-spec (cross-workbook links banned). | I12: =C12 | J12: =D12-C12
B13: Precedent Transactions (EV/EBITDA 25th-75th) | C13: 475.56 | D13: 961.58 | G13: Source: Akul Veauli - Precedent Transactions.xlsx, ImpliedVal tab (transcribed; per master-spec convention, cross-workbook links are banned). Method = EV/LTM EBITDA applied to subject LTM EBITDA (per this workbook's Inputs tab), using the Precedents core-set (n=10 of 12 deals) 25th-75th pctile multiple range (18.0x-36.6x). Range is wide because the core set's 75th pctile is pulled up by thin-EBITDA outlier deals (Twitter/X ~67.5x, MSFT/Activision ~39.7x); 25th pctile (~18.0x) is anchored by cleaner large-cap software/hardware deals (Broadcom/VMware ~16.8x, Mellanox ~18.4x). Precedent ranges embed a control premium and sit above trading-comps (minority-stake) ranges by construction. | I13: =C13 | J13: =D13-C13
B14: Current Share Price (reference marker) | C14: =Comps!D6
B16: NVDA - NVIDIA Corporation (current price = $214.72)
B17: Range | C17: Low | D17: High | G17: Notes | I17: Low (chart spacer) | J17: Range (High-Low, chart)
B18: 52-Week Trading Range | C18: =Inputs!Q7 | D18: =Inputs!R7 | G18: Green link from Inputs tab (52-wk low/high, as of 8/21/26). | I18: =C18 | J18: =D18-C18
B19: Comps - EV / NTM EBITDA (25th-75th) | C19: =ImpliedVal!C49 | D19: =ImpliedVal!E49 | G19: Green link from ImpliedVal tab (25th/75th implied price, EV/EBITDA method). | I19: =C19 | J19: =D19-C19
B20: Comps - P / NTM E (25th-75th) | C20: =ImpliedVal!C58 | D20: =ImpliedVal!E58 | G20: Green link from ImpliedVal tab (25th/75th implied price, P/E method). | I20: =C20 | J20: =D20-C20
B21: Comps - EV / NTM Revenue (25th-75th) | C21: =ImpliedVal!C55 | D21: =ImpliedVal!E55 | G21: Green link from ImpliedVal tab (25th/75th implied price, EV/Revenue method). | I21: =C21 | J21: =D21-C21
B22: DCF Range (Gordon low / Exit-multiple high) | C22: 96.93 | D22: 179.08 | G22: Source: Akul Veauli - DCF Model (NVIDIA Corporation).xlsx - Gordon Growth method (low) / Exit Multiple method (high) implied share price. Sourced blue input per master-spec (cross-workbook links banned). | I22: =C22 | J22: =D22-C22
B23: Precedent Transactions (EV/EBITDA 25th-75th) | C23: 101.32 | D23: 203.76 | G23: Source: Akul Veauli - Precedent Transactions.xlsx, ImpliedVal tab (transcribed; per master-spec convention, cross-workbook links are banned). Method = EV/LTM EBITDA applied to subject LTM EBITDA (per this workbook's Inputs tab), using the Precedents core-set (n=10 of 12 deals) 25th-75th pctile multiple range (18.0x-36.6x). Range is wide because the core set's 75th pctile is pulled up by thin-EBITDA outlier deals (Twitter/X ~67.5x, MSFT/Activision ~39.7x); 25th pctile (~18.0x) is anchored by cleaner large-cap software/hardware deals (Broadcom/VMware ~16.8x, Mellanox ~18.4x). Precedent ranges embed a control premium and sit above trading-comps (minority-stake) ranges by construction. | I23: =C23 | J23: =D23-C23
B24: Current Share Price (reference marker) | C24: =Comps!D7
B26: AAPL - Apple Inc. (current price = $309.35)
B27: Range | C27: Low | D27: High | G27: Notes | I27: Low (chart spacer) | J27: Range (High-Low, chart)
B28: 52-Week Trading Range | C28: =Inputs!Q8 | D28: =Inputs!R8 | G28: Green link from Inputs tab (52-wk low/high, as of 8/21/26). | I28: =C28 | J28: =D28-C28
B29: Comps - EV / NTM EBITDA (25th-75th) | C29: =ImpliedVal!C79 | D29: =ImpliedVal!E79 | G29: Green link from ImpliedVal tab (25th/75th implied price, EV/EBITDA method). | I29: =C29 | J29: =D29-C29
B30: Comps - P / NTM E (25th-75th) | C30: =ImpliedVal!C88 | D30: =ImpliedVal!E88 | G30: Green link from ImpliedVal tab (25th/75th implied price, P/E method). | I30: =C30 | J30: =D30-C30
B31: Comps - EV / NTM Revenue (25th-75th) | C31: =ImpliedVal!C85 | D31: =ImpliedVal!E85 | G31: Green link from ImpliedVal tab (25th/75th implied price, EV/Revenue method). | I31: =C31 | J31: =D31-C31
B32: DCF Range (Gordon low / Exit-multiple high) | C32: 124.77 | D32: 136.49 | G32: Source: Akul Veauli - DCF Model (Apple Inc.).xlsx - Gordon Growth method (low) / Exit Multiple method (high) implied share price. Sourced blue input per master-spec (cross-workbook links banned). | I32: =C32 | J32: =D32-C32
B33: Precedent Transactions (EV/EBITDA 25th-75th) | C33: 182.08 | D33: 366.57 | G33: Source: Akul Veauli - Precedent Transactions.xlsx, ImpliedVal tab (transcribed; per master-spec convention, cross-workbook links are banned). Method = EV/LTM EBITDA applied to subject LTM EBITDA (per this workbook's Inputs tab), using the Precedents core-set (n=10 of 12 deals) 25th-75th pctile multiple range (18.0x-36.6x). Range is wide because the core set's 75th pctile is pulled up by thin-EBITDA outlier deals (Twitter/X ~67.5x, MSFT/Activision ~39.7x); 25th pctile (~18.0x) is anchored by cleaner large-cap software/hardware deals (Broadcom/VMware ~16.8x, Mellanox ~18.4x). Precedent ranges embed a control premium and sit above trading-comps (minority-stake) ranges by construction. | I33: =C33 | J33: =D33-C33
B34: Current Share Price (reference marker) | C34: =Comps!D8
B36: GOOGL - Alphabet Inc. (current price = $344.82)
B37: Range | C37: Low | D37: High | G37: Notes | I37: Low (chart spacer) | J37: Range (High-Low, chart)
B38: 52-Week Trading Range | C38: =Inputs!Q9 | D38: =Inputs!R9 | G38: Green link from Inputs tab (52-wk low/high, as of 8/21/26). | I38: =C38 | J38: =D38-C38
B39: Comps - EV / NTM EBITDA (25th-75th) | C39: =ImpliedVal!C109 | D39: =ImpliedVal!E109 | G39: Green link from ImpliedVal tab (25th/75th implied price, EV/EBITDA method). | I39: =C39 | J39: =D39-C39
B40: Comps - P / NTM E (25th-75th) | C40: =ImpliedVal!C118 | D40: =ImpliedVal!E118 | G40: Green link from ImpliedVal tab (25th/75th implied price, P/E method). | I40: =C40 | J40: =D40-C40
B41: Comps - EV / NTM Revenue (25th-75th) | C41: =ImpliedVal!C115 | D41: =ImpliedVal!E115 | G41: Green link from ImpliedVal tab (25th/75th implied price, EV/Revenue method). | I41: =C41 | J41: =D41-C41
B42: DCF Range (Gordon low / Exit-multiple high) | C42: 193.21 | D42: 288.64 | G42: Source: Akul Veauli - DCF Model (Alphabet Inc.).xlsx - Gordon Growth method (low) / Exit Multiple method (high) implied share price. Sourced blue input per master-spec (cross-workbook links banned). | I42: =C42 | J42: =D42-C42
B43: Precedent Transactions (EV/EBITDA 25th-75th) | C43: 219.58 | D43: 433.27 | G43: Source: Akul Veauli - Precedent Transactions.xlsx, ImpliedVal tab (transcribed; per master-spec convention, cross-workbook links are banned). Method = EV/LTM EBITDA applied to subject LTM EBITDA (per this workbook's Inputs tab), using the Precedents core-set (n=10 of 12 deals) 25th-75th pctile multiple range (18.0x-36.6x). Range is wide because the core set's 75th pctile is pulled up by thin-EBITDA outlier deals (Twitter/X ~67.5x, MSFT/Activision ~39.7x); 25th pctile (~18.0x) is anchored by cleaner large-cap software/hardware deals (Broadcom/VMware ~16.8x, Mellanox ~18.4x). Precedent ranges embed a control premium and sit above trading-comps (minority-stake) ranges by construction. | I43: =C43 | J43: =D43-C43
B44: Current Share Price (reference marker) | C44: =Comps!D9
B63: Chart note: charts are presentation only, not load-bearing (per spec). The data TABLE (columns B-D, notes in G) is the deliverable; helper columns I-J (hidden) exist only to drive the stacked horizontal bar visualization (invisible 'Low' spacer series + visible 'High-Low' range series). Current price is shown as a bold reference row beneath each table (chart marker line omitted per spec's acceptable fallback).
