Workbook
Name Alpha: Assumptions!$G$24
Name C1: Assumptions!$D$21
Name C2: Assumptions!$D$22
Name C3: Assumptions!$D$23
Name CarryRate: Assumptions!$C$15
Name CheckSize: Assumptions!$C$14
Name CondGood: Assumptions!$C$30
Name CondReturn: Assumptions!$C$29
Name FeeAdj: Assumptions!$C$10
Name FeeRate: Assumptions!$C$8
Name FeeYears: Assumptions!$C$9
Name FundSize: Assumptions!$C$5
Name HurdleRate: Assumptions!$C$16
Name HurdleToggle: Assumptions!$C$17
Name InitialCheck: Assumptions!$C$13
Name InvestableCapital: Assumptions!$C$11
Name MaxMultiple: Assumptions!$C$25
Name MC_GrossMOIC: 'Monte Carlo'!$AB$6:$AB$505
Name MC_NetMOIC: 'Monte Carlo'!$AI$6:$AI$505
Name Mu1: Assumptions!$F$22
Name Mu2: Assumptions!$F$23
Name N_Companies: Assumptions!$C$6
Name OutlierEM: Assumptions!$C$34
Name OutlierEM2: Assumptions!$C$35
Name P_Good: Assumptions!$C$23
Name P_Outlier: Assumptions!$C$24
Name P_Return: Assumptions!$C$22
Name P_Zero: Assumptions!$C$21
Name ReservePool: Assumptions!$C$12
Name ReserveRatio: Assumptions!$C$7
Name Sigma1: Assumptions!$G$22
Name Sigma2: Assumptions!$G$23
Name Xm: Assumptions!$F$24

Sheet Overview
B2: VC FUND MONTE CARLO & PORTFOLIO CONSTRUCTION MODEL
B3: Prepared by Akul Veauli
B5: PURPOSE
B6: Simulate the fund-level MOIC distribution of a seed/Series-A venture fund under stylized power-law company outcomes, and use closed-form portfolio-construction math to solve for an appropriate portfolio size (N) and reserve/check-sizing strategy - i.e., how many bets a fund needs to place, and how big, to reliably capture outlier-driven returns without taking on excessive variance.
B10: METHODOLOGY
B11: Each portfolio company's exit outcome is drawn from a four-bucket mixture (Assumptions tab): a write-off probability, a 'return capital-ish' lognormal bucket, a 'good outcome' lognormal bucket, and an 8% power-law outlier bucket modeled as a Pareto tail (alpha≈1.1) capped at 300x - deliberately fat-tailed so that a small share of trials produce the 50-100x+ outcomes that drive real venture returns. The Single Fund Sim tab shows one fund's mechanics company-by-company; the Monte Carlo tab repeats this 500 times (12,500 company draws) to build an empirical net-MOIC distribution after a 2%×10yr management-fee drag on investable capital and a 20% carry (with an 8% toggleable hurdle). The Portfolio Construction tab then derives, in closed form, how many companies a fund needs to reasonably guarantee landing at least one outlier, how fund MOIC variance (not its mean) scales with N, and an illustrative Kelly-criterion cross-check on check sizing.
B18: KEY RESULTS (live - re-randomizes on every recalculation)
B19: Fund Size | D19: =FundSize -> 60000000
B20: Portfolio Companies (N) | D20: =N_Companies -> 25
B21: Investable Capital | D21: =InvestableCapital -> 48000000
B22: Mean Net MOIC (500 trials) | D22: =Results!$C$6 -> 2.6469918
B23: Median Net MOIC (500 trials) | D23: =Results!$C$7 -> 1.8563701
B24: P(Net MOIC < 1.0x) | D24: =Results!$C$13 -> 0.192
B25: P5 / P95 Net MOIC | D25: =Results!$C$9&" / "&Results!$C$12&"x" -> 0.468179526705523 / 8.32861791466085x
B26: Recommended N range (closed-form) | D26: ='Portfolio Construction'!$C$15&" – "&'Portfolio Construction'!$C$16 -> 28 – 36
B28: Note: RAND()-driven results are NOT seeded. Every recalculation (F9, or opening the file) draws a fresh set of 500 simulated funds and a fresh single-fund illustration - figures above and on the Monte Carlo / Results / Single Fund Sim tabs will fluctuate run to run by design.
B30: LEGEND
B31: Input (edit me) | D31: Formula (live, do not overwrite)
B32: Header | D32: Section banner

Sheet Assumptions
B2: ASSUMPTIONS - VC FUND TERMS & OUTCOME DISTRIBUTION
B4: FUND TERMS
B5: Fund Size ($) | C5: 60000000 | E5: Blue = input. Black = formula. See legend on Overview tab.
B6: Number of Portfolio Companies (N) | C6: 25
B7: Reserve Ratio (follow-on % of investable capital) | C7: 0.5
B8: Annual Management Fee Rate | C8: 0.02
B9: Fee Term (years) | C9: 10
B10: Fee Drag Adjustment Factor (1.0 = full straight-line drag) | C10: 1
B11: Investable Capital ($) = Fund Size × (1 − Fee×Years×Adj) | C11: =C5*(1-C8*C9*C10) -> 48000000
B12: Reserve Pool ($) = Investable Capital × Reserve Ratio | C12: =C11*C7 -> 24000000
B13: Initial Check per Company ($) = Investable × (1−Reserve) / N | C13: =C11*(1-C7)/C6 -> 960000
B14: Total Invested per Company at Full Deployment ($) | C14: =C11/C6 -> 1920000
B15: Carry Rate | C15: 0.2
B16: Hurdle Rate (preferred return, compounded over fee term) | C16: 0.08
B17: Hurdle Toggle (1 = hurdle applies, 0 = American-style straight 20%) | C17: 1
B19: OUTCOME DISTRIBUTION (stylized power-law, per stage bucket)
B20: Bucket | C20: Probability | D20: Cumulative | E20: Multiple Model | F20: Param 1 | G20: Param 2
B21: Zero (write-off) | C21: 0.4 | D21: =C21 -> 0.4 | E21: Fixed 0x | F21: - | G21: -
B22: Return of Capital-ish | C22: 0.3 | D22: =D21+C22 -> 0.7 | E22: Lognormal | F22: 0 | G22: 0.5
B23: Good Outcome | C23: 0.22 | D23: =D22+C23 -> 0.92 | E23: Lognormal | F23: 1.3 | G23: 0.5
B24: Outlier (power-law tail) | C24: 0.08 | D24: =D23+C24 -> 1 | E24: Pareto | F24: 10 | G24: 1.1
B25: Max Multiple Cap (applies to Pareto tail only) | C25: 300
B26: Bucket probabilities/multiples are stylized to be broadly consistent with published VC return-dispersion studies (e.g., Correlation Ventures' analysis of seed/Series-A outcomes, and AngelList portfolio data) - no specific dataset's figures are reproduced; treat as illustrative, not empirical fact.
B28: CONDITIONAL PROBABILITIES (for compact single-cell Monte Carlo formulas)
B29: P(Return | not Zero) = P(Return)/(1−P(Zero)) | C29: =C22/(1-C21) -> 0.5
B30: P(Good | not Zero, not Return) = P(Good)/(1−P(Zero)−P(Return)) | C30: =C23/(1-C21-C22) -> 0.73333333
B31: These convert the cumulative bucket structure into nested independent RAND() draws, used where a single compact formula (no helper column) is required - see Monte Carlo tab.
B33: OUTLIER BUCKET - CAPPED MOMENTS (numerical, alpha=1.1 < 2 ⇒ divergent raw variance)
B34: Outlier E[M] - capped Pareto mean (numerically integrated) | C34: 38.83149
B35: Outlier E[M²] - capped Pareto 2nd moment (numerically integrated) | C35: 4622.3451
B36: Because alpha=1.1 is below 2, the *uncapped* Pareto distribution has an infinite raw second moment (and its variance is likewise undefined). The 300x cap makes the moments finite; the two values above are computed by numerically integrating E[min(X,M)] and E[min(X,M)^2] for X~Pareto(xm=10, alpha=1.1) at cap M=300, then entered here as input constants (blue) for use in the closed-form Portfolio Construction tab.

Sheet Single Fund Sim
B2: SINGLE FUND SIMULATION - ONE FUND, COMPANY-BY-COMPANY MECHANICS
B3: Press F9 to re-randomize this fund. Each row is one portfolio company; RAND() draws are live and non-seeded.
B5: Company # | C5: Check Size ($) | D5: RAND() Draw | E5: Outcome Bucket | F5: Exit Multiple | G5: Proceeds ($)
B6: 1 | C6: =CheckSize -> 1920000 | D6: =RAND() -> 0.022915082 | E6: =IF(D6<Assumptions!$D$21,"Zero",IF(D6<Assumptions!$D$22,"Return Capital",IF(D6<Assumptions!$D$23,"Good","Outlier"))) -> Zero | F6: =IF(E6="Zero",0,IF(E6="Return Capital",_xlfn.LOGNORM.INV(RAND(),MV2,Sigma1),IF(E6="Good",_xlfn.LOGNORM.INV(RAND(),MV3,Sigma2),MIN(MaxMultiple,Xm/(1-RAND())^(1/Alpha))))) -> 0 | G6: =C6*F6 -> 0
B7: 2 | C7: =CheckSize -> 1920000 | D7: =RAND() -> 0.87510859 | E7: =IF(D7<Assumptions!$D$21,"Zero",IF(D7<Assumptions!$D$22,"Return Capital",IF(D7<Assumptions!$D$23,"Good","Outlier"))) -> Good | F7: =IF(E7="Zero",0,IF(E7="Return Capital",_xlfn.LOGNORM.INV(RAND(),MV2,Sigma1),IF(E7="Good",_xlfn.LOGNORM.INV(RAND(),MV3,Sigma2),MIN(MaxMultiple,Xm/(1-RAND())^(1/Alpha))))) -> 0.62143872 | G7: =C7*F7 -> 1193162.3
B8: 3 | C8: =CheckSize -> 1920000 | D8: =RAND() -> 0.51629581 | E8: =IF(D8<Assumptions!$D$21,"Zero",IF(D8<Assumptions!$D$22,"Return Capital",IF(D8<Assumptions!$D$23,"Good","Outlier"))) -> Return Capital | F8: =IF(E8="Zero",0,IF(E8="Return Capital",_xlfn.LOGNORM.INV(RAND(),MV2,Sigma1),IF(E8="Good",_xlfn.LOGNORM.INV(RAND(),MV3,Sigma2),MIN(MaxMultiple,Xm/(1-RAND())^(1/Alpha))))) -> 1.5285873 | G8: =C8*F8 -> 2934887.6
B9: 4 | C9: =CheckSize -> 1920000 | D9: =RAND() -> 0.15094128 | E9: =IF(D9<Assumptions!$D$21,"Zero",IF(D9<Assumptions!$D$22,"Return Capital",IF(D9<Assumptions!$D$23,"Good","Outlier"))) -> Zero | F9: =IF(E9="Zero",0,IF(E9="Return Capital",_xlfn.LOGNORM.INV(RAND(),MV2,Sigma1),IF(E9="Good",_xlfn.LOGNORM.INV(RAND(),MV3,Sigma2),MIN(MaxMultiple,Xm/(1-RAND())^(1/Alpha))))) -> 0 | G9: =C9*F9 -> 0
B10: 5 | C10: =CheckSize -> 1920000 | D10: =RAND() -> 0.41040435 | E10: =IF(D10<Assumptions!$D$21,"Zero",IF(D10<Assumptions!$D$22,"Return Capital",IF(D10<Assumptions!$D$23,"Good","Outlier"))) -> Return Capital | F10: =IF(E10="Zero",0,IF(E10="Return Capital",_xlfn.LOGNORM.INV(RAND(),MV2,Sigma1),IF(E10="Good",_xlfn.LOGNORM.INV(RAND(),MV3,Sigma2),MIN(MaxMultiple,Xm/(1-RAND())^(1/Alpha))))) -> 0.54226445 | G10: =C10*F10 -> 1041147.7
B11: 6 | C11: =CheckSize -> 1920000 | D11: =RAND() -> 0.074017059 | E11: =IF(D11<Assumptions!$D$21,"Zero",IF(D11<Assumptions!$D$22,"Return Capital",IF(D11<Assumptions!$D$23,"Good","Outlier"))) -> Zero | F11: =IF(E11="Zero",0,IF(E11="Return Capital",_xlfn.LOGNORM.INV(RAND(),MV2,Sigma1),IF(E11="Good",_xlfn.LOGNORM.INV(RAND(),MV3,Sigma2),MIN(MaxMultiple,Xm/(1-RAND())^(1/Alpha))))) -> 0 | G11: =C11*F11 -> 0
B12: 7 | C12: =CheckSize -> 1920000 | D12: =RAND() -> 0.87005154 | E12: =IF(D12<Assumptions!$D$21,"Zero",IF(D12<Assumptions!$D$22,"Return Capital",IF(D12<Assumptions!$D$23,"Good","Outlier"))) -> Good | F12: =IF(E12="Zero",0,IF(E12="Return Capital",_xlfn.LOGNORM.INV(RAND(),MV2,Sigma1),IF(E12="Good",_xlfn.LOGNORM.INV(RAND(),MV3,Sigma2),MIN(MaxMultiple,Xm/(1-RAND())^(1/Alpha))))) -> 0.52907652 | G12: =C12*F12 -> 1015826.9
B13: 8 | C13: =CheckSize -> 1920000 | D13: =RAND() -> 0.06632847 | E13: =IF(D13<Assumptions!$D$21,"Zero",IF(D13<Assumptions!$D$22,"Return Capital",IF(D13<Assumptions!$D$23,"Good","Outlier"))) -> Zero | F13: =IF(E13="Zero",0,IF(E13="Return Capital",_xlfn.LOGNORM.INV(RAND(),MV2,Sigma1),IF(E13="Good",_xlfn.LOGNORM.INV(RAND(),MV3,Sigma2),MIN(MaxMultiple,Xm/(1-RAND())^(1/Alpha))))) -> 0 | G13: =C13*F13 -> 0
B14: 9 | C14: =CheckSize -> 1920000 | D14: =RAND() -> 0.40087459 | E14: =IF(D14<Assumptions!$D$21,"Zero",IF(D14<Assumptions!$D$22,"Return Capital",IF(D14<Assumptions!$D$23,"Good","Outlier"))) -> Return Capital | F14: =IF(E14="Zero",0,IF(E14="Return Capital",_xlfn.LOGNORM.INV(RAND(),MV2,Sigma1),IF(E14="Good",_xlfn.LOGNORM.INV(RAND(),MV3,Sigma2),MIN(MaxMultiple,Xm/(1-RAND())^(1/Alpha))))) -> 0.83255863 | G14: =C14*F14 -> 1598512.6
B15: 10 | C15: =CheckSize -> 1920000 | D15: =RAND() -> 0.15350217 | E15: =IF(D15<Assumptions!$D$21,"Zero",IF(D15<Assumptions!$D$22,"Return Capital",IF(D15<Assumptions!$D$23,"Good","Outlier"))) -> Zero | F15: =IF(E15="Zero",0,IF(E15="Return Capital",_xlfn.LOGNORM.INV(RAND(),MV2,Sigma1),IF(E15="Good",_xlfn.LOGNORM.INV(RAND(),MV3,Sigma2),MIN(MaxMultiple,Xm/(1-RAND())^(1/Alpha))))) -> 0 | G15: =C15*F15 -> 0
B16: 11 | C16: =CheckSize -> 1920000 | D16: =RAND() -> 0.75336676 | E16: =IF(D16<Assumptions!$D$21,"Zero",IF(D16<Assumptions!$D$22,"Return Capital",IF(D16<Assumptions!$D$23,"Good","Outlier"))) -> Good | F16: =IF(E16="Zero",0,IF(E16="Return Capital",_xlfn.LOGNORM.INV(RAND(),MV2,Sigma1),IF(E16="Good",_xlfn.LOGNORM.INV(RAND(),MV3,Sigma2),MIN(MaxMultiple,Xm/(1-RAND())^(1/Alpha))))) -> 2.9853605 | G16: =C16*F16 -> 5731892.2
B17: 12 | C17: =CheckSize -> 1920000 | D17: =RAND() -> 0.53327729 | E17: =IF(D17<Assumptions!$D$21,"Zero",IF(D17<Assumptions!$D$22,"Return Capital",IF(D17<Assumptions!$D$23,"Good","Outlier"))) -> Return Capital | F17: =IF(E17="Zero",0,IF(E17="Return Capital",_xlfn.LOGNORM.INV(RAND(),MV2,Sigma1),IF(E17="Good",_xlfn.LOGNORM.INV(RAND(),MV3,Sigma2),MIN(MaxMultiple,Xm/(1-RAND())^(1/Alpha))))) -> 1.2952869 | G17: =C17*F17 -> 2486950.9
B18: 13 | C18: =CheckSize -> 1920000 | D18: =RAND() -> 0.44886546 | E18: =IF(D18<Assumptions!$D$21,"Zero",IF(D18<Assumptions!$D$22,"Return Capital",IF(D18<Assumptions!$D$23,"Good","Outlier"))) -> Return Capital | F18: =IF(E18="Zero",0,IF(E18="Return Capital",_xlfn.LOGNORM.INV(RAND(),MV2,Sigma1),IF(E18="Good",_xlfn.LOGNORM.INV(RAND(),MV3,Sigma2),MIN(MaxMultiple,Xm/(1-RAND())^(1/Alpha))))) -> 2.3302572 | G18: =C18*F18 -> 4474093.9
B19: 14 | C19: =CheckSize -> 1920000 | D19: =RAND() -> 0.50272475 | E19: =IF(D19<Assumptions!$D$21,"Zero",IF(D19<Assumptions!$D$22,"Return Capital",IF(D19<Assumptions!$D$23,"Good","Outlier"))) -> Return Capital | F19: =IF(E19="Zero",0,IF(E19="Return Capital",_xlfn.LOGNORM.INV(RAND(),MV2,Sigma1),IF(E19="Good",_xlfn.LOGNORM.INV(RAND(),MV3,Sigma2),MIN(MaxMultiple,Xm/(1-RAND())^(1/Alpha))))) -> 0.53088034 | G19: =C19*F19 -> 1019290.2
B20: 15 | C20: =CheckSize -> 1920000 | D20: =RAND() -> 0.24428027 | E20: =IF(D20<Assumptions!$D$21,"Zero",IF(D20<Assumptions!$D$22,"Return Capital",IF(D20<Assumptions!$D$23,"Good","Outlier"))) -> Zero | F20: =IF(E20="Zero",0,IF(E20="Return Capital",_xlfn.LOGNORM.INV(RAND(),MV2,Sigma1),IF(E20="Good",_xlfn.LOGNORM.INV(RAND(),MV3,Sigma2),MIN(MaxMultiple,Xm/(1-RAND())^(1/Alpha))))) -> 0 | G20: =C20*F20 -> 0
B21: 16 | C21: =CheckSize -> 1920000 | D21: =RAND() -> 0.056275045 | E21: =IF(D21<Assumptions!$D$21,"Zero",IF(D21<Assumptions!$D$22,"Return Capital",IF(D21<Assumptions!$D$23,"Good","Outlier"))) -> Zero | F21: =IF(E21="Zero",0,IF(E21="Return Capital",_xlfn.LOGNORM.INV(RAND(),MV2,Sigma1),IF(E21="Good",_xlfn.LOGNORM.INV(RAND(),MV3,Sigma2),MIN(MaxMultiple,Xm/(1-RAND())^(1/Alpha))))) -> 0 | G21: =C21*F21 -> 0
B22: 17 | C22: =CheckSize -> 1920000 | D22: =RAND() -> 0.73163001 | E22: =IF(D22<Assumptions!$D$21,"Zero",IF(D22<Assumptions!$D$22,"Return Capital",IF(D22<Assumptions!$D$23,"Good","Outlier"))) -> Good | F22: =IF(E22="Zero",0,IF(E22="Return Capital",_xlfn.LOGNORM.INV(RAND(),MV2,Sigma1),IF(E22="Good",_xlfn.LOGNORM.INV(RAND(),MV3,Sigma2),MIN(MaxMultiple,Xm/(1-RAND())^(1/Alpha))))) -> 0.47773563 | G22: =C22*F22 -> 917252.42
B23: 18 | C23: =CheckSize -> 1920000 | D23: =RAND() -> 0.53076098 | E23: =IF(D23<Assumptions!$D$21,"Zero",IF(D23<Assumptions!$D$22,"Return Capital",IF(D23<Assumptions!$D$23,"Good","Outlier"))) -> Return Capital | F23: =IF(E23="Zero",0,IF(E23="Return Capital",_xlfn.LOGNORM.INV(RAND(),MV2,Sigma1),IF(E23="Good",_xlfn.LOGNORM.INV(RAND(),MV3,Sigma2),MIN(MaxMultiple,Xm/(1-RAND())^(1/Alpha))))) -> 0.87114083 | G23: =C23*F23 -> 1672590.4
B24: 19 | C24: =CheckSize -> 1920000 | D24: =RAND() -> 0.61642503 | E24: =IF(D24<Assumptions!$D$21,"Zero",IF(D24<Assumptions!$D$22,"Return Capital",IF(D24<Assumptions!$D$23,"Good","Outlier"))) -> Return Capital | F24: =IF(E24="Zero",0,IF(E24="Return Capital",_xlfn.LOGNORM.INV(RAND(),MV2,Sigma1),IF(E24="Good",_xlfn.LOGNORM.INV(RAND(),MV3,Sigma2),MIN(MaxMultiple,Xm/(1-RAND())^(1/Alpha))))) -> 0.46949686 | G24: =C24*F24 -> 901433.97
B25: 20 | C25: =CheckSize -> 1920000 | D25: =RAND() -> 0.44088034 | E25: =IF(D25<Assumptions!$D$21,"Zero",IF(D25<Assumptions!$D$22,"Return Capital",IF(D25<Assumptions!$D$23,"Good","Outlier"))) -> Return Capital | F25: =IF(E25="Zero",0,IF(E25="Return Capital",_xlfn.LOGNORM.INV(RAND(),MV2,Sigma1),IF(E25="Good",_xlfn.LOGNORM.INV(RAND(),MV3,Sigma2),MIN(MaxMultiple,Xm/(1-RAND())^(1/Alpha))))) -> 1.191138 | G25: =C25*F25 -> 2286985
B26: 21 | C26: =CheckSize -> 1920000 | D26: =RAND() -> 0.14005457 | E26: =IF(D26<Assumptions!$D$21,"Zero",IF(D26<Assumptions!$D$22,"Return Capital",IF(D26<Assumptions!$D$23,"Good","Outlier"))) -> Zero | F26: =IF(E26="Zero",0,IF(E26="Return Capital",_xlfn.LOGNORM.INV(RAND(),MV2,Sigma1),IF(E26="Good",_xlfn.LOGNORM.INV(RAND(),MV3,Sigma2),MIN(MaxMultiple,Xm/(1-RAND())^(1/Alpha))))) -> 0 | G26: =C26*F26 -> 0
B27: 22 | C27: =CheckSize -> 1920000 | D27: =RAND() -> 0.65858015 | E27: =IF(D27<Assumptions!$D$21,"Zero",IF(D27<Assumptions!$D$22,"Return Capital",IF(D27<Assumptions!$D$23,"Good","Outlier"))) -> Return Capital | F27: =IF(E27="Zero",0,IF(E27="Return Capital",_xlfn.LOGNORM.INV(RAND(),MV2,Sigma1),IF(E27="Good",_xlfn.LOGNORM.INV(RAND(),MV3,Sigma2),MIN(MaxMultiple,Xm/(1-RAND())^(1/Alpha))))) -> 2.4695626 | G27: =C27*F27 -> 4741560.2
B28: 23 | C28: =CheckSize -> 1920000 | D28: =RAND() -> 0.052060985 | E28: =IF(D28<Assumptions!$D$21,"Zero",IF(D28<Assumptions!$D$22,"Return Capital",IF(D28<Assumptions!$D$23,"Good","Outlier"))) -> Zero | F28: =IF(E28="Zero",0,IF(E28="Return Capital",_xlfn.LOGNORM.INV(RAND(),MV2,Sigma1),IF(E28="Good",_xlfn.LOGNORM.INV(RAND(),MV3,Sigma2),MIN(MaxMultiple,Xm/(1-RAND())^(1/Alpha))))) -> 0 | G28: =C28*F28 -> 0
B29: 24 | C29: =CheckSize -> 1920000 | D29: =RAND() -> 0.54068001 | E29: =IF(D29<Assumptions!$D$21,"Zero",IF(D29<Assumptions!$D$22,"Return Capital",IF(D29<Assumptions!$D$23,"Good","Outlier"))) -> Return Capital | F29: =IF(E29="Zero",0,IF(E29="Return Capital",_xlfn.LOGNORM.INV(RAND(),MV2,Sigma1),IF(E29="Good",_xlfn.LOGNORM.INV(RAND(),MV3,Sigma2),MIN(MaxMultiple,Xm/(1-RAND())^(1/Alpha))))) -> 0.35826976 | G29: =C29*F29 -> 687877.93
B30: 25 | C30: =CheckSize -> 1920000 | D30: =RAND() -> 0.44559464 | E30: =IF(D30<Assumptions!$D$21,"Zero",IF(D30<Assumptions!$D$22,"Return Capital",IF(D30<Assumptions!$D$23,"Good","Outlier"))) -> Return Capital | F30: =IF(E30="Zero",0,IF(E30="Return Capital",_xlfn.LOGNORM.INV(RAND(),MV2,Sigma1),IF(E30="Good",_xlfn.LOGNORM.INV(RAND(),MV3,Sigma2),MIN(MaxMultiple,Xm/(1-RAND())^(1/Alpha))))) -> 0.63881191 | G30: =C30*F30 -> 1226518.9
B32: FUND TOTALS
B33: Gross Proceeds ($) | C33: =SUM(G6:G30) -> 33929983
B34: Investable Capital ($) | C34: =InvestableCapital -> 48000000
B35: Gross MOIC (on invested capital) | C35: =C33/C34 -> 0.70687465
B36: Profit ($) = Gross Proceeds − Investable Capital | C36: =C33-C34 -> -14070017
B37: Hurdle Amount ($) = Toggle × Investable × ((1+Hurdle)^Years − 1) | C37: =HurdleToggle*C34*((1+HurdleRate)^FeeYears-1) -> 55628400
B38: Carry Base ($) = MAX(0, Profit − Hurdle Amount) | C38: =MAX(0,C36-C37) -> 0
B39: GP Carry ($) = 20% × Carry Base | C39: =CarryRate*C38 -> 0
B40: Net Proceeds to LPs ($) | C40: =C33-C39 -> 33929983
B41: Net MOIC to LPs (on Fund Size) | C41: =C40/FundSize -> 0.56549972

Sheet Monte Carlo
B2: MONTE CARLO - 500 SIMULATED FUNDS (25 COMPANIES EACH, INLINE)
B3: Each row = one independently simulated fund. Each of the 25 company columns is ONE compact formula returning proceeds-per-$1-invested (the exit multiple), using nested independent RAND() draws calibrated to the bucket probabilities in Assumptions. Recalculates (F9) live - 12,500 formula cells total.
B5: Trial # | C5: Co.1 | D5: Co.2 | E5: Co.3 | F5: Co.4 | G5: Co.5 | H5: Co.6 | I5: Co.7 | J5: Co.8 | K5: Co.9 | L5: Co.10 | M5: Co.11 | N5: Co.12 | O5: Co.13 | P5: Co.14 | Q5: Co.15 | R5: Co.16 | S5: Co.17 | T5: Co.18 | U5: Co.19 | V5: Co.20 | W5: Co.21 | X5: Co.22 | Y5: Co.23 | Z5: Co.24 | AA5: Co.25 | AB5: Gross MOIC | AC5: Gross Proceeds | AD5: Profit | AE5: Hurdle Amt | AF5: Carry Base | AG5: GP Carry | AH5: Net Proceeds | AI5: Net MOIC
B6: 1 | C6: =IF(RAND()<P_Zero,0,IF(RAND()<CondReturn,_xlfn.LOGNORM.INV(RAND(),MV2,Sigma1),IF(RAND()<CondGood,_xlfn.LOGNORM.INV(RAND(),MV3,Sigma2),MIN(MaxMultiple,Xm/(1-RAND())^(1/Alpha))))) -> 0 | D6: =IF(RAND()<P_Zero,0,IF(RAND()<CondReturn,_xlfn.LOGNORM.INV(RAND(),MV2,Sigma1),IF(RAND()<CondGood,_xlfn.LOGNORM.INV(RAND(),MV3,Sigma2),MIN(MaxMultiple,Xm/(1-RAND())^(1/Alpha))))) -> 2.3706426 | E6: =IF(RAND()<P_Zero,0,IF(RAND()<CondReturn,_xlfn.LOGNORM.INV(RAND(),MV2,Sigma1),IF(RAND()<CondGood,_xlfn.LOGNORM.INV(RAND(),MV3,Sigma2),MIN(MaxMultiple,Xm/(1-RAND())^(1/Alpha))))) -> 0 | F6: =IF(RAND()<P_Zero,0,IF(RAND()<CondReturn,_xlfn.LOGNORM.INV(RAND(),MV2,Sigma1),IF(RAND()<CondGood,_xlfn.LOGNORM.INV(RAND(),MV3,Sigma2),MIN(MaxMultiple,Xm/(1-RAND())^(1/Alpha))))) -> 0 | G6: =IF(RAND()<P_Zero,0,IF(RAND()<CondReturn,_xlfn.LOGNORM.INV(RAND(),MV2,Sigma1),IF(RAND()<CondGood,_xlfn.LOGNORM.INV(RAND(),MV3,Sigma2),MIN(MaxMultiple,Xm/(1-RAND())^(1/Alpha))))) -> 0 | H6: =IF(RAND()<P_Zero,0,IF(RAND()<CondReturn,_xlfn.LOGNORM.INV(RAND(),MV2,Sigma1),IF(RAND()<CondGood,_xlfn.LOGNORM.INV(RAND(),MV3,Sigma2),MIN(MaxMultiple,Xm/(1-RAND())^(1/Alpha))))) -> 0 | I6: =IF(RAND()<P_Zero,0,IF(RAND()<CondReturn,_xlfn.LOGNORM.INV(RAND(),MV2,Sigma1),IF(RAND()<CondGood,_xlfn.LOGNORM.INV(RAND(),MV3,Sigma2),MIN(MaxMultiple,Xm/(1-RAND())^(1/Alpha))))) -> 0.86419459 | J6: =IF(RAND()<P_Zero,0,IF(RAND()<CondReturn,_xlfn.LOGNORM.INV(RAND(),MV2,Sigma1),IF(RAND()<CondGood,_xlfn.LOGNORM.INV(RAND(),MV3,Sigma2),MIN(MaxMultiple,Xm/(1-RAND())^(1/Alpha))))) -> 0 | K6: =IF(RAND()<P_Zero,0,IF(RAND()<CondReturn,_xlfn.LOGNORM.INV(RAND(),MV2,Sigma1),IF(RAND()<CondGood,_xlfn.LOGNORM.INV(RAND(),MV3,Sigma2),MIN(MaxMultiple,Xm/(1-RAND())^(1/Alpha))))) -> 0.71190435 | L6: =IF(RAND()<P_Zero,0,IF(RAND()<CondReturn,_xlfn.LOGNORM.INV(RAND(),MV2,Sigma1),IF(RAND()<CondGood,_xlfn.LOGNORM.INV(RAND(),MV3,Sigma2),MIN(MaxMultiple,Xm/(1-RAND())^(1/Alpha))))) -> 1.5978971 | M6: =IF(RAND()<P_Zero,0,IF(RAND()<CondReturn,_xlfn.LOGNORM.INV(RAND(),MV2,Sigma1),IF(RAND()<CondGood,_xlfn.LOGNORM.INV(RAND(),MV3,Sigma2),MIN(MaxMultiple,Xm/(1-RAND())^(1/Alpha))))) -> 1.2087929 | N6: =IF(RAND()<P_Zero,0,IF(RAND()<CondReturn,_xlfn.LOGNORM.INV(RAND(),MV2,Sigma1),IF(RAND()<CondGood,_xlfn.LOGNORM.INV(RAND(),MV3,Sigma2),MIN(MaxMultiple,Xm/(1-RAND())^(1/Alpha))))) -> 1.1222729 | O6: =IF(RAND()<P_Zero,0,IF(RAND()<CondReturn,_xlfn.LOGNORM.INV(RAND(),MV2,Sigma1),IF(RAND()<CondGood,_xlfn.LOGNORM.INV(RAND(),MV3,Sigma2),MIN(MaxMultiple,Xm/(1-RAND())^(1/Alpha))))) -> 23.133995 | P6: =IF(RAND()<P_Zero,0,IF(RAND()<CondReturn,_xlfn.LOGNORM.INV(RAND(),MV2,Sigma1),IF(RAND()<CondGood,_xlfn.LOGNORM.INV(RAND(),MV3,Sigma2),MIN(MaxMultiple,Xm/(1-RAND())^(1/Alpha))))) -> 0.86534651 | Q6: =IF(RAND()<P_Zero,0,IF(RAND()<CondReturn,_xlfn.LOGNORM.INV(RAND(),MV2,Sigma1),IF(RAND()<CondGood,_xlfn.LOGNORM.INV(RAND(),MV3,Sigma2),MIN(MaxMultiple,Xm/(1-RAND())^(1/Alpha))))) -> 22.615605 | R6: =IF(RAND()<P_Zero,0,IF(RAND()<CondReturn,_xlfn.LOGNORM.INV(RAND(),MV2,Sigma1),IF(RAND()<CondGood,_xlfn.LOGNORM.INV(RAND(),MV3,Sigma2),MIN(MaxMultiple,Xm/(1-RAND())^(1/Alpha))))) -> 0 | S6: =IF(RAND()<P_Zero,0,IF(RAND()<CondReturn,_xlfn.LOGNORM.INV(RAND(),MV2,Sigma1),IF(RAND()<CondGood,_xlfn.LOGNORM.INV(RAND(),MV3,Sigma2),MIN(MaxMultiple,Xm/(1-RAND())^(1/Alpha))))) -> 1.1034049 | T6: =IF(RAND()<P_Zero,0,IF(RAND()<CondReturn,_xlfn.LOGNORM.INV(RAND(),MV2,Sigma1),IF(RAND()<CondGood,_xlfn.LOGNORM.INV(RAND(),MV3,Sigma2),MIN(MaxMultiple,Xm/(1-RAND())^(1/Alpha))))) -> 0.49597041 | U6: =IF(RAND()<P_Zero,0,IF(RAND()<CondReturn,_xlfn.LOGNORM.INV(RAND(),MV2,Sigma1),IF(RAND()<CondGood,_xlfn.LOGNORM.INV(RAND(),MV3,Sigma2),MIN(MaxMultiple,Xm/(1-RAND())^(1/Alpha))))) -> 1.0287368 | V6: =IF(RAND()<P_Zero,0,IF(RAND()<CondReturn,_xlfn.LOGNORM.INV(RAND(),MV2,Sigma1),IF(RAND()<CondGood,_xlfn.LOGNORM.INV(RAND(),MV3,Sigma2),MIN(MaxMultiple,Xm/(1-RAND())^(1/Alpha))))) -> 0 | W6: =IF(RAND()<P_Zero,0,IF(RAND()<CondReturn,_xlfn.LOGNORM.INV(RAND(),MV2,Sigma1),IF(RAND()<CondGood,_xlfn.LOGNORM.INV(RAND(),MV3,Sigma2),MIN(MaxMultiple,Xm/(1-RAND())^(1/Alpha))))) -> 0.89121852 | X6: =IF(RAND()<P_Zero,0,IF(RAND()<CondReturn,_xlfn.LOGNORM.INV(RAND(),MV2,Sigma1),IF(RAND()<CondGood,_xlfn.LOGNORM.INV(RAND(),MV3,Sigma2),MIN(MaxMultiple,Xm/(1-RAND())^(1/Alpha))))) -> 0.7288076 | Y6: =IF(RAND()<P_Zero,0,IF(RAND()<CondReturn,_xlfn.LOGNORM.INV(RAND(),MV2,Sigma1),IF(RAND()<CondGood,_xlfn.LOGNORM.INV(RAND(),MV3,Sigma2),MIN(MaxMultiple,Xm/(1-RAND())^(1/Alpha))))) -> 0 | Z6: =IF(RAND()<P_Zero,0,IF(RAND()<CondReturn,_xlfn.LOGNORM.INV(RAND(),MV2,Sigma1),IF(RAND()<CondGood,_xlfn.LOGNORM.INV(RAND(),MV3,Sigma2),MIN(MaxMultiple,Xm/(1-RAND())^(1/Alpha))))) -> 0.97652723 | AA6: =IF(RAND()<P_Zero,0,IF(RAND()<CondReturn,_xlfn.LOGNORM.INV(RAND(),MV2,Sigma1),IF(RAND()<CondGood,_xlfn.LOGNORM.INV(RAND(),MV3,Sigma2),MIN(MaxMultiple,Xm/(1-RAND())^(1/Alpha))))) -> 18.537949 | AB6: =AVERAGE(C6:AA6) -> 3.1301306 | AC6: =AB6*InvestableCapital -> 1.5024627e+08 | AD6: =AC6-InvestableCapital -> 1.0224627e+08 | AE6: =HurdleToggle*InvestableCapital*((1+HurdleRate)^FeeYears-1) -> 55628400 | AF6: =MAX(0,AD6-AE6) -> 46617869 | AG6: =CarryRate*AF6 -> 9323573.8 | AH6: =AC6-AG6 -> 1.409227e+08 | AI6: =AH6/FundSize -> 2.3487116
B7: 2 | C7: =IF(RAND()<P_Zero,0,IF(RAND()<CondReturn,_xlfn.LOGNORM.INV(RAND(),MV2,Sigma1),IF(RAND()<CondGood,_xlfn.LOGNORM.INV(RAND(),MV3,Sigma2),MIN(MaxMultiple,Xm/(1-RAND())^(1/Alpha))))) -> 1.148446 | D7: =IF(RAND()<P_Zero,0,IF(RAND()<CondReturn,_xlfn.LOGNORM.INV(RAND(),MV2,Sigma1),IF(RAND()<CondGood,_xlfn.LOGNORM.INV(RAND(),MV3,Sigma2),MIN(MaxMultiple,Xm/(1-RAND())^(1/Alpha))))) -> 0.69132586 | E7: =IF(RAND()<P_Zero,0,IF(RAND()<CondReturn,_xlfn.LOGNORM.INV(RAND(),MV2,Sigma1),IF(RAND()<CondGood,_xlfn.LOGNORM.INV(RAND(),MV3,Sigma2),MIN(MaxMultiple,Xm/(1-RAND())^(1/Alpha))))) -> 1.5908165 | F7: =IF(RAND()<P_Zero,0,IF(RAND()<CondReturn,_xlfn.LOGNORM.INV(RAND(),MV2,Sigma1),IF(RAND()<CondGood,_xlfn.LOGNORM.INV(RAND(),MV3,Sigma2),MIN(MaxMultiple,Xm/(1-RAND())^(1/Alpha))))) -> 0.45060673 | G7: =IF(RAND()<P_Zero,0,IF(RAND()<CondReturn,_xlfn.LOGNORM.INV(RAND(),MV2,Sigma1),IF(RAND()<CondGood,_xlfn.LOGNORM.INV(RAND(),MV3,Sigma2),MIN(MaxMultiple,Xm/(1-RAND())^(1/Alpha))))) -> 1.3055467 | H7: =IF(RAND()<P_Zero,0,IF(RAND()<CondReturn,_xlfn.LOGNORM.INV(RAND(),MV2,Sigma1),IF(RAND()<CondGood,_xlfn.LOGNORM.INV(RAND(),MV3,Sigma2),MIN(MaxMultiple,Xm/(1-RAND())^(1/Alpha))))) -> 0 | I7: =IF(RAND()<P_Zero,0,IF(RAND()<CondReturn,_xlfn.LOGNORM.INV(RAND(),MV2,Sigma1),IF(RAND()<CondGood,_xlfn.LOGNORM.INV(RAND(),MV3,Sigma2),MIN(MaxMultiple,Xm/(1-RAND())^(1/Alpha))))) -> 0.90531197 | J7: =IF(RAND()<P_Zero,0,IF(RAND()<CondReturn,_xlfn.LOGNORM.INV(RAND(),MV2,Sigma1),IF(RAND()<CondGood,_xlfn.LOGNORM.INV(RAND(),MV3,Sigma2),MIN(MaxMultiple,Xm/(1-RAND())^(1/Alpha))))) -> 0 | K7: =IF(RAND()<P_Zero,0,IF(RAND()<CondReturn,_xlfn.LOGNORM.INV(RAND(),MV2,Sigma1),IF(RAND()<CondGood,_xlfn.LOGNORM.INV(RAND(),MV3,Sigma2),MIN(MaxMultiple,Xm/(1-RAND())^(1/Alpha))))) -> 0 | L7: =IF(RAND()<P_Zero,0,IF(RAND()<CondReturn,_xlfn.LOGNORM.INV(RAND(),MV2,Sigma1),IF(RAND()<CondGood,_xlfn.LOGNORM.INV(RAND(),MV3,Sigma2),MIN(MaxMultiple,Xm/(1-RAND())^(1/Alpha))))) -> 0.27972218 | M7: =IF(RAND()<P_Zero,0,IF(RAND()<CondReturn,_xlfn.LOGNORM.INV(RAND(),MV2,Sigma1),IF(RAND()<CondGood,_xlfn.LOGNORM.INV(RAND(),MV3,Sigma2),MIN(MaxMultiple,Xm/(1-RAND())^(1/Alpha))))) -> 2.7220785 | N7: =IF(RAND()<P_Zero,0,IF(RAND()<CondReturn,_xlfn.LOGNORM.INV(RAND(),MV2,Sigma1),IF(RAND()<CondGood,_xlfn.LOGNORM.INV(RAND(),MV3,Sigma2),MIN(MaxMultiple,Xm/(1-RAND())^(1/Alpha))))) -> 0 | O7: =IF(RAND()<P_Zero,0,IF(RAND()<CondReturn,_xlfn.LOGNORM.INV(RAND(),MV2,Sigma1),IF(RAND()<CondGood,_xlfn.LOGNORM.INV(RAND(),MV3,Sigma2),MIN(MaxMultiple,Xm/(1-RAND())^(1/Alpha))))) -> 1.3712503 | P7: =IF(RAND()<P_Zero,0,IF(RAND()<CondReturn,_xlfn.LOGNORM.INV(RAND(),MV2,Sigma1),IF(RAND()<CondGood,_xlfn.LOGNORM.INV(RAND(),MV3,Sigma2),MIN(MaxMultiple,Xm/(1-RAND())^(1/Alpha))))) -> 0 | Q7: =IF(RAND()<P_Zero,0,IF(RAND()<CondReturn,_xlfn.LOGNORM.INV(RAND(),MV2,Sigma1),IF(RAND()<CondGood,_xlfn.LOGNORM.INV(RAND(),MV3,Sigma2),MIN(MaxMultiple,Xm/(1-RAND())^(1/Alpha))))) -> 0 | R7: =IF(RAND()<P_Zero,0,IF(RAND()<CondReturn,_xlfn.LOGNORM.INV(RAND(),MV2,Sigma1),IF(RAND()<CondGood,_xlfn.LOGNORM.INV(RAND(),MV3,Sigma2),MIN(MaxMultiple,Xm/(1-RAND())^(1/Alpha))))) -> 2.820115 | S7: =IF(RAND()<P_Zero,0,IF(RAND()<CondReturn,_xlfn.LOGNORM.INV(RAND(),MV2,Sigma1),IF(RAND()<CondGood,_xlfn.LOGNORM.INV(RAND(),MV3,Sigma2),MIN(MaxMultiple,Xm/(1-RAND())^(1/Alpha))))) -> 41.42021 | T7: =IF(RAND()<P_Zero,0,IF(RAND()<CondReturn,_xlfn.LOGNORM.INV(RAND(),MV2,Sigma1),IF(RAND()<CondGood,_xlfn.LOGNORM.INV(RAND(),MV3,Sigma2),MIN(MaxMultiple,Xm/(1-RAND())^(1/Alpha))))) -> 0.68104349 | U7: =IF(RAND()<P_Zero,0,IF(RAND()<CondReturn,_xlfn.LOGNORM.INV(RAND(),MV2,Sigma1),IF(RAND()<CondGood,_xlfn.LOGNORM.INV(RAND(),MV3,Sigma2),MIN(MaxMultiple,Xm/(1-RAND())^(1/Alpha))))) -> 1.9741889 | V7: =IF(RAND()<P_Zero,0,IF(RAND()<CondReturn,_xlfn.LOGNORM.INV(RAND(),MV2,Sigma1),IF(RAND()<CondGood,_xlfn.LOGNORM.INV(RAND(),MV3,Sigma2),MIN(MaxMultiple,Xm/(1-RAND())^(1/Alpha))))) -> 1.1122484 | W7: =IF(RAND()<P_Zero,0,IF(RAND()<CondReturn,_xlfn.LOGNORM.INV(RAND(),MV2,Sigma1),IF(RAND()<CondGood,_xlfn.LOGNORM.INV(RAND(),MV3,Sigma2),MIN(MaxMultiple,Xm/(1-RAND())^(1/Alpha))))) -> 0 | X7: =IF(RAND()<P_Zero,0,IF(RAND()<CondReturn,_xlfn.LOGNORM.INV(RAND(),MV2,Sigma1),IF(RAND()<CondGood,_xlfn.LOGNORM.INV(RAND(),MV3,Sigma2),MIN(MaxMultiple,Xm/(1-RAND())^(1/Alpha))))) -> 0.98433688 | Y7: =IF(RAND()<P_Zero,0,IF(RAND()<CondReturn,_xlfn.LOGNORM.INV(RAND(),MV2,Sigma1),IF(RAND()<CondGood,_xlfn.LOGNORM.INV(RAND(),MV3,Sigma2),MIN(MaxMultiple,Xm/(1-RAND())^(1/Alpha))))) -> 0 | Z7: =IF(RAND()<P_Zero,0,IF(RAND()<CondReturn,_xlfn.LOGNORM.INV(RAND(),MV2,Sigma1),IF(RAND()<CondGood,_xlfn.LOGNORM.INV(RAND(),MV3,Sigma2),MIN(MaxMultiple,Xm/(1-RAND())^(1/Alpha))))) -> 0.91237954 | AA7: =IF(RAND()<P_Zero,0,IF(RAND()<CondReturn,_xlfn.LOGNORM.INV(RAND(),MV2,Sigma1),IF(RAND()<CondGood,_xlfn.LOGNORM.INV(RAND(),MV3,Sigma2),MIN(MaxMultiple,Xm/(1-RAND())^(1/Alpha))))) -> 1.0624646 | AB7: =AVERAGE(C7:AA7) -> 2.4572837 | AC7: =AB7*InvestableCapital -> 1.1794962e+08 | AD7: =AC7-InvestableCapital -> 69949616 | AE7: =HurdleToggle*InvestableCapital*((1+HurdleRate)^FeeYears-1) -> 55628400 | AF7: =MAX(0,AD7-AE7) -> 14321216 | AG7: =CarryRate*AF7 -> 2864243.2 | AH7: =AC7-AG7 -> 1.1508537e+08 | AI7: =AH7/FundSize -> 1.9180895
B8: 3 | C8: =IF(RAND()<P_Zero,0,IF(RAND()<CondReturn,_xlfn.LOGNORM.INV(RAND(),MV2,Sigma1),IF(RAND()<CondGood,_xlfn.LOGNORM.INV(RAND(),MV3,Sigma2),MIN(MaxMultiple,Xm/(1-RAND())^(1/Alpha))))) -> 23.020823 | D8: =IF(RAND()<P_Zero,0,IF(RAND()<CondReturn,_xlfn.LOGNORM.INV(RAND(),MV2,Sigma1),IF(RAND()<CondGood,_xlfn.LOGNORM.INV(RAND(),MV3,Sigma2),MIN(MaxMultiple,Xm/(1-RAND())^(1/Alpha))))) -> 0 | E8: =IF(RAND()<P_Zero,0,IF(RAND()<CondReturn,_xlfn.LOGNORM.INV(RAND(),MV2,Sigma1),IF(RAND()<CondGood,_xlfn.LOGNORM.INV(RAND(),MV3,Sigma2),MIN(MaxMultiple,Xm/(1-RAND())^(1/Alpha))))) -> 0.88947828 | F8: =IF(RAND()<P_Zero,0,IF(RAND()<CondReturn,_xlfn.LOGNORM.INV(RAND(),MV2,Sigma1),IF(RAND()<CondGood,_xlfn.LOGNORM.INV(RAND(),MV3,Sigma2),MIN(MaxMultiple,Xm/(1-RAND())^(1/Alpha))))) -> 50.502866 | G8: =IF(RAND()<P_Zero,0,IF(RAND()<CondReturn,_xlfn.LOGNORM.INV(RAND(),MV2,Sigma1),IF(RAND()<CondGood,_xlfn.LOGNORM.INV(RAND(),MV3,Sigma2),MIN(MaxMultiple,Xm/(1-RAND())^(1/Alpha))))) -> 1.0510485 | H8: =IF(RAND()<P_Zero,0,IF(RAND()<CondReturn,_xlfn.LOGNORM.INV(RAND(),MV2,Sigma1),IF(RAND()<CondGood,_xlfn.LOGNORM.INV(RAND(),MV3,Sigma2),MIN(MaxMultiple,Xm/(1-RAND())^(1/Alpha))))) -> 13.469861 | I8: =IF(RAND()<P_Zero,0,IF(RAND()<CondReturn,_xlfn.LOGNORM.INV(RAND(),MV2,Sigma1),IF(RAND()<CondGood,_xlfn.LOGNORM.INV(RAND(),MV3,Sigma2),MIN(MaxMultiple,Xm/(1-RAND())^(1/Alpha))))) -> 0 | J8: =IF(RAND()<P_Zero,0,IF(RAND()<CondReturn,_xlfn.LOGNORM.INV(RAND(),MV2,Sigma1),IF(RAND()<CondGood,_xlfn.LOGNORM.INV(RAND(),MV3,Sigma2),MIN(MaxMultiple,Xm/(1-RAND())^(1/Alpha))))) -> 0 | K8: =IF(RAND()<P_Zero,0,IF(RAND()<CondReturn,_xlfn.LOGNORM.INV(RAND(),MV2,Sigma1),IF(RAND()<CondGood,_xlfn.LOGNORM.INV(RAND(),MV3,Sigma2),MIN(MaxMultiple,Xm/(1-RAND())^(1/Alpha))))) -> 0 | L8: =IF(RAND()<P_Zero,0,IF(RAND()<CondReturn,_xlfn.LOGNORM.INV(RAND(),MV2,Sigma1),IF(RAND()<CondGood,_xlfn.LOGNORM.INV(RAND(),MV3,Sigma2),MIN(MaxMultiple,Xm/(1-RAND())^(1/Alpha))))) -> 1.7041172 | M8: =IF(RAND()<P_Zero,0,IF(RAND()<CondReturn,_xlfn.LOGNORM.INV(RAND(),MV2,Sigma1),IF(RAND()<CondGood,_xlfn.LOGNORM.INV(RAND(),MV3,Sigma2),MIN(MaxMultiple,Xm/(1-RAND())^(1/Alpha))))) -> 1.159678 | N8: =IF(RAND()<P_Zero,0,IF(RAND()<CondReturn,_xlfn.LOGNORM.INV(RAND(),MV2,Sigma1),IF(RAND()<CondGood,_xlfn.LOGNORM.INV(RAND(),MV3,Sigma2),MIN(MaxMultiple,Xm/(1-RAND())^(1/Alpha))))) -> 1.331213 | O8: =IF(RAND()<P_Zero,0,IF(RAND()<CondReturn,_xlfn.LOGNORM.INV(RAND(),MV2,Sigma1),IF(RAND()<CondGood,_xlfn.LOGNORM.INV(RAND(),MV3,Sigma2),MIN(MaxMultiple,Xm/(1-RAND())^(1/Alpha))))) -> 1.9612136 | P8: =IF(RAND()<P_Zero,0,IF(RAND()<CondReturn,_xlfn.LOGNORM.INV(RAND(),MV2,Sigma1),IF(RAND()<CondGood,_xlfn.LOGNORM.INV(RAND(),MV3,Sigma2),MIN(MaxMultiple,Xm/(1-RAND())^(1/Alpha))))) -> 0 | Q8: =IF(RAND()<P_Zero,0,IF(RAND()<CondReturn,_xlfn.LOGNORM.INV(RAND(),MV2,Sigma1),IF(RAND()<CondGood,_xlfn.LOGNORM.INV(RAND(),MV3,Sigma2),MIN(MaxMultiple,Xm/(1-RAND())^(1/Alpha))))) -> 0 | R8: =IF(RAND()<P_Zero,0,IF(RAND()<CondReturn,_xlfn.LOGNORM.INV(RAND(),MV2,Sigma1),IF(RAND()<CondGood,_xlfn.LOGNORM.INV(RAND(),MV3,Sigma2),MIN(MaxMultiple,Xm/(1-RAND())^(1/Alpha))))) -> 0.4460862 | S8: =IF(RAND()<P_Zero,0,IF(RAND()<CondReturn,_xlfn.LOGNORM.INV(RAND(),MV2,Sigma1),IF(RAND()<CondGood,_xlfn.LOGNORM.INV(RAND(),MV3,Sigma2),MIN(MaxMultiple,Xm/(1-RAND())^(1/Alpha))))) -> 1.4931892 | T8: =IF(RAND()<P_Zero,0,IF(RAND()<CondReturn,_xlfn.LOGNORM.INV(RAND(),MV2,Sigma1),IF(RAND()<CondGood,_xlfn.LOGNORM.INV(RAND(),MV3,Sigma2),MIN(MaxMultiple,Xm/(1-RAND())^(1/Alpha))))) -> 1.6835398 | U8: =IF(RAND()<P_Zero,0,IF(RAND()<CondReturn,_xlfn.LOGNORM.INV(RAND(),MV2,Sigma1),IF(RAND()<CondGood,_xlfn.LOGNORM.INV(RAND(),MV3,Sigma2),MIN(MaxMultiple,Xm/(1-RAND())^(1/Alpha))))) -> 0.54910796 | V8: =IF(RAND()<P_Zero,0,IF(RAND()<CondReturn,_xlfn.LOGNORM.INV(RAND(),MV2,Sigma1),IF(RAND()<CondGood,_xlfn.LOGNORM.INV(RAND(),MV3,Sigma2),MIN(MaxMultiple,Xm/(1-RAND())^(1/Alpha))))) -> 0.62107712 | W8: =IF(RAND()<P_Zero,0,IF(RAND()<CondReturn,_xlfn.LOGNORM.INV(RAND(),MV2,Sigma1),IF(RAND()<CondGood,_xlfn.LOGNORM.INV(RAND(),MV3,Sigma2),MIN(MaxMultiple,Xm/(1-RAND())^(1/Alpha))))) -> 1.7423138 | X8: =IF(RAND()<P_Zero,0,IF(RAND()<CondReturn,_xlfn.LOGNORM.INV(RAND(),MV2,Sigma1),IF(RAND()<CondGood,_xlfn.LOGNORM.INV(RAND(),MV3,Sigma2),MIN(MaxMultiple,Xm/(1-RAND())^(1/Alpha))))) -> 0 | Y8: =IF(RAND()<P_Zero,0,IF(RAND()<CondReturn,_xlfn.LOGNORM.INV(RAND(),MV2,Sigma1),IF(RAND()<CondGood,_xlfn.LOGNORM.INV(RAND(),MV3,Sigma2),MIN(MaxMultiple,Xm/(1-RAND())^(1/Alpha))))) -> 0.55833884 | Z8: =IF(RAND()<P_Zero,0,IF(RAND()<CondReturn,_xlfn.LOGNORM.INV(RAND(),MV2,Sigma1),IF(RAND()<CondGood,_xlfn.LOGNORM.INV(RAND(),MV3,Sigma2),MIN(MaxMultiple,Xm/(1-RAND())^(1/Alpha))))) -> 0 | AA8: =IF(RAND()<P_Zero,0,IF(RAND()<CondReturn,_xlfn.LOGNORM.INV(RAND(),MV2,Sigma1),IF(RAND()<CondGood,_xlfn.LOGNORM.INV(RAND(),MV3,Sigma2),MIN(MaxMultiple,Xm/(1-RAND())^(1/Alpha))))) -> 0.72702586 | AB8: =AVERAGE(C8:AA8) -> 4.1164391 | AC8: =AB8*InvestableCapital -> 1.9758908e+08 | AD8: =AC8-InvestableCapital -> 1.4958908e+08 | AE8: =HurdleToggle*InvestableCapital*((1+HurdleRate)^FeeYears-1) -> 55628400 | AF8: =MAX(0,AD8-AE8) -> 93960679 | AG8: =CarryRate*AF8 -> 18792136 | AH8: =AC8-AG8 -> 1.7879694e+08 | AI8: =AH8/FundSize -> 2.979949
B9: 4 | C9: =IF(RAND()<P_Zero,0,IF(RAND()<CondReturn,_xlfn.LOGNORM.INV(RAND(),MV2,Sigma1),IF(RAND()<CondGood,_xlfn.LOGNORM.INV(RAND(),MV3,Sigma2),MIN(MaxMultiple,Xm/(1-RAND())^(1/Alpha))))) -> 1.3207637 | D9: =IF(RAND()<P_Zero,0,IF(RAND()<CondReturn,_xlfn.LOGNORM.INV(RAND(),MV2,Sigma1),IF(RAND()<CondGood,_xlfn.LOGNORM.INV(RAND(),MV3,Sigma2),MIN(MaxMultiple,Xm/(1-RAND())^(1/Alpha))))) -> 1.029933 | E9: =IF(RAND()<P_Zero,0,IF(RAND()<CondReturn,_xlfn.LOGNORM.INV(RAND(),MV2,Sigma1),IF(RAND()<CondGood,_xlfn.LOGNORM.INV(RAND(),MV3,Sigma2),MIN(MaxMultiple,Xm/(1-RAND())^(1/Alpha))))) -> 2.1489923 | F9: =IF(RAND()<P_Zero,0,IF(RAND()<CondReturn,_xlfn.LOGNORM.INV(RAND(),MV2,Sigma1),IF(RAND()<CondGood,_xlfn.LOGNORM.INV(RAND(),MV3,Sigma2),MIN(MaxMultiple,Xm/(1-RAND())^(1/Alpha))))) -> 1.2523058 | G9: =IF(RAND()<P_Zero,0,IF(RAND()<CondReturn,_xlfn.LOGNORM.INV(RAND(),MV2,Sigma1),IF(RAND()<CondGood,_xlfn.LOGNORM.INV(RAND(),MV3,Sigma2),MIN(MaxMultiple,Xm/(1-RAND())^(1/Alpha))))) -> 1.2250737 | H9: =IF(RAND()<P_Zero,0,IF(RAND()<CondReturn,_xlfn.LOGNORM.INV(RAND(),MV2,Sigma1),IF(RAND()<CondGood,_xlfn.LOGNORM.INV(RAND(),MV3,Sigma2),MIN(MaxMultiple,Xm/(1-RAND())^(1/Alpha))))) -> 1.4362851 | I9: =IF(RAND()<P_Zero,0,IF(RAND()<CondReturn,_xlfn.LOGNORM.INV(RAND(),MV2,Sigma1),IF(RAND()<CondGood,_xlfn.LOGNORM.INV(RAND(),MV3,Sigma2),MIN(MaxMultiple,Xm/(1-RAND())^(1/Alpha))))) -> 0 | J9: =IF(RAND()<P_Zero,0,IF(RAND()<CondReturn,_xlfn.LOGNORM.INV(RAND(),MV2,Sigma1),IF(RAND()<CondGood,_xlfn.LOGNORM.INV(RAND(),MV3,Sigma2),MIN(MaxMultiple,Xm/(1-RAND())^(1/Alpha))))) -> 0 | K9: =IF(RAND()<P_Zero,0,IF(RAND()<CondReturn,_xlfn.LOGNORM.INV(RAND(),MV2,Sigma1),IF(RAND()<CondGood,_xlfn.LOGNORM.INV(RAND(),MV3,Sigma2),MIN(MaxMultiple,Xm/(1-RAND())^(1/Alpha))))) -> 0 | L9: =IF(RAND()<P_Zero,0,IF(RAND()<CondReturn,_xlfn.LOGNORM.INV(RAND(),MV2,Sigma1),IF(RAND()<CondGood,_xlfn.LOGNORM.INV(RAND(),MV3,Sigma2),MIN(MaxMultiple,Xm/(1-RAND())^(1/Alpha))))) -> 0 | M9: =IF(RAND()<P_Zero,0,IF(RAND()<CondReturn,_xlfn.LOGNORM.INV(RAND(),MV2,Sigma1),IF(RAND()<CondGood,_xlfn.LOGNORM.INV(RAND(),MV3,Sigma2),MIN(MaxMultiple,Xm/(1-RAND())^(1/Alpha))))) -> 1.1553973 | N9: =IF(RAND()<P_Zero,0,IF(RAND()<CondReturn,_xlfn.LOGNORM.INV(RAND(),MV2,Sigma1),IF(RAND()<CondGood,_xlfn.LOGNORM.INV(RAND(),MV3,Sigma2),MIN(MaxMultiple,Xm/(1-RAND())^(1/Alpha))))) -> 0 | O9: =IF(RAND()<P_Zero,0,IF(RAND()<CondReturn,_xlfn.LOGNORM.INV(RAND(),MV2,Sigma1),IF(RAND()<CondGood,_xlfn.LOGNORM.INV(RAND(),MV3,Sigma2),MIN(MaxMultiple,Xm/(1-RAND())^(1/Alpha))))) -> 1.5207064 | P9: =IF(RAND()<P_Zero,0,IF(RAND()<CondReturn,_xlfn.LOGNORM.INV(RAND(),MV2,Sigma1),IF(RAND()<CondGood,_xlfn.LOGNORM.INV(RAND(),MV3,Sigma2),MIN(MaxMultiple,Xm/(1-RAND())^(1/Alpha))))) -> 0 | Q9: =IF(RAND()<P_Zero,0,IF(RAND()<CondReturn,_xlfn.LOGNORM.INV(RAND(),MV2,Sigma1),IF(RAND()<CondGood,_xlfn.LOGNORM.INV(RAND(),MV3,Sigma2),MIN(MaxMultiple,Xm/(1-RAND())^(1/Alpha))))) -> 0 | R9: =IF(RAND()<P_Zero,0,IF(RAND()<CondReturn,_xlfn.LOGNORM.INV(RAND(),MV2,Sigma1),IF(RAND()<CondGood,_xlfn.LOGNORM.INV(RAND(),MV3,Sigma2),MIN(MaxMultiple,Xm/(1-RAND())^(1/Alpha))))) -> 1.0709694 | S9: =IF(RAND()<P_Zero,0,IF(RAND()<CondReturn,_xlfn.LOGNORM.INV(RAND(),MV2,Sigma1),IF(RAND()<CondGood,_xlfn.LOGNORM.INV(RAND(),MV3,Sigma2),MIN(MaxMultiple,Xm/(1-RAND())^(1/Alpha))))) -> 0 | T9: =IF(RAND()<P_Zero,0,IF(RAND()<CondReturn,_xlfn.LOGNORM.INV(RAND(),MV2,Sigma1),IF(RAND()<CondGood,_xlfn.LOGNORM.INV(RAND(),MV3,Sigma2),MIN(MaxMultiple,Xm/(1-RAND())^(1/Alpha))))) -> 0.61976411 | U9: =IF(RAND()<P_Zero,0,IF(RAND()<CondReturn,_xlfn.LOGNORM.INV(RAND(),MV2,Sigma1),IF(RAND()<CondGood,_xlfn.LOGNORM.INV(RAND(),MV3,Sigma2),MIN(MaxMultiple,Xm/(1-RAND())^(1/Alpha))))) -> 1.0078457 | V9: =IF(RAND()<P_Zero,0,IF(RAND()<CondReturn,_xlfn.LOGNORM.INV(RAND(),MV2,Sigma1),IF(RAND()<CondGood,_xlfn.LOGNORM.INV(RAND(),MV3,Sigma2),MIN(MaxMultiple,Xm/(1-RAND())^(1/Alpha))))) -> 1.6936059 | W9: =IF(RAND()<P_Zero,0,IF(RAND()<CondReturn,_xlfn.LOGNORM.INV(RAND(),MV2,Sigma1),IF(RAND()<CondGood,_xlfn.LOGNORM.INV(RAND(),MV3,Sigma2),MIN(MaxMultiple,Xm/(1-RAND())^(1/Alpha))))) -> 0.95642555 | X9: =IF(RAND()<P_Zero,0,IF(RAND()<CondReturn,_xlfn.LOGNORM.INV(RAND(),MV2,Sigma1),IF(RAND()<CondGood,_xlfn.LOGNORM.INV(RAND(),MV3,Sigma2),MIN(MaxMultiple,Xm/(1-RAND())^(1/Alpha))))) -> 0.85474686 | Y9: =IF(RAND()<P_Zero,0,IF(RAND()<CondReturn,_xlfn.LOGNORM.INV(RAND(),MV2,Sigma1),IF(RAND()<CondGood,_xlfn.LOGNORM.INV(RAND(),MV3,Sigma2),MIN(MaxMultiple,Xm/(1-RAND())^(1/Alpha))))) -> 23.047494 | Z9: =IF(RAND()<P_Zero,0,IF(RAND()<CondReturn,_xlfn.LOGNORM.INV(RAND(),MV2,Sigma1),IF(RAND()<CondGood,_xlfn.LOGNORM.INV(RAND(),MV3,Sigma2),MIN(MaxMultiple,Xm/(1-RAND())^(1/Alpha))))) -> 0.48380287 | AA9: =IF(RAND()<P_Zero,0,IF(RAND()<CondReturn,_xlfn.LOGNORM.INV(RAND(),MV2,Sigma1),IF(RAND()<CondGood,_xlfn.LOGNORM.INV(RAND(),MV3,Sigma2),MIN(MaxMultiple,Xm/(1-RAND())^(1/Alpha))))) -> 0 | AB9: =AVERAGE(C9:AA9) -> 1.6329645 | AC9: =AB9*InvestableCapital -> 78382294 | AD9: =AC9-InvestableCapital -> 30382294 | AE9: =HurdleToggle*InvestableCapital*((1+HurdleRate)^FeeYears-1) -> 55628400 | AF9: =MAX(0,AD9-AE9) -> 0 | AG9: =CarryRate*AF9 -> 0 | AH9: =AC9-AG9 -> 78382294 | AI9: =AH9/FundSize -> 1.3063716
B10: 5 | C10: =IF(RAND()<P_Zero,0,IF(RAND()<CondReturn,_xlfn.LOGNORM.INV(RAND(),MV2,Sigma1),IF(RAND()<CondGood,_xlfn.LOGNORM.INV(RAND(),MV3,Sigma2),MIN(MaxMultiple,Xm/(1-RAND())^(1/Alpha))))) -> 3.5600795 | D10: =IF(RAND()<P_Zero,0,IF(RAND()<CondReturn,_xlfn.LOGNORM.INV(RAND(),MV2,Sigma1),IF(RAND()<CondGood,_xlfn.LOGNORM.INV(RAND(),MV3,Sigma2),MIN(MaxMultiple,Xm/(1-RAND())^(1/Alpha))))) -> 0.55702074 | E10: =IF(RAND()<P_Zero,0,IF(RAND()<CondReturn,_xlfn.LOGNORM.INV(RAND(),MV2,Sigma1),IF(RAND()<CondGood,_xlfn.LOGNORM.INV(RAND(),MV3,Sigma2),MIN(MaxMultiple,Xm/(1-RAND())^(1/Alpha))))) -> 11.565695 | F10: =IF(RAND()<P_Zero,0,IF(RAND()<CondReturn,_xlfn.LOGNORM.INV(RAND(),MV2,Sigma1),IF(RAND()<CondGood,_xlfn.LOGNORM.INV(RAND(),MV3,Sigma2),MIN(MaxMultiple,Xm/(1-RAND())^(1/Alpha))))) -> 0 | G10: =IF(RAND()<P_Zero,0,IF(RAND()<CondReturn,_xlfn.LOGNORM.INV(RAND(),MV2,Sigma1),IF(RAND()<CondGood,_xlfn.LOGNORM.INV(RAND(),MV3,Sigma2),MIN(MaxMultiple,Xm/(1-RAND())^(1/Alpha))))) -> 0 | H10: =IF(RAND()<P_Zero,0,IF(RAND()<CondReturn,_xlfn.LOGNORM.INV(RAND(),MV2,Sigma1),IF(RAND()<CondGood,_xlfn.LOGNORM.INV(RAND(),MV3,Sigma2),MIN(MaxMultiple,Xm/(1-RAND())^(1/Alpha))))) -> 0.60003556 | I10: =IF(RAND()<P_Zero,0,IF(RAND()<CondReturn,_xlfn.LOGNORM.INV(RAND(),MV2,Sigma1),IF(RAND()<CondGood,_xlfn.LOGNORM.INV(RAND(),MV3,Sigma2),MIN(MaxMultiple,Xm/(1-RAND())^(1/Alpha))))) -> 11.470691 | J10: =IF(RAND()<P_Zero,0,IF(RAND()<CondReturn,_xlfn.LOGNORM.INV(RAND(),MV2,Sigma1),IF(RAND()<CondGood,_xlfn.LOGNORM.INV(RAND(),MV3,Sigma2),MIN(MaxMultiple,Xm/(1-RAND())^(1/Alpha))))) -> 0 | K10: =IF(RAND()<P_Zero,0,IF(RAND()<CondReturn,_xlfn.LOGNORM.INV(RAND(),MV2,Sigma1),IF(RAND()<CondGood,_xlfn.LOGNORM.INV(RAND(),MV3,Sigma2),MIN(MaxMultiple,Xm/(1-RAND())^(1/Alpha))))) -> 0 | L10: =IF(RAND()<P_Zero,0,IF(RAND()<CondReturn,_xlfn.LOGNORM.INV(RAND(),MV2,Sigma1),IF(RAND()<CondGood,_xlfn.LOGNORM.INV(RAND(),MV3,Sigma2),MIN(MaxMultiple,Xm/(1-RAND())^(1/Alpha))))) -> 0 | M10: =IF(RAND()<P_Zero,0,IF(RAND()<CondReturn,_xlfn.LOGNORM.INV(RAND(),MV2,Sigma1),IF(RAND()<CondGood,_xlfn.LOGNORM.INV(RAND(),MV3,Sigma2),MIN(MaxMultiple,Xm/(1-RAND())^(1/Alpha))))) -> 0 | N10: =IF(RAND()<P_Zero,0,IF(RAND()<CondReturn,_xlfn.LOGNORM.INV(RAND(),MV2,Sigma1),IF(RAND()<CondGood,_xlfn.LOGNORM.INV(RAND(),MV3,Sigma2),MIN(MaxMultiple,Xm/(1-RAND())^(1/Alpha))))) -> 0.95881777 | O10: =IF(RAND()<P_Zero,0,IF(RAND()<CondReturn,_xlfn.LOGNORM.INV(RAND(),MV2,Sigma1),IF(RAND()<CondGood,_xlfn.LOGNORM.INV(RAND(),MV3,Sigma2),MIN(MaxMultiple,Xm/(1-RAND())^(1/Alpha))))) -> 0 | P10: =IF(RAND()<P_Zero,0,IF(RAND()<CondReturn,_xlfn.LOGNORM.INV(RAND(),MV2,Sigma1),IF(RAND()<CondGood,_xlfn.LOGNORM.INV(RAND(),MV3,Sigma2),MIN(MaxMultiple,Xm/(1-RAND())^(1/Alpha))))) -> 0 | Q10: =IF(RAND()<P_Zero,0,IF(RAND()<CondReturn,_xlfn.LOGNORM.INV(RAND(),MV2,Sigma1),IF(RAND()<CondGood,_xlfn.LOGNORM.INV(RAND(),MV3,Sigma2),MIN(MaxMultiple,Xm/(1-RAND())^(1/Alpha))))) -> 0.51871465 | R10: =IF(RAND()<P_Zero,0,IF(RAND()<CondReturn,_xlfn.LOGNORM.INV(RAND(),MV2,Sigma1),IF(RAND()<CondGood,_xlfn.LOGNORM.INV(RAND(),MV3,Sigma2),MIN(MaxMultiple,Xm/(1-RAND())^(1/Alpha))))) -> 1.5704738 | S10: =IF(RAND()<P_Zero,0,IF(RAND()<CondReturn,_xlfn.LOGNORM.INV(RAND(),MV2,Sigma1),IF(RAND()<CondGood,_xlfn.LOGNORM.INV(RAND(),MV3,Sigma2),MIN(MaxMultiple,Xm/(1-RAND())^(1/Alpha))))) -> 1.2391077 | T10: =IF(RAND()<P_Zero,0,IF(RAND()<CondReturn,_xlfn.LOGNORM.INV(RAND(),MV2,Sigma1),IF(RAND()<CondGood,_xlfn.LOGNORM.INV(RAND(),MV3,Sigma2),MIN(MaxMultiple,Xm/(1-RAND())^(1/Alpha))))) -> 0.55627548 | U10: =IF(RAND()<P_Zero,0,IF(RAND()<CondReturn,_xlfn.LOGNORM.INV(RAND(),MV2,Sigma1),IF(RAND()<CondGood,_xlfn.LOGNORM.INV(RAND(),MV3,Sigma2),MIN(MaxMultiple,Xm/(1-RAND())^(1/Alpha))))) -> 0 | V10: =IF(RAND()<P_Zero,0,IF(RAND()<CondReturn,_xlfn.LOGNORM.INV(RAND(),MV2,Sigma1),IF(RAND()<CondGood,_xlfn.LOGNORM.INV(RAND(),MV3,Sigma2),MIN(MaxMultiple,Xm/(1-RAND())^(1/Alpha))))) -> 0 | W10: =IF(RAND()<P_Zero,0,IF(RAND()<CondReturn,_xlfn.LOGNORM.INV(RAND(),MV2,Sigma1),IF(RAND()<CondGood,_xlfn.LOGNORM.INV(RAND(),MV3,Sigma2),MIN(MaxMultiple,Xm/(1-RAND())^(1/Alpha))))) -> 1.2842095 | X10: =IF(RAND()<P_Zero,0,IF(RAND()<CondReturn,_xlfn.LOGNORM.INV(RAND(),MV2,Sigma1),IF(RAND()<CondGood,_xlfn.LOGNORM.INV(RAND(),MV3,Sigma2),MIN(MaxMultiple,Xm/(1-RAND())^(1/Alpha))))) -> 0 | Y10: =IF(RAND()<P_Zero,0,IF(RAND()<CondReturn,_xlfn.LOGNORM.INV(RAND(),MV2,Sigma1),IF(RAND()<CondGood,_xlfn.LOGNORM.INV(RAND(),MV3,Sigma2),MIN(MaxMultiple,Xm/(1-RAND())^(1/Alpha))))) -> 11.41649 | Z10: =IF(RAND()<P_Zero,0,IF(RAND()<CondReturn,_xlfn.LOGNORM.INV(RAND(),MV2,Sigma1),IF(RAND()<CondGood,_xlfn.LOGNORM.INV(RAND(),MV3,Sigma2),MIN(MaxMultiple,Xm/(1-RAND())^(1/Alpha))))) -> 0 | AA10: =IF(RAND()<P_Zero,0,IF(RAND()<CondReturn,_xlfn.LOGNORM.INV(RAND(),MV2,Sigma1),IF(RAND()<CondGood,_xlfn.LOGNORM.INV(RAND(),MV3,Sigma2),MIN(MaxMultiple,Xm/(1-RAND())^(1/Alpha))))) -> 0.95191466 | AB10: =AVERAGE(C10:AA10) -> 1.849981 | AC10: =AB10*InvestableCapital -> 88799090 | AD10: =AC10-InvestableCapital -> 40799090 | AE10: =HurdleToggle*InvestableCapital*((1+HurdleRate)^FeeYears-1) -> 55628400 | AF10: =MAX(0,AD10-AE10) -> 0 | AG10: =CarryRate*AF10 -> 0 | AH10: =AC10-AG10 -> 88799090 | AI10: =AH10/FundSize -> 1.4799848
B11: 6 | C11: =IF(RAND()<P_Zero,0,IF(RAND()<CondReturn,_xlfn.LOGNORM.INV(RAND(),MV2,Sigma1),IF(RAND()<CondGood,_xlfn.LOGNORM.INV(RAND(),MV3,Sigma2),MIN(MaxMultiple,Xm/(1-RAND())^(1/Alpha))))) -> 0 | D11: =IF(RAND()<P_Zero,0,IF(RAND()<CondReturn,_xlfn.LOGNORM.INV(RAND(),MV2,Sigma1),IF(RAND()<CondGood,_xlfn.LOGNORM.INV(RAND(),MV3,Sigma2),MIN(MaxMultiple,Xm/(1-RAND())^(1/Alpha))))) -> 1.0417888 | E11: =IF(RAND()<P_Zero,0,IF(RAND()<CondReturn,_xlfn.LOGNORM.INV(RAND(),MV2,Sigma1),IF(RAND()<CondGood,_xlfn.LOGNORM.INV(RAND(),MV3,Sigma2),MIN(MaxMultiple,Xm/(1-RAND())^(1/Alpha))))) -> 3.0326514 | F11: =IF(RAND()<P_Zero,0,IF(RAND()<CondReturn,_xlfn.LOGNORM.INV(RAND(),MV2,Sigma1),IF(RAND()<CondGood,_xlfn.LOGNORM.INV(RAND(),MV3,Sigma2),MIN(MaxMultiple,Xm/(1-RAND())^(1/Alpha))))) -> 0.46576833 | G11: =IF(RAND()<P_Zero,0,IF(RAND()<CondReturn,_xlfn.LOGNORM.INV(RAND(),MV2,Sigma1),IF(RAND()<CondGood,_xlfn.LOGNORM.INV(RAND(),MV3,Sigma2),MIN(MaxMultiple,Xm/(1-RAND())^(1/Alpha))))) -> 1.2253228 | H11: =IF(RAND()<P_Zero,0,IF(RAND()<CondReturn,_xlfn.LOGNORM.INV(RAND(),MV2,Sigma1),IF(RAND()<CondGood,_xlfn.LOGNORM.INV(RAND(),MV3,Sigma2),MIN(MaxMultiple,Xm/(1-RAND())^(1/Alpha))))) -> 0 | I11: =IF(RAND()<P_Zero,0,IF(RAND()<CondReturn,_xlfn.LOGNORM.INV(RAND(),MV2,Sigma1),IF(RAND()<CondGood,_xlfn.LOGNORM.INV(RAND(),MV3,Sigma2),MIN(MaxMultiple,Xm/(1-RAND())^(1/Alpha))))) -> 0.64431358 | J11: =IF(RAND()<P_Zero,0,IF(RAND()<CondReturn,_xlfn.LOGNORM.INV(RAND(),MV2,Sigma1),IF(RAND()<CondGood,_xlfn.LOGNORM.INV(RAND(),MV3,Sigma2),MIN(MaxMultiple,Xm/(1-RAND())^(1/Alpha))))) -> 0 | K11: =IF(RAND()<P_Zero,0,IF(RAND()<CondReturn,_xlfn.LOGNORM.INV(RAND(),MV2,Sigma1),IF(RAND()<CondGood,_xlfn.LOGNORM.INV(RAND(),MV3,Sigma2),MIN(MaxMultiple,Xm/(1-RAND())^(1/Alpha))))) -> 0 | L11: =IF(RAND()<P_Zero,0,IF(RAND()<CondReturn,_xlfn.LOGNORM.INV(RAND(),MV2,Sigma1),IF(RAND()<CondGood,_xlfn.LOGNORM.INV(RAND(),MV3,Sigma2),MIN(MaxMultiple,Xm/(1-RAND())^(1/Alpha))))) -> 0 | M11: =IF(RAND()<P_Zero,0,IF(RAND()<CondReturn,_xlfn.LOGNORM.INV(RAND(),MV2,Sigma1),IF(RAND()<CondGood,_xlfn.LOGNORM.INV(RAND(),MV3,Sigma2),MIN(MaxMultiple,Xm/(1-RAND())^(1/Alpha))))) -> 0 | N11: =IF(RAND()<P_Zero,0,IF(RAND()<CondReturn,_xlfn.LOGNORM.INV(RAND(),MV2,Sigma1),IF(RAND()<CondGood,_xlfn.LOGNORM.INV(RAND(),MV3,Sigma2),MIN(MaxMultiple,Xm/(1-RAND())^(1/Alpha))))) -> 1.0981271 | O11: =IF(RAND()<P_Zero,0,IF(RAND()<CondReturn,_xlfn.LOGNORM.INV(RAND(),MV2,Sigma1),IF(RAND()<CondGood,_xlfn.LOGNORM.INV(RAND(),MV3,Sigma2),MIN(MaxMultiple,Xm/(1-RAND())^(1/Alpha))))) -> 0 | P11: =IF(RAND()<P_Zero,0,IF(RAND()<CondReturn,_xlfn.LOGNORM.INV(RAND(),MV2,Sigma1),IF(RAND()<CondGood,_xlfn.LOGNORM.INV(RAND(),MV3,Sigma2),MIN(MaxMultiple,Xm/(1-RAND())^(1/Alpha))))) -> 0.56097269 | Q11: =IF(RAND()<P_Zero,0,IF(RAND()<CondReturn,_xlfn.LOGNORM.INV(RAND(),MV2,Sigma1),IF(RAND()<CondGood,_xlfn.LOGNORM.INV(RAND(),MV3,Sigma2),MIN(MaxMultiple,Xm/(1-RAND())^(1/Alpha))))) -> 1.4301478 | R11: =IF(RAND()<P_Zero,0,IF(RAND()<CondReturn,_xlfn.LOGNORM.INV(RAND(),MV2,Sigma1),IF(RAND()<CondGood,_xlfn.LOGNORM.INV(RAND(),MV3,Sigma2),MIN(MaxMultiple,Xm/(1-RAND())^(1/Alpha))))) -> 0 | S11: =IF(RAND()<P_Zero,0,IF(RAND()<CondReturn,_xlfn.LOGNORM.INV(RAND(),MV2,Sigma1),IF(RAND()<CondGood,_xlfn.LOGNORM.INV(RAND(),MV3,Sigma2),MIN(MaxMultiple,Xm/(1-RAND())^(1/Alpha))))) -> 10.302981 | T11: =IF(RAND()<P_Zero,0,IF(RAND()<CondReturn,_xlfn.LOGNORM.INV(RAND(),MV2,Sigma1),IF(RAND()<CondGood,_xlfn.LOGNORM.INV(RAND(),MV3,Sigma2),MIN(MaxMultiple,Xm/(1-RAND())^(1/Alpha))))) -> 25.373767 | U11: =IF(RAND()<P_Zero,0,IF(RAND()<CondReturn,_xlfn.LOGNORM.INV(RAND(),MV2,Sigma1),IF(RAND()<CondGood,_xlfn.LOGNORM.INV(RAND(),MV3,Sigma2),MIN(MaxMultiple,Xm/(1-RAND())^(1/Alpha))))) -> 0 | V11: =IF(RAND()<P_Zero,0,IF(RAND()<CondReturn,_xlfn.LOGNORM.INV(RAND(),MV2,Sigma1),IF(RAND()<CondGood,_xlfn.LOGNORM.INV(RAND(),MV3,Sigma2),MIN(MaxMultiple,Xm/(1-RAND())^(1/Alpha))))) -> 54.126397 | W11: =IF(RAND()<P_Zero,0,IF(RAND()<CondReturn,_xlfn.LOGNORM.INV(RAND(),MV2,Sigma1),IF(RAND()<CondGood,_xlfn.LOGNORM.INV(RAND(),MV3,Sigma2),MIN(MaxMultiple,Xm/(1-RAND())^(1/Alpha))))) -> 17.553742 | X11: =IF(RAND()<P_Zero,0,IF(RAND()<CondReturn,_xlfn.LOGNORM.INV(RAND(),MV2,Sigma1),IF(RAND()<CondGood,_xlfn.LOGNORM.INV(RAND(),MV3,Sigma2),MIN(MaxMultiple,Xm/(1-RAND())^(1/Alpha))))) -> 1.2336726 | Y11: =IF(RAND()<P_Zero,0,IF(RAND()<CondReturn,_xlfn.LOGNORM.INV(RAND(),MV2,Sigma1),IF(RAND()<CondGood,_xlfn.LOGNORM.INV(RAND(),MV3,Sigma2),MIN(MaxMultiple,Xm/(1-RAND())^(1/Alpha))))) -> 17.273219 | Z11: =IF(RAND()<P_Zero,0,IF(RAND()<CondReturn,_xlfn.LOGNORM.INV(RAND(),MV2,Sigma1),IF(RAND()<CondGood,_xlfn.LOGNORM.INV(RAND(),MV3,Sigma2),MIN(MaxMultiple,Xm/(1-RAND())^(1/Alpha))))) -> 0 | AA11: =IF(RAND()<P_Zero,0,IF(RAND()<CondReturn,_xlfn.LOGNORM.INV(RAND(),MV2,Sigma1),IF(RAND()<CondGood,_xlfn.LOGNORM.INV(RAND(),MV3,Sigma2),MIN(MaxMultiple,Xm/(1-RAND())^(1/Alpha))))) -> 0.95436286 | AB11: =AVERAGE(C11:AA11) -> 5.4526893 | AC11: =AB11*InvestableCapital -> 2.6172909e+08 | AD11: =AC11-InvestableCapital -> 2.1372909e+08 | AE11: =HurdleToggle*InvestableCapital*((1+HurdleRate)^FeeYears-1) -> 55628400 | AF11: =MAX(0,AD11-AE11) -> 1.5810069e+08 | AG11: =CarryRate*AF11 -> 31620138 | AH11: =AC11-AG11 -> 2.3010895e+08 | AI11: =AH11/FundSize -> 3.8351492
B12: 7 | C12: =IF(RAND()<P_Zero,0,IF(RAND()<CondReturn,_xlfn.LOGNORM.INV(RAND(),MV2,Sigma1),IF(RAND()<CondGood,_xlfn.LOGNORM.INV(RAND(),MV3,Sigma2),MIN(MaxMultiple,Xm/(1-RAND())^(1/Alpha))))) -> 1.3032065 | D12: =IF(RAND()<P_Zero,0,IF(RAND()<CondReturn,_xlfn.LOGNORM.INV(RAND(),MV2,Sigma1),IF(RAND()<CondGood,_xlfn.LOGNORM.INV(RAND(),MV3,Sigma2),MIN(MaxMultiple,Xm/(1-RAND())^(1/Alpha))))) -> 0 | E12: =IF(RAND()<P_Zero,0,IF(RAND()<CondReturn,_xlfn.LOGNORM.INV(RAND(),MV2,Sigma1),IF(RAND()<CondGood,_xlfn.LOGNORM.INV(RAND(),MV3,Sigma2),MIN(MaxMultiple,Xm/(1-RAND())^(1/Alpha))))) -> 0 | F12: =IF(RAND()<P_Zero,0,IF(RAND()<CondReturn,_xlfn.LOGNORM.INV(RAND(),MV2,Sigma1),IF(RAND()<CondGood,_xlfn.LOGNORM.INV(RAND(),MV3,Sigma2),MIN(MaxMultiple,Xm/(1-RAND())^(1/Alpha))))) -> 1.4693885 | G12: =IF(RAND()<P_Zero,0,IF(RAND()<CondReturn,_xlfn.LOGNORM.INV(RAND(),MV2,Sigma1),IF(RAND()<CondGood,_xlfn.LOGNORM.INV(RAND(),MV3,Sigma2),MIN(MaxMultiple,Xm/(1-RAND())^(1/Alpha))))) -> 0 | H12: =IF(RAND()<P_Zero,0,IF(RAND()<CondReturn,_xlfn.LOGNORM.INV(RAND(),MV2,Sigma1),IF(RAND()<CondGood,_xlfn.LOGNORM.INV(RAND(),MV3,Sigma2),MIN(MaxMultiple,Xm/(1-RAND())^(1/Alpha))))) -> 0 | I12: =IF(RAND()<P_Zero,0,IF(RAND()<CondReturn,_xlfn.LOGNORM.INV(RAND(),MV2,Sigma1),IF(RAND()<CondGood,_xlfn.LOGNORM.INV(RAND(),MV3,Sigma2),MIN(MaxMultiple,Xm/(1-RAND())^(1/Alpha))))) -> 0 | J12: =IF(RAND()<P_Zero,0,IF(RAND()<CondReturn,_xlfn.LOGNORM.INV(RAND(),MV2,Sigma1),IF(RAND()<CondGood,_xlfn.LOGNORM.INV(RAND(),MV3,Sigma2),MIN(MaxMultiple,Xm/(1-RAND())^(1/Alpha))))) -> 0 | K12: =IF(RAND()<P_Zero,0,IF(RAND()<CondReturn,_xlfn.LOGNORM.INV(RAND(),MV2,Sigma1),IF(RAND()<CondGood,_xlfn.LOGNORM.INV(RAND(),MV3,Sigma2),MIN(MaxMultiple,Xm/(1-RAND())^(1/Alpha))))) -> 1.1103981 | L12: =IF(RAND()<P_Zero,0,IF(RAND()<CondReturn,_xlfn.LOGNORM.INV(RAND(),MV2,Sigma1),IF(RAND()<CondGood,_xlfn.LOGNORM.INV(RAND(),MV3,Sigma2),MIN(MaxMultiple,Xm/(1-RAND())^(1/Alpha))))) -> 0.51516316 | M12: =IF(RAND()<P_Zero,0,IF(RAND()<CondReturn,_xlfn.LOGNORM.INV(RAND(),MV2,Sigma1),IF(RAND()<CondGood,_xlfn.LOGNORM.INV(RAND(),MV3,Sigma2),MIN(MaxMultiple,Xm/(1-RAND())^(1/Alpha))))) -> 1.7859228 | N12: =IF(RAND()<P_Zero,0,IF(RAND()<CondReturn,_xlfn.LOGNORM.INV(RAND(),MV2,Sigma1),IF(RAND()<CondGood,_xlfn.LOGNORM.INV(RAND(),MV3,Sigma2),MIN(MaxMultiple,Xm/(1-RAND())^(1/Alpha))))) -> 0 | O12: =IF(RAND()<P_Zero,0,IF(RAND()<CondReturn,_xlfn.LOGNORM.INV(RAND(),MV2,Sigma1),IF(RAND()<CondGood,_xlfn.LOGNORM.INV(RAND(),MV3,Sigma2),MIN(MaxMultiple,Xm/(1-RAND())^(1/Alpha))))) -> 0.60785724 | P12: =IF(RAND()<P_Zero,0,IF(RAND()<CondReturn,_xlfn.LOGNORM.INV(RAND(),MV2,Sigma1),IF(RAND()<CondGood,_xlfn.LOGNORM.INV(RAND(),MV3,Sigma2),MIN(MaxMultiple,Xm/(1-RAND())^(1/Alpha))))) -> 1.7921005 | Q12: =IF(RAND()<P_Zero,0,IF(RAND()<CondReturn,_xlfn.LOGNORM.INV(RAND(),MV2,Sigma1),IF(RAND()<CondGood,_xlfn.LOGNORM.INV(RAND(),MV3,Sigma2),MIN(MaxMultiple,Xm/(1-RAND())^(1/Alpha))))) -> 1.7345568 | R12: =IF(RAND()<P_Zero,0,IF(RAND()<CondReturn,_xlfn.LOGNORM.INV(RAND(),MV2,Sigma1),IF(RAND()<CondGood,_xlfn.LOGNORM.INV(RAND(),MV3,Sigma2),MIN(MaxMultiple,Xm/(1-RAND())^(1/Alpha))))) -> 1.0661423 | S12: =IF(RAND()<P_Zero,0,IF(RAND()<CondReturn,_xlfn.LOGNORM.INV(RAND(),MV2,Sigma1),IF(RAND()<CondGood,_xlfn.LOGNORM.INV(RAND(),MV3,Sigma2),MIN(MaxMultiple,Xm/(1-RAND())^(1/Alpha))))) -> 0 | T12: =IF(RAND()<P_Zero,0,IF(RAND()<CondReturn,_xlfn.LOGNORM.INV(RAND(),MV2,Sigma1),IF(RAND()<CondGood,_xlfn.LOGNORM.INV(RAND(),MV3,Sigma2),MIN(MaxMultiple,Xm/(1-RAND())^(1/Alpha))))) -> 0.92871864 | U12: =IF(RAND()<P_Zero,0,IF(RAND()<CondReturn,_xlfn.LOGNORM.INV(RAND(),MV2,Sigma1),IF(RAND()<CondGood,_xlfn.LOGNORM.INV(RAND(),MV3,Sigma2),MIN(MaxMultiple,Xm/(1-RAND())^(1/Alpha))))) -> 0 | V12: =IF(RAND()<P_Zero,0,IF(RAND()<CondReturn,_xlfn.LOGNORM.INV(RAND(),MV2,Sigma1),IF(RAND()<CondGood,_xlfn.LOGNORM.INV(RAND(),MV3,Sigma2),MIN(MaxMultiple,Xm/(1-RAND())^(1/Alpha))))) -> 1.5588884 | W12: =IF(RAND()<P_Zero,0,IF(RAND()<CondReturn,_xlfn.LOGNORM.INV(RAND(),MV2,Sigma1),IF(RAND()<CondGood,_xlfn.LOGNORM.INV(RAND(),MV3,Sigma2),MIN(MaxMultiple,Xm/(1-RAND())^(1/Alpha))))) -> 0 | X12: =IF(RAND()<P_Zero,0,IF(RAND()<CondReturn,_xlfn.LOGNORM.INV(RAND(),MV2,Sigma1),IF(RAND()<CondGood,_xlfn.LOGNORM.INV(RAND(),MV3,Sigma2),MIN(MaxMultiple,Xm/(1-RAND())^(1/Alpha))))) -> 0 | Y12: =IF(RAND()<P_Zero,0,IF(RAND()<CondReturn,_xlfn.LOGNORM.INV(RAND(),MV2,Sigma1),IF(RAND()<CondGood,_xlfn.LOGNORM.INV(RAND(),MV3,Sigma2),MIN(MaxMultiple,Xm/(1-RAND())^(1/Alpha))))) -> 1.2819161 | Z12: =IF(RAND()<P_Zero,0,IF(RAND()<CondReturn,_xlfn.LOGNORM.INV(RAND(),MV2,Sigma1),IF(RAND()<CondGood,_xlfn.LOGNORM.INV(RAND(),MV3,Sigma2),MIN(MaxMultiple,Xm/(1-RAND())^(1/Alpha))))) -> 1.8105765 | AA12: =IF(RAND()<P_Zero,0,IF(RAND()<CondReturn,_xlfn.LOGNORM.INV(RAND(),MV2,Sigma1),IF(RAND()<CondGood,_xlfn.LOGNORM.INV(RAND(),MV3,Sigma2),MIN(MaxMultiple,Xm/(1-RAND())^(1/Alpha))))) -> 0 | AB12: =AVERAGE(C12:AA12) -> 0.67859342 | AC12: =AB12*InvestableCapital -> 32572484 | AD12: =AC12-InvestableCapital -> -15427516 | AE12: =HurdleToggle*InvestableCapital*((1+HurdleRate)^FeeYears-1) -> 55628400 | AF12: =MAX(0,AD12-AE12) -> 0 | AG12: =CarryRate*AF12 -> 0 | AH12: =AC12-AG12 -> 32572484 | AI12: =AH12/FundSize -> 0.54287474
