Workbook

Sheet Cover Page
A1: VERIZON / VODAFONE – M&A Deal Analysis
A2: Transaction: Verizon acquires Vodafone's 45% stake in Verizon Wireless | Announced Sep 2 2013 | Closed Feb 21 2014
A4: Currently Running | B4: Base Case
A10: All Data From:
A11: Pitchbook
A12: Verizon SEC 10k Filings
A13: Bloomberg
A14: Yahoo Finance
A15: Federal Reserve Economic Data - St. Louis Fed

Sheet Data Validation
A1: VERIZON / VODAFONE – Data Validation
A2: Used for BBB case switching
B4: Case Switcher | D4: Verizon Rev Growth Rates | F4: Vodafone Rev Growth Rates | H4: Paydown Amounts | J4: Paydown Switcher
B5: Base Case | D5: 0.03 | F5: 0.01 | H5: 5000000000 | J5: $5B
B6: Bear Case | D6: 0.02 | F6: -0.01 | H6: 10000000000 | J6: $10B
B7: Bull Case | D7: 0.04 | F7: 0.03 | H7: 20000000000 | J7: $20B

Sheet Counterfactual Analysis ->
A1: VERIZON / VODAFONE – COUNTERFACTUAL ANALYSIS

Sheet Verizon Counterfactual DCF
A1: Counterfactual DCF Assuming Verizon Continued after 2012
C2: Historical Financials, All Amounts in Thousands | L2: Forecasted Financials, All Amounts in Thousands | S2: WACC Calculations, All Amounts as Normal | V2: Implied Share Price Assuming No Deal with Vodafone
G3: Merger Announced | H3: Merger Closed | L3: 1 | M3: =L3+1 -> 2 | N3: =M3+1 -> 3 | O3: =N3+1 -> 4 | P3: =O3+1 -> 5 | Q3: =P3+1 -> 6
B4: Operating and Financial Summary | C4: FY2009 | D4: FY2010 | E4: FY2011 | F4: FY2012 | G4: FY2013 | H4: FY2014 | I4: CAGR | J4: Rev Growth Rate | K4: Average | L4: FY2013 | M4: FY2014 | N4: FY2015 | O4: FY2016 | P4: FY2017 | Q4: FY2018
B5: Revenue | C5: 107808000 | D5: 106565000 | E5: 110875000 | F5: 115846000 | G5: 120550000 | H5: 127079000 | I5: =('Verizon Counterfactual DCF'!$G5/'Verizon Counterfactual DCF'!$C5)^(1/5)-1 -> 0.022594011 | J5: {=_xlfn.SWITCH('Cover Page'!B4,'Data Validation'!B5,'Data Validation'!D5,'Data Validation'!B6,'Data Validation'!D6,'Data Validation'!B7,'Data Validation'!D7)} -> 0.03 | K5: =AVERAGE(K6,I5) -> 0.02814851 | L5: ='Verizon Counterfactual DCF'!$F5*(1+$J$5) -> 119321380 | M5: =L5*(1+$J$5) -> 1.2290102e+08 | N5: =M5*(1+$J$5) -> 1.2658805e+08 | O5: =N5*(1+$J$5) -> 1.3038569e+08 | P5: =O5*(1+$J$5) -> 1.3429726e+08 | Q5: =P5*(1+$J$5) -> 1.3832618e+08 | S5: WACC Calculation | T5: =((T18/T17)*T13)+((T19/T17)*T8*(1-T15)) -> 0.047013644 | V5: December 31st 2012 MOC Price | W5: 43.27
B6: Growth % | C6: - | D6: =(D5-C5)/C5 -> -0.011529757 | E6: =(E5-D5)/D5 -> 0.040444799 | F6: =(F5-E5)/E5 -> 0.044834273 | G6: =(G5-F5)/F5 -> 0.040605632 | H6: =(H5-G5)/G5 -> 0.0541601 | K6: =AVERAGE(D6:H6) -> 0.033703009 | V6: Fully Diluted Shares O/S | W6: 2800000000
B7: COGS | C7: 44579000 | D7: 44149000 | E7: 45875000 | F7: 46275000 | G7: 44887000 | H7: 49931000 | L7: =L5*$K$8 -> 47853186 | M7: =M5*$K$8 -> 49288781 | N7: =N5*$K$8 -> 50767445 | O7: =O5*$K$8 -> 52290468 | P7: =P5*$K$8 -> 53859182 | Q7: =Q5*$K$8 -> 55474957 | S7: RF rate | T7: 0.0304 | V7: Market Cap | W7: =W5*W6 -> 1.21156e+11
B8: % of Rev | C8: =C7/C5 -> 0.41350364 | D8: =D7/D5 -> 0.41429175 | E8: =E7/E5 -> 0.41375423 | F8: =F7/F5 -> 0.39945272 | G8: =G7/G5 -> 0.37235172 | H8: =H7/H5 -> 0.39291307 | K8: =AVERAGE('Verizon Counterfactual DCF'!$C8:$H8) -> 0.40104452 | S8: AVG Cost of debt | T8: =K34 -> 0.048263087
B9: EBITDA | C9: 33081000 | D9: 31520000 | E9: 29738000 | F9: 28871000 | G9: 48486000 | H9: 36610000 | L9: =L5*$K$10 -> 36002418 | M9: =M5*$K$10 -> 37082491 | N9: =N5*$K$10 -> 38194965 | O9: =O5*$K$10 -> 39340814 | P9: =P5*$K$10 -> 40521039 | Q9: =Q5*$K$10 -> 41736670 | V9: TV | W9: =W10*0.5+(W11*0.5) -> 3.1045665e+11
B10: % of Rev | C10: =C9/C5 -> 0.30685107 | D10: =D9/D5 -> 0.29578192 | E10: =E9/E5 -> 0.26821195 | F10: =F9/F5 -> 0.24921879 | G10: =G9/G5 -> 0.40220655 | H10: =H9/H5 -> 0.28808851 | K10: =AVERAGE('Verizon Counterfactual DCF'!$C10:$H10) -> 0.30172647 | S10: Beta | T10: 0.3 | V10: Exit Multiple | W10: =((Q9*1000)*W20)/(1+T5)^Q3 -> 2.5345084e+11
B11: D&A | C11: 16534000 | D11: 16405000 | E11: 16496000 | F11: 16460000 | G11: 16606000 | H11: 16533000 | L11: =L5*$K$12 -> 17222576 | M11: =M5*$K$12 -> 17739253 | N11: =N5*$K$12 -> 18271431 | O11: =O5*$K$12 -> 18819574 | P11: =P5*$K$12 -> 19384161 | Q11: =Q5*$K$12 -> 19965686 | S11: Rm | T11: 0.1 | V11: Perpetuity Growth | W11: =(((Q30*1000)*(1+W19))/(T5-W19))/(1+T5)^Q3 -> 3.6746246e+11
B12: % of Rev | C12: =C11/C5 -> 0.15336524 | D12: =D11/D5 -> 0.1539436 | E12: =E11/E5 -> 0.14878016 | F12: =F11/F5 -> 0.14208518 | G12: =G11/G5 -> 0.13775197 | H12: =H11/H5 -> 0.13010017 | K12: =AVERAGE('Verizon Counterfactual DCF'!$C12:$H12) -> 0.14433772
B13: EBIT | C13: 16547000 | D13: 15115000 | E13: 13242000 | F13: 12411000 | G13: 31880000 | H13: 20077000 | L13: =L9-L11 -> 18779842 | M13: =M9-M11 -> 19343237 | N13: =N9-N11 -> 19923535 | O13: =O9-O11 -> 20521241 | P13: =P9-P11 -> 21136878 | Q13: =Q9-Q11 -> 21770984 | S13: CAPM | T13: =(T7+(T10*(T11-T7))) -> 0.05128 | V13: Enterprise Value | W13: =W9+(L38*1000) -> 3.737337e+11
B14: EBT | C14: 13520000 | D14: 12684000 | E14: 10483000 | F14: 9897000 | G14: 29277000 | H14: 15270000 | L14: =L13-L35 -> 15646917 | M14: =M13-M35 -> 16116325 | N14: =N13-N35 -> 16599814 | O14: =O13-O35 -> 17097809 | P14: =P13-P35 -> 17610743 | Q14: =Q13-Q35 -> 18139065 | V14: Equity Value Firm | W14: =W13-(F37*1000) -> 3.253097e+11
B15: Income Tax | C15: 1919000 | D15: 2467000 | E15: 285000 | F15: -660000 | G15: 5730000 | H15: 3314000 | L15: =L14*L16 -> 3628520.1 | M15: =M14*M16 -> 3737375.7 | N15: =N14*N16 -> 3849497 | O15: =O14*O16 -> 3964981.9 | P15: =P14*P16 -> 4083931.3 | Q15: =Q14*Q16 -> 4206449.3 | S15: Tax Rate | T15: ='Assumptions (3) Old'!F17 -> 0.2319 | V15: Equity Value Verizon | W15: =W14-(W14*0.45) -> 1.7892034e+11
B16: ETR | C16: 0.2319 | D16: 0.2319 | E16: 0.2319 | F16: 0.2319 | G16: 0.2319 | H16: 0.2319 | L16: 0.2319 | M16: 0.2319 | N16: 0.2319 | O16: 0.2319 | P16: 0.2319 | Q16: 0.2319
B17: NOPAT | C17: =C13*(1-C16) -> 12709751 | D17: =D13*(1-D16) -> 11609832 | E17: =E13*(1-E16) -> 10171180 | F17: =F13*(1-F16) -> 9532889.1 | G17: =G13*(1-G16) -> 24487028 | H17: =H13*(1-H16) -> 15421144 | L17: =L14*(1-L16) -> 12018397 | M17: =M14*(1-M16) -> 12378949 | N17: =N14*(1-N16) -> 12750317 | O17: =O14*(1-O16) -> 13132827 | P17: =P14*(1-P16) -> 13526812 | Q17: =Q14*(1-Q16) -> 13932616 | S17: Value of firm | T17: =T18+T19 -> 173143000000 | V17: Implied Share price | W17: =W15/W6 -> 63.90012
B18: Capex | C18: 16872000 | D18: 17244000 | E18: 16465000 | F18: 20473000 | G18: 17184000 | H18: 17545000 | L18: =L5*$K$19 -> 18378558 | M18: =M5*$K$19 -> 18929914 | N18: =N5*$K$19 -> 19497812 | O18: =O5*$K$19 -> 20082746 | P18: =P5*$K$19 -> 20685228 | Q18: =Q5*$K$19 -> 21305785 | S18: MKT Cap | T18: =W7 -> 1.21156e+11
B19: % of Rev | C19: =C18/C5 -> 0.15650045 | D19: =D18/D5 -> 0.16181673 | E19: =E18/E5 -> 0.14850056 | F19: =F18/F5 -> 0.176726 | G19: =G18/G5 -> 0.14254666 | H19: =H18/H5 -> 0.13806372 | K19: =AVERAGE(C19:H19) -> 0.15402569 | S19: Total Debt | T19: =F33*1000 -> 51987000000 | V19: Growth rate | W19: 0.02
B20: AR | C20: 12573000 | D20: 11781000 | E20: 11776000 | F20: 12576000 | G20: 12439000 | H20: 13993000 | L20: =L5*$K$21 -> 13030727 | M20: =M5*$K$21 -> 13421649 | N20: =N5*$K$21 -> 13824298 | O20: =O5*$K$21 -> 14239027 | P20: =P5*$K$21 -> 14666198 | Q20: =Q5*$K$21 -> 15106184 | V20: Multiple | W20: 8
B21: % of Rev | C21: =C20/C5 -> 0.116624 | D21: =D20/D5 -> 0.11055225 | E21: =E20/E5 -> 0.1062097 | F21: =F20/F5 -> 0.10855791 | G21: =G20/G5 -> 0.1031854 | H21: =H20/H5 -> 0.11011261 | K21: =AVERAGE(C21:H21) -> 0.10920698
B22: Inventory | C22: 1426000 | D22: 1131000 | E22: 940000 | F22: 1075000 | G22: 1020000 | H22: 1153000 | L22: =L7*$K$23 -> 1173541.1 | M22: =M7*$K$23 -> 1208747.3 | N22: =N7*$K$23 -> 1245009.8 | O22: =O7*$K$23 -> 1282360.1 | P22: =P7*$K$23 -> 1320830.9 | Q22: =Q7*$K$23 -> 1360455.8 | V22: Counterfactual Growth % | W22: =W17/W5-1 -> 0.47677651
B23: % of COGS | C23: =C22/C7 -> 0.031988156 | D23: =D22/D7 -> 0.025617794 | E23: =E22/E7 -> 0.020490463 | F23: =F22/F7 -> 0.023230686 | G23: =G22/G7 -> 0.022723728 | H23: =H22/H7 -> 0.023091867 | K23: =AVERAGE(C23:H23) -> 0.024523782 | V23: Realized Growth % | W23: =(37.65/22.06)-1 -> 0.70670898
B24: AP | C24: 13361000 | D24: 13259000 | E24: 11986000 | F24: 8141000 | G24: 9248000 | H24: 10840000 | L24: =L7*$K$25 -> 11647217 | M24: =M7*$K$25 -> 11996633 | N24: =N7*$K$25 -> 12356532 | O24: =O7*$K$25 -> 12727228 | P24: =P7*$K$25 -> 13109045 | Q24: =Q7*$K$25 -> 13502316
B25: % of COGS | C25: =C24/C7 -> 0.29971511 | D25: =D24/D7 -> 0.3003239 | E25: =E24/E7 -> 0.2612752 | F25: =F24/F7 -> 0.17592653 | G25: =G24/G7 -> 0.20602847 | H25: =H24/H7 -> 0.2170996 | K25: =AVERAGE(C25:H25) -> 0.2433948
B26: Accrued Expenses | C26: 8570000 | D26: 9796000 | E26: 8643000 | F26: 9535000 | G26: 8744000 | H26: 8147000 | L26: =L5*$K$27 -> 9313479.8 | M26: =M5*$K$27 -> 9592884.2 | N26: =N5*$K$27 -> 9880670.7 | O26: =O5*$K$27 -> 10177091 | P26: =P5*$K$27 -> 10482404 | Q26: =Q5*$K$27 -> 10796876
B27: % of Rev | C27: =C26/C5 -> 0.079493173 | D27: =D26/D5 -> 0.091925116 | E27: =E26/E5 -> 0.077952649 | F27: =F26/F5 -> 0.082307546 | G27: =G26/G5 -> 0.072534218 | H27: =H26/H5 -> 0.064109727 | K27: =AVERAGE(C27:H27) -> 0.078053738
B28: NWC | C28: =(C20+C22)-(C24+C26) -> -7932000 | D28: =(D20+D22)-(D24+D26) -> -10143000 | E28: =(E20+E22)-(E24+E26) -> -7913000 | F28: =(F20+F22)-(F24+F26) -> -4025000 | G28: =(G20+G22)-(G24+G26) -> -4533000 | H28: =(H20+H22)-(H24+H26) -> -3841000 | L28: =(L20+L22)-(L24+L26) -> -6756428.2 | M28: =(M20+M22)-(M24+M26) -> -6959121 | N28: =(N20+N22)-(N24+N26) -> -7167894.7 | O28: =(O20+O22)-(O24+O26) -> -7382931.5 | P28: =(P20+P22)-(P24+P26) -> -7604419.4 | Q28: =(Q20+Q22)-(Q24+Q26) -> -7832552
B29: Changes in NWC | C29: 0 | D29: =D28-C28 -> -2211000 | E29: =E28-D28 -> 2230000 | F29: =F28-E28 -> 3888000 | G29: =G28-F28 -> -508000 | H29: =H28-G28 -> 692000 | L29: =L28-F28 -> -2731428.2 | M29: =M28-L28 -> -202692.85 | N29: =N28-M28 -> -208773.63 | O29: =O28-N28 -> -215036.84 | P29: =P28-O28 -> -221487.94 | Q29: =Q28-P28 -> -228132.58
B30: FCFF | C30: 19690709 | D30: 17950538 | E30: 18344671 | F30: 13087150 | G30: 23783268 | H30: 19094445 | L30: =L17+L11-L18-L29 -> 13593844 | M30: =M17+M11-M18-M29 -> 11390981 | N30: =N17+N11-N18-N29 -> 11732710 | O30: =O17+O11-O18-O29 -> 12084692 | P30: =P17+P11-P18-P29 -> 12447232 | Q30: =Q17+Q11-Q18-Q29 -> 12820649
B31: Short Term Debt | C31: 7205000 | D31: 7542000 | E31: 4849000 | F31: 4369000 | G31: 3933000 | H31: 2735000
B32: LT Debt | C32: 55051000 | D32: 45252000 | E32: 50303000 | F32: 47618000 | G32: 89658000 | H32: 110536000
B33: Total Debt | C33: =SUM(C31:C32) -> 62256000 | D33: =SUM(D31:D32) -> 52794000 | E33: =SUM(E31:E32) -> 55152000 | F33: =SUM(F31:F32) -> 51987000 | G33: =SUM(G31:G32) -> 93591000 | H33: =SUM(H31:H32) -> 113271000 | L33: =L9*$K$40 -> 64913481 | M33: =M9*$K$40 -> 66860886 | N33: =N9*$K$40 -> 68866712 | O33: =O9*$K$40 -> 70932714 | P33: =P9*$K$40 -> 73060695 | Q33: =Q9*$K$40 -> 75252516
B34: Avg Int Rate | C34: =C35/C33 -> 0.04862182 | D34: =D35/D33 -> 0.046046899 | E34: =E35/E33 -> 0.050025384 | F34: =F35/F33 -> 0.048358243 | G34: =G35/G33 -> 0.027812503 | H34: =H35/H33 -> 0.042438047 | K34: =AVERAGE(C34:F34) -> 0.048263087
B35: Interest Expense | C35: 3027000 | D35: 2431000 | E35: 2759000 | F35: 2514000 | G35: 2603000 | H35: 4807000 | L35: =L33*$K$34 -> 3132925 | M35: =M33*$K$34 -> 3226912.7 | N35: =N33*$K$34 -> 3323720.1 | O35: =O33*$K$34 -> 3423431.7 | P35: =P33*$K$34 -> 3526134.7 | Q35: =Q33*$K$34 -> 3631918.7
B36: C&CE | C36: 2499000 | D36: 7213000 | E36: 13954000 | F36: 3563000 | G36: 54129000 | H36: 11153000
B37: Net Debt | C37: =C33-C36 -> 59757000 | D37: =D33-D36 -> 45581000 | E37: =E33-E36 -> 41198000 | F37: =F33-F36 -> 48424000 | G37: =G33-G36 -> 39462000 | H37: =H33-H36 -> 102118000 | J37: Discounted FCF | L37: =L30/(1+$T$5)^L3 -> 12983445 | M37: =M30/(1+$T$5)^M3 -> 10390978 | N37: =N30/(1+$T$5)^N3 -> 10222128 | O37: =O30/(1+$T$5)^O3 -> 10056022 | P37: =P30/(1+$T$5)^P3 -> 9892614.7 | Q37: =Q30/(1+$T$5)^Q3 -> 9731862.8
B38: Total Shareholder Equity | C38: 84143000 | D38: 86912000 | E38: 85908000 | F38: 85533000 | G38: 95416000 | H38: 13676000 | J38: Sum of FCF | L38: =SUM(L37:Q37) -> 63277051
B39: Debt to Equity | C39: =C33/C38 -> 0.73988329 | D39: =D33/D38 -> 0.60744201 | E39: =E33/E38 -> 0.6419891 | F39: =F33/F38 -> 0.6078005 | G39: =G33/G38 -> 0.98087323 | H39: =H33/H38 -> 8.2824656
B40: Debt to Ebitda | C40: =C33/C9 -> 1.8819262 | D40: =D33/D9 -> 1.6749365 | E40: =E33/E9 -> 1.8545968 | F40: =F33/F9 -> 1.800665 | G40: =G33/G9 -> 1.9302685 | H40: =H33/H9 -> 3.0939907 | K40: =AVERAGE('Verizon Counterfactual DCF'!$C40:$F40) -> 1.8030311

Sheet Counterfactual Buybacks&Paydown
B2: Average Interest Rate | C2: ='Verizon Counterfactual DCF'!T8 -> 0.048263087
B3: December 31st 2012 MOC Price | C3: 43.27
B4: Fully Diluted Shares O/S | C4: 2800000000
B5: Market Cap | C5: 1.21156e+11
B7: TV | C7: 3.1045665e+11
B8: Exit Multiple | C8: 2.5345084e+11
B9: Perpetuity Growth | C9: 3.6746246e+11
B11: Enterprise Value | C11: 3.737337e+11
B12: Equity Value Firm | C12: 3.253097e+11
B13: Equity Value Verizon | C13: 1.7892034e+11
B15: Implied Share price | C15: 63.90012
B18: Buyback Accretion | C18: $ Amount | D18: Share Price | E18: Amount of shares Bought Back | G18: New Share Count | I18: New Share Price | K18: Average Repurchase Price | M18: Actual Shares bought back | N18: Actual Shares Remaining
B19: Total Budget | C19: 130000000000
B20: Cash (new debt + BS) | C20: 58893000000 | D20: 43.27 | E20: =C20/D20 -> 1.3610585e+09 | G20: =$C$4-E20 -> 1.4389415e+09 | I20: =$C$13/G20 -> 124.34163 | K20: =(I20+D20)/2 -> 83.805815 | M20: =C20/K20 -> 7.0273167e+08 | N20: =$C$4-M20 -> 2.0972683e+09
B21: CCE 2012 | C21: ='Verizon Counterfactual DCF'!F36*1000 -> 3563000000 | D21: 43.27 | E21: =C21/D21 -> 82343425 | G21: =$C$4-E21 -> 2.7176566e+09 | I21: =$C$13/G21 -> 65.836256 | K21: =(I21+D21)/2 -> 54.553128 | M21: =C21/K21 -> 65312478 | N21: =$C$4-M21 -> 2.7346875e+09
B22: 5B Buyback | C22: 5000000000 | D22: 43.27 | E22: =C22/D22 -> 1.155535e+08 | G22: =$C$4-E22 -> 2.6844465e+09 | I22: =$C$13/G22 -> 66.650736 | K22: =(I22+D22)/2 -> 54.960368 | M22: =C22/K22 -> 90974646 | N22: =$C$4-M22 -> 2.7090254e+09
B23: 10B Buyback | C23: 10000000000 | D23: 43.27 | E23: =C23/D23 -> 2.31107e+08 | G23: =$C$4-E23 -> 2.568893e+09 | I23: =$C$13/G23 -> 69.648808 | K23: =(I23+D23)/2 -> 56.459404 | M23: =C23/K23 -> 1.7711841e+08 | N23: =$C$4-M23 -> 2.6228816e+09
B24: 20B Buyback | C24: 20000000000 | D24: 43.27 | E24: =C24/D24 -> 4.6221401e+08 | G24: =$C$4-E24 -> 2.337786e+09 | I24: =$C$13/G24 -> 76.534095 | K24: =(I24+D24)/2 -> 59.902047 | M24: =C24/K24 -> 3.338784e+08 | N24: =$C$4-M24 -> 2.4661216e+09
B27: Item | C27: FY2012A | D27: FY2013A | E27: FY2014A | F27: FY2013E | G27: FY2014E | H27: FY2015E | I27: FY2016E | J27: FY2017E | K27: FY2018E
B28: Net Income | C28: ='Verizon Counterfactual DCF'!F9-'Verizon Counterfactual DCF'!F11-'Verizon Counterfactual DCF'!F35-'Verizon Counterfactual DCF'!F15 -> 10557000 | D28: ='Verizon Counterfactual DCF'!G9-'Verizon Counterfactual DCF'!G11-'Verizon Counterfactual DCF'!G35-'Verizon Counterfactual DCF'!G15 -> 23547000 | E28: ='Verizon Counterfactual DCF'!H9-'Verizon Counterfactual DCF'!H11-'Verizon Counterfactual DCF'!H35-'Verizon Counterfactual DCF'!H15 -> 11956000 | F28: ='Verizon Counterfactual DCF'!L9-'Verizon Counterfactual DCF'!L11-'Verizon Counterfactual DCF'!L35-'Verizon Counterfactual DCF'!L15 -> 12018397 | G28: ='Verizon Counterfactual DCF'!M9-'Verizon Counterfactual DCF'!M11-'Verizon Counterfactual DCF'!M35-'Verizon Counterfactual DCF'!M15 -> 12378949 | H28: ='Verizon Counterfactual DCF'!N9-'Verizon Counterfactual DCF'!N11-'Verizon Counterfactual DCF'!N35-'Verizon Counterfactual DCF'!N15 -> 12750317 | I28: ='Verizon Counterfactual DCF'!O9-'Verizon Counterfactual DCF'!O11-'Verizon Counterfactual DCF'!O35-'Verizon Counterfactual DCF'!O15 -> 13132827 | J28: ='Verizon Counterfactual DCF'!P9-'Verizon Counterfactual DCF'!P11-'Verizon Counterfactual DCF'!P35-'Verizon Counterfactual DCF'!P15 -> 13526812 | K28: ='Verizon Counterfactual DCF'!Q9-'Verizon Counterfactual DCF'!Q11-'Verizon Counterfactual DCF'!Q35-'Verizon Counterfactual DCF'!Q15 -> 13932616
B29: EPS No Buybacks | C29: =(1000*C28)/$C$4 -> 3.7703571 | D29: =(1000*D28)/$C$4 -> 8.4096429 | E29: =(1000*E28)/$C$4 -> 4.27 | F29: =(1000*F28)/$C$4 -> 4.2922847 | G29: =(1000*G28)/$C$4 -> 4.4210532 | H29: =(1000*H28)/$C$4 -> 4.5536848 | I29: =(1000*I28)/$C$4 -> 4.6902953 | J29: =(1000*J28)/$C$4 -> 4.8310042 | K29: =(1000*K28)/$C$4 -> 4.9759343
B30: EPS 5B | C30: =($C$28*1000)/$N$22 -> 3.8969735 | D30: =(D$28*1000)/$N22 -> 8.692056 | E30: =(E$28*1000)/$N22 -> 4.4133954 | F30: =(F$28*1000)/$N22 -> 4.4364284 | G30: =(G$28*1000)/$N22 -> 4.5695213 | H30: =(H$28*1000)/$N22 -> 4.7066069 | I30: =(I$28*1000)/$N22 -> 4.8478051 | J30: =(J$28*1000)/$N22 -> 4.9932393 | K30: =(K$28*1000)/$N22 -> 5.1430364
B31: EPS 10B | C31: =($C$28*1000)/$N$21 -> 3.8604045 | D31: =(D$28*1000)/$N23 -> 8.9775307 | E31: =(E$28*1000)/$N23 -> 4.5583453 | F31: =(F$28*1000)/$N23 -> 4.5821348 | G31: =(G$28*1000)/$N23 -> 4.7195989 | H31: =(H$28*1000)/$N23 -> 4.8611868 | I31: =(I$28*1000)/$N23 -> 5.0070224 | J31: =(J$28*1000)/$N23 -> 5.1572331 | K31: =(K$28*1000)/$N23 -> 5.3119501
B32: EPS 20B | C32: =($C$28*1000)/$N$22 -> 3.8969735 | D32: =(D$28*1000)/$N24 -> 9.548191 | E32: =(E$28*1000)/$N24 -> 4.8480983 | F32: =(F$28*1000)/$N24 -> 4.8734 | G32: =(G$28*1000)/$N24 -> 5.019602 | H32: =(H$28*1000)/$N24 -> 5.1701901 | I32: =(I$28*1000)/$N24 -> 5.3252958 | J32: =(J$28*1000)/$N24 -> 5.4850547 | K32: =(K$28*1000)/$N24 -> 5.6496063
B38: Case | C38: $5B
B39: Item | C39: 0 | D39: FY2013A | E39: FY2014A | F39: FY2013E | G39: FY2014E | H39: FY2015E | I39: FY2016E | J39: FY2017E | K39: FY2018E
B40: New Net Income | C40: =C43+(C44*(1-C45)) -> 1.2298849e+10 | D40: =D43+(D44*(1-D45)) -> 2.6831146e+10 | E40: =E43+(E44*(1-E45)) -> 1.5969701e+10 | F40: =F43+(F44*(1-F45)) -> 1.4239442e+10 | G40: =G43+(G44*(1-G45)) -> 1.4672186e+10 | H40: =H43+(H44*(1-H45)) -> 1.5117912e+10 | I40: =I43+(I44*(1-I45)) -> 1.557701e+10 | J40: =J43+(J44*(1-J45)) -> 1.6049881e+10 | K40: =K43+(K44*(1-K45)) -> 1.6536938e+10
B41: Debt Repaid | C41: {=_xlfn.SWITCH(C38,'Data Validation'!J5,'Data Validation'!H5,'Data Validation'!J6,'Data Validation'!H6,'Data Validation'!J7,'Data Validation'!H7)} -> 5000000000
B42: Total Debt | C42: ='Verizon Counterfactual DCF'!F33*1000 -> 51987000000 | D42: ='Verizon Counterfactual DCF'!G33*1000 -> 93591000000 | E42: ='Verizon Counterfactual DCF'!H33*1000 -> 113271000000 | F42: 6.4913481e+10 | G42: 6.6860886e+10 | H42: 6.8866712e+10 | I42: 7.0932714e+10 | J42: 7.3060695e+10 | K42: 7.5252516e+10
B43: Old Net Income | C43: 10557000000 | D43: 23547000000 | E43: 11956000000 | F43: 1.2018397e+10 | G43: 1.2378949e+10 | H43: 1.2750317e+10 | I43: 1.3132827e+10 | J43: 1.3526812e+10 | K43: 1.3932616e+10
B44: Interest Savings | C44: =(C42-$C$41)*$C$2 -> 2.2677377e+09 | D44: =(D42-$C$41)*$C$2 -> 4.2756751e+09 | E44: =(E42-$C$41)*$C$2 -> 5.2254927e+09 | F44: =(F42-$C$41)*$C$2 -> 2.8916095e+09 | G44: =(G42-$C$41)*$C$2 -> 2.9855973e+09 | H44: =(H42-$C$41)*$C$2 -> 3.0824047e+09 | I44: =(I42-$C$41)*$C$2 -> 3.1821163e+09 | J44: =(J42-$C$41)*$C$2 -> 3.2848192e+09 | K44: =(K42-$C$41)*$C$2 -> 3.3906033e+09
B45: Tax Rate | C45: 0.2319 | D45: 0.2319 | E45: 0.2319 | F45: 0.2319 | G45: 0.2319 | H45: 0.2319 | I45: 0.2319 | J45: 0.2319 | K45: 0.2319
B46: New EPS | C46: =C40/$C$4 -> 4.3924462 | D46: =D40/$C$4 -> 9.5825522 | E46: =E40/$C$4 -> 5.7034646 | F46: =F40/$C$4 -> 5.0855151 | G46: =G40/$C$4 -> 5.2400665 | H46: =H40/$C$4 -> 5.3992545 | I46: =I40/$C$4 -> 5.563218 | J46: =J40/$C$4 -> 5.7321005 | K46: =K40/$C$4 -> 5.9060495
B47: Actual EPS | C47: 0.31 | D47: 4.01 | E47: 2.42 | F47: 4.01 | G47: 2.42 | H47: 4.38 | I47: 3.22 | J47: 7.37 | K47: 3.76

Sheet EPS Accretion V1

Sheet Assumptions
A1: VERIZON / VODAFONE – EPS ACCRETION / DILUTION MODEL (v1)
A2: Transaction: Verizon acquires Vodafone's 45% stake in Verizon Wireless | Announced Sep 2 2013 | Closed Feb 21 2014
A4: A. ACQUIRER – VERIZON COMMUNICATIONS (VZ) | E4: B. TARGET / DEAL TERMS – VODAFONE 45% STAKE
A5: Assumption | B5: Value | C5: Notes / Source | E5: Assumption | F5: Value | G5: Notes / Source
A6: Share Price (at announcement) | B6: 46.31 | C6: Bloomberg, Sep 2 2013 | E6: Total Transaction Value ($mm) | F6: 130000 | G6: VZ press release, Sep 2 2013
A7: Diluted Shares Outstanding (mm) | B7: 2868 | C7: VZ 10-K FY2013, p.38 | E7: Cash Consideration ($mm) | F7: 58893 | G7: VZ 8-K, Sep 2 2013
A8: Market Capitalization ($mm) | B8: 132817.08 | C8: Calculated | E8: VZ Stock Consideration ($mm) | F8: 60895 | G8: VZ 8-K Sep 2 2013 (new VZ shares)
A9: Net Debt ($mm) | B9: 45922 | C9: VZ 10-K FY2013, p.42 | E9: Verizon Notes to Vodafone ($mm) | F9: 3500 | G9: 8.5-yr notes, 5.9% coupon
A10: Enterprise Value ($mm) | B10: 178739.08 | C10: Calculated | E10: Other (Omnitel stake, misc.) ($mm) | F10: 6712 | G10: Calculated
A12: Historical Net Income – 2009 ($mm) | B12: 4894 | C12: VZ 10-K FY2009 (SEC EDGAR) | E12: New Shares Issued (mm) | F12: 1274 | G12: VZ 8-K – 1,274mm new VZ shares
A13: Historical Net Income – 2010 ($mm) | B13: 2549 | C13: VZ 10-K FY2010 (SEC EDGAR) | E13: Issue Price (implied) | F13: 47.798273 | G13: Avg. price at closing
A14: Historical Net Income – 2011 ($mm) | B14: 2404 | C14: VZ 10-K FY2011 (SEC EDGAR)
A15: Historical Net Income – 2012 ($mm) | B15: 875 | C15: VZ 10-K FY2012 (SEC EDGAR) | E15: New Debt Raised ($mm) | F15: 49000 | G15: VZ record bond offering, Feb 2014
A16: Historical Net Income – 2013 ($mm) | B16: 11497 | C16: VZ 10-K FY2013, p.50 (55% VZW share) | E16: Blended Interest Rate on New Debt | F16: 0.055 | G16: Weighted avg. coupon assumption
A17: 5-Yr Trailing CAGR (2009–2013) | B17: 0.23802707 | C17: CAGR preferred; YoY avg distorted by 2012 dip & 2013 Vodafone distributions | E17: Tax Rate | F17: 0.2319 | G17: Updated: 23.19% blended effective rate
E18: After-tax Interest Cost ($mm) – Yr 1 | F18: 2070.0295 | G18: Calculated
A19: LTM Net Income Attr. to VZ ($mm) | B19: 11497 | C19: 2013 actuals (55% VZW ownership)
A20: Standalone EPS (Diluted) | B20: 4.0087169 | C20: Calculated | E20: Annual Synergies ($mm) – Pre-Tax | F20: 500 | G20: Conservative; VZ guided $1B+ LT
E21: D&A on Purchase Price Step-Up ($mm/yr) | F21: 800 | G21: Est. incremental amortization
A22: NI Growth Rate (Yr 2) – 5yr Trailing CAGR | B22: 0.23802707 | C22: Linked from 5-yr CAGR above | E22: Yr 1 Transaction/Integration Costs ($mm) | F22: 1200 | G22: One-time costs, Year 1 only
A23: NI Growth Rate (Yr 3) – 5yr Trailing CAGR | B23: 0.23802707 | C23: Same rate applied; sensitivities on sheet 2
A25: Pro Forma Net Income – Year 1 ($mm) | B25: 17800 | C25: Mgmt guidance, Feb 2014 IR presentation
A26: Pro Forma Net Income – Year 2 ($mm) | B26: 22036.882 | C26: Calculated using 5-yr CAGR
A27: Pro Forma Net Income – Year 3 ($mm) | B27: 27282.256 | C27: Calculated using 5-yr CAGR
A29: Color Key: Blue = Hardcoded Input Black = Formula Green = Cross-sheet link

Sheet EPS Accretion-Dilution
A1: VERIZON / VODAFONE – EPS ACCRETION / DILUTION ANALYSIS (v1)
A2: $mm unless noted | NI growth = 5-yr trailing CAGR (23.8%) | Tax Rate = 23.19%
A4: Description | B4: Year 1 (FY2014E) | C4: Year 2 (FY2015E) | D4: Year 3 (FY2016E)
A5: 1. PRO FORMA SHARE COUNT
A6: Standalone Diluted Shares (mm) | B6: 2868 | C6: 2868 | D6: 2868
A7: (+) New Shares Issued to Vodafone (mm) | B7: 1274 | C7: 1274 | D7: 1274
A8: Pro Forma Diluted Shares (mm) | B8: 4142 | C8: 4142 | D8: 4142
A10: 2. STANDALONE EPS (55% VZW OWNERSHIP)
A11: Standalone Net Income ($mm) | B11: 11497 | C11: 14233.597 | D11: 17621.579
A12: Standalone Diluted Shares (mm) | B12: 2868 | C12: 2868 | D12: 2868
A13: STANDALONE EPS (Diluted) | B13: 4.0087169 | C13: 4.9629 | D13: 6.1442046
A15: 3. PRO FORMA NET INCOME BRIDGE ($MM)
A16: Standalone Net Income ($mm) | B16: 11497 | C16: 14233.597 | D16: 17621.579
A17: (+) Incr. NI from 100% VZW Ownership | B17: 6303 | C17: 7803.2846 | D17: 9660.6776
A18: (-) After-tax Interest on New Debt | B18: -2070.0295 | C18: -2070.0295 | D18: -2070.0295
A19: (+) After-tax Synergies | B19: 384.05 | C19: 422.455 | D19: 460.86
A20: (-) D&A on Purchase Price Step-Up | B20: -800 | C20: -800 | D20: -800
A21: (-) Transaction / Integration Costs | B21: -1200 | C21: 0 | D21: 0
A22: PRO FORMA NET INCOME ($mm) | B22: 14114.021 | C22: 19589.307 | D22: 24873.087
A24: 4. PRO FORMA EPS & ACCRETION / (DILUTION)
A25: Pro Forma Net Income ($mm) | B25: 14114.021 | C25: 19589.307 | D25: 24873.087
A26: Pro Forma Diluted Shares (mm) | B26: 4142 | C26: 4142 | D26: 4142
A27: PRO FORMA EPS (Diluted) | B27: 3.4075375 | C27: 4.729432 | D27: 6.005091
A29: Standalone EPS | B29: 4.0087169 | C29: 4.9629 | D29: 6.1442046
A30: Pro Forma EPS | B30: 3.4075375 | C30: 4.729432 | D30: 6.005091
A31: $ Accretion / (Dilution) | B31: -0.60117933 | C31: -0.23346801 | D31: -0.13911359
A32: % Accretion / (Dilution) | B32: -0.14996802 | C32: -0.047042658 | D32: -0.022641432
A35: VERIZON / VODAFONE – YEAR 3 EPS SENSITIVITY ANALYSIS
A36: Vary Pre-Tax Synergies ($mm) vs. Pro Forma NI Growth Rate (5-yr CAGR base = 23.8%)
A38: TABLE 1 – PRO FORMA EPS (YEAR 3)
A39: Synergies ($mm) ↓ / NI Grwth → | B39: 10.0% | C39: 15.0% | D39: 23.8% (Base) | E39: 30.0% | F39: 35.0% | G39: 40.0%
A40: 0 | B40: 4.5069943 | C40: 4.9904564 | D40: 5.8935378 | E40: 6.5697659 | F40: 7.1391768 | G40: 7.730075
A41: 250 | B41: 4.5626269 | C41: 5.046089 | D41: 5.9491704 | E41: 6.6253985 | F41: 7.1948094 | G41: 7.7857075
A42: 500 | B42: 4.6182594 | C42: 5.1017215 | D42: 6.0048029 | E42: 6.681031 | F42: 7.2504419 | G42: 7.8413401
A43: 750 | B43: 4.673892 | C43: 5.1573541 | D43: 6.0604355 | E43: 6.7366636 | F43: 7.3060745 | G43: 7.8969726
A44: 1000 | B44: 4.7295245 | C44: 5.2129866 | D44: 6.116068 | E44: 6.7922961 | F44: 7.361707 | G44: 7.9526051
A45: 1500 | B45: 4.8407896 | C45: 5.3242517 | D45: 6.2273331 | E45: 6.9035612 | F45: 7.4729721 | G45: 8.0638702
A46: 2000 | B46: 4.9520547 | C46: 5.4355168 | D46: 6.3385982 | E46: 7.0148263 | F46: 7.5842372 | G46: 8.1751353
A48: TABLE 2 – % ACCRETION / (DILUTION) (YEAR 3)
A49: Synergies ($mm) ↓ / NI Grwth → | B49: 10.0% | C49: 15.0% | D49: 23.8% (Base) | E49: 30.0% | F49: 35.0% | G49: 40.0%
...

Sheet Deal Structure
A1: VERIZON / VODAFONE – DEAL STRUCTURE & CONSIDERATION
A2: Breakdown of $130bn total consideration | Closed February 21, 2014
A4: Consideration Component | B4: Amount ($mm) | C4: % of Total | D4: Notes
A5: Cash (new debt + balance sheet) | B5: 58893 | C5: 0.45302308 | D5: Record bond offering at time ($49bn new debt)
A6: Verizon Stock (new shares) | B6: 60895 | C6: 0.46842308 | D6: 1,274mm new VZ shares issued to Vodafone
A7: Verizon Notes to Vodafone | B7: 3500 | C7: 0.026923077 | D7: 8.5-yr notes, 5.9% coupon
A8: Other (Omnitel, misc.) | B8: 6712 | C8: 0.051630769 | D8: Verizon Italy stake + other
A9: TOTAL CONSIDERATION | B9: 130000 | C9: 1 | D9: Announced Sep 2, 2013
A11: OWNERSHIP – VERIZON WIRELESS
A12: Entity | B12: Pre-Deal % | C12: Post-Deal % | D12: Change
A13: Verizon Communications | B13: 0.55 | C13: 1 | D13: 0.45
A14: Vodafone Group | B14: 0.45 | C14: 0 | D14: -0.45

Sheet EPS Accretion V2

Sheet Assumptions (2)
A1: VERIZON / VODAFONE – EPS ACCRETION / DILUTION MODEL (v3)
A2: Transaction: Verizon acquires Vodafone's 45% stake in Verizon Wireless | Announced Sep 2 2013 | Closed Feb 21 2014
A4: A. ACQUIRER – VERIZON COMMUNICATIONS (VZ) | E4: B. TARGET / DEAL TERMS – VODAFONE 45% STAKE
A5: Assumption | B5: Value | C5: Notes / Source | E5: Assumption | F5: Value | G5: Notes / Source
A6: Share Price (at announcement) | B6: 46.31 | C6: Bloomberg, Sep 2 2013 | E6: Total Transaction Value ($mm) | F6: 130000 | G6: VZ press release, Sep 2 2013
A7: Diluted Shares Outstanding (mm) | B7: 2868 | C7: VZ 10-K FY2013, p.38 (SEC EDGAR) | E7: Cash Consideration ($mm) | F7: 58893 | G7: VZ 8-K, Sep 2 2013
A8: Market Capitalization ($mm) | B8: 132817.08 | C8: Calculated | E8: VZ Stock Consideration ($mm) | F8: 60895 | G8: VZ 8-K Sep 2 2013 (new VZ shares)
A9: Net Debt ($mm) | B9: 45922 | C9: VZ 10-K FY2013, p.42 | E9: Verizon Notes to Vodafone ($mm) | F9: 3500 | G9: 8.5-yr notes, 5.9% coupon
A10: Enterprise Value ($mm) | B10: 178739.08 | C10: Calculated | E10: Other (Omnitel stake, misc.) ($mm) | F10: 6712 | G10: Calculated
A12: Historical NI – 2008 ($mm) | B12: -2193 | C12: VZ 10-K FY2010; pension remeasurement loss renders 2008 NI negative | E12: New Shares Issued (mm) | F12: 1274 | G12: VZ 8-K – 1,274mm new VZ shares
A13: Historical NI – 2009 ($mm) | B13: 4894 | C13: VZ 10-K FY2012 (SEC EDGAR), Selected Financial Data | E13: Issue Price (implied) | F13: 47.798273 | G13: Avg. price at closing
A14: Historical NI – 2010 ($mm) | B14: 2549 | C14: VZ 10-K FY2012 (SEC EDGAR), Selected Financial Data
A15: Historical NI – 2011 ($mm) | B15: 2404 | C15: VZ 10-K FY2012 (SEC EDGAR), Selected Financial Data | E15: New Debt Raised ($mm) | F15: 49000 | G15: VZ record bond offering, Feb 2014
A16: Historical NI – 2012 ($mm) | B16: 875 | C16: VZ 10-K FY2013 (SEC EDGAR), Selected Financial Data | E16: Blended Interest Rate on New Debt | F16: 0.055 | G16: Weighted avg. coupon assumption
A17: 5-Yr CAGR 2008–2012 | B17: N/A – neg. base | C17: ⚠ 2008 NI is negative (pension charge) → CAGR undefined; see note below | E17: Tax Rate | F17: 0.2319 | G17: 23.19% blended effective rate
E18: After-tax Interest Cost ($mm) – Yr 1 | F18: 2070.0295 | G18: Calculated
A19: NI Growth Rate – Analyst Consensus | B19: 0.055 | C19: Buy-side consensus fwd EPS growth for VZ at time of deal (FactSet ~5–6%)
A20: Used for Year 2 growth | B20: 0.055 | C20: Linked from consensus rate | E20: Annual Synergies ($mm) – Pre-Tax | F20: 500 | G20: Conservative; VZ guided $1B+ LT
A21: Used for Year 3 growth | B21: 0.055 | C21: Linked from consensus rate | E21: D&A on Purchase Price Step-Up ($mm/yr) | F21: 800 | G21: Est. incremental amortization
E22: Yr 1 Transaction/Integration Costs ($mm) | F22: 1200 | G22: One-time costs, Year 1 only
A23: LTM Net Income Attr. to VZ ($mm) | B23: 11497 | C23: VZ 10-K FY2013, p.50 (55% VZW share)
A24: Standalone EPS (Diluted) | B24: 4.0087169 | C24: Calculated
A26: Pro Forma Net Income – Year 1 ($mm) | B26: 17800 | C26: Mgmt guidance, Feb 2014 IR presentation
A27: Pro Forma Net Income – Year 2 ($mm) | B27: 18779 | C27: Calculated using consensus growth
A28: Pro Forma Net Income – Year 3 ($mm) | B28: 19811.845 | C28: Calculated using consensus growth
A29: ⚠ NOTE: 2008–2012 CAGR cannot be calculated because 2008 VZ net income was $(2,193)mm (negative), driven by a large non-cash pension/OPEB remeasurement loss. A CAGR from a negative base is mathematically undefined. Analyst consensus forward growth (~5.5%) is used instead as the industry-standard approach for accretion/dilution models.
A32: Color Key: Blue = Hardcoded Input Black = Formula Green = Cross-sheet link

Sheet EPS Accretion-Dilution (2)
A1: VERIZON / VODAFONE – EPS ACCRETION / DILUTION ANALYSIS (v2)
A2: NI growth = analyst consensus ~5.5% | Tax Rate = 23.19% | $mm unless noted
A4: Description | B4: Year 1 (FY2014E) | C4: Year 2 (FY2015E) | D4: Year 3 (FY2016E)
A5: 1. PRO FORMA SHARE COUNT
A6: Standalone Diluted Shares (mm) | B6: 2868 | C6: 2868 | D6: 2868
A7: (+) New Shares Issued to Vodafone (mm) | B7: 1274 | C7: 1274 | D7: 1274
A8: Pro Forma Diluted Shares (mm) | B8: 4142 | C8: 4142 | D8: 4142
A10: 2. STANDALONE EPS (55% VZW OWNERSHIP)
A11: Standalone Net Income ($mm) | B11: 11497 | C11: 12129.335 | D11: 12796.448
A12: Standalone Diluted Shares (mm) | B12: 2868 | C12: 2868 | D12: 2868
A13: STANDALONE EPS (Diluted) | B13: 4.0087169 | C13: 4.2291963 | D13: 4.4618021
A15: 3. PRO FORMA NET INCOME BRIDGE ($MM)
A16: Standalone Net Income ($mm) | B16: 11497 | C16: 12129.335 | D16: 12796.448
A17: (+) Incr. NI from 100% VZW Ownership | B17: 6303 | C17: 6649.665 | D17: 7015.3966
A18: (-) After-tax Interest on New Debt | B18: -2070.0295 | C18: -2070.0295 | D18: -2070.0295
A19: (+) After-tax Synergies | B19: 384.05 | C19: 422.455 | D19: 460.86
A20: (-) D&A on Purchase Price Step-Up | B20: -800 | C20: -800 | D20: -800
A21: (-) Transaction / Integration Costs | B21: -1200 | C21: 0 | D21: 0
A22: PRO FORMA NET INCOME ($mm) | B22: 14114.021 | C22: 16331.425 | D22: 17402.676
A24: 4. PRO FORMA EPS & ACCRETION / (DILUTION)
A25: Pro Forma Net Income ($mm) | B25: 14114.021 | C25: 16331.425 | D25: 17402.676
A26: Pro Forma Diluted Shares (mm) | B26: 4142 | C26: 4142 | D26: 4142
A27: PRO FORMA EPS (Diluted) | B27: 3.4075375 | C27: 3.942884 | D27: 4.2015151
A29: Standalone EPS | B29: 4.0087169 | C29: 4.2291963 | D29: 4.4618021
A30: Pro Forma EPS | B30: 3.4075375 | C30: 3.942884 | D30: 4.2015151
A31: $ Accretion / (Dilution) | B31: -0.60117933 | C31: -0.28631231 | D31: -0.26028701
A32: % Accretion / (Dilution) | B32: -0.14996802 | C32: -0.067698988 | D32: -0.058336745
A34: Color Key: Green fill = Accretive Red fill = Dilutive Yellow = Breakeven (±2%)
A35: VERIZON / VODAFONE – YEAR 3 EPS SENSITIVITY ANALYSIS
A36: Vary Pre-Tax Synergies ($mm) vs. NI Growth Rate | Base: Synergies=$500mm, Growth=5.5%
A38: TABLE 1 – PRO FORMA EPS (YEAR 3)
A39: Synergies ($mm) ↓ / Growth → | B39: 3.0% | C39: 4.0% | D39: 5.5% (Base) | E39: 7.0% | F39: 9.0% | G39: 11.0%
A40: 0 | B40: 3.8662459 | C40: 3.9552029 | D40: 4.09025 | E40: 4.2272309 | F40: 4.4128804 | G40: 4.6019678
A41: 250 | B41: 3.9218784 | C41: 4.0108355 | D41: 4.1458825 | E41: 4.2828635 | F41: 4.4685129 | G41: 4.6576003
A42: 500 | B42: 3.977511 | C42: 4.066468 | D42: 4.2015151 | E42: 4.338496 | F42: 4.5241455 | G42: 4.7132329
A43: 750 | B43: 4.0331435 | C43: 4.1221006 | D43: 4.2571476 | E43: 4.3941286 | F43: 4.579778 | G43: 4.7688654
A44: 1000 | B44: 4.0887761 | C44: 4.1777331 | D44: 4.3127802 | E44: 4.4497611 | F44: 4.6354106 | G44: 4.8244979
A45: 1500 | B45: 4.2000412 | C45: 4.2889982 | D45: 4.4240453 | E45: 4.5610262 | F45: 4.7466756 | G45: 4.935763
A46: 2000 | B46: 4.3113063 | C46: 4.4002633 | D46: 4.5353104 | E46: 4.6722913 | F46: 4.8579407 | G46: 5.0470281
A48: TABLE 2 – % ACCRETION / (DILUTION) (YEAR 3)
...

Sheet Deal Structure (2)
A1: VERIZON / VODAFONE – DEAL STRUCTURE & CONSIDERATION
A2: Breakdown of $130bn total consideration | Closed February 21, 2014
A4: Consideration Component | B4: Amount ($mm) | C4: % of Total | D4: Notes
A5: Cash (new debt + balance sheet) | B5: 58893 | C5: 0.45302308 | D5: Record bond offering ($49bn new debt)
A6: Verizon Stock (new shares) | B6: 60895 | C6: 0.46842308 | D6: 1,274mm new VZ shares issued
A7: Verizon Notes to Vodafone | B7: 3500 | C7: 0.026923077 | D7: 8.5-yr notes, 5.9% coupon
A8: Other (Omnitel, misc.) | B8: 6712 | C8: 0.051630769 | D8: Verizon Italy + other non-cash
A9: TOTAL CONSIDERATION | B9: 130000 | C9: 1 | D9: Announced Sep 2, 2013
A11: OWNERSHIP – VERIZON WIRELESS
A12: Entity | B12: Pre-Deal | C12: Post-Deal | D12: Change
A13: Verizon Communications | B13: 0.55 | C13: 1 | D13: 0.45
A14: Vodafone Group | B14: 0.45 | C14: 0 | D14: -0.45

Sheet EPS Accretion Analysis ->
A1: VERIZON / VODAFONE – EPS ACCRETION MODEL - PREVIOUS VERSIONS HIDDEN

Sheet Assumptions (3) Old
A1: VERIZON / VODAFONE – EPS ACCRETION / DILUTION MODEL (v3)
A2: Transaction: Verizon acquires Vodafone's 45% stake in Verizon Wireless | Announced Sep 2 2013 | Closed Feb 21 2014
A4: A. ACQUIRER – VERIZON COMMUNICATIONS (VZ) | E4: B. TARGET / DEAL TERMS – VODAFONE 45% STAKE
A5: Assumption | B5: Value | C5: Notes / Source | E5: Assumption | F5: Value | G5: Notes / Source
A6: Share Price (at announcement) | B6: 46.31 | C6: Bloomberg, Sep 2 2013 | E6: Total Transaction Value ($mm) | F6: 130000 | G6: VZ press release, Sep 2 2013
A7: Diluted Shares Outstanding (mm) | B7: 2868 | C7: VZ 10-K FY2013, p.38 (SEC EDGAR) | E7: Cash Consideration ($mm) | F7: 58893 | G7: VZ 8-K, Sep 2 2013
A8: Market Capitalization ($mm) | B8: 132817.08 | C8: Calculated | E8: VZ Stock Consideration ($mm) | F8: 60895 | G8: VZ 8-K Sep 2 2013 (new VZ shares)
A9: Net Debt ($mm) | B9: 45922 | C9: VZ 10-K FY2013, p.42 | E9: Verizon Notes to Vodafone ($mm) | F9: 3500 | G9: 8.5-yr notes, 5.9% coupon
A10: Enterprise Value ($mm) | B10: 178739.08 | C10: Calculated | E10: Other (Omnitel stake, misc.) ($mm) | F10: 6712 | G10: Calculated
A12: Historical NI – 2008 ($mm) | B12: -2193 | C12: VZ 10-K FY2010; pension remeasurement loss renders 2008 NI negative | E12: New Shares Issued (mm) | F12: 1274 | G12: VZ 8-K – 1,274mm new VZ shares
A13: Historical NI – 2009 ($mm) | B13: 4894 | C13: VZ 10-K FY2012 (SEC EDGAR), Selected Financial Data | E13: Issue Price (implied) | F13: 47.798273 | G13: Avg. price at closing
A14: Historical NI – 2010 ($mm) | B14: 2549 | C14: VZ 10-K FY2012 (SEC EDGAR), Selected Financial Data
A15: Historical NI – 2011 ($mm) | B15: 2404 | C15: VZ 10-K FY2012 (SEC EDGAR), Selected Financial Data | E15: New Debt Raised ($mm) | F15: 49000 | G15: VZ record bond offering, Feb 2014
A16: Historical NI – 2012 ($mm) | B16: 875 | C16: VZ 10-K FY2013 (SEC EDGAR), Selected Financial Data | E16: Blended Interest Rate on New Debt | F16: 0.055 | G16: Weighted avg. coupon assumption
A17: 5-Yr CAGR 2008–2012 | B17: N/A – neg. base | C17: ⚠ 2008 NI is negative (pension charge) → CAGR undefined; see note below | E17: Tax Rate | F17: 0.2319 | G17: 23.19% blended effective rate
E18: After-tax Interest Cost ($mm) – Yr 1 | F18: 2070.0295 | G18: Calculated
A19: NI Growth Rate – Analyst Consensus | B19: 0.04 | C19: NI growth rate per instruction (4.0%) for VZ at time of deal (FactSet ~5–6%)
A20: Used for Year 2 growth | B20: 0.04 | C20: Linked from consensus rate | E20: Annual Synergies ($mm) – Pre-Tax | F20: 500 | G20: Conservative; VZ guided $1B+ LT
A21: Used for Year 3 growth | B21: 0.04 | C21: Linked from consensus rate | E21: D&A on Purchase Price Step-Up ($mm/yr) | F21: 800 | G21: Est. incremental amortization
E22: Yr 1 Transaction/Integration Costs ($mm) | F22: 1200 | G22: One-time costs, Year 1 only
A23: LTM Net Income Attr. to VZ ($mm) | B23: 11497 | C23: VZ 10-K FY2013, p.50 (55% VZW share)
A24: Standalone EPS (Diluted) | B24: 4.0087169 | C24: Calculated
A26: Pro Forma Net Income – Year 1 ($mm) | B26: 17800 | C26: Mgmt guidance, Feb 2014 IR presentation
A27: Pro Forma Net Income – Year 2 ($mm) | B27: 18512 | C27: Calculated using consensus growth
A28: Pro Forma Net Income – Year 3 ($mm) | B28: 19252.48 | C28: Calculated using consensus growth
A29: ⚠ NOTE: 2008–2012 CAGR cannot be calculated because 2008 VZ net income was $(2,193)mm (negative), driven by a large non-cash pension/OPEB remeasurement loss. A CAGR from a negative base is mathematically undefined. NI growth rate of 4.0% is used per instruction. used instead as the industry-standard approach for accretion/dilution models.
A32: Color Key: Blue = Hardcoded Input Black = Formula Green = Cross-sheet link

Sheet EPS Accretion-Dilution (3) old
A1: VERIZON / VODAFONE – EPS ACCRETION / DILUTION ANALYSIS (v3)
A2: NI growth = 4.0% | Tax Rate = 23.19% | $mm unless noted
A4: Description | B4: Year 1 (FY2014E) | C4: Year 2 (FY2015E) | D4: Year 3 (FY2016E)
A5: 1. PRO FORMA SHARE COUNT
A6: Standalone Diluted Shares (mm) | B6: 2868 | C6: 2868 | D6: 2868
A7: (+) New Shares Issued to Vodafone (mm) | B7: 1274 | C7: 1274 | D7: 1274
A8: Pro Forma Diluted Shares (mm) | B8: 4142 | C8: 4142 | D8: 4142
A10: 2. STANDALONE EPS (55% VZW OWNERSHIP)
A11: Standalone Net Income ($mm) | B11: 11497 | C11: 11956.88 | D11: 12435.155
A12: Standalone Diluted Shares (mm) | B12: 2868 | C12: 2868 | D12: 2868
A13: STANDALONE EPS (Diluted) | B13: 4.0087169 | C13: 4.1690656 | D13: 4.3358282
A15: 3. PRO FORMA NET INCOME BRIDGE ($MM)
A16: Standalone Net Income ($mm) | B16: 11497 | C16: 11956.88 | D16: 12435.155
A17: (+) Incr. NI from 100% VZW Ownership | B17: 6303 | C17: 6555.12 | D17: 6817.3248
A18: (-) After-tax Interest on New Debt | B18: -2070.0295 | C18: -2070.0295 | D18: -2070.0295
A19: (+) After-tax Synergies | B19: 384.05 | C19: 422.455 | D19: 460.86
A20: (-) D&A on Purchase Price Step-Up | B20: -800 | C20: -800 | D20: -800
A21: (-) Transaction / Integration Costs | B21: -1200 | C21: 0 | D21: 0
A22: PRO FORMA NET INCOME ($mm) | B22: 14114.021 | C22: 16064.425 | D22: 16843.31
A24: 4. PRO FORMA EPS & ACCRETION / (DILUTION)
A25: Pro Forma Net Income ($mm) | B25: 14114.021 | C25: 16064.425 | D25: 16843.31
A26: Pro Forma Diluted Shares (mm) | B26: 4142 | C26: 4142 | D26: 4142
A27: PRO FORMA EPS (Diluted) | B27: 3.4075375 | C27: 3.8784224 | D27: 4.066468
A29: Standalone EPS | B29: 4.0087169 | C29: 4.1690656 | D29: 4.3358282
A30: Pro Forma EPS | B30: 3.4075375 | C30: 3.8784224 | D30: 4.066468
A31: $ Accretion / (Dilution) | B31: -0.60117933 | C31: -0.29064317 | D31: -0.26936016
A32: % Accretion / (Dilution) | B32: -0.14996802 | C32: -0.069714224 | D32: -0.062124271
A34: Color Key: Green fill = Accretive Red fill = Dilutive Yellow = Breakeven (±2%)
A35: VERIZON / VODAFONE – YEAR 3 EPS SENSITIVITY ANALYSIS
A36: Vary Pre-Tax Synergies ($mm) vs. NI Growth Rate | Base: Synergies=$500mm, Growth=4.0%
A38: TABLE 1 – PRO FORMA EPS (YEAR 3)
A39: Synergies ($mm) ↓ / Growth → | B39: 2.0% | C39: 3.0% | D39: 4.0% (Base) | E39: 5.0% | F39: 6.0% | G39: 7.0%
A40: 0 | B40: 3.7781484 | C40: 3.8662459 | D40: 3.9552029 | E40: 4.0450194 | F40: 4.1356954 | G40: 4.2272309
A41: 250 | B41: 3.8337809 | C41: 3.9218784 | D41: 4.0108355 | E41: 4.100652 | F41: 4.191328 | G41: 4.2828635
A42: 500 | B42: 3.8894134 | C42: 3.977511 | D42: 4.066468 | E42: 4.1562845 | F42: 4.2469605 | G42: 4.338496
A43: 750 | B43: 3.945046 | C43: 4.0331435 | D43: 4.1221006 | E43: 4.2119171 | F43: 4.3025931 | G43: 4.3941286
A44: 1000 | B44: 4.0006785 | C44: 4.0887761 | D44: 4.1777331 | E44: 4.2675496 | F44: 4.3582256 | G44: 4.4497611
A45: 1500 | B45: 4.1119436 | C45: 4.2000412 | D45: 4.2889982 | E45: 4.3788147 | F45: 4.4694907 | G45: 4.5610262
A46: 2000 | B46: 4.2232087 | C46: 4.3113063 | D46: 4.4002633 | E46: 4.4900798 | F46: 4.5807558 | G46: 4.6722913
A48: TABLE 2 – % ACCRETION / (DILUTION) (YEAR 3)
...

Sheet Deal Structure (3) Old
A1: VERIZON / VODAFONE – DEAL STRUCTURE & CONSIDERATION
A2: Breakdown of $130bn total consideration | Closed February 21, 2014
A4: Consideration Component | B4: Amount ($mm) | C4: % of Total | D4: Notes
A5: Cash (new debt + balance sheet) | B5: 58893 | C5: 0.45302308 | D5: Record bond offering ($49bn new debt)
A6: Verizon Stock (new shares) | B6: 60895 | C6: 0.46842308 | D6: 1,274mm new VZ shares issued
A7: Verizon Notes to Vodafone | B7: 3500 | C7: 0.026923077 | D7: 8.5-yr notes, 5.9% coupon
A8: Other (Omnitel, misc.) | B8: 6712 | C8: 0.051630769 | D8: Verizon Italy + other non-cash
A9: TOTAL CONSIDERATION | B9: 130000 | C9: 1 | D9: Announced Sep 2, 2013
A11: OWNERSHIP – VERIZON WIRELESS
A12: Entity | B12: Pre-Deal | C12: Post-Deal | D12: Change
A13: Verizon Communications | B13: 0.55 | C13: 1 | D13: 0.45
A14: Vodafone Group | B14: 0.45 | C14: 0 | D14: -0.45

Sheet Assumptions (VF)
A1: VERIZON / VODAFONE – EPS ACCRETION / DILUTION MODEL (v4)
A2: Transaction: Verizon acquires Vodafone's 45% stake in Verizon Wireless | Announced Sep 2 2013 | Closed Feb 21 2014
A4: A. ACQUIRER – VERIZON COMMUNICATIONS (VZ) | E4: B. TARGET / DEAL TERMS – VODAFONE 45% STAKE
A5: Assumption | B5: Value | C5: Notes / Source | E5: Assumption | F5: Value | G5: Notes / Source
A6: Share Price (at announcement) | B6: 46.31 | C6: Bloomberg, Sep 2 2013 | E6: Total Transaction Value ($mm) | F6: 130000 | G6: VZ press release, Sep 2 2013
A7: Diluted Shares Outstanding (mm) | B7: 2868 | C7: VZ 10-K FY2013, p.38 (SEC EDGAR) | E7: Cash Consideration ($mm) | F7: 58893 | G7: VZ 8-K, Sep 2 2013
A8: Market Capitalization ($mm) | B8: =B6*B7 -> 132817.08 | C8: Calculated | E8: VZ Stock Consideration ($mm) | F8: 60895 | G8: VZ 8-K Sep 2 2013 (new VZ shares)
A9: Net Debt ($mm) | B9: 45922 | C9: VZ 10-K FY2013, p.42 | E9: Verizon Notes to Vodafone ($mm) | F9: 3500 | G9: 8.5-yr notes, 5.9% coupon
A10: Enterprise Value ($mm) | B10: =B8+B9 -> 178739.08 | C10: Calculated | E10: Other (Omnitel stake, misc.) ($mm) | F10: =F6-F7-F8-F9 -> 6712 | G10: Calculated
A12: Historical NI – 2008 ($mm) | B12: -2193 | C12: VZ 10-K FY2010; pension remeasurement loss renders 2008 NI negative | E12: New Shares Issued (mm) | F12: 1274 | G12: VZ 8-K – 1,274mm new VZ shares
A13: Historical NI – 2009 ($mm) | B13: 4894 | C13: VZ 10-K FY2012 (SEC EDGAR), Selected Financial Data | E13: Issue Price (implied) | F13: =F8/F12 -> 47.798273 | G13: Avg. price at closing
A14: Historical NI – 2010 ($mm) | B14: 2549 | C14: VZ 10-K FY2012 (SEC EDGAR), Selected Financial Data
A15: Historical NI – 2011 ($mm) | B15: 2404 | C15: VZ 10-K FY2012 (SEC EDGAR), Selected Financial Data | E15: New Debt Raised ($mm) | F15: 49000 | G15: VZ record bond offering, Feb 2014
A16: Historical NI – 2012 ($mm) | B16: 875 | C16: VZ 10-K FY2013 (SEC EDGAR), Selected Financial Data | E16: Blended Interest Rate on New Debt | F16: 0.055 | G16: Weighted avg. coupon assumption
A17: 5-Yr CAGR 2008–2012 | B17: =IF(B12<0,"N/A – neg. base",((B16/B12)^(1/4)-1)) -> N/A – neg. base | C17: ⚠ 2008 NI is negative (pension charge) → CAGR undefined; see note below | E17: Tax Rate | F17: 0.2319 | G17: 23.19% blended effective rate
E18: After-tax Interest Cost ($mm) – Yr 1 | F18: =F15*F16*(1-F17) -> 2070.0295 | G18: Calculated
A19: NI Growth Rate – Analyst Consensus | B19: 0.04 | C19: NI growth rate per instruction (4.0%) for VZ at time of deal (FactSet ~5–6%)
A20: Used for Year 2 growth | B20: =B19 -> 0.04 | C20: Linked from consensus rate | E20: Annual Synergies ($mm) – Pre-Tax | F20: 500 | G20: Conservative; VZ guided $1B+ LT
A21: Used for Year 3 growth | B21: =B19 -> 0.04 | C21: Linked from consensus rate | E21: D&A on Purchase Price Step-Up ($mm/yr) | F21: 800 | G21: Est. incremental amortization
E22: Yr 1 Transaction/Integration Costs ($mm) | F22: 1200 | G22: One-time costs, Year 1 only
A23: LTM Net Income Attr. to VZ ($mm) | B23: 11497 | C23: VZ 10-K FY2013, p.50 (55% VZW share)
A24: Standalone EPS (Diluted) | B24: =B23/B7 -> 4.0087169 | C24: Calculated
A26: Pro Forma Net Income – Year 1 ($mm) | B26: 17800 | C26: Mgmt guidance, Feb 2014 IR presentation
A27: Pro Forma Net Income – Year 2 ($mm) | B27: =B26*(1+B20) -> 18512 | C27: Calculated using consensus growth
A28: Pro Forma Net Income – Year 3 ($mm) | B28: =B27*(1+B21) -> 19252.48 | C28: Calculated using consensus growth
A29: ⚠ NOTE: 2008–2012 CAGR cannot be calculated because 2008 VZ net income was $(2,193)mm (negative), driven by a large non-cash pension/OPEB remeasurement loss. A CAGR from a negative base is mathematically undefined. NI growth rate of 4.0% is used per instruction. used instead as the industry-standard approach for accretion/dilution models.
A32: Color Key: Blue = Hardcoded Input Black = Formula Green = Cross-sheet link

Sheet EPS Accretion-Dilution (VF)
A1: VERIZON / VODAFONE – EPS ACCRETION / DILUTION ANALYSIS (v4)
A2: NI growth = 4.0% | Tax Rate = 23.19% | $mm unless noted
A4: Description | B4: Year 1 (FY2014E) | C4: Year 2 (FY2015E) | D4: Year 3 (FY2016E)
A5: 1. PRO FORMA SHARE COUNT
A6: Standalone Diluted Shares (mm) | B6: ='Assumptions (VF)'!B7 -> 2868 | C6: ='Assumptions (VF)'!B7 -> 2868 | D6: ='Assumptions (VF)'!B7 -> 2868
A7: (+) New Shares Issued to Vodafone (mm) | B7: ='Assumptions (VF)'!F12 -> 1274 | C7: ='Assumptions (VF)'!F12 -> 1274 | D7: ='Assumptions (VF)'!F12 -> 1274
A8: Pro Forma Diluted Shares (mm) | B8: =B6+B7 -> 4142 | C8: =C6+C7 -> 4142 | D8: =D6+D7 -> 4142
A10: 2. STANDALONE EPS (55% VZW OWNERSHIP)
A11: Standalone Net Income ($mm) | B11: ='Assumptions (VF)'!B23 -> 11497 | C11: =B11*(1+'Assumptions (VF)'!B20) -> 11956.88 | D11: =C11*(1+'Assumptions (VF)'!B21) -> 12435.155
A12: Standalone Diluted Shares (mm) | B12: ='Assumptions (VF)'!B7 -> 2868 | C12: ='Assumptions (VF)'!B7 -> 2868 | D12: ='Assumptions (VF)'!B7 -> 2868
A13: STANDALONE EPS (Diluted) | B13: =B11/B12 -> 4.0087169 | C13: =C11/C12 -> 4.1690656 | D13: =D11/D12 -> 4.3358282
A15: 3. PRO FORMA NET INCOME BRIDGE ($MM)
A16: Standalone Net Income ($mm) | B16: =B11 -> 11497 | C16: =C11 -> 11956.88 | D16: =D11 -> 12435.155
A17: (+) Incr. NI from 100% VZW Ownership | B17: ='Assumptions (VF)'!B26-'Assumptions (VF)'!B23 -> 6303 | C17: ='Assumptions (VF)'!B27-B11*(1+'Assumptions (VF)'!B20) -> 6555.12 | D17: ='Assumptions (VF)'!B28-C11*(1+'Assumptions (VF)'!B21) -> 6817.3248
A18: (-) After-tax Interest on New Debt | B18: =-'Assumptions (VF)'!F18 -> -2070.0295 | C18: =-'Assumptions (VF)'!F18 -> -2070.0295 | D18: =-'Assumptions (VF)'!F18 -> -2070.0295
A19: (+) After-tax Synergies | B19: ='Assumptions (VF)'!F20*(1-'Assumptions (VF)'!F17) -> 384.05 | C19: ='Assumptions (VF)'!F20*(1-'Assumptions (VF)'!F17)*1.1 -> 422.455 | D19: ='Assumptions (VF)'!F20*(1-'Assumptions (VF)'!F17)*1.2 -> 460.86
A20: (-) D&A on Purchase Price Step-Up | B20: =-'Assumptions (VF)'!F21 -> -800 | C20: =-'Assumptions (VF)'!F21 -> -800 | D20: =-'Assumptions (VF)'!F21 -> -800
A21: (-) Transaction / Integration Costs | B21: =-'Assumptions (VF)'!F22 -> -1200 | C21: =0 -> 0 | D21: =0 -> 0
A22: PRO FORMA NET INCOME ($mm) | B22: =SUM(B16:B21) -> 14114.02 | C22: =SUM(C16:C21) -> 16064.426 | D22: =SUM(D16:D21) -> 16843.31
A24: 4. PRO FORMA EPS & ACCRETION / (DILUTION)
A25: Pro Forma Net Income ($mm) | B25: =B22 -> 14114.02 | C25: =C22 -> 16064.426 | D25: =D22 -> 16843.31
A26: Pro Forma Diluted Shares (mm) | B26: =B8 -> 4142 | C26: =C8 -> 4142 | D26: =D8 -> 4142
A27: PRO FORMA EPS (Diluted) | B27: =B25/B26 -> 3.4075375 | C27: =C25/C26 -> 3.8784224 | D27: =D25/D26 -> 4.066468
A29: Standalone EPS | B29: =B13 -> 4.0087169 | C29: =C13 -> 4.1690656 | D29: =D13 -> 4.3358282
A30: Pro Forma EPS | B30: =B27 -> 3.4075375 | C30: =C27 -> 3.8784224 | D30: =D27 -> 4.066468
A31: $ Accretion / (Dilution) | B31: =B30-B29 -> -0.60117933 | C31: =C30-C29 -> -0.29064317 | D31: =D30-D29 -> -0.26936016
A32: % Accretion / (Dilution) | B32: =B31/B29 -> -0.14996802 | C32: =C31/C29 -> -0.069714224 | D32: =D31/D29 -> -0.062124271
A34: Color Key: Green fill = Accretive Red fill = Dilutive Yellow = Breakeven (±2%)
A35: VERIZON / VODAFONE – YEAR 3 EPS SENSITIVITY ANALYSIS
A36: Vary Pre-Tax Synergies ($mm) vs. NI Growth Rate | Base: Synergies=$500mm, Growth=4.0%
A38: TABLE 1 – PRO FORMA EPS (YEAR 3)
A39: Synergies ($mm) ↓ / Growth → | B39: 0.02 | C39: 0.03 | D39: 4.0% (Base) | E39: 0.05 | F39: 0.06 | G39: 0.07
A40: 0 | B40: =('Assumptions (VF)'!B26*(1+0.02)^2+0*1.2*(1-'Assumptions (VF)'!F17)-'Assumptions (VF)'!F18-'Assumptions (VF)'!F21)/('Assumptions (VF)'!B7+'Assumptions (VF)'!F12) -> 3.7781484 | C40: =('Assumptions (VF)'!B26*(1+0.03)^2+0*1.2*(1-'Assumptions (VF)'!F17)-'Assumptions (VF)'!F18-'Assumptions (VF)'!F21)/('Assumptions (VF)'!B7+'Assumptions (VF)'!F12) -> 3.8662459 | D40: =('Assumptions (VF)'!B26*(1+0.04)^2+0*1.2*(1-'Assumptions (VF)'!F17)-'Assumptions (VF)'!F18-'Assumptions (VF)'!F21)/('Assumptions (VF)'!B7+'Assumptions (VF)'!F12) -> 3.9552029 | E40: =('Assumptions (VF)'!B26*(1+0.05)^2+0*1.2*(1-'Assumptions (VF)'!F17)-'Assumptions (VF)'!F18-'Assumptions (VF)'!F21)/('Assumptions (VF)'!B7+'Assumptions (VF)'!F12) -> 4.0450194 | F40: =('Assumptions (VF)'!B26*(1+0.06)^2+0*1.2*(1-'Assumptions (VF)'!F17)-'Assumptions (VF)'!F18-'Assumptions (VF)'!F21)/('Assumptions (VF)'!B7+'Assumptions (VF)'!F12) -> 4.1356954 | G40: =('Assumptions (VF)'!B26*(1+0.07)^2+0*1.2*(1-'Assumptions (VF)'!F17)-'Assumptions (VF)'!F18-'Assumptions (VF)'!F21)/('Assumptions (VF)'!B7+'Assumptions (VF)'!F12) -> 4.2272309
A41: 250 | B41: =('Assumptions (VF)'!B26*(1+0.02)^2+250*1.2*(1-'Assumptions (VF)'!F17)-'Assumptions (VF)'!F18-'Assumptions (VF)'!F21)/('Assumptions (VF)'!B7+'Assumptions (VF)'!F12) -> 3.8337809 | C41: =('Assumptions (VF)'!B26*(1+0.03)^2+250*1.2*(1-'Assumptions (VF)'!F17)-'Assumptions (VF)'!F18-'Assumptions (VF)'!F21)/('Assumptions (VF)'!B7+'Assumptions (VF)'!F12) -> 3.9218784 | D41: =('Assumptions (VF)'!B26*(1+0.04)^2+250*1.2*(1-'Assumptions (VF)'!F17)-'Assumptions (VF)'!F18-'Assumptions (VF)'!F21)/('Assumptions (VF)'!B7+'Assumptions (VF)'!F12) -> 4.0108355 | E41: =('Assumptions (VF)'!B26*(1+0.05)^2+250*1.2*(1-'Assumptions (VF)'!F17)-'Assumptions (VF)'!F18-'Assumptions (VF)'!F21)/('Assumptions (VF)'!B7+'Assumptions (VF)'!F12) -> 4.100652 | F41: =('Assumptions (VF)'!B26*(1+0.06)^2+250*1.2*(1-'Assumptions (VF)'!F17)-'Assumptions (VF)'!F18-'Assumptions (VF)'!F21)/('Assumptions (VF)'!B7+'Assumptions (VF)'!F12) -> 4.191328 | G41: =('Assumptions (VF)'!B26*(1+0.07)^2+250*1.2*(1-'Assumptions (VF)'!F17)-'Assumptions (VF)'!F18-'Assumptions (VF)'!F21)/('Assumptions (VF)'!B7+'Assumptions (VF)'!F12) -> 4.2828635
A42: 500 | B42: =('Assumptions (VF)'!B26*(1+0.02)^2+500*1.2*(1-'Assumptions (VF)'!F17)-'Assumptions (VF)'!F18-'Assumptions (VF)'!F21)/('Assumptions (VF)'!B7+'Assumptions (VF)'!F12) -> 3.8894134 | C42: =('Assumptions (VF)'!B26*(1+0.03)^2+500*1.2*(1-'Assumptions (VF)'!F17)-'Assumptions (VF)'!F18-'Assumptions (VF)'!F21)/('Assumptions (VF)'!B7+'Assumptions (VF)'!F12) -> 3.977511 | D42: =('Assumptions (VF)'!B26*(1+0.04)^2+500*1.2*(1-'Assumptions (VF)'!F17)-'Assumptions (VF)'!F18-'Assumptions (VF)'!F21)/('Assumptions (VF)'!B7+'Assumptions (VF)'!F12) -> 4.066468 | E42: =('Assumptions (VF)'!B26*(1+0.05)^2+500*1.2*(1-'Assumptions (VF)'!F17)-'Assumptions (VF)'!F18-'Assumptions (VF)'!F21)/('Assumptions (VF)'!B7+'Assumptions (VF)'!F12) -> 4.1562845 | F42: =('Assumptions (VF)'!B26*(1+0.06)^2+500*1.2*(1-'Assumptions (VF)'!F17)-'Assumptions (VF)'!F18-'Assumptions (VF)'!F21)/('Assumptions (VF)'!B7+'Assumptions (VF)'!F12) -> 4.2469605 | G42: =('Assumptions (VF)'!B26*(1+0.07)^2+500*1.2*(1-'Assumptions (VF)'!F17)-'Assumptions (VF)'!F18-'Assumptions (VF)'!F21)/('Assumptions (VF)'!B7+'Assumptions (VF)'!F12) -> 4.338496
A43: 750 | B43: =('Assumptions (VF)'!B26*(1+0.02)^2+750*1.2*(1-'Assumptions (VF)'!F17)-'Assumptions (VF)'!F18-'Assumptions (VF)'!F21)/('Assumptions (VF)'!B7+'Assumptions (VF)'!F12) -> 3.945046 | C43: =('Assumptions (VF)'!B26*(1+0.03)^2+750*1.2*(1-'Assumptions (VF)'!F17)-'Assumptions (VF)'!F18-'Assumptions (VF)'!F21)/('Assumptions (VF)'!B7+'Assumptions (VF)'!F12) -> 4.0331435 | D43: =('Assumptions (VF)'!B26*(1+0.04)^2+750*1.2*(1-'Assumptions (VF)'!F17)-'Assumptions (VF)'!F18-'Assumptions (VF)'!F21)/('Assumptions (VF)'!B7+'Assumptions (VF)'!F12) -> 4.1221006 | E43: =('Assumptions (VF)'!B26*(1+0.05)^2+750*1.2*(1-'Assumptions (VF)'!F17)-'Assumptions (VF)'!F18-'Assumptions (VF)'!F21)/('Assumptions (VF)'!B7+'Assumptions (VF)'!F12) -> 4.2119171 | F43: =('Assumptions (VF)'!B26*(1+0.06)^2+750*1.2*(1-'Assumptions (VF)'!F17)-'Assumptions (VF)'!F18-'Assumptions (VF)'!F21)/('Assumptions (VF)'!B7+'Assumptions (VF)'!F12) -> 4.3025931 | G43: =('Assumptions (VF)'!B26*(1+0.07)^2+750*1.2*(1-'Assumptions (VF)'!F17)-'Assumptions (VF)'!F18-'Assumptions (VF)'!F21)/('Assumptions (VF)'!B7+'Assumptions (VF)'!F12) -> 4.3941286
A44: 1000 | B44: =('Assumptions (VF)'!B26*(1+0.02)^2+1000*1.2*(1-'Assumptions (VF)'!F17)-'Assumptions (VF)'!F18-'Assumptions (VF)'!F21)/('Assumptions (VF)'!B7+'Assumptions (VF)'!F12) -> 4.0006785 | C44: =('Assumptions (VF)'!B26*(1+0.03)^2+1000*1.2*(1-'Assumptions (VF)'!F17)-'Assumptions (VF)'!F18-'Assumptions (VF)'!F21)/('Assumptions (VF)'!B7+'Assumptions (VF)'!F12) -> 4.0887761 | D44: =('Assumptions (VF)'!B26*(1+0.04)^2+1000*1.2*(1-'Assumptions (VF)'!F17)-'Assumptions (VF)'!F18-'Assumptions (VF)'!F21)/('Assumptions (VF)'!B7+'Assumptions (VF)'!F12) -> 4.1777331 | E44: =('Assumptions (VF)'!B26*(1+0.05)^2+1000*1.2*(1-'Assumptions (VF)'!F17)-'Assumptions (VF)'!F18-'Assumptions (VF)'!F21)/('Assumptions (VF)'!B7+'Assumptions (VF)'!F12) -> 4.2675496 | F44: =('Assumptions (VF)'!B26*(1+0.06)^2+1000*1.2*(1-'Assumptions (VF)'!F17)-'Assumptions (VF)'!F18-'Assumptions (VF)'!F21)/('Assumptions (VF)'!B7+'Assumptions (VF)'!F12) -> 4.3582256 | G44: =('Assumptions (VF)'!B26*(1+0.07)^2+1000*1.2*(1-'Assumptions (VF)'!F17)-'Assumptions (VF)'!F18-'Assumptions (VF)'!F21)/('Assumptions (VF)'!B7+'Assumptions (VF)'!F12) -> 4.4497611
A45: 1500 | B45: =('Assumptions (VF)'!B26*(1+0.02)^2+1500*1.2*(1-'Assumptions (VF)'!F17)-'Assumptions (VF)'!F18-'Assumptions (VF)'!F21)/('Assumptions (VF)'!B7+'Assumptions (VF)'!F12) -> 4.1119436 | C45: =('Assumptions (VF)'!B26*(1+0.03)^2+1500*1.2*(1-'Assumptions (VF)'!F17)-'Assumptions (VF)'!F18-'Assumptions (VF)'!F21)/('Assumptions (VF)'!B7+'Assumptions (VF)'!F12) -> 4.2000412 | D45: =('Assumptions (VF)'!B26*(1+0.04)^2+1500*1.2*(1-'Assumptions (VF)'!F17)-'Assumptions (VF)'!F18-'Assumptions (VF)'!F21)/('Assumptions (VF)'!B7+'Assumptions (VF)'!F12) -> 4.2889982 | E45: =('Assumptions (VF)'!B26*(1+0.05)^2+1500*1.2*(1-'Assumptions (VF)'!F17)-'Assumptions (VF)'!F18-'Assumptions (VF)'!F21)/('Assumptions (VF)'!B7+'Assumptions (VF)'!F12) -> 4.3788147 | F45: =('Assumptions (VF)'!B26*(1+0.06)^2+1500*1.2*(1-'Assumptions (VF)'!F17)-'Assumptions (VF)'!F18-'Assumptions (VF)'!F21)/('Assumptions (VF)'!B7+'Assumptions (VF)'!F12) -> 4.4694907 | G45: =('Assumptions (VF)'!B26*(1+0.07)^2+1500*1.2*(1-'Assumptions (VF)'!F17)-'Assumptions (VF)'!F18-'Assumptions (VF)'!F21)/('Assumptions (VF)'!B7+'Assumptions (VF)'!F12) -> 4.5610262
A46: 2000 | B46: =('Assumptions (VF)'!B26*(1+0.02)^2+2000*1.2*(1-'Assumptions (VF)'!F17)-'Assumptions (VF)'!F18-'Assumptions (VF)'!F21)/('Assumptions (VF)'!B7+'Assumptions (VF)'!F12) -> 4.2232087 | C46: =('Assumptions (VF)'!B26*(1+0.03)^2+2000*1.2*(1-'Assumptions (VF)'!F17)-'Assumptions (VF)'!F18-'Assumptions (VF)'!F21)/('Assumptions (VF)'!B7+'Assumptions (VF)'!F12) -> 4.3113063 | D46: =('Assumptions (VF)'!B26*(1+0.04)^2+2000*1.2*(1-'Assumptions (VF)'!F17)-'Assumptions (VF)'!F18-'Assumptions (VF)'!F21)/('Assumptions (VF)'!B7+'Assumptions (VF)'!F12) -> 4.4002633 | E46: =('Assumptions (VF)'!B26*(1+0.05)^2+2000*1.2*(1-'Assumptions (VF)'!F17)-'Assumptions (VF)'!F18-'Assumptions (VF)'!F21)/('Assumptions (VF)'!B7+'Assumptions (VF)'!F12) -> 4.4900798 | F46: =('Assumptions (VF)'!B26*(1+0.06)^2+2000*1.2*(1-'Assumptions (VF)'!F17)-'Assumptions (VF)'!F18-'Assumptions (VF)'!F21)/('Assumptions (VF)'!B7+'Assumptions (VF)'!F12) -> 4.5807558 | G46: =('Assumptions (VF)'!B26*(1+0.07)^2+2000*1.2*(1-'Assumptions (VF)'!F17)-'Assumptions (VF)'!F18-'Assumptions (VF)'!F21)/('Assumptions (VF)'!B7+'Assumptions (VF)'!F12) -> 4.6722913
A48: TABLE 2 – % ACCRETION / (DILUTION) (YEAR 3)
...

Sheet Deal Structure (VF)
A1: VERIZON / VODAFONE – DEAL STRUCTURE & CONSIDERATION
A2: Breakdown of $130bn total consideration | Closed February 21, 2014
A4: Consideration Component | B4: Amount ($mm) | C4: % of Total | D4: Notes
A5: Cash (new debt + balance sheet) | B5: 58893 | C5: =B5/B9 -> 0.45302308 | D5: Record bond offering ($49bn new debt)
A6: Verizon Stock (new shares) | B6: 60895 | C6: =B6/B9 -> 0.46842308 | D6: 1,274mm new VZ shares issued
A7: Verizon Notes to Vodafone | B7: 5000 | C7: =B7/B9 -> 0.038461538 | D7: 8.5-yr notes, 5.9% coupon
A8: Other (Omnitel, misc.) | B8: =B9-B5-B6-B7 -> 5212 | C8: =B8/B9 -> 0.040092308 | D8: Verizon Italy + other non-cash
A9: TOTAL CONSIDERATION | B9: 130000 | C9: =SUM(C5:C8) -> 1 | D9: Announced Sep 2, 2013
A11: OWNERSHIP – VERIZON WIRELESS
A12: Entity | B12: Pre-Deal | C12: Post-Deal | D12: Change
A13: Verizon Communications | B13: 0.55 | C13: 1 | D13: =C13-B13 -> 0.45
A14: Vodafone Group | B14: 0.45 | C14: 0 | D14: =C14-B14 -> -0.45

Sheet ROIC VS WACC ->
A1: VERIZON / VODAFONE – ROIC VS WACC ANALYSIS

Sheet ROIC vs WACC
A1: VERIZON COMMUNICATIONS | ROIC vs. WACC — VALUE CREATION / DESTRUCTION ANALYSIS
A2: Verizon acquired Vodafone's 45% minority interest in Verizon Wireless on Feb 21, 2014 | Deal value: ~$130 Bn | Cash: ~$58.9 Bn | Stock: ~$61.3 Bn Analysis spans 2011–2018: pre-deal baseline → announcement → closing → post-deal integration
B3: ◀ PRE-DEAL BASELINE ▶ | E3: CLOSING | F3: ◀ POST-DEAL INTEGRATION ▶
A4: Metric | B4: 2011 | C4: 2012 | D4: 2013 | E4: 2014 | F4: 2015 | G4: 2016 | H4: 2017 | I4: 2018
A5: INCOME STATEMENT INPUTS ($mm)
A6: Revenue | B6: 115846 | C6: 115302 | D6: 120550 | E6: 127079 | F6: 131620 | G6: 125980 | H6: 126034 | I6: 130863
